/*******************************************************************************
 * @author Reika Kalseki
 * 
 * Copyright 2015
 * 
 * All rights reserved.
 * Distribution of the software in any form is only allowed with
 * explicit, prior permission from the owner.
 ******************************************************************************/
package Reika.ChromatiCraft.World.Dimension.Structure.Monument;

import java.util.Random;

import net.minecraft.block.Block;
import Reika.ChromatiCraft.Block.Worldgen.BlockStructureShield.BlockType;
import Reika.ChromatiCraft.Registry.ChromaBlocks;
import Reika.DragonAPI.Instantiable.Worldgen.ChunkSplicedGenerationCache;

public class MonumentStructure {

	private final Block sh = ChromaBlocks.STRUCTSHIELD.getBlockInstance();

	private final int ms = BlockType.STONE.metadata;
	private final int mc = BlockType.CLOAK.metadata;

	public void generate(ChunkSplicedGenerationCache world, Random r, int i, int j, int k) {
		this.doGenerate(world, i, j, k);
		this.doGenerate2(world, i, j, k);
		this.doGenerate3(world, i, j, k);
	}

	private void doGenerate(ChunkSplicedGenerationCache world, int i, int j, int k) {

		world.setBlock(i + 21, j + 0, k + 19, sh, mc);
		world.setBlock(i + 21, j + 0, k + 20, sh, mc);
		world.setBlock(i + 21, j + 0, k + 22, sh, mc);
		world.setBlock(i + 21, j + 0, k + 23, sh, mc);
		world.setBlock(i + 20, j + 0, k + 19, sh, mc);
		world.setBlock(i + 20, j + 0, k + 20, sh, mc);
		world.setBlock(i + 20, j + 0, k + 21, sh, mc);
		world.setBlock(i + 20, j + 0, k + 22, sh, mc);
		world.setBlock(i + 20, j + 0, k + 23, sh, mc);
		world.setBlock(i + 19, j + 0, k + 20, sh, mc);
		world.setBlock(i + 19, j + 0, k + 21, sh, mc);
		world.setBlock(i + 19, j + 0, k + 22, sh, mc);
		world.setBlock(i + 23, j + 0, k + 20, sh, mc);
		world.setBlock(i + 23, j + 0, k + 21, sh, mc);
		world.setBlock(i + 23, j + 0, k + 22, sh, mc);
		world.setBlock(i + 22, j + 0, k + 19, sh, mc);
		world.setBlock(i + 22, j + 0, k + 20, sh, mc);
		world.setBlock(i + 22, j + 0, k + 21, sh, mc);
		world.setBlock(i + 22, j + 0, k + 22, sh, mc);
		world.setBlock(i + 22, j + 0, k + 23, sh, mc);

		world.setBlock(i + 0, j + 0, k + 18, sh, ms);
		world.setBlock(i + 0, j + 0, k + 24, sh, ms);
		world.setBlock(i + 0, j + 1, k + 17, sh, ms);
		world.setBlock(i + 0, j + 1, k + 18, sh, ms);
		world.setBlock(i + 0, j + 1, k + 19, sh, ms);
		world.setBlock(i + 0, j + 1, k + 23, sh, ms);
		world.setBlock(i + 0, j + 1, k + 24, sh, ms);
		world.setBlock(i + 0, j + 1, k + 25, sh, ms);
		world.setBlock(i + 0, j + 2, k + 17, sh, ms);
		world.setBlock(i + 0, j + 2, k + 18, sh, ms);
		world.setBlock(i + 0, j + 2, k + 19, sh, ms);
		world.setBlock(i + 0, j + 2, k + 23, sh, ms);
		world.setBlock(i + 0, j + 2, k + 24, sh, ms);
		world.setBlock(i + 0, j + 2, k + 25, sh, ms);
		world.setBlock(i + 0, j + 3, k + 16, sh, ms);
		world.setBlock(i + 0, j + 3, k + 17, sh, ms);
		world.setBlock(i + 0, j + 3, k + 18, sh, ms);
		world.setBlock(i + 0, j + 3, k + 19, sh, ms);
		world.setBlock(i + 0, j + 3, k + 20, sh, ms);
		world.setBlock(i + 0, j + 3, k + 22, sh, ms);
		world.setBlock(i + 0, j + 3, k + 23, sh, ms);
		world.setBlock(i + 0, j + 3, k + 24, sh, ms);
		world.setBlock(i + 0, j + 3, k + 25, sh, ms);
		world.setBlock(i + 0, j + 3, k + 26, sh, ms);
		world.setBlock(i + 0, j + 4, k + 16, sh, ms);
		world.setBlock(i + 0, j + 4, k + 17, sh, ms);
		world.setBlock(i + 0, j + 4, k + 18, sh, ms);
		world.setBlock(i + 0, j + 4, k + 19, sh, ms);
		world.setBlock(i + 0, j + 4, k + 20, sh, ms);
		world.setBlock(i + 0, j + 4, k + 22, sh, ms);
		world.setBlock(i + 0, j + 4, k + 23, sh, ms);
		world.setBlock(i + 0, j + 4, k + 24, sh, ms);
		world.setBlock(i + 0, j + 4, k + 25, sh, ms);
		world.setBlock(i + 0, j + 4, k + 26, sh, ms);
		world.setBlock(i + 0, j + 5, k + 16, sh, ms);
		world.setBlock(i + 0, j + 5, k + 20, sh, ms);
		world.setBlock(i + 0, j + 5, k + 22, sh, ms);
		world.setBlock(i + 0, j + 5, k + 26, sh, ms);
		world.setBlock(i + 0, j + 6, k + 16, sh, ms);
		world.setBlock(i + 0, j + 6, k + 20, sh, ms);
		world.setBlock(i + 0, j + 6, k + 22, sh, ms);
		world.setBlock(i + 0, j + 6, k + 24, sh, ms);
		world.setBlock(i + 0, j + 6, k + 18, sh, ms);
		world.setBlock(i + 0, j + 6, k + 26, sh, ms);
		world.setBlock(i + 0, j + 7, k + 16, sh, ms);
		world.setBlock(i + 0, j + 7, k + 20, sh, ms);
		world.setBlock(i + 0, j + 7, k + 22, sh, ms);
		world.setBlock(i + 0, j + 7, k + 26, sh, ms);
		world.setBlock(i + 0, j + 8, k + 16, sh, ms);
		world.setBlock(i + 0, j + 8, k + 17, sh, ms);
		world.setBlock(i + 0, j + 8, k + 18, sh, ms);
		world.setBlock(i + 0, j + 8, k + 19, sh, ms);
		world.setBlock(i + 0, j + 8, k + 20, sh, ms);
		world.setBlock(i + 0, j + 8, k + 22, sh, ms);
		world.setBlock(i + 0, j + 8, k + 23, sh, ms);
		world.setBlock(i + 0, j + 8, k + 24, sh, ms);
		world.setBlock(i + 0, j + 8, k + 25, sh, ms);
		world.setBlock(i + 0, j + 8, k + 26, sh, ms);
		world.setBlock(i + 0, j + 9, k + 17, sh, ms);
		world.setBlock(i + 0, j + 9, k + 18, sh, ms);
		world.setBlock(i + 0, j + 9, k + 19, sh, ms);
		world.setBlock(i + 0, j + 9, k + 23, sh, ms);
		world.setBlock(i + 0, j + 9, k + 24, sh, ms);
		world.setBlock(i + 0, j + 9, k + 25, sh, ms);
		world.setBlock(i + 0, j + 10, k + 17, sh, ms);
		world.setBlock(i + 0, j + 10, k + 18, sh, ms);
		world.setBlock(i + 0, j + 10, k + 19, sh, ms);
		world.setBlock(i + 0, j + 10, k + 23, sh, ms);
		world.setBlock(i + 0, j + 10, k + 24, sh, ms);
		world.setBlock(i + 0, j + 10, k + 25, sh, ms);
		world.setBlock(i + 0, j + 11, k + 18, sh, ms);
		world.setBlock(i + 0, j + 11, k + 24, sh, ms);
		world.setBlock(i + 1, j + 0, k + 17, sh, ms);
		world.setBlock(i + 1, j + 0, k + 18, sh, ms);
		world.setBlock(i + 1, j + 0, k + 19, sh, ms);
		world.setBlock(i + 1, j + 0, k + 23, sh, ms);
		world.setBlock(i + 1, j + 0, k + 24, sh, ms);
		world.setBlock(i + 1, j + 0, k + 25, sh, ms);
		world.setBlock(i + 1, j + 1, k + 16, sh, ms);
		world.setBlock(i + 1, j + 1, k + 17, sh, ms);
		world.setBlock(i + 1, j + 1, k + 18, sh, ms);
		world.setBlock(i + 1, j + 1, k + 19, sh, ms);
		world.setBlock(i + 1, j + 1, k + 20, sh, ms);
		world.setBlock(i + 1, j + 1, k + 22, sh, ms);
		world.setBlock(i + 1, j + 1, k + 23, sh, ms);
		world.setBlock(i + 1, j + 1, k + 24, sh, ms);
		world.setBlock(i + 1, j + 1, k + 25, sh, ms);
		world.setBlock(i + 1, j + 1, k + 26, sh, ms);
		world.setBlock(i + 1, j + 2, k + 16, sh, ms);
		world.setBlock(i + 1, j + 2, k + 17, sh, ms);
		world.setBlock(i + 1, j + 2, k + 18, sh, ms);
		world.setBlock(i + 1, j + 2, k + 19, sh, ms);
		world.setBlock(i + 1, j + 2, k + 20, sh, ms);
		world.setBlock(i + 1, j + 2, k + 22, sh, ms);
		world.setBlock(i + 1, j + 2, k + 23, sh, ms);
		world.setBlock(i + 1, j + 2, k + 24, sh, ms);
		world.setBlock(i + 1, j + 2, k + 25, sh, ms);
		world.setBlock(i + 1, j + 2, k + 26, sh, ms);
		world.setBlock(i + 1, j + 3, k + 10, sh, ms);
		world.setBlock(i + 1, j + 3, k + 16, sh, ms);
		world.setBlock(i + 1, j + 3, k + 17, sh, ms);
		world.setBlock(i + 1, j + 3, k + 19, sh, ms);
		world.setBlock(i + 1, j + 3, k + 20, sh, ms);
		world.setBlock(i + 1, j + 3, k + 22, sh, ms);
		world.setBlock(i + 1, j + 3, k + 23, sh, ms);
		world.setBlock(i + 1, j + 3, k + 25, sh, ms);
		world.setBlock(i + 1, j + 3, k + 26, sh, ms);
		world.setBlock(i + 1, j + 3, k + 32, sh, ms);
		world.setBlock(i + 1, j + 4, k + 10, sh, ms);
		world.setBlock(i + 1, j + 4, k + 16, sh, ms);
		world.setBlock(i + 1, j + 4, k + 20, sh, ms);
		world.setBlock(i + 1, j + 4, k + 22, sh, ms);
		world.setBlock(i + 1, j + 4, k + 26, sh, ms);
		world.setBlock(i + 1, j + 4, k + 32, sh, ms);
		world.setBlock(i + 1, j + 5, k + 9, sh, ms);
		world.setBlock(i + 1, j + 5, k + 10, sh, ms);
		world.setBlock(i + 1, j + 5, k + 32, sh, ms);
		world.setBlock(i + 1, j + 5, k + 33, sh, ms);
		world.setBlock(i + 1, j + 6, k + 9, sh, ms);
		world.setBlock(i + 1, j + 6, k + 10, sh, ms);
		world.setBlock(i + 1, j + 6, k + 32, sh, ms);
		world.setBlock(i + 1, j + 6, k + 33, sh, ms);
		world.setBlock(i + 1, j + 7, k + 9, sh, ms);
		world.setBlock(i + 1, j + 7, k + 10, sh, ms);
		world.setBlock(i + 1, j + 7, k + 32, sh, ms);
		world.setBlock(i + 1, j + 7, k + 33, sh, ms);
		world.setBlock(i + 1, j + 8, k + 10, sh, ms);
		world.setBlock(i + 1, j + 8, k + 16, sh, ms);
		world.setBlock(i + 1, j + 8, k + 20, sh, ms);
		world.setBlock(i + 1, j + 8, k + 22, sh, ms);
		world.setBlock(i + 1, j + 8, k + 26, sh, ms);
		world.setBlock(i + 1, j + 8, k + 32, sh, ms);
		world.setBlock(i + 1, j + 9, k + 10, sh, ms);
		world.setBlock(i + 1, j + 9, k + 16, sh, ms);
		world.setBlock(i + 1, j + 9, k + 17, sh, ms);
		world.setBlock(i + 1, j + 9, k + 19, sh, ms);
		world.setBlock(i + 1, j + 9, k + 20, sh, ms);
		world.setBlock(i + 1, j + 9, k + 22, sh, ms);
		world.setBlock(i + 1, j + 9, k + 23, sh, ms);
		world.setBlock(i + 1, j + 9, k + 25, sh, ms);
		world.setBlock(i + 1, j + 9, k + 26, sh, ms);
		world.setBlock(i + 1, j + 9, k + 32, sh, ms);
		world.setBlock(i + 1, j + 10, k + 16, sh, ms);
		world.setBlock(i + 1, j + 10, k + 17, sh, ms);
		world.setBlock(i + 1, j + 10, k + 18, sh, ms);
		world.setBlock(i + 1, j + 10, k + 19, sh, ms);
		world.setBlock(i + 1, j + 10, k + 20, sh, ms);
		world.setBlock(i + 1, j + 10, k + 22, sh, ms);
		world.setBlock(i + 1, j + 10, k + 23, sh, ms);
		world.setBlock(i + 1, j + 10, k + 24, sh, ms);
		world.setBlock(i + 1, j + 10, k + 25, sh, ms);
		world.setBlock(i + 1, j + 10, k + 26, sh, ms);
		world.setBlock(i + 1, j + 11, k + 17, sh, ms);
		world.setBlock(i + 1, j + 11, k + 18, sh, ms);
		world.setBlock(i + 1, j + 11, k + 19, sh, ms);
		world.setBlock(i + 1, j + 11, k + 23, sh, ms);
		world.setBlock(i + 1, j + 11, k + 24, sh, ms);
		world.setBlock(i + 1, j + 11, k + 25, sh, ms);
		world.setBlock(i + 1, j + 12, k + 18, sh, ms);
		world.setBlock(i + 1, j + 12, k + 24, sh, ms);
		world.setBlock(i + 2, j + 0, k + 17, sh, ms);
		world.setBlock(i + 2, j + 0, k + 18, sh, ms);
		world.setBlock(i + 2, j + 0, k + 19, sh, ms);
		world.setBlock(i + 2, j + 0, k + 23, sh, ms);
		world.setBlock(i + 2, j + 0, k + 24, sh, ms);
		world.setBlock(i + 2, j + 0, k + 25, sh, ms);
		world.setBlock(i + 2, j + 1, k + 10, sh, ms);
		world.setBlock(i + 2, j + 1, k + 16, sh, ms);
		world.setBlock(i + 2, j + 1, k + 17, sh, ms);
		world.setBlock(i + 2, j + 1, k + 18, sh, ms);
		world.setBlock(i + 2, j + 1, k + 19, sh, ms);
		world.setBlock(i + 2, j + 1, k + 20, sh, ms);
		world.setBlock(i + 2, j + 1, k + 22, sh, ms);
		world.setBlock(i + 2, j + 1, k + 23, sh, ms);
		world.setBlock(i + 2, j + 1, k + 24, sh, ms);
		world.setBlock(i + 2, j + 1, k + 25, sh, ms);
		world.setBlock(i + 2, j + 1, k + 26, sh, ms);
		world.setBlock(i + 2, j + 1, k + 32, sh, ms);
		world.setBlock(i + 2, j + 2, k + 9, sh, ms);
		world.setBlock(i + 2, j + 2, k + 10, sh, ms);
		world.setBlock(i + 2, j + 2, k + 11, sh, ms);
		world.setBlock(i + 2, j + 2, k + 16, sh, ms);
		world.setBlock(i + 2, j + 2, k + 20, sh, ms);
		world.setBlock(i + 2, j + 2, k + 22, sh, ms);
		world.setBlock(i + 2, j + 2, k + 26, sh, ms);
		world.setBlock(i + 2, j + 2, k + 31, sh, ms);
		world.setBlock(i + 2, j + 2, k + 32, sh, ms);
		world.setBlock(i + 2, j + 2, k + 33, sh, ms);
		world.setBlock(i + 2, j + 3, k + 9, sh, ms);
		world.setBlock(i + 2, j + 3, k + 10, sh, ms);
		world.setBlock(i + 2, j + 3, k + 11, sh, ms);
		world.setBlock(i + 2, j + 3, k + 31, sh, ms);
		world.setBlock(i + 2, j + 3, k + 32, sh, ms);
		world.setBlock(i + 2, j + 3, k + 33, sh, ms);
		world.setBlock(i + 2, j + 4, k + 8, sh, ms);
		world.setBlock(i + 2, j + 4, k + 9, sh, ms);
		world.setBlock(i + 2, j + 4, k + 10, sh, ms);
		world.setBlock(i + 2, j + 4, k + 11, sh, ms);
		world.setBlock(i + 2, j + 4, k + 31, sh, ms);
		world.setBlock(i + 2, j + 4, k + 32, sh, ms);
		world.setBlock(i + 2, j + 4, k + 33, sh, ms);
		world.setBlock(i + 2, j + 4, k + 34, sh, ms);
		world.setBlock(i + 2, j + 5, k + 9, sh, ms);
		world.setBlock(i + 2, j + 5, k + 10, sh, ms);
		world.setBlock(i + 2, j + 5, k + 11, sh, ms);
		world.setBlock(i + 2, j + 5, k + 31, sh, ms);
		world.setBlock(i + 2, j + 5, k + 32, sh, ms);
		world.setBlock(i + 2, j + 5, k + 33, sh, ms);
		world.setBlock(i + 2, j + 6, k + 9, sh, ms);
		world.setBlock(i + 2, j + 6, k + 11, sh, ms);
		world.setBlock(i + 2, j + 6, k + 31, sh, ms);
		world.setBlock(i + 2, j + 6, k + 33, sh, ms);
		world.setBlock(i + 2, j + 7, k + 9, sh, ms);
		world.setBlock(i + 2, j + 7, k + 10, sh, ms);
		world.setBlock(i + 2, j + 7, k + 11, sh, ms);
		world.setBlock(i + 2, j + 7, k + 31, sh, ms);
		world.setBlock(i + 2, j + 7, k + 32, sh, ms);
		world.setBlock(i + 2, j + 7, k + 33, sh, ms);
		world.setBlock(i + 2, j + 8, k + 8, sh, ms);
		world.setBlock(i + 2, j + 8, k + 9, sh, ms);
		world.setBlock(i + 2, j + 8, k + 10, sh, ms);
		world.setBlock(i + 2, j + 8, k + 11, sh, ms);
		world.setBlock(i + 2, j + 8, k + 31, sh, ms);
		world.setBlock(i + 2, j + 8, k + 32, sh, ms);
		world.setBlock(i + 2, j + 8, k + 33, sh, ms);
		world.setBlock(i + 2, j + 8, k + 34, sh, ms);
		world.setBlock(i + 2, j + 9, k + 9, sh, ms);
		world.setBlock(i + 2, j + 9, k + 10, sh, ms);
		world.setBlock(i + 2, j + 9, k + 11, sh, ms);
		world.setBlock(i + 2, j + 9, k + 31, sh, ms);
		world.setBlock(i + 2, j + 9, k + 32, sh, ms);
		world.setBlock(i + 2, j + 9, k + 33, sh, ms);
		world.setBlock(i + 2, j + 10, k + 9, sh, ms);
		world.setBlock(i + 2, j + 10, k + 10, sh, ms);
		world.setBlock(i + 2, j + 10, k + 11, sh, ms);
		world.setBlock(i + 2, j + 10, k + 16, sh, ms);
		world.setBlock(i + 2, j + 10, k + 17, sh, ms);
		world.setBlock(i + 2, j + 10, k + 18, sh, ms);
		world.setBlock(i + 2, j + 10, k + 19, sh, ms);
		world.setBlock(i + 2, j + 10, k + 20, sh, ms);
		world.setBlock(i + 2, j + 10, k + 22, sh, ms);
		world.setBlock(i + 2, j + 10, k + 23, sh, ms);
		world.setBlock(i + 2, j + 10, k + 24, sh, ms);
		world.setBlock(i + 2, j + 10, k + 25, sh, ms);
		world.setBlock(i + 2, j + 10, k + 26, sh, ms);
		world.setBlock(i + 2, j + 10, k + 31, sh, ms);
		world.setBlock(i + 2, j + 10, k + 32, sh, ms);
		world.setBlock(i + 2, j + 10, k + 33, sh, ms);
		world.setBlock(i + 2, j + 11, k + 10, sh, ms);
		world.setBlock(i + 2, j + 11, k + 16, sh, ms);
		world.setBlock(i + 2, j + 11, k + 17, sh, ms);
		world.setBlock(i + 2, j + 11, k + 18, sh, ms);
		world.setBlock(i + 2, j + 11, k + 19, sh, ms);
		world.setBlock(i + 2, j + 11, k + 20, sh, ms);
		world.setBlock(i + 2, j + 11, k + 22, sh, ms);
		world.setBlock(i + 2, j + 11, k + 23, sh, ms);
		world.setBlock(i + 2, j + 11, k + 24, sh, ms);
		world.setBlock(i + 2, j + 11, k + 25, sh, ms);
		world.setBlock(i + 2, j + 11, k + 26, sh, ms);
		world.setBlock(i + 2, j + 11, k + 32, sh, ms);
		world.setBlock(i + 2, j + 12, k + 17, sh, ms);
		world.setBlock(i + 2, j + 12, k + 18, sh, ms);
		world.setBlock(i + 2, j + 12, k + 19, sh, ms);
		world.setBlock(i + 2, j + 12, k + 23, sh, ms);
		world.setBlock(i + 2, j + 12, k + 24, sh, ms);
		world.setBlock(i + 2, j + 12, k + 25, sh, ms);
		world.setBlock(i + 3, j + 0, k + 10, sh, ms);
		world.setBlock(i + 3, j + 0, k + 11, sh, ms);
		world.setBlock(i + 3, j + 0, k + 16, sh, ms);
		world.setBlock(i + 3, j + 0, k + 17, sh, ms);
		world.setBlock(i + 3, j + 0, k + 18, sh, ms);
		world.setBlock(i + 3, j + 0, k + 19, sh, ms);
		world.setBlock(i + 3, j + 0, k + 20, sh, ms);
		world.setBlock(i + 3, j + 0, k + 22, sh, ms);
		world.setBlock(i + 3, j + 0, k + 23, sh, ms);
		world.setBlock(i + 3, j + 0, k + 24, sh, ms);
		world.setBlock(i + 3, j + 0, k + 25, sh, ms);
		world.setBlock(i + 3, j + 0, k + 26, sh, ms);
		world.setBlock(i + 3, j + 0, k + 31, sh, ms);
		world.setBlock(i + 3, j + 0, k + 32, sh, ms);
		world.setBlock(i + 3, j + 1, k + 9, sh, ms);
		world.setBlock(i + 3, j + 1, k + 10, sh, ms);
		world.setBlock(i + 3, j + 1, k + 11, sh, ms);
		world.setBlock(i + 3, j + 1, k + 12, sh, ms);
		world.setBlock(i + 3, j + 1, k + 16, sh, ms);
		world.setBlock(i + 3, j + 1, k + 20, sh, ms);
		world.setBlock(i + 3, j + 1, k + 22, sh, ms);
		world.setBlock(i + 3, j + 1, k + 26, sh, ms);
		world.setBlock(i + 3, j + 1, k + 30, sh, ms);
		world.setBlock(i + 3, j + 1, k + 31, sh, ms);
		world.setBlock(i + 3, j + 1, k + 32, sh, ms);
		world.setBlock(i + 3, j + 1, k + 33, sh, ms);
		world.setBlock(i + 3, j + 2, k + 8, sh, ms);
		world.setBlock(i + 3, j + 2, k + 9, sh, ms);
		world.setBlock(i + 3, j + 2, k + 10, sh, ms);
		world.setBlock(i + 3, j + 2, k + 11, sh, ms);
		world.setBlock(i + 3, j + 2, k + 12, sh, ms);
		world.setBlock(i + 3, j + 2, k + 30, sh, ms);
		world.setBlock(i + 3, j + 2, k + 31, sh, ms);
		world.setBlock(i + 3, j + 2, k + 32, sh, ms);
		world.setBlock(i + 3, j + 2, k + 33, sh, ms);
		world.setBlock(i + 3, j + 2, k + 34, sh, ms);
		world.setBlock(i + 3, j + 3, k + 8, sh, ms);
		world.setBlock(i + 3, j + 3, k + 9, sh, ms);
		world.setBlock(i + 3, j + 3, k + 10, sh, ms);
		world.setBlock(i + 3, j + 3, k + 11, sh, ms);
		world.setBlock(i + 3, j + 3, k + 12, sh, ms);
		world.setBlock(i + 3, j + 3, k + 30, sh, ms);
		world.setBlock(i + 3, j + 3, k + 31, sh, ms);
		world.setBlock(i + 3, j + 3, k + 32, sh, ms);
		world.setBlock(i + 3, j + 3, k + 33, sh, ms);
		world.setBlock(i + 3, j + 3, k + 34, sh, ms);
		world.setBlock(i + 3, j + 4, k + 8, sh, ms);
		world.setBlock(i + 3, j + 4, k + 9, sh, ms);
		world.setBlock(i + 3, j + 4, k + 10, sh, ms);
		world.setBlock(i + 3, j + 4, k + 11, sh, ms);
		world.setBlock(i + 3, j + 4, k + 12, sh, ms);
		world.setBlock(i + 3, j + 4, k + 30, sh, ms);
		world.setBlock(i + 3, j + 4, k + 31, sh, ms);
		world.setBlock(i + 3, j + 4, k + 32, sh, ms);
		world.setBlock(i + 3, j + 4, k + 33, sh, ms);
		world.setBlock(i + 3, j + 4, k + 34, sh, ms);
		world.setBlock(i + 3, j + 5, k + 7, sh, ms);
		world.setBlock(i + 3, j + 5, k + 8, sh, ms);
		world.setBlock(i + 3, j + 5, k + 9, sh, ms);
		world.setBlock(i + 3, j + 5, k + 33, sh, ms);
		world.setBlock(i + 3, j + 5, k + 34, sh, ms);
		world.setBlock(i + 3, j + 5, k + 35, sh, ms);
		world.setBlock(i + 3, j + 6, k + 7, sh, ms);
		world.setBlock(i + 3, j + 6, k + 8, sh, ms);
		world.setBlock(i + 3, j + 6, k + 34, sh, ms);
		world.setBlock(i + 3, j + 6, k + 35, sh, ms);
		world.setBlock(i + 3, j + 7, k + 7, sh, ms);
		world.setBlock(i + 3, j + 7, k + 8, sh, ms);
		world.setBlock(i + 3, j + 7, k + 9, sh, ms);
		world.setBlock(i + 3, j + 7, k + 33, sh, ms);
		world.setBlock(i + 3, j + 7, k + 34, sh, ms);
		world.setBlock(i + 3, j + 7, k + 35, sh, ms);
		world.setBlock(i + 3, j + 8, k + 8, sh, ms);
		world.setBlock(i + 3, j + 8, k + 9, sh, ms);
		world.setBlock(i + 3, j + 8, k + 10, sh, ms);
		world.setBlock(i + 3, j + 8, k + 11, sh, ms);
		world.setBlock(i + 3, j + 8, k + 12, sh, ms);
		world.setBlock(i + 3, j + 8, k + 30, sh, ms);
		world.setBlock(i + 3, j + 8, k + 31, sh, ms);
		world.setBlock(i + 3, j + 8, k + 32, sh, ms);
		world.setBlock(i + 3, j + 8, k + 33, sh, ms);
		world.setBlock(i + 3, j + 8, k + 34, sh, ms);
		world.setBlock(i + 3, j + 9, k + 8, sh, ms);
		world.setBlock(i + 3, j + 9, k + 9, sh, ms);
		world.setBlock(i + 3, j + 9, k + 10, sh, ms);
		world.setBlock(i + 3, j + 9, k + 11, sh, ms);
		world.setBlock(i + 3, j + 9, k + 12, sh, ms);
		world.setBlock(i + 3, j + 9, k + 30, sh, ms);
		world.setBlock(i + 3, j + 9, k + 31, sh, ms);
		world.setBlock(i + 3, j + 9, k + 32, sh, ms);
		world.setBlock(i + 3, j + 9, k + 33, sh, ms);
		world.setBlock(i + 3, j + 9, k + 34, sh, ms);
		world.setBlock(i + 3, j + 10, k + 8, sh, ms);
		world.setBlock(i + 3, j + 10, k + 9, sh, ms);
		world.setBlock(i + 3, j + 10, k + 10, sh, ms);
		world.setBlock(i + 3, j + 10, k + 11, sh, ms);
		world.setBlock(i + 3, j + 10, k + 12, sh, ms);
		world.setBlock(i + 3, j + 10, k + 30, sh, ms);
		world.setBlock(i + 3, j + 10, k + 31, sh, ms);
		world.setBlock(i + 3, j + 10, k + 32, sh, ms);
		world.setBlock(i + 3, j + 10, k + 33, sh, ms);
		world.setBlock(i + 3, j + 10, k + 34, sh, ms);
		world.setBlock(i + 3, j + 11, k + 9, sh, ms);
		world.setBlock(i + 3, j + 11, k + 10, sh, ms);
		world.setBlock(i + 3, j + 11, k + 11, sh, ms);
		world.setBlock(i + 3, j + 11, k + 12, sh, ms);
		world.setBlock(i + 3, j + 11, k + 16, sh, ms);
		world.setBlock(i + 3, j + 11, k + 17, sh, ms);
		world.setBlock(i + 3, j + 11, k + 19, sh, ms);
		world.setBlock(i + 3, j + 11, k + 20, sh, ms);
		world.setBlock(i + 3, j + 11, k + 22, sh, ms);
		world.setBlock(i + 3, j + 11, k + 23, sh, ms);
		world.setBlock(i + 3, j + 11, k + 25, sh, ms);
		world.setBlock(i + 3, j + 11, k + 26, sh, ms);
		world.setBlock(i + 3, j + 11, k + 30, sh, ms);
		world.setBlock(i + 3, j + 11, k + 31, sh, ms);
		world.setBlock(i + 3, j + 11, k + 32, sh, ms);
		world.setBlock(i + 3, j + 11, k + 33, sh, ms);
		world.setBlock(i + 3, j + 12, k + 10, sh, ms);
		world.setBlock(i + 3, j + 12, k + 11, sh, ms);
		world.setBlock(i + 3, j + 12, k + 17, sh, ms);
		world.setBlock(i + 3, j + 12, k + 19, sh, ms);
		world.setBlock(i + 3, j + 12, k + 23, sh, ms);
		world.setBlock(i + 3, j + 12, k + 25, sh, ms);
		world.setBlock(i + 3, j + 12, k + 31, sh, ms);
		world.setBlock(i + 3, j + 12, k + 32, sh, ms);
		world.setBlock(i + 4, j + 0, k + 9, sh, ms);
		world.setBlock(i + 4, j + 0, k + 10, sh, ms);
		world.setBlock(i + 4, j + 0, k + 11, sh, ms);
		world.setBlock(i + 4, j + 0, k + 12, sh, ms);
		world.setBlock(i + 4, j + 0, k + 13, sh, ms);
		world.setBlock(i + 4, j + 0, k + 16, sh, ms);
		world.setBlock(i + 4, j + 0, k + 20, sh, ms);
		world.setBlock(i + 4, j + 0, k + 22, sh, ms);
		world.setBlock(i + 4, j + 0, k + 29, sh, ms);
		world.setBlock(i + 4, j + 0, k + 30, sh, ms);
		world.setBlock(i + 4, j + 0, k + 31, sh, ms);
		world.setBlock(i + 4, j + 0, k + 32, sh, ms);
		world.setBlock(i + 4, j + 0, k + 33, sh, ms);
		world.setBlock(i + 4, j + 1, k + 8, sh, ms);
		world.setBlock(i + 4, j + 1, k + 9, sh, ms);
		world.setBlock(i + 4, j + 1, k + 10, sh, ms);
		world.setBlock(i + 4, j + 1, k + 11, sh, ms);
		world.setBlock(i + 4, j + 1, k + 12, sh, ms);
		world.setBlock(i + 4, j + 1, k + 13, sh, ms);
		world.setBlock(i + 4, j + 1, k + 29, sh, ms);
		world.setBlock(i + 4, j + 1, k + 30, sh, ms);
		world.setBlock(i + 4, j + 1, k + 31, sh, ms);
		world.setBlock(i + 4, j + 1, k + 32, sh, ms);
		world.setBlock(i + 4, j + 1, k + 33, sh, ms);
		world.setBlock(i + 4, j + 1, k + 34, sh, ms);
		world.setBlock(i + 4, j + 2, k + 8, sh, ms);
		world.setBlock(i + 4, j + 2, k + 9, sh, ms);
		world.setBlock(i + 4, j + 2, k + 10, sh, ms);
		world.setBlock(i + 4, j + 2, k + 11, sh, ms);
		world.setBlock(i + 4, j + 2, k + 12, sh, ms);
		world.setBlock(i + 4, j + 2, k + 13, sh, ms);
		world.setBlock(i + 4, j + 2, k + 29, sh, ms);
		world.setBlock(i + 4, j + 2, k + 30, sh, ms);
		world.setBlock(i + 4, j + 2, k + 31, sh, ms);
		world.setBlock(i + 4, j + 2, k + 32, sh, ms);
		world.setBlock(i + 4, j + 2, k + 33, sh, ms);
		world.setBlock(i + 4, j + 2, k + 34, sh, ms);
		world.setBlock(i + 4, j + 3, k + 7, sh, ms);
		world.setBlock(i + 4, j + 3, k + 8, sh, ms);
		world.setBlock(i + 4, j + 3, k + 9, sh, ms);
		world.setBlock(i + 4, j + 3, k + 10, sh, ms);
		world.setBlock(i + 4, j + 3, k + 11, sh, ms);
		world.setBlock(i + 4, j + 3, k + 31, sh, ms);
		world.setBlock(i + 4, j + 3, k + 32, sh, ms);
		world.setBlock(i + 4, j + 3, k + 33, sh, ms);
		world.setBlock(i + 4, j + 3, k + 34, sh, ms);
		world.setBlock(i + 4, j + 3, k + 35, sh, ms);
		world.setBlock(i + 4, j + 4, k + 7, sh, ms);
		world.setBlock(i + 4, j + 4, k + 8, sh, ms);
		world.setBlock(i + 4, j + 4, k + 9, sh, ms);
		world.setBlock(i + 4, j + 4, k + 33, sh, ms);
		world.setBlock(i + 4, j + 4, k + 34, sh, ms);
		world.setBlock(i + 4, j + 4, k + 35, sh, ms);
		world.setBlock(i + 4, j + 5, k + 7, sh, ms);
		world.setBlock(i + 4, j + 5, k + 8, sh, ms);
		world.setBlock(i + 4, j + 5, k + 34, sh, ms);
		world.setBlock(i + 4, j + 5, k + 35, sh, ms);
		world.setBlock(i + 4, j + 6, k + 7, sh, ms);
		world.setBlock(i + 4, j + 6, k + 35, sh, ms);
		world.setBlock(i + 4, j + 7, k + 7, sh, ms);
		world.setBlock(i + 4, j + 7, k + 8, sh, ms);
		world.setBlock(i + 4, j + 7, k + 34, sh, ms);
		world.setBlock(i + 4, j + 7, k + 35, sh, ms);
		world.setBlock(i + 4, j + 8, k + 7, sh, ms);
		world.setBlock(i + 4, j + 8, k + 8, sh, ms);
		world.setBlock(i + 4, j + 8, k + 9, sh, ms);
		world.setBlock(i + 4, j + 8, k + 33, sh, ms);
		world.setBlock(i + 4, j + 8, k + 34, sh, ms);
		world.setBlock(i + 4, j + 8, k + 35, sh, ms);
		world.setBlock(i + 4, j + 9, k + 7, sh, ms);
		world.setBlock(i + 4, j + 9, k + 8, sh, ms);
		world.setBlock(i + 4, j + 9, k + 9, sh, ms);
		world.setBlock(i + 4, j + 9, k + 10, sh, ms);
		world.setBlock(i + 4, j + 9, k + 11, sh, ms);
		world.setBlock(i + 4, j + 9, k + 31, sh, ms);
		world.setBlock(i + 4, j + 9, k + 32, sh, ms);
		world.setBlock(i + 4, j + 9, k + 33, sh, ms);
		world.setBlock(i + 4, j + 9, k + 34, sh, ms);
		world.setBlock(i + 4, j + 9, k + 35, sh, ms);
		world.setBlock(i + 4, j + 10, k + 8, sh, ms);
		world.setBlock(i + 4, j + 10, k + 9, sh, ms);
		world.setBlock(i + 4, j + 10, k + 10, sh, ms);
		world.setBlock(i + 4, j + 10, k + 11, sh, ms);
		world.setBlock(i + 4, j + 10, k + 12, sh, ms);
		world.setBlock(i + 4, j + 10, k + 13, sh, ms);
		world.setBlock(i + 4, j + 10, k + 29, sh, ms);
		world.setBlock(i + 4, j + 10, k + 30, sh, ms);
		world.setBlock(i + 4, j + 10, k + 31, sh, ms);
		world.setBlock(i + 4, j + 10, k + 32, sh, ms);
		world.setBlock(i + 4, j + 10, k + 33, sh, ms);
		world.setBlock(i + 4, j + 10, k + 34, sh, ms);
		world.setBlock(i + 4, j + 11, k + 8, sh, ms);
		world.setBlock(i + 4, j + 11, k + 9, sh, ms);
		world.setBlock(i + 4, j + 11, k + 10, sh, ms);
		world.setBlock(i + 4, j + 11, k + 11, sh, ms);
		world.setBlock(i + 4, j + 11, k + 12, sh, ms);
		world.setBlock(i + 4, j + 11, k + 13, sh, ms);
		world.setBlock(i + 4, j + 11, k + 29, sh, ms);
		world.setBlock(i + 4, j + 11, k + 30, sh, ms);
		world.setBlock(i + 4, j + 11, k + 31, sh, ms);
		world.setBlock(i + 4, j + 11, k + 32, sh, ms);
		world.setBlock(i + 4, j + 11, k + 33, sh, ms);
		world.setBlock(i + 4, j + 11, k + 34, sh, ms);
		world.setBlock(i + 4, j + 12, k + 9, sh, ms);
		world.setBlock(i + 4, j + 12, k + 10, sh, ms);
		world.setBlock(i + 4, j + 12, k + 11, sh, ms);
		world.setBlock(i + 4, j + 12, k + 12, sh, ms);
		world.setBlock(i + 4, j + 12, k + 17, sh, ms);
		world.setBlock(i + 4, j + 12, k + 18, sh, ms);
		world.setBlock(i + 4, j + 12, k + 19, sh, ms);
		world.setBlock(i + 4, j + 12, k + 23, sh, ms);
		world.setBlock(i + 4, j + 12, k + 24, sh, ms);
		world.setBlock(i + 4, j + 12, k + 25, sh, ms);
		world.setBlock(i + 4, j + 12, k + 30, sh, ms);
		world.setBlock(i + 4, j + 12, k + 31, sh, ms);
		world.setBlock(i + 4, j + 12, k + 32, sh, ms);
		world.setBlock(i + 4, j + 12, k + 33, sh, ms);
		world.setBlock(i + 5, j + 0, k + 9, sh, ms);
		world.setBlock(i + 5, j + 0, k + 10, sh, ms);
		world.setBlock(i + 5, j + 0, k + 11, sh, ms);
		world.setBlock(i + 5, j + 0, k + 12, sh, ms);
		world.setBlock(i + 5, j + 0, k + 13, sh, ms);
		world.setBlock(i + 5, j + 0, k + 14, sh, ms);
		world.setBlock(i + 5, j + 0, k + 16, sh, ms);
		world.setBlock(i + 5, j + 0, k + 17, sh, ms);
		world.setBlock(i + 5, j + 0, k + 18, sh, ms);
		world.setBlock(i + 5, j + 0, k + 19, sh, ms);
		world.setBlock(i + 5, j + 0, k + 20, sh, ms);
		world.setBlock(i + 5, j + 0, k + 21, sh, ms);
		world.setBlock(i + 5, j + 0, k + 22, sh, ms);
		world.setBlock(i + 5, j + 0, k + 23, sh, ms);
		world.setBlock(i + 5, j + 0, k + 24, sh, ms);
		world.setBlock(i + 5, j + 0, k + 25, sh, ms);
		world.setBlock(i + 5, j + 0, k + 26, sh, ms);
		world.setBlock(i + 5, j + 0, k + 27, sh, ms);
		world.setBlock(i + 5, j + 0, k + 28, sh, ms);
		world.setBlock(i + 5, j + 0, k + 29, sh, ms);
		world.setBlock(i + 5, j + 0, k + 30, sh, ms);
		world.setBlock(i + 5, j + 0, k + 31, sh, ms);
		world.setBlock(i + 5, j + 0, k + 32, sh, ms);
		world.setBlock(i + 5, j + 0, k + 33, sh, ms);
		world.setBlock(i + 5, j + 1, k + 9, sh, ms);
		world.setBlock(i + 5, j + 1, k + 10, sh, ms);
		world.setBlock(i + 5, j + 1, k + 11, sh, ms);
		world.setBlock(i + 5, j + 1, k + 12, sh, ms);
		world.setBlock(i + 5, j + 1, k + 13, sh, ms);
		world.setBlock(i + 5, j + 1, k + 14, sh, ms);
		world.setBlock(i + 5, j + 1, k + 28, sh, ms);
		world.setBlock(i + 5, j + 1, k + 29, sh, ms);
		world.setBlock(i + 5, j + 1, k + 30, sh, ms);
		world.setBlock(i + 5, j + 1, k + 31, sh, ms);
		world.setBlock(i + 5, j + 1, k + 32, sh, ms);
		world.setBlock(i + 5, j + 1, k + 33, sh, ms);
		world.setBlock(i + 5, j + 2, k + 8, sh, ms);
		world.setBlock(i + 5, j + 2, k + 9, sh, ms);
		world.setBlock(i + 5, j + 2, k + 10, sh, ms);
		world.setBlock(i + 5, j + 2, k + 11, sh, ms);
		world.setBlock(i + 5, j + 2, k + 31, sh, ms);
		world.setBlock(i + 5, j + 2, k + 32, sh, ms);
		world.setBlock(i + 5, j + 2, k + 33, sh, ms);
		world.setBlock(i + 5, j + 2, k + 34, sh, ms);
		world.setBlock(i + 5, j + 3, k + 8, sh, ms);
		world.setBlock(i + 5, j + 3, k + 9, sh, ms);
		world.setBlock(i + 5, j + 3, k + 10, sh, ms);
		world.setBlock(i + 5, j + 3, k + 32, sh, ms);
		world.setBlock(i + 5, j + 3, k + 33, sh, ms);
		world.setBlock(i + 5, j + 3, k + 34, sh, ms);
		world.setBlock(i + 5, j + 4, k + 8, sh, ms);
		world.setBlock(i + 5, j + 4, k + 9, sh, ms);
		world.setBlock(i + 5, j + 4, k + 33, sh, ms);
		world.setBlock(i + 5, j + 4, k + 34, sh, ms);
		world.setBlock(i + 5, j + 5, k + 8, sh, ms);
		world.setBlock(i + 5, j + 5, k + 34, sh, ms);
		world.setBlock(i + 5, j + 6, k + 8, sh, ms);
		world.setBlock(i + 5, j + 6, k + 34, sh, ms);
		world.setBlock(i + 5, j + 7, k + 8, sh, ms);
		world.setBlock(i + 5, j + 7, k + 34, sh, ms);
		world.setBlock(i + 5, j + 8, k + 8, sh, ms);
		world.setBlock(i + 5, j + 8, k + 9, sh, ms);
		world.setBlock(i + 5, j + 8, k + 33, sh, ms);
		world.setBlock(i + 5, j + 8, k + 34, sh, ms);
		world.setBlock(i + 5, j + 9, k + 8, sh, ms);
		world.setBlock(i + 5, j + 9, k + 9, sh, ms);
		world.setBlock(i + 5, j + 9, k + 10, sh, ms);
		world.setBlock(i + 5, j + 9, k + 32, sh, ms);
		world.setBlock(i + 5, j + 9, k + 33, sh, ms);
		world.setBlock(i + 5, j + 9, k + 34, sh, ms);
		world.setBlock(i + 5, j + 10, k + 8, sh, ms);
		world.setBlock(i + 5, j + 10, k + 9, sh, ms);
		world.setBlock(i + 5, j + 10, k + 10, sh, ms);
		world.setBlock(i + 5, j + 10, k + 11, sh, ms);
		world.setBlock(i + 5, j + 10, k + 12, sh, ms);
		world.setBlock(i + 5, j + 10, k + 30, sh, ms);
		world.setBlock(i + 5, j + 10, k + 31, sh, ms);
		world.setBlock(i + 5, j + 10, k + 32, sh, ms);
		world.setBlock(i + 5, j + 10, k + 33, sh, ms);
		world.setBlock(i + 5, j + 10, k + 34, sh, ms);
		world.setBlock(i + 5, j + 11, k + 9, sh, ms);
		world.setBlock(i + 5, j + 11, k + 10, sh, ms);
		world.setBlock(i + 5, j + 11, k + 11, sh, ms);
		world.setBlock(i + 5, j + 11, k + 12, sh, ms);
		world.setBlock(i + 5, j + 11, k + 13, sh, ms);
		world.setBlock(i + 5, j + 11, k + 14, sh, ms);
		world.setBlock(i + 5, j + 11, k + 28, sh, ms);
		world.setBlock(i + 5, j + 11, k + 29, sh, ms);
		world.setBlock(i + 5, j + 11, k + 30, sh, ms);
		world.setBlock(i + 5, j + 11, k + 31, sh, ms);
		world.setBlock(i + 5, j + 11, k + 32, sh, ms);
		world.setBlock(i + 5, j + 11, k + 33, sh, ms);
		world.setBlock(i + 5, j + 12, k + 9, sh, ms);
		world.setBlock(i + 5, j + 12, k + 10, sh, ms);
		world.setBlock(i + 5, j + 12, k + 12, sh, ms);
		world.setBlock(i + 5, j + 12, k + 13, sh, ms);
		world.setBlock(i + 5, j + 12, k + 18, sh, ms);
		world.setBlock(i + 5, j + 12, k + 24, sh, ms);
		world.setBlock(i + 5, j + 12, k + 29, sh, ms);
		world.setBlock(i + 5, j + 12, k + 30, sh, ms);
		world.setBlock(i + 5, j + 12, k + 32, sh, ms);
		world.setBlock(i + 5, j + 12, k + 33, sh, ms);
		world.setBlock(i + 6, j + 0, k + 10, sh, ms);
		world.setBlock(i + 6, j + 0, k + 11, sh, ms);
		world.setBlock(i + 6, j + 0, k + 12, sh, ms);
		world.setBlock(i + 6, j + 0, k + 13, sh, ms);
		world.setBlock(i + 6, j + 0, k + 14, sh, ms);
		world.setBlock(i + 6, j + 0, k + 15, sh, ms);
		world.setBlock(i + 6, j + 0, k + 16, sh, ms);
		world.setBlock(i + 6, j + 0, k + 26, sh, ms);
		world.setBlock(i + 6, j + 0, k + 27, sh, ms);
		world.setBlock(i + 6, j + 0, k + 28, sh, ms);
		world.setBlock(i + 6, j + 0, k + 29, sh, ms);
		world.setBlock(i + 6, j + 0, k + 30, sh, ms);
		world.setBlock(i + 6, j + 0, k + 31, sh, ms);
		world.setBlock(i + 6, j + 0, k + 32, sh, ms);
		world.setBlock(i + 6, j + 1, k + 9, sh, ms);
		world.setBlock(i + 6, j + 1, k + 10, sh, ms);
		world.setBlock(i + 6, j + 1, k + 11, sh, ms);
		world.setBlock(i + 6, j + 1, k + 12, sh, ms);
		world.setBlock(i + 6, j + 1, k + 30, sh, ms);
		world.setBlock(i + 6, j + 1, k + 31, sh, ms);
		world.setBlock(i + 6, j + 1, k + 32, sh, ms);
		world.setBlock(i + 6, j + 1, k + 33, sh, ms);
		world.setBlock(i + 6, j + 2, k + 9, sh, ms);
		world.setBlock(i + 6, j + 2, k + 10, sh, ms);
		world.setBlock(i + 6, j + 2, k + 32, sh, ms);
		world.setBlock(i + 6, j + 2, k + 33, sh, ms);
		world.setBlock(i + 6, j + 3, k + 9, sh, ms);
		world.setBlock(i + 6, j + 3, k + 33, sh, ms);
		world.setBlock(i + 6, j + 4, k + 9, sh, ms);
		world.setBlock(i + 6, j + 4, k + 33, sh, ms);
		world.setBlock(i + 6, j + 8, k + 9, sh, ms);
		world.setBlock(i + 6, j + 8, k + 33, sh, ms);
		world.setBlock(i + 6, j + 9, k + 9, sh, ms);
		world.setBlock(i + 6, j + 9, k + 33, sh, ms);
		world.setBlock(i + 6, j + 10, k + 9, sh, ms);
		world.setBlock(i + 6, j + 10, k + 10, sh, ms);
		world.setBlock(i + 6, j + 10, k + 11, sh, ms);
		world.setBlock(i + 6, j + 10, k + 31, sh, ms);
		world.setBlock(i + 6, j + 10, k + 32, sh, ms);
		world.setBlock(i + 6, j + 10, k + 33, sh, ms);
		world.setBlock(i + 6, j + 11, k + 9, sh, ms);
		world.setBlock(i + 6, j + 11, k + 10, sh, ms);
		world.setBlock(i + 6, j + 11, k + 11, sh, ms);
		world.setBlock(i + 6, j + 11, k + 12, sh, ms);
		world.setBlock(i + 6, j + 11, k + 13, sh, ms);
		world.setBlock(i + 6, j + 11, k + 14, sh, ms);
		world.setBlock(i + 6, j + 11, k + 28, sh, ms);
		world.setBlock(i + 6, j + 11, k + 29, sh, ms);
		world.setBlock(i + 6, j + 11, k + 30, sh, ms);
		world.setBlock(i + 6, j + 11, k + 31, sh, ms);
		world.setBlock(i + 6, j + 11, k + 32, sh, ms);
		world.setBlock(i + 6, j + 11, k + 33, sh, ms);
		world.setBlock(i + 6, j + 12, k + 10, sh, ms);
		world.setBlock(i + 6, j + 12, k + 11, sh, ms);
		world.setBlock(i + 6, j + 12, k + 13, sh, ms);
		world.setBlock(i + 6, j + 12, k + 29, sh, ms);
		world.setBlock(i + 6, j + 12, k + 31, sh, ms);
		world.setBlock(i + 6, j + 12, k + 32, sh, ms);
		world.setBlock(i + 7, j + 0, k + 10, sh, ms);
		world.setBlock(i + 7, j + 0, k + 11, sh, ms);
		world.setBlock(i + 7, j + 0, k + 12, sh, ms);
		world.setBlock(i + 7, j + 0, k + 13, sh, ms);
		world.setBlock(i + 7, j + 0, k + 15, sh, ms);
		world.setBlock(i + 7, j + 0, k + 16, sh, ms);
		world.setBlock(i + 7, j + 0, k + 17, sh, ms);
		world.setBlock(i + 7, j + 0, k + 18, sh, ms);
		world.setBlock(i + 7, j + 0, k + 19, sh, ms);
		world.setBlock(i + 7, j + 0, k + 20, sh, ms);
		world.setBlock(i + 7, j + 0, k + 21, sh, ms);
		world.setBlock(i + 7, j + 0, k + 22, sh, ms);
		world.setBlock(i + 7, j + 0, k + 23, sh, ms);
		world.setBlock(i + 7, j + 0, k + 24, sh, ms);
		world.setBlock(i + 7, j + 0, k + 25, sh, ms);
		world.setBlock(i + 7, j + 0, k + 26, sh, ms);
		world.setBlock(i + 7, j + 0, k + 27, sh, ms);
		world.setBlock(i + 7, j + 0, k + 29, sh, ms);
		world.setBlock(i + 7, j + 0, k + 30, sh, ms);
		world.setBlock(i + 7, j + 0, k + 31, sh, ms);
		world.setBlock(i + 7, j + 0, k + 32, sh, ms);
		world.setBlock(i + 7, j + 1, k + 10, sh, ms);
		world.setBlock(i + 7, j + 1, k + 11, sh, ms);
		world.setBlock(i + 7, j + 1, k + 31, sh, ms);
		world.setBlock(i + 7, j + 1, k + 32, sh, ms);
		world.setBlock(i + 7, j + 2, k + 10, sh, ms);
		world.setBlock(i + 7, j + 2, k + 32, sh, ms);
		world.setBlock(i + 7, j + 3, k + 4, sh, ms);
		world.setBlock(i + 7, j + 3, k + 38, sh, ms);
		world.setBlock(i + 7, j + 4, k + 4, sh, ms);
		world.setBlock(i + 7, j + 4, k + 38, sh, ms);
		world.setBlock(i + 7, j + 5, k + 3, sh, ms);
		world.setBlock(i + 7, j + 5, k + 4, sh, ms);
		world.setBlock(i + 7, j + 5, k + 38, sh, ms);
		world.setBlock(i + 7, j + 5, k + 39, sh, ms);
		world.setBlock(i + 7, j + 6, k + 3, sh, ms);
		world.setBlock(i + 7, j + 6, k + 4, sh, ms);
		world.setBlock(i + 7, j + 6, k + 38, sh, ms);
		world.setBlock(i + 7, j + 6, k + 39, sh, ms);
		world.setBlock(i + 7, j + 7, k + 3, sh, ms);
		world.setBlock(i + 7, j + 7, k + 4, sh, ms);
		world.setBlock(i + 7, j + 7, k + 38, sh, ms);
		world.setBlock(i + 7, j + 7, k + 39, sh, ms);
		world.setBlock(i + 7, j + 8, k + 4, sh, ms);
		world.setBlock(i + 7, j + 8, k + 38, sh, ms);
		world.setBlock(i + 7, j + 9, k + 4, sh, ms);
		world.setBlock(i + 7, j + 9, k + 38, sh, ms);
		world.setBlock(i + 7, j + 10, k + 10, sh, ms);
		world.setBlock(i + 7, j + 10, k + 32, sh, ms);
		world.setBlock(i + 7, j + 11, k + 10, sh, ms);
		world.setBlock(i + 7, j + 11, k + 11, sh, ms);
		world.setBlock(i + 7, j + 11, k + 12, sh, ms);
		world.setBlock(i + 7, j + 11, k + 30, sh, ms);
		world.setBlock(i + 7, j + 11, k + 31, sh, ms);
		world.setBlock(i + 7, j + 11, k + 32, sh, ms);
		world.setBlock(i + 7, j + 12, k + 11, sh, ms);
		world.setBlock(i + 7, j + 12, k + 12, sh, ms);
		world.setBlock(i + 7, j + 12, k + 13, sh, ms);
		world.setBlock(i + 7, j + 12, k + 14, sh, ms);
		world.setBlock(i + 7, j + 12, k + 28, sh, ms);
		world.setBlock(i + 7, j + 12, k + 29, sh, ms);
		world.setBlock(i + 7, j + 12, k + 30, sh, ms);
		world.setBlock(i + 7, j + 12, k + 31, sh, ms);
		world.setBlock(i + 8, j + 0, k + 11, sh, ms);
		world.setBlock(i + 8, j + 0, k + 12, sh, ms);
		world.setBlock(i + 8, j + 0, k + 14, sh, ms);
		world.setBlock(i + 8, j + 0, k + 15, sh, ms);
		world.setBlock(i + 8, j + 0, k + 27, sh, ms);
		world.setBlock(i + 8, j + 0, k + 28, sh, ms);
		world.setBlock(i + 8, j + 0, k + 30, sh, ms);
		world.setBlock(i + 8, j + 0, k + 31, sh, ms);
		world.setBlock(i + 8, j + 1, k + 4, sh, ms);
		world.setBlock(i + 8, j + 1, k + 11, sh, ms);
		world.setBlock(i + 8, j + 1, k + 31, sh, ms);
		world.setBlock(i + 8, j + 1, k + 38, sh, ms);
		world.setBlock(i + 8, j + 2, k + 3, sh, ms);
		world.setBlock(i + 8, j + 2, k + 4, sh, ms);
		world.setBlock(i + 8, j + 2, k + 5, sh, ms);
		world.setBlock(i + 8, j + 2, k + 37, sh, ms);
		world.setBlock(i + 8, j + 2, k + 38, sh, ms);
		world.setBlock(i + 8, j + 2, k + 39, sh, ms);
		world.setBlock(i + 8, j + 3, k + 3, sh, ms);
		world.setBlock(i + 8, j + 3, k + 4, sh, ms);
		world.setBlock(i + 8, j + 3, k + 5, sh, ms);
		world.setBlock(i + 8, j + 3, k + 37, sh, ms);
		world.setBlock(i + 8, j + 3, k + 38, sh, ms);
		world.setBlock(i + 8, j + 3, k + 39, sh, ms);
		world.setBlock(i + 8, j + 4, k + 2, sh, ms);
		world.setBlock(i + 8, j + 4, k + 3, sh, ms);
		world.setBlock(i + 8, j + 4, k + 4, sh, ms);
		world.setBlock(i + 8, j + 4, k + 5, sh, ms);
		world.setBlock(i + 8, j + 4, k + 37, sh, ms);
		world.setBlock(i + 8, j + 4, k + 38, sh, ms);
		world.setBlock(i + 8, j + 4, k + 39, sh, ms);
		world.setBlock(i + 8, j + 4, k + 40, sh, ms);
		world.setBlock(i + 8, j + 5, k + 3, sh, ms);
		world.setBlock(i + 8, j + 5, k + 4, sh, ms);
		world.setBlock(i + 8, j + 5, k + 5, sh, ms);
		world.setBlock(i + 8, j + 5, k + 37, sh, ms);
		world.setBlock(i + 8, j + 5, k + 38, sh, ms);
		world.setBlock(i + 8, j + 5, k + 39, sh, ms);
		world.setBlock(i + 8, j + 6, k + 3, sh, ms);
		world.setBlock(i + 8, j + 6, k + 5, sh, ms);
		world.setBlock(i + 8, j + 6, k + 37, sh, ms);
		world.setBlock(i + 8, j + 6, k + 39, sh, ms);
		world.setBlock(i + 8, j + 7, k + 3, sh, ms);
		world.setBlock(i + 8, j + 7, k + 4, sh, ms);
		world.setBlock(i + 8, j + 7, k + 5, sh, ms);
		world.setBlock(i + 8, j + 7, k + 37, sh, ms);
		world.setBlock(i + 8, j + 7, k + 38, sh, ms);
		world.setBlock(i + 8, j + 7, k + 39, sh, ms);
		world.setBlock(i + 8, j + 8, k + 2, sh, ms);
		world.setBlock(i + 8, j + 8, k + 3, sh, ms);
		world.setBlock(i + 8, j + 8, k + 4, sh, ms);
		world.setBlock(i + 8, j + 8, k + 5, sh, ms);
		world.setBlock(i + 8, j + 8, k + 37, sh, ms);
		world.setBlock(i + 8, j + 8, k + 38, sh, ms);
		world.setBlock(i + 8, j + 8, k + 39, sh, ms);
		world.setBlock(i + 8, j + 8, k + 40, sh, ms);
		world.setBlock(i + 8, j + 9, k + 3, sh, ms);
		world.setBlock(i + 8, j + 9, k + 4, sh, ms);
		world.setBlock(i + 8, j + 9, k + 5, sh, ms);
		world.setBlock(i + 8, j + 9, k + 37, sh, ms);
		world.setBlock(i + 8, j + 9, k + 38, sh, ms);
		world.setBlock(i + 8, j + 9, k + 39, sh, ms);
		world.setBlock(i + 8, j + 10, k + 3, sh, ms);
		world.setBlock(i + 8, j + 10, k + 4, sh, ms);
		world.setBlock(i + 8, j + 10, k + 5, sh, ms);
		world.setBlock(i + 8, j + 10, k + 37, sh, ms);
		world.setBlock(i + 8, j + 10, k + 38, sh, ms);
		world.setBlock(i + 8, j + 10, k + 39, sh, ms);
		world.setBlock(i + 8, j + 11, k + 4, sh, ms);
		world.setBlock(i + 8, j + 11, k + 11, sh, ms);
		world.setBlock(i + 8, j + 11, k + 12, sh, ms);
		world.setBlock(i + 8, j + 11, k + 30, sh, ms);
		world.setBlock(i + 8, j + 11, k + 31, sh, ms);
		world.setBlock(i + 8, j + 11, k + 38, sh, ms);
		world.setBlock(i + 8, j + 12, k + 13, sh, ms);
		world.setBlock(i + 8, j + 12, k + 14, sh, ms);
		world.setBlock(i + 8, j + 12, k + 28, sh, ms);
		world.setBlock(i + 8, j + 12, k + 29, sh, ms);
		world.setBlock(i + 9, j + 0, k + 4, sh, ms);
		world.setBlock(i + 9, j + 0, k + 5, sh, ms);
		world.setBlock(i + 9, j + 0, k + 12, sh, ms);
		world.setBlock(i + 9, j + 0, k + 13, sh, ms);
		world.setBlock(i + 9, j + 0, k + 14, sh, ms);
		world.setBlock(i + 9, j + 0, k + 16, sh, ms);
		world.setBlock(i + 9, j + 0, k + 17, sh, ms);
		world.setBlock(i + 9, j + 0, k + 18, sh, ms);
		world.setBlock(i + 9, j + 0, k + 19, sh, ms);
		world.setBlock(i + 9, j + 0, k + 20, sh, ms);
		world.setBlock(i + 9, j + 0, k + 21, sh, ms);
		world.setBlock(i + 9, j + 0, k + 22, sh, ms);
		world.setBlock(i + 9, j + 0, k + 23, sh, ms);
		world.setBlock(i + 9, j + 0, k + 24, sh, ms);
		world.setBlock(i + 9, j + 0, k + 25, sh, ms);
		world.setBlock(i + 9, j + 0, k + 26, sh, ms);
		world.setBlock(i + 9, j + 0, k + 28, sh, ms);
		world.setBlock(i + 9, j + 0, k + 29, sh, ms);
		world.setBlock(i + 9, j + 0, k + 30, sh, ms);
		world.setBlock(i + 9, j + 0, k + 37, sh, ms);
		world.setBlock(i + 9, j + 0, k + 38, sh, ms);
		world.setBlock(i + 9, j + 1, k + 3, sh, ms);
		world.setBlock(i + 9, j + 1, k + 4, sh, ms);
		world.setBlock(i + 9, j + 1, k + 5, sh, ms);
		world.setBlock(i + 9, j + 1, k + 6, sh, ms);
		world.setBlock(i + 9, j + 1, k + 36, sh, ms);
		world.setBlock(i + 9, j + 1, k + 37, sh, ms);
		world.setBlock(i + 9, j + 1, k + 38, sh, ms);
		world.setBlock(i + 9, j + 1, k + 39, sh, ms);
		world.setBlock(i + 9, j + 2, k + 2, sh, ms);
		world.setBlock(i + 9, j + 2, k + 3, sh, ms);
		world.setBlock(i + 9, j + 2, k + 4, sh, ms);
		world.setBlock(i + 9, j + 2, k + 5, sh, ms);
		world.setBlock(i + 9, j + 2, k + 6, sh, ms);
		world.setBlock(i + 9, j + 2, k + 36, sh, ms);
		world.setBlock(i + 9, j + 2, k + 37, sh, ms);
		world.setBlock(i + 9, j + 2, k + 38, sh, ms);
		world.setBlock(i + 9, j + 2, k + 39, sh, ms);
		world.setBlock(i + 9, j + 2, k + 40, sh, ms);
		world.setBlock(i + 9, j + 3, k + 2, sh, ms);
		world.setBlock(i + 9, j + 3, k + 3, sh, ms);
		world.setBlock(i + 9, j + 3, k + 4, sh, ms);
		world.setBlock(i + 9, j + 3, k + 5, sh, ms);
		world.setBlock(i + 9, j + 3, k + 6, sh, ms);
		world.setBlock(i + 9, j + 3, k + 36, sh, ms);
		world.setBlock(i + 9, j + 3, k + 37, sh, ms);
		world.setBlock(i + 9, j + 3, k + 38, sh, ms);
		world.setBlock(i + 9, j + 3, k + 39, sh, ms);
		world.setBlock(i + 9, j + 3, k + 40, sh, ms);
		world.setBlock(i + 9, j + 4, k + 2, sh, ms);
		world.setBlock(i + 9, j + 4, k + 3, sh, ms);
		world.setBlock(i + 9, j + 4, k + 4, sh, ms);
		world.setBlock(i + 9, j + 4, k + 5, sh, ms);
		world.setBlock(i + 9, j + 4, k + 6, sh, ms);
		world.setBlock(i + 9, j + 4, k + 36, sh, ms);
		world.setBlock(i + 9, j + 4, k + 37, sh, ms);
		world.setBlock(i + 9, j + 4, k + 38, sh, ms);
		world.setBlock(i + 9, j + 4, k + 39, sh, ms);
		world.setBlock(i + 9, j + 4, k + 40, sh, ms);
		world.setBlock(i + 9, j + 5, k + 1, sh, ms);
		world.setBlock(i + 9, j + 5, k + 2, sh, ms);
		world.setBlock(i + 9, j + 5, k + 3, sh, ms);
		world.setBlock(i + 9, j + 5, k + 39, sh, ms);
		world.setBlock(i + 9, j + 5, k + 40, sh, ms);
		world.setBlock(i + 9, j + 5, k + 41, sh, ms);
		world.setBlock(i + 9, j + 6, k + 1, sh, ms);
		world.setBlock(i + 9, j + 6, k + 2, sh, ms);
		world.setBlock(i + 9, j + 6, k + 40, sh, ms);
		world.setBlock(i + 9, j + 6, k + 41, sh, ms);
		world.setBlock(i + 9, j + 7, k + 1, sh, ms);
		world.setBlock(i + 9, j + 7, k + 2, sh, ms);
		world.setBlock(i + 9, j + 7, k + 3, sh, ms);
		world.setBlock(i + 9, j + 7, k + 39, sh, ms);
		world.setBlock(i + 9, j + 7, k + 40, sh, ms);
		world.setBlock(i + 9, j + 7, k + 41, sh, ms);
		world.setBlock(i + 9, j + 8, k + 2, sh, ms);
		world.setBlock(i + 9, j + 8, k + 3, sh, ms);
		world.setBlock(i + 9, j + 8, k + 4, sh, ms);
		world.setBlock(i + 9, j + 8, k + 5, sh, ms);
		world.setBlock(i + 9, j + 8, k + 6, sh, ms);
		world.setBlock(i + 9, j + 8, k + 36, sh, ms);
		world.setBlock(i + 9, j + 8, k + 37, sh, ms);
		world.setBlock(i + 9, j + 8, k + 38, sh, ms);
		world.setBlock(i + 9, j + 8, k + 39, sh, ms);
		world.setBlock(i + 9, j + 8, k + 40, sh, ms);
		world.setBlock(i + 9, j + 9, k + 2, sh, ms);
		world.setBlock(i + 9, j + 9, k + 3, sh, ms);
		world.setBlock(i + 9, j + 9, k + 4, sh, ms);
		world.setBlock(i + 9, j + 9, k + 5, sh, ms);
		world.setBlock(i + 9, j + 9, k + 6, sh, ms);
		world.setBlock(i + 9, j + 9, k + 36, sh, ms);
		world.setBlock(i + 9, j + 9, k + 37, sh, ms);
		world.setBlock(i + 9, j + 9, k + 38, sh, ms);
		world.setBlock(i + 9, j + 9, k + 39, sh, ms);
		world.setBlock(i + 9, j + 9, k + 40, sh, ms);
		world.setBlock(i + 9, j + 10, k + 2, sh, ms);
		world.setBlock(i + 9, j + 10, k + 3, sh, ms);
		world.setBlock(i + 9, j + 10, k + 4, sh, ms);
		world.setBlock(i + 9, j + 10, k + 5, sh, ms);
		world.setBlock(i + 9, j + 10, k + 6, sh, ms);
		world.setBlock(i + 9, j + 10, k + 36, sh, ms);
		world.setBlock(i + 9, j + 10, k + 37, sh, ms);
		world.setBlock(i + 9, j + 10, k + 38, sh, ms);
		world.setBlock(i + 9, j + 10, k + 39, sh, ms);
		world.setBlock(i + 9, j + 10, k + 40, sh, ms);
		world.setBlock(i + 9, j + 11, k + 3, sh, ms);
		world.setBlock(i + 9, j + 11, k + 4, sh, ms);
		world.setBlock(i + 9, j + 11, k + 5, sh, ms);
		world.setBlock(i + 9, j + 11, k + 6, sh, ms);
		world.setBlock(i + 9, j + 11, k + 36, sh, ms);
		world.setBlock(i + 9, j + 11, k + 37, sh, ms);
		world.setBlock(i + 9, j + 11, k + 38, sh, ms);
		world.setBlock(i + 9, j + 11, k + 39, sh, ms);
		world.setBlock(i + 9, j + 12, k + 4, sh, ms);
		world.setBlock(i + 9, j + 12, k + 5, sh, ms);
		world.setBlock(i + 9, j + 12, k + 37, sh, ms);
		world.setBlock(i + 9, j + 12, k + 38, sh, ms);
		world.setBlock(i + 10, j + 0, k + 3, sh, ms);
		world.setBlock(i + 10, j + 0, k + 4, sh, ms);
		world.setBlock(i + 10, j + 0, k + 5, sh, ms);
		world.setBlock(i + 10, j + 0, k + 6, sh, ms);
		world.setBlock(i + 10, j + 0, k + 7, sh, ms);
		world.setBlock(i + 10, j + 0, k + 11, sh, ms);
		world.setBlock(i + 10, j + 0, k + 12, sh, ms);
		world.setBlock(i + 10, j + 0, k + 13, sh, ms);
		world.setBlock(i + 10, j + 0, k + 15, sh, ms);
		world.setBlock(i + 10, j + 0, k + 16, sh, ms);
		world.setBlock(i + 10, j + 0, k + 17, sh, ms);
		world.setBlock(i + 10, j + 0, k + 18, sh, ms);
		world.setBlock(i + 10, j + 0, k + 19, sh, ms);
		world.setBlock(i + 10, j + 0, k + 20, sh, ms);
		world.setBlock(i + 10, j + 0, k + 21, sh, ms);
		world.setBlock(i + 10, j + 0, k + 22, sh, ms);
		world.setBlock(i + 10, j + 0, k + 23, sh, ms);
		world.setBlock(i + 10, j + 0, k + 24, sh, ms);
		world.setBlock(i + 10, j + 0, k + 25, sh, ms);
		world.setBlock(i + 10, j + 0, k + 26, sh, ms);
		world.setBlock(i + 10, j + 0, k + 27, sh, ms);
		world.setBlock(i + 10, j + 0, k + 29, sh, ms);
		world.setBlock(i + 10, j + 0, k + 30, sh, ms);
		world.setBlock(i + 10, j + 0, k + 31, sh, ms);
		world.setBlock(i + 10, j + 0, k + 35, sh, ms);
		world.setBlock(i + 10, j + 0, k + 36, sh, ms);
		world.setBlock(i + 10, j + 0, k + 37, sh, ms);
		world.setBlock(i + 10, j + 0, k + 38, sh, ms);
		world.setBlock(i + 10, j + 0, k + 39, sh, ms);
		world.setBlock(i + 10, j + 1, k + 2, sh, ms);
		world.setBlock(i + 10, j + 1, k + 3, sh, ms);
		world.setBlock(i + 10, j + 1, k + 4, sh, ms);
		world.setBlock(i + 10, j + 1, k + 5, sh, ms);
		world.setBlock(i + 10, j + 1, k + 6, sh, ms);
		world.setBlock(i + 10, j + 1, k + 7, sh, ms);
		world.setBlock(i + 10, j + 1, k + 35, sh, ms);
		world.setBlock(i + 10, j + 1, k + 36, sh, ms);
		world.setBlock(i + 10, j + 1, k + 37, sh, ms);
		world.setBlock(i + 10, j + 1, k + 38, sh, ms);
		world.setBlock(i + 10, j + 1, k + 39, sh, ms);
		world.setBlock(i + 10, j + 1, k + 40, sh, ms);
		world.setBlock(i + 10, j + 2, k + 2, sh, ms);
		world.setBlock(i + 10, j + 2, k + 3, sh, ms);
		world.setBlock(i + 10, j + 2, k + 4, sh, ms);
		world.setBlock(i + 10, j + 2, k + 5, sh, ms);
		world.setBlock(i + 10, j + 2, k + 6, sh, ms);
		world.setBlock(i + 10, j + 2, k + 7, sh, ms);
		world.setBlock(i + 10, j + 2, k + 35, sh, ms);
		world.setBlock(i + 10, j + 2, k + 36, sh, ms);
		world.setBlock(i + 10, j + 2, k + 37, sh, ms);
		world.setBlock(i + 10, j + 2, k + 38, sh, ms);
		world.setBlock(i + 10, j + 2, k + 39, sh, ms);
		world.setBlock(i + 10, j + 2, k + 40, sh, ms);
		world.setBlock(i + 10, j + 3, k + 1, sh, ms);
		world.setBlock(i + 10, j + 3, k + 2, sh, ms);
		world.setBlock(i + 10, j + 3, k + 3, sh, ms);
		world.setBlock(i + 10, j + 3, k + 4, sh, ms);
		world.setBlock(i + 10, j + 3, k + 5, sh, ms);
		world.setBlock(i + 10, j + 3, k + 37, sh, ms);
		world.setBlock(i + 10, j + 3, k + 38, sh, ms);
		world.setBlock(i + 10, j + 3, k + 39, sh, ms);
		world.setBlock(i + 10, j + 3, k + 40, sh, ms);
		world.setBlock(i + 10, j + 3, k + 41, sh, ms);
		world.setBlock(i + 10, j + 4, k + 1, sh, ms);
		world.setBlock(i + 10, j + 4, k + 2, sh, ms);
		world.setBlock(i + 10, j + 4, k + 3, sh, ms);
		world.setBlock(i + 10, j + 4, k + 39, sh, ms);
		world.setBlock(i + 10, j + 4, k + 40, sh, ms);
		world.setBlock(i + 10, j + 4, k + 41, sh, ms);
		world.setBlock(i + 10, j + 5, k + 1, sh, ms);
		world.setBlock(i + 10, j + 5, k + 2, sh, ms);
		world.setBlock(i + 10, j + 5, k + 40, sh, ms);
		world.setBlock(i + 10, j + 5, k + 41, sh, ms);
		world.setBlock(i + 10, j + 6, k + 1, sh, ms);
		world.setBlock(i + 10, j + 6, k + 41, sh, ms);
		world.setBlock(i + 10, j + 7, k + 1, sh, ms);
		world.setBlock(i + 10, j + 7, k + 2, sh, ms);
		world.setBlock(i + 10, j + 7, k + 40, sh, ms);
		world.setBlock(i + 10, j + 7, k + 41, sh, ms);
		world.setBlock(i + 10, j + 8, k + 1, sh, ms);
		world.setBlock(i + 10, j + 8, k + 2, sh, ms);
		world.setBlock(i + 10, j + 8, k + 3, sh, ms);
		world.setBlock(i + 10, j + 8, k + 39, sh, ms);
		world.setBlock(i + 10, j + 8, k + 40, sh, ms);
		world.setBlock(i + 10, j + 8, k + 41, sh, ms);
		world.setBlock(i + 10, j + 9, k + 1, sh, ms);
		world.setBlock(i + 10, j + 9, k + 2, sh, ms);
		world.setBlock(i + 10, j + 9, k + 3, sh, ms);
		world.setBlock(i + 10, j + 9, k + 4, sh, ms);
		world.setBlock(i + 10, j + 9, k + 5, sh, ms);
		world.setBlock(i + 10, j + 9, k + 37, sh, ms);
		world.setBlock(i + 10, j + 9, k + 38, sh, ms);
		world.setBlock(i + 10, j + 9, k + 39, sh, ms);
		world.setBlock(i + 10, j + 9, k + 40, sh, ms);
		world.setBlock(i + 10, j + 9, k + 41, sh, ms);
		world.setBlock(i + 10, j + 10, k + 2, sh, ms);
		world.setBlock(i + 10, j + 10, k + 3, sh, ms);
		world.setBlock(i + 10, j + 10, k + 4, sh, ms);
		world.setBlock(i + 10, j + 10, k + 5, sh, ms);
		world.setBlock(i + 10, j + 10, k + 6, sh, ms);
		world.setBlock(i + 10, j + 10, k + 7, sh, ms);
		world.setBlock(i + 10, j + 10, k + 35, sh, ms);
		world.setBlock(i + 10, j + 10, k + 36, sh, ms);
		world.setBlock(i + 10, j + 10, k + 37, sh, ms);
		world.setBlock(i + 10, j + 10, k + 38, sh, ms);
		world.setBlock(i + 10, j + 10, k + 39, sh, ms);
		world.setBlock(i + 10, j + 10, k + 40, sh, ms);
		world.setBlock(i + 10, j + 11, k + 2, sh, ms);
		world.setBlock(i + 10, j + 11, k + 3, sh, ms);
		world.setBlock(i + 10, j + 11, k + 4, sh, ms);
		world.setBlock(i + 10, j + 11, k + 5, sh, ms);
		world.setBlock(i + 10, j + 11, k + 6, sh, ms);
		world.setBlock(i + 10, j + 11, k + 7, sh, ms);
		world.setBlock(i + 10, j + 11, k + 35, sh, ms);
		world.setBlock(i + 10, j + 11, k + 36, sh, ms);
		world.setBlock(i + 10, j + 11, k + 37, sh, ms);
		world.setBlock(i + 10, j + 11, k + 38, sh, ms);
		world.setBlock(i + 10, j + 11, k + 39, sh, ms);
		world.setBlock(i + 10, j + 11, k + 40, sh, ms);
		world.setBlock(i + 10, j + 12, k + 3, sh, ms);
		world.setBlock(i + 10, j + 12, k + 4, sh, ms);
		world.setBlock(i + 10, j + 12, k + 5, sh, ms);
		world.setBlock(i + 10, j + 12, k + 6, sh, ms);
		world.setBlock(i + 10, j + 12, k + 36, sh, ms);
		world.setBlock(i + 10, j + 12, k + 37, sh, ms);
		world.setBlock(i + 10, j + 12, k + 38, sh, ms);
		world.setBlock(i + 10, j + 12, k + 39, sh, ms);
		world.setBlock(i + 11, j + 0, k + 3, sh, ms);
		world.setBlock(i + 11, j + 0, k + 4, sh, ms);
		world.setBlock(i + 11, j + 0, k + 5, sh, ms);
		world.setBlock(i + 11, j + 0, k + 6, sh, ms);
		world.setBlock(i + 11, j + 0, k + 7, sh, ms);
		world.setBlock(i + 11, j + 0, k + 8, sh, ms);
		world.setBlock(i + 11, j + 0, k + 10, sh, ms);
		world.setBlock(i + 11, j + 0, k + 11, sh, ms);
		world.setBlock(i + 11, j + 0, k + 12, sh, ms);
		world.setBlock(i + 11, j + 0, k + 14, sh, ms);
		world.setBlock(i + 11, j + 0, k + 15, sh, ms);
		world.setBlock(i + 11, j + 0, k + 16, sh, ms);
		world.setBlock(i + 11, j + 0, k + 17, sh, ms);
		world.setBlock(i + 11, j + 0, k + 18, sh, ms);
		world.setBlock(i + 11, j + 0, k + 19, sh, ms);
		world.setBlock(i + 11, j + 0, k + 20, sh, ms);
		world.setBlock(i + 11, j + 0, k + 21, sh, ms);
		world.setBlock(i + 11, j + 0, k + 22, sh, ms);
		world.setBlock(i + 11, j + 0, k + 23, sh, ms);
		world.setBlock(i + 11, j + 0, k + 24, sh, ms);
		world.setBlock(i + 11, j + 0, k + 25, sh, ms);
		world.setBlock(i + 11, j + 0, k + 26, sh, ms);
		world.setBlock(i + 11, j + 0, k + 27, sh, ms);
		world.setBlock(i + 11, j + 0, k + 28, sh, ms);
		world.setBlock(i + 11, j + 0, k + 30, sh, ms);
		world.setBlock(i + 11, j + 0, k + 31, sh, ms);
		world.setBlock(i + 11, j + 0, k + 32, sh, ms);
		world.setBlock(i + 11, j + 0, k + 34, sh, ms);
		world.setBlock(i + 11, j + 0, k + 35, sh, ms);
		world.setBlock(i + 11, j + 0, k + 36, sh, ms);
		world.setBlock(i + 11, j + 0, k + 37, sh, ms);
		world.setBlock(i + 11, j + 0, k + 38, sh, ms);
		world.setBlock(i + 11, j + 0, k + 39, sh, ms);
		world.setBlock(i + 11, j + 1, k + 3, sh, ms);
		world.setBlock(i + 11, j + 1, k + 4, sh, ms);
		world.setBlock(i + 11, j + 1, k + 5, sh, ms);
		world.setBlock(i + 11, j + 1, k + 6, sh, ms);
		world.setBlock(i + 11, j + 1, k + 7, sh, ms);
		world.setBlock(i + 11, j + 1, k + 8, sh, ms);
		world.setBlock(i + 11, j + 1, k + 34, sh, ms);
		world.setBlock(i + 11, j + 1, k + 35, sh, ms);
		world.setBlock(i + 11, j + 1, k + 36, sh, ms);
		world.setBlock(i + 11, j + 1, k + 37, sh, ms);
		world.setBlock(i + 11, j + 1, k + 38, sh, ms);
		world.setBlock(i + 11, j + 1, k + 39, sh, ms);
		world.setBlock(i + 11, j + 2, k + 2, sh, ms);
		world.setBlock(i + 11, j + 2, k + 3, sh, ms);
		world.setBlock(i + 11, j + 2, k + 4, sh, ms);
		world.setBlock(i + 11, j + 2, k + 5, sh, ms);
		world.setBlock(i + 11, j + 2, k + 37, sh, ms);
		world.setBlock(i + 11, j + 2, k + 38, sh, ms);
		world.setBlock(i + 11, j + 2, k + 39, sh, ms);
		world.setBlock(i + 11, j + 2, k + 40, sh, ms);
		world.setBlock(i + 11, j + 3, k + 2, sh, ms);
		world.setBlock(i + 11, j + 3, k + 3, sh, ms);
		world.setBlock(i + 11, j + 3, k + 4, sh, ms);
		world.setBlock(i + 11, j + 3, k + 38, sh, ms);
		world.setBlock(i + 11, j + 3, k + 39, sh, ms);
		world.setBlock(i + 11, j + 3, k + 40, sh, ms);
		world.setBlock(i + 11, j + 4, k + 2, sh, ms);
		world.setBlock(i + 11, j + 4, k + 3, sh, ms);
		world.setBlock(i + 11, j + 4, k + 39, sh, ms);
		world.setBlock(i + 11, j + 4, k + 40, sh, ms);
		world.setBlock(i + 11, j + 5, k + 2, sh, ms);
		world.setBlock(i + 11, j + 5, k + 40, sh, ms);
		world.setBlock(i + 11, j + 6, k + 2, sh, ms);
		world.setBlock(i + 11, j + 6, k + 40, sh, ms);
		world.setBlock(i + 11, j + 7, k + 2, sh, ms);
		world.setBlock(i + 11, j + 7, k + 40, sh, ms);
		world.setBlock(i + 11, j + 8, k + 2, sh, ms);
		world.setBlock(i + 11, j + 8, k + 3, sh, ms);
		world.setBlock(i + 11, j + 8, k + 39, sh, ms);
		world.setBlock(i + 11, j + 8, k + 40, sh, ms);
		world.setBlock(i + 11, j + 9, k + 2, sh, ms);
		world.setBlock(i + 11, j + 9, k + 3, sh, ms);
		world.setBlock(i + 11, j + 9, k + 4, sh, ms);
		world.setBlock(i + 11, j + 9, k + 38, sh, ms);
		world.setBlock(i + 11, j + 9, k + 39, sh, ms);
		world.setBlock(i + 11, j + 9, k + 40, sh, ms);
		world.setBlock(i + 11, j + 10, k + 2, sh, ms);
		world.setBlock(i + 11, j + 10, k + 3, sh, ms);
		world.setBlock(i + 11, j + 10, k + 4, sh, ms);
		world.setBlock(i + 11, j + 10, k + 5, sh, ms);
		world.setBlock(i + 11, j + 10, k + 6, sh, ms);
		world.setBlock(i + 11, j + 10, k + 36, sh, ms);
		world.setBlock(i + 11, j + 10, k + 37, sh, ms);
		world.setBlock(i + 11, j + 10, k + 38, sh, ms);
		world.setBlock(i + 11, j + 10, k + 39, sh, ms);
		world.setBlock(i + 11, j + 10, k + 40, sh, ms);
		world.setBlock(i + 11, j + 11, k + 3, sh, ms);
		world.setBlock(i + 11, j + 11, k + 4, sh, ms);
		world.setBlock(i + 11, j + 11, k + 5, sh, ms);
		world.setBlock(i + 11, j + 11, k + 6, sh, ms);
		world.setBlock(i + 11, j + 11, k + 7, sh, ms);
		world.setBlock(i + 11, j + 11, k + 8, sh, ms);
		world.setBlock(i + 11, j + 11, k + 34, sh, ms);
		world.setBlock(i + 11, j + 11, k + 35, sh, ms);
		world.setBlock(i + 11, j + 11, k + 36, sh, ms);
		world.setBlock(i + 11, j + 11, k + 37, sh, ms);
		world.setBlock(i + 11, j + 11, k + 38, sh, ms);
		world.setBlock(i + 11, j + 11, k + 39, sh, ms);
		world.setBlock(i + 11, j + 12, k + 3, sh, ms);
		world.setBlock(i + 11, j + 12, k + 4, sh, ms);
		world.setBlock(i + 11, j + 12, k + 6, sh, ms);
		world.setBlock(i + 11, j + 12, k + 7, sh, ms);
		world.setBlock(i + 11, j + 12, k + 35, sh, ms);
		world.setBlock(i + 11, j + 12, k + 36, sh, ms);
		world.setBlock(i + 11, j + 12, k + 38, sh, ms);
		world.setBlock(i + 11, j + 12, k + 39, sh, ms);
		world.setBlock(i + 12, j + 0, k + 4, sh, ms);
		world.setBlock(i + 12, j + 0, k + 5, sh, ms);
		world.setBlock(i + 12, j + 0, k + 6, sh, ms);
		world.setBlock(i + 12, j + 0, k + 7, sh, ms);
		world.setBlock(i + 12, j + 0, k + 8, sh, ms);
		world.setBlock(i + 12, j + 0, k + 9, sh, ms);
		world.setBlock(i + 12, j + 0, k + 10, sh, ms);
		world.setBlock(i + 12, j + 0, k + 11, sh, ms);
		world.setBlock(i + 12, j + 0, k + 13, sh, ms);
		world.setBlock(i + 12, j + 0, k + 14, sh, ms);
		world.setBlock(i + 12, j + 0, k + 15, sh, ms);
		world.setBlock(i + 12, j + 0, k + 16, sh, ms);
		world.setBlock(i + 12, j + 0, k + 26, sh, ms);
		world.setBlock(i + 12, j + 0, k + 27, sh, ms);
		world.setBlock(i + 12, j + 0, k + 28, sh, ms);
		world.setBlock(i + 12, j + 0, k + 29, sh, ms);
		world.setBlock(i + 12, j + 0, k + 31, sh, ms);
		world.setBlock(i + 12, j + 0, k + 32, sh, ms);
		world.setBlock(i + 12, j + 0, k + 33, sh, ms);
		world.setBlock(i + 12, j + 0, k + 34, sh, ms);
		world.setBlock(i + 12, j + 0, k + 35, sh, ms);
		world.setBlock(i + 12, j + 0, k + 36, sh, ms);
		world.setBlock(i + 12, j + 0, k + 37, sh, ms);
		world.setBlock(i + 12, j + 0, k + 38, sh, ms);
		world.setBlock(i + 12, j + 1, k + 3, sh, ms);
		world.setBlock(i + 12, j + 1, k + 4, sh, ms);
		world.setBlock(i + 12, j + 1, k + 5, sh, ms);
		world.setBlock(i + 12, j + 1, k + 6, sh, ms);
		world.setBlock(i + 12, j + 1, k + 36, sh, ms);
		world.setBlock(i + 12, j + 1, k + 37, sh, ms);
		world.setBlock(i + 12, j + 1, k + 38, sh, ms);
		world.setBlock(i + 12, j + 1, k + 39, sh, ms);
		world.setBlock(i + 12, j + 2, k + 3, sh, ms);
		world.setBlock(i + 12, j + 2, k + 4, sh, ms);
		world.setBlock(i + 12, j + 2, k + 38, sh, ms);
		world.setBlock(i + 12, j + 2, k + 39, sh, ms);
		world.setBlock(i + 12, j + 3, k + 3, sh, ms);
		world.setBlock(i + 12, j + 3, k + 39, sh, ms);
		world.setBlock(i + 12, j + 4, k + 3, sh, ms);
		world.setBlock(i + 12, j + 4, k + 39, sh, ms);
		world.setBlock(i + 12, j + 8, k + 3, sh, ms);
		world.setBlock(i + 12, j + 8, k + 39, sh, ms);
		world.setBlock(i + 12, j + 9, k + 3, sh, ms);
		world.setBlock(i + 12, j + 9, k + 39, sh, ms);
		world.setBlock(i + 12, j + 10, k + 3, sh, ms);
		world.setBlock(i + 12, j + 10, k + 4, sh, ms);
		world.setBlock(i + 12, j + 10, k + 5, sh, ms);
		world.setBlock(i + 12, j + 10, k + 37, sh, ms);
		world.setBlock(i + 12, j + 10, k + 38, sh, ms);
		world.setBlock(i + 12, j + 10, k + 39, sh, ms);
		world.setBlock(i + 12, j + 11, k + 3, sh, ms);
		world.setBlock(i + 12, j + 11, k + 4, sh, ms);
		world.setBlock(i + 12, j + 11, k + 5, sh, ms);
		world.setBlock(i + 12, j + 11, k + 6, sh, ms);
		world.setBlock(i + 12, j + 11, k + 7, sh, ms);
		world.setBlock(i + 12, j + 11, k + 8, sh, ms);
		world.setBlock(i + 12, j + 11, k + 34, sh, ms);
		world.setBlock(i + 12, j + 11, k + 35, sh, ms);
		world.setBlock(i + 12, j + 11, k + 36, sh, ms);
		world.setBlock(i + 12, j + 11, k + 37, sh, ms);
		world.setBlock(i + 12, j + 11, k + 38, sh, ms);
		world.setBlock(i + 12, j + 11, k + 39, sh, ms);
		world.setBlock(i + 12, j + 12, k + 4, sh, ms);
		world.setBlock(i + 12, j + 12, k + 5, sh, ms);
		world.setBlock(i + 12, j + 12, k + 7, sh, ms);
		world.setBlock(i + 12, j + 12, k + 35, sh, ms);
		world.setBlock(i + 12, j + 12, k + 37, sh, ms);
		world.setBlock(i + 12, j + 12, k + 38, sh, ms);
		world.setBlock(i + 13, j + 0, k + 4, sh, ms);
		world.setBlock(i + 13, j + 0, k + 5, sh, ms);
		world.setBlock(i + 13, j + 0, k + 6, sh, ms);
		world.setBlock(i + 13, j + 0, k + 7, sh, ms);
		world.setBlock(i + 13, j + 0, k + 9, sh, ms);
		world.setBlock(i + 13, j + 0, k + 10, sh, ms);
		world.setBlock(i + 13, j + 0, k + 12, sh, ms);
		world.setBlock(i + 13, j + 0, k + 13, sh, ms);
		world.setBlock(i + 13, j + 0, k + 14, sh, ms);
		world.setBlock(i + 13, j + 0, k + 15, sh, ms);
		world.setBlock(i + 13, j + 0, k + 17, sh, ms);
		world.setBlock(i + 13, j + 0, k + 18, sh, ms);
		world.setBlock(i + 13, j + 0, k + 19, sh, ms);
		world.setBlock(i + 13, j + 0, k + 20, sh, ms);
		world.setBlock(i + 13, j + 0, k + 21, sh, ms);
		world.setBlock(i + 13, j + 0, k + 22, sh, ms);
		world.setBlock(i + 13, j + 0, k + 23, sh, ms);
		world.setBlock(i + 13, j + 0, k + 24, sh, ms);
		world.setBlock(i + 13, j + 0, k + 25, sh, ms);
		world.setBlock(i + 13, j + 0, k + 27, sh, ms);
		world.setBlock(i + 13, j + 0, k + 28, sh, ms);
		world.setBlock(i + 13, j + 0, k + 29, sh, ms);
		world.setBlock(i + 13, j + 0, k + 30, sh, ms);
		world.setBlock(i + 13, j + 0, k + 32, sh, ms);
		world.setBlock(i + 13, j + 0, k + 33, sh, ms);
		world.setBlock(i + 13, j + 0, k + 35, sh, ms);
		world.setBlock(i + 13, j + 0, k + 36, sh, ms);
		world.setBlock(i + 13, j + 0, k + 37, sh, ms);
		world.setBlock(i + 13, j + 0, k + 38, sh, ms);
		world.setBlock(i + 13, j + 1, k + 4, sh, ms);
		world.setBlock(i + 13, j + 1, k + 5, sh, ms);
		world.setBlock(i + 13, j + 1, k + 37, sh, ms);
		world.setBlock(i + 13, j + 1, k + 38, sh, ms);
		world.setBlock(i + 13, j + 2, k + 4, sh, ms);
		world.setBlock(i + 13, j + 2, k + 38, sh, ms);
		world.setBlock(i + 13, j + 10, k + 4, sh, ms);
		world.setBlock(i + 13, j + 10, k + 38, sh, ms);
		world.setBlock(i + 13, j + 11, k + 4, sh, ms);
		world.setBlock(i + 13, j + 11, k + 5, sh, ms);
		world.setBlock(i + 13, j + 11, k + 6, sh, ms);
		world.setBlock(i + 13, j + 11, k + 36, sh, ms);
		world.setBlock(i + 13, j + 11, k + 37, sh, ms);
		world.setBlock(i + 13, j + 11, k + 38, sh, ms);
		world.setBlock(i + 13, j + 12, k + 5, sh, ms);
		world.setBlock(i + 13, j + 12, k + 6, sh, ms);
		world.setBlock(i + 13, j + 12, k + 7, sh, ms);
		world.setBlock(i + 13, j + 12, k + 8, sh, ms);
		world.setBlock(i + 13, j + 12, k + 34, sh, ms);
		world.setBlock(i + 13, j + 12, k + 35, sh, ms);
		world.setBlock(i + 13, j + 12, k + 36, sh, ms);
		world.setBlock(i + 13, j + 12, k + 37, sh, ms);
		world.setBlock(i + 14, j + 0, k + 5, sh, ms);
		world.setBlock(i + 14, j + 0, k + 6, sh, ms);
		world.setBlock(i + 14, j + 0, k + 8, sh, ms);
		world.setBlock(i + 14, j + 0, k + 9, sh, ms);
		world.setBlock(i + 14, j + 0, k + 11, sh, ms);
		world.setBlock(i + 14, j + 0, k + 12, sh, ms);
		world.setBlock(i + 14, j + 0, k + 13, sh, ms);
		world.setBlock(i + 14, j + 0, k + 14, sh, ms);
		world.setBlock(i + 14, j + 0, k + 16, sh, ms);
		world.setBlock(i + 14, j + 0, k + 17, sh, ms);
		world.setBlock(i + 14, j + 0, k + 18, sh, ms);
		world.setBlock(i + 14, j + 0, k + 19, sh, ms);
		world.setBlock(i + 14, j + 0, k + 20, sh, ms);
		world.setBlock(i + 14, j + 0, k + 21, sh, ms);
		world.setBlock(i + 14, j + 0, k + 22, sh, ms);
		world.setBlock(i + 14, j + 0, k + 23, sh, ms);
		world.setBlock(i + 14, j + 0, k + 24, sh, ms);
		world.setBlock(i + 14, j + 0, k + 25, sh, ms);
		world.setBlock(i + 14, j + 0, k + 26, sh, ms);
		world.setBlock(i + 14, j + 0, k + 28, sh, ms);
		world.setBlock(i + 14, j + 0, k + 29, sh, ms);
		world.setBlock(i + 14, j + 0, k + 30, sh, ms);
		world.setBlock(i + 14, j + 0, k + 31, sh, ms);
		world.setBlock(i + 14, j + 0, k + 33, sh, ms);
		world.setBlock(i + 14, j + 0, k + 34, sh, ms);
		world.setBlock(i + 14, j + 0, k + 36, sh, ms);
		world.setBlock(i + 14, j + 0, k + 37, sh, ms);
		world.setBlock(i + 14, j + 1, k + 5, sh, ms);
		world.setBlock(i + 14, j + 1, k + 37, sh, ms);
		world.setBlock(i + 14, j + 11, k + 5, sh, ms);
		world.setBlock(i + 14, j + 11, k + 6, sh, ms);
		world.setBlock(i + 14, j + 11, k + 36, sh, ms);
		world.setBlock(i + 14, j + 11, k + 37, sh, ms);
		world.setBlock(i + 14, j + 12, k + 7, sh, ms);
		world.setBlock(i + 14, j + 12, k + 8, sh, ms);
		world.setBlock(i + 14, j + 12, k + 34, sh, ms);
		world.setBlock(i + 14, j + 12, k + 35, sh, ms);
		world.setBlock(i + 15, j + 0, k + 5, sh, ms);
		world.setBlock(i + 15, j + 0, k + 6, sh, ms);
		world.setBlock(i + 15, j + 0, k + 7, sh, ms);
		world.setBlock(i + 15, j + 0, k + 8, sh, ms);
		world.setBlock(i + 15, j + 0, k + 10, sh, ms);
		world.setBlock(i + 15, j + 0, k + 11, sh, ms);
		world.setBlock(i + 15, j + 0, k + 12, sh, ms);
		world.setBlock(i + 15, j + 0, k + 13, sh, ms);
		world.setBlock(i + 15, j + 0, k + 15, sh, ms);
		world.setBlock(i + 15, j + 0, k + 16, sh, ms);
		world.setBlock(i + 15, j + 0, k + 17, sh, ms);
		world.setBlock(i + 15, j + 0, k + 18, sh, ms);
		world.setBlock(i + 15, j + 0, k + 19, sh, ms);
		world.setBlock(i + 15, j + 0, k + 20, sh, ms);
		world.setBlock(i + 15, j + 0, k + 21, sh, ms);
		world.setBlock(i + 15, j + 0, k + 22, sh, ms);
		world.setBlock(i + 15, j + 0, k + 23, sh, ms);
		world.setBlock(i + 15, j + 0, k + 24, sh, ms);
		world.setBlock(i + 15, j + 0, k + 25, sh, ms);
		world.setBlock(i + 15, j + 0, k + 26, sh, ms);
		world.setBlock(i + 15, j + 0, k + 27, sh, ms);
		world.setBlock(i + 15, j + 0, k + 29, sh, ms);
		world.setBlock(i + 15, j + 0, k + 30, sh, ms);
		world.setBlock(i + 15, j + 0, k + 31, sh, ms);
		world.setBlock(i + 15, j + 0, k + 32, sh, ms);
		world.setBlock(i + 15, j + 0, k + 34, sh, ms);
		world.setBlock(i + 15, j + 0, k + 35, sh, ms);
		world.setBlock(i + 15, j + 0, k + 36, sh, ms);
		world.setBlock(i + 16, j + 0, k + 3, sh, ms);
		world.setBlock(i + 16, j + 0, k + 5, sh, ms);
		world.setBlock(i + 16, j + 0, k + 6, sh, ms);
		world.setBlock(i + 16, j + 0, k + 7, sh, ms);
		world.setBlock(i + 16, j + 0, k + 9, sh, ms);
		world.setBlock(i + 16, j + 0, k + 10, sh, ms);
		world.setBlock(i + 16, j + 0, k + 11, sh, ms);
		world.setBlock(i + 16, j + 0, k + 12, sh, ms);
		world.setBlock(i + 16, j + 0, k + 14, sh, ms);
		world.setBlock(i + 16, j + 0, k + 15, sh, ms);
		world.setBlock(i + 16, j + 0, k + 16, sh, ms);
		world.setBlock(i + 16, j + 0, k + 17, sh, ms);
		world.setBlock(i + 16, j + 0, k + 25, sh, ms);
		world.setBlock(i + 16, j + 0, k + 26, sh, ms);
		world.setBlock(i + 16, j + 0, k + 27, sh, ms);
		world.setBlock(i + 16, j + 0, k + 28, sh, ms);
		world.setBlock(i + 16, j + 0, k + 30, sh, ms);
		world.setBlock(i + 16, j + 0, k + 31, sh, ms);
	}

	private void doGenerate2(ChunkSplicedGenerationCache world, int i, int j, int k) {
		world.setBlock(i + 16, j + 0, k + 32, sh, ms);
		world.setBlock(i + 16, j + 0, k + 33, sh, ms);
		world.setBlock(i + 16, j + 0, k + 35, sh, ms);
		world.setBlock(i + 16, j + 0, k + 36, sh, ms);
		world.setBlock(i + 16, j + 0, k + 37, sh, ms);
		world.setBlock(i + 16, j + 0, k + 38, sh, ms);
		world.setBlock(i + 16, j + 0, k + 39, sh, ms);
		world.setBlock(i + 16, j + 1, k + 1, sh, ms);
		world.setBlock(i + 16, j + 1, k + 2, sh, ms);
		world.setBlock(i + 16, j + 1, k + 3, sh, ms);
		world.setBlock(i + 16, j + 1, k + 39, sh, ms);
		world.setBlock(i + 16, j + 1, k + 40, sh, ms);
		world.setBlock(i + 16, j + 1, k + 41, sh, ms);
		world.setBlock(i + 16, j + 2, k + 1, sh, ms);
		world.setBlock(i + 16, j + 2, k + 2, sh, ms);
		world.setBlock(i + 16, j + 2, k + 40, sh, ms);
		world.setBlock(i + 16, j + 2, k + 41, sh, ms);
		world.setBlock(i + 16, j + 3, k + 0, sh, ms);
		world.setBlock(i + 16, j + 3, k + 1, sh, ms);
		world.setBlock(i + 16, j + 3, k + 41, sh, ms);
		world.setBlock(i + 16, j + 3, k + 42, sh, ms);
		world.setBlock(i + 16, j + 4, k + 0, sh, ms);
		world.setBlock(i + 16, j + 4, k + 1, sh, ms);
		world.setBlock(i + 16, j + 4, k + 41, sh, ms);
		world.setBlock(i + 16, j + 4, k + 42, sh, ms);
		world.setBlock(i + 16, j + 5, k + 0, sh, ms);
		world.setBlock(i + 16, j + 5, k + 42, sh, ms);
		world.setBlock(i + 16, j + 6, k + 0, sh, ms);
		world.setBlock(i + 16, j + 6, k + 42, sh, ms);
		world.setBlock(i + 16, j + 7, k + 0, sh, ms);
		world.setBlock(i + 16, j + 7, k + 42, sh, ms);
		world.setBlock(i + 16, j + 8, k + 0, sh, ms);
		world.setBlock(i + 16, j + 8, k + 1, sh, ms);
		world.setBlock(i + 16, j + 8, k + 41, sh, ms);
		world.setBlock(i + 16, j + 8, k + 42, sh, ms);
		world.setBlock(i + 16, j + 9, k + 1, sh, ms);
		world.setBlock(i + 16, j + 9, k + 41, sh, ms);
		world.setBlock(i + 16, j + 10, k + 1, sh, ms);
		world.setBlock(i + 16, j + 10, k + 2, sh, ms);
		world.setBlock(i + 16, j + 10, k + 40, sh, ms);
		world.setBlock(i + 16, j + 10, k + 41, sh, ms);
		world.setBlock(i + 16, j + 11, k + 2, sh, ms);
		world.setBlock(i + 16, j + 11, k + 3, sh, ms);
		world.setBlock(i + 16, j + 11, k + 39, sh, ms);
		world.setBlock(i + 16, j + 11, k + 40, sh, ms);
		world.setBlock(i + 17, j + 0, k + 1, sh, ms);
		world.setBlock(i + 17, j + 0, k + 2, sh, ms);
		world.setBlock(i + 17, j + 0, k + 3, sh, ms);
		world.setBlock(i + 17, j + 0, k + 5, sh, ms);
		world.setBlock(i + 17, j + 0, k + 7, sh, ms);
		world.setBlock(i + 17, j + 0, k + 9, sh, ms);
		world.setBlock(i + 17, j + 0, k + 10, sh, ms);
		world.setBlock(i + 17, j + 0, k + 11, sh, ms);
		world.setBlock(i + 17, j + 0, k + 13, sh, ms);
		world.setBlock(i + 17, j + 0, k + 14, sh, ms);
		world.setBlock(i + 17, j + 0, k + 15, sh, ms);
		world.setBlock(i + 17, j + 0, k + 16, sh, ms);
		world.setBlock(i + 17, j + 0, k + 18, sh, ms);
		world.setBlock(i + 17, j + 0, k + 19, sh, ms);
		world.setBlock(i + 17, j + 0, k + 20, sh, ms);
		world.setBlock(i + 17, j + 0, k + 21, sh, ms);
		world.setBlock(i + 17, j + 0, k + 22, sh, ms);
		world.setBlock(i + 17, j + 0, k + 23, sh, ms);
		world.setBlock(i + 17, j + 0, k + 24, sh, ms);
		world.setBlock(i + 17, j + 0, k + 26, sh, ms);
		world.setBlock(i + 17, j + 0, k + 27, sh, ms);
		world.setBlock(i + 17, j + 0, k + 28, sh, ms);
		world.setBlock(i + 17, j + 0, k + 29, sh, ms);
		world.setBlock(i + 17, j + 0, k + 31, sh, ms);
		world.setBlock(i + 17, j + 0, k + 32, sh, ms);
		world.setBlock(i + 17, j + 0, k + 33, sh, ms);
		world.setBlock(i + 17, j + 0, k + 35, sh, ms);
		world.setBlock(i + 17, j + 0, k + 37, sh, ms);
		world.setBlock(i + 17, j + 0, k + 39, sh, ms);
		world.setBlock(i + 17, j + 0, k + 40, sh, ms);
		world.setBlock(i + 17, j + 0, k + 41, sh, ms);
		world.setBlock(i + 17, j + 1, k + 0, sh, ms);
		world.setBlock(i + 17, j + 1, k + 1, sh, ms);
		world.setBlock(i + 17, j + 1, k + 2, sh, ms);
		world.setBlock(i + 17, j + 1, k + 40, sh, ms);
		world.setBlock(i + 17, j + 1, k + 41, sh, ms);
		world.setBlock(i + 17, j + 1, k + 42, sh, ms);
		world.setBlock(i + 17, j + 2, k + 0, sh, ms);
		world.setBlock(i + 17, j + 2, k + 1, sh, ms);
		world.setBlock(i + 17, j + 2, k + 41, sh, ms);
		world.setBlock(i + 17, j + 2, k + 42, sh, ms);
		world.setBlock(i + 17, j + 3, k + 0, sh, ms);
		world.setBlock(i + 17, j + 3, k + 1, sh, ms);
		world.setBlock(i + 17, j + 3, k + 41, sh, ms);
		world.setBlock(i + 17, j + 3, k + 42, sh, ms);
		world.setBlock(i + 17, j + 4, k + 0, sh, ms);
		world.setBlock(i + 17, j + 4, k + 42, sh, ms);
		world.setBlock(i + 17, j + 8, k + 0, sh, ms);
		world.setBlock(i + 17, j + 8, k + 42, sh, ms);
		world.setBlock(i + 17, j + 9, k + 0, sh, ms);
		world.setBlock(i + 17, j + 9, k + 1, sh, ms);
		world.setBlock(i + 17, j + 9, k + 41, sh, ms);
		world.setBlock(i + 17, j + 9, k + 42, sh, ms);
		world.setBlock(i + 17, j + 10, k + 0, sh, ms);
		world.setBlock(i + 17, j + 10, k + 1, sh, ms);
		world.setBlock(i + 17, j + 10, k + 2, sh, ms);
		world.setBlock(i + 17, j + 10, k + 40, sh, ms);
		world.setBlock(i + 17, j + 10, k + 41, sh, ms);
		world.setBlock(i + 17, j + 10, k + 42, sh, ms);
		world.setBlock(i + 17, j + 11, k + 1, sh, ms);
		world.setBlock(i + 17, j + 11, k + 2, sh, ms);
		world.setBlock(i + 17, j + 11, k + 3, sh, ms);
		world.setBlock(i + 17, j + 11, k + 39, sh, ms);
		world.setBlock(i + 17, j + 11, k + 40, sh, ms);
		world.setBlock(i + 17, j + 11, k + 41, sh, ms);
		world.setBlock(i + 17, j + 12, k + 2, sh, ms);
		world.setBlock(i + 17, j + 12, k + 3, sh, ms);
		world.setBlock(i + 17, j + 12, k + 4, sh, ms);
		world.setBlock(i + 17, j + 12, k + 38, sh, ms);
		world.setBlock(i + 17, j + 12, k + 39, sh, ms);
		world.setBlock(i + 17, j + 12, k + 40, sh, ms);
		world.setBlock(i + 18, j + 0, k + 0, sh, ms);
		world.setBlock(i + 18, j + 0, k + 1, sh, ms);
		world.setBlock(i + 18, j + 0, k + 2, sh, ms);
		world.setBlock(i + 18, j + 0, k + 3, sh, ms);
		world.setBlock(i + 18, j + 0, k + 5, sh, ms);
		world.setBlock(i + 18, j + 0, k + 7, sh, ms);
		world.setBlock(i + 18, j + 0, k + 9, sh, ms);
		world.setBlock(i + 18, j + 0, k + 10, sh, ms);
		world.setBlock(i + 18, j + 0, k + 11, sh, ms);
		world.setBlock(i + 18, j + 0, k + 13, sh, ms);
		world.setBlock(i + 18, j + 0, k + 14, sh, ms);
		world.setBlock(i + 18, j + 0, k + 15, sh, ms);
		world.setBlock(i + 18, j + 0, k + 17, sh, ms);
		world.setBlock(i + 18, j + 0, k + 18, sh, ms);
		world.setBlock(i + 18, j + 0, k + 19, sh, ms);
		world.setBlock(i + 18, j + 0, k + 20, sh, ms);
		world.setBlock(i + 18, j + 0, k + 21, sh, ms);
		world.setBlock(i + 18, j + 0, k + 22, sh, ms);
		world.setBlock(i + 18, j + 0, k + 23, sh, ms);
		world.setBlock(i + 18, j + 0, k + 24, sh, ms);
		world.setBlock(i + 18, j + 0, k + 25, sh, ms);
		world.setBlock(i + 18, j + 0, k + 27, sh, ms);
		world.setBlock(i + 18, j + 0, k + 28, sh, ms);
		world.setBlock(i + 18, j + 0, k + 29, sh, ms);
		world.setBlock(i + 18, j + 0, k + 31, sh, ms);
		world.setBlock(i + 18, j + 0, k + 32, sh, ms);
		world.setBlock(i + 18, j + 0, k + 33, sh, ms);
		world.setBlock(i + 18, j + 0, k + 35, sh, ms);
		world.setBlock(i + 18, j + 0, k + 37, sh, ms);
		world.setBlock(i + 18, j + 0, k + 39, sh, ms);
		world.setBlock(i + 18, j + 0, k + 40, sh, ms);
		world.setBlock(i + 18, j + 0, k + 41, sh, ms);
		world.setBlock(i + 18, j + 0, k + 42, sh, ms);
		world.setBlock(i + 18, j + 1, k + 0, sh, ms);
		world.setBlock(i + 18, j + 1, k + 1, sh, ms);
		world.setBlock(i + 18, j + 1, k + 2, sh, ms);
		world.setBlock(i + 18, j + 1, k + 20, sh, ms);
		world.setBlock(i + 18, j + 1, k + 21, sh, ms);
		world.setBlock(i + 18, j + 1, k + 22, sh, ms);
		world.setBlock(i + 18, j + 1, k + 40, sh, ms);
		world.setBlock(i + 18, j + 1, k + 41, sh, ms);
		world.setBlock(i + 18, j + 1, k + 42, sh, ms);
		world.setBlock(i + 18, j + 2, k + 0, sh, ms);
		world.setBlock(i + 18, j + 2, k + 1, sh, ms);
		world.setBlock(i + 18, j + 2, k + 41, sh, ms);
		world.setBlock(i + 18, j + 2, k + 42, sh, ms);
		world.setBlock(i + 18, j + 3, k + 0, sh, ms);
		world.setBlock(i + 18, j + 3, k + 42, sh, ms);
		world.setBlock(i + 18, j + 4, k + 0, sh, ms);
		world.setBlock(i + 18, j + 4, k + 42, sh, ms);
		world.setBlock(i + 18, j + 6, k + 0, sh, ms);
		world.setBlock(i + 18, j + 6, k + 42, sh, ms);
		world.setBlock(i + 18, j + 8, k + 0, sh, ms);
		world.setBlock(i + 18, j + 8, k + 42, sh, ms);
		world.setBlock(i + 18, j + 9, k + 0, sh, ms);
		world.setBlock(i + 18, j + 9, k + 42, sh, ms);
		world.setBlock(i + 18, j + 10, k + 0, sh, ms);
		world.setBlock(i + 18, j + 10, k + 1, sh, ms);
		world.setBlock(i + 18, j + 10, k + 2, sh, ms);
		world.setBlock(i + 18, j + 10, k + 40, sh, ms);
		world.setBlock(i + 18, j + 10, k + 41, sh, ms);
		world.setBlock(i + 18, j + 10, k + 42, sh, ms);
		world.setBlock(i + 18, j + 11, k + 0, sh, ms);
		world.setBlock(i + 18, j + 11, k + 1, sh, ms);
		world.setBlock(i + 18, j + 11, k + 2, sh, ms);
		world.setBlock(i + 18, j + 11, k + 40, sh, ms);
		world.setBlock(i + 18, j + 11, k + 41, sh, ms);
		world.setBlock(i + 18, j + 11, k + 42, sh, ms);
		world.setBlock(i + 18, j + 12, k + 1, sh, ms);
		world.setBlock(i + 18, j + 12, k + 2, sh, ms);
		world.setBlock(i + 18, j + 12, k + 4, sh, ms);
		world.setBlock(i + 18, j + 12, k + 5, sh, ms);
		world.setBlock(i + 18, j + 12, k + 37, sh, ms);
		world.setBlock(i + 18, j + 12, k + 38, sh, ms);
		world.setBlock(i + 18, j + 12, k + 40, sh, ms);
		world.setBlock(i + 18, j + 12, k + 41, sh, ms);
		world.setBlock(i + 19, j + 0, k + 1, sh, ms);
		world.setBlock(i + 19, j + 0, k + 2, sh, ms);
		world.setBlock(i + 19, j + 0, k + 3, sh, ms);
		world.setBlock(i + 19, j + 0, k + 5, sh, ms);
		world.setBlock(i + 19, j + 0, k + 7, sh, ms);
		world.setBlock(i + 19, j + 0, k + 9, sh, ms);
		world.setBlock(i + 19, j + 0, k + 10, sh, ms);
		world.setBlock(i + 19, j + 0, k + 11, sh, ms);
		world.setBlock(i + 19, j + 0, k + 13, sh, ms);
		world.setBlock(i + 19, j + 0, k + 14, sh, ms);
		world.setBlock(i + 19, j + 0, k + 15, sh, ms);
		world.setBlock(i + 19, j + 0, k + 17, sh, ms);
		world.setBlock(i + 19, j + 0, k + 18, sh, ms);
		world.setBlock(i + 19, j + 0, k + 19, sh, ms);
		world.setBlock(i + 19, j + 0, k + 23, sh, ms);
		world.setBlock(i + 19, j + 0, k + 24, sh, ms);
		world.setBlock(i + 19, j + 0, k + 25, sh, ms);
		world.setBlock(i + 19, j + 0, k + 27, sh, ms);
		world.setBlock(i + 19, j + 0, k + 28, sh, ms);
		world.setBlock(i + 19, j + 0, k + 29, sh, ms);
		world.setBlock(i + 19, j + 0, k + 31, sh, ms);
		world.setBlock(i + 19, j + 0, k + 32, sh, ms);
		world.setBlock(i + 19, j + 0, k + 33, sh, ms);
		world.setBlock(i + 19, j + 0, k + 35, sh, ms);
		world.setBlock(i + 19, j + 0, k + 37, sh, ms);
		world.setBlock(i + 19, j + 0, k + 39, sh, ms);
		world.setBlock(i + 19, j + 0, k + 40, sh, ms);
		world.setBlock(i + 19, j + 0, k + 41, sh, ms);
		world.setBlock(i + 19, j + 1, k + 0, sh, ms);
		world.setBlock(i + 19, j + 1, k + 1, sh, ms);
		world.setBlock(i + 19, j + 1, k + 2, sh, ms);
		world.setBlock(i + 19, j + 1, k + 19, sh, ms);
		world.setBlock(i + 19, j + 1, k + 23, sh, ms);
		world.setBlock(i + 19, j + 1, k + 40, sh, ms);
		world.setBlock(i + 19, j + 1, k + 41, sh, ms);
		world.setBlock(i + 19, j + 1, k + 42, sh, ms);
		world.setBlock(i + 19, j + 2, k + 0, sh, ms);
		world.setBlock(i + 19, j + 2, k + 1, sh, ms);
		world.setBlock(i + 19, j + 2, k + 41, sh, ms);
		world.setBlock(i + 19, j + 2, k + 42, sh, ms);
		world.setBlock(i + 19, j + 3, k + 0, sh, ms);
		world.setBlock(i + 19, j + 3, k + 1, sh, ms);
		world.setBlock(i + 19, j + 3, k + 41, sh, ms);
		world.setBlock(i + 19, j + 3, k + 42, sh, ms);
		world.setBlock(i + 19, j + 4, k + 0, sh, ms);
		world.setBlock(i + 19, j + 4, k + 42, sh, ms);
		world.setBlock(i + 19, j + 8, k + 0, sh, ms);
		world.setBlock(i + 19, j + 8, k + 42, sh, ms);
		world.setBlock(i + 19, j + 9, k + 0, sh, ms);
		world.setBlock(i + 19, j + 9, k + 1, sh, ms);
		world.setBlock(i + 19, j + 9, k + 41, sh, ms);
		world.setBlock(i + 19, j + 9, k + 42, sh, ms);
		world.setBlock(i + 19, j + 10, k + 0, sh, ms);
		world.setBlock(i + 19, j + 10, k + 1, sh, ms);
		world.setBlock(i + 19, j + 10, k + 2, sh, ms);
		world.setBlock(i + 19, j + 10, k + 40, sh, ms);
		world.setBlock(i + 19, j + 10, k + 41, sh, ms);
		world.setBlock(i + 19, j + 10, k + 42, sh, ms);
		world.setBlock(i + 19, j + 11, k + 1, sh, ms);
		world.setBlock(i + 19, j + 11, k + 2, sh, ms);
		world.setBlock(i + 19, j + 11, k + 3, sh, ms);
		world.setBlock(i + 19, j + 11, k + 39, sh, ms);
		world.setBlock(i + 19, j + 11, k + 40, sh, ms);
		world.setBlock(i + 19, j + 11, k + 41, sh, ms);
		world.setBlock(i + 19, j + 12, k + 2, sh, ms);
		world.setBlock(i + 19, j + 12, k + 3, sh, ms);
		world.setBlock(i + 19, j + 12, k + 4, sh, ms);
		world.setBlock(i + 19, j + 12, k + 38, sh, ms);
		world.setBlock(i + 19, j + 12, k + 39, sh, ms);
		world.setBlock(i + 19, j + 12, k + 40, sh, ms);
		world.setBlock(i + 20, j + 0, k + 3, sh, ms);
		world.setBlock(i + 20, j + 0, k + 4, sh, ms);
		world.setBlock(i + 20, j + 0, k + 5, sh, ms);
		world.setBlock(i + 20, j + 0, k + 7, sh, ms);
		world.setBlock(i + 20, j + 0, k + 9, sh, ms);
		world.setBlock(i + 20, j + 0, k + 10, sh, ms);
		world.setBlock(i + 20, j + 0, k + 11, sh, ms);
		world.setBlock(i + 20, j + 0, k + 13, sh, ms);
		world.setBlock(i + 20, j + 0, k + 14, sh, ms);
		world.setBlock(i + 20, j + 0, k + 15, sh, ms);
		world.setBlock(i + 20, j + 0, k + 17, sh, ms);
		world.setBlock(i + 20, j + 0, k + 18, sh, ms);
		world.setBlock(i + 20, j + 0, k + 24, sh, ms);
		world.setBlock(i + 20, j + 0, k + 25, sh, ms);
		world.setBlock(i + 20, j + 0, k + 27, sh, ms);
		world.setBlock(i + 20, j + 0, k + 28, sh, ms);
		world.setBlock(i + 20, j + 0, k + 29, sh, ms);
		world.setBlock(i + 20, j + 0, k + 31, sh, ms);
		world.setBlock(i + 20, j + 0, k + 32, sh, ms);
		world.setBlock(i + 20, j + 0, k + 33, sh, ms);
		world.setBlock(i + 20, j + 0, k + 35, sh, ms);
		world.setBlock(i + 20, j + 0, k + 37, sh, ms);
		world.setBlock(i + 20, j + 0, k + 38, sh, ms);
		world.setBlock(i + 20, j + 0, k + 39, sh, ms);
		world.setBlock(i + 20, j + 1, k + 1, sh, ms);
		world.setBlock(i + 20, j + 1, k + 2, sh, ms);
		world.setBlock(i + 20, j + 1, k + 3, sh, ms);
		world.setBlock(i + 20, j + 1, k + 18, sh, ms);
		world.setBlock(i + 20, j + 1, k + 24, sh, ms);
		world.setBlock(i + 20, j + 1, k + 39, sh, ms);
		world.setBlock(i + 20, j + 1, k + 40, sh, ms);
		world.setBlock(i + 20, j + 1, k + 41, sh, ms);
		world.setBlock(i + 20, j + 2, k + 1, sh, ms);
		world.setBlock(i + 20, j + 2, k + 2, sh, ms);
		world.setBlock(i + 20, j + 2, k + 40, sh, ms);
		world.setBlock(i + 20, j + 2, k + 41, sh, ms);
		world.setBlock(i + 20, j + 3, k + 0, sh, ms);
		world.setBlock(i + 20, j + 3, k + 1, sh, ms);
		world.setBlock(i + 20, j + 3, k + 41, sh, ms);
		world.setBlock(i + 20, j + 3, k + 42, sh, ms);
		world.setBlock(i + 20, j + 4, k + 0, sh, ms);
		world.setBlock(i + 20, j + 4, k + 1, sh, ms);
		world.setBlock(i + 20, j + 4, k + 41, sh, ms);
		world.setBlock(i + 20, j + 4, k + 42, sh, ms);
		world.setBlock(i + 20, j + 5, k + 0, sh, ms);
		world.setBlock(i + 20, j + 5, k + 42, sh, ms);
		world.setBlock(i + 20, j + 6, k + 0, sh, ms);
		world.setBlock(i + 20, j + 6, k + 42, sh, ms);
		world.setBlock(i + 20, j + 7, k + 0, sh, ms);
		world.setBlock(i + 20, j + 7, k + 42, sh, ms);
		world.setBlock(i + 20, j + 8, k + 0, sh, ms);
		world.setBlock(i + 20, j + 8, k + 1, sh, ms);
		world.setBlock(i + 20, j + 8, k + 41, sh, ms);
		world.setBlock(i + 20, j + 8, k + 42, sh, ms);
		world.setBlock(i + 20, j + 9, k + 1, sh, ms);
		world.setBlock(i + 20, j + 9, k + 41, sh, ms);
		world.setBlock(i + 20, j + 10, k + 1, sh, ms);
		world.setBlock(i + 20, j + 10, k + 2, sh, ms);
		world.setBlock(i + 20, j + 10, k + 40, sh, ms);
		world.setBlock(i + 20, j + 10, k + 41, sh, ms);
		world.setBlock(i + 20, j + 11, k + 2, sh, ms);
		world.setBlock(i + 20, j + 11, k + 3, sh, ms);
		world.setBlock(i + 20, j + 11, k + 39, sh, ms);
		world.setBlock(i + 20, j + 11, k + 40, sh, ms);
		world.setBlock(i + 21, j + 0, k + 5, sh, ms);
		world.setBlock(i + 21, j + 0, k + 7, sh, ms);
		world.setBlock(i + 21, j + 0, k + 9, sh, ms);
		world.setBlock(i + 21, j + 0, k + 10, sh, ms);
		world.setBlock(i + 21, j + 0, k + 11, sh, ms);
		world.setBlock(i + 21, j + 0, k + 13, sh, ms);
		world.setBlock(i + 21, j + 0, k + 14, sh, ms);
		world.setBlock(i + 21, j + 0, k + 15, sh, ms);
		world.setBlock(i + 21, j + 0, k + 17, sh, ms);
		world.setBlock(i + 21, j + 0, k + 18, sh, ms);
		world.setBlock(i + 21, j + 0, k + 21, sh, ms);
		world.setBlock(i + 21, j + 0, k + 24, sh, ms);
		world.setBlock(i + 21, j + 0, k + 25, sh, ms);
		world.setBlock(i + 21, j + 0, k + 27, sh, ms);
		world.setBlock(i + 21, j + 0, k + 28, sh, ms);
		world.setBlock(i + 21, j + 0, k + 29, sh, ms);
		world.setBlock(i + 21, j + 0, k + 31, sh, ms);
		world.setBlock(i + 21, j + 0, k + 32, sh, ms);
		world.setBlock(i + 21, j + 0, k + 33, sh, ms);
		world.setBlock(i + 21, j + 0, k + 35, sh, ms);
		world.setBlock(i + 21, j + 0, k + 37, sh, ms);
		world.setBlock(i + 21, j + 1, k + 18, sh, ms);
		world.setBlock(i + 21, j + 1, k + 21, sh, ms);
		world.setBlock(i + 21, j + 1, k + 24, sh, ms);
		world.setBlock(i + 21, j + 2, k + 21, sh, ms);
		world.setBlock(i + 22, j + 0, k + 3, sh, ms);
		world.setBlock(i + 22, j + 0, k + 4, sh, ms);
		world.setBlock(i + 22, j + 0, k + 5, sh, ms);
		world.setBlock(i + 22, j + 0, k + 7, sh, ms);
		world.setBlock(i + 22, j + 0, k + 9, sh, ms);
		world.setBlock(i + 22, j + 0, k + 10, sh, ms);
		world.setBlock(i + 22, j + 0, k + 11, sh, ms);
		world.setBlock(i + 22, j + 0, k + 13, sh, ms);
		world.setBlock(i + 22, j + 0, k + 14, sh, ms);
		world.setBlock(i + 22, j + 0, k + 15, sh, ms);
		world.setBlock(i + 22, j + 0, k + 17, sh, ms);
		world.setBlock(i + 22, j + 0, k + 18, sh, ms);
		world.setBlock(i + 22, j + 0, k + 24, sh, ms);
		world.setBlock(i + 22, j + 0, k + 25, sh, ms);
		world.setBlock(i + 22, j + 0, k + 27, sh, ms);
		world.setBlock(i + 22, j + 0, k + 28, sh, ms);
		world.setBlock(i + 22, j + 0, k + 29, sh, ms);
		world.setBlock(i + 22, j + 0, k + 31, sh, ms);
		world.setBlock(i + 22, j + 0, k + 32, sh, ms);
		world.setBlock(i + 22, j + 0, k + 33, sh, ms);
		world.setBlock(i + 22, j + 0, k + 35, sh, ms);
		world.setBlock(i + 22, j + 0, k + 37, sh, ms);
		world.setBlock(i + 22, j + 0, k + 38, sh, ms);
		world.setBlock(i + 22, j + 0, k + 39, sh, ms);
		world.setBlock(i + 22, j + 1, k + 1, sh, ms);
		world.setBlock(i + 22, j + 1, k + 2, sh, ms);
		world.setBlock(i + 22, j + 1, k + 3, sh, ms);
		world.setBlock(i + 22, j + 1, k + 18, sh, ms);
		world.setBlock(i + 22, j + 1, k + 24, sh, ms);
		world.setBlock(i + 22, j + 1, k + 39, sh, ms);
		world.setBlock(i + 22, j + 1, k + 40, sh, ms);
		world.setBlock(i + 22, j + 1, k + 41, sh, ms);
		world.setBlock(i + 22, j + 2, k + 1, sh, ms);
		world.setBlock(i + 22, j + 2, k + 2, sh, ms);
		world.setBlock(i + 22, j + 2, k + 40, sh, ms);
		world.setBlock(i + 22, j + 2, k + 41, sh, ms);
		world.setBlock(i + 22, j + 3, k + 0, sh, ms);
		world.setBlock(i + 22, j + 3, k + 1, sh, ms);
		world.setBlock(i + 22, j + 3, k + 41, sh, ms);
		world.setBlock(i + 22, j + 3, k + 42, sh, ms);
		world.setBlock(i + 22, j + 4, k + 0, sh, ms);
		world.setBlock(i + 22, j + 4, k + 1, sh, ms);
		world.setBlock(i + 22, j + 4, k + 41, sh, ms);
		world.setBlock(i + 22, j + 4, k + 42, sh, ms);
		world.setBlock(i + 22, j + 5, k + 0, sh, ms);
		world.setBlock(i + 22, j + 5, k + 42, sh, ms);
		world.setBlock(i + 22, j + 6, k + 0, sh, ms);
		world.setBlock(i + 22, j + 6, k + 42, sh, ms);
		world.setBlock(i + 22, j + 7, k + 0, sh, ms);
		world.setBlock(i + 22, j + 7, k + 42, sh, ms);
		world.setBlock(i + 22, j + 8, k + 0, sh, ms);
		world.setBlock(i + 22, j + 8, k + 1, sh, ms);
		world.setBlock(i + 22, j + 8, k + 41, sh, ms);
		world.setBlock(i + 22, j + 8, k + 42, sh, ms);
		world.setBlock(i + 22, j + 9, k + 1, sh, ms);
		world.setBlock(i + 22, j + 9, k + 41, sh, ms);
		world.setBlock(i + 22, j + 10, k + 1, sh, ms);
		world.setBlock(i + 22, j + 10, k + 2, sh, ms);
		world.setBlock(i + 22, j + 10, k + 40, sh, ms);
		world.setBlock(i + 22, j + 10, k + 41, sh, ms);
		world.setBlock(i + 22, j + 11, k + 2, sh, ms);
		world.setBlock(i + 22, j + 11, k + 3, sh, ms);
		world.setBlock(i + 22, j + 11, k + 39, sh, ms);
		world.setBlock(i + 22, j + 11, k + 40, sh, ms);
		world.setBlock(i + 23, j + 0, k + 1, sh, ms);
		world.setBlock(i + 23, j + 0, k + 2, sh, ms);
		world.setBlock(i + 23, j + 0, k + 3, sh, ms);
		world.setBlock(i + 23, j + 0, k + 5, sh, ms);
		world.setBlock(i + 23, j + 0, k + 7, sh, ms);
		world.setBlock(i + 23, j + 0, k + 9, sh, ms);
		world.setBlock(i + 23, j + 0, k + 10, sh, ms);
		world.setBlock(i + 23, j + 0, k + 11, sh, ms);
		world.setBlock(i + 23, j + 0, k + 13, sh, ms);
		world.setBlock(i + 23, j + 0, k + 14, sh, ms);
		world.setBlock(i + 23, j + 0, k + 15, sh, ms);
		world.setBlock(i + 23, j + 0, k + 17, sh, ms);
		world.setBlock(i + 23, j + 0, k + 18, sh, ms);
		world.setBlock(i + 23, j + 0, k + 19, sh, ms);
		world.setBlock(i + 23, j + 0, k + 23, sh, ms);
		world.setBlock(i + 23, j + 0, k + 24, sh, ms);
		world.setBlock(i + 23, j + 0, k + 25, sh, ms);
		world.setBlock(i + 23, j + 0, k + 27, sh, ms);
		world.setBlock(i + 23, j + 0, k + 28, sh, ms);
		world.setBlock(i + 23, j + 0, k + 29, sh, ms);
		world.setBlock(i + 23, j + 0, k + 31, sh, ms);
		world.setBlock(i + 23, j + 0, k + 32, sh, ms);
		world.setBlock(i + 23, j + 0, k + 33, sh, ms);
		world.setBlock(i + 23, j + 0, k + 35, sh, ms);
		world.setBlock(i + 23, j + 0, k + 37, sh, ms);
		world.setBlock(i + 23, j + 0, k + 39, sh, ms);
		world.setBlock(i + 23, j + 0, k + 40, sh, ms);
		world.setBlock(i + 23, j + 0, k + 41, sh, ms);
		world.setBlock(i + 23, j + 1, k + 0, sh, ms);
		world.setBlock(i + 23, j + 1, k + 1, sh, ms);
		world.setBlock(i + 23, j + 1, k + 2, sh, ms);
		world.setBlock(i + 23, j + 1, k + 19, sh, ms);
		world.setBlock(i + 23, j + 1, k + 23, sh, ms);
		world.setBlock(i + 23, j + 1, k + 40, sh, ms);
		world.setBlock(i + 23, j + 1, k + 41, sh, ms);
		world.setBlock(i + 23, j + 1, k + 42, sh, ms);
		world.setBlock(i + 23, j + 2, k + 0, sh, ms);
		world.setBlock(i + 23, j + 2, k + 1, sh, ms);
		world.setBlock(i + 23, j + 2, k + 41, sh, ms);
		world.setBlock(i + 23, j + 2, k + 42, sh, ms);
		world.setBlock(i + 23, j + 3, k + 0, sh, ms);
		world.setBlock(i + 23, j + 3, k + 1, sh, ms);
		world.setBlock(i + 23, j + 3, k + 41, sh, ms);
		world.setBlock(i + 23, j + 3, k + 42, sh, ms);
		world.setBlock(i + 23, j + 4, k + 0, sh, ms);
		world.setBlock(i + 23, j + 4, k + 42, sh, ms);
		world.setBlock(i + 23, j + 8, k + 0, sh, ms);
		world.setBlock(i + 23, j + 8, k + 42, sh, ms);
		world.setBlock(i + 23, j + 9, k + 0, sh, ms);
		world.setBlock(i + 23, j + 9, k + 1, sh, ms);
		world.setBlock(i + 23, j + 9, k + 41, sh, ms);
		world.setBlock(i + 23, j + 9, k + 42, sh, ms);
		world.setBlock(i + 23, j + 10, k + 0, sh, ms);
		world.setBlock(i + 23, j + 10, k + 1, sh, ms);
		world.setBlock(i + 23, j + 10, k + 2, sh, ms);
		world.setBlock(i + 23, j + 10, k + 40, sh, ms);
		world.setBlock(i + 23, j + 10, k + 41, sh, ms);
		world.setBlock(i + 23, j + 10, k + 42, sh, ms);
		world.setBlock(i + 23, j + 11, k + 1, sh, ms);
		world.setBlock(i + 23, j + 11, k + 2, sh, ms);
		world.setBlock(i + 23, j + 11, k + 3, sh, ms);
		world.setBlock(i + 23, j + 11, k + 39, sh, ms);
		world.setBlock(i + 23, j + 11, k + 40, sh, ms);
		world.setBlock(i + 23, j + 11, k + 41, sh, ms);
		world.setBlock(i + 23, j + 12, k + 2, sh, ms);
		world.setBlock(i + 23, j + 12, k + 3, sh, ms);
		world.setBlock(i + 23, j + 12, k + 4, sh, ms);
		world.setBlock(i + 23, j + 12, k + 38, sh, ms);
		world.setBlock(i + 23, j + 12, k + 39, sh, ms);
		world.setBlock(i + 23, j + 12, k + 40, sh, ms);
		world.setBlock(i + 24, j + 0, k + 0, sh, ms);
		world.setBlock(i + 24, j + 0, k + 1, sh, ms);
		world.setBlock(i + 24, j + 0, k + 2, sh, ms);
		world.setBlock(i + 24, j + 0, k + 3, sh, ms);
		world.setBlock(i + 24, j + 0, k + 5, sh, ms);
		world.setBlock(i + 24, j + 0, k + 7, sh, ms);
		world.setBlock(i + 24, j + 0, k + 9, sh, ms);
		world.setBlock(i + 24, j + 0, k + 10, sh, ms);
		world.setBlock(i + 24, j + 0, k + 11, sh, ms);
		world.setBlock(i + 24, j + 0, k + 13, sh, ms);
		world.setBlock(i + 24, j + 0, k + 14, sh, ms);
		world.setBlock(i + 24, j + 0, k + 15, sh, ms);
		world.setBlock(i + 24, j + 0, k + 17, sh, ms);
		world.setBlock(i + 24, j + 0, k + 18, sh, ms);
		world.setBlock(i + 24, j + 0, k + 19, sh, ms);
		world.setBlock(i + 24, j + 0, k + 20, sh, ms);
		world.setBlock(i + 24, j + 0, k + 21, sh, ms);
		world.setBlock(i + 24, j + 0, k + 22, sh, ms);
		world.setBlock(i + 24, j + 0, k + 23, sh, ms);
		world.setBlock(i + 24, j + 0, k + 24, sh, ms);
		world.setBlock(i + 24, j + 0, k + 25, sh, ms);
		world.setBlock(i + 24, j + 0, k + 27, sh, ms);
		world.setBlock(i + 24, j + 0, k + 28, sh, ms);
		world.setBlock(i + 24, j + 0, k + 29, sh, ms);
		world.setBlock(i + 24, j + 0, k + 31, sh, ms);
		world.setBlock(i + 24, j + 0, k + 32, sh, ms);
		world.setBlock(i + 24, j + 0, k + 33, sh, ms);
		world.setBlock(i + 24, j + 0, k + 35, sh, ms);
		world.setBlock(i + 24, j + 0, k + 37, sh, ms);
		world.setBlock(i + 24, j + 0, k + 39, sh, ms);
		world.setBlock(i + 24, j + 0, k + 40, sh, ms);
		world.setBlock(i + 24, j + 0, k + 41, sh, ms);
		world.setBlock(i + 24, j + 0, k + 42, sh, ms);
		world.setBlock(i + 24, j + 1, k + 0, sh, ms);
		world.setBlock(i + 24, j + 1, k + 1, sh, ms);
		world.setBlock(i + 24, j + 1, k + 2, sh, ms);
		world.setBlock(i + 24, j + 1, k + 20, sh, ms);
		world.setBlock(i + 24, j + 1, k + 21, sh, ms);
		world.setBlock(i + 24, j + 1, k + 22, sh, ms);
		world.setBlock(i + 24, j + 1, k + 40, sh, ms);
		world.setBlock(i + 24, j + 1, k + 41, sh, ms);
		world.setBlock(i + 24, j + 1, k + 42, sh, ms);
		world.setBlock(i + 24, j + 2, k + 0, sh, ms);
		world.setBlock(i + 24, j + 2, k + 1, sh, ms);
		world.setBlock(i + 24, j + 2, k + 41, sh, ms);
		world.setBlock(i + 24, j + 2, k + 42, sh, ms);
		world.setBlock(i + 24, j + 3, k + 0, sh, ms);
		world.setBlock(i + 24, j + 3, k + 42, sh, ms);
		world.setBlock(i + 24, j + 4, k + 0, sh, ms);
		world.setBlock(i + 24, j + 4, k + 42, sh, ms);
		world.setBlock(i + 24, j + 6, k + 0, sh, ms);
		world.setBlock(i + 24, j + 6, k + 42, sh, ms);
		world.setBlock(i + 24, j + 8, k + 0, sh, ms);
		world.setBlock(i + 24, j + 8, k + 42, sh, ms);
		world.setBlock(i + 24, j + 9, k + 0, sh, ms);
		world.setBlock(i + 24, j + 9, k + 42, sh, ms);
		world.setBlock(i + 24, j + 10, k + 0, sh, ms);
		world.setBlock(i + 24, j + 10, k + 1, sh, ms);
		world.setBlock(i + 24, j + 10, k + 2, sh, ms);
		world.setBlock(i + 24, j + 10, k + 40, sh, ms);
		world.setBlock(i + 24, j + 10, k + 41, sh, ms);
		world.setBlock(i + 24, j + 10, k + 42, sh, ms);
		world.setBlock(i + 24, j + 11, k + 0, sh, ms);
		world.setBlock(i + 24, j + 11, k + 1, sh, ms);
		world.setBlock(i + 24, j + 11, k + 2, sh, ms);
		world.setBlock(i + 24, j + 11, k + 40, sh, ms);
		world.setBlock(i + 24, j + 11, k + 41, sh, ms);
		world.setBlock(i + 24, j + 11, k + 42, sh, ms);
		world.setBlock(i + 24, j + 12, k + 1, sh, ms);
		world.setBlock(i + 24, j + 12, k + 2, sh, ms);
		world.setBlock(i + 24, j + 12, k + 4, sh, ms);
		world.setBlock(i + 24, j + 12, k + 5, sh, ms);
		world.setBlock(i + 24, j + 12, k + 37, sh, ms);
		world.setBlock(i + 24, j + 12, k + 38, sh, ms);
		world.setBlock(i + 24, j + 12, k + 40, sh, ms);
		world.setBlock(i + 24, j + 12, k + 41, sh, ms);
		world.setBlock(i + 25, j + 0, k + 1, sh, ms);
		world.setBlock(i + 25, j + 0, k + 2, sh, ms);
		world.setBlock(i + 25, j + 0, k + 3, sh, ms);
		world.setBlock(i + 25, j + 0, k + 5, sh, ms);
		world.setBlock(i + 25, j + 0, k + 7, sh, ms);
		world.setBlock(i + 25, j + 0, k + 9, sh, ms);
		world.setBlock(i + 25, j + 0, k + 10, sh, ms);
		world.setBlock(i + 25, j + 0, k + 11, sh, ms);
		world.setBlock(i + 25, j + 0, k + 13, sh, ms);
		world.setBlock(i + 25, j + 0, k + 14, sh, ms);
		world.setBlock(i + 25, j + 0, k + 15, sh, ms);
		world.setBlock(i + 25, j + 0, k + 16, sh, ms);
		world.setBlock(i + 25, j + 0, k + 18, sh, ms);
		world.setBlock(i + 25, j + 0, k + 19, sh, ms);
		world.setBlock(i + 25, j + 0, k + 20, sh, ms);
		world.setBlock(i + 25, j + 0, k + 21, sh, ms);
		world.setBlock(i + 25, j + 0, k + 22, sh, ms);
		world.setBlock(i + 25, j + 0, k + 23, sh, ms);
		world.setBlock(i + 25, j + 0, k + 24, sh, ms);
		world.setBlock(i + 25, j + 0, k + 26, sh, ms);
		world.setBlock(i + 25, j + 0, k + 27, sh, ms);
		world.setBlock(i + 25, j + 0, k + 28, sh, ms);
		world.setBlock(i + 25, j + 0, k + 29, sh, ms);
		world.setBlock(i + 25, j + 0, k + 31, sh, ms);
		world.setBlock(i + 25, j + 0, k + 32, sh, ms);
		world.setBlock(i + 25, j + 0, k + 33, sh, ms);
		world.setBlock(i + 25, j + 0, k + 35, sh, ms);
		world.setBlock(i + 25, j + 0, k + 37, sh, ms);
		world.setBlock(i + 25, j + 0, k + 39, sh, ms);
		world.setBlock(i + 25, j + 0, k + 40, sh, ms);
		world.setBlock(i + 25, j + 0, k + 41, sh, ms);
		world.setBlock(i + 25, j + 1, k + 0, sh, ms);
		world.setBlock(i + 25, j + 1, k + 1, sh, ms);
		world.setBlock(i + 25, j + 1, k + 2, sh, ms);
		world.setBlock(i + 25, j + 1, k + 40, sh, ms);
		world.setBlock(i + 25, j + 1, k + 41, sh, ms);
		world.setBlock(i + 25, j + 1, k + 42, sh, ms);
		world.setBlock(i + 25, j + 2, k + 0, sh, ms);
		world.setBlock(i + 25, j + 2, k + 1, sh, ms);
		world.setBlock(i + 25, j + 2, k + 41, sh, ms);
		world.setBlock(i + 25, j + 2, k + 42, sh, ms);
		world.setBlock(i + 25, j + 3, k + 0, sh, ms);
		world.setBlock(i + 25, j + 3, k + 1, sh, ms);
		world.setBlock(i + 25, j + 3, k + 41, sh, ms);
		world.setBlock(i + 25, j + 3, k + 42, sh, ms);
		world.setBlock(i + 25, j + 4, k + 0, sh, ms);
		world.setBlock(i + 25, j + 4, k + 42, sh, ms);
		world.setBlock(i + 25, j + 8, k + 0, sh, ms);
		world.setBlock(i + 25, j + 8, k + 42, sh, ms);
		world.setBlock(i + 25, j + 9, k + 0, sh, ms);
		world.setBlock(i + 25, j + 9, k + 1, sh, ms);
		world.setBlock(i + 25, j + 9, k + 41, sh, ms);
		world.setBlock(i + 25, j + 9, k + 42, sh, ms);
		world.setBlock(i + 25, j + 10, k + 0, sh, ms);
		world.setBlock(i + 25, j + 10, k + 1, sh, ms);
		world.setBlock(i + 25, j + 10, k + 2, sh, ms);
		world.setBlock(i + 25, j + 10, k + 40, sh, ms);
		world.setBlock(i + 25, j + 10, k + 41, sh, ms);
		world.setBlock(i + 25, j + 10, k + 42, sh, ms);
		world.setBlock(i + 25, j + 11, k + 1, sh, ms);
		world.setBlock(i + 25, j + 11, k + 2, sh, ms);
		world.setBlock(i + 25, j + 11, k + 3, sh, ms);
		world.setBlock(i + 25, j + 11, k + 39, sh, ms);
		world.setBlock(i + 25, j + 11, k + 40, sh, ms);
		world.setBlock(i + 25, j + 11, k + 41, sh, ms);
		world.setBlock(i + 25, j + 12, k + 2, sh, ms);
		world.setBlock(i + 25, j + 12, k + 3, sh, ms);
		world.setBlock(i + 25, j + 12, k + 4, sh, ms);
		world.setBlock(i + 25, j + 12, k + 38, sh, ms);
		world.setBlock(i + 25, j + 12, k + 39, sh, ms);
		world.setBlock(i + 25, j + 12, k + 40, sh, ms);
		world.setBlock(i + 26, j + 0, k + 3, sh, ms);
		world.setBlock(i + 26, j + 0, k + 4, sh, ms);
		world.setBlock(i + 26, j + 0, k + 5, sh, ms);
		world.setBlock(i + 26, j + 0, k + 6, sh, ms);
		world.setBlock(i + 26, j + 0, k + 7, sh, ms);
		world.setBlock(i + 26, j + 0, k + 9, sh, ms);
		world.setBlock(i + 26, j + 0, k + 10, sh, ms);
		world.setBlock(i + 26, j + 0, k + 11, sh, ms);
		world.setBlock(i + 26, j + 0, k + 12, sh, ms);
		world.setBlock(i + 26, j + 0, k + 14, sh, ms);
		world.setBlock(i + 26, j + 0, k + 15, sh, ms);
		world.setBlock(i + 26, j + 0, k + 16, sh, ms);
		world.setBlock(i + 26, j + 0, k + 17, sh, ms);
		world.setBlock(i + 26, j + 0, k + 25, sh, ms);
		world.setBlock(i + 26, j + 0, k + 26, sh, ms);
		world.setBlock(i + 26, j + 0, k + 27, sh, ms);
		world.setBlock(i + 26, j + 0, k + 28, sh, ms);
		world.setBlock(i + 26, j + 0, k + 30, sh, ms);
