/*******************************************************************************
 * @author Reika Kalseki
 * 
 * Copyright 2017
 * 
 * All rights reserved.
 * Distribution of the software in any form is only allowed with
 * explicit, prior permission from the owner.
 ******************************************************************************/
package Reika.ChromatiCraft.World.Dimension.Structure.Locks;

import net.minecraft.block.Block;
import net.minecraft.init.Blocks;

import Reika.ChromatiCraft.Base.LockLevel;
import Reika.ChromatiCraft.Block.Dimension.Structure.Locks.BlockLockKey.LockChannel;
import Reika.ChromatiCraft.Block.Worldgen.BlockStructureShield.BlockType;
import Reika.ChromatiCraft.Registry.ChromaBlocks;
import Reika.ChromatiCraft.World.Dimension.Structure.LocksGenerator;
import Reika.DragonAPI.Instantiable.Worldgen.OriginBlockCache;

public class LocksRoomFence extends LockLevel {

	public LocksRoomFence(LocksGenerator g) {
		super(g, LockChannel.FENCE);
	}

	@Override
	public void generate(OriginBlockCache world, int x, int y, int z) {
		Block b = ChromaBlocks.STRUCTSHIELD.getBlockInstance();
		Block fnc = ChromaBlocks.LOCKFENCE.getBlockInstance();
		int ms = BlockType.STONE.metadata;
		int ml = BlockType.LIGHT.metadata;
		int mc = BlockType.CLOAK.metadata;
		this.generate1(world, x, y, z, b, ms, ml, mc, fnc);
		this.generate2(world, x, y, z, b, ms, ml, mc, fnc);
		this.generate3(world, x, y, z, b, ms, ml, mc, fnc);
		this.generate4(world, x, y, z, b, ms, ml, mc, fnc);
		this.generate5(world, x, y, z, b, ms, ml, mc, fnc);
	}

	private void generate1(OriginBlockCache world, int x, int y, int z, Block b, int ms, int ml, int mc, Block fnc) {
		world.setBlock(x+0, y+0, z+25, b, ms);
		world.setBlock(x+0, y+0, z+26, b, ms);
		world.setBlock(x+0, y+0, z+27, b, ms);
		world.setBlock(x+0, y+0, z+28, b, ms);
		world.setBlock(x+0, y+0, z+29, b, ms);
		world.setBlock(x+0, y+0, z+30, b, ms);
		world.setBlock(x+0, y+0, z+31, b, ms);
		world.setBlock(x+0, y+0, z+32, b, ms);
		world.setBlock(x+0, y+0, z+33, b, ms);
		world.setBlock(x+0, y+0, z+34, b, ms);
		world.setBlock(x+0, y+0, z+35, b, ms);
		world.setBlock(x+0, y+0, z+36, b, ms);
		world.setBlock(x+0, y+0, z+37, b, ms);
		world.setBlock(x+0, y+0, z+38, b, ms);
		world.setBlock(x+0, y+0, z+39, b, ms);
		world.setBlock(x+0, y+1, z+25, b, ms);
		world.setBlock(x+0, y+1, z+26, b, ms);
		world.setBlock(x+0, y+1, z+27, b, ms);
		world.setBlock(x+0, y+1, z+28, b, ms);
		world.setBlock(x+0, y+1, z+29, b, ms);
		world.setBlock(x+0, y+1, z+30, b, ms);
		world.setBlock(x+0, y+1, z+31, b, ms);
		world.setBlock(x+0, y+1, z+32, b, ms);
		world.setBlock(x+0, y+1, z+33, b, ms);
		world.setBlock(x+0, y+1, z+34, b, ms);
		world.setBlock(x+0, y+1, z+35, b, ms);
		world.setBlock(x+0, y+1, z+36, b, ms);
		world.setBlock(x+0, y+1, z+37, b, ms);
		world.setBlock(x+0, y+1, z+38, b, ms);
		world.setBlock(x+0, y+1, z+39, b, ms);
		world.setBlock(x+0, y+2, z+25, b, ms);
		world.setBlock(x+0, y+2, z+26, b, ms);
		world.setBlock(x+0, y+2, z+27, b, ms);
		world.setBlock(x+0, y+2, z+28, b, ms);
		world.setBlock(x+0, y+2, z+29, b, ms);
		world.setBlock(x+0, y+2, z+30, b, ml);
		world.setBlock(x+0, y+2, z+31, b, ms);
		world.setBlock(x+0, y+2, z+32, b, ms);
		world.setBlock(x+0, y+2, z+33, b, ms);
		world.setBlock(x+0, y+2, z+34, b, ms);
		world.setBlock(x+0, y+2, z+35, b, ms);
		world.setBlock(x+0, y+2, z+36, b, ms);
		world.setBlock(x+0, y+2, z+37, b, ms);
		world.setBlock(x+0, y+2, z+38, b, ml);
		world.setBlock(x+0, y+2, z+39, b, ms);
		world.setBlock(x+0, y+3, z+25, b, ms);
		world.setBlock(x+0, y+3, z+26, b, ms);
		world.setBlock(x+0, y+3, z+27, b, ms);
		world.setBlock(x+0, y+3, z+28, b, ms);
		world.setBlock(x+0, y+3, z+29, b, ms);
		world.setBlock(x+0, y+3, z+30, b, ms);
		world.setBlock(x+0, y+3, z+31, b, ms);
		world.setBlock(x+0, y+3, z+32, b, ms);
		world.setBlock(x+0, y+3, z+33, b, ms);
		world.setBlock(x+0, y+3, z+34, b, ms);
		world.setBlock(x+0, y+3, z+35, b, ms);
		world.setBlock(x+0, y+3, z+36, b, ms);
		world.setBlock(x+0, y+3, z+37, b, ms);
		world.setBlock(x+0, y+3, z+38, b, ms);
		world.setBlock(x+0, y+3, z+39, b, ms);
		world.setBlock(x+0, y+4, z+25, b, ms);
		world.setBlock(x+0, y+4, z+26, b, ms);
		world.setBlock(x+0, y+4, z+27, b, ms);
		world.setBlock(x+0, y+4, z+28, b, ms);
		world.setBlock(x+0, y+4, z+29, b, ms);
		world.setBlock(x+0, y+4, z+30, b, ms);
		world.setBlock(x+0, y+4, z+31, b, ms);
		world.setBlock(x+0, y+4, z+32, b, ms);
		world.setBlock(x+0, y+4, z+33, b, ms);
		world.setBlock(x+0, y+4, z+34, b, ms);
		world.setBlock(x+0, y+4, z+35, b, ms);
		world.setBlock(x+0, y+4, z+36, b, ms);
		world.setBlock(x+0, y+4, z+37, b, ms);
		world.setBlock(x+0, y+4, z+38, b, ms);
		world.setBlock(x+0, y+4, z+39, b, ms);
		world.setBlock(x+0, y+5, z+25, b, ms);
		world.setBlock(x+0, y+5, z+26, b, ms);
		world.setBlock(x+0, y+5, z+27, b, ms);
		world.setBlock(x+0, y+5, z+28, b, ms);
		world.setBlock(x+0, y+5, z+29, b, ms);
		world.setBlock(x+0, y+5, z+30, b, ms);
		world.setBlock(x+0, y+5, z+31, b, ms);
		world.setBlock(x+0, y+5, z+32, b, ms);
		world.setBlock(x+0, y+5, z+33, b, ms);
		world.setBlock(x+0, y+5, z+34, b, ms);
		world.setBlock(x+0, y+5, z+35, b, ms);
		world.setBlock(x+0, y+5, z+36, b, ms);
		world.setBlock(x+0, y+5, z+37, b, ms);
		world.setBlock(x+0, y+5, z+38, b, ms);
		world.setBlock(x+0, y+5, z+39, b, ms);
		world.setBlock(x+1, y+0, z+25, b, ms);
		world.setBlock(x+1, y+0, z+26, b, ms);
		world.setBlock(x+1, y+0, z+27, b, ms);
		world.setBlock(x+1, y+0, z+28, b, ms);
		world.setBlock(x+1, y+0, z+29, b, ms);
		world.setBlock(x+1, y+0, z+30, b, ms);
		world.setBlock(x+1, y+0, z+31, b, ms);
		world.setBlock(x+1, y+0, z+32, b, ms);
		world.setBlock(x+1, y+0, z+33, b, ms);
		world.setBlock(x+1, y+0, z+34, b, ms);
		world.setBlock(x+1, y+0, z+35, b, ms);
		world.setBlock(x+1, y+0, z+36, b, ms);
		world.setBlock(x+1, y+0, z+37, b, ms);
		world.setBlock(x+1, y+0, z+38, b, ms);
		world.setBlock(x+1, y+0, z+39, b, ms);
		world.setBlock(x+1, y+0, z+40, b, ms);
		world.setBlock(x+1, y+1, z+25, b, ms);
		world.setBlock(x+1, y+1, z+26, b, ms);
		world.setBlock(x+1, y+1, z+34, b, ms);
		world.setBlock(x+1, y+1, z+35, b, ms);
		world.setBlock(x+1, y+1, z+40, b, ms);
		world.setBlock(x+1, y+2, z+25, b, ms);
		world.setBlock(x+1, y+2, z+26, b, ms);
		world.setBlock(x+1, y+2, z+34, b, ms);
		world.setBlock(x+1, y+2, z+35, b, ms);
		world.setBlock(x+1, y+2, z+40, b, ms);
		world.setBlock(x+1, y+3, z+25, b, ms);
		world.setBlock(x+1, y+3, z+26, b, ms);
		world.setBlock(x+1, y+3, z+34, b, ms);
		world.setBlock(x+1, y+3, z+35, b, ms);
		world.setBlock(x+1, y+3, z+40, b, ms);
		world.setBlock(x+1, y+4, z+25, b, ms);
		world.setBlock(x+1, y+4, z+26, b, ms);
		world.setBlock(x+1, y+4, z+34, b, ms);
		world.setBlock(x+1, y+4, z+35, b, ms);
		world.setBlock(x+1, y+4, z+40, b, ms);
		world.setBlock(x+1, y+5, z+25, b, ms);
		world.setBlock(x+1, y+5, z+26, b, ms);
		world.setBlock(x+1, y+5, z+27, b, ms);
		world.setBlock(x+1, y+5, z+28, b, ms);
		world.setBlock(x+1, y+5, z+29, b, ms);
		world.setBlock(x+1, y+5, z+30, b, ms);
		world.setBlock(x+1, y+5, z+31, b, ms);
		world.setBlock(x+1, y+5, z+32, b, ms);
		world.setBlock(x+1, y+5, z+33, b, ms);
		world.setBlock(x+1, y+5, z+34, b, ms);
		world.setBlock(x+1, y+5, z+35, b, ms);
		world.setBlock(x+1, y+5, z+36, b, ms);
		world.setBlock(x+1, y+5, z+37, b, ms);
		world.setBlock(x+1, y+5, z+38, b, ms);
		world.setBlock(x+1, y+5, z+39, b, ms);
		world.setBlock(x+1, y+5, z+40, b, ms);
		world.setBlock(x+2, y+0, z+25, b, ms);
		world.setBlock(x+2, y+0, z+26, b, ms);
		world.setBlock(x+2, y+0, z+27, b, ms);
		world.setBlock(x+2, y+0, z+28, b, ms);
		world.setBlock(x+2, y+0, z+29, b, ms);
		world.setBlock(x+2, y+0, z+30, b, ms);
		world.setBlock(x+2, y+0, z+31, b, ms);
		world.setBlock(x+2, y+0, z+32, b, ms);
		world.setBlock(x+2, y+0, z+33, b, ms);
		world.setBlock(x+2, y+0, z+34, b, ms);
		world.setBlock(x+2, y+0, z+35, b, ms);
		world.setBlock(x+2, y+0, z+36, b, ms);
		world.setBlock(x+2, y+0, z+37, b, ms);
		world.setBlock(x+2, y+0, z+38, b, ms);
		world.setBlock(x+2, y+0, z+39, b, ms);
		world.setBlock(x+2, y+0, z+40, b, ms);
		world.setBlock(x+2, y+0, z+41, b, ms);
		world.setBlock(x+2, y+1, z+25, b, ms);
		this.generateLock(x+2, y+1, z+35, LockColor.GREEN);
		world.setBlock(x+2, y+1, z+41, b, ms);
		world.setBlock(x+2, y+2, z+25, b, ms);
		this.generateLock(x+2, y+2, z+35, LockColor.GREEN);
		world.setBlock(x+2, y+2, z+41, b, ms);
		world.setBlock(x+2, y+3, z+25, b, ms);
		this.generateLock(x+2, y+3, z+35, LockColor.GREEN);
		world.setBlock(x+2, y+3, z+41, b, ms);
		world.setBlock(x+2, y+4, z+25, b, ms);
		world.setBlock(x+2, y+4, z+34, b, ms);
		world.setBlock(x+2, y+4, z+35, b, ms);
		world.setBlock(x+2, y+4, z+41, b, ms);
		world.setBlock(x+2, y+5, z+25, b, ms);
		world.setBlock(x+2, y+5, z+26, b, ms);
		world.setBlock(x+2, y+5, z+27, b, ms);
		world.setBlock(x+2, y+5, z+28, b, ms);
		world.setBlock(x+2, y+5, z+29, b, ms);
		world.setBlock(x+2, y+5, z+30, b, ms);
		world.setBlock(x+2, y+5, z+31, b, ms);
		world.setBlock(x+2, y+5, z+32, b, ms);
		world.setBlock(x+2, y+5, z+33, b, ms);
		world.setBlock(x+2, y+5, z+34, b, ms);
		world.setBlock(x+2, y+5, z+35, b, ms);
		world.setBlock(x+2, y+5, z+36, b, ms);
		world.setBlock(x+2, y+5, z+37, b, ms);
		world.setBlock(x+2, y+5, z+38, b, ms);
		world.setBlock(x+2, y+5, z+39, b, ms);
		world.setBlock(x+2, y+5, z+40, b, ms);
		world.setBlock(x+2, y+5, z+41, b, ms);
		world.setBlock(x+3, y+0, z+25, b, ms);
		world.setBlock(x+3, y+0, z+26, b, ms);
		world.setBlock(x+3, y+0, z+27, b, ms);
		this.generateRune(x+3, y+0, z+28, LockColor.YELLOW);
		world.setBlock(x+3, y+0, z+29, b, ms);
		world.setBlock(x+3, y+0, z+30, b, ms);
		world.setBlock(x+3, y+0, z+31, b, ms);
		this.generateRune(x+3, y+0, z+32, LockColor.PURPLE);
		world.setBlock(x+3, y+0, z+33, b, ms);
		world.setBlock(x+3, y+0, z+34, b, ms);
		world.setBlock(x+3, y+0, z+35, b, ms);
		world.setBlock(x+3, y+0, z+36, b, ms);
		world.setBlock(x+3, y+0, z+37, b, ms);
		world.setBlock(x+3, y+0, z+38, b, ms);
		world.setBlock(x+3, y+0, z+39, b, ms);
		world.setBlock(x+3, y+0, z+40, b, ms);
		world.setBlock(x+3, y+0, z+41, b, ms);
		world.setBlock(x+3, y+0, z+42, b, ms);
		world.setBlock(x+3, y+0, z+43, b, ms);
		world.setBlock(x+3, y+1, z+25, b, ms);
		this.generateLock(x+3, y+1, z+35, LockColor.GREEN);
		world.setBlock(x+3, y+1, z+41, b, ms);
		world.setBlock(x+3, y+1, z+42, b, ms);
		world.setBlock(x+3, y+1, z+43, b, ms);
		world.setBlock(x+3, y+2, z+25, b, ml);
		this.generateLock(x+3, y+2, z+35, LockColor.GREEN);
		world.setBlock(x+3, y+2, z+41, b, ms);
		world.setBlock(x+3, y+2, z+42, b, ms);
		world.setBlock(x+3, y+2, z+43, b, ms);
		world.setBlock(x+3, y+3, z+25, b, ms);
		this.generateLock(x+3, y+3, z+35, LockColor.GREEN);
		world.setBlock(x+3, y+3, z+41, b, ms);
		world.setBlock(x+3, y+3, z+42, b, ms);
		world.setBlock(x+3, y+3, z+43, b, ms);
		world.setBlock(x+3, y+4, z+25, b, ms);
		world.setBlock(x+3, y+4, z+34, b, ml);
		world.setBlock(x+3, y+4, z+35, b, ms);
		world.setBlock(x+3, y+4, z+41, b, ms);
		world.setBlock(x+3, y+5, z+25, b, ms);
		world.setBlock(x+3, y+5, z+26, b, ms);
		world.setBlock(x+3, y+5, z+27, b, ms);
		world.setBlock(x+3, y+5, z+28, b, ms);
		world.setBlock(x+3, y+5, z+29, b, ms);
		world.setBlock(x+3, y+5, z+30, b, ms);
		world.setBlock(x+3, y+5, z+31, b, ms);
		world.setBlock(x+3, y+5, z+32, b, ms);
		world.setBlock(x+3, y+5, z+33, b, ms);
		world.setBlock(x+3, y+5, z+34, b, ms);
		world.setBlock(x+3, y+5, z+35, b, ms);
		world.setBlock(x+3, y+5, z+36, b, ms);
		world.setBlock(x+3, y+5, z+37, b, ms);
		world.setBlock(x+3, y+5, z+38, b, ms);
		world.setBlock(x+3, y+5, z+39, b, ms);
		world.setBlock(x+3, y+5, z+40, b, ms);
		world.setBlock(x+3, y+5, z+41, b, ms);
		world.setBlock(x+4, y+0, z+25, b, ms);
		world.setBlock(x+4, y+0, z+26, b, ms);
		world.setBlock(x+4, y+0, z+27, b, ms);
		world.setBlock(x+4, y+0, z+28, b, ms);
		world.setBlock(x+4, y+0, z+29, b, ms);
		world.setBlock(x+4, y+0, z+30, b, ms);
		world.setBlock(x+4, y+0, z+31, b, ms);
		world.setBlock(x+4, y+0, z+32, b, ms);
		world.setBlock(x+4, y+0, z+33, b, ms);
		world.setBlock(x+4, y+0, z+34, b, ms);
		world.setBlock(x+4, y+0, z+35, b, ms);
		world.setBlock(x+4, y+0, z+36, b, ms);
		world.setBlock(x+4, y+0, z+37, b, ms);
		world.setBlock(x+4, y+0, z+38, b, ms);
		world.setBlock(x+4, y+0, z+39, b, ms);
		world.setBlock(x+4, y+0, z+40, b, ms);
		world.setBlock(x+4, y+0, z+41, b, ms);
		world.setBlock(x+4, y+0, z+42, b, ms);
		world.setBlock(x+4, y+0, z+43, b, ms);
		world.setBlock(x+4, y+1, z+25, b, ms);
		this.generateLock(x+4, y+1, z+35, LockColor.GREEN);
		world.setBlock(x+4, y+1, z+41, b, ms);
		world.setBlock(x+4, y+1, z+42, b, ms);
		world.setBlock(x+4, y+1, z+43, b, ms);
		world.setBlock(x+4, y+2, z+25, b, ms);
		this.generateLock(x+4, y+2, z+35, LockColor.GREEN);
		this.generateRune(x+4, y+2, z+42, LockColor.BLUE);
		world.setBlock(x+4, y+2, z+43, b, ms);
		world.setBlock(x+4, y+3, z+25, b, ms);
		this.generateLock(x+4, y+3, z+35, LockColor.GREEN);
		world.setBlock(x+4, y+3, z+41, b, ms);
		world.setBlock(x+4, y+3, z+42, b, ms);
		world.setBlock(x+4, y+3, z+43, b, ms);
		world.setBlock(x+4, y+4, z+25, b, ms);
		world.setBlock(x+4, y+4, z+34, b, ms);
		world.setBlock(x+4, y+4, z+35, b, ms);
		world.setBlock(x+4, y+4, z+41, b, ms);
		world.setBlock(x+4, y+5, z+25, b, ms);
		world.setBlock(x+4, y+5, z+26, b, ms);
		world.setBlock(x+4, y+5, z+27, b, ms);
		world.setBlock(x+4, y+5, z+28, b, ms);
		world.setBlock(x+4, y+5, z+29, b, ms);
		world.setBlock(x+4, y+5, z+30, b, ms);
		world.setBlock(x+4, y+5, z+31, b, ms);
		world.setBlock(x+4, y+5, z+32, b, ms);
		world.setBlock(x+4, y+5, z+33, b, ms);
		world.setBlock(x+4, y+5, z+34, b, ms);
		world.setBlock(x+4, y+5, z+35, b, ms);
		world.setBlock(x+4, y+5, z+36, b, ms);
		world.setBlock(x+4, y+5, z+37, b, ms);
		world.setBlock(x+4, y+5, z+38, b, ms);
		world.setBlock(x+4, y+5, z+39, b, ms);
		world.setBlock(x+4, y+5, z+40, b, ms);
		world.setBlock(x+4, y+5, z+41, b, ms);
		world.setBlock(x+5, y+0, z+25, b, ms);
		world.setBlock(x+5, y+0, z+26, b, ms);
		world.setBlock(x+5, y+0, z+27, b, ms);
		world.setBlock(x+5, y+0, z+28, b, ms);
		world.setBlock(x+5, y+0, z+29, b, ms);
		world.setBlock(x+5, y+0, z+30, b, ms);
		world.setBlock(x+5, y+0, z+31, b, ms);
		world.setBlock(x+5, y+0, z+32, b, ms);
		world.setBlock(x+5, y+0, z+33, b, ms);
		world.setBlock(x+5, y+0, z+34, b, ms);
		world.setBlock(x+5, y+0, z+35, b, ms);
		world.setBlock(x+5, y+0, z+36, b, ms);
		world.setBlock(x+5, y+0, z+37, b, ms);
		world.setBlock(x+5, y+0, z+38, b, ms);
		world.setBlock(x+5, y+0, z+39, b, ms);
		world.setBlock(x+5, y+0, z+40, b, ms);
		world.setBlock(x+5, y+0, z+41, b, ms);
		world.setBlock(x+5, y+0, z+42, b, ms);
		world.setBlock(x+5, y+0, z+43, b, ms);
		world.setBlock(x+5, y+1, z+25, b, ms);
		world.setBlock(x+5, y+1, z+26, b, ms);
		world.setBlock(x+5, y+1, z+34, b, ms);
		world.setBlock(x+5, y+1, z+35, b, ms);
		world.setBlock(x+5, y+1, z+41, b, ms);
		world.setBlock(x+5, y+1, z+42, b, ms);
		world.setBlock(x+5, y+1, z+43, b, ms);
		world.setBlock(x+5, y+2, z+25, b, ms);
		world.setBlock(x+5, y+2, z+26, b, ms);
		world.setBlock(x+5, y+2, z+34, b, ms);
		world.setBlock(x+5, y+2, z+35, b, ms);
		world.setBlock(x+5, y+2, z+41, b, ms);
		world.setBlock(x+5, y+2, z+42, b, ms);
		world.setBlock(x+5, y+2, z+43, b, ms);
		world.setBlock(x+5, y+3, z+25, b, ms);
		world.setBlock(x+5, y+3, z+26, b, ms);
		world.setBlock(x+5, y+3, z+34, b, ms);
		world.setBlock(x+5, y+3, z+35, b, ms);
		world.setBlock(x+5, y+3, z+41, b, ms);
		world.setBlock(x+5, y+3, z+42, b, ms);
		world.setBlock(x+5, y+3, z+43, b, ms);
		world.setBlock(x+5, y+4, z+25, b, ms);
		world.setBlock(x+5, y+4, z+26, b, ms);
		world.setBlock(x+5, y+4, z+34, b, ms);
		world.setBlock(x+5, y+4, z+35, b, ms);
		world.setBlock(x+5, y+4, z+41, b, ml);
		world.setBlock(x+5, y+5, z+25, b, ms);
		world.setBlock(x+5, y+5, z+26, b, ms);
		world.setBlock(x+5, y+5, z+27, b, ms);
		world.setBlock(x+5, y+5, z+28, b, ms);
		world.setBlock(x+5, y+5, z+29, b, ms);
		world.setBlock(x+5, y+5, z+30, b, ms);
		world.setBlock(x+5, y+5, z+31, b, ms);
		world.setBlock(x+5, y+5, z+32, b, ms);
		world.setBlock(x+5, y+5, z+33, b, ms);
		world.setBlock(x+5, y+5, z+34, b, ms);
		world.setBlock(x+5, y+5, z+35, b, ms);
		world.setBlock(x+5, y+5, z+36, b, ms);
		world.setBlock(x+5, y+5, z+37, b, ms);
		world.setBlock(x+5, y+5, z+38, b, ms);
		world.setBlock(x+5, y+5, z+39, b, ms);
		world.setBlock(x+5, y+5, z+40, b, ms);
		world.setBlock(x+5, y+5, z+41, b, ms);
		world.setBlock(x+6, y+0, z+5, b, ms);
		world.setBlock(x+6, y+0, z+6, b, ms);
		world.setBlock(x+6, y+0, z+7, b, ms);
		world.setBlock(x+6, y+0, z+8, b, ms);
		world.setBlock(x+6, y+0, z+9, b, ms);
		world.setBlock(x+6, y+0, z+10, b, ms);
		world.setBlock(x+6, y+0, z+11, b, ms);
		world.setBlock(x+6, y+0, z+12, b, ms);
		world.setBlock(x+6, y+0, z+13, b, ms);
		world.setBlock(x+6, y+0, z+14, b, ms);
		world.setBlock(x+6, y+0, z+15, b, ms);
		world.setBlock(x+6, y+0, z+16, b, ms);
		world.setBlock(x+6, y+0, z+17, b, ms);
		world.setBlock(x+6, y+0, z+18, b, ms);
		world.setBlock(x+6, y+0, z+19, b, ms);
		world.setBlock(x+6, y+0, z+20, b, ms);
		world.setBlock(x+6, y+0, z+21, b, ms);
		world.setBlock(x+6, y+0, z+22, b, ms);
		world.setBlock(x+6, y+0, z+23, b, ms);
		world.setBlock(x+6, y+0, z+24, b, ms);
		world.setBlock(x+6, y+0, z+25, b, ms);
		world.setBlock(x+6, y+0, z+26, b, ms);
		world.setBlock(x+6, y+0, z+27, b, ms);
		world.setBlock(x+6, y+0, z+28, b, ms);
		world.setBlock(x+6, y+0, z+29, b, ms);
		world.setBlock(x+6, y+0, z+30, b, ms);
		world.setBlock(x+6, y+0, z+31, b, ms);
		world.setBlock(x+6, y+0, z+32, b, ms);
		world.setBlock(x+6, y+0, z+33, b, ms);
		world.setBlock(x+6, y+0, z+34, b, ms);
		world.setBlock(x+6, y+0, z+35, b, ms);
		world.setBlock(x+6, y+0, z+36, b, ms);
		world.setBlock(x+6, y+0, z+37, b, ms);
		world.setBlock(x+6, y+0, z+38, b, ms);
		world.setBlock(x+6, y+0, z+39, b, ms);
		world.setBlock(x+6, y+0, z+40, b, ms);
		world.setBlock(x+6, y+0, z+41, b, ms);
		world.setBlock(x+6, y+0, z+42, b, ms);
		world.setBlock(x+6, y+0, z+43, b, ms);
		world.setBlock(x+6, y+0, z+44, b, ms);
		world.setBlock(x+6, y+1, z+5, b, ms);
		world.setBlock(x+6, y+1, z+6, b, ms);
		world.setBlock(x+6, y+1, z+7, b, ms);
		world.setBlock(x+6, y+1, z+8, b, ms);
		world.setBlock(x+6, y+1, z+9, b, ms);
		world.setBlock(x+6, y+1, z+10, b, ms);
		world.setBlock(x+6, y+1, z+11, b, ms);
		world.setBlock(x+6, y+1, z+12, b, ms);
		world.setBlock(x+6, y+1, z+13, b, ms);
		world.setBlock(x+6, y+1, z+14, b, ms);
		world.setBlock(x+6, y+1, z+15, b, ms);
		world.setBlock(x+6, y+1, z+16, b, ms);
		world.setBlock(x+6, y+1, z+17, b, ms);
		world.setBlock(x+6, y+1, z+18, b, ms);
		world.setBlock(x+6, y+1, z+19, b, ms);
		world.setBlock(x+6, y+1, z+20, b, ms);
		world.setBlock(x+6, y+1, z+21, b, ms);
		world.setBlock(x+6, y+1, z+22, b, ms);
		world.setBlock(x+6, y+1, z+23, b, ms);
		world.setBlock(x+6, y+1, z+24, b, ms);
		world.setBlock(x+6, y+1, z+25, b, ms);
		world.setBlock(x+6, y+1, z+26, b, ms);
		world.setBlock(x+6, y+1, z+27, b, ms);
		world.setBlock(x+6, y+1, z+28, b, ms);
		world.setBlock(x+6, y+1, z+29, b, ms);
		world.setBlock(x+6, y+1, z+30, b, ms);
		world.setBlock(x+6, y+1, z+31, b, ms);
		world.setBlock(x+6, y+1, z+32, b, ms);
		world.setBlock(x+6, y+1, z+33, b, ms);
		world.setBlock(x+6, y+1, z+34, b, ms);
		world.setBlock(x+6, y+1, z+35, b, ms);
		world.setBlock(x+6, y+1, z+36, b, ms);
		world.setBlock(x+6, y+1, z+41, b, ms);
		world.setBlock(x+6, y+1, z+42, b, ms);
		world.setBlock(x+6, y+1, z+43, b, ms);
		world.setBlock(x+6, y+1, z+44, b, ms);
		world.setBlock(x+6, y+2, z+5, b, ms);
		world.setBlock(x+6, y+2, z+6, b, ms);
		world.setBlock(x+6, y+2, z+7, b, ms);
		world.setBlock(x+6, y+2, z+8, b, ml);
		world.setBlock(x+6, y+2, z+9, b, ms);
		world.setBlock(x+6, y+2, z+10, b, ms);
		world.setBlock(x+6, y+2, z+11, b, ms);
		world.setBlock(x+6, y+2, z+12, b, ms);
		world.setBlock(x+6, y+2, z+13, b, ml);
		world.setBlock(x+6, y+2, z+14, b, ms);
		world.setBlock(x+6, y+2, z+15, b, ms);
		world.setBlock(x+6, y+2, z+16, b, ms);
		world.setBlock(x+6, y+2, z+17, b, ms);
		world.setBlock(x+6, y+2, z+18, b, ms);
		world.setBlock(x+6, y+2, z+19, b, ml);
		world.setBlock(x+6, y+2, z+20, b, ms);
		world.setBlock(x+6, y+2, z+21, b, ms);
		world.setBlock(x+6, y+2, z+22, b, ms);
		world.setBlock(x+6, y+2, z+23, b, ms);
		world.setBlock(x+6, y+2, z+24, b, ml);
		world.setBlock(x+6, y+2, z+25, b, ms);
		world.setBlock(x+6, y+2, z+26, b, ms);
		world.setBlock(x+6, y+2, z+27, b, ms);
		world.setBlock(x+6, y+2, z+28, b, ms);
		world.setBlock(x+6, y+2, z+29, b, ml);
		world.setBlock(x+6, y+2, z+30, b, ms);
		world.setBlock(x+6, y+2, z+31, b, ms);
		world.setBlock(x+6, y+2, z+32, b, ms);
		world.setBlock(x+6, y+2, z+33, b, ms);
		world.setBlock(x+6, y+2, z+34, b, ml);
		world.setBlock(x+6, y+2, z+35, b, ms);
		world.setBlock(x+6, y+2, z+36, b, ml);
		this.generateRune(x+6, y+2, z+42, LockColor.RED);
		this.generateRune(x+6, y+2, z+43, LockColor.PURPLE);
		world.setBlock(x+6, y+2, z+44, b, ms);
		world.setBlock(x+6, y+3, z+5, b, ms);
		world.setBlock(x+6, y+3, z+6, b, ms);
		world.setBlock(x+6, y+3, z+7, b, ms);
		world.setBlock(x+6, y+3, z+8, b, ms);
		world.setBlock(x+6, y+3, z+9, b, ms);
		world.setBlock(x+6, y+3, z+10, b, ms);
		world.setBlock(x+6, y+3, z+11, b, ms);
		world.setBlock(x+6, y+3, z+12, b, ms);
		world.setBlock(x+6, y+3, z+13, b, ms);
		world.setBlock(x+6, y+3, z+14, b, ms);
		world.setBlock(x+6, y+3, z+15, b, ms);
		world.setBlock(x+6, y+3, z+16, b, ms);
		world.setBlock(x+6, y+3, z+17, b, ms);
		world.setBlock(x+6, y+3, z+18, b, ms);
		world.setBlock(x+6, y+3, z+19, b, ms);
		world.setBlock(x+6, y+3, z+20, b, ms);
		world.setBlock(x+6, y+3, z+21, b, ms);
		world.setBlock(x+6, y+3, z+22, b, ms);
		world.setBlock(x+6, y+3, z+23, b, ms);
		world.setBlock(x+6, y+3, z+24, b, ms);
		world.setBlock(x+6, y+3, z+25, b, ms);
		world.setBlock(x+6, y+3, z+26, b, ms);
		world.setBlock(x+6, y+3, z+27, b, ms);
		world.setBlock(x+6, y+3, z+28, b, ms);
		world.setBlock(x+6, y+3, z+29, b, ms);
		world.setBlock(x+6, y+3, z+30, b, ms);
		world.setBlock(x+6, y+3, z+31, b, ms);
		world.setBlock(x+6, y+3, z+32, b, ms);
		world.setBlock(x+6, y+3, z+33, b, ms);
		world.setBlock(x+6, y+3, z+34, b, ms);
		world.setBlock(x+6, y+3, z+35, b, ms);
		world.setBlock(x+6, y+3, z+36, b, ms);
		world.setBlock(x+6, y+3, z+41, b, ms);
		world.setBlock(x+6, y+3, z+42, b, ms);
		world.setBlock(x+6, y+3, z+43, b, ms);
		world.setBlock(x+6, y+3, z+44, b, ms);
		world.setBlock(x+6, y+4, z+5, b, ms);
		world.setBlock(x+6, y+4, z+6, b, ms);
		world.setBlock(x+6, y+4, z+7, b, ms);
		world.setBlock(x+6, y+4, z+8, b, ms);
		world.setBlock(x+6, y+4, z+9, b, ms);
		world.setBlock(x+6, y+4, z+10, b, ms);
		world.setBlock(x+6, y+4, z+11, b, ms);
		world.setBlock(x+6, y+4, z+12, b, ms);
		world.setBlock(x+6, y+4, z+13, b, ms);
		world.setBlock(x+6, y+4, z+14, b, ms);
		world.setBlock(x+6, y+4, z+15, b, ms);
		world.setBlock(x+6, y+4, z+16, b, ms);
		world.setBlock(x+6, y+4, z+17, b, ms);
		world.setBlock(x+6, y+4, z+18, b, ms);
		world.setBlock(x+6, y+4, z+19, b, ms);
		world.setBlock(x+6, y+4, z+20, b, ms);
		world.setBlock(x+6, y+4, z+21, b, ms);
		world.setBlock(x+6, y+4, z+22, b, ms);
		world.setBlock(x+6, y+4, z+23, b, ms);
		world.setBlock(x+6, y+4, z+24, b, ms);
		world.setBlock(x+6, y+4, z+25, b, ms);
		world.setBlock(x+6, y+4, z+26, b, ms);
		world.setBlock(x+6, y+4, z+27, b, ms);
		world.setBlock(x+6, y+4, z+28, b, ms);
		world.setBlock(x+6, y+4, z+29, b, ms);
		world.setBlock(x+6, y+4, z+30, b, ms);
		world.setBlock(x+6, y+4, z+31, b, ms);
		world.setBlock(x+6, y+4, z+32, b, ms);
		world.setBlock(x+6, y+4, z+33, b, ms);
		world.setBlock(x+6, y+4, z+34, b, ms);
		world.setBlock(x+6, y+4, z+35, b, ms);
		world.setBlock(x+6, y+4, z+36, b, ms);
		world.setBlock(x+6, y+4, z+41, b, ms);
		world.setBlock(x+6, y+5, z+5, b, ms);
		world.setBlock(x+6, y+5, z+6, b, ms);
		world.setBlock(x+6, y+5, z+7, b, ms);
		world.setBlock(x+6, y+5, z+8, b, ms);
		world.setBlock(x+6, y+5, z+9, b, ms);
		world.setBlock(x+6, y+5, z+10, b, ms);
		world.setBlock(x+6, y+5, z+11, b, ms);
		world.setBlock(x+6, y+5, z+12, b, ms);
		world.setBlock(x+6, y+5, z+13, b, ms);
		world.setBlock(x+6, y+5, z+14, b, ms);
		world.setBlock(x+6, y+5, z+15, b, ms);
		world.setBlock(x+6, y+5, z+16, b, ms);
		world.setBlock(x+6, y+5, z+17, b, ms);
		world.setBlock(x+6, y+5, z+18, b, ms);
		world.setBlock(x+6, y+5, z+19, b, ms);
		world.setBlock(x+6, y+5, z+20, b, ms);
		world.setBlock(x+6, y+5, z+21, b, ms);
		world.setBlock(x+6, y+5, z+22, b, ms);
		world.setBlock(x+6, y+5, z+23, b, ms);
		world.setBlock(x+6, y+5, z+24, b, ms);
		world.setBlock(x+6, y+5, z+25, b, ms);
		world.setBlock(x+6, y+5, z+26, b, ms);
		world.setBlock(x+6, y+5, z+27, b, ms);
		world.setBlock(x+6, y+5, z+28, b, ms);
		world.setBlock(x+6, y+5, z+29, b, ms);
		world.setBlock(x+6, y+5, z+30, b, ms);
		world.setBlock(x+6, y+5, z+31, b, ms);
		world.setBlock(x+6, y+5, z+32, b, ms);
		world.setBlock(x+6, y+5, z+33, b, ms);
		world.setBlock(x+6, y+5, z+34, b, ms);
		world.setBlock(x+6, y+5, z+35, b, ms);
		world.setBlock(x+6, y+5, z+36, b, ms);
		world.setBlock(x+6, y+5, z+37, b, ms);
		world.setBlock(x+6, y+5, z+38, b, ms);
		world.setBlock(x+6, y+5, z+39, b, ms);
		world.setBlock(x+6, y+5, z+40, b, ms);
		world.setBlock(x+6, y+5, z+41, b, ms);
		world.setBlock(x+7, y+0, z+4, b, ms);
		world.setBlock(x+7, y+0, z+5, b, ms);
		world.setBlock(x+7, y+0, z+6, b, ms);
		world.setBlock(x+7, y+0, z+7, b, ms);
		world.setBlock(x+7, y+0, z+8, b, ms);
		world.setBlock(x+7, y+0, z+9, b, ms);
		world.setBlock(x+7, y+0, z+10, b, ms);
		world.setBlock(x+7, y+0, z+11, b, ms);
		world.setBlock(x+7, y+0, z+12, b, ms);
		world.setBlock(x+7, y+0, z+13, b, ms);
		world.setBlock(x+7, y+0, z+14, b, ms);
		world.setBlock(x+7, y+0, z+15, b, ms);
		world.setBlock(x+7, y+0, z+16, b, ms);
		world.setBlock(x+7, y+0, z+17, b, ms);
		world.setBlock(x+7, y+0, z+18, b, ms);
		world.setBlock(x+7, y+0, z+19, b, ms);
		world.setBlock(x+7, y+0, z+20, b, ms);
		world.setBlock(x+7, y+0, z+21, b, ms);
		world.setBlock(x+7, y+0, z+22, b, ms);
		world.setBlock(x+7, y+0, z+23, b, ms);
		world.setBlock(x+7, y+0, z+24, b, ms);
		world.setBlock(x+7, y+0, z+25, b, ms);
		world.setBlock(x+7, y+0, z+26, b, ms);
		world.setBlock(x+7, y+0, z+27, b, ms);
		world.setBlock(x+7, y+0, z+28, b, ms);
		world.setBlock(x+7, y+0, z+29, b, ms);
		world.setBlock(x+7, y+0, z+30, b, ms);
		world.setBlock(x+7, y+0, z+31, b, ms);
		world.setBlock(x+7, y+0, z+32, b, ms);
		world.setBlock(x+7, y+0, z+33, b, ms);
		world.setBlock(x+7, y+0, z+34, b, ms);
		world.setBlock(x+7, y+0, z+35, b, ms);
		world.setBlock(x+7, y+0, z+36, b, ms);
		world.setBlock(x+7, y+0, z+37, b, ms);
		world.setBlock(x+7, y+0, z+38, b, ms);
		world.setBlock(x+7, y+0, z+39, b, ms);
		world.setBlock(x+7, y+0, z+40, b, ms);
		world.setBlock(x+7, y+0, z+41, b, ms);
		world.setBlock(x+7, y+0, z+42, b, ms);
		world.setBlock(x+7, y+0, z+43, b, ms);
		world.setBlock(x+7, y+0, z+44, b, ms);
		world.setBlock(x+7, y+0, z+45, b, ms);
		world.setBlock(x+7, y+1, z+4, b, ms);
		world.setBlock(x+7, y+1, z+5, b, ms);
		world.setBlock(x+7, y+1, z+17, b, ms);
		world.setBlock(x+7, y+1, z+36, b, ms);
		world.setBlock(x+7, y+1, z+37, b, ms);
		world.setBlock(x+7, y+1, z+41, b, ms);
		world.setBlock(x+7, y+1, z+42, b, ms);
		world.setBlock(x+7, y+1, z+43, b, ms);
		world.setBlock(x+7, y+1, z+44, b, ms);
		world.setBlock(x+7, y+1, z+45, b, ms);
		world.setBlock(x+7, y+2, z+4, b, ms);
		world.setBlock(x+7, y+2, z+5, b, ms);
		world.setBlock(x+7, y+2, z+17, b, ms);
		world.setBlock(x+7, y+2, z+36, b, ms);
		world.setBlock(x+7, y+2, z+37, b, ms);
		world.setBlock(x+7, y+2, z+41, b, ms);
		world.setBlock(x+7, y+2, z+42, b, ms);
		world.setBlock(x+7, y+2, z+44, b, ms);
		world.setBlock(x+7, y+2, z+45, b, ms);
		world.setBlock(x+7, y+3, z+4, b, ms);
		world.setBlock(x+7, y+3, z+5, b, ms);
		world.setBlock(x+7, y+3, z+17, b, ms);
		world.setBlock(x+7, y+3, z+36, b, ms);
		world.setBlock(x+7, y+3, z+37, b, ms);
		world.setBlock(x+7, y+3, z+41, b, ms);
		world.setBlock(x+7, y+3, z+42, b, ms);
		world.setBlock(x+7, y+3, z+43, b, ms);
		world.setBlock(x+7, y+3, z+44, b, ms);
		world.setBlock(x+7, y+3, z+45, b, ms);
		world.setBlock(x+7, y+4, z+4, b, ms);
		world.setBlock(x+7, y+4, z+5, b, ms);
		world.setBlock(x+7, y+4, z+17, b, ms);
		world.setBlock(x+7, y+4, z+36, b, ms);
		world.setBlock(x+7, y+4, z+37, b, ms);
		world.setBlock(x+7, y+4, z+41, b, ms);
		world.setBlock(x+7, y+4, z+42, b, ms);
		world.setBlock(x+7, y+4, z+43, b, ml);
		world.setBlock(x+7, y+4, z+44, b, ms);
		world.setBlock(x+7, y+4, z+45, b, ms);
		world.setBlock(x+7, y+5, z+4, b, ms);
		world.setBlock(x+7, y+5, z+5, b, ms);
		world.setBlock(x+7, y+5, z+6, b, ms);
		world.setBlock(x+7, y+5, z+7, b, ms);
		world.setBlock(x+7, y+5, z+8, b, ms);
		world.setBlock(x+7, y+5, z+9, b, ms);
		world.setBlock(x+7, y+5, z+10, b, ms);
		world.setBlock(x+7, y+5, z+11, b, ms);
		world.setBlock(x+7, y+5, z+12, b, ms);
		world.setBlock(x+7, y+5, z+13, b, ms);
		world.setBlock(x+7, y+5, z+14, b, ms);
		world.setBlock(x+7, y+5, z+15, b, ms);
		world.setBlock(x+7, y+5, z+16, b, ms);
		world.setBlock(x+7, y+5, z+17, b, ms);
		world.setBlock(x+7, y+5, z+18, b, ms);
		world.setBlock(x+7, y+5, z+19, b, ms);
		world.setBlock(x+7, y+5, z+20, b, ms);
		world.setBlock(x+7, y+5, z+21, b, ms);
		world.setBlock(x+7, y+5, z+22, b, ms);
		world.setBlock(x+7, y+5, z+23, b, ms);
		world.setBlock(x+7, y+5, z+24, b, ms);
		world.setBlock(x+7, y+5, z+25, b, ms);
		world.setBlock(x+7, y+5, z+26, b, ms);
		world.setBlock(x+7, y+5, z+27, b, ms);
		world.setBlock(x+7, y+5, z+28, b, ms);
		world.setBlock(x+7, y+5, z+29, b, ms);
		world.setBlock(x+7, y+5, z+30, b, ms);
		world.setBlock(x+7, y+5, z+31, b, ms);
		world.setBlock(x+7, y+5, z+32, b, ms);
		world.setBlock(x+7, y+5, z+33, b, ms);
		world.setBlock(x+7, y+5, z+34, b, ms);
		world.setBlock(x+7, y+5, z+35, b, ms);
		world.setBlock(x+7, y+5, z+36, b, ms);
		world.setBlock(x+7, y+5, z+37, b, ms);
		world.setBlock(x+7, y+5, z+38, b, ms);
		world.setBlock(x+7, y+5, z+39, b, ms);
		world.setBlock(x+7, y+5, z+40, b, ms);
		world.setBlock(x+7, y+5, z+41, b, ms);
		world.setBlock(x+7, y+5, z+42, b, ms);
		world.setBlock(x+7, y+5, z+43, b, ms);
		world.setBlock(x+7, y+5, z+44, b, ms);
		world.setBlock(x+7, y+5, z+45, b, ms);
		world.setBlock(x+8, y+0, z+3, b, ms);
		world.setBlock(x+8, y+0, z+4, b, ms);
		world.setBlock(x+8, y+0, z+5, b, ms);
		world.setBlock(x+8, y+0, z+6, b, ms);
		world.setBlock(x+8, y+0, z+7, b, ms);
		world.setBlock(x+8, y+0, z+8, b, ms);
		world.setBlock(x+8, y+0, z+9, b, ms);
		world.setBlock(x+8, y+0, z+10, b, ms);
		world.setBlock(x+8, y+0, z+11, b, ms);
		world.setBlock(x+8, y+0, z+12, b, ms);
		world.setBlock(x+8, y+0, z+13, b, ms);
		world.setBlock(x+8, y+0, z+14, b, ms);
		world.setBlock(x+8, y+0, z+15, b, ms);
		world.setBlock(x+8, y+0, z+16, b, ms);
		world.setBlock(x+8, y+0, z+17, b, ms);
		world.setBlock(x+8, y+0, z+18, b, ms);
		world.setBlock(x+8, y+0, z+19, b, ms);
		world.setBlock(x+8, y+0, z+20, b, ms);
		world.setBlock(x+8, y+0, z+21, b, ms);
		world.setBlock(x+8, y+0, z+22, b, ms);
		world.setBlock(x+8, y+0, z+23, b, ms);
		world.setBlock(x+8, y+0, z+24, b, ms);
		world.setBlock(x+8, y+0, z+25, b, ms);
		world.setBlock(x+8, y+0, z+26, b, ms);
		world.setBlock(x+8, y+0, z+27, b, ms);
		world.setBlock(x+8, y+0, z+28, b, ms);
		world.setBlock(x+8, y+0, z+29, b, ms);
		world.setBlock(x+8, y+0, z+30, b, ms);
		world.setBlock(x+8, y+0, z+31, b, ms);
		world.setBlock(x+8, y+0, z+32, b, ms);
		world.setBlock(x+8, y+0, z+33, b, ms);
		world.setBlock(x+8, y+0, z+34, b, ms);
		world.setBlock(x+8, y+0, z+35, b, ms);
		world.setBlock(x+8, y+0, z+36, b, ms);
		world.setBlock(x+8, y+0, z+37, b, ms);
		world.setBlock(x+8, y+0, z+38, b, ms);
		world.setBlock(x+8, y+0, z+39, b, ms);
		world.setBlock(x+8, y+0, z+40, b, ms);
		world.setBlock(x+8, y+0, z+41, b, ms);
		world.setBlock(x+8, y+0, z+42, b, ms);
		world.setBlock(x+8, y+0, z+43, b, ms);
		world.setBlock(x+8, y+0, z+44, b, ms);
		world.setBlock(x+8, y+0, z+45, b, ms);
		world.setBlock(x+8, y+0, z+46, b, ms);
		world.setBlock(x+8, y+1, z+3, b, ms);
		world.setBlock(x+8, y+1, z+4, b, ms);
		this.generateLock(x+8, y+1, z+17, LockColor.RED);
		world.setBlock(x+8, y+1, z+37, b, ms);
		world.setBlock(x+8, y+1, z+41, b, ms);
		world.setBlock(x+8, y+1, z+45, b, ms);
		world.setBlock(x+8, y+1, z+46, b, ms);
		world.setBlock(x+8, y+2, z+3, b, ms);
		world.setBlock(x+8, y+2, z+4, b, ms);
		this.generateLock(x+8, y+2, z+17, LockColor.RED);
		world.setBlock(x+8, y+2, z+37, b, ms);
		world.setBlock(x+8, y+2, z+41, b, ms);
		world.setBlock(x+8, y+2, z+45, b, ms);
		world.setBlock(x+8, y+2, z+46, b, ms);
		world.setBlock(x+8, y+3, z+3, b, ms);
		world.setBlock(x+8, y+3, z+4, b, ms);
		this.generateLock(x+8, y+3, z+17, LockColor.RED);
		world.setBlock(x+8, y+3, z+37, b, ms);
		world.setBlock(x+8, y+3, z+41, b, ms);
		world.setBlock(x+8, y+3, z+45, b, ms);
		world.setBlock(x+8, y+3, z+46, b, ms);
		world.setBlock(x+8, y+4, z+3, b, ms);
		world.setBlock(x+8, y+4, z+4, b, ms);
		world.setBlock(x+8, y+4, z+17, b, ms);
		world.setBlock(x+8, y+4, z+37, b, ms);
		world.setBlock(x+8, y+4, z+41, b, ms);
		world.setBlock(x+8, y+4, z+45, b, ms);
		world.setBlock(x+8, y+4, z+46, b, ms);
		world.setBlock(x+8, y+5, z+3, b, ms);
		world.setBlock(x+8, y+5, z+4, b, ms);
		world.setBlock(x+8, y+5, z+5, b, ms);
		world.setBlock(x+8, y+5, z+6, b, ms);
		world.setBlock(x+8, y+5, z+7, b, ms);
		world.setBlock(x+8, y+5, z+8, b, ms);
		world.setBlock(x+8, y+5, z+9, b, ms);
		world.setBlock(x+8, y+5, z+10, b, ms);
		world.setBlock(x+8, y+5, z+11, b, ms);
		world.setBlock(x+8, y+5, z+12, b, ms);
		world.setBlock(x+8, y+5, z+13, b, ms);
		world.setBlock(x+8, y+5, z+14, b, ms);
		world.setBlock(x+8, y+5, z+15, b, ms);
		world.setBlock(x+8, y+5, z+16, b, ms);
		world.setBlock(x+8, y+5, z+17, b, ms);
		world.setBlock(x+8, y+5, z+18, b, ms);
		world.setBlock(x+8, y+5, z+19, b, ms);
		world.setBlock(x+8, y+5, z+20, b, ms);
		world.setBlock(x+8, y+5, z+21, b, ms);
		world.setBlock(x+8, y+5, z+22, b, ms);
		world.setBlock(x+8, y+5, z+23, b, ms);
		world.setBlock(x+8, y+5, z+24, b, ms);
		world.setBlock(x+8, y+5, z+25, b, ms);
		world.setBlock(x+8, y+5, z+26, b, ms);
		world.setBlock(x+8, y+5, z+27, b, ms);
		world.setBlock(x+8, y+5, z+28, b, ms);
		world.setBlock(x+8, y+5, z+29, b, ms);
		world.setBlock(x+8, y+5, z+30, b, ms);
		world.setBlock(x+8, y+5, z+31, b, ms);
		world.setBlock(x+8, y+5, z+32, b, ms);
		world.setBlock(x+8, y+5, z+33, b, ms);
		world.setBlock(x+8, y+5, z+34, b, ms);
		world.setBlock(x+8, y+5, z+35, b, ms);
		world.setBlock(x+8, y+5, z+36, b, ms);
		world.setBlock(x+8, y+5, z+37, b, ms);
		world.setBlock(x+8, y+5, z+38, b, ms);
		world.setBlock(x+8, y+5, z+39, b, ms);
		world.setBlock(x+8, y+5, z+40, b, ms);
		world.setBlock(x+8, y+5, z+41, b, ms);
		world.setBlock(x+8, y+5, z+42, b, ms);
		world.setBlock(x+8, y+5, z+43, b, ms);
		world.setBlock(x+8, y+5, z+44, b, ms);
		world.setBlock(x+8, y+5, z+45, b, ms);
		world.setBlock(x+9, y+0, z+3, b, ms);
		world.setBlock(x+9, y+0, z+4, b, ms);
		world.setBlock(x+9, y+0, z+5, b, ms);
		world.setBlock(x+9, y+0, z+6, b, ms);
		world.setBlock(x+9, y+0, z+7, b, ms);
		world.setBlock(x+9, y+0, z+8, b, ms);
		world.setBlock(x+9, y+0, z+9, b, ms);
		world.setBlock(x+9, y+0, z+10, b, ms);
		world.setBlock(x+9, y+0, z+11, b, ms);
		world.setBlock(x+9, y+0, z+12, b, ms);
		world.setBlock(x+9, y+0, z+13, b, ms);
		world.setBlock(x+9, y+0, z+14, b, ms);
		world.setBlock(x+9, y+0, z+15, b, ms);
		world.setBlock(x+9, y+0, z+16, b, ms);
		world.setBlock(x+9, y+0, z+17, b, ms);
		world.setBlock(x+9, y+0, z+18, b, ms);
		world.setBlock(x+9, y+0, z+19, b, ms);
		world.setBlock(x+9, y+0, z+20, b, ms);
		world.setBlock(x+9, y+0, z+21, b, ms);
		world.setBlock(x+9, y+0, z+22, b, ms);
		world.setBlock(x+9, y+0, z+23, b, ms);
		world.setBlock(x+9, y+0, z+24, b, ms);
		world.setBlock(x+9, y+0, z+25, b, ms);
		world.setBlock(x+9, y+0, z+26, b, ms);
		world.setBlock(x+9, y+0, z+27, b, ms);
		world.setBlock(x+9, y+0, z+28, b, ms);
		world.setBlock(x+9, y+0, z+29, b, ms);
		world.setBlock(x+9, y+0, z+30, b, ms);
		world.setBlock(x+9, y+0, z+31, b, ms);
		world.setBlock(x+9, y+0, z+32, b, ms);
		world.setBlock(x+9, y+0, z+33, b, ms);
		this.generateRune(x+9, y+0, z+34, LockColor.YELLOW);
		world.setBlock(x+9, y+0, z+35, b, ms);
		world.setBlock(x+9, y+0, z+36, b, ms);
		world.setBlock(x+9, y+0, z+37, b, ms);
		world.setBlock(x+9, y+0, z+38, b, ms);
		world.setBlock(x+9, y+0, z+39, b, ms);
		world.setBlock(x+9, y+0, z+40, b, ms);
		world.setBlock(x+9, y+0, z+41, b, ms);
		world.setBlock(x+9, y+0, z+42, b, ms);
		world.setBlock(x+9, y+0, z+43, b, ml);
		world.setBlock(x+9, y+0, z+44, b, ms);
		world.setBlock(x+9, y+0, z+45, b, ms);
		world.setBlock(x+9, y+0, z+46, b, ms);
		world.setBlock(x+9, y+1, z+3, b, ms);
		this.generateLock(x+9, y+1, z+17, LockColor.RED);
		world.setBlock(x+9, y+1, z+37, b, ms);
		this.generateLock(x+9, y+1, z+41, LockColor.PURPLE);
		this.generateGate(x+9, y+1, z+45);
		world.setBlock(x+9, y+2, z+3, b, ms);
		this.generateLock(x+9, y+2, z+17, LockColor.RED);
		world.setBlock(x+9, y+2, z+37, b, ms);
		this.generateLock(x+9, y+2, z+41, LockColor.PURPLE);
		this.generateGate(x+9, y+2, z+45);
		world.setBlock(x+9, y+3, z+3, b, ms);
		this.generateLock(x+9, y+3, z+17, LockColor.RED);
		world.setBlock(x+9, y+3, z+37, b, ms);
		this.generateLock(x+9, y+3, z+41, LockColor.PURPLE);
		this.generateGate(x+9, y+3, z+45);
		world.setBlock(x+9, y+4, z+3, b, ms);
		world.setBlock(x+9, y+4, z+17, b, ms);
		world.setBlock(x+9, y+4, z+37, b, ms);
		world.setBlock(x+9, y+4, z+41, b, ms);
		world.setBlock(x+9, y+4, z+45, b, ms);
		world.setBlock(x+9, y+4, z+46, b, ms);
		world.setBlock(x+9, y+5, z+3, b, ms);
		world.setBlock(x+9, y+5, z+4, b, ms);
		world.setBlock(x+9, y+5, z+5, b, ms);
		world.setBlock(x+9, y+5, z+6, b, ms);
		world.setBlock(x+9, y+5, z+7, b, ms);
		world.setBlock(x+9, y+5, z+8, b, ms);
		world.setBlock(x+9, y+5, z+9, b, ms);
		world.setBlock(x+9, y+5, z+10, b, ms);
		world.setBlock(x+9, y+5, z+11, b, ms);
		world.setBlock(x+9, y+5, z+12, b, ms);
		world.setBlock(x+9, y+5, z+13, b, ms);
		world.setBlock(x+9, y+5, z+14, b, ms);
		world.setBlock(x+9, y+5, z+15, b, ms);
		world.setBlock(x+9, y+5, z+16, b, ms);
		world.setBlock(x+9, y+5, z+17, b, ms);
		world.setBlock(x+9, y+5, z+18, b, ms);
		world.setBlock(x+9, y+5, z+19, b, ms);
		world.setBlock(x+9, y+5, z+20, b, ms);
		world.setBlock(x+9, y+5, z+21, b, ms);
		world.setBlock(x+9, y+5, z+22, b, ms);
		world.setBlock(x+9, y+5, z+23, b, ms);
		world.setBlock(x+9, y+5, z+24, b, ms);
		world.setBlock(x+9, y+5, z+25, b, ms);
		world.setBlock(x+9, y+5, z+26, b, ms);
		world.setBlock(x+9, y+5, z+27, b, ms);
		world.setBlock(x+9, y+5, z+28, b, ms);
		world.setBlock(x+9, y+5, z+29, b, ms);
		world.setBlock(x+9, y+5, z+30, b, ms);
		world.setBlock(x+9, y+5, z+31, b, ms);
		world.setBlock(x+9, y+5, z+32, b, ms);
		world.setBlock(x+9, y+5, z+33, b, ms);
		world.setBlock(x+9, y+5, z+34, b, ms);
		world.setBlock(x+9, y+5, z+35, b, ms);
		world.setBlock(x+9, y+5, z+36, b, ms);
		world.setBlock(x+9, y+5, z+37, b, ms);
		world.setBlock(x+9, y+5, z+38, b, ms);
		world.setBlock(x+9, y+5, z+39, b, ms);
		world.setBlock(x+9, y+5, z+40, b, ms);
		world.setBlock(x+9, y+5, z+41, b, ms);
		world.setBlock(x+9, y+5, z+42, b, ms);
		world.setBlock(x+9, y+5, z+43, b, ms);
		world.setBlock(x+9, y+5, z+44, b, ms);
		world.setBlock(x+9, y+5, z+45, b, ms);
		world.setBlock(x+10, y+0, z+3, b, ms);
		world.setBlock(x+10, y+0, z+4, b, ms);
		world.setBlock(x+10, y+0, z+5, b, ms);
		world.setBlock(x+10, y+0, z+6, b, ms);
		world.setBlock(x+10, y+0, z+7, b, ms);
		world.setBlock(x+10, y+0, z+8, b, ms);
		world.setBlock(x+10, y+0, z+9, b, ms);
		world.setBlock(x+10, y+0, z+10, b, ms);
		world.setBlock(x+10, y+0, z+11, b, ms);
		world.setBlock(x+10, y+0, z+12, b, ms);
		world.setBlock(x+10, y+0, z+13, b, ms);
		world.setBlock(x+10, y+0, z+14, b, ms);
		world.setBlock(x+10, y+0, z+15, b, ms);
		world.setBlock(x+10, y+0, z+16, b, ms);
		world.setBlock(x+10, y+0, z+17, b, ms);
		world.setBlock(x+10, y+0, z+18, b, ms);
		world.setBlock(x+10, y+0, z+19, b, ms);
		world.setBlock(x+10, y+0, z+20, b, ms);
		world.setBlock(x+10, y+0, z+21, b, ms);
		world.setBlock(x+10, y+0, z+22, b, ms);
		world.setBlock(x+10, y+0, z+23, b, ms);
		world.setBlock(x+10, y+0, z+24, b, ms);
		world.setBlock(x+10, y+0, z+25, b, ms);
		world.setBlock(x+10, y+0, z+26, b, ms);
		world.setBlock(x+10, y+0, z+27, b, ms);
		world.setBlock(x+10, y+0, z+28, b, ms);
		world.setBlock(x+10, y+0, z+29, b, ms);
		world.setBlock(x+10, y+0, z+30, b, ml);
		world.setBlock(x+10, y+0, z+31, b, ms);
		world.setBlock(x+10, y+0, z+32, b, ms);
		world.setBlock(x+10, y+0, z+33, b, ms);
		world.setBlock(x+10, y+0, z+34, b, ms);
		world.setBlock(x+10, y+0, z+35, b, ms);
		world.setBlock(x+10, y+0, z+36, b, ms);
		world.setBlock(x+10, y+0, z+37, b, ms);
		world.setBlock(x+10, y+0, z+38, b, ms);
		world.setBlock(x+10, y+0, z+39, b, ms);
		world.setBlock(x+10, y+0, z+40, b, ms);
		world.setBlock(x+10, y+0, z+41, b, ms);
		world.setBlock(x+10, y+0, z+42, b, ms);
		world.setBlock(x+10, y+0, z+43, b, ms);
		world.setBlock(x+10, y+0, z+44, b, ms);
		world.setBlock(x+10, y+0, z+45, b, ms);
		world.setBlock(x+10, y+0, z+46, b, ms);
		world.setBlock(x+10, y+1, z+3, b, ms);
		this.generateLock(x+10, y+1, z+17, LockColor.RED);
		this.generateKey(x+10, y+1, z+30);
		world.setBlock(x+10, y+1, z+37, b, ms);
		this.generateLock(x+10, y+1, z+41, LockColor.PURPLE);
		this.generateGate(x+10, y+1, z+45);
		world.setBlock(x+10, y+2, z+3, b, ml);
		this.generateLock(x+10, y+2, z+17, LockColor.RED);
		world.setBlock(x+10, y+2, z+37, b, ml);
		this.generateLock(x+10, y+2, z+41, LockColor.PURPLE);
		this.generateGate(x+10, y+2, z+45);
		world.setBlock(x+10, y+3, z+3, b, ms);
		this.generateLock(x+10, y+3, z+17, LockColor.RED);
		world.setBlock(x+10, y+3, z+37, b, ms);
		this.generateLock(x+10, y+3, z+41, LockColor.PURPLE);
		this.generateGate(x+10, y+3, z+45);
		world.setBlock(x+10, y+4, z+3, b, ms);
		world.setBlock(x+10, y+4, z+17, b, ms);
		world.setBlock(x+10, y+4, z+37, b, ms);
		world.setBlock(x+10, y+4, z+41, b, ms);
		world.setBlock(x+10, y+4, z+45, b, ms);
		world.setBlock(x+10, y+4, z+46, b, ms);
		world.setBlock(x+10, y+5, z+3, b, ms);
		world.setBlock(x+10, y+5, z+4, b, ms);
		world.setBlock(x+10, y+5, z+5, b, ms);
		world.setBlock(x+10, y+5, z+6, b, ms);
		world.setBlock(x+10, y+5, z+7, b, ms);
		world.setBlock(x+10, y+5, z+8, b, ms);
		world.setBlock(x+10, y+5, z+9, b, ms);
		world.setBlock(x+10, y+5, z+10, b, ms);
		world.setBlock(x+10, y+5, z+11, b, ms);
		world.setBlock(x+10, y+5, z+12, b, ms);
		world.setBlock(x+10, y+5, z+13, b, ms);
		world.setBlock(x+10, y+5, z+14, b, ms);
		world.setBlock(x+10, y+5, z+15, b, ms);
		world.setBlock(x+10, y+5, z+16, b, ms);
		world.setBlock(x+10, y+5, z+17, b, ms);
		world.setBlock(x+10, y+5, z+18, b, ms);
		world.setBlock(x+10, y+5, z+19, b, ms);
		world.setBlock(x+10, y+5, z+20, b, ms);
		world.setBlock(x+10, y+5, z+21, b, ms);
		world.setBlock(x+10, y+5, z+22, b, ms);
		world.setBlock(x+10, y+5, z+23, b, ms);
		world.setBlock(x+10, y+5, z+24, b, ms);
		world.setBlock(x+10, y+5, z+25, b, ms);
		world.setBlock(x+10, y+5, z+26, b, ms);
		world.setBlock(x+10, y+5, z+27, b, ms);
		world.setBlock(x+10, y+5, z+28, b, ms);
		world.setBlock(x+10, y+5, z+29, b, ms);
		world.setBlock(x+10, y+5, z+30, b, ms);
		world.setBlock(x+10, y+5, z+31, b, ms);
		world.setBlock(x+10, y+5, z+32, b, ms);
		world.setBlock(x+10, y+5, z+33, b, ms);
		world.setBlock(x+10, y+5, z+34, b, ms);
		world.setBlock(x+10, y+5, z+35, b, ms);
		world.setBlock(x+10, y+5, z+36, b, ms);
		world.setBlock(x+10, y+5, z+37, b, ms);
		world.setBlock(x+10, y+5, z+38, b, ms);
		world.setBlock(x+10, y+5, z+39, b, ms);
		world.setBlock(x+10, y+5, z+40, b, ms);
		world.setBlock(x+10, y+5, z+41, b, ms);
		world.setBlock(x+10, y+5, z+42, b, ms);
		world.setBlock(x+10, y+5, z+43, b, ms);
		world.setBlock(x+10, y+5, z+44, b, ms);
		world.setBlock(x+10, y+5, z+45, b, ms);
		world.setBlock(x+11, y+0, z+1, b, ms);
		world.setBlock(x+11, y+0, z+2, b, ms);
		world.setBlock(x+11, y+0, z+3, b, ms);
		world.setBlock(x+11, y+0, z+4, b, ms);
		world.setBlock(x+11, y+0, z+5, b, ms);
		world.setBlock(x+11, y+0, z+6, b, ms);
		world.setBlock(x+11, y+0, z+7, b, ms);
		world.setBlock(x+11, y+0, z+8, b, ms);
		world.setBlock(x+11, y+0, z+9, b, ms);
		world.setBlock(x+11, y+0, z+10, b, ms);
		world.setBlock(x+11, y+0, z+11, b, ms);
		world.setBlock(x+11, y+0, z+12, b, ms);
		world.setBlock(x+11, y+0, z+13, b, ms);
		world.setBlock(x+11, y+0, z+14, b, ms);
		world.setBlock(x+11, y+0, z+15, b, ms);
		world.setBlock(x+11, y+0, z+16, b, ms);
		world.setBlock(x+11, y+0, z+17, b, ms);
		world.setBlock(x+11, y+0, z+18, b, ms);
		world.setBlock(x+11, y+0, z+19, b, ms);
		world.setBlock(x+11, y+0, z+20, b, ms);
		world.setBlock(x+11, y+0, z+21, b, ms);
		world.setBlock(x+11, y+0, z+22, b, ms);
		world.setBlock(x+11, y+0, z+23, b, ms);
		world.setBlock(x+11, y+0, z+24, b, ms);
		world.setBlock(x+11, y+0, z+25, b, ms);
		world.setBlock(x+11, y+0, z+26, b, ms);
		world.setBlock(x+11, y+0, z+27, b, ms);
		world.setBlock(x+11, y+0, z+28, b, ms);
		world.setBlock(x+11, y+0, z+29, b, ms);
		world.setBlock(x+11, y+0, z+30, b, ms);
		world.setBlock(x+11, y+0, z+31, b, ms);
		world.setBlock(x+11, y+0, z+32, b, ms);
		world.setBlock(x+11, y+0, z+33, b, ms);
		world.setBlock(x+11, y+0, z+34, b, ms);
		world.setBlock(x+11, y+0, z+35, b, ms);
		world.setBlock(x+11, y+0, z+36, b, ms);
		world.setBlock(x+11, y+0, z+37, b, ms);
		world.setBlock(x+11, y+0, z+38, b, ms);
		world.setBlock(x+11, y+0, z+39, b, ms);
		world.setBlock(x+11, y+0, z+40, b, ms);
		world.setBlock(x+11, y+0, z+41, b, ms);
		world.setBlock(x+11, y+0, z+42, b, ms);
		world.setBlock(x+11, y+0, z+43, b, ms);
		world.setBlock(x+11, y+0, z+44, b, ms);
		world.setBlock(x+11, y+0, z+45, b, ms);
		world.setBlock(x+11, y+0, z+46, b, ms);
		world.setBlock(x+11, y+1, z+1, b, ms);
		world.setBlock(x+11, y+1, z+2, b, ms);
		world.setBlock(x+11, y+1, z+3, b, ms);
		world.setBlock(x+11, y+1, z+17, b, ms);
		world.setBlock(x+11, y+1, z+37, b, ms);
		this.generateLock(x+11, y+1, z+41, LockColor.PURPLE);
		this.generateGate(x+11, y+1, z+45);
		world.setBlock(x+11, y+2, z+1, b, ms);
		world.setBlock(x+11, y+2, z+2, b, ms);
		world.setBlock(x+11, y+2, z+3, b, ms);
		world.setBlock(x+11, y+2, z+17, b, ms);
		world.setBlock(x+11, y+2, z+37, b, ms);
		this.generateLock(x+11, y+2, z+41, LockColor.PURPLE);
		this.generateGate(x+11, y+2, z+45);
		world.setBlock(x+11, y+3, z+1, b, ms);
		world.setBlock(x+11, y+3, z+2, b, ms);
		world.setBlock(x+11, y+3, z+3, b, ms);
		world.setBlock(x+11, y+3, z+17, b, ms);
		world.setBlock(x+11, y+3, z+37, b, ms);
		this.generateLock(x+11, y+3, z+41, LockColor.PURPLE);
		this.generateGate(x+11, y+3, z+45);
		world.setBlock(x+11, y+4, z+1, b, ms);
		world.setBlock(x+11, y+4, z+2, b, ms);
		world.setBlock(x+11, y+4, z+3, b, ms);
		world.setBlock(x+11, y+4, z+17, b, ms);
		world.setBlock(x+11, y+4, z+37, b, ms);
		world.setBlock(x+11, y+4, z+41, b, ms);
		world.setBlock(x+11, y+4, z+45, b, ms);
		world.setBlock(x+11, y+4, z+46, b, ms);
		world.setBlock(x+11, y+5, z+1, b, ms);
		world.setBlock(x+11, y+5, z+2, b, ms);
		world.setBlock(x+11, y+5, z+3, b, ms);
		world.setBlock(x+11, y+5, z+4, b, ms);
		world.setBlock(x+11, y+5, z+5, b, ms);
		world.setBlock(x+11, y+5, z+6, b, ms);
		world.setBlock(x+11, y+5, z+7, b, ms);
		world.setBlock(x+11, y+5, z+8, b, ms);
		world.setBlock(x+11, y+5, z+9, b, ms);
		world.setBlock(x+11, y+5, z+10, b, ms);
		world.setBlock(x+11, y+5, z+11, b, ms);
		world.setBlock(x+11, y+5, z+12, b, ms);
		world.setBlock(x+11, y+5, z+13, b, ms);
		world.setBlock(x+11, y+5, z+14, b, ms);
		world.setBlock(x+11, y+5, z+15, b, ms);
		world.setBlock(x+11, y+5, z+16, b, ms);
		world.setBlock(x+11, y+5, z+17, b, ms);
		world.setBlock(x+11, y+5, z+18, b, ms);
		world.setBlock(x+11, y+5, z+19, b, ms);
		world.setBlock(x+11, y+5, z+20, b, ms);
		world.setBlock(x+11, y+5, z+21, b, ms);
		world.setBlock(x+11, y+5, z+22, b, ms);
		world.setBlock(x+11, y+5, z+23, b, ms);
		world.setBlock(x+11, y+5, z+24, b, ms);
		world.setBlock(x+11, y+5, z+25, b, ms);
		world.setBlock(x+11, y+5, z+26, b, ms);
		world.setBlock(x+11, y+5, z+27, b, ms);
		world.setBlock(x+11, y+5, z+28, b, ms);
		world.setBlock(x+11, y+5, z+29, b, ms);
		world.setBlock(x+11, y+5, z+30, b, ms);
		world.setBlock(x+11, y+5, z+31, b, ms);
		world.setBlock(x+11, y+5, z+32, b, ms);
		world.setBlock(x+11, y+5, z+33, b, ms);
		world.setBlock(x+11, y+5, z+34, b, ms);
		world.setBlock(x+11, y+5, z+35, b, ms);
		world.setBlock(x+11, y+5, z+36, b, ms);
		world.setBlock(x+11, y+5, z+37, b, ms);
		world.setBlock(x+11, y+5, z+38, b, ms);
		world.setBlock(x+11, y+5, z+39, b, ms);
		world.setBlock(x+11, y+5, z+40, b, ms);
		world.setBlock(x+11, y+5, z+41, b, ms);
		world.setBlock(x+11, y+5, z+42, b, ms);
		world.setBlock(x+11, y+5, z+43, b, ms);
		world.setBlock(x+11, y+5, z+44, b, ms);
		world.setBlock(x+11, y+5, z+45, b, ms);
		world.setBlock(x+12, y+0, z+1, b, ms);
		world.setBlock(x+12, y+0, z+2, b, ms);
		world.setBlock(x+12, y+0, z+3, b, ms);
		world.setBlock(x+12, y+0, z+4, b, ms);
		world.setBlock(x+12, y+0, z+5, b, ms);
		world.setBlock(x+12, y+0, z+6, b, ms);
		world.setBlock(x+12, y+0, z+7, b, ms);
		world.setBlock(x+12, y+0, z+8, b, ms);
		world.setBlock(x+12, y+0, z+9, b, ms);
		world.setBlock(x+12, y+0, z+10, b, ms);
		world.setBlock(x+12, y+0, z+11, b, ms);
		world.setBlock(x+12, y+0, z+12, b, ms);
		world.setBlock(x+12, y+0, z+13, b, ms);
		world.setBlock(x+12, y+0, z+14, b, ms);
		world.setBlock(x+12, y+0, z+15, b, ms);
		world.setBlock(x+12, y+0, z+16, b, ms);
		world.setBlock(x+12, y+0, z+17, b, ms);
		world.setBlock(x+12, y+0, z+18, b, ms);
		world.setBlock(x+12, y+0, z+19, b, ms);
		world.setBlock(x+12, y+0, z+20, b, ms);
		world.setBlock(x+12, y+0, z+21, b, ms);
		world.setBlock(x+12, y+0, z+22, b, ms);
		world.setBlock(x+12, y+0, z+23, b, ms);
		world.setBlock(x+12, y+0, z+24, b, ms);
		world.setBlock(x+12, y+0, z+25, b, ms);
		world.setBlock(x+12, y+0, z+26, b, ms);
		world.setBlock(x+12, y+0, z+27, b, ms);
		world.setBlock(x+12, y+0, z+28, b, ms);
		world.setBlock(x+12, y+0, z+29, b, ms);
		world.setBlock(x+12, y+0, z+30, b, ms);
		world.setBlock(x+12, y+0, z+31, b, ms);
		world.setBlock(x+12, y+0, z+32, b, ms);
		world.setBlock(x+12, y+0, z+33, b, ms);
		world.setBlock(x+12, y+0, z+34, b, ms);
		world.setBlock(x+12, y+0, z+35, b, ms);
		world.setBlock(x+12, y+0, z+36, b, ms);
		world.setBlock(x+12, y+0, z+37, b, ms);
		world.setBlock(x+12, y+0, z+38, b, ms);
		world.setBlock(x+12, y+0, z+39, b, ms);
		world.setBlock(x+12, y+0, z+40, b, ms);
		world.setBlock(x+12, y+0, z+41, b, ms);
		world.setBlock(x+12, y+0, z+42, b, ms);
		world.setBlock(x+12, y+0, z+43, b, ms);
		world.setBlock(x+12, y+0, z+44, b, ms);
		world.setBlock(x+12, y+0, z+45, b, ms);
		world.setBlock(x+12, y+0, z+46, b, ms);
		world.setBlock(x+12, y+1, z+1, b, ms);
		world.setBlock(x+12, y+1, z+9, b, ms);
		world.setBlock(x+12, y+1, z+10, b, ms);
		world.setBlock(x+12, y+1, z+11, b, ms);
		world.setBlock(x+12, y+1, z+12, b, ms);
		world.setBlock(x+12, y+1, z+13, b, ms);
		world.setBlock(x+12, y+1, z+14, b, ms);
		world.setBlock(x+12, y+1, z+15, b, ms);
		world.setBlock(x+12, y+1, z+16, b, ms);
		world.setBlock(x+12, y+1, z+17, b, ms);
		world.setBlock(x+12, y+1, z+18, b, ms);
		world.setBlock(x+12, y+1, z+19, b, ms);
		world.setBlock(x+12, y+1, z+37, b, ms);
		world.setBlock(x+12, y+1, z+41, b, ms);
		world.setBlock(x+12, y+1, z+45, b, ms);
		world.setBlock(x+12, y+1, z+46, b, ms);
		world.setBlock(x+12, y+2, z+1, b, ms);
		world.setBlock(x+12, y+2, z+9, b, ms);
		world.setBlock(x+12, y+2, z+10, b, ms);
		world.setBlock(x+12, y+2, z+11, b, ml);
		world.setBlock(x+12, y+2, z+12, b, ms);
		world.setBlock(x+12, y+2, z+13, b, ms);
		world.setBlock(x+12, y+2, z+14, b, ms);
		world.setBlock(x+12, y+2, z+15, b, ms);
		world.setBlock(x+12, y+2, z+16, b, ml);
		world.setBlock(x+12, y+2, z+17, b, ms);
		world.setBlock(x+12, y+2, z+18, b, ms);
		world.setBlock(x+12, y+2, z+19, b, ms);
		world.setBlock(x+12, y+2, z+37, b, ms);
		world.setBlock(x+12, y+2, z+41, b, ms);
		world.setBlock(x+12, y+2, z+45, b, ms);
		world.setBlock(x+12, y+2, z+46, b, ms);
		world.setBlock(x+12, y+3, z+1, b, ms);
		world.setBlock(x+12, y+3, z+9, b, ms);
		world.setBlock(x+12, y+3, z+10, b, ms);
		world.setBlock(x+12, y+3, z+11, b, ms);
		world.setBlock(x+12, y+3, z+12, b, ms);
		world.setBlock(x+12, y+3, z+13, b, ms);
		world.setBlock(x+12, y+3, z+14, b, ms);
		world.setBlock(x+12, y+3, z+15, b, ms);
		world.setBlock(x+12, y+3, z+16, b, ms);
		world.setBlock(x+12, y+3, z+17, b, ms);
		world.setBlock(x+12, y+3, z+18, b, ms);
		world.setBlock(x+12, y+3, z+19, b, ms);
		world.setBlock(x+12, y+3, z+37, b, ms);
		world.setBlock(x+12, y+3, z+41, b, ms);
		world.setBlock(x+12, y+3, z+45, b, ms);
		world.setBlock(x+12, y+3, z+46, b, ms);
		world.setBlock(x+12, y+4, z+1, b, ms);
		world.setBlock(x+12, y+4, z+9, b, ms);
		world.setBlock(x+12, y+4, z+10, b, ms);
		world.setBlock(x+12, y+4, z+11, b, ms);
		world.setBlock(x+12, y+4, z+12, b, ms);
		world.setBlock(x+12, y+4, z+13, b, ms);
		world.setBlock(x+12, y+4, z+14, b, ms);
		world.setBlock(x+12, y+4, z+15, b, ms);
		world.setBlock(x+12, y+4, z+16, b, ms);
		world.setBlock(x+12, y+4, z+17, b, ms);
		world.setBlock(x+12, y+4, z+18, b, ms);
		world.setBlock(x+12, y+4, z+19, b, ms);
		world.setBlock(x+12, y+4, z+37, b, ms);
		world.setBlock(x+12, y+4, z+41, b, ms);
		world.setBlock(x+12, y+4, z+45, b, ms);
		world.setBlock(x+12, y+4, z+46, b, ms);
		world.setBlock(x+12, y+5, z+1, b, ms);
		world.setBlock(x+12, y+5, z+2, b, ms);
		world.setBlock(x+12, y+5, z+3, b, ms);
		world.setBlock(x+12, y+5, z+4, b, ms);
		world.setBlock(x+12, y+5, z+5, b, ms);
		world.setBlock(x+12, y+5, z+6, b, ms);
		world.setBlock(x+12, y+5, z+7, b, ms);
		world.setBlock(x+12, y+5, z+8, b, ms);
		world.setBlock(x+12, y+5, z+9, b, ms);
		world.setBlock(x+12, y+5, z+10, b, ms);
		world.setBlock(x+12, y+5, z+11, b, ms);
		world.setBlock(x+12, y+5, z+12, b, ms);
		world.setBlock(x+12, y+5, z+13, b, ms);
		world.setBlock(x+12, y+5, z+14, b, ms);
		world.setBlock(x+12, y+5, z+15, b, ms);
		world.setBlock(x+12, y+5, z+16, b, ms);
		world.setBlock(x+12, y+5, z+17, b, ms);
		world.setBlock(x+12, y+5, z+18, b, ms);
		world.setBlock(x+12, y+5, z+19, b, ms);
		world.setBlock(x+12, y+5, z+20, b, ms);
		world.setBlock(x+12, y+5, z+21, b, ms);
		world.setBlock(x+12, y+5, z+22, b, ms);
		world.setBlock(x+12, y+5, z+23, b, ms);
		world.setBlock(x+12, y+5, z+24, b, ms);
		world.setBlock(x+12, y+5, z+25, b, ms);
		world.setBlock(x+12, y+5, z+26, b, ms);
		world.setBlock(x+12, y+5, z+27, b, ms);
		world.setBlock(x+12, y+5, z+28, b, ms);
		world.setBlock(x+12, y+5, z+29, b, ms);
		world.setBlock(x+12, y+5, z+30, b, ms);
		world.setBlock(x+12, y+5, z+31, b, ms);
		world.setBlock(x+12, y+5, z+32, b, ms);
		world.setBlock(x+12, y+5, z+33, b, ms);
		world.setBlock(x+12, y+5, z+34, b, ms);
		world.setBlock(x+12, y+5, z+35, b, ms);
		world.setBlock(x+12, y+5, z+36, b, ms);
		world.setBlock(x+12, y+5, z+37, b, ms);
		world.setBlock(x+12, y+5, z+38, b, ms);
		world.setBlock(x+12, y+5, z+39, b, ms);
		world.setBlock(x+12, y+5, z+40, b, ms);
		world.setBlock(x+12, y+5, z+41, b, ms);
		world.setBlock(x+12, y+5, z+42, b, ms);
		world.setBlock(x+12, y+5, z+43, b, ms);
		world.setBlock(x+12, y+5, z+44, b, ms);
		world.setBlock(x+12, y+5, z+45, b, ms);
		world.setBlock(x+13, y+0, z+1, b, ms);
		world.setBlock(x+13, y+0, z+2, b, ms);
		world.setBlock(x+13, y+0, z+3, b, ms);
		world.setBlock(x+13, y+0, z+4, b, ms);
		world.setBlock(x+13, y+0, z+5, b, ms);
		world.setBlock(x+13, y+0, z+6, b, ms);
		world.setBlock(x+13, y+0, z+7, b, ms);
		world.setBlock(x+13, y+0, z+8, b, ms);
		world.setBlock(x+13, y+0, z+9, b, ms);
		world.setBlock(x+13, y+0, z+10, b, ms);
		world.setBlock(x+13, y+0, z+11, b, ms);
		world.setBlock(x+13, y+0, z+12, b, ms);
		world.setBlock(x+13, y+0, z+13, b, ms);
		world.setBlock(x+13, y+0, z+14, b, ms);
		world.setBlock(x+13, y+0, z+15, b, ms);
		world.setBlock(x+13, y+0, z+16, b, ms);
		world.setBlock(x+13, y+0, z+17, b, ms);
		world.setBlock(x+13, y+0, z+18, b, ms);
		world.setBlock(x+13, y+0, z+19, b, ms);
		world.setBlock(x+13, y+0, z+20, b, ms);
		world.setBlock(x+13, y+0, z+21, b, ms);
		world.setBlock(x+13, y+0, z+22, b, ms);
		world.setBlock(x+13, y+0, z+23, b, ms);
		world.setBlock(x+13, y+0, z+24, b, ms);
		world.setBlock(x+13, y+0, z+25, b, ms);
		world.setBlock(x+13, y+0, z+26, b, ms);
		world.setBlock(x+13, y+0, z+27, b, ms);
		world.setBlock(x+13, y+0, z+28, b, ms);
		world.setBlock(x+13, y+0, z+29, b, ms);
		world.setBlock(x+13, y+0, z+30, b, ms);
		world.setBlock(x+13, y+0, z+31, b, ms);
		world.setBlock(x+13, y+0, z+32, b, ms);
		world.setBlock(x+13, y+0, z+33, b, ms);
		world.setBlock(x+13, y+0, z+34, b, ms);
		world.setBlock(x+13, y+0, z+35, b, ms);
		world.setBlock(x+13, y+0, z+36, b, ms);
		world.setBlock(x+13, y+0, z+37, b, ms);
		world.setBlock(x+13, y+0, z+38, b, ms);
		world.setBlock(x+13, y+0, z+39, b, ms);
		world.setBlock(x+13, y+0, z+40, b, ms);
		world.setBlock(x+13, y+0, z+41, b, ms);
		world.setBlock(x+13, y+0, z+42, b, ms);
		world.setBlock(x+13, y+0, z+43, b, mc);
		world.setBlock(x+13, y+0, z+44, b, ms);
		world.setBlock(x+13, y+0, z+45, b, ms);
		world.setBlock(x+13, y+1, z+1, b, ms);
		world.setBlock(x+13, y+1, z+9, b, ms);
		world.setBlock(x+13, y+1, z+19, b, ms);
		world.setBlock(x+13, y+1, z+20, b, ms);
		world.setBlock(x+13, y+1, z+21, b, ms);
		world.setBlock(x+13, y+1, z+22, b, ms);
		world.setBlock(x+13, y+1, z+23, b, ms);
		world.setBlock(x+13, y+1, z+24, b, ms);
		world.setBlock(x+13, y+1, z+25, fnc);
		world.setBlock(x+13, y+1, z+26, fnc);
		world.setBlock(x+13, y+1, z+27, fnc);
		world.setBlock(x+13, y+1, z+28, b, ms);
		world.setBlock(x+13, y+1, z+29, fnc);
		world.setBlock(x+13, y+1, z+30, fnc);
		world.setBlock(x+13, y+1, z+31, fnc);
		world.setBlock(x+13, y+1, z+32, b, ms);
		world.setBlock(x+13, y+1, z+33, fnc);
		world.setBlock(x+13, y+1, z+34, fnc);
		world.setBlock(x+13, y+1, z+35, fnc);
		world.setBlock(x+13, y+1, z+36, b, ms);
		world.setBlock(x+13, y+1, z+37, b, ms);
		world.setBlock(x+13, y+1, z+41, b, ms);
		world.setBlock(x+13, y+1, z+45, b, ms);
		world.setBlock(x+13, y+2, z+1, b, ms);
		world.setBlock(x+13, y+2, z+9, b, ms);
		world.setBlock(x+13, y+2, z+19, b, ms);
		world.setBlock(x+13, y+2, z+20, b, ms);
		world.setBlock(x+13, y+2, z+21, b, ms);
		world.setBlock(x+13, y+2, z+22, b, ml);
		world.setBlock(x+13, y+2, z+23, b, ms);
		world.setBlock(x+13, y+2, z+24, b, ms);
		world.setBlock(x+13, y+2, z+25, fnc);
		world.setBlock(x+13, y+2, z+26, fnc);
		world.setBlock(x+13, y+2, z+27, fnc);
		world.setBlock(x+13, y+2, z+28, b, ms);
		world.setBlock(x+13, y+2, z+29, fnc);
		world.setBlock(x+13, y+2, z+30, fnc);
		world.setBlock(x+13, y+2, z+31, fnc);
		world.setBlock(x+13, y+2, z+32, b, ms);
		world.setBlock(x+13, y+2, z+33, fnc);
		world.setBlock(x+13, y+2, z+34, fnc);
		world.setBlock(x+13, y+2, z+35, fnc);
		world.setBlock(x+13, y+2, z+36, b, ms);
		world.setBlock(x+13, y+2, z+37, b, ms);
		world.setBlock(x+13, y+2, z+41, b, ms);
		world.setBlock(x+13, y+2, z+45, b, ms);
		world.setBlock(x+13, y+3, z+1, b, ms);
		world.setBlock(x+13, y+3, z+9, b, ms);
		world.setBlock(x+13, y+3, z+19, b, ms);
		world.setBlock(x+13, y+3, z+20, b, ms);
		world.setBlock(x+13, y+3, z+21, b, ms);
		world.setBlock(x+13, y+3, z+22, b, ms);
		world.setBlock(x+13, y+3, z+23, b, ms);
		world.setBlock(x+13, y+3, z+24, b, ms);
		world.setBlock(x+13, y+3, z+25, fnc);
		world.setBlock(x+13, y+3, z+26, fnc);
		world.setBlock(x+13, y+3, z+27, fnc);
		world.setBlock(x+13, y+3, z+28, b, ms);
		world.setBlock(x+13, y+3, z+29, fnc);
		world.setBlock(x+13, y+3, z+30, fnc);
		world.setBlock(x+13, y+3, z+31, fnc);
		world.setBlock(x+13, y+3, z+32, b, ms);
		world.setBlock(x+13, y+3, z+33, fnc);
		world.setBlock(x+13, y+3, z+34, fnc);
		world.setBlock(x+13, y+3, z+35, fnc);
		world.setBlock(x+13, y+3, z+36, b, ms);
		world.setBlock(x+13, y+3, z+37, b, ms);
		world.setBlock(x+13, y+3, z+41, b, ms);
		world.setBlock(x+13, y+3, z+45, b, ms);
		world.setBlock(x+13, y+4, z+1, b, ms);
		world.setBlock(x+13, y+4, z+9, b, ms);
		world.setBlock(x+13, y+4, z+19, b, ms);
		world.setBlock(x+13, y+4, z+20, b, ms);
		world.setBlock(x+13, y+4, z+21, b, ms);
		world.setBlock(x+13, y+4, z+22, b, ms);
		world.setBlock(x+13, y+4, z+23, b, ms);
		world.setBlock(x+13, y+4, z+24, b, ms);
		world.setBlock(x+13, y+4, z+25, b, ms);
		world.setBlock(x+13, y+4, z+26, b, ms);
		world.setBlock(x+13, y+4, z+27, b, ms);
		world.setBlock(x+13, y+4, z+28, b, ms);
		world.setBlock(x+13, y+4, z+29, b, ms);
		world.setBlock(x+13, y+4, z+30, b, ml);
		world.setBlock(x+13, y+4, z+31, b, ms);
		world.setBlock(x+13, y+4, z+32, b, ms);
		world.setBlock(x+13, y+4, z+33, b, ms);
		world.setBlock(x+13, y+4, z+34, b, ms);
		world.setBlock(x+13, y+4, z+35, b, ms);
		world.setBlock(x+13, y+4, z+36, b, ms);
		world.setBlock(x+13, y+4, z+37, b, ms);
		world.setBlock(x+13, y+4, z+41, b, ms);
		world.setBlock(x+13, y+4, z+45, b, ms);
		world.setBlock(x+13, y+5, z+1, b, ms);
		world.setBlock(x+13, y+5, z+2, b, ms);
		world.setBlock(x+13, y+5, z+3, b, ms);
		world.setBlock(x+13, y+5, z+4, b, ms);
		world.setBlock(x+13, y+5, z+5, b, ms);
		world.setBlock(x+13, y+5, z+6, b, ms);
		world.setBlock(x+13, y+5, z+7, b, ms);
		world.setBlock(x+13, y+5, z+8, b, ms);
		world.setBlock(x+13, y+5, z+9, b, ms);
		world.setBlock(x+13, y+5, z+10, b, ms);
		world.setBlock(x+13, y+5, z+11, b, ms);
		world.setBlock(x+13, y+5, z+12, b, ms);
		world.setBlock(x+13, y+5, z+13, b, ms);
		world.setBlock(x+13, y+5, z+14, b, ms);
		world.setBlock(x+13, y+5, z+15, b, ms);
		world.setBlock(x+13, y+5, z+16, b, ms);
		world.setBlock(x+13, y+5, z+17, b, ms);
		world.setBlock(x+13, y+5, z+18, b, ms);
		world.setBlock(x+13, y+5, z+19, b, ms);
		world.setBlock(x+13, y+5, z+20, b, ms);
		world.setBlock(x+13, y+5, z+21, b, ms);
		world.setBlock(x+13, y+5, z+22, b, ms);
		world.setBlock(x+13, y+5, z+23, b, ms);
		world.setBlock(x+13, y+5, z+24, b, ms);
		world.setBlock(x+13, y+5, z+25, b, ms);
		world.setBlock(x+13, y+5, z+26, b, ms);
		world.setBlock(x+13, y+5, z+27, b, ms);
		world.setBlock(x+13, y+5, z+28, b, ms);
		world.setBlock(x+13, y+5, z+29, b, ms);
		world.setBlock(x+13, y+5, z+30, b, ms);
		world.setBlock(x+13, y+5, z+31, b, ms);
		world.setBlock(x+13, y+5, z+32, b, ms);
		world.setBlock(x+13, y+5, z+33, b, ms);
		world.setBlock(x+13, y+5, z+34, b, ms);
		world.setBlock(x+13, y+5, z+35, b, ms);
		world.setBlock(x+13, y+5, z+36, b, ms);
		world.setBlock(x+13, y+5, z+37, b, ms);
		world.setBlock(x+13, y+5, z+38, b, ms);
		world.setBlock(x+13, y+5, z+39, b, ms);
		world.setBlock(x+13, y+5, z+40, b, ms);
		world.setBlock(x+13, y+5, z+41, b, ms);
		world.setBlock(x+13, y+5, z+42, b, ms);
		world.setBlock(x+13, y+5, z+43, b, ms);
		world.setBlock(x+13, y+5, z+44, b, ms);
		world.setBlock(x+13, y+5, z+45, b, ms);
		world.setBlock(x+14, y+0, z+0, b, ms);
		world.setBlock(x+14, y+0, z+1, b, ms);
		world.setBlock(x+14, y+0, z+2, b, ms);
		world.setBlock(x+14, y+0, z+3, b, ms);
		world.setBlock(x+14, y+0, z+4, b, ms);
		world.setBlock(x+14, y+0, z+5, b, ms);
		world.setBlock(x+14, y+0, z+6, b, ms);
		world.setBlock(x+14, y+0, z+7, b, ms);
		world.setBlock(x+14, y+0, z+8, b, ms);
		world.setBlock(x+14, y+0, z+9, b, ms);
		world.setBlock(x+14, y+0, z+10, b, ms);
	}

	private void generate2(OriginBlockCache world, int x, int y, int z, Block b, int ms, int ml, int mc, Block fnc) {
		world.setBlock(x+14, y+0, z+11, b, ms);
		world.setBlock(x+14, y+0, z+12, b, ms);
		world.setBlock(x+14, y+0, z+13, b, ms);
		world.setBlock(x+14, y+0, z+14, b, ms);
		world.setBlock(x+14, y+0, z+15, b, ms);
		world.setBlock(x+14, y+0, z+16, b, ms);
		world.setBlock(x+14, y+0, z+17, b, ms);
		world.setBlock(x+14, y+0, z+18, b, ms);
		world.setBlock(x+14, y+0, z+19, b, ms);
		world.setBlock(x+14, y+0, z+20, b, ms);
		world.setBlock(x+14, y+0, z+21, b, ms);
		world.setBlock(x+14, y+0, z+22, b, ms);
		world.setBlock(x+14, y+0, z+23, b, ms);
		world.setBlock(x+14, y+0, z+24, b, ms);
		world.setBlock(x+14, y+0, z+25, b, ms);
		world.setBlock(x+14, y+0, z+26, b, ms);
		world.setBlock(x+14, y+0, z+27, b, ms);
		world.setBlock(x+14, y+0, z+28, b, ms);
		world.setBlock(x+14, y+0, z+29, b, ms);
		world.setBlock(x+14, y+0, z+30, b, ms);
		world.setBlock(x+14, y+0, z+31, b, ms);
		world.setBlock(x+14, y+0, z+32, b, ms);
		world.setBlock(x+14, y+0, z+33, b, ms);
		world.setBlock(x+14, y+0, z+34, b, ms);
		world.setBlock(x+14, y+0, z+35, b, ms);
		world.setBlock(x+14, y+0, z+36, b, ms);
		world.setBlock(x+14, y+0, z+37, b, ms);
		world.setBlock(x+14, y+0, z+38, b, ms);
		world.setBlock(x+14, y+0, z+39, b, ms);
		world.setBlock(x+14, y+0, z+40, b, ms);
		world.setBlock(x+14, y+0, z+41, b, ms);
		world.setBlock(x+14, y+0, z+42, b, ms);
		world.setBlock(x+14, y+0, z+43, b, ms);
		world.setBlock(x+14, y+0, z+44, b, ms);
		world.setBlock(x+14, y+0, z+45, b, ms);
		world.setBlock(x+14, y+1, z+0, b, ms);
		this.generateLock(x+14, y+1, z+20, LockColor.RED);
		world.setBlock(x+14, y+1, z+24, b, ms);
		world.setBlock(x+14, y+1, z+28, b, ms);
		world.setBlock(x+14, y+1, z+32, b, ms);
		world.setBlock(x+14, y+1, z+36, b, ms);
		world.setBlock(x+14, y+1, z+37, b, ms);
		world.setBlock(x+14, y+1, z+41, b, ms);
		world.setBlock(x+14, y+1, z+45, b, ms);
		world.setBlock(x+14, y+2, z+0, b, ms);
		this.generateLock(x+14, y+2, z+20, LockColor.RED);
		world.setBlock(x+14, y+2, z+24, b, ms);
		world.setBlock(x+14, y+2, z+28, b, ms);
		world.setBlock(x+14, y+2, z+32, b, ms);
		world.setBlock(x+14, y+2, z+36, b, ms);
		world.setBlock(x+14, y+2, z+37, b, ms);
		world.setBlock(x+14, y+2, z+41, b, ml);
		world.setBlock(x+14, y+2, z+45, b, ms);
		world.setBlock(x+14, y+3, z+0, b, ms);
		this.generateLock(x+14, y+3, z+20, LockColor.RED);
		world.setBlock(x+14, y+3, z+24, b, ms);
		world.setBlock(x+14, y+3, z+28, b, ms);
		world.setBlock(x+14, y+3, z+32, b, ms);
		world.setBlock(x+14, y+3, z+36, b, ms);
		world.setBlock(x+14, y+3, z+37, b, ms);
		world.setBlock(x+14, y+3, z+41, b, ms);
		world.setBlock(x+14, y+3, z+45, b, ms);
		world.setBlock(x+14, y+4, z+0, b, ms);
		world.setBlock(x+14, y+4, z+1, b, ms);
		world.setBlock(x+14, y+4, z+19, b, ms);
		world.setBlock(x+14, y+4, z+20, b, ms);
		world.setBlock(x+14, y+4, z+24, b, ms);
		world.setBlock(x+14, y+4, z+28, b, ms);
		world.setBlock(x+14, y+4, z+32, b, ms);
		world.setBlock(x+14, y+4, z+36, b, ms);
		world.setBlock(x+14, y+4, z+37, b, ms);
		world.setBlock(x+14, y+4, z+41, b, ms);
		world.setBlock(x+14, y+4, z+45, b, ms);
		world.setBlock(x+14, y+5, z+1, b, ms);
		world.setBlock(x+14, y+5, z+2, b, ms);
		world.setBlock(x+14, y+5, z+3, b, ms);
		world.setBlock(x+14, y+5, z+4, b, ms);
		world.setBlock(x+14, y+5, z+5, b, ms);
		world.setBlock(x+14, y+5, z+6, b, ms);
		world.setBlock(x+14, y+5, z+7, b, ms);
		world.setBlock(x+14, y+5, z+8, b, ms);
		world.setBlock(x+14, y+5, z+9, b, ms);
		world.setBlock(x+14, y+5, z+10, b, ms);
		world.setBlock(x+14, y+5, z+11, b, ms);
		world.setBlock(x+14, y+5, z+12, b, ms);
		world.setBlock(x+14, y+5, z+13, b, ms);
		world.setBlock(x+14, y+5, z+14, b, ms);
		world.setBlock(x+14, y+5, z+15, b, ms);
		world.setBlock(x+14, y+5, z+16, b, ms);
		world.setBlock(x+14, y+5, z+17, b, ms);
		world.setBlock(x+14, y+5, z+18, b, ms);
		world.setBlock(x+14, y+5, z+19, b, ms);
		world.setBlock(x+14, y+5, z+20, b, ms);
		world.setBlock(x+14, y+5, z+21, b, ms);
		world.setBlock(x+14, y+5, z+22, b, ms);
		world.setBlock(x+14, y+5, z+23, b, ms);
		world.setBlock(x+14, y+5, z+24, b, ms);
		world.setBlock(x+14, y+5, z+25, b, ms);
		world.setBlock(x+14, y+5, z+26, b, ms);
		world.setBlock(x+14, y+5, z+27, b, ms);
		world.setBlock(x+14, y+5, z+28, b, ms);
		world.setBlock(x+14, y+5, z+29, b, ms);
		world.setBlock(x+14, y+5, z+30, b, ms);
		world.setBlock(x+14, y+5, z+31, b, ms);
		world.setBlock(x+14, y+5, z+32, b, ms);
		world.setBlock(x+14, y+5, z+33, b, ms);
		world.setBlock(x+14, y+5, z+34, b, ms);
		world.setBlock(x+14, y+5, z+35, b, ms);
		world.setBlock(x+14, y+5, z+36, b, ms);
		world.setBlock(x+14, y+5, z+37, b, ms);
		world.setBlock(x+14, y+5, z+38, b, ms);
		world.setBlock(x+14, y+5, z+39, b, ms);
		world.setBlock(x+14, y+5, z+40, b, ms);
		world.setBlock(x+14, y+5, z+41, b, ms);
		world.setBlock(x+14, y+5, z+42, b, ms);
		world.setBlock(x+14, y+5, z+43, b, ms);
		world.setBlock(x+14, y+5, z+44, b, ms);
		world.setBlock(x+14, y+5, z+45, b, ms);
		world.setBlock(x+15, y+0, z+0, b, ms);
		world.setBlock(x+15, y+0, z+1, b, ms);
		world.setBlock(x+15, y+0, z+2, b, ms);
		world.setBlock(x+15, y+0, z+3, b, ms);
		world.setBlock(x+15, y+0, z+4, b, ms);
		world.setBlock(x+15, y+0, z+5, b, ms);
		world.setBlock(x+15, y+0, z+6, b, ms);
		world.setBlock(x+15, y+0, z+7, b, ms);
		world.setBlock(x+15, y+0, z+8, b, ms);
		world.setBlock(x+15, y+0, z+9, b, ms);
		world.setBlock(x+15, y+0, z+10, b, ms);
		world.setBlock(x+15, y+0, z+11, b, ms);
		world.setBlock(x+15, y+0, z+12, b, ms);
		world.setBlock(x+15, y+0, z+13, b, ms);
		world.setBlock(x+15, y+0, z+14, b, ms);
		world.setBlock(x+15, y+0, z+15, b, ms);
		world.setBlock(x+15, y+0, z+16, b, ms);
		world.setBlock(x+15, y+0, z+17, b, ms);
		world.setBlock(x+15, y+0, z+18, b, ms);
		world.setBlock(x+15, y+0, z+19, b, ms);
		world.setBlock(x+15, y+0, z+20, b, ms);
		world.setBlock(x+15, y+0, z+21, b, ms);
		world.setBlock(x+15, y+0, z+22, b, ms);
		world.setBlock(x+15, y+0, z+23, b, ms);
		world.setBlock(x+15, y+0, z+24, b, ms);
		world.setBlock(x+15, y+0, z+25, b, ms);
		world.setBlock(x+15, y+0, z+26, b, ms);
		world.setBlock(x+15, y+0, z+27, b, ms);
		world.setBlock(x+15, y+0, z+28, b, ms);
		world.setBlock(x+15, y+0, z+29, b, ms);
		world.setBlock(x+15, y+0, z+30, b, ms);
		world.setBlock(x+15, y+0, z+31, b, ms);
		world.setBlock(x+15, y+0, z+32, b, ms);
		world.setBlock(x+15, y+0, z+33, b, ms);
		world.setBlock(x+15, y+0, z+34, b, ms);
		world.setBlock(x+15, y+0, z+35, b, ms);
		world.setBlock(x+15, y+0, z+36, b, ms);
		world.setBlock(x+15, y+0, z+37, b, ms);
		world.setBlock(x+15, y+0, z+38, b, ms);
		world.setBlock(x+15, y+0, z+39, b, ms);
		world.setBlock(x+15, y+0, z+40, b, ms);
		world.setBlock(x+15, y+0, z+41, b, ms);
		world.setBlock(x+15, y+0, z+42, b, ms);
		world.setBlock(x+15, y+0, z+43, b, mc);
		world.setBlock(x+15, y+0, z+44, b, ms);
		world.setBlock(x+15, y+0, z+45, b, ms);
		this.generateLock(x+15, y+1, z+20, LockColor.RED);
		this.generateLock(x+15, y+1, z+24, LockColor.BLUE);
		this.generateLock(x+15, y+1, z+28, LockColor.YELLOW);
		this.generateLock(x+15, y+1, z+32, LockColor.PURPLE);
		this.generateLock(x+15, y+1, z+36, LockColor.GREEN);
		world.setBlock(x+15, y+1, z+41, b, ms);
		world.setBlock(x+15, y+1, z+45, b, ms);
		this.generateLock(x+15, y+2, z+20, LockColor.RED);
		this.generateLock(x+15, y+2, z+24, LockColor.BLUE);
		this.generateLock(x+15, y+2, z+28, LockColor.YELLOW);
		this.generateLock(x+15, y+2, z+32, LockColor.PURPLE);
		this.generateLock(x+15, y+2, z+36, LockColor.GREEN);
		world.setBlock(x+15, y+2, z+41, b, ms);
		world.setBlock(x+15, y+2, z+45, b, ms);
		this.generateLock(x+15, y+3, z+20, LockColor.RED);
		this.generateLock(x+15, y+3, z+24, LockColor.BLUE);
		this.generateLock(x+15, y+3, z+28, LockColor.YELLOW);
		this.generateLock(x+15, y+3, z+32, LockColor.PURPLE);
		this.generateLock(x+15, y+3, z+36, LockColor.GREEN);
		world.setBlock(x+15, y+3, z+41, b, ms);
		world.setBlock(x+15, y+3, z+45, b, ms);
		world.setBlock(x+15, y+4, z+0, b, ms);
		world.setBlock(x+15, y+4, z+1, b, ms);
		world.setBlock(x+15, y+4, z+19, b, ml);
		world.setBlock(x+15, y+4, z+20, b, ms);
		world.setBlock(x+15, y+4, z+24, b, ms);
		world.setBlock(x+15, y+4, z+28, b, ms);
		world.setBlock(x+15, y+4, z+32, b, ms);
		world.setBlock(x+15, y+4, z+36, b, ms);
		world.setBlock(x+15, y+4, z+37, b, ms);
		world.setBlock(x+15, y+4, z+41, b, ms);
		world.setBlock(x+15, y+4, z+45, b, ms);
		world.setBlock(x+15, y+5, z+1, b, ms);
		world.setBlock(x+15, y+5, z+2, b, ms);
		world.setBlock(x+15, y+5, z+3, b, ms);
		world.setBlock(x+15, y+5, z+4, b, ms);
		world.setBlock(x+15, y+5, z+5, b, ms);
		world.setBlock(x+15, y+5, z+6, b, ms);
		world.setBlock(x+15, y+5, z+7, b, ms);
		world.setBlock(x+15, y+5, z+8, b, ms);
		world.setBlock(x+15, y+5, z+9, b, ms);
		world.setBlock(x+15, y+5, z+10, b, ms);
		world.setBlock(x+15, y+5, z+11, b, ms);
		world.setBlock(x+15, y+5, z+12, b, ms);
		world.setBlock(x+15, y+5, z+13, b, ms);
		world.setBlock(x+15, y+5, z+14, b, ms);
		world.setBlock(x+15, y+5, z+15, b, ms);
		world.setBlock(x+15, y+5, z+16, b, ms);
		world.setBlock(x+15, y+5, z+17, b, ms);
		world.setBlock(x+15, y+5, z+18, b, ms);
		world.setBlock(x+15, y+5, z+19, b, ms);
		world.setBlock(x+15, y+5, z+20, b, ms);
		world.setBlock(x+15, y+5, z+21, b, ms);
		world.setBlock(x+15, y+5, z+22, b, ms);
		world.setBlock(x+15, y+5, z+23, b, ms);
		world.setBlock(x+15, y+5, z+24, b, ms);
		world.setBlock(x+15, y+5, z+25, b, ms);
		world.setBlock(x+15, y+5, z+26, b, ms);
		world.setBlock(x+15, y+5, z+27, b, ms);
		world.setBlock(x+15, y+5, z+28, b, ms);
		world.setBlock(x+15, y+5, z+29, b, ms);
		world.setBlock(x+15, y+5, z+30, b, ms);
		world.setBlock(x+15, y+5, z+31, b, ms);
		world.setBlock(x+15, y+5, z+32, b, ms);
		world.setBlock(x+15, y+5, z+33, b, ms);
		world.setBlock(x+15, y+5, z+34, b, ms);
		world.setBlock(x+15, y+5, z+35, b, ms);
		world.setBlock(x+15, y+5, z+36, b, ms);
		world.setBlock(x+15, y+5, z+37, b, ms);
		world.setBlock(x+15, y+5, z+38, b, ms);
		world.setBlock(x+15, y+5, z+39, b, ms);
		world.setBlock(x+15, y+5, z+40, b, ms);
		world.setBlock(x+15, y+5, z+41, b, ms);
		world.setBlock(x+15, y+5, z+42, b, ms);
		world.setBlock(x+15, y+5, z+43, b, ms);
		world.setBlock(x+15, y+5, z+44, b, ms);
		world.setBlock(x+15, y+5, z+45, b, ms);
		world.setBlock(x+16, y+0, z+0, b, ms);
		world.setBlock(x+16, y+0, z+1, b, ms);
		world.setBlock(x+16, y+0, z+2, b, ms);
		world.setBlock(x+16, y+0, z+3, b, ms);
		world.setBlock(x+16, y+0, z+4, b, ms);
		world.setBlock(x+16, y+0, z+5, b, ms);
		world.setBlock(x+16, y+0, z+6, b, ml);
		world.setBlock(x+16, y+0, z+7, b, ms);
		world.setBlock(x+16, y+0, z+8, b, ms);
		world.setBlock(x+16, y+0, z+9, b, ms);
		world.setBlock(x+16, y+0, z+10, b, ms);
		world.setBlock(x+16, y+0, z+11, b, ms);
		world.setBlock(x+16, y+0, z+12, b, ms);
		world.setBlock(x+16, y+0, z+13, b, ms);
		world.setBlock(x+16, y+0, z+14, b, ms);
		world.setBlock(x+16, y+0, z+15, b, ms);
		world.setBlock(x+16, y+0, z+16, b, ms);
		world.setBlock(x+16, y+0, z+17, b, ms);
		world.setBlock(x+16, y+0, z+18, b, ms);
		world.setBlock(x+16, y+0, z+19, b, ms);
		world.setBlock(x+16, y+0, z+20, b, ms);
		world.setBlock(x+16, y+0, z+21, b, ms);
		world.setBlock(x+16, y+0, z+22, b, ms);
		world.setBlock(x+16, y+0, z+23, b, ms);
		world.setBlock(x+16, y+0, z+24, b, ms);
		world.setBlock(x+16, y+0, z+25, b, ms);
		world.setBlock(x+16, y+0, z+26, b, ml);
		world.setBlock(x+16, y+0, z+27, b, ms);
		world.setBlock(x+16, y+0, z+28, b, ms);
		world.setBlock(x+16, y+0, z+29, b, ms);
		world.setBlock(x+16, y+0, z+30, b, ms);
		world.setBlock(x+16, y+0, z+31, b, ms);
		world.setBlock(x+16, y+0, z+32, b, ms);
		world.setBlock(x+16, y+0, z+33, b, ms);
		world.setBlock(x+16, y+0, z+34, b, ml);
		world.setBlock(x+16, y+0, z+35, b, ms);
		world.setBlock(x+16, y+0, z+36, b, ms);
		world.setBlock(x+16, y+0, z+37, b, ms);
		world.setBlock(x+16, y+0, z+38, b, ms);
		world.setBlock(x+16, y+0, z+39, b, ms);
		world.setBlock(x+16, y+0, z+40, b, ms);
		world.setBlock(x+16, y+0, z+41, b, ms);
		world.setBlock(x+16, y+0, z+42, b, ms);
		world.setBlock(x+16, y+0, z+43, b, ms);
		world.setBlock(x+16, y+0, z+44, b, ms);
		world.setBlock(x+16, y+0, z+45, b, ms);
		this.generateKey(x+16, y+1, z+6);
		this.generateLock(x+16, y+1, z+20, LockColor.RED);
		this.generateLock(x+16, y+1, z+24, LockColor.BLUE);
		this.generateLock(x+16, y+1, z+28, LockColor.YELLOW);
		this.generateLock(x+16, y+1, z+32, LockColor.PURPLE);
		this.generateKey(x+16, y+1, z+34);
		this.generateLock(x+16, y+1, z+36, LockColor.GREEN);
		world.setBlock(x+16, y+1, z+41, b, ms);
		world.setBlock(x+16, y+1, z+45, b, ms);
		this.generateLock(x+16, y+2, z+20, LockColor.RED);
		this.generateLock(x+16, y+2, z+24, LockColor.BLUE);
		this.generateLock(x+16, y+2, z+28, LockColor.YELLOW);
		this.generateLock(x+16, y+2, z+32, LockColor.PURPLE);
		this.generateLock(x+16, y+2, z+36, LockColor.GREEN);
		world.setBlock(x+16, y+2, z+41, b, ms);
		world.setBlock(x+16, y+2, z+45, b, ml);
		this.generateLock(x+16, y+3, z+20, LockColor.RED);
		this.generateLock(x+16, y+3, z+24, LockColor.BLUE);
		this.generateLock(x+16, y+3, z+28, LockColor.YELLOW);
		this.generateLock(x+16, y+3, z+32, LockColor.PURPLE);
		this.generateLock(x+16, y+3, z+36, LockColor.GREEN);
		world.setBlock(x+16, y+3, z+41, b, ms);
		world.setBlock(x+16, y+3, z+45, b, ms);
		world.setBlock(x+16, y+4, z+0, b, ms);
		world.setBlock(x+16, y+4, z+1, b, ml);
		world.setBlock(x+16, y+4, z+19, b, ms);
		world.setBlock(x+16, y+4, z+20, b, ms);
		world.setBlock(x+16, y+4, z+24, b, ms);
		world.setBlock(x+16, y+4, z+28, b, ms);
		world.setBlock(x+16, y+4, z+32, b, ms);
		world.setBlock(x+16, y+4, z+36, b, ms);
		world.setBlock(x+16, y+4, z+37, b, ms);
		world.setBlock(x+16, y+4, z+41, b, ms);
		world.setBlock(x+16, y+4, z+45, b, ms);
		world.setBlock(x+16, y+5, z+1, b, ms);
		world.setBlock(x+16, y+5, z+2, b, ms);
		world.setBlock(x+16, y+5, z+3, b, ms);
		world.setBlock(x+16, y+5, z+4, b, ms);
		world.setBlock(x+16, y+5, z+5, b, ms);
		world.setBlock(x+16, y+5, z+6, b, ms);
		world.setBlock(x+16, y+5, z+7, b, ms);
		world.setBlock(x+16, y+5, z+8, b, ms);
		world.setBlock(x+16, y+5, z+9, b, ms);
		world.setBlock(x+16, y+5, z+10, b, ms);
		world.setBlock(x+16, y+5, z+11, b, ms);
		world.setBlock(x+16, y+5, z+12, b, ms);
		world.setBlock(x+16, y+5, z+13, b, ms);
		world.setBlock(x+16, y+5, z+14, b, ms);
		world.setBlock(x+16, y+5, z+15, b, ms);
		world.setBlock(x+16, y+5, z+16, b, ms);
		world.setBlock(x+16, y+5, z+17, b, ms);
		world.setBlock(x+16, y+5, z+18, b, ms);
		world.setBlock(x+16, y+5, z+19, b, ms);
		world.setBlock(x+16, y+5, z+20, b, ms);
		world.setBlock(x+16, y+5, z+21, b, ms);
		world.setBlock(x+16, y+5, z+22, b, ms);
		world.setBlock(x+16, y+5, z+23, b, ms);
		world.setBlock(x+16, y+5, z+24, b, ms);
		world.setBlock(x+16, y+5, z+25, b, ms);
		world.setBlock(x+16, y+5, z+26, b, ms);
		world.setBlock(x+16, y+5, z+27, b, ms);
		world.setBlock(x+16, y+5, z+28, b, ms);
		world.setBlock(x+16, y+5, z+29, b, ms);
		world.setBlock(x+16, y+5, z+30, b, ms);
		world.setBlock(x+16, y+5, z+31, b, ms);
		world.setBlock(x+16, y+5, z+32, b, ms);
		world.setBlock(x+16, y+5, z+33, b, ms);
		world.setBlock(x+16, y+5, z+34, b, ms);
		world.setBlock(x+16, y+5, z+35, b, ms);
		world.setBlock(x+16, y+5, z+36, b, ms);
		world.setBlock(x+16, y+5, z+37, b, ms);
		world.setBlock(x+16, y+5, z+38, b, ms);
		world.setBlock(x+16, y+5, z+39, b, ms);
		world.setBlock(x+16, y+5, z+40, b, ms);
		world.setBlock(x+16, y+5, z+41, b, ms);
		world.setBlock(x+16, y+5, z+42, b, ms);
		world.setBlock(x+16, y+5, z+43, b, ms);
		world.setBlock(x+16, y+5, z+44, b, ms);
		world.setBlock(x+16, y+5, z+45, b, ms);
		world.setBlock(x+17, y+0, z+0, b, ms);
		world.setBlock(x+17, y+0, z+1, b, ms);
		world.setBlock(x+17, y+0, z+2, b, ms);
		world.setBlock(x+17, y+0, z+3, b, ms);
		world.setBlock(x+17, y+0, z+4, b, ms);
		world.setBlock(x+17, y+0, z+5, b, ms);
		world.setBlock(x+17, y+0, z+6, b, ms);
		world.setBlock(x+17, y+0, z+7, b, ms);
		world.setBlock(x+17, y+0, z+8, b, ms);
		world.setBlock(x+17, y+0, z+9, b, ms);
		world.setBlock(x+17, y+0, z+10, b, ms);
		world.setBlock(x+17, y+0, z+11, b, ms);
		world.setBlock(x+17, y+0, z+12, b, ms);
		world.setBlock(x+17, y+0, z+13, b, ms);
		world.setBlock(x+17, y+0, z+14, b, ms);
		world.setBlock(x+17, y+0, z+15, b, ms);
		world.setBlock(x+17, y+0, z+16, b, ms);
		world.setBlock(x+17, y+0, z+17, b, ms);
		world.setBlock(x+17, y+0, z+18, b, ms);
		world.setBlock(x+17, y+0, z+19, b, ms);
		world.setBlock(x+17, y+0, z+20, b, ms);
		world.setBlock(x+17, y+0, z+21, b, ms);
		world.setBlock(x+17, y+0, z+22, b, ms);
		world.setBlock(x+17, y+0, z+23, b, ms);
		world.setBlock(x+17, y+0, z+24, b, ms);
		world.setBlock(x+17, y+0, z+25, b, ms);
		world.setBlock(x+17, y+0, z+26, b, ms);
		world.setBlock(x+17, y+0, z+27, b, ms);
		world.setBlock(x+17, y+0, z+28, b, ms);
		world.setBlock(x+17, y+0, z+29, b, ms);
		world.setBlock(x+17, y+0, z+30, b, ms);
		world.setBlock(x+17, y+0, z+31, b, ms);
		world.setBlock(x+17, y+0, z+32, b, ms);
		world.setBlock(x+17, y+0, z+33, b, ms);
		world.setBlock(x+17, y+0, z+34, b, ms);
		world.setBlock(x+17, y+0, z+35, b, ms);
		world.setBlock(x+17, y+0, z+36, b, ms);
		world.setBlock(x+17, y+0, z+37, b, ms);
		world.setBlock(x+17, y+0, z+38, b, ms);
		world.setBlock(x+17, y+0, z+39, b, ms);
		world.setBlock(x+17, y+0, z+40, b, ms);
		world.setBlock(x+17, y+0, z+41, b, ms);
		world.setBlock(x+17, y+0, z+42, b, ms);
		world.setBlock(x+17, y+0, z+43, b, mc);
		world.setBlock(x+17, y+0, z+44, b, ms);
		world.setBlock(x+17, y+0, z+45, b, ms);
		world.setBlock(x+17, y+1, z+19, b, ms);
		world.setBlock(x+17, y+1, z+20, b, ms);
		this.generateLock(x+17, y+1, z+24, LockColor.BLUE);
		this.generateLock(x+17, y+1, z+28, LockColor.YELLOW);
		this.generateLock(x+17, y+1, z+32, LockColor.PURPLE);
		this.generateLock(x+17, y+1, z+36, LockColor.GREEN);
		world.setBlock(x+17, y+1, z+41, b, ms);
		world.setBlock(x+17, y+1, z+45, b, ms);
		world.setBlock(x+17, y+2, z+19, b, ms);
		world.setBlock(x+17, y+2, z+20, b, ms);
		this.generateLock(x+17, y+2, z+24, LockColor.BLUE);
		this.generateLock(x+17, y+2, z+28, LockColor.YELLOW);
		this.generateLock(x+17, y+2, z+32, LockColor.PURPLE);
		this.generateLock(x+17, y+2, z+36, LockColor.GREEN);
		world.setBlock(x+17, y+2, z+41, b, ms);
		world.setBlock(x+17, y+2, z+45, b, ms);
		world.setBlock(x+17, y+3, z+19, b, ms);
		world.setBlock(x+17, y+3, z+20, b, ms);
		this.generateLock(x+17, y+3, z+24, LockColor.BLUE);
		this.generateLock(x+17, y+3, z+28, LockColor.YELLOW);
		this.generateLock(x+17, y+3, z+32, LockColor.PURPLE);
		this.generateLock(x+17, y+3, z+36, LockColor.GREEN);
		world.setBlock(x+17, y+3, z+41, b, ms);
		world.setBlock(x+17, y+3, z+45, b, ms);
		world.setBlock(x+17, y+4, z+0, b, ms);
		world.setBlock(x+17, y+4, z+1, b, ms);
		world.setBlock(x+17, y+4, z+19, b, ms);
		world.setBlock(x+17, y+4, z+20, b, ms);
		world.setBlock(x+17, y+4, z+24, b, ms);
		world.setBlock(x+17, y+4, z+28, b, ms);
		world.setBlock(x+17, y+4, z+32, b, ms);
		world.setBlock(x+17, y+4, z+36, b, ms);
		world.setBlock(x+17, y+4, z+37, b, ms);
		world.setBlock(x+17, y+4, z+41, b, ms);
		world.setBlock(x+17, y+4, z+45, b, ms);
		world.setBlock(x+17, y+5, z+1, b, ms);
		world.setBlock(x+17, y+5, z+2, b, ms);
		world.setBlock(x+17, y+5, z+3, b, ms);
		world.setBlock(x+17, y+5, z+4, b, ms);
		world.setBlock(x+17, y+5, z+5, b, ms);
		world.setBlock(x+17, y+5, z+6, b, ms);
		world.setBlock(x+17, y+5, z+7, b, ms);
		world.setBlock(x+17, y+5, z+8, b, ms);
		world.setBlock(x+17, y+5, z+9, b, ms);
		world.setBlock(x+17, y+5, z+10, b, ms);
		world.setBlock(x+17, y+5, z+11, b, ms);
		world.setBlock(x+17, y+5, z+12, b, ms);
		world.setBlock(x+17, y+5, z+13, b, ms);
		world.setBlock(x+17, y+5, z+14, b, ms);
		world.setBlock(x+17, y+5, z+15, b, ms);
		world.setBlock(x+17, y+5, z+16, b, ms);
		world.setBlock(x+17, y+5, z+17, b, ms);
		world.setBlock(x+17, y+5, z+18, b, ms);
		world.setBlock(x+17, y+5, z+19, b, ms);
		world.setBlock(x+17, y+5, z+20, b, ms);
		world.setBlock(x+17, y+5, z+21, b, ms);
		world.setBlock(x+17, y+5, z+22, b, ms);
		world.setBlock(x+17, y+5, z+23, b, ms);
		world.setBlock(x+17, y+5, z+24, b, ms);
		world.setBlock(x+17, y+5, z+25, b, ms);
		world.setBlock(x+17, y+5, z+26, b, ms);
		world.setBlock(x+17, y+5, z+27, b, ms);
		world.setBlock(x+17, y+5, z+28, b, ms);
		world.setBlock(x+17, y+5, z+29, b, ms);
		world.setBlock(x+17, y+5, z+30, b, ms);
		world.setBlock(x+17, y+5, z+31, b, ms);
		world.setBlock(x+17, y+5, z+32, b, ms);
		world.setBlock(x+17, y+5, z+33, b, ms);
		world.setBlock(x+17, y+5, z+34, b, ms);
		world.setBlock(x+17, y+5, z+35, b, ms);
		world.setBlock(x+17, y+5, z+36, b, ms);
		world.setBlock(x+17, y+5, z+37, b, ms);
		world.setBlock(x+17, y+5, z+38, b, ms);
		world.setBlock(x+17, y+5, z+39, b, ms);
		world.setBlock(x+17, y+5, z+40, b, ms);
		world.setBlock(x+17, y+5, z+41, b, ms);
		world.setBlock(x+17, y+5, z+42, b, ms);
		world.setBlock(x+17, y+5, z+43, b, ms);
		world.setBlock(x+17, y+5, z+44, b, ms);
		world.setBlock(x+17, y+5, z+45, b, ms);
		world.setBlock(x+18, y+0, z+0, b, ms);
		world.setBlock(x+18, y+0, z+1, b, ms);
		world.setBlock(x+18, y+0, z+2, b, ms);
		world.setBlock(x+18, y+0, z+3, b, ms);
		world.setBlock(x+18, y+0, z+4, b, ms);
		world.setBlock(x+18, y+0, z+5, b, ms);
		world.setBlock(x+18, y+0, z+6, b, ms);
		world.setBlock(x+18, y+0, z+7, b, ms);
		world.setBlock(x+18, y+0, z+8, b, ms);
		world.setBlock(x+18, y+0, z+9, b, ms);
		world.setBlock(x+18, y+0, z+10, b, ms);
		world.setBlock(x+18, y+0, z+11, b, ms);
		world.setBlock(x+18, y+0, z+12, b, ms);
		world.setBlock(x+18, y+0, z+13, b, ms);
		world.setBlock(x+18, y+0, z+14, b, ms);
		world.setBlock(x+18, y+0, z+15, b, ms);
		world.setBlock(x+18, y+0, z+16, b, ms);
		world.setBlock(x+18, y+0, z+17, b, ms);
		world.setBlock(x+18, y+0, z+18, b, ms);
		world.setBlock(x+18, y+0, z+19, b, ms);
		world.setBlock(x+18, y+0, z+20, b, ms);
		world.setBlock(x+18, y+0, z+21, b, ms);
		world.setBlock(x+18, y+0, z+22, b, ms);
		world.setBlock(x+18, y+0, z+23, b, ms);
		world.setBlock(x+18, y+0, z+24, b, ms);
		world.setBlock(x+18, y+0, z+25, b, ms);
		world.setBlock(x+18, y+0, z+26, b, ms);
		world.setBlock(x+18, y+0, z+27, b, ms);
		world.setBlock(x+18, y+0, z+28, b, ms);
		world.setBlock(x+18, y+0, z+29, b, ms);
		world.setBlock(x+18, y+0, z+30, b, ms);
		world.setBlock(x+18, y+0, z+31, b, ms);
		world.setBlock(x+18, y+0, z+32, b, ms);
		world.setBlock(x+18, y+0, z+33, b, ms);
		world.setBlock(x+18, y+0, z+34, b, ms);
		world.setBlock(x+18, y+0, z+35, b, ms);
		world.setBlock(x+18, y+0, z+36, b, ms);
		world.setBlock(x+18, y+0, z+37, b, ms);
		world.setBlock(x+18, y+0, z+38, b, ms);
		world.setBlock(x+18, y+0, z+39, b, ms);
		world.setBlock(x+18, y+0, z+40, b, ms);
		world.setBlock(x+18, y+0, z+41, b, ms);
		world.setBlock(x+18, y+0, z+42, b, ms);
		world.setBlock(x+18, y+0, z+43, b, ms);
		world.setBlock(x+18, y+0, z+44, b, ms);
		world.setBlock(x+18, y+0, z+45, b, ms);
		world.setBlock(x+18, y+1, z+0, b, ms);
		world.setBlock(x+18, y+1, z+20, fnc);
		world.setBlock(x+18, y+1, z+24, b, ms);
		world.setBlock(x+18, y+1, z+28, b, ms);
		world.setBlock(x+18, y+1, z+32, b, ms);
		world.setBlock(x+18, y+1, z+36, b, ms);
		world.setBlock(x+18, y+1, z+37, b, ms);
		world.setBlock(x+18, y+1, z+41, b, ms);
		world.setBlock(x+18, y+1, z+45, b, ms);
		world.setBlock(x+18, y+2, z+0, b, ms);
		world.setBlock(x+18, y+2, z+20, fnc);
		world.setBlock(x+18, y+2, z+24, b, ms);
		world.setBlock(x+18, y+2, z+28, b, ms);
		world.setBlock(x+18, y+2, z+32, b, ms);
		world.setBlock(x+18, y+2, z+36, b, ms);
		world.setBlock(x+18, y+2, z+37, b, ms);
		world.setBlock(x+18, y+2, z+41, b, ms);
		world.setBlock(x+18, y+2, z+45, b, ms);
		world.setBlock(x+18, y+3, z+0, b, ms);
		world.setBlock(x+18, y+3, z+20, fnc);
		world.setBlock(x+18, y+3, z+24, b, ms);
		world.setBlock(x+18, y+3, z+28, b, ms);
		world.setBlock(x+18, y+3, z+32, b, ms);
		world.setBlock(x+18, y+3, z+36, b, ms);
		world.setBlock(x+18, y+3, z+37, b, ms);
		world.setBlock(x+18, y+3, z+41, b, ms);
		world.setBlock(x+18, y+3, z+45, b, ms);
		world.setBlock(x+18, y+4, z+0, b, ms);
		world.setBlock(x+18, y+4, z+1, b, ms);
		world.setBlock(x+18, y+4, z+19, b, ms);
		world.setBlock(x+18, y+4, z+20, b, ms);
		world.setBlock(x+18, y+4, z+24, b, ms);
		world.setBlock(x+18, y+4, z+28, b, ms);
		world.setBlock(x+18, y+4, z+32, b, ms);
		world.setBlock(x+18, y+4, z+36, b, ms);
		world.setBlock(x+18, y+4, z+37, b, ms);
		world.setBlock(x+18, y+4, z+41, b, ms);
		world.setBlock(x+18, y+4, z+45, b, ms);
		world.setBlock(x+18, y+5, z+1, b, ms);
		world.setBlock(x+18, y+5, z+2, b, ms);
		world.setBlock(x+18, y+5, z+3, b, ms);
		world.setBlock(x+18, y+5, z+4, b, ms);
		world.setBlock(x+18, y+5, z+5, b, ms);
		world.setBlock(x+18, y+5, z+6, b, ms);
		world.setBlock(x+18, y+5, z+7, b, ms);
		world.setBlock(x+18, y+5, z+8, b, ms);
		world.setBlock(x+18, y+5, z+9, b, ms);
		world.setBlock(x+18, y+5, z+10, b, ms);
		world.setBlock(x+18, y+5, z+11, b, ms);
		world.setBlock(x+18, y+5, z+12, b, ms);
		world.setBlock(x+18, y+5, z+13, b, ms);
		world.setBlock(x+18, y+5, z+14, b, ms);
		world.setBlock(x+18, y+5, z+15, b, ms);
		world.setBlock(x+18, y+5, z+16, b, ms);
		world.setBlock(x+18, y+5, z+17, b, ms);
		world.setBlock(x+18, y+5, z+18, b, ms);
		world.setBlock(x+18, y+5, z+19, b, ms);
		world.setBlock(x+18, y+5, z+20, b, ms);
		world.setBlock(x+18, y+5, z+21, b, ms);
		world.setBlock(x+18, y+5, z+22, b, ms);
		world.setBlock(x+18, y+5, z+23, b, ms);
		world.setBlock(x+18, y+5, z+24, b, ms);
		world.setBlock(x+18, y+5, z+25, b, ms);
		world.setBlock(x+18, y+5, z+26, b, ms);
		world.setBlock(x+18, y+5, z+27, b, ms);
		world.setBlock(x+18, y+5, z+28, b, ms);
		world.setBlock(x+18, y+5, z+29, b, ms);
		world.setBlock(x+18, y+5, z+30, b, ms);
		world.setBlock(x+18, y+5, z+31, b, ms);
		world.setBlock(x+18, y+5, z+32, b, ms);
		world.setBlock(x+18, y+5, z+33, b, ms);
		world.setBlock(x+18, y+5, z+34, b, ms);
		world.setBlock(x+18, y+5, z+35, b, ms);
		world.setBlock(x+18, y+5, z+36, b, ms);
		world.setBlock(x+18, y+5, z+37, b, ms);
		world.setBlock(x+18, y+5, z+38, b, ms);
		world.setBlock(x+18, y+5, z+39, b, ms);
		world.setBlock(x+18, y+5, z+40, b, ms);
		world.setBlock(x+18, y+5, z+41, b, ms);
		world.setBlock(x+18, y+5, z+42, b, ms);
		world.setBlock(x+18, y+5, z+43, b, ms);
		world.setBlock(x+18, y+5, z+44, b, ms);
		world.setBlock(x+18, y+5, z+45, b, ms);
		world.setBlock(x+19, y+0, z+1, b, ms);
		world.setBlock(x+19, y+0, z+2, b, ms);
		world.setBlock(x+19, y+0, z+3, b, ms);
		world.setBlock(x+19, y+0, z+4, b, ms);
		world.setBlock(x+19, y+0, z+5, b, ms);
		world.setBlock(x+19, y+0, z+6, b, ms);
		world.setBlock(x+19, y+0, z+7, b, ms);
		world.setBlock(x+19, y+0, z+8, b, ms);
		world.setBlock(x+19, y+0, z+9, b, ms);
		world.setBlock(x+19, y+0, z+10, b, ms);
		world.setBlock(x+19, y+0, z+11, b, ms);
		world.setBlock(x+19, y+0, z+12, b, ms);
		world.setBlock(x+19, y+0, z+13, b, ms);
		world.setBlock(x+19, y+0, z+14, b, ms);
		world.setBlock(x+19, y+0, z+15, b, ms);
		world.setBlock(x+19, y+0, z+16, b, ms);
		world.setBlock(x+19, y+0, z+17, b, ms);
		world.setBlock(x+19, y+0, z+18, b, ms);
		world.setBlock(x+19, y+0, z+19, b, ms);
		world.setBlock(x+19, y+0, z+20, b, ms);
		world.setBlock(x+19, y+0, z+21, b, ms);
		world.setBlock(x+19, y+0, z+22, b, ms);
		world.setBlock(x+19, y+0, z+23, b, ms);
		world.setBlock(x+19, y+0, z+24, b, ms);
		world.setBlock(x+19, y+0, z+25, b, ms);
		world.setBlock(x+19, y+0, z+26, b, ms);
		world.setBlock(x+19, y+0, z+27, b, ms);
		world.setBlock(x+19, y+0, z+28, b, ms);
		world.setBlock(x+19, y+0, z+29, b, ms);
		world.setBlock(x+19, y+0, z+30, b, ms);
		world.setBlock(x+19, y+0, z+31, b, ms);
		world.setBlock(x+19, y+0, z+32, b, ms);
		world.setBlock(x+19, y+0, z+33, b, ms);
		world.setBlock(x+19, y+0, z+34, b, ms);
		world.setBlock(x+19, y+0, z+35, b, ms);
		world.setBlock(x+19, y+0, z+36, b, ms);
		world.setBlock(x+19, y+0, z+37, b, ms);
		world.setBlock(x+19, y+0, z+38, b, ms);
		world.setBlock(x+19, y+0, z+39, b, ms);
		world.setBlock(x+19, y+0, z+40, b, ms);
		world.setBlock(x+19, y+0, z+41, b, ms);
		world.setBlock(x+19, y+0, z+42, b, ms);
		world.setBlock(x+19, y+0, z+43, b, mc);
		world.setBlock(x+19, y+0, z+44, b, ms);
		world.setBlock(x+19, y+0, z+45, b, ms);
		world.setBlock(x+19, y+1, z+1, b, ms);
		world.setBlock(x+19, y+1, z+9, b, ms);
		world.setBlock(x+19, y+1, z+19, b, ms);
		world.setBlock(x+19, y+1, z+20, b, ms);
		world.setBlock(x+19, y+1, z+24, b, ms);
		world.setBlock(x+19, y+1, z+28, b, ms);
		world.setBlock(x+19, y+1, z+32, b, ms);
		world.setBlock(x+19, y+1, z+36, b, ms);
		world.setBlock(x+19, y+1, z+41, b, ms);
		world.setBlock(x+19, y+1, z+45, b, ms);
		world.setBlock(x+19, y+2, z+1, b, ms);
		world.setBlock(x+19, y+2, z+9, b, ms);
		world.setBlock(x+19, y+2, z+19, b, ml);
		world.setBlock(x+19, y+2, z+20, b, ms);
		world.setBlock(x+19, y+2, z+24, b, ms);
		world.setBlock(x+19, y+2, z+28, b, ms);
		world.setBlock(x+19, y+2, z+32, b, ms);
		world.setBlock(x+19, y+2, z+36, b, ms);
		world.setBlock(x+19, y+2, z+41, b, ml);
		world.setBlock(x+19, y+2, z+45, b, ms);
		world.setBlock(x+19, y+3, z+1, b, ms);
		world.setBlock(x+19, y+3, z+9, b, ms);
		world.setBlock(x+19, y+3, z+19, b, ms);
		world.setBlock(x+19, y+3, z+20, b, ms);
		world.setBlock(x+19, y+3, z+24, b, ms);
		world.setBlock(x+19, y+3, z+28, b, ms);
		world.setBlock(x+19, y+3, z+32, b, ms);
		world.setBlock(x+19, y+3, z+36, b, ms);
		world.setBlock(x+19, y+3, z+41, b, ms);
		world.setBlock(x+19, y+3, z+45, b, ms);
		world.setBlock(x+19, y+4, z+1, b, ms);
		world.setBlock(x+19, y+4, z+9, b, ms);
		world.setBlock(x+19, y+4, z+19, b, ms);
		world.setBlock(x+19, y+4, z+20, b, ms);
		world.setBlock(x+19, y+4, z+21, b, ms);
		world.setBlock(x+19, y+4, z+22, b, ms);
		world.setBlock(x+19, y+4, z+23, b, ms);
		world.setBlock(x+19, y+4, z+24, b, ms);
		world.setBlock(x+19, y+4, z+25, b, ms);
		world.setBlock(x+19, y+4, z+26, b, ms);
		world.setBlock(x+19, y+4, z+27, b, ms);
		world.setBlock(x+19, y+4, z+28, b, ms);
		world.setBlock(x+19, y+4, z+29, b, ms);
		world.setBlock(x+19, y+4, z+30, b, ms);
		world.setBlock(x+19, y+4, z+31, b, ms);
		world.setBlock(x+19, y+4, z+32, b, ms);
		world.setBlock(x+19, y+4, z+33, b, ms);
		world.setBlock(x+19, y+4, z+34, b, ms);
		world.setBlock(x+19, y+4, z+35, b, ms);
		world.setBlock(x+19, y+4, z+36, b, ms);
		world.setBlock(x+19, y+4, z+41, b, ms);
		world.setBlock(x+19, y+4, z+45, b, ms);
		world.setBlock(x+19, y+5, z+1, b, ms);
		world.setBlock(x+19, y+5, z+2, b, ms);
		world.setBlock(x+19, y+5, z+3, b, ms);
		world.setBlock(x+19, y+5, z+4, b, ms);
		world.setBlock(x+19, y+5, z+5, b, ms);
		world.setBlock(x+19, y+5, z+6, b, ms);
		world.setBlock(x+19, y+5, z+7, b, ms);
		world.setBlock(x+19, y+5, z+8, b, ms);
		world.setBlock(x+19, y+5, z+9, b, ms);
		world.setBlock(x+19, y+5, z+10, b, ms);
		world.setBlock(x+19, y+5, z+11, b, ms);
		world.setBlock(x+19, y+5, z+12, b, ms);
		world.setBlock(x+19, y+5, z+13, b, ms);
		world.setBlock(x+19, y+5, z+14, b, ms);
		world.setBlock(x+19, y+5, z+15, b, ms);
		world.setBlock(x+19, y+5, z+16, b, ms);
		world.setBlock(x+19, y+5, z+17, b, ms);
		world.setBlock(x+19, y+5, z+18, b, ms);
		world.setBlock(x+19, y+5, z+19, b, ms);
		world.setBlock(x+19, y+5, z+20, b, ms);
		world.setBlock(x+19, y+5, z+21, b, ms);
		world.setBlock(x+19, y+5, z+22, b, ms);
		world.setBlock(x+19, y+5, z+23, b, ms);
		world.setBlock(x+19, y+5, z+24, b, ms);
		world.setBlock(x+19, y+5, z+25, b, ms);
		world.setBlock(x+19, y+5, z+26, b, ms);
		world.setBlock(x+19, y+5, z+27, b, ms);
		world.setBlock(x+19, y+5, z+28, b, ms);
		world.setBlock(x+19, y+5, z+29, b, ms);
		world.setBlock(x+19, y+5, z+30, b, ms);
		world.setBlock(x+19, y+5, z+31, b, ms);
		world.setBlock(x+19, y+5, z+32, b, ms);
		world.setBlock(x+19, y+5, z+33, b, ms);
		world.setBlock(x+19, y+5, z+34, b, ms);
		world.setBlock(x+19, y+5, z+35, b, ms);
		world.setBlock(x+19, y+5, z+36, b, ms);
		world.setBlock(x+19, y+5, z+37, b, ms);
		world.setBlock(x+19, y+5, z+38, b, ms);
		world.setBlock(x+19, y+5, z+39, b, ms);
		world.setBlock(x+19, y+5, z+40, b, ms);
		world.setBlock(x+19, y+5, z+41, b, ms);
		world.setBlock(x+19, y+5, z+42, b, ms);
		world.setBlock(x+19, y+5, z+43, b, ms);
		world.setBlock(x+19, y+5, z+44, b, ms);
		world.setBlock(x+19, y+5, z+45, b, ms);
		world.setBlock(x+20, y+0, z+1, b, ms);
		world.setBlock(x+20, y+0, z+2, b, ms);
		world.setBlock(x+20, y+0, z+3, b, ms);
		world.setBlock(x+20, y+0, z+4, b, ms);
		world.setBlock(x+20, y+0, z+5, b, ms);
		world.setBlock(x+20, y+0, z+6, b, ms);
		world.setBlock(x+20, y+0, z+7, b, ms);
		world.setBlock(x+20, y+0, z+8, b, ms);
		world.setBlock(x+20, y+0, z+9, b, ms);
		world.setBlock(x+20, y+0, z+10, b, ms);
		world.setBlock(x+20, y+0, z+11, b, ms);
		world.setBlock(x+20, y+0, z+12, b, ms);
		world.setBlock(x+20, y+0, z+13, b, ms);
		world.setBlock(x+20, y+0, z+14, b, ms);
		world.setBlock(x+20, y+0, z+15, b, ms);
		world.setBlock(x+20, y+0, z+16, b, ms);
		world.setBlock(x+20, y+0, z+17, b, ms);
		world.setBlock(x+20, y+0, z+18, b, ms);
		world.setBlock(x+20, y+0, z+19, b, ms);
		world.setBlock(x+20, y+0, z+20, b, ms);
		world.setBlock(x+20, y+0, z+21, b, ms);
		this.generateRune(x+20, y+0, z+22, LockColor.PURPLE);
		world.setBlock(x+20, y+0, z+23, b, ms);
		world.setBlock(x+20, y+0, z+24, b, ms);
		world.setBlock(x+20, y+0, z+25, b, ms);
		this.generateRune(x+20, y+0, z+26, LockColor.GREEN);
		world.setBlock(x+20, y+0, z+27, b, ms);
		world.setBlock(x+20, y+0, z+28, b, ms);
		world.setBlock(x+20, y+0, z+29, b, ms);
		world.setBlock(x+20, y+0, z+30, b, ms);
		world.setBlock(x+20, y+0, z+31, b, ms);
		world.setBlock(x+20, y+0, z+32, b, ms);
		world.setBlock(x+20, y+0, z+33, b, ms);
		this.generateRune(x+20, y+0, z+34, LockColor.BLUE);
		world.setBlock(x+20, y+0, z+35, b, ms);
		world.setBlock(x+20, y+0, z+36, b, ms);
		world.setBlock(x+20, y+0, z+37, b, ms);
		world.setBlock(x+20, y+0, z+38, b, ms);
		world.setBlock(x+20, y+0, z+39, b, ms);
		world.setBlock(x+20, y+0, z+40, b, ms);
		world.setBlock(x+20, y+0, z+41, b, ms);
		world.setBlock(x+20, y+0, z+42, b, ms);
		world.setBlock(x+20, y+0, z+43, b, ms);
		world.setBlock(x+20, y+0, z+44, b, ms);
		world.setBlock(x+20, y+0, z+45, b, ms);
		world.setBlock(x+20, y+1, z+1, b, ms);
		world.setBlock(x+20, y+1, z+9, b, ms);
		world.setBlock(x+20, y+1, z+10, b, ms);
		world.setBlock(x+20, y+1, z+11, b, ms);
		world.setBlock(x+20, y+1, z+12, b, ms);
		world.setBlock(x+20, y+1, z+13, b, ms);
		world.setBlock(x+20, y+1, z+14, b, ms);
		world.setBlock(x+20, y+1, z+15, b, ms);
		world.setBlock(x+20, y+1, z+16, b, ms);
		world.setBlock(x+20, y+1, z+17, b, ms);
		world.setBlock(x+20, y+1, z+18, b, ms);
		world.setBlock(x+20, y+1, z+19, b, ms);
		world.setBlock(x+20, y+1, z+20, b, ms);
		world.setBlock(x+20, y+1, z+24, b, ms);
		world.setBlock(x+20, y+1, z+28, b, ms);
		world.setBlock(x+20, y+1, z+32, b, ms);
		world.setBlock(x+20, y+1, z+36, b, ms);
		world.setBlock(x+20, y+1, z+41, b, ms);
		world.setBlock(x+20, y+1, z+45, b, ms);
		world.setBlock(x+20, y+2, z+1, b, ms);
		world.setBlock(x+20, y+2, z+9, b, ml);
		world.setBlock(x+20, y+2, z+10, b, ms);
		world.setBlock(x+20, y+2, z+11, b, ms);
		world.setBlock(x+20, y+2, z+13, b, ms);
		world.setBlock(x+20, y+2, z+14, b, ml);
		world.setBlock(x+20, y+2, z+15, b, ms);
		world.setBlock(x+20, y+2, z+17, b, ms);
		world.setBlock(x+20, y+2, z+18, b, ms);
		world.setBlock(x+20, y+2, z+19, b, ms);
		world.setBlock(x+20, y+2, z+20, b, ms);
		world.setBlock(x+20, y+2, z+24, b, ml);
		world.setBlock(x+20, y+2, z+28, b, ml);
		world.setBlock(x+20, y+2, z+32, b, ml);
		world.setBlock(x+20, y+2, z+36, b, ml);
		world.setBlock(x+20, y+2, z+41, b, ms);
		world.setBlock(x+20, y+2, z+45, b, ms);
		world.setBlock(x+20, y+3, z+1, b, ms);
		world.setBlock(x+20, y+3, z+9, b, ms);
