/*******************************************************************************
 * @author Reika Kalseki
 * 
 * Copyright 2017
 * 
 * All rights reserved.
 * Distribution of the software in any form is only allowed with
 * explicit, prior permission from the owner.
 ******************************************************************************/
package Reika.ChromatiCraft.World.Dimension.Structure.Locks;

import net.minecraft.block.Block;
import net.minecraft.init.Blocks;

import Reika.ChromatiCraft.Base.LockLevel;
import Reika.ChromatiCraft.Block.Dimension.Structure.Locks.BlockLockKey.LockChannel;
import Reika.ChromatiCraft.Block.Worldgen.BlockStructureShield.BlockType;
import Reika.ChromatiCraft.Registry.ChromaBlocks;
import Reika.ChromatiCraft.World.Dimension.Structure.LocksGenerator;
import Reika.DragonAPI.Instantiable.Worldgen.OriginBlockCache;

public class LocksRoomEntry extends LockLevel {

	public LocksRoomEntry(LocksGenerator g) {
		super(g, LockChannel.ENTRY);
	}

	@Override
	public void generate(OriginBlockCache world, int x, int y, int z) {
		Block b = ChromaBlocks.STRUCTSHIELD.getBlockInstance();
		int ms = BlockType.STONE.metadata;
		int ml = BlockType.LIGHT.metadata;
		int mc = BlockType.CLOAK.metadata;
		this.generate1(world, x, y, z, b, ms, ml, mc);
		this.generate2(world, x, y, z, b, ms, ml, mc);
	}

	private void generate1(OriginBlockCache world, int x, int y, int z, Block b, int ms, int ml, int mc) {
		world.setBlock(x+0, y+0, z+2, b, ms);
		world.setBlock(x+0, y+0, z+3, b, ms);
		world.setBlock(x+0, y+0, z+4, b, ms);
		world.setBlock(x+0, y+0, z+5, b, ms);
		world.setBlock(x+0, y+0, z+6, b, ms);
		world.setBlock(x+0, y+0, z+7, b, ms);
		world.setBlock(x+0, y+0, z+8, b, ms);
		world.setBlock(x+0, y+0, z+13, b, ms);
		world.setBlock(x+0, y+0, z+14, b, ms);
		world.setBlock(x+0, y+0, z+15, b, ms);
		world.setBlock(x+0, y+0, z+16, b, ms);
		world.setBlock(x+0, y+0, z+17, b, ms);
		world.setBlock(x+0, y+0, z+18, b, ms);
		world.setBlock(x+0, y+0, z+19, b, ms);
		world.setBlock(x+0, y+1, z+2, b, ms);
		world.setBlock(x+0, y+1, z+3, b, ms);
		world.setBlock(x+0, y+1, z+4, b, ms);
		world.setBlock(x+0, y+1, z+5, b, ms);
		world.setBlock(x+0, y+1, z+6, b, ms);
		world.setBlock(x+0, y+1, z+7, b, ms);
		world.setBlock(x+0, y+1, z+8, b, ms);
		world.setBlock(x+0, y+1, z+13, b, ms);
		world.setBlock(x+0, y+1, z+14, b, ms);
		world.setBlock(x+0, y+1, z+15, b, ms);
		world.setBlock(x+0, y+1, z+16, b, ms);
		world.setBlock(x+0, y+1, z+17, b, ms);
		world.setBlock(x+0, y+1, z+18, b, ms);
		world.setBlock(x+0, y+1, z+19, b, ms);
		world.setBlock(x+0, y+2, z+2, b, ms);
		world.setBlock(x+0, y+2, z+3, b, ms);
		world.setBlock(x+0, y+2, z+4, b, ms);
		world.setBlock(x+0, y+2, z+5, b, ml);
		world.setBlock(x+0, y+2, z+6, b, ms);
		world.setBlock(x+0, y+2, z+7, b, ms);
		world.setBlock(x+0, y+2, z+8, b, ms);
		world.setBlock(x+0, y+2, z+13, b, ms);
		world.setBlock(x+0, y+2, z+14, b, ms);
		world.setBlock(x+0, y+2, z+15, b, ms);
		world.setBlock(x+0, y+2, z+16, b, ml);
		world.setBlock(x+0, y+2, z+17, b, ms);
		world.setBlock(x+0, y+2, z+18, b, ms);
		world.setBlock(x+0, y+2, z+19, b, ms);
		world.setBlock(x+0, y+3, z+2, b, ms);
		world.setBlock(x+0, y+3, z+3, b, ms);
		world.setBlock(x+0, y+3, z+4, b, ms);
		world.setBlock(x+0, y+3, z+5, b, ms);
		world.setBlock(x+0, y+3, z+6, b, ms);
		world.setBlock(x+0, y+3, z+7, b, ms);
		world.setBlock(x+0, y+3, z+8, b, ms);
		world.setBlock(x+0, y+3, z+13, b, ms);
		world.setBlock(x+0, y+3, z+14, b, ms);
		world.setBlock(x+0, y+3, z+15, b, ms);
		world.setBlock(x+0, y+3, z+16, b, ms);
		world.setBlock(x+0, y+3, z+17, b, ms);
		world.setBlock(x+0, y+3, z+18, b, ms);
		world.setBlock(x+0, y+3, z+19, b, ms);
		world.setBlock(x+0, y+4, z+2, b, ms);
		world.setBlock(x+0, y+4, z+3, b, ms);
		world.setBlock(x+0, y+4, z+4, b, ms);
		world.setBlock(x+0, y+4, z+5, b, ms);
		world.setBlock(x+0, y+4, z+6, b, ms);
		world.setBlock(x+0, y+4, z+7, b, ms);
		world.setBlock(x+0, y+4, z+8, b, ms);
		world.setBlock(x+0, y+4, z+13, b, ms);
		world.setBlock(x+0, y+4, z+14, b, ms);
		world.setBlock(x+0, y+4, z+15, b, ms);
		world.setBlock(x+0, y+4, z+16, b, ms);
		world.setBlock(x+0, y+4, z+17, b, ms);
		world.setBlock(x+0, y+4, z+18, b, ms);
		world.setBlock(x+0, y+4, z+19, b, ms);
		world.setBlock(x+0, y+5, z+2, b, ms);
		world.setBlock(x+0, y+5, z+3, b, ms);
		world.setBlock(x+0, y+5, z+4, b, ms);
		world.setBlock(x+0, y+5, z+5, b, ms);
		world.setBlock(x+0, y+5, z+6, b, ms);
		world.setBlock(x+0, y+5, z+7, b, ms);
		world.setBlock(x+0, y+5, z+8, b, ms);
		world.setBlock(x+0, y+5, z+13, b, ms);
		world.setBlock(x+0, y+5, z+14, b, ms);
		world.setBlock(x+0, y+5, z+15, b, ms);
		world.setBlock(x+0, y+5, z+16, b, ms);
		world.setBlock(x+0, y+5, z+17, b, ms);
		world.setBlock(x+0, y+5, z+18, b, ms);
		world.setBlock(x+0, y+5, z+19, b, ms);
		world.setBlock(x+1, y+0, z+2, b, ms);
		world.setBlock(x+1, y+0, z+3, b, ms);
		world.setBlock(x+1, y+0, z+4, b, ms);
		world.setBlock(x+1, y+0, z+5, b, ms);
		world.setBlock(x+1, y+0, z+6, b, ms);
		world.setBlock(x+1, y+0, z+7, b, ms);
		world.setBlock(x+1, y+0, z+8, b, ms);
		world.setBlock(x+1, y+0, z+13, b, ms);
		world.setBlock(x+1, y+0, z+14, b, ms);
		world.setBlock(x+1, y+0, z+15, b, ms);
		world.setBlock(x+1, y+0, z+16, b, ms);
		world.setBlock(x+1, y+0, z+17, b, ms);
		world.setBlock(x+1, y+0, z+18, b, ms);
		world.setBlock(x+1, y+0, z+19, b, ms);
		world.setBlock(x+1, y+1, z+2, b, ms);
		world.setBlock(x+1, y+1, z+8, b, ms);
		world.setBlock(x+1, y+1, z+13, b, ms);
		world.setBlock(x+1, y+1, z+19, b, ms);
		world.setBlock(x+1, y+2, z+2, b, ms);
		world.setBlock(x+1, y+2, z+8, b, ms);
		world.setBlock(x+1, y+2, z+13, b, ms);
		world.setBlock(x+1, y+2, z+19, b, ms);
		world.setBlock(x+1, y+3, z+2, b, ms);
		world.setBlock(x+1, y+3, z+8, b, ms);
		world.setBlock(x+1, y+3, z+13, b, ms);
		world.setBlock(x+1, y+3, z+19, b, ms);
		world.setBlock(x+1, y+4, z+2, b, ms);
		world.setBlock(x+1, y+4, z+8, b, ms);
		world.setBlock(x+1, y+4, z+13, b, ms);
		world.setBlock(x+1, y+4, z+19, b, ms);
		world.setBlock(x+1, y+5, z+2, b, ms);
		world.setBlock(x+1, y+5, z+3, b, ms);
		world.setBlock(x+1, y+5, z+4, b, ms);
		world.setBlock(x+1, y+5, z+5, b, ms);
		world.setBlock(x+1, y+5, z+6, b, ms);
		world.setBlock(x+1, y+5, z+7, b, ms);
		world.setBlock(x+1, y+5, z+8, b, ms);
		world.setBlock(x+1, y+5, z+13, b, ms);
		world.setBlock(x+1, y+5, z+14, b, ms);
		world.setBlock(x+1, y+5, z+15, b, ms);
		world.setBlock(x+1, y+5, z+16, b, ms);
		world.setBlock(x+1, y+5, z+17, b, ms);
		world.setBlock(x+1, y+5, z+18, b, ms);
		world.setBlock(x+1, y+5, z+19, b, ms);
		world.setBlock(x+2, y+0, z+2, b, ms);
		world.setBlock(x+2, y+0, z+3, b, ms);
		world.setBlock(x+2, y+0, z+4, b, ms);
		world.setBlock(x+2, y+0, z+5, b, ms);
		world.setBlock(x+2, y+0, z+6, b, ms);
		world.setBlock(x+2, y+0, z+7, b, ms);
		world.setBlock(x+2, y+0, z+8, b, ms);
		world.setBlock(x+2, y+0, z+13, b, ms);
		world.setBlock(x+2, y+0, z+14, b, ms);
		world.setBlock(x+2, y+0, z+15, b, ms);
		world.setBlock(x+2, y+0, z+16, b, ms);
		world.setBlock(x+2, y+0, z+17, b, ms);
		world.setBlock(x+2, y+0, z+18, b, ms);
		world.setBlock(x+2, y+0, z+19, b, ms);
		world.setBlock(x+2, y+1, z+2, b, ms);
		world.setBlock(x+2, y+1, z+8, b, ms);
		world.setBlock(x+2, y+1, z+13, b, ms);
		world.setBlock(x+2, y+1, z+19, b, ms);
		world.setBlock(x+2, y+2, z+2, b, ms);
		world.setBlock(x+2, y+2, z+8, b, ms);
		world.setBlock(x+2, y+2, z+13, b, ms);
		world.setBlock(x+2, y+2, z+19, b, ms);
		world.setBlock(x+2, y+3, z+2, b, ms);
		world.setBlock(x+2, y+3, z+8, b, ms);
		world.setBlock(x+2, y+3, z+13, b, ms);
		world.setBlock(x+2, y+3, z+19, b, ms);
		world.setBlock(x+2, y+4, z+2, b, ms);
		world.setBlock(x+2, y+4, z+8, b, ms);
		world.setBlock(x+2, y+4, z+13, b, ms);
		world.setBlock(x+2, y+4, z+19, b, ms);
		world.setBlock(x+2, y+5, z+2, b, ms);
		world.setBlock(x+2, y+5, z+3, b, ms);
		world.setBlock(x+2, y+5, z+4, b, ms);
		world.setBlock(x+2, y+5, z+5, b, ms);
		world.setBlock(x+2, y+5, z+6, b, ms);
		world.setBlock(x+2, y+5, z+7, b, ms);
		world.setBlock(x+2, y+5, z+8, b, ms);
		world.setBlock(x+2, y+5, z+13, b, ms);
		world.setBlock(x+2, y+5, z+14, b, ms);
		world.setBlock(x+2, y+5, z+15, b, ms);
		world.setBlock(x+2, y+5, z+16, b, ms);
		world.setBlock(x+2, y+5, z+17, b, ms);
		world.setBlock(x+2, y+5, z+18, b, ms);
		world.setBlock(x+2, y+5, z+19, b, ms);
		world.setBlock(x+3, y+0, z+1, b, ms);
		world.setBlock(x+3, y+0, z+2, b, ms);
		world.setBlock(x+3, y+0, z+3, b, ms);
		world.setBlock(x+3, y+0, z+4, b, ms);
		this.generateRune(x+3, y+0, z+5, LockColor.BLUE);
		world.setBlock(x+3, y+0, z+6, b, ms);
		world.setBlock(x+3, y+0, z+7, b, ms);
		world.setBlock(x+3, y+0, z+8, b, ms);
		world.setBlock(x+3, y+0, z+13, b, ms);
		world.setBlock(x+3, y+0, z+14, b, ms);
		world.setBlock(x+3, y+0, z+15, b, ms);
		this.generateRune(x+3, y+0, z+16, LockColor.RED);
		world.setBlock(x+3, y+0, z+17, b, ms);
		world.setBlock(x+3, y+0, z+18, b, ms);
		world.setBlock(x+3, y+0, z+19, b, ms);
		world.setBlock(x+3, y+0, z+20, b, ms);
		world.setBlock(x+3, y+0, z+21, b, ms);
		world.setBlock(x+3, y+0, z+22, b, ms);
		world.setBlock(x+3, y+0, z+23, b, ms);
		world.setBlock(x+3, y+0, z+24, b, ms);
		world.setBlock(x+3, y+0, z+25, b, ms);
		world.setBlock(x+3, y+0, z+26, b, ms);
		world.setBlock(x+3, y+0, z+27, b, ms);
		world.setBlock(x+3, y+0, z+28, b, ms);
		world.setBlock(x+3, y+0, z+29, b, ms);
		world.setBlock(x+3, y+1, z+1, b, ms);
		world.setBlock(x+3, y+1, z+2, b, ms);
		this.generateKey(x+3, y+1, z+6);
		world.setBlock(x+3, y+1, z+8, b, ms);
		world.setBlock(x+3, y+1, z+13, b, ms);
		world.setBlock(x+3, y+1, z+19, b, ms);
		world.setBlock(x+3, y+1, z+20, b, ms);
		world.setBlock(x+3, y+1, z+21, b, ms);
		world.setBlock(x+3, y+1, z+22, b, ms);
		world.setBlock(x+3, y+1, z+23, b, ms);
		world.setBlock(x+3, y+1, z+24, b, ms);
		world.setBlock(x+3, y+1, z+25, b, ms);
		world.setBlock(x+3, y+1, z+26, b, ms);
		world.setBlock(x+3, y+1, z+27, b, ms);
		world.setBlock(x+3, y+1, z+28, b, ms);
		world.setBlock(x+3, y+1, z+29, b, ms);
		world.setBlock(x+3, y+2, z+1, b, ms);
		world.setBlock(x+3, y+2, z+2, b, ml);
		world.setBlock(x+3, y+2, z+8, b, ms);
		world.setBlock(x+3, y+2, z+13, b, ms);
		world.setBlock(x+3, y+2, z+19, b, ms);
		world.setBlock(x+3, y+2, z+20, b, ms);
		world.setBlock(x+3, y+2, z+21, b, ms);
		world.setBlock(x+3, y+2, z+22, b, ms);
		world.setBlock(x+3, y+2, z+23, b, ms);
		world.setBlock(x+3, y+2, z+24, b, ml);
		world.setBlock(x+3, y+2, z+25, b, ms);
		world.setBlock(x+3, y+2, z+26, b, ms);
		world.setBlock(x+3, y+2, z+27, b, ms);
		world.setBlock(x+3, y+2, z+28, b, ms);
		world.setBlock(x+3, y+2, z+29, b, ms);
		world.setBlock(x+3, y+3, z+1, b, ms);
		world.setBlock(x+3, y+3, z+2, b, ms);
		world.setBlock(x+3, y+3, z+8, b, ms);
		world.setBlock(x+3, y+3, z+13, b, ms);
		world.setBlock(x+3, y+3, z+19, b, ms);
		world.setBlock(x+3, y+3, z+20, b, ms);
		world.setBlock(x+3, y+3, z+21, b, ms);
		world.setBlock(x+3, y+3, z+22, b, ms);
		world.setBlock(x+3, y+3, z+23, b, ms);
		world.setBlock(x+3, y+3, z+24, b, ms);
		world.setBlock(x+3, y+3, z+25, b, ms);
		world.setBlock(x+3, y+3, z+26, b, ms);
		world.setBlock(x+3, y+3, z+27, b, ms);
		world.setBlock(x+3, y+3, z+28, b, ms);
		world.setBlock(x+3, y+3, z+29, b, ms);
		world.setBlock(x+3, y+4, z+1, b, ms);
		world.setBlock(x+3, y+4, z+2, b, ms);
		world.setBlock(x+3, y+4, z+8, b, ms);
		world.setBlock(x+3, y+4, z+13, b, ms);
		world.setBlock(x+3, y+4, z+19, b, ms);
		world.setBlock(x+3, y+4, z+20, b, ms);
		world.setBlock(x+3, y+4, z+21, b, ms);
		world.setBlock(x+3, y+4, z+22, b, ms);
		world.setBlock(x+3, y+4, z+23, b, ms);
		world.setBlock(x+3, y+4, z+24, b, ms);
		world.setBlock(x+3, y+4, z+25, b, ms);
		world.setBlock(x+3, y+4, z+26, b, ms);
		world.setBlock(x+3, y+4, z+27, b, ms);
		world.setBlock(x+3, y+4, z+28, b, ms);
		world.setBlock(x+3, y+4, z+29, b, ms);
		world.setBlock(x+3, y+5, z+1, b, ms);
		world.setBlock(x+3, y+5, z+2, b, ms);
		world.setBlock(x+3, y+5, z+3, b, ms);
		world.setBlock(x+3, y+5, z+4, b, ms);
		world.setBlock(x+3, y+5, z+5, b, ms);
		world.setBlock(x+3, y+5, z+6, b, ms);
		world.setBlock(x+3, y+5, z+7, b, ms);
		world.setBlock(x+3, y+5, z+8, b, ms);
		world.setBlock(x+3, y+5, z+13, b, ms);
		world.setBlock(x+3, y+5, z+14, b, ms);
		world.setBlock(x+3, y+5, z+15, b, ms);
		world.setBlock(x+3, y+5, z+16, b, ms);
		world.setBlock(x+3, y+5, z+17, b, ms);
		world.setBlock(x+3, y+5, z+18, b, ms);
		world.setBlock(x+3, y+5, z+19, b, ms);
		world.setBlock(x+3, y+5, z+20, b, ms);
		world.setBlock(x+3, y+5, z+21, b, ms);
		world.setBlock(x+3, y+5, z+22, b, ms);
		world.setBlock(x+3, y+5, z+23, b, ms);
		world.setBlock(x+3, y+5, z+24, b, ms);
		world.setBlock(x+3, y+5, z+25, b, ms);
		world.setBlock(x+3, y+5, z+26, b, ms);
		world.setBlock(x+3, y+5, z+27, b, ms);
		world.setBlock(x+3, y+5, z+28, b, ms);
		world.setBlock(x+3, y+5, z+29, b, ms);
		world.setBlock(x+4, y+0, z+0, b, ms);
		world.setBlock(x+4, y+0, z+1, b, ms);
		world.setBlock(x+4, y+0, z+2, b, ms);
		world.setBlock(x+4, y+0, z+3, b, ms);
		world.setBlock(x+4, y+0, z+4, b, ms);
		world.setBlock(x+4, y+0, z+5, b, ms);
		world.setBlock(x+4, y+0, z+6, b, ms);
		world.setBlock(x+4, y+0, z+7, b, ms);
		world.setBlock(x+4, y+0, z+8, b, ms);
		world.setBlock(x+4, y+0, z+9, b, ms);
		world.setBlock(x+4, y+0, z+10, b, ms);
		world.setBlock(x+4, y+0, z+11, b, ms);
		world.setBlock(x+4, y+0, z+12, b, ms);
		world.setBlock(x+4, y+0, z+13, b, ms);
		world.setBlock(x+4, y+0, z+14, b, ms);
		world.setBlock(x+4, y+0, z+15, b, ms);
		world.setBlock(x+4, y+0, z+16, b, ms);
		world.setBlock(x+4, y+0, z+17, b, ms);
		world.setBlock(x+4, y+0, z+18, b, ms);
		world.setBlock(x+4, y+0, z+19, b, ms);
		world.setBlock(x+4, y+0, z+20, b, ms);
		world.setBlock(x+4, y+0, z+21, b, ms);
		world.setBlock(x+4, y+0, z+22, b, ms);
		world.setBlock(x+4, y+0, z+23, b, ms);
		world.setBlock(x+4, y+0, z+24, b, ms);
		world.setBlock(x+4, y+0, z+25, b, ms);
		world.setBlock(x+4, y+0, z+26, b, mc);
		world.setBlock(x+4, y+0, z+27, b, ms);
		world.setBlock(x+4, y+0, z+28, b, ms);
		world.setBlock(x+4, y+0, z+29, b, ms);
		world.setBlock(x+4, y+0, z+30, b, ms);
		world.setBlock(x+4, y+1, z+0, b, ms);
		world.setBlock(x+4, y+1, z+1, b, ms);
		world.setBlock(x+4, y+1, z+8, b, ms);
		world.setBlock(x+4, y+1, z+9, b, ms);
		world.setBlock(x+4, y+1, z+10, b, ms);
		world.setBlock(x+4, y+1, z+11, b, ms);
		world.setBlock(x+4, y+1, z+12, b, ms);
		world.setBlock(x+4, y+1, z+13, b, ms);
		world.setBlock(x+4, y+1, z+19, b, ms);
		world.setBlock(x+4, y+1, z+20, b, ms);
		world.setBlock(x+4, y+1, z+21, b, ms);
		world.setBlock(x+4, y+1, z+28, b, ms);
		world.setBlock(x+4, y+1, z+29, b, ms);
		world.setBlock(x+4, y+1, z+30, b, ms);
		world.setBlock(x+4, y+2, z+0, b, ms);
		world.setBlock(x+4, y+2, z+1, b, ms);
		world.setBlock(x+4, y+2, z+8, b, ms);
		world.setBlock(x+4, y+2, z+9, b, ms);
		world.setBlock(x+4, y+2, z+10, b, ms);
		world.setBlock(x+4, y+2, z+11, b, ms);
		world.setBlock(x+4, y+2, z+12, b, ms);
		world.setBlock(x+4, y+2, z+13, b, ms);
		world.setBlock(x+4, y+2, z+19, b, ms);
		world.setBlock(x+4, y+2, z+20, b, ms);
		world.setBlock(x+4, y+2, z+21, b, ms);
		world.setBlock(x+4, y+2, z+28, b, ms);
		world.setBlock(x+4, y+2, z+29, b, ms);
		world.setBlock(x+4, y+2, z+30, b, ms);
		world.setBlock(x+4, y+3, z+0, b, ms);
		world.setBlock(x+4, y+3, z+1, b, ms);
		world.setBlock(x+4, y+3, z+8, b, ms);
		world.setBlock(x+4, y+3, z+9, b, ms);
		world.setBlock(x+4, y+3, z+10, b, ms);
		world.setBlock(x+4, y+3, z+11, b, ms);
		world.setBlock(x+4, y+3, z+12, b, ms);
		world.setBlock(x+4, y+3, z+13, b, ms);
		world.setBlock(x+4, y+3, z+19, b, ms);
		world.setBlock(x+4, y+3, z+20, b, ms);
		world.setBlock(x+4, y+3, z+21, b, ms);
		world.setBlock(x+4, y+3, z+28, b, ms);
		world.setBlock(x+4, y+3, z+29, b, ms);
		world.setBlock(x+4, y+3, z+30, b, ms);
		world.setBlock(x+4, y+4, z+0, b, ms);
		world.setBlock(x+4, y+4, z+1, b, ms);
		world.setBlock(x+4, y+4, z+8, b, ms);
		world.setBlock(x+4, y+4, z+9, b, ms);
		world.setBlock(x+4, y+4, z+10, b, ms);
		world.setBlock(x+4, y+4, z+11, b, ms);
		world.setBlock(x+4, y+4, z+12, b, ms);
		world.setBlock(x+4, y+4, z+13, b, ms);
		world.setBlock(x+4, y+4, z+19, b, ms);
		world.setBlock(x+4, y+4, z+20, b, ms);
		world.setBlock(x+4, y+4, z+21, b, ms);
		world.setBlock(x+4, y+4, z+28, b, ms);
		world.setBlock(x+4, y+4, z+29, b, ms);
		world.setBlock(x+4, y+4, z+30, b, ms);
		world.setBlock(x+4, y+5, z+1, b, ms);
		world.setBlock(x+4, y+5, z+2, b, ms);
		world.setBlock(x+4, y+5, z+3, b, ms);
		world.setBlock(x+4, y+5, z+4, b, ms);
		world.setBlock(x+4, y+5, z+5, b, ms);
		world.setBlock(x+4, y+5, z+6, b, ms);
		world.setBlock(x+4, y+5, z+7, b, ms);
		world.setBlock(x+4, y+5, z+8, b, ms);
		world.setBlock(x+4, y+5, z+9, b, ms);
		world.setBlock(x+4, y+5, z+10, b, ms);
		world.setBlock(x+4, y+5, z+11, b, ms);
		world.setBlock(x+4, y+5, z+12, b, ms);
		world.setBlock(x+4, y+5, z+13, b, ms);
		world.setBlock(x+4, y+5, z+14, b, ms);
		world.setBlock(x+4, y+5, z+15, b, ms);
		world.setBlock(x+4, y+5, z+16, b, ms);
		world.setBlock(x+4, y+5, z+17, b, ms);
		world.setBlock(x+4, y+5, z+18, b, ms);
		world.setBlock(x+4, y+5, z+19, b, ms);
		world.setBlock(x+4, y+5, z+20, b, ms);
		world.setBlock(x+4, y+5, z+21, b, ms);
		world.setBlock(x+4, y+5, z+22, b, ms);
		world.setBlock(x+4, y+5, z+23, b, ms);
		world.setBlock(x+4, y+5, z+24, b, ms);
		world.setBlock(x+4, y+5, z+25, b, ms);
		world.setBlock(x+4, y+5, z+26, b, ms);
		world.setBlock(x+4, y+5, z+27, b, ms);
		world.setBlock(x+4, y+5, z+28, b, ms);
		world.setBlock(x+4, y+5, z+29, b, ms);
		world.setBlock(x+5, y+0, z+0, b, ms);
		world.setBlock(x+5, y+0, z+1, b, ms);
		world.setBlock(x+5, y+0, z+2, b, ms);
		world.setBlock(x+5, y+0, z+3, b, ms);
		world.setBlock(x+5, y+0, z+4, b, ms);
		world.setBlock(x+5, y+0, z+5, b, ms);
		world.setBlock(x+5, y+0, z+6, b, ms);
		world.setBlock(x+5, y+0, z+7, b, ms);
		world.setBlock(x+5, y+0, z+8, b, ms);
		world.setBlock(x+5, y+0, z+9, b, ms);
		world.setBlock(x+5, y+0, z+10, b, ms);
		world.setBlock(x+5, y+0, z+11, b, ms);
		world.setBlock(x+5, y+0, z+12, b, ms);
		world.setBlock(x+5, y+0, z+13, b, ms);
		world.setBlock(x+5, y+0, z+14, b, ms);
		world.setBlock(x+5, y+0, z+15, b, ms);
		world.setBlock(x+5, y+0, z+16, b, ms);
		world.setBlock(x+5, y+0, z+17, b, ms);
		world.setBlock(x+5, y+0, z+18, b, ms);
		world.setBlock(x+5, y+0, z+19, b, ms);
		world.setBlock(x+5, y+0, z+20, b, ms);
		world.setBlock(x+5, y+0, z+21, b, ms);
		world.setBlock(x+5, y+0, z+22, b, ms);
		world.setBlock(x+5, y+0, z+23, b, ms);
		world.setBlock(x+5, y+0, z+24, b, ms);
		world.setBlock(x+5, y+0, z+25, b, ms);
		world.setBlock(x+5, y+0, z+26, b, ms);
		world.setBlock(x+5, y+0, z+27, b, ms);
		world.setBlock(x+5, y+0, z+28, b, ms);
		world.setBlock(x+5, y+0, z+29, b, ms);
		world.setBlock(x+5, y+0, z+30, b, ms);
		this.generateLock(x+5, y+1, z+9, LockColor.RED);
		this.generateLock(x+5, y+1, z+12, LockColor.BLUE);
		this.generateLock(x+5, y+1, z+20, LockColor.GREEN);
		this.generateGate(x+5, y+1, z+29);
		this.generateLock(x+5, y+2, z+9, LockColor.RED);
		this.generateLock(x+5, y+2, z+12, LockColor.BLUE);
		this.generateLock(x+5, y+2, z+20, LockColor.GREEN);
		this.generateGate(x+5, y+2, z+29);
		this.generateLock(x+5, y+3, z+9, LockColor.RED);
		this.generateLock(x+5, y+3, z+12, LockColor.BLUE);
		this.generateLock(x+5, y+3, z+20, LockColor.GREEN);
		this.generateGate(x+5, y+3, z+29);
		world.setBlock(x+5, y+4, z+0, b, ms);
		world.setBlock(x+5, y+4, z+1, b, ms);
		world.setBlock(x+5, y+4, z+8, b, ms);
		world.setBlock(x+5, y+4, z+9, b, ms);
		world.setBlock(x+5, y+4, z+10, b, ms);
		world.setBlock(x+5, y+4, z+11, b, ms);
		world.setBlock(x+5, y+4, z+12, b, ms);
		world.setBlock(x+5, y+4, z+13, b, ms);
		world.setBlock(x+5, y+4, z+19, b, ms);
		world.setBlock(x+5, y+4, z+20, b, ms);
		world.setBlock(x+5, y+4, z+21, b, ms);
		world.setBlock(x+5, y+4, z+28, b, ms);
		world.setBlock(x+5, y+4, z+29, b, ms);
		world.setBlock(x+5, y+4, z+30, b, ms);
		world.setBlock(x+5, y+5, z+1, b, ms);
		world.setBlock(x+5, y+5, z+2, b, ms);
		world.setBlock(x+5, y+5, z+3, b, ms);
		world.setBlock(x+5, y+5, z+4, b, ms);
		world.setBlock(x+5, y+5, z+5, b, ms);
		world.setBlock(x+5, y+5, z+6, b, ms);
		world.setBlock(x+5, y+5, z+7, b, ms);
		world.setBlock(x+5, y+5, z+8, b, ms);
		world.setBlock(x+5, y+5, z+9, b, ms);
		world.setBlock(x+5, y+5, z+10, b, ms);
		world.setBlock(x+5, y+5, z+11, b, ms);
		world.setBlock(x+5, y+5, z+12, b, ms);
		world.setBlock(x+5, y+5, z+13, b, ms);
		world.setBlock(x+5, y+5, z+14, b, ms);
		world.setBlock(x+5, y+5, z+15, b, ms);
		world.setBlock(x+5, y+5, z+16, b, ms);
		world.setBlock(x+5, y+5, z+17, b, ms);
		world.setBlock(x+5, y+5, z+18, b, ms);
		world.setBlock(x+5, y+5, z+19, b, ms);
		world.setBlock(x+5, y+5, z+20, b, ms);
		world.setBlock(x+5, y+5, z+21, b, ms);
		world.setBlock(x+5, y+5, z+22, b, ms);
		world.setBlock(x+5, y+5, z+23, b, ms);
		world.setBlock(x+5, y+5, z+24, b, ms);
		world.setBlock(x+5, y+5, z+25, b, ms);
		world.setBlock(x+5, y+5, z+26, b, ms);
		world.setBlock(x+5, y+5, z+27, b, ms);
		world.setBlock(x+5, y+5, z+28, b, ms);
		world.setBlock(x+5, y+5, z+29, b, ms);
		world.setBlock(x+6, y+0, z+0, b, ms);
		world.setBlock(x+6, y+0, z+1, b, ms);
		world.setBlock(x+6, y+0, z+2, b, ms);
		world.setBlock(x+6, y+0, z+3, b, ms);
		world.setBlock(x+6, y+0, z+4, b, ms);
		world.setBlock(x+6, y+0, z+5, b, ml);
		world.setBlock(x+6, y+0, z+6, b, ms);
		world.setBlock(x+6, y+0, z+7, b, ms);
		world.setBlock(x+6, y+0, z+8, b, ms);
		world.setBlock(x+6, y+0, z+9, b, ms);
		world.setBlock(x+6, y+0, z+10, b, ms);
		world.setBlock(x+6, y+0, z+11, b, ms);
		world.setBlock(x+6, y+0, z+12, b, ms);
		world.setBlock(x+6, y+0, z+13, b, ms);
		world.setBlock(x+6, y+0, z+14, b, ms);
		world.setBlock(x+6, y+0, z+15, b, ms);
		this.generateRune(x+6, y+0, z+16, LockColor.BLUE);
		world.setBlock(x+6, y+0, z+17, b, ms);
		world.setBlock(x+6, y+0, z+18, b, ms);
		world.setBlock(x+6, y+0, z+19, b, ms);
		world.setBlock(x+6, y+0, z+20, b, ms);
		world.setBlock(x+6, y+0, z+21, b, ms);
		world.setBlock(x+6, y+0, z+22, b, ms);
		world.setBlock(x+6, y+0, z+23, b, ms);
		this.generateRune(x+6, y+0, z+24, LockColor.GREEN);
		world.setBlock(x+6, y+0, z+25, b, ms);
		world.setBlock(x+6, y+0, z+26, b, mc);
		world.setBlock(x+6, y+0, z+27, b, ms);
		world.setBlock(x+6, y+0, z+28, b, ms);
		world.setBlock(x+6, y+0, z+29, b, ms);
		world.setBlock(x+6, y+0, z+30, b, ms);
		this.generateKey(x+6, y+1, z+6);
		this.generateLock(x+6, y+1, z+9, LockColor.RED);
		this.generateLock(x+6, y+1, z+12, LockColor.BLUE);
		this.generateLock(x+6, y+1, z+20, LockColor.GREEN);
		this.generateGate(x+6, y+1, z+29);
		this.generateLock(x+6, y+2, z+9, LockColor.RED);
		this.generateLock(x+6, y+2, z+12, LockColor.BLUE);
		this.generateLock(x+6, y+2, z+20, LockColor.GREEN);
		this.generateGate(x+6, y+2, z+29);
		this.generateLock(x+6, y+3, z+9, LockColor.RED);
		this.generateLock(x+6, y+3, z+12, LockColor.BLUE);
		this.generateLock(x+6, y+3, z+20, LockColor.GREEN);
		this.generateGate(x+6, y+3, z+29);
		world.setBlock(x+6, y+4, z+0, b, ms);
		world.setBlock(x+6, y+4, z+1, b, ms);
		world.setBlock(x+6, y+4, z+8, b, ml);
		world.setBlock(x+6, y+4, z+9, b, ms);
		world.setBlock(x+6, y+4, z+10, b, ms);
		world.setBlock(x+6, y+4, z+11, b, ms);
		world.setBlock(x+6, y+4, z+12, b, ms);
		world.setBlock(x+6, y+4, z+13, b, ml);
		world.setBlock(x+6, y+4, z+19, b, ml);
		world.setBlock(x+6, y+4, z+20, b, ms);
		world.setBlock(x+6, y+4, z+21, b, ms);
		world.setBlock(x+6, y+4, z+28, b, ms);
		world.setBlock(x+6, y+4, z+29, b, ms);
		world.setBlock(x+6, y+4, z+30, b, ms);
		world.setBlock(x+6, y+5, z+1, b, ms);
		world.setBlock(x+6, y+5, z+2, b, ms);
		world.setBlock(x+6, y+5, z+3, b, ms);
		world.setBlock(x+6, y+5, z+4, b, ms);
		world.setBlock(x+6, y+5, z+5, b, ms);
		world.setBlock(x+6, y+5, z+6, b, ms);
		world.setBlock(x+6, y+5, z+7, b, ms);
		world.setBlock(x+6, y+5, z+8, b, ms);
		world.setBlock(x+6, y+5, z+9, b, ms);
		world.setBlock(x+6, y+5, z+10, b, ms);
		world.setBlock(x+6, y+5, z+11, b, ms);
		world.setBlock(x+6, y+5, z+12, b, ms);
		world.setBlock(x+6, y+5, z+13, b, ms);
		world.setBlock(x+6, y+5, z+14, b, ms);
		world.setBlock(x+6, y+5, z+15, b, ms);
		world.setBlock(x+6, y+5, z+16, b, ms);
		world.setBlock(x+6, y+5, z+17, b, ms);
		world.setBlock(x+6, y+5, z+18, b, ms);
		world.setBlock(x+6, y+5, z+19, b, ms);
		world.setBlock(x+6, y+5, z+20, b, ms);
		world.setBlock(x+6, y+5, z+21, b, ms);
		world.setBlock(x+6, y+5, z+22, b, ms);
		world.setBlock(x+6, y+5, z+23, b, ms);
		world.setBlock(x+6, y+5, z+24, b, ms);
		world.setBlock(x+6, y+5, z+25, b, ms);
		world.setBlock(x+6, y+5, z+26, b, ms);
		world.setBlock(x+6, y+5, z+27, b, ms);
		world.setBlock(x+6, y+5, z+28, b, ms);
		world.setBlock(x+6, y+5, z+29, b, ms);
		world.setBlock(x+7, y+0, z+0, b, ms);
		world.setBlock(x+7, y+0, z+1, b, ms);
		world.setBlock(x+7, y+0, z+2, b, ms);
		world.setBlock(x+7, y+0, z+3, b, ms);
		world.setBlock(x+7, y+0, z+4, b, ms);
		world.setBlock(x+7, y+0, z+5, b, ms);
		world.setBlock(x+7, y+0, z+6, b, ms);
		world.setBlock(x+7, y+0, z+7, b, ms);
		world.setBlock(x+7, y+0, z+8, b, ms);
		world.setBlock(x+7, y+0, z+9, b, ms);
		world.setBlock(x+7, y+0, z+10, b, ms);
		world.setBlock(x+7, y+0, z+11, b, ms);
		world.setBlock(x+7, y+0, z+12, b, ms);
		world.setBlock(x+7, y+0, z+13, b, ms);
		world.setBlock(x+7, y+0, z+14, b, ms);
		world.setBlock(x+7, y+0, z+15, b, ms);
		world.setBlock(x+7, y+0, z+16, b, ms);
		world.setBlock(x+7, y+0, z+17, b, ms);
		world.setBlock(x+7, y+0, z+18, b, ms);
		world.setBlock(x+7, y+0, z+19, b, ms);
		world.setBlock(x+7, y+0, z+20, b, ms);
		world.setBlock(x+7, y+0, z+21, b, ms);
		world.setBlock(x+7, y+0, z+22, b, ms);
		world.setBlock(x+7, y+0, z+23, b, ms);
		world.setBlock(x+7, y+0, z+24, b, ms);
		world.setBlock(x+7, y+0, z+25, b, ms);
		world.setBlock(x+7, y+0, z+26, b, ms);
		world.setBlock(x+7, y+0, z+27, b, ms);
		world.setBlock(x+7, y+0, z+28, b, ms);
		world.setBlock(x+7, y+0, z+29, b, ms);
		world.setBlock(x+7, y+0, z+30, b, ms);
		this.generateLock(x+7, y+1, z+9, LockColor.RED);
		this.generateLock(x+7, y+1, z+12, LockColor.BLUE);
		this.generateLock(x+7, y+1, z+20, LockColor.GREEN);
		this.generateGate(x+7, y+1, z+29);
		this.generateLock(x+7, y+2, z+9, LockColor.RED);
		this.generateLock(x+7, y+2, z+12, LockColor.BLUE);
		this.generateLock(x+7, y+2, z+20, LockColor.GREEN);
		this.generateGate(x+7, y+2, z+29);
		this.generateLock(x+7, y+3, z+9, LockColor.RED);
		this.generateLock(x+7, y+3, z+12, LockColor.BLUE);
		this.generateLock(x+7, y+3, z+20, LockColor.GREEN);
		this.generateGate(x+7, y+3, z+29);
		world.setBlock(x+7, y+4, z+0, b, ms);
		world.setBlock(x+7, y+4, z+1, b, ms);
		world.setBlock(x+7, y+4, z+8, b, ms);
		world.setBlock(x+7, y+4, z+9, b, ms);
		world.setBlock(x+7, y+4, z+10, b, ms);
		world.setBlock(x+7, y+4, z+11, b, ms);
		world.setBlock(x+7, y+4, z+12, b, ms);
		world.setBlock(x+7, y+4, z+13, b, ms);
		world.setBlock(x+7, y+4, z+19, b, ms);
		world.setBlock(x+7, y+4, z+20, b, ms);
		world.setBlock(x+7, y+4, z+21, b, ms);
		world.setBlock(x+7, y+4, z+28, b, ms);
		world.setBlock(x+7, y+4, z+29, b, ms);
		world.setBlock(x+7, y+4, z+30, b, ms);
		world.setBlock(x+7, y+5, z+1, b, ms);
		world.setBlock(x+7, y+5, z+2, b, ms);
		world.setBlock(x+7, y+5, z+3, b, ms);
		world.setBlock(x+7, y+5, z+4, b, ms);
		world.setBlock(x+7, y+5, z+5, b, ms);
		world.setBlock(x+7, y+5, z+6, b, ms);
		world.setBlock(x+7, y+5, z+7, b, ms);
		world.setBlock(x+7, y+5, z+8, b, ms);
		world.setBlock(x+7, y+5, z+9, b, ms);
		world.setBlock(x+7, y+5, z+10, b, ms);
		world.setBlock(x+7, y+5, z+11, b, ms);
		world.setBlock(x+7, y+5, z+12, b, ms);
		world.setBlock(x+7, y+5, z+13, b, ms);
		world.setBlock(x+7, y+5, z+14, b, ms);
		world.setBlock(x+7, y+5, z+15, b, ms);
		world.setBlock(x+7, y+5, z+16, b, ms);
		world.setBlock(x+7, y+5, z+17, b, ms);
		world.setBlock(x+7, y+5, z+18, b, ms);
		world.setBlock(x+7, y+5, z+19, b, ms);
		world.setBlock(x+7, y+5, z+20, b, ms);
		world.setBlock(x+7, y+5, z+21, b, ms);
		world.setBlock(x+7, y+5, z+22, b, ms);
		world.setBlock(x+7, y+5, z+23, b, ms);
		world.setBlock(x+7, y+5, z+24, b, ms);
		world.setBlock(x+7, y+5, z+25, b, ms);
		world.setBlock(x+7, y+5, z+26, b, ms);
		world.setBlock(x+7, y+5, z+27, b, ms);
		world.setBlock(x+7, y+5, z+28, b, ms);
		world.setBlock(x+7, y+5, z+29, b, ms);
		world.setBlock(x+8, y+0, z+0, b, ms);
		world.setBlock(x+8, y+0, z+1, b, ms);
		world.setBlock(x+8, y+0, z+2, b, ms);
		world.setBlock(x+8, y+0, z+3, b, ms);
		world.setBlock(x+8, y+0, z+4, b, ms);
		world.setBlock(x+8, y+0, z+5, b, ms);
		world.setBlock(x+8, y+0, z+6, b, ms);
		world.setBlock(x+8, y+0, z+7, b, ms);
		world.setBlock(x+8, y+0, z+8, b, ms);
		world.setBlock(x+8, y+0, z+9, b, ms);
		world.setBlock(x+8, y+0, z+10, b, ms);
		world.setBlock(x+8, y+0, z+11, b, ms);
		world.setBlock(x+8, y+0, z+12, b, ms);
		world.setBlock(x+8, y+0, z+13, b, ms);
		world.setBlock(x+8, y+0, z+14, b, ms);
		world.setBlock(x+8, y+0, z+15, b, ms);
		world.setBlock(x+8, y+0, z+16, b, ms);
		world.setBlock(x+8, y+0, z+17, b, ms);
		world.setBlock(x+8, y+0, z+18, b, ms);
		world.setBlock(x+8, y+0, z+19, b, ms);
		world.setBlock(x+8, y+0, z+20, b, ms);
		world.setBlock(x+8, y+0, z+21, b, ms);
		world.setBlock(x+8, y+0, z+22, b, ms);
		world.setBlock(x+8, y+0, z+23, b, ms);
		world.setBlock(x+8, y+0, z+24, b, ms);
		world.setBlock(x+8, y+0, z+25, b, ms);
		world.setBlock(x+8, y+0, z+26, b, mc);
		world.setBlock(x+8, y+0, z+27, b, ms);
		world.setBlock(x+8, y+0, z+28, b, ms);
		world.setBlock(x+8, y+0, z+29, b, ms);
		world.setBlock(x+8, y+0, z+30, b, ms);
		world.setBlock(x+8, y+1, z+0, b, ms);
		world.setBlock(x+8, y+1, z+1, b, ms);
		world.setBlock(x+8, y+1, z+8, b, ms);
		world.setBlock(x+8, y+1, z+9, b, ms);
		world.setBlock(x+8, y+1, z+10, b, ms);
		world.setBlock(x+8, y+1, z+11, b, ms);
		world.setBlock(x+8, y+1, z+12, b, ms);
		world.setBlock(x+8, y+1, z+13, b, ms);
		world.setBlock(x+8, y+1, z+19, b, ms);
		world.setBlock(x+8, y+1, z+20, b, ms);
		world.setBlock(x+8, y+1, z+21, b, ms);
		world.setBlock(x+8, y+1, z+28, b, ms);
		world.setBlock(x+8, y+1, z+29, b, ms);
		world.setBlock(x+8, y+1, z+30, b, ms);
		world.setBlock(x+8, y+2, z+0, b, ms);
		world.setBlock(x+8, y+2, z+1, b, ms);
		world.setBlock(x+8, y+2, z+8, b, ms);
		world.setBlock(x+8, y+2, z+9, b, ms);
		world.setBlock(x+8, y+2, z+10, b, ms);
		world.setBlock(x+8, y+2, z+11, b, ms);
		world.setBlock(x+8, y+2, z+12, b, ms);
		world.setBlock(x+8, y+2, z+13, b, ms);
		world.setBlock(x+8, y+2, z+19, b, ms);
		world.setBlock(x+8, y+2, z+20, b, ms);
		world.setBlock(x+8, y+2, z+21, b, ms);
		world.setBlock(x+8, y+2, z+28, b, ms);
		world.setBlock(x+8, y+2, z+29, b, ms);
		world.setBlock(x+8, y+2, z+30, b, ms);
		world.setBlock(x+8, y+3, z+0, b, ms);
		world.setBlock(x+8, y+3, z+1, b, ms);
		world.setBlock(x+8, y+3, z+8, b, ms);
		world.setBlock(x+8, y+3, z+9, b, ms);
		world.setBlock(x+8, y+3, z+10, b, ms);
		world.setBlock(x+8, y+3, z+11, b, ms);
		world.setBlock(x+8, y+3, z+12, b, ms);
		world.setBlock(x+8, y+3, z+13, b, ms);
		world.setBlock(x+8, y+3, z+19, b, ms);
		world.setBlock(x+8, y+3, z+20, b, ms);
		world.setBlock(x+8, y+3, z+21, b, ms);
		world.setBlock(x+8, y+3, z+28, b, ms);
		world.setBlock(x+8, y+3, z+29, b, ms);
		world.setBlock(x+8, y+3, z+30, b, ms);
		world.setBlock(x+8, y+4, z+0, b, ms);
		world.setBlock(x+8, y+4, z+1, b, ms);
		world.setBlock(x+8, y+4, z+8, b, ms);
		world.setBlock(x+8, y+4, z+9, b, ms);
		world.setBlock(x+8, y+4, z+10, b, ms);
		world.setBlock(x+8, y+4, z+11, b, ms);
		world.setBlock(x+8, y+4, z+12, b, ms);
		world.setBlock(x+8, y+4, z+13, b, ms);
		world.setBlock(x+8, y+4, z+19, b, ms);
		world.setBlock(x+8, y+4, z+20, b, ms);
		world.setBlock(x+8, y+4, z+21, b, ms);
		world.setBlock(x+8, y+4, z+28, b, ms);
		world.setBlock(x+8, y+4, z+29, b, ms);
		world.setBlock(x+8, y+4, z+30, b, ms);
		world.setBlock(x+8, y+5, z+1, b, ms);
		world.setBlock(x+8, y+5, z+2, b, ms);
		world.setBlock(x+8, y+5, z+3, b, ms);
		world.setBlock(x+8, y+5, z+4, b, ms);
		world.setBlock(x+8, y+5, z+5, b, ms);
		world.setBlock(x+8, y+5, z+6, b, ms);
		world.setBlock(x+8, y+5, z+7, b, ms);
		world.setBlock(x+8, y+5, z+8, b, ms);
		world.setBlock(x+8, y+5, z+9, b, ms);
		world.setBlock(x+8, y+5, z+10, b, ms);
		world.setBlock(x+8, y+5, z+11, b, ms);
		world.setBlock(x+8, y+5, z+12, b, ms);
		world.setBlock(x+8, y+5, z+13, b, ms);
		world.setBlock(x+8, y+5, z+14, b, ms);
		world.setBlock(x+8, y+5, z+15, b, ms);
		world.setBlock(x+8, y+5, z+16, b, ms);
		world.setBlock(x+8, y+5, z+17, b, ms);
		world.setBlock(x+8, y+5, z+18, b, ms);
		world.setBlock(x+8, y+5, z+19, b, ms);
		world.setBlock(x+8, y+5, z+20, b, ms);
		world.setBlock(x+8, y+5, z+21, b, ms);
		world.setBlock(x+8, y+5, z+22, b, ms);
		world.setBlock(x+8, y+5, z+23, b, ms);
		world.setBlock(x+8, y+5, z+24, b, ms);
		world.setBlock(x+8, y+5, z+25, b, ms);
		world.setBlock(x+8, y+5, z+26, b, ms);
		world.setBlock(x+8, y+5, z+27, b, ms);
		world.setBlock(x+8, y+5, z+28, b, ms);
		world.setBlock(x+8, y+5, z+29, b, ms);
		world.setBlock(x+9, y+0, z+1, b, ms);
		world.setBlock(x+9, y+0, z+2, b, ms);
		world.setBlock(x+9, y+0, z+3, b, ms);
		world.setBlock(x+9, y+0, z+4, b, ms);
		this.generateRune(x+9, y+0, z+5, LockColor.RED);
		world.setBlock(x+9, y+0, z+6, b, ms);
		world.setBlock(x+9, y+0, z+7, b, ms);
		world.setBlock(x+9, y+0, z+8, b, ms);
		world.setBlock(x+9, y+0, z+13, b, ms);
		world.setBlock(x+9, y+0, z+14, b, ms);
		world.setBlock(x+9, y+0, z+15, b, ms);
		this.generateRune(x+9, y+0, z+16, LockColor.GREEN);
		world.setBlock(x+9, y+0, z+17, b, ms);
		world.setBlock(x+9, y+0, z+18, b, ms);
		world.setBlock(x+9, y+0, z+19, b, ms);
		world.setBlock(x+9, y+0, z+20, b, ms);
		world.setBlock(x+9, y+0, z+21, b, ms);
		world.setBlock(x+9, y+0, z+22, b, ms);
		world.setBlock(x+9, y+0, z+23, b, ms);
		world.setBlock(x+9, y+0, z+24, b, ms);
		world.setBlock(x+9, y+0, z+25, b, ms);
		world.setBlock(x+9, y+0, z+26, b, ms);
		world.setBlock(x+9, y+0, z+27, b, ms);
		world.setBlock(x+9, y+0, z+28, b, ms);
		world.setBlock(x+9, y+0, z+29, b, ms);
		world.setBlock(x+9, y+1, z+1, b, ms);
		world.setBlock(x+9, y+1, z+2, b, ms);
		this.generateKey(x+9, y+1, z+6);
		world.setBlock(x+9, y+1, z+8, b, ms);
		world.setBlock(x+9, y+1, z+13, b, ms);
		world.setBlock(x+9, y+1, z+19, b, ms);
		world.setBlock(x+9, y+1, z+20, b, ms);
		world.setBlock(x+9, y+1, z+21, b, ms);
		world.setBlock(x+9, y+1, z+22, b, ms);
		world.setBlock(x+9, y+1, z+23, b, ms);
		world.setBlock(x+9, y+1, z+24, b, ms);
		world.setBlock(x+9, y+1, z+25, b, ms);
		world.setBlock(x+9, y+1, z+26, b, ms);
		world.setBlock(x+9, y+1, z+27, b, ms);
		world.setBlock(x+9, y+1, z+28, b, ms);
		world.setBlock(x+9, y+1, z+29, b, ms);
		world.setBlock(x+9, y+2, z+1, b, ms);
		world.setBlock(x+9, y+2, z+2, b, ml);
		world.setBlock(x+9, y+2, z+8, b, ms);
		world.setBlock(x+9, y+2, z+13, b, ms);
		world.setBlock(x+9, y+2, z+19, b, ms);
		world.setBlock(x+9, y+2, z+20, b, ms);
		world.setBlock(x+9, y+2, z+21, b, ms);
		world.setBlock(x+9, y+2, z+22, b, ms);
		world.setBlock(x+9, y+2, z+23, b, ms);
		world.setBlock(x+9, y+2, z+24, b, ml);
		world.setBlock(x+9, y+2, z+25, b, ms);
		world.setBlock(x+9, y+2, z+26, b, ms);
		world.setBlock(x+9, y+2, z+27, b, ms);
		world.setBlock(x+9, y+2, z+28, b, ms);
		world.setBlock(x+9, y+2, z+29, b, ms);
		world.setBlock(x+9, y+3, z+1, b, ms);
		world.setBlock(x+9, y+3, z+2, b, ms);
		world.setBlock(x+9, y+3, z+8, b, ms);
		world.setBlock(x+9, y+3, z+13, b, ms);
		world.setBlock(x+9, y+3, z+19, b, ms);
		world.setBlock(x+9, y+3, z+20, b, ms);
		world.setBlock(x+9, y+3, z+21, b, ms);
		world.setBlock(x+9, y+3, z+22, b, ms);
		world.setBlock(x+9, y+3, z+23, b, ms);
		world.setBlock(x+9, y+3, z+24, b, ms);
		world.setBlock(x+9, y+3, z+25, b, ms);
		world.setBlock(x+9, y+3, z+26, b, ms);
		world.setBlock(x+9, y+3, z+27, b, ms);
		world.setBlock(x+9, y+3, z+28, b, ms);
		world.setBlock(x+9, y+3, z+29, b, ms);
		world.setBlock(x+9, y+4, z+1, b, ms);
		world.setBlock(x+9, y+4, z+2, b, ms);
		world.setBlock(x+9, y+4, z+8, b, ms);
		world.setBlock(x+9, y+4, z+13, b, ms);
		world.setBlock(x+9, y+4, z+19, b, ms);
		world.setBlock(x+9, y+4, z+20, b, ms);
		world.setBlock(x+9, y+4, z+21, b, ms);
		world.setBlock(x+9, y+4, z+22, b, ms);
		world.setBlock(x+9, y+4, z+23, b, ms);
		world.setBlock(x+9, y+4, z+24, b, ms);
		world.setBlock(x+9, y+4, z+25, b, ms);
		world.setBlock(x+9, y+4, z+26, b, ms);
		world.setBlock(x+9, y+4, z+27, b, ms);
		world.setBlock(x+9, y+4, z+28, b, ms);
		world.setBlock(x+9, y+4, z+29, b, ms);
		world.setBlock(x+9, y+5, z+1, b, ms);
		world.setBlock(x+9, y+5, z+2, b, ms);
		world.setBlock(x+9, y+5, z+3, b, ms);
		world.setBlock(x+9, y+5, z+4, b, ms);
		world.setBlock(x+9, y+5, z+5, b, ms);
		world.setBlock(x+9, y+5, z+6, b, ms);
		world.setBlock(x+9, y+5, z+7, b, ms);
		world.setBlock(x+9, y+5, z+8, b, ms);
		world.setBlock(x+9, y+5, z+13, b, ms);
		world.setBlock(x+9, y+5, z+14, b, ms);
		world.setBlock(x+9, y+5, z+15, b, ms);
		world.setBlock(x+9, y+5, z+16, b, ms);
		world.setBlock(x+9, y+5, z+17, b, ms);
		world.setBlock(x+9, y+5, z+18, b, ms);
		world.setBlock(x+9, y+5, z+19, b, ms);
		world.setBlock(x+9, y+5, z+20, b, ms);
		world.setBlock(x+9, y+5, z+21, b, ms);
		world.setBlock(x+9, y+5, z+22, b, ms);
		world.setBlock(x+9, y+5, z+23, b, ms);
		world.setBlock(x+9, y+5, z+24, b, ms);
		world.setBlock(x+9, y+5, z+25, b, ms);
		world.setBlock(x+9, y+5, z+26, b, ms);
		world.setBlock(x+9, y+5, z+27, b, ms);
		world.setBlock(x+9, y+5, z+28, b, ms);
		world.setBlock(x+9, y+5, z+29, b, ms);
		world.setBlock(x+10, y+0, z+2, b, ms);
		world.setBlock(x+10, y+0, z+3, b, ms);
		world.setBlock(x+10, y+0, z+4, b, ms);
		world.setBlock(x+10, y+0, z+5, b, ms);
		world.setBlock(x+10, y+0, z+6, b, ms);
		world.setBlock(x+10, y+0, z+7, b, ms);
		world.setBlock(x+10, y+0, z+8, b, ms);
		world.setBlock(x+10, y+0, z+13, b, ms);
		world.setBlock(x+10, y+0, z+14, b, ms);
		world.setBlock(x+10, y+0, z+15, b, ms);
		world.setBlock(x+10, y+0, z+16, b, ms);
		world.setBlock(x+10, y+0, z+17, b, ms);
		world.setBlock(x+10, y+0, z+18, b, ms);
		world.setBlock(x+10, y+0, z+19, b, ms);
		world.setBlock(x+10, y+1, z+2, b, ms);
		world.setBlock(x+10, y+1, z+8, b, ms);
		world.setBlock(x+10, y+1, z+13, b, ms);
		world.setBlock(x+10, y+1, z+19, b, ms);
		world.setBlock(x+10, y+2, z+2, b, ms);
		world.setBlock(x+10, y+2, z+8, b, ms);
		world.setBlock(x+10, y+2, z+13, b, ms);
		world.setBlock(x+10, y+2, z+19, b, ms);
		world.setBlock(x+10, y+3, z+2, b, ms);
		world.setBlock(x+10, y+3, z+8, b, ms);
		world.setBlock(x+10, y+3, z+13, b, ms);
		world.setBlock(x+10, y+3, z+19, b, ms);
		world.setBlock(x+10, y+4, z+2, b, ms);
		world.setBlock(x+10, y+4, z+8, b, ms);
		world.setBlock(x+10, y+4, z+13, b, ms);
		world.setBlock(x+10, y+4, z+19, b, ms);
		world.setBlock(x+10, y+5, z+2, b, ms);
		world.setBlock(x+10, y+5, z+3, b, ms);
		world.setBlock(x+10, y+5, z+4, b, ms);
		world.setBlock(x+10, y+5, z+5, b, ms);
		world.setBlock(x+10, y+5, z+6, b, ms);
		world.setBlock(x+10, y+5, z+7, b, ms);
		world.setBlock(x+10, y+5, z+8, b, ms);
		world.setBlock(x+10, y+5, z+13, b, ms);
		world.setBlock(x+10, y+5, z+14, b, ms);
		world.setBlock(x+10, y+5, z+15, b, ms);
		world.setBlock(x+10, y+5, z+16, b, ms);
		world.setBlock(x+10, y+5, z+17, b, ms);
		world.setBlock(x+10, y+5, z+18, b, ms);
		world.setBlock(x+10, y+5, z+19, b, ms);
		world.setBlock(x+11, y+0, z+2, b, ms);
		world.setBlock(x+11, y+0, z+3, b, ms);
		world.setBlock(x+11, y+0, z+4, b, ms);
		world.setBlock(x+11, y+0, z+5, b, ms);
		world.setBlock(x+11, y+0, z+6, b, ms);
		world.setBlock(x+11, y+0, z+7, b, ms);
		world.setBlock(x+11, y+0, z+8, b, ms);
		world.setBlock(x+11, y+0, z+13, b, ms);
		world.setBlock(x+11, y+0, z+14, b, ms);
		world.setBlock(x+11, y+0, z+15, b, ms);
		world.setBlock(x+11, y+0, z+16, b, ms);
		world.setBlock(x+11, y+0, z+17, b, ms);
		world.setBlock(x+11, y+0, z+18, b, ms);
		world.setBlock(x+11, y+0, z+19, b, ms);
		world.setBlock(x+11, y+1, z+2, b, ms);
		world.setBlock(x+11, y+1, z+8, b, ms);
		world.setBlock(x+11, y+1, z+13, b, ms);
		world.setBlock(x+11, y+1, z+19, b, ms);
		world.setBlock(x+11, y+2, z+2, b, ms);
		world.setBlock(x+11, y+2, z+8, b, ms);
		world.setBlock(x+11, y+2, z+13, b, ms);
		world.setBlock(x+11, y+2, z+19, b, ms);
		world.setBlock(x+11, y+3, z+2, b, ms);
		world.setBlock(x+11, y+3, z+8, b, ms);
		world.setBlock(x+11, y+3, z+13, b, ms);
		world.setBlock(x+11, y+3, z+19, b, ms);
		world.setBlock(x+11, y+4, z+2, b, ms);
		world.setBlock(x+11, y+4, z+8, b, ms);
		world.setBlock(x+11, y+4, z+13, b, ms);
		world.setBlock(x+11, y+4, z+19, b, ms);
		world.setBlock(x+11, y+5, z+2, b, ms);
		world.setBlock(x+11, y+5, z+3, b, ms);
		world.setBlock(x+11, y+5, z+4, b, ms);
		world.setBlock(x+11, y+5, z+5, b, ms);
		world.setBlock(x+11, y+5, z+6, b, ms);
		world.setBlock(x+11, y+5, z+7, b, ms);
		world.setBlock(x+11, y+5, z+8, b, ms);
		world.setBlock(x+11, y+5, z+13, b, ms);
		world.setBlock(x+11, y+5, z+14, b, ms);
		world.setBlock(x+11, y+5, z+15, b, ms);
		world.setBlock(x+11, y+5, z+16, b, ms);
		world.setBlock(x+11, y+5, z+17, b, ms);
		world.setBlock(x+11, y+5, z+18, b, ms);
		world.setBlock(x+11, y+5, z+19, b, ms);
		world.setBlock(x+12, y+0, z+2, b, ms);
		world.setBlock(x+12, y+0, z+3, b, ms);
		world.setBlock(x+12, y+0, z+4, b, ms);
		world.setBlock(x+12, y+0, z+5, b, ms);
		world.setBlock(x+12, y+0, z+6, b, ms);
		world.setBlock(x+12, y+0, z+7, b, ms);
		world.setBlock(x+12, y+0, z+8, b, ms);
		world.setBlock(x+12, y+0, z+13, b, ms);
		world.setBlock(x+12, y+0, z+14, b, ms);
		world.setBlock(x+12, y+0, z+15, b, ms);
		world.setBlock(x+12, y+0, z+16, b, ms);
		world.setBlock(x+12, y+0, z+17, b, ms);
		world.setBlock(x+12, y+0, z+18, b, ms);
		world.setBlock(x+12, y+0, z+19, b, ms);
		world.setBlock(x+12, y+1, z+2, b, ms);
		world.setBlock(x+12, y+1, z+3, b, ms);
		world.setBlock(x+12, y+1, z+4, b, ms);
		world.setBlock(x+12, y+1, z+5, b, ms);
		world.setBlock(x+12, y+1, z+6, b, ms);
		world.setBlock(x+12, y+1, z+7, b, ms);
		world.setBlock(x+12, y+1, z+8, b, ms);
		world.setBlock(x+12, y+1, z+13, b, ms);
		world.setBlock(x+12, y+1, z+14, b, ms);
		world.setBlock(x+12, y+1, z+15, b, ms);
		world.setBlock(x+12, y+1, z+16, b, ms);
		world.setBlock(x+12, y+1, z+17, b, ms);
		world.setBlock(x+12, y+1, z+18, b, ms);
		world.setBlock(x+12, y+1, z+19, b, ms);
		world.setBlock(x+12, y+2, z+2, b, ms);
		world.setBlock(x+12, y+2, z+3, b, ms);
		world.setBlock(x+12, y+2, z+4, b, ms);
		world.setBlock(x+12, y+2, z+5, b, ml);
		world.setBlock(x+12, y+2, z+6, b, ms);
		world.setBlock(x+12, y+2, z+7, b, ms);
		world.setBlock(x+12, y+2, z+8, b, ms);
		world.setBlock(x+12, y+2, z+13, b, ms);
		world.setBlock(x+12, y+2, z+14, b, ms);
		world.setBlock(x+12, y+2, z+15, b, ms);
		world.setBlock(x+12, y+2, z+16, b, ml);
		world.setBlock(x+12, y+2, z+17, b, ms);
		world.setBlock(x+12, y+2, z+18, b, ms);
		world.setBlock(x+12, y+2, z+19, b, ms);
		world.setBlock(x+12, y+3, z+2, b, ms);
		world.setBlock(x+12, y+3, z+3, b, ms);
		world.setBlock(x+12, y+3, z+4, b, ms);
		world.setBlock(x+12, y+3, z+5, b, ms);
		world.setBlock(x+12, y+3, z+6, b, ms);
		world.setBlock(x+12, y+3, z+7, b, ms);
		world.setBlock(x+12, y+3, z+8, b, ms);
		world.setBlock(x+12, y+3, z+13, b, ms);
		world.setBlock(x+12, y+3, z+14, b, ms);
		world.setBlock(x+12, y+3, z+15, b, ms);
		world.setBlock(x+12, y+3, z+16, b, ms);
		world.setBlock(x+12, y+3, z+17, b, ms);
		world.setBlock(x+12, y+3, z+18, b, ms);
		world.setBlock(x+12, y+3, z+19, b, ms);
		world.setBlock(x+12, y+4, z+2, b, ms);
		world.setBlock(x+12, y+4, z+3, b, ms);
		world.setBlock(x+12, y+4, z+4, b, ms);
		world.setBlock(x+12, y+4, z+5, b, ms);
		world.setBlock(x+12, y+4, z+6, b, ms);
		world.setBlock(x+12, y+4, z+7, b, ms);
		world.setBlock(x+12, y+4, z+8, b, ms);
		world.setBlock(x+12, y+4, z+13, b, ms);
		world.setBlock(x+12, y+4, z+14, b, ms);
		world.setBlock(x+12, y+4, z+15, b, ms);
		world.setBlock(x+12, y+4, z+16, b, ms);
		world.setBlock(x+12, y+4, z+17, b, ms);
		world.setBlock(x+12, y+4, z+18, b, ms);
		world.setBlock(x+12, y+4, z+19, b, ms);
		world.setBlock(x+12, y+5, z+2, b, ms);
		world.setBlock(x+12, y+5, z+3, b, ms);
		world.setBlock(x+12, y+5, z+4, b, ms);
		world.setBlock(x+12, y+5, z+5, b, ms);
		world.setBlock(x+12, y+5, z+6, b, ms);
		world.setBlock(x+12, y+5, z+7, b, ms);
		world.setBlock(x+12, y+5, z+8, b, ms);
		world.setBlock(x+12, y+5, z+13, b, ms);
		world.setBlock(x+12, y+5, z+14, b, ms);
		world.setBlock(x+12, y+5, z+15, b, ms);
		world.setBlock(x+12, y+5, z+16, b, ms);
		world.setBlock(x+12, y+5, z+17, b, ms);
		world.setBlock(x+12, y+5, z+18, b, ms);
		world.setBlock(x+12, y+5, z+19, b, ms);
		world.setBlock(x+1, y+1, z+3, STRUCTURE_AIR);
		world.setBlock(x+1, y+1, z+4, STRUCTURE_AIR);
		world.setBlock(x+1, y+1, z+5, STRUCTURE_AIR);
		world.setBlock(x+1, y+1, z+6, STRUCTURE_AIR);
		world.setBlock(x+1, y+1, z+7, STRUCTURE_AIR);
		world.setBlock(x+1, y+1, z+14, STRUCTURE_AIR);
		world.setBlock(x+1, y+1, z+15, STRUCTURE_AIR);
		world.setBlock(x+1, y+1, z+16, STRUCTURE_AIR);
		world.setBlock(x+1, y+1, z+17, STRUCTURE_AIR);
		world.setBlock(x+1, y+1, z+18, STRUCTURE_AIR);
		world.setBlock(x+1, y+2, z+3, STRUCTURE_AIR);
		world.setBlock(x+1, y+2, z+4, STRUCTURE_AIR);
		world.setBlock(x+1, y+2, z+5, STRUCTURE_AIR);
		world.setBlock(x+1, y+2, z+6, STRUCTURE_AIR);
		world.setBlock(x+1, y+2, z+7, STRUCTURE_AIR);
		world.setBlock(x+1, y+2, z+14, STRUCTURE_AIR);
		world.setBlock(x+1, y+2, z+15, STRUCTURE_AIR);
		world.setBlock(x+1, y+2, z+16, STRUCTURE_AIR);
		world.setBlock(x+1, y+2, z+17, STRUCTURE_AIR);
		world.setBlock(x+1, y+2, z+18, STRUCTURE_AIR);
		world.setBlock(x+1, y+3, z+3, STRUCTURE_AIR);
		world.setBlock(x+1, y+3, z+4, STRUCTURE_AIR);
		world.setBlock(x+1, y+3, z+5, STRUCTURE_AIR);
		world.setBlock(x+1, y+3, z+6, STRUCTURE_AIR);
		world.setBlock(x+1, y+3, z+7, STRUCTURE_AIR);
		world.setBlock(x+1, y+3, z+14, STRUCTURE_AIR);
		world.setBlock(x+1, y+3, z+15, STRUCTURE_AIR);
		world.setBlock(x+1, y+3, z+16, STRUCTURE_AIR);
		world.setBlock(x+1, y+3, z+17, STRUCTURE_AIR);
		world.setBlock(x+1, y+3, z+18, STRUCTURE_AIR);
		world.setBlock(x+1, y+4, z+3, STRUCTURE_AIR);
		world.setBlock(x+1, y+4, z+4, STRUCTURE_AIR);
		world.setBlock(x+1, y+4, z+5, STRUCTURE_AIR);
		world.setBlock(x+1, y+4, z+6, STRUCTURE_AIR);
		world.setBlock(x+1, y+4, z+7, STRUCTURE_AIR);
		world.setBlock(x+1, y+4, z+14, STRUCTURE_AIR);
		world.setBlock(x+1, y+4, z+15, STRUCTURE_AIR);
		world.setBlock(x+1, y+4, z+16, STRUCTURE_AIR);
		world.setBlock(x+1, y+4, z+17, STRUCTURE_AIR);
		world.setBlock(x+1, y+4, z+18, STRUCTURE_AIR);
		world.setBlock(x+2, y+1, z+3, STRUCTURE_AIR);
		world.setBlock(x+2, y+1, z+4, STRUCTURE_AIR);
		world.setBlock(x+2, y+1, z+5, STRUCTURE_AIR);
		world.setBlock(x+2, y+1, z+6, STRUCTURE_AIR);
		world.setBlock(x+2, y+1, z+7, STRUCTURE_AIR);
		world.setBlock(x+2, y+1, z+14, STRUCTURE_AIR);
		world.setBlock(x+2, y+1, z+15, STRUCTURE_AIR);
		world.setBlock(x+2, y+1, z+16, STRUCTURE_AIR);
		world.setBlock(x+2, y+1, z+17, STRUCTURE_AIR);
		world.setBlock(x+2, y+1, z+18, STRUCTURE_AIR);
		world.setBlock(x+2, y+2, z+3, STRUCTURE_AIR);
		world.setBlock(x+2, y+2, z+4, STRUCTURE_AIR);
		world.setBlock(x+2, y+2, z+5, STRUCTURE_AIR);
		world.setBlock(x+2, y+2, z+6, STRUCTURE_AIR);
		world.setBlock(x+2, y+2, z+7, STRUCTURE_AIR);
		world.setBlock(x+2, y+2, z+14, STRUCTURE_AIR);
		world.setBlock(x+2, y+2, z+15, STRUCTURE_AIR);
		world.setBlock(x+2, y+2, z+16, STRUCTURE_AIR);
		world.setBlock(x+2, y+2, z+17, STRUCTURE_AIR);
		world.setBlock(x+2, y+2, z+18, STRUCTURE_AIR);
		world.setBlock(x+2, y+3, z+3, STRUCTURE_AIR);
		world.setBlock(x+2, y+3, z+4, STRUCTURE_AIR);
		world.setBlock(x+2, y+3, z+5, STRUCTURE_AIR);
		world.setBlock(x+2, y+3, z+6, STRUCTURE_AIR);
		world.setBlock(x+2, y+3, z+7, STRUCTURE_AIR);
		world.setBlock(x+2, y+3, z+14, STRUCTURE_AIR);
		world.setBlock(x+2, y+3, z+15, STRUCTURE_AIR);
		world.setBlock(x+2, y+3, z+16, STRUCTURE_AIR);
		world.setBlock(x+2, y+3, z+17, STRUCTURE_AIR);
		world.setBlock(x+2, y+3, z+18, STRUCTURE_AIR);
		world.setBlock(x+2, y+4, z+3, STRUCTURE_AIR);
		world.setBlock(x+2, y+4, z+4, STRUCTURE_AIR);
		world.setBlock(x+2, y+4, z+5, STRUCTURE_AIR);
		world.setBlock(x+2, y+4, z+6, STRUCTURE_AIR);
		world.setBlock(x+2, y+4, z+7, STRUCTURE_AIR);
		world.setBlock(x+2, y+4, z+14, STRUCTURE_AIR);
		world.setBlock(x+2, y+4, z+15, STRUCTURE_AIR);
		world.setBlock(x+2, y+4, z+16, STRUCTURE_AIR);
		world.setBlock(x+2, y+4, z+17, STRUCTURE_AIR);
		world.setBlock(x+2, y+4, z+18, STRUCTURE_AIR);
		world.setBlock(x+3, y+1, z+3, STRUCTURE_AIR);
		world.setBlock(x+3, y+1, z+4, STRUCTURE_AIR);
		world.setBlock(x+3, y+1, z+5, STRUCTURE_AIR);
		world.setBlock(x+3, y+1, z+7, STRUCTURE_AIR);
		world.setBlock(x+3, y+1, z+14, STRUCTURE_AIR);
		world.setBlock(x+3, y+1, z+15, STRUCTURE_AIR);
		world.setBlock(x+3, y+1, z+16, STRUCTURE_AIR);
		world.setBlock(x+3, y+1, z+17, STRUCTURE_AIR);
		world.setBlock(x+3, y+1, z+18, STRUCTURE_AIR);
		world.setBlock(x+3, y+2, z+3, STRUCTURE_AIR);
		world.setBlock(x+3, y+2, z+4, STRUCTURE_AIR);
		world.setBlock(x+3, y+2, z+5, STRUCTURE_AIR);
		world.setBlock(x+3, y+2, z+6, STRUCTURE_AIR);
		world.setBlock(x+3, y+2, z+7, STRUCTURE_AIR);
		world.setBlock(x+3, y+2, z+14, STRUCTURE_AIR);
		world.setBlock(x+3, y+2, z+15, STRUCTURE_AIR);
		world.setBlock(x+3, y+2, z+16, STRUCTURE_AIR);
		world.setBlock(x+3, y+2, z+17, STRUCTURE_AIR);
		world.setBlock(x+3, y+2, z+18, STRUCTURE_AIR);
		world.setBlock(x+3, y+3, z+3, STRUCTURE_AIR);
		world.setBlock(x+3, y+3, z+4, STRUCTURE_AIR);
		world.setBlock(x+3, y+3, z+5, STRUCTURE_AIR);
		world.setBlock(x+3, y+3, z+6, STRUCTURE_AIR);
		world.setBlock(x+3, y+3, z+7, STRUCTURE_AIR);
		world.setBlock(x+3, y+3, z+14, STRUCTURE_AIR);
		world.setBlock(x+3, y+3, z+15, STRUCTURE_AIR);
		world.setBlock(x+3, y+3, z+16, STRUCTURE_AIR);
		world.setBlock(x+3, y+3, z+17, STRUCTURE_AIR);
		world.setBlock(x+3, y+3, z+18, STRUCTURE_AIR);
		world.setBlock(x+3, y+4, z+3, STRUCTURE_AIR);
		world.setBlock(x+3, y+4, z+4, STRUCTURE_AIR);
		world.setBlock(x+3, y+4, z+5, STRUCTURE_AIR);
		world.setBlock(x+3, y+4, z+6, STRUCTURE_AIR);
		world.setBlock(x+3, y+4, z+7, STRUCTURE_AIR);
		world.setBlock(x+3, y+4, z+14, STRUCTURE_AIR);
		world.setBlock(x+3, y+4, z+15, STRUCTURE_AIR);
		world.setBlock(x+3, y+4, z+16, STRUCTURE_AIR);
		world.setBlock(x+3, y+4, z+17, STRUCTURE_AIR);
		world.setBlock(x+3, y+4, z+18, STRUCTURE_AIR);
		world.setBlock(x+4, y+1, z+2, STRUCTURE_AIR);
		world.setBlock(x+4, y+1, z+3, STRUCTURE_AIR);
		world.setBlock(x+4, y+1, z+4, STRUCTURE_AIR);
		world.setBlock(x+4, y+1, z+5, STRUCTURE_AIR);
		world.setBlock(x+4, y+1, z+6, STRUCTURE_AIR);
		world.setBlock(x+4, y+1, z+7, STRUCTURE_AIR);
		world.setBlock(x+4, y+1, z+14, STRUCTURE_AIR);
		world.setBlock(x+4, y+1, z+15, STRUCTURE_AIR);
		world.setBlock(x+4, y+1, z+16, STRUCTURE_AIR);
		world.setBlock(x+4, y+1, z+17, STRUCTURE_AIR);
		world.setBlock(x+4, y+1, z+18, STRUCTURE_AIR);
		world.setBlock(x+4, y+1, z+22, STRUCTURE_AIR);
		world.setBlock(x+4, y+1, z+23, STRUCTURE_AIR);
		world.setBlock(x+4, y+1, z+24, STRUCTURE_AIR);
		world.setBlock(x+4, y+1, z+25, STRUCTURE_AIR);
		world.setBlock(x+4, y+1, z+26, STRUCTURE_AIR);
		world.setBlock(x+4, y+1, z+27, STRUCTURE_AIR);
		world.setBlock(x+4, y+2, z+2, STRUCTURE_AIR);
		world.setBlock(x+4, y+2, z+3, STRUCTURE_AIR);
		world.setBlock(x+4, y+2, z+4, STRUCTURE_AIR);
		world.setBlock(x+4, y+2, z+5, STRUCTURE_AIR);
		world.setBlock(x+4, y+2, z+6, STRUCTURE_AIR);
		world.setBlock(x+4, y+2, z+7, STRUCTURE_AIR);
		world.setBlock(x+4, y+2, z+14, STRUCTURE_AIR);
		world.setBlock(x+4, y+2, z+15, STRUCTURE_AIR);
		world.setBlock(x+4, y+2, z+16, STRUCTURE_AIR);
		world.setBlock(x+4, y+2, z+17, STRUCTURE_AIR);
		world.setBlock(x+4, y+2, z+18, STRUCTURE_AIR);
		world.setBlock(x+4, y+2, z+22, STRUCTURE_AIR);
		world.setBlock(x+4, y+2, z+23, STRUCTURE_AIR);
		world.setBlock(x+4, y+2, z+24, STRUCTURE_AIR);
		world.setBlock(x+4, y+2, z+25, STRUCTURE_AIR);
		world.setBlock(x+4, y+2, z+26, STRUCTURE_AIR);
		world.setBlock(x+4, y+2, z+27, STRUCTURE_AIR);
		world.setBlock(x+4, y+3, z+2, STRUCTURE_AIR);
		world.setBlock(x+4, y+3, z+3, STRUCTURE_AIR);
		world.setBlock(x+4, y+3, z+4, STRUCTURE_AIR);
		world.setBlock(x+4, y+3, z+5, STRUCTURE_AIR);
		world.setBlock(x+4, y+3, z+6, STRUCTURE_AIR);
		world.setBlock(x+4, y+3, z+7, STRUCTURE_AIR);
		world.setBlock(x+4, y+3, z+14, STRUCTURE_AIR);
		world.setBlock(x+4, y+3, z+15, STRUCTURE_AIR);
		world.setBlock(x+4, y+3, z+16, STRUCTURE_AIR);
		world.setBlock(x+4, y+3, z+17, STRUCTURE_AIR);
		world.setBlock(x+4, y+3, z+18, STRUCTURE_AIR);
		world.setBlock(x+4, y+3, z+22, STRUCTURE_AIR);
		world.setBlock(x+4, y+3, z+23, STRUCTURE_AIR);
		world.setBlock(x+4, y+3, z+24, STRUCTURE_AIR);
		world.setBlock(x+4, y+3, z+25, STRUCTURE_AIR);
		world.setBlock(x+4, y+3, z+26, STRUCTURE_AIR);
		world.setBlock(x+4, y+3, z+27, STRUCTURE_AIR);
		world.setBlock(x+4, y+4, z+2, STRUCTURE_AIR);
		world.setBlock(x+4, y+4, z+3, STRUCTURE_AIR);
		world.setBlock(x+4, y+4, z+4, STRUCTURE_AIR);
		world.setBlock(x+4, y+4, z+5, STRUCTURE_AIR);
		world.setBlock(x+4, y+4, z+6, STRUCTURE_AIR);
		world.setBlock(x+4, y+4, z+7, STRUCTURE_AIR);
		world.setBlock(x+4, y+4, z+14, STRUCTURE_AIR);
		world.setBlock(x+4, y+4, z+15, STRUCTURE_AIR);
		world.setBlock(x+4, y+4, z+16, STRUCTURE_AIR);
		world.setBlock(x+4, y+4, z+17, STRUCTURE_AIR);
		world.setBlock(x+4, y+4, z+18, STRUCTURE_AIR);
		world.setBlock(x+4, y+4, z+22, STRUCTURE_AIR);
		world.setBlock(x+4, y+4, z+23, STRUCTURE_AIR);
		world.setBlock(x+4, y+4, z+24, STRUCTURE_AIR);
		world.setBlock(x+4, y+4, z+25, STRUCTURE_AIR);
		world.setBlock(x+4, y+4, z+26, STRUCTURE_AIR);
		world.setBlock(x+4, y+4, z+27, STRUCTURE_AIR);
		world.setBlock(x+5, y+1, z+0, STRUCTURE_AIR);
		world.setBlock(x+5, y+1, z+1, STRUCTURE_AIR);
		world.setBlock(x+5, y+1, z+2, STRUCTURE_AIR);
		world.setBlock(x+5, y+1, z+3, STRUCTURE_AIR);
		world.setBlock(x+5, y+1, z+4, STRUCTURE_AIR);
		world.setBlock(x+5, y+1, z+5, STRUCTURE_AIR);
		world.setBlock(x+5, y+1, z+6, STRUCTURE_AIR);
		world.setBlock(x+5, y+1, z+7, STRUCTURE_AIR);
		world.setBlock(x+5, y+1, z+8, STRUCTURE_AIR);
		world.setBlock(x+5, y+1, z+10, STRUCTURE_AIR);
		world.setBlock(x+5, y+1, z+11, STRUCTURE_AIR);
		world.setBlock(x+5, y+1, z+13, STRUCTURE_AIR);
		world.setBlock(x+5, y+1, z+14, STRUCTURE_AIR);
		world.setBlock(x+5, y+1, z+15, STRUCTURE_AIR);
		world.setBlock(x+5, y+1, z+16, STRUCTURE_AIR);
		world.setBlock(x+5, y+1, z+17, STRUCTURE_AIR);
		world.setBlock(x+5, y+1, z+18, STRUCTURE_AIR);
		world.setBlock(x+5, y+1, z+19, STRUCTURE_AIR);
		world.setBlock(x+5, y+1, z+21, STRUCTURE_AIR);
		world.setBlock(x+5, y+1, z+22, STRUCTURE_AIR);
		world.setBlock(x+5, y+1, z+23, STRUCTURE_AIR);
		world.setBlock(x+5, y+1, z+24, STRUCTURE_AIR);
		world.setBlock(x+5, y+1, z+25, STRUCTURE_AIR);
		world.setBlock(x+5, y+1, z+26, STRUCTURE_AIR);
		world.setBlock(x+5, y+1, z+27, STRUCTURE_AIR);
		world.setBlock(x+5, y+1, z+28, STRUCTURE_AIR);
		world.setBlock(x+5, y+1, z+30, STRUCTURE_AIR);
		world.setBlock(x+5, y+2, z+0, STRUCTURE_AIR);
		world.setBlock(x+5, y+2, z+1, STRUCTURE_AIR);
		world.setBlock(x+5, y+2, z+2, STRUCTURE_AIR);
		world.setBlock(x+5, y+2, z+3, STRUCTURE_AIR);
		world.setBlock(x+5, y+2, z+4, STRUCTURE_AIR);
		world.setBlock(x+5, y+2, z+5, STRUCTURE_AIR);
		world.setBlock(x+5, y+2, z+6, STRUCTURE_AIR);
		world.setBlock(x+5, y+2, z+7, STRUCTURE_AIR);
		world.setBlock(x+5, y+2, z+8, STRUCTURE_AIR);
		world.setBlock(x+5, y+2, z+10, STRUCTURE_AIR);
		world.setBlock(x+5, y+2, z+11, STRUCTURE_AIR);
		world.setBlock(x+5, y+2, z+13, STRUCTURE_AIR);
		world.setBlock(x+5, y+2, z+14, STRUCTURE_AIR);
		world.setBlock(x+5, y+2, z+15, STRUCTURE_AIR);
		world.setBlock(x+5, y+2, z+16, STRUCTURE_AIR);
		world.setBlock(x+5, y+2, z+17, STRUCTURE_AIR);
		world.setBlock(x+5, y+2, z+18, STRUCTURE_AIR);
		world.setBlock(x+5, y+2, z+19, STRUCTURE_AIR);
		world.setBlock(x+5, y+2, z+21, STRUCTURE_AIR);
		world.setBlock(x+5, y+2, z+22, STRUCTURE_AIR);
		world.setBlock(x+5, y+2, z+23, STRUCTURE_AIR);
		world.setBlock(x+5, y+2, z+24, STRUCTURE_AIR);
		world.setBlock(x+5, y+2, z+25, STRUCTURE_AIR);
		world.setBlock(x+5, y+2, z+26, STRUCTURE_AIR);
		world.setBlock(x+5, y+2, z+27, STRUCTURE_AIR);
		world.setBlock(x+5, y+2, z+28, STRUCTURE_AIR);
		world.setBlock(x+5, y+2, z+30, STRUCTURE_AIR);
		world.setBlock(x+5, y+3, z+0, STRUCTURE_AIR);
		world.setBlock(x+5, y+3, z+1, STRUCTURE_AIR);
		world.setBlock(x+5, y+3, z+2, STRUCTURE_AIR);
		world.setBlock(x+5, y+3, z+3, STRUCTURE_AIR);
		world.setBlock(x+5, y+3, z+4, STRUCTURE_AIR);
		world.setBlock(x+5, y+3, z+5, STRUCTURE_AIR);
		world.setBlock(x+5, y+3, z+6, STRUCTURE_AIR);
		world.setBlock(x+5, y+3, z+7, STRUCTURE_AIR);
		world.setBlock(x+5, y+3, z+8, STRUCTURE_AIR);
		world.setBlock(x+5, y+3, z+10, STRUCTURE_AIR);
		world.setBlock(x+5, y+3, z+11, STRUCTURE_AIR);
		world.setBlock(x+5, y+3, z+13, STRUCTURE_AIR);
		world.setBlock(x+5, y+3, z+14, STRUCTURE_AIR);
		world.setBlock(x+5, y+3, z+15, STRUCTURE_AIR);
		world.setBlock(x+5, y+3, z+16, STRUCTURE_AIR);
		world.setBlock(x+5, y+3, z+17, STRUCTURE_AIR);
		world.setBlock(x+5, y+3, z+18, STRUCTURE_AIR);
		world.setBlock(x+5, y+3, z+19, STRUCTURE_AIR);
		world.setBlock(x+5, y+3, z+21, STRUCTURE_AIR);
		world.setBlock(x+5, y+3, z+22, STRUCTURE_AIR);
		world.setBlock(x+5, y+3, z+23, STRUCTURE_AIR);
		world.setBlock(x+5, y+3, z+24, STRUCTURE_AIR);
		world.setBlock(x+5, y+3, z+25, STRUCTURE_AIR);
		world.setBlock(x+5, y+3, z+26, STRUCTURE_AIR);
		world.setBlock(x+5, y+3, z+27, STRUCTURE_AIR);
		world.setBlock(x+5, y+3, z+28, STRUCTURE_AIR);
		world.setBlock(x+5, y+3, z+30, STRUCTURE_AIR);
		world.setBlock(x+5, y+4, z+2, STRUCTURE_AIR);
		world.setBlock(x+5, y+4, z+3, STRUCTURE_AIR);
		world.setBlock(x+5, y+4, z+4, STRUCTURE_AIR);
		world.setBlock(x+5, y+4, z+5, STRUCTURE_AIR);
		world.setBlock(x+5, y+4, z+6, STRUCTURE_AIR);
		world.setBlock(x+5, y+4, z+7, STRUCTURE_AIR);
		world.setBlock(x+5, y+4, z+14, STRUCTURE_AIR);
		world.setBlock(x+5, y+4, z+15, STRUCTURE_AIR);
		world.setBlock(x+5, y+4, z+16, STRUCTURE_AIR);
		world.setBlock(x+5, y+4, z+17, STRUCTURE_AIR);
		world.setBlock(x+5, y+4, z+18, STRUCTURE_AIR);
		world.setBlock(x+5, y+4, z+22, STRUCTURE_AIR);
		world.setBlock(x+5, y+4, z+23, STRUCTURE_AIR);
		world.setBlock(x+5, y+4, z+24, STRUCTURE_AIR);
		world.setBlock(x+5, y+4, z+25, STRUCTURE_AIR);
		world.setBlock(x+5, y+4, z+26, STRUCTURE_AIR);
		world.setBlock(x+5, y+4, z+27, STRUCTURE_AIR);
		world.setBlock(x+6, y+1, z+0, STRUCTURE_AIR);
		world.setBlock(x+6, y+1, z+1, STRUCTURE_AIR);
		world.setBlock(x+6, y+1, z+2, STRUCTURE_AIR);
		world.setBlock(x+6, y+1, z+3, STRUCTURE_AIR);
		world.setBlock(x+6, y+1, z+4, STRUCTURE_AIR);
		world.setBlock(x+6, y+1, z+5, STRUCTURE_AIR);
		world.setBlock(x+6, y+1, z+7, STRUCTURE_AIR);
		world.setBlock(x+6, y+1, z+8, STRUCTURE_AIR);
		world.setBlock(x+6, y+1, z+10, STRUCTURE_AIR);
		world.setBlock(x+6, y+1, z+11, STRUCTURE_AIR);
		world.setBlock(x+6, y+1, z+13, STRUCTURE_AIR);
		world.setBlock(x+6, y+1, z+14, STRUCTURE_AIR);
		world.setBlock(x+6, y+1, z+15, STRUCTURE_AIR);
		world.setBlock(x+6, y+1, z+16, STRUCTURE_AIR);
		world.setBlock(x+6, y+1, z+17, STRUCTURE_AIR);
		world.setBlock(x+6, y+1, z+18, STRUCTURE_AIR);
		world.setBlock(x+6, y+1, z+19, STRUCTURE_AIR);
		world.setBlock(x+6, y+1, z+21, STRUCTURE_AIR);
		world.setBlock(x+6, y+1, z+22, STRUCTURE_AIR);
		world.setBlock(x+6, y+1, z+23, STRUCTURE_AIR);
		world.setBlock(x+6, y+1, z+24, STRUCTURE_AIR);
		world.setBlock(x+6, y+1, z+25, STRUCTURE_AIR);
		world.setBlock(x+6, y+1, z+26, STRUCTURE_AIR);
		world.setBlock(x+6, y+1, z+27, STRUCTURE_AIR);
		world.setBlock(x+6, y+1, z+28, STRUCTURE_AIR);
		world.setBlock(x+6, y+1, z+30, STRUCTURE_AIR);
		world.setBlock(x+6, y+2, z+0, STRUCTURE_AIR);
		world.setBlock(x+6, y+2, z+1, STRUCTURE_AIR);
		world.setBlock(x+6, y+2, z+2, STRUCTURE_AIR);
		world.setBlock(x+6, y+2, z+3, STRUCTURE_AIR);
		world.setBlock(x+6, y+2, z+4, STRUCTURE_AIR);
		world.setBlock(x+6, y+2, z+5, STRUCTURE_AIR);
		world.setBlock(x+6, y+2, z+6, STRUCTURE_AIR);
		world.setBlock(x+6, y+2, z+7, STRUCTURE_AIR);
		world.setBlock(x+6, y+2, z+8, STRUCTURE_AIR);
		world.setBlock(x+6, y+2, z+10, STRUCTURE_AIR);
		world.setBlock(x+6, y+2, z+11, STRUCTURE_AIR);
		world.setBlock(x+6, y+2, z+13, STRUCTURE_AIR);
		world.setBlock(x+6, y+2, z+14, STRUCTURE_AIR);
		world.setBlock(x+6, y+2, z+15, STRUCTURE_AIR);
		world.setBlock(x+6, y+2, z+16, STRUCTURE_AIR);
		world.setBlock(x+6, y+2, z+17, STRUCTURE_AIR);
		world.setBlock(x+6, y+2, z+18, STRUCTURE_AIR);
		world.setBlock(x+6, y+2, z+19, STRUCTURE_AIR);
		world.setBlock(x+6, y+2, z+21, STRUCTURE_AIR);
		world.setBlock(x+6, y+2, z+22, STRUCTURE_AIR);
		world.setBlock(x+6, y+2, z+23, STRUCTURE_AIR);
		world.setBlock(x+6, y+2, z+24, STRUCTURE_AIR);
		world.setBlock(x+6, y+2, z+25, STRUCTURE_AIR);
		world.setBlock(x+6, y+2, z+26, STRUCTURE_AIR);
		world.setBlock(x+6, y+2, z+27, STRUCTURE_AIR);
		world.setBlock(x+6, y+2, z+28, STRUCTURE_AIR);
		world.setBlock(x+6, y+2, z+30, STRUCTURE_AIR);
		world.setBlock(x+6, y+3, z+0, STRUCTURE_AIR);
		world.setBlock(x+6, y+3, z+1, STRUCTURE_AIR);
		world.setBlock(x+6, y+3, z+2, STRUCTURE_AIR);
		world.setBlock(x+6, y+3, z+3, STRUCTURE_AIR);
		world.setBlock(x+6, y+3, z+4, STRUCTURE_AIR);
		world.setBlock(x+6, y+3, z+5, STRUCTURE_AIR);
		world.setBlock(x+6, y+3, z+6, STRUCTURE_AIR);
		world.setBlock(x+6, y+3, z+7, STRUCTURE_AIR);
		world.setBlock(x+6, y+3, z+8, STRUCTURE_AIR);
		world.setBlock(x+6, y+3, z+10, STRUCTURE_AIR);
		world.setBlock(x+6, y+3, z+11, STRUCTURE_AIR);
		world.setBlock(x+6, y+3, z+13, STRUCTURE_AIR);
		world.setBlock(x+6, y+3, z+14, STRUCTURE_AIR);
		world.setBlock(x+6, y+3, z+15, STRUCTURE_AIR);
		world.setBlock(x+6, y+3, z+16, STRUCTURE_AIR);
		world.setBlock(x+6, y+3, z+17, STRUCTURE_AIR);
		world.setBlock(x+6, y+3, z+18, STRUCTURE_AIR);
		world.setBlock(x+6, y+3, z+19, STRUCTURE_AIR);
		world.setBlock(x+6, y+3, z+21, STRUCTURE_AIR);
		world.setBlock(x+6, y+3, z+22, STRUCTURE_AIR);
		world.setBlock(x+6, y+3, z+23, STRUCTURE_AIR);
		world.setBlock(x+6, y+3, z+24, STRUCTURE_AIR);
		world.setBlock(x+6, y+3, z+25, STRUCTURE_AIR);
		world.setBlock(x+6, y+3, z+26, STRUCTURE_AIR);
		world.setBlock(x+6, y+3, z+27, STRUCTURE_AIR);
		world.setBlock(x+6, y+3, z+28, STRUCTURE_AIR);
		world.setBlock(x+6, y+3, z+30, STRUCTURE_AIR);
		world.setBlock(x+6, y+4, z+2, STRUCTURE_AIR);
		world.setBlock(x+6, y+4, z+3, STRUCTURE_AIR);
		world.setBlock(x+6, y+4, z+4, STRUCTURE_AIR);
		world.setBlock(x+6, y+4, z+5, STRUCTURE_AIR);
		world.setBlock(x+6, y+4, z+6, STRUCTURE_AIR);
		world.setBlock(x+6, y+4, z+7, STRUCTURE_AIR);
		world.setBlock(x+6, y+4, z+14, STRUCTURE_AIR);
		world.setBlock(x+6, y+4, z+15, STRUCTURE_AIR);
		world.setBlock(x+6, y+4, z+16, STRUCTURE_AIR);
		world.setBlock(x+6, y+4, z+17, STRUCTURE_AIR);
		world.setBlock(x+6, y+4, z+18, STRUCTURE_AIR);
		world.setBlock(x+6, y+4, z+22, STRUCTURE_AIR);
		world.setBlock(x+6, y+4, z+23, STRUCTURE_AIR);
		world.setBlock(x+6, y+4, z+24, STRUCTURE_AIR);
		world.setBlock(x+6, y+4, z+25, STRUCTURE_AIR);
		world.setBlock(x+6, y+4, z+26, STRUCTURE_AIR);
		world.setBlock(x+6, y+4, z+27, STRUCTURE_AIR);
		world.setBlock(x+7, y+1, z+0, STRUCTURE_AIR);
		world.setBlock(x+7, y+1, z+1, STRUCTURE_AIR);
		world.setBlock(x+7, y+1, z+2, STRUCTURE_AIR);
		world.setBlock(x+7, y+1, z+3, STRUCTURE_AIR);
		world.setBlock(x+7, y+1, z+4, STRUCTURE_AIR);
		world.setBlock(x+7, y+1, z+5, STRUCTURE_AIR);
		world.setBlock(x+7, y+1, z+6, STRUCTURE_AIR);
		world.setBlock(x+7, y+1, z+7, STRUCTURE_AIR);
		world.setBlock(x+7, y+1, z+8, STRUCTURE_AIR);
		world.setBlock(x+7, y+1, z+10, STRUCTURE_AIR);
		world.setBlock(x+7, y+1, z+11, STRUCTURE_AIR);
		world.setBlock(x+7, y+1, z+13, STRUCTURE_AIR);
		world.setBlock(x+7, y+1, z+14, STRUCTURE_AIR);
		world.setBlock(x+7, y+1, z+15, STRUCTURE_AIR);
		world.setBlock(x+7, y+1, z+16, STRUCTURE_AIR);
		world.setBlock(x+7, y+1, z+17, STRUCTURE_AIR);
		world.setBlock(x+7, y+1, z+18, STRUCTURE_AIR);
		world.setBlock(x+7, y+1, z+19, STRUCTURE_AIR);
		world.setBlock(x+7, y+1, z+21, STRUCTURE_AIR);
		world.setBlock(x+7, y+1, z+22, STRUCTURE_AIR);
		world.setBlock(x+7, y+1, z+23, STRUCTURE_AIR);
		world.setBlock(x+7, y+1, z+24, STRUCTURE_AIR);
		world.setBlock(x+7, y+1, z+25, STRUCTURE_AIR);
		world.setBlock(x+7, y+1, z+26, STRUCTURE_AIR);
		world.setBlock(x+7, y+1, z+27, STRUCTURE_AIR);
		world.setBlock(x+7, y+1, z+28, STRUCTURE_AIR);
		world.setBlock(x+7, y+1, z+30, STRUCTURE_AIR);
		world.setBlock(x+7, y+2, z+0, STRUCTURE_AIR);
		world.setBlock(x+7, y+2, z+1, STRUCTURE_AIR);
		world.setBlock(x+7, y+2, z+2, STRUCTURE_AIR);
		world.setBlock(x+7, y+2, z+3, STRUCTURE_AIR);
		world.setBlock(x+7, y+2, z+4, STRUCTURE_AIR);
		world.setBlock(x+7, y+2, z+5, STRUCTURE_AIR);
		world.setBlock(x+7, y+2, z+6, STRUCTURE_AIR);
		world.setBlock(x+7, y+2, z+7, STRUCTURE_AIR);
		world.setBlock(x+7, y+2, z+8, STRUCTURE_AIR);
		world.setBlock(x+7, y+2, z+10, STRUCTURE_AIR);
		world.setBlock(x+7, y+2, z+11, STRUCTURE_AIR);
		world.setBlock(x+7, y+2, z+13, STRUCTURE_AIR);
		world.setBlock(x+7, y+2, z+14, STRUCTURE_AIR);
		world.setBlock(x+7, y+2, z+15, STRUCTURE_AIR);
		world.setBlock(x+7, y+2, z+16, STRUCTURE_AIR);
		world.setBlock(x+7, y+2, z+17, STRUCTURE_AIR);
		world.setBlock(x+7, y+2, z+18, STRUCTURE_AIR);
		world.setBlock(x+7, y+2, z+19, STRUCTURE_AIR);
		world.setBlock(x+7, y+2, z+21, STRUCTURE_AIR);
		world.setBlock(x+7, y+2, z+22, STRUCTURE_AIR);
		world.setBlock(x+7, y+2, z+23, STRUCTURE_AIR);
		world.setBlock(x+7, y+2, z+24, STRUCTURE_AIR);
		world.setBlock(x+7, y+2, z+25, STRUCTURE_AIR);
		world.setBlock(x+7, y+2, z+26, STRUCTURE_AIR);
		world.setBlock(x+7, y+2, z+27, STRUCTURE_AIR);
		world.setBlock(x+7, y+2, z+28, STRUCTURE_AIR);
		world.setBlock(x+7, y+2, z+30, STRUCTURE_AIR);
		world.setBlock(x+7, y+3, z+0, STRUCTURE_AIR);
		world.setBlock(x+7, y+3, z+1, STRUCTURE_AIR);
		world.setBlock(x+7, y+3, z+2, STRUCTURE_AIR);
		world.setBlock(x+7, y+3, z+3, STRUCTURE_AIR);
		world.setBlock(x+7, y+3, z+4, STRUCTURE_AIR);
		world.setBlock(x+7, y+3, z+5, STRUCTURE_AIR);
		world.setBlock(x+7, y+3, z+6, STRUCTURE_AIR);
	}

	private void generate2(OriginBlockCache world, int x, int y, int z, Block b, int ms, int ml, int mc) {
		world.setBlock(x+7, y+3, z+7, STRUCTURE_AIR);
		world.setBlock(x+7, y+3, z+8, STRUCTURE_AIR);
		world.setBlock(x+7, y+3, z+10, STRUCTURE_AIR);
		world.setBlock(x+7, y+3, z+11, STRUCTURE_AIR);
		world.setBlock(x+7, y+3, z+13, STRUCTURE_AIR);
		world.setBlock(x+7, y+3, z+14, STRUCTURE_AIR);
		world.setBlock(x+7, y+3, z+15, STRUCTURE_AIR);
		world.setBlock(x+7, y+3, z+16, STRUCTURE_AIR);
		world.setBlock(x+7, y+3, z+17, STRUCTURE_AIR);
		world.setBlock(x+7, y+3, z+18, STRUCTURE_AIR);
		world.setBlock(x+7, y+3, z+19, STRUCTURE_AIR);
		world.setBlock(x+7, y+3, z+21, STRUCTURE_AIR);
		world.setBlock(x+7, y+3, z+22, STRUCTURE_AIR);
		world.setBlock(x+7, y+3, z+23, STRUCTURE_AIR);
		world.setBlock(x+7, y+3, z+24, STRUCTURE_AIR);
		world.setBlock(x+7, y+3, z+25, STRUCTURE_AIR);
		world.setBlock(x+7, y+3, z+26, STRUCTURE_AIR);
		world.setBlock(x+7, y+3, z+27, STRUCTURE_AIR);
		world.setBlock(x+7, y+3, z+28, STRUCTURE_AIR);
		world.setBlock(x+7, y+3, z+30, STRUCTURE_AIR);
		world.setBlock(x+7, y+4, z+2, STRUCTURE_AIR);
		world.setBlock(x+7, y+4, z+3, STRUCTURE_AIR);
		world.setBlock(x+7, y+4, z+4, STRUCTURE_AIR);
		world.setBlock(x+7, y+4, z+5, STRUCTURE_AIR);
		world.setBlock(x+7, y+4, z+6, STRUCTURE_AIR);
		world.setBlock(x+7, y+4, z+7, STRUCTURE_AIR);
		world.setBlock(x+7, y+4, z+14, STRUCTURE_AIR);
		world.setBlock(x+7, y+4, z+15, STRUCTURE_AIR);
		world.setBlock(x+7, y+4, z+16, STRUCTURE_AIR);
		world.setBlock(x+7, y+4, z+17, STRUCTURE_AIR);
		world.setBlock(x+7, y+4, z+18, STRUCTURE_AIR);
		world.setBlock(x+7, y+4, z+22, STRUCTURE_AIR);
		world.setBlock(x+7, y+4, z+23, STRUCTURE_AIR);
		world.setBlock(x+7, y+4, z+24, STRUCTURE_AIR);
		world.setBlock(x+7, y+4, z+25, STRUCTURE_AIR);
		world.setBlock(x+7, y+4, z+26, STRUCTURE_AIR);
		world.setBlock(x+7, y+4, z+27, STRUCTURE_AIR);
		world.setBlock(x+8, y+1, z+2, STRUCTURE_AIR);
		world.setBlock(x+8, y+1, z+3, STRUCTURE_AIR);
		world.setBlock(x+8, y+1, z+4, STRUCTURE_AIR);
		world.setBlock(x+8, y+1, z+5, STRUCTURE_AIR);
		world.setBlock(x+8, y+1, z+6, STRUCTURE_AIR);
		world.setBlock(x+8, y+1, z+7, STRUCTURE_AIR);
		world.setBlock(x+8, y+1, z+14, STRUCTURE_AIR);
		world.setBlock(x+8, y+1, z+15, STRUCTURE_AIR);
		world.setBlock(x+8, y+1, z+16, STRUCTURE_AIR);
		world.setBlock(x+8, y+1, z+17, STRUCTURE_AIR);
		world.setBlock(x+8, y+1, z+18, STRUCTURE_AIR);
		world.setBlock(x+8, y+1, z+22, STRUCTURE_AIR);
		world.setBlock(x+8, y+1, z+23, STRUCTURE_AIR);
		world.setBlock(x+8, y+1, z+24, STRUCTURE_AIR);
		world.setBlock(x+8, y+1, z+25, STRUCTURE_AIR);
		world.setBlock(x+8, y+1, z+26, STRUCTURE_AIR);
		world.setBlock(x+8, y+1, z+27, STRUCTURE_AIR);
		world.setBlock(x+8, y+2, z+2, STRUCTURE_AIR);
		world.setBlock(x+8, y+2, z+3, STRUCTURE_AIR);
		world.setBlock(x+8, y+2, z+4, STRUCTURE_AIR);
		world.setBlock(x+8, y+2, z+5, STRUCTURE_AIR);
		world.setBlock(x+8, y+2, z+6, STRUCTURE_AIR);
		world.setBlock(x+8, y+2, z+7, STRUCTURE_AIR);
		world.setBlock(x+8, y+2, z+14, STRUCTURE_AIR);
		world.setBlock(x+8, y+2, z+15, STRUCTURE_AIR);
		world.setBlock(x+8, y+2, z+16, STRUCTURE_AIR);
		world.setBlock(x+8, y+2, z+17, STRUCTURE_AIR);
		world.setBlock(x+8, y+2, z+18, STRUCTURE_AIR);
		world.setBlock(x+8, y+2, z+22, STRUCTURE_AIR);
		world.setBlock(x+8, y+2, z+23, STRUCTURE_AIR);
		world.setBlock(x+8, y+2, z+24, STRUCTURE_AIR);
		world.setBlock(x+8, y+2, z+25, STRUCTURE_AIR);
		world.setBlock(x+8, y+2, z+26, STRUCTURE_AIR);
		world.setBlock(x+8, y+2, z+27, STRUCTURE_AIR);
		world.setBlock(x+8, y+3, z+2, STRUCTURE_AIR);
		world.setBlock(x+8, y+3, z+3, STRUCTURE_AIR);
		world.setBlock(x+8, y+3, z+4, STRUCTURE_AIR);
		world.setBlock(x+8, y+3, z+5, STRUCTURE_AIR);
		world.setBlock(x+8, y+3, z+6, STRUCTURE_AIR);
		world.setBlock(x+8, y+3, z+7, STRUCTURE_AIR);
		world.setBlock(x+8, y+3, z+14, STRUCTURE_AIR);
		world.setBlock(x+8, y+3, z+15, STRUCTURE_AIR);
		world.setBlock(x+8, y+3, z+16, STRUCTURE_AIR);
		world.setBlock(x+8, y+3, z+17, STRUCTURE_AIR);
		world.setBlock(x+8, y+3, z+18, STRUCTURE_AIR);
		world.setBlock(x+8, y+3, z+22, STRUCTURE_AIR);
		world.setBlock(x+8, y+3, z+23, STRUCTURE_AIR);
		world.setBlock(x+8, y+3, z+24, STRUCTURE_AIR);
		world.setBlock(x+8, y+3, z+25, STRUCTURE_AIR);
		world.setBlock(x+8, y+3, z+26, STRUCTURE_AIR);
		world.setBlock(x+8, y+3, z+27, STRUCTURE_AIR);
		world.setBlock(x+8, y+4, z+2, STRUCTURE_AIR);
		world.setBlock(x+8, y+4, z+3, STRUCTURE_AIR);
		world.setBlock(x+8, y+4, z+4, STRUCTURE_AIR);
		world.setBlock(x+8, y+4, z+5, STRUCTURE_AIR);
		world.setBlock(x+8, y+4, z+6, STRUCTURE_AIR);
		world.setBlock(x+8, y+4, z+7, STRUCTURE_AIR);
		world.setBlock(x+8, y+4, z+14, STRUCTURE_AIR);
		world.setBlock(x+8, y+4, z+15, STRUCTURE_AIR);
		world.setBlock(x+8, y+4, z+16, STRUCTURE_AIR);
		world.setBlock(x+8, y+4, z+17, STRUCTURE_AIR);
		world.setBlock(x+8, y+4, z+18, STRUCTURE_AIR);
		world.setBlock(x+8, y+4, z+22, STRUCTURE_AIR);
		world.setBlock(x+8, y+4, z+23, STRUCTURE_AIR);
		world.setBlock(x+8, y+4, z+24, STRUCTURE_AIR);
		world.setBlock(x+8, y+4, z+25, STRUCTURE_AIR);
		world.setBlock(x+8, y+4, z+26, STRUCTURE_AIR);
		world.setBlock(x+8, y+4, z+27, STRUCTURE_AIR);
		world.setBlock(x+9, y+1, z+3, STRUCTURE_AIR);
		world.setBlock(x+9, y+1, z+4, STRUCTURE_AIR);
		world.setBlock(x+9, y+1, z+5, STRUCTURE_AIR);
		world.setBlock(x+9, y+1, z+7, STRUCTURE_AIR);
		world.setBlock(x+9, y+1, z+14, STRUCTURE_AIR);
		world.setBlock(x+9, y+1, z+15, STRUCTURE_AIR);
		world.setBlock(x+9, y+1, z+16, STRUCTURE_AIR);
		world.setBlock(x+9, y+1, z+17, STRUCTURE_AIR);
		world.setBlock(x+9, y+1, z+18, STRUCTURE_AIR);
		world.setBlock(x+9, y+2, z+3, STRUCTURE_AIR);
		world.setBlock(x+9, y+2, z+4, STRUCTURE_AIR);
		world.setBlock(x+9, y+2, z+5, STRUCTURE_AIR);
		world.setBlock(x+9, y+2, z+6, STRUCTURE_AIR);
		world.setBlock(x+9, y+2, z+7, STRUCTURE_AIR);
		world.setBlock(x+9, y+2, z+14, STRUCTURE_AIR);
		world.setBlock(x+9, y+2, z+15, STRUCTURE_AIR);
		world.setBlock(x+9, y+2, z+16, STRUCTURE_AIR);
		world.setBlock(x+9, y+2, z+17, STRUCTURE_AIR);
		world.setBlock(x+9, y+2, z+18, STRUCTURE_AIR);
		world.setBlock(x+9, y+3, z+3, STRUCTURE_AIR);
		world.setBlock(x+9, y+3, z+4, STRUCTURE_AIR);
		world.setBlock(x+9, y+3, z+5, STRUCTURE_AIR);
		world.setBlock(x+9, y+3, z+6, STRUCTURE_AIR);
		world.setBlock(x+9, y+3, z+7, STRUCTURE_AIR);
		world.setBlock(x+9, y+3, z+14, STRUCTURE_AIR);
		world.setBlock(x+9, y+3, z+15, STRUCTURE_AIR);
		world.setBlock(x+9, y+3, z+16, STRUCTURE_AIR);
		world.setBlock(x+9, y+3, z+17, STRUCTURE_AIR);
		world.setBlock(x+9, y+3, z+18, STRUCTURE_AIR);
		world.setBlock(x+9, y+4, z+3, STRUCTURE_AIR);
		world.setBlock(x+9, y+4, z+4, STRUCTURE_AIR);
		world.setBlock(x+9, y+4, z+5, STRUCTURE_AIR);
		world.setBlock(x+9, y+4, z+6, STRUCTURE_AIR);
		world.setBlock(x+9, y+4, z+7, STRUCTURE_AIR);
		world.setBlock(x+9, y+4, z+14, STRUCTURE_AIR);
		world.setBlock(x+9, y+4, z+15, STRUCTURE_AIR);
		world.setBlock(x+9, y+4, z+16, STRUCTURE_AIR);
		world.setBlock(x+9, y+4, z+17, STRUCTURE_AIR);
		world.setBlock(x+9, y+4, z+18, STRUCTURE_AIR);
		world.setBlock(x+10, y+1, z+3, STRUCTURE_AIR);
		world.setBlock(x+10, y+1, z+4, STRUCTURE_AIR);
		world.setBlock(x+10, y+1, z+5, STRUCTURE_AIR);
		world.setBlock(x+10, y+1, z+6, STRUCTURE_AIR);
		world.setBlock(x+10, y+1, z+7, STRUCTURE_AIR);
		world.setBlock(x+10, y+1, z+14, STRUCTURE_AIR);
		world.setBlock(x+10, y+1, z+15, STRUCTURE_AIR);
		world.setBlock(x+10, y+1, z+16, STRUCTURE_AIR);
		world.setBlock(x+10, y+1, z+17, STRUCTURE_AIR);
		world.setBlock(x+10, y+1, z+18, STRUCTURE_AIR);
		world.setBlock(x+10, y+2, z+3, STRUCTURE_AIR);
		world.setBlock(x+10, y+2, z+4, STRUCTURE_AIR);
		world.setBlock(x+10, y+2, z+5, STRUCTURE_AIR);
		world.setBlock(x+10, y+2, z+6, STRUCTURE_AIR);
		world.setBlock(x+10, y+2, z+7, STRUCTURE_AIR);
		world.setBlock(x+10, y+2, z+14, STRUCTURE_AIR);
		world.setBlock(x+10, y+2, z+15, STRUCTURE_AIR);
		world.setBlock(x+10, y+2, z+16, STRUCTURE_AIR);
		world.setBlock(x+10, y+2, z+17, STRUCTURE_AIR);
		world.setBlock(x+10, y+2, z+18, STRUCTURE_AIR);
		world.setBlock(x+10, y+3, z+3, STRUCTURE_AIR);
		world.setBlock(x+10, y+3, z+4, STRUCTURE_AIR);
		world.setBlock(x+10, y+3, z+5, STRUCTURE_AIR);
		world.setBlock(x+10, y+3, z+6, STRUCTURE_AIR);
		world.setBlock(x+10, y+3, z+7, STRUCTURE_AIR);
		world.setBlock(x+10, y+3, z+14, STRUCTURE_AIR);
		world.setBlock(x+10, y+3, z+15, STRUCTURE_AIR);
		world.setBlock(x+10, y+3, z+16, STRUCTURE_AIR);
		world.setBlock(x+10, y+3, z+17, STRUCTURE_AIR);
		world.setBlock(x+10, y+3, z+18, STRUCTURE_AIR);
		world.setBlock(x+10, y+4, z+3, STRUCTURE_AIR);
		world.setBlock(x+10, y+4, z+4, STRUCTURE_AIR);
		world.setBlock(x+10, y+4, z+5, STRUCTURE_AIR);
		world.setBlock(x+10, y+4, z+6, STRUCTURE_AIR);
		world.setBlock(x+10, y+4, z+7, STRUCTURE_AIR);
		world.setBlock(x+10, y+4, z+14, STRUCTURE_AIR);
		world.setBlock(x+10, y+4, z+15, STRUCTURE_AIR);
		world.setBlock(x+10, y+4, z+16, STRUCTURE_AIR);
		world.setBlock(x+10, y+4, z+17, STRUCTURE_AIR);
		world.setBlock(x+10, y+4, z+18, STRUCTURE_AIR);
		world.setBlock(x+11, y+1, z+3, STRUCTURE_AIR);
		world.setBlock(x+11, y+1, z+4, STRUCTURE_AIR);
		world.setBlock(x+11, y+1, z+5, STRUCTURE_AIR);
		world.setBlock(x+11, y+1, z+6, STRUCTURE_AIR);
		world.setBlock(x+11, y+1, z+7, STRUCTURE_AIR);
		world.setBlock(x+11, y+1, z+14, STRUCTURE_AIR);
		world.setBlock(x+11, y+1, z+15, STRUCTURE_AIR);
		world.setBlock(x+11, y+1, z+16, STRUCTURE_AIR);
		world.setBlock(x+11, y+1, z+17, STRUCTURE_AIR);
		world.setBlock(x+11, y+1, z+18, STRUCTURE_AIR);
		world.setBlock(x+11, y+2, z+3, STRUCTURE_AIR);
		world.setBlock(x+11, y+2, z+4, STRUCTURE_AIR);
		world.setBlock(x+11, y+2, z+5, STRUCTURE_AIR);
		world.setBlock(x+11, y+2, z+6, STRUCTURE_AIR);
		world.setBlock(x+11, y+2, z+7, STRUCTURE_AIR);
		world.setBlock(x+11, y+2, z+14, STRUCTURE_AIR);
		world.setBlock(x+11, y+2, z+15, STRUCTURE_AIR);
		world.setBlock(x+11, y+2, z+16, STRUCTURE_AIR);
		world.setBlock(x+11, y+2, z+17, STRUCTURE_AIR);
		world.setBlock(x+11, y+2, z+18, STRUCTURE_AIR);
		world.setBlock(x+11, y+3, z+3, STRUCTURE_AIR);
		world.setBlock(x+11, y+3, z+4, STRUCTURE_AIR);
		world.setBlock(x+11, y+3, z+5, STRUCTURE_AIR);
		world.setBlock(x+11, y+3, z+6, STRUCTURE_AIR);
		world.setBlock(x+11, y+3, z+7, STRUCTURE_AIR);
		world.setBlock(x+11, y+3, z+14, STRUCTURE_AIR);
		world.setBlock(x+11, y+3, z+15, STRUCTURE_AIR);
		world.setBlock(x+11, y+3, z+16, STRUCTURE_AIR);
		world.setBlock(x+11, y+3, z+17, STRUCTURE_AIR);
		world.setBlock(x+11, y+3, z+18, STRUCTURE_AIR);
		world.setBlock(x+11, y+4, z+3, STRUCTURE_AIR);
		world.setBlock(x+11, y+4, z+4, STRUCTURE_AIR);
		world.setBlock(x+11, y+4, z+5, STRUCTURE_AIR);
		world.setBlock(x+11, y+4, z+6, STRUCTURE_AIR);
		world.setBlock(x+11, y+4, z+7, STRUCTURE_AIR);
		world.setBlock(x+11, y+4, z+14, STRUCTURE_AIR);
		world.setBlock(x+11, y+4, z+15, STRUCTURE_AIR);
		world.setBlock(x+11, y+4, z+16, STRUCTURE_AIR);
		world.setBlock(x+11, y+4, z+17, STRUCTURE_AIR);
		world.setBlock(x+11, y+4, z+18, STRUCTURE_AIR);
	}

	@Override
	public int getWidth() {
		return 13;
	}

	@Override
	public int getLength() {
		return 29;
	}

	@Override
	public int getEnterExitDL() {
		return 31;
	}

	@Override
	public int getEnterExitDT() {
		return 0;
	}

	@Override
	public int getInitialOffset() {
		return 0;
	}

	@Override
	public int getMirroredOffset() {
		return 0;
	}

	@Override
	public int getDifficultyRating() {
		return 1;
	}

	@Override
	public int getFeatureRating() {
		return 0;
	}

	@Override
	public int getWeightValue() {
		return Integer.MIN_VALUE/2;
	}

}
