/*******************************************************************************
 * @author Reika Kalseki
 * 
 * Copyright 2017
 * 
 * All rights reserved.
 * Distribution of the software in any form is only allowed with
 * explicit, prior permission from the owner.
 ******************************************************************************/
package Reika.ChromatiCraft.World.Dimension.Structure.Locks;

import net.minecraft.block.Block;
import net.minecraft.init.Blocks;

import Reika.ChromatiCraft.Base.LockLevel;
import Reika.ChromatiCraft.Block.Dimension.Structure.Locks.BlockLockKey.LockChannel;
import Reika.ChromatiCraft.Block.Worldgen.BlockStructureShield.BlockType;
import Reika.ChromatiCraft.Registry.ChromaBlocks;
import Reika.ChromatiCraft.World.Dimension.Structure.LocksGenerator;
import Reika.DragonAPI.Instantiable.Worldgen.OriginBlockCache;

public class LocksRoomWhite extends LockLevel {

	public LocksRoomWhite(LocksGenerator g) {
		super(g, LockChannel.WHITE);
	}

	@Override
	public void generate(OriginBlockCache world, int x, int y, int z) {
		Block b = ChromaBlocks.STRUCTSHIELD.getBlockInstance();
		int ms = BlockType.STONE.metadata;
		int ml = BlockType.LIGHT.metadata;
		int mc = BlockType.CLOAK.metadata;
		this.generate1(world, x, y, z, b, ms, ml, mc);
		this.generate2(world, x, y, z, b, ms, ml, mc);
	}

	private void generate1(OriginBlockCache world, int x, int y, int z, Block b, int ms, int ml, int mc) {
		world.setBlock(x+0, y+0, z+2, b, ms);
		world.setBlock(x+0, y+0, z+3, b, ms);
		world.setBlock(x+0, y+0, z+4, b, ms);
		world.setBlock(x+0, y+0, z+5, b, ms);
		world.setBlock(x+0, y+0, z+18, b, ms);
		world.setBlock(x+0, y+0, z+19, b, ms);
		world.setBlock(x+0, y+0, z+20, b, ms);
		world.setBlock(x+0, y+0, z+21, b, ms);
		world.setBlock(x+0, y+0, z+22, b, ms);
		world.setBlock(x+0, y+0, z+23, b, ms);
		world.setBlock(x+0, y+1, z+2, b, ms);
		world.setBlock(x+0, y+1, z+3, b, ms);
		world.setBlock(x+0, y+1, z+4, b, ms);
		world.setBlock(x+0, y+1, z+5, b, ms);
		world.setBlock(x+0, y+1, z+18, b, ms);
		world.setBlock(x+0, y+1, z+19, b, ms);
		world.setBlock(x+0, y+1, z+20, b, ms);
		world.setBlock(x+0, y+1, z+21, b, ms);
		world.setBlock(x+0, y+1, z+22, b, ms);
		world.setBlock(x+0, y+1, z+23, b, ms);
		world.setBlock(x+0, y+2, z+2, b, ms);
		world.setBlock(x+0, y+2, z+3, b, ms);
		world.setBlock(x+0, y+2, z+4, b, ms);
		world.setBlock(x+0, y+2, z+5, b, ms);
		world.setBlock(x+0, y+2, z+18, b, ms);
		world.setBlock(x+0, y+2, z+19, b, ms);
		world.setBlock(x+0, y+2, z+20, b, ml);
		world.setBlock(x+0, y+2, z+21, b, ms);
		world.setBlock(x+0, y+2, z+22, b, ms);
		world.setBlock(x+0, y+2, z+23, b, ms);
		world.setBlock(x+0, y+3, z+2, b, ms);
		world.setBlock(x+0, y+3, z+3, b, ms);
		world.setBlock(x+0, y+3, z+4, b, ms);
		world.setBlock(x+0, y+3, z+5, b, ms);
		world.setBlock(x+0, y+3, z+18, b, ms);
		world.setBlock(x+0, y+3, z+19, b, ms);
		world.setBlock(x+0, y+3, z+20, b, ms);
		world.setBlock(x+0, y+3, z+21, b, ms);
		world.setBlock(x+0, y+3, z+22, b, ms);
		world.setBlock(x+0, y+3, z+23, b, ms);
		world.setBlock(x+0, y+4, z+18, b, ms);
		world.setBlock(x+0, y+4, z+19, b, ms);
		world.setBlock(x+0, y+4, z+20, b, ms);
		world.setBlock(x+0, y+4, z+21, b, ms);
		world.setBlock(x+0, y+4, z+22, b, ms);
		world.setBlock(x+0, y+4, z+23, b, ms);
		world.setBlock(x+0, y+5, z+18, b, ms);
		world.setBlock(x+0, y+5, z+19, b, ms);
		world.setBlock(x+0, y+5, z+20, b, ms);
		world.setBlock(x+0, y+5, z+21, b, ms);
		world.setBlock(x+0, y+5, z+22, b, ms);
		world.setBlock(x+0, y+5, z+23, b, ms);
		world.setBlock(x+1, y+0, z+2, b, ms);
		world.setBlock(x+1, y+0, z+3, b, ms);
		world.setBlock(x+1, y+0, z+4, b, ms);
		world.setBlock(x+1, y+0, z+5, b, ms);
		world.setBlock(x+1, y+0, z+16, b, ms);
		world.setBlock(x+1, y+0, z+17, b, ms);
		world.setBlock(x+1, y+0, z+18, b, ms);
		world.setBlock(x+1, y+0, z+19, b, ms);
		world.setBlock(x+1, y+0, z+20, b, ms);
		world.setBlock(x+1, y+0, z+21, b, ms);
		world.setBlock(x+1, y+0, z+22, b, ms);
		world.setBlock(x+1, y+0, z+23, b, ms);
		world.setBlock(x+1, y+0, z+24, b, ms);
		world.setBlock(x+1, y+0, z+25, b, ms);
		world.setBlock(x+1, y+0, z+26, b, ms);
		world.setBlock(x+1, y+0, z+27, b, ms);
		world.setBlock(x+1, y+0, z+28, b, ms);
		world.setBlock(x+1, y+0, z+29, b, ms);
		world.setBlock(x+1, y+0, z+30, b, ms);
		world.setBlock(x+1, y+0, z+31, b, ms);
		world.setBlock(x+1, y+0, z+32, b, ms);
		world.setBlock(x+1, y+0, z+33, b, ms);
		world.setBlock(x+1, y+0, z+34, b, ms);
		world.setBlock(x+1, y+1, z+2, b, ms);
		world.setBlock(x+1, y+1, z+3, b, ms);
		world.setBlock(x+1, y+1, z+4, b, ms);
		world.setBlock(x+1, y+1, z+5, b, ms);
		world.setBlock(x+1, y+1, z+16, b, ms);
		world.setBlock(x+1, y+1, z+17, b, ms);
		world.setBlock(x+1, y+1, z+18, b, ms);
		world.setBlock(x+1, y+1, z+23, b, ms);
		world.setBlock(x+1, y+1, z+24, b, ms);
		world.setBlock(x+1, y+1, z+25, b, ms);
		world.setBlock(x+1, y+1, z+26, b, ms);
		world.setBlock(x+1, y+1, z+27, b, ms);
		world.setBlock(x+1, y+1, z+28, b, ms);
		world.setBlock(x+1, y+1, z+29, b, ms);
		world.setBlock(x+1, y+1, z+30, b, ms);
		world.setBlock(x+1, y+1, z+31, b, ms);
		world.setBlock(x+1, y+1, z+32, b, ms);
		world.setBlock(x+1, y+1, z+33, b, ms);
		world.setBlock(x+1, y+1, z+34, b, ms);
		world.setBlock(x+1, y+2, z+2, b, ms);
		world.setBlock(x+1, y+2, z+3, b, ms);
		this.generateRune(x+1, y+2, z+4, LockColor.RED);
		world.setBlock(x+1, y+2, z+5, b, ms);
		world.setBlock(x+1, y+2, z+16, b, ms);
		world.setBlock(x+1, y+2, z+17, b, ms);
		world.setBlock(x+1, y+2, z+18, b, ms);
		world.setBlock(x+1, y+2, z+23, b, ms);
		world.setBlock(x+1, y+2, z+24, b, ms);
		world.setBlock(x+1, y+2, z+25, b, ms);
		world.setBlock(x+1, y+2, z+26, b, ms);
		world.setBlock(x+1, y+2, z+27, b, ms);
		world.setBlock(x+1, y+2, z+28, b, ml);
		world.setBlock(x+1, y+2, z+29, b, ms);
		world.setBlock(x+1, y+2, z+30, b, ms);
		world.setBlock(x+1, y+2, z+31, b, ms);
		world.setBlock(x+1, y+2, z+32, b, ms);
		world.setBlock(x+1, y+2, z+33, b, ms);
		world.setBlock(x+1, y+2, z+34, b, ms);
		world.setBlock(x+1, y+3, z+2, b, ms);
		world.setBlock(x+1, y+3, z+3, b, ms);
		world.setBlock(x+1, y+3, z+4, b, ms);
		world.setBlock(x+1, y+3, z+5, b, ms);
		world.setBlock(x+1, y+3, z+16, b, ms);
		world.setBlock(x+1, y+3, z+17, b, ms);
		world.setBlock(x+1, y+3, z+18, b, ms);
		world.setBlock(x+1, y+3, z+23, b, ms);
		world.setBlock(x+1, y+3, z+24, b, ms);
		world.setBlock(x+1, y+3, z+25, b, ms);
		world.setBlock(x+1, y+3, z+26, b, ms);
		world.setBlock(x+1, y+3, z+27, b, ms);
		world.setBlock(x+1, y+3, z+28, b, ms);
		world.setBlock(x+1, y+3, z+29, b, ms);
		world.setBlock(x+1, y+3, z+30, b, ms);
		world.setBlock(x+1, y+3, z+31, b, ms);
		world.setBlock(x+1, y+3, z+32, b, ms);
		world.setBlock(x+1, y+3, z+33, b, ms);
		world.setBlock(x+1, y+3, z+34, b, ms);
		world.setBlock(x+1, y+4, z+18, b, ms);
		world.setBlock(x+1, y+4, z+23, b, ms);
		world.setBlock(x+1, y+4, z+24, b, ms);
		world.setBlock(x+1, y+4, z+25, b, ms);
		world.setBlock(x+1, y+4, z+26, b, ms);
		world.setBlock(x+1, y+4, z+27, b, ms);
		world.setBlock(x+1, y+4, z+28, b, ms);
		world.setBlock(x+1, y+4, z+29, b, ms);
		world.setBlock(x+1, y+4, z+30, b, ms);
		world.setBlock(x+1, y+4, z+31, b, ms);
		world.setBlock(x+1, y+4, z+32, b, ms);
		world.setBlock(x+1, y+4, z+33, b, ms);
		world.setBlock(x+1, y+4, z+34, b, ms);
		world.setBlock(x+1, y+5, z+18, b, ms);
		world.setBlock(x+1, y+5, z+19, b, ms);
		world.setBlock(x+1, y+5, z+20, b, ms);
		world.setBlock(x+1, y+5, z+21, b, ms);
		world.setBlock(x+1, y+5, z+22, b, ms);
		world.setBlock(x+1, y+5, z+23, b, ms);
		world.setBlock(x+1, y+5, z+24, b, ms);
		world.setBlock(x+1, y+5, z+25, b, ms);
		world.setBlock(x+1, y+5, z+26, b, ms);
		world.setBlock(x+1, y+5, z+27, b, ms);
		world.setBlock(x+1, y+5, z+28, b, ms);
		world.setBlock(x+1, y+5, z+29, b, ms);
		world.setBlock(x+1, y+5, z+30, b, ms);
		world.setBlock(x+1, y+5, z+31, b, ms);
		world.setBlock(x+1, y+5, z+32, b, ms);
		world.setBlock(x+2, y+0, z+1, b, ms);
		world.setBlock(x+2, y+0, z+2, b, ms);
		world.setBlock(x+2, y+0, z+3, b, ms);
		world.setBlock(x+2, y+0, z+4, b, ms);
		world.setBlock(x+2, y+0, z+5, b, ms);
		world.setBlock(x+2, y+0, z+6, b, ms);
		world.setBlock(x+2, y+0, z+7, b, ms);
		world.setBlock(x+2, y+0, z+8, b, ms);
		world.setBlock(x+2, y+0, z+9, b, ms);
		world.setBlock(x+2, y+0, z+10, b, ms);
		world.setBlock(x+2, y+0, z+11, b, ms);
		world.setBlock(x+2, y+0, z+12, b, ms);
		world.setBlock(x+2, y+0, z+13, b, ms);
		world.setBlock(x+2, y+0, z+14, b, ms);
		world.setBlock(x+2, y+0, z+15, b, ms);
		world.setBlock(x+2, y+0, z+16, b, ms);
		world.setBlock(x+2, y+0, z+17, b, ms);
		world.setBlock(x+2, y+0, z+18, b, ms);
		world.setBlock(x+2, y+0, z+19, b, ms);
		world.setBlock(x+2, y+0, z+20, b, ms);
		world.setBlock(x+2, y+0, z+21, b, ms);
		world.setBlock(x+2, y+0, z+22, b, ms);
		world.setBlock(x+2, y+0, z+23, b, ms);
		world.setBlock(x+2, y+0, z+24, b, ms);
		world.setBlock(x+2, y+0, z+25, b, ms);
		world.setBlock(x+2, y+0, z+26, b, ms);
		world.setBlock(x+2, y+0, z+27, b, ms);
		world.setBlock(x+2, y+0, z+28, b, ms);
		world.setBlock(x+2, y+0, z+29, b, ms);
		world.setBlock(x+2, y+0, z+30, b, ms);
		world.setBlock(x+2, y+0, z+31, b, ms);
		world.setBlock(x+2, y+0, z+32, b, ms);
		world.setBlock(x+2, y+0, z+33, b, ms);
		world.setBlock(x+2, y+0, z+34, b, ms);
		world.setBlock(x+2, y+1, z+1, b, ms);
		world.setBlock(x+2, y+1, z+2, b, ms);
		world.setBlock(x+2, y+1, z+3, b, ms);
		world.setBlock(x+2, y+1, z+4, b, ms);
		world.setBlock(x+2, y+1, z+5, b, ms);
		world.setBlock(x+2, y+1, z+6, b, ms);
		world.setBlock(x+2, y+1, z+7, b, ms);
		world.setBlock(x+2, y+1, z+8, b, ms);
		world.setBlock(x+2, y+1, z+9, b, ms);
		world.setBlock(x+2, y+1, z+10, b, ms);
		world.setBlock(x+2, y+1, z+11, b, ms);
		world.setBlock(x+2, y+1, z+12, b, ms);
		world.setBlock(x+2, y+1, z+13, b, ms);
		world.setBlock(x+2, y+1, z+14, b, ms);
		world.setBlock(x+2, y+1, z+15, b, ms);
		world.setBlock(x+2, y+1, z+16, b, ms);
		world.setBlock(x+2, y+1, z+17, b, ms);
		world.setBlock(x+2, y+1, z+18, b, ms);
		this.generateLock(x+2, y+1, z+24, LockColor.YELLOW);
		this.generateGate(x+2, y+1, z+33);
		world.setBlock(x+2, y+2, z+1, b, ms);
		world.setBlock(x+2, y+2, z+2, b, ms);
		world.setBlock(x+2, y+2, z+3, b, ms);
		world.setBlock(x+2, y+2, z+5, b, ms);
		world.setBlock(x+2, y+2, z+6, b, ms);
		world.setBlock(x+2, y+2, z+7, b, ms);
		world.setBlock(x+2, y+2, z+8, b, ms);
		world.setBlock(x+2, y+2, z+9, b, ms);
		world.setBlock(x+2, y+2, z+10, b, ms);
		world.setBlock(x+2, y+2, z+11, b, ms);
		world.setBlock(x+2, y+2, z+12, b, ml);
		world.setBlock(x+2, y+2, z+13, b, ms);
		world.setBlock(x+2, y+2, z+14, b, ms);
		world.setBlock(x+2, y+2, z+15, b, ms);
		world.setBlock(x+2, y+2, z+16, b, ms);
		this.generateWhiteRune(x+2, y+2, z+17);
		this.generateLock(x+2, y+2, z+24, LockColor.YELLOW);
		this.generateGate(x+2, y+2, z+33);
		world.setBlock(x+2, y+3, z+1, b, ms);
		world.setBlock(x+2, y+3, z+2, b, ms);
		world.setBlock(x+2, y+3, z+3, b, ms);
		world.setBlock(x+2, y+3, z+4, b, ms);
		world.setBlock(x+2, y+3, z+5, b, ms);
		world.setBlock(x+2, y+3, z+6, b, ms);
		world.setBlock(x+2, y+3, z+7, b, ms);
		world.setBlock(x+2, y+3, z+8, b, ms);
		world.setBlock(x+2, y+3, z+9, b, ms);
		world.setBlock(x+2, y+3, z+10, b, ms);
		world.setBlock(x+2, y+3, z+11, b, ms);
		world.setBlock(x+2, y+3, z+12, b, ms);
		world.setBlock(x+2, y+3, z+13, b, ms);
		world.setBlock(x+2, y+3, z+14, b, ms);
		world.setBlock(x+2, y+3, z+15, b, ms);
		world.setBlock(x+2, y+3, z+16, b, ms);
		world.setBlock(x+2, y+3, z+17, b, ms);
		world.setBlock(x+2, y+3, z+18, b, ms);
		this.generateLock(x+2, y+3, z+24, LockColor.YELLOW);
		this.generateGate(x+2, y+3, z+33);
		world.setBlock(x+2, y+4, z+1, b, ms);
		world.setBlock(x+2, y+4, z+2, b, ms);
		world.setBlock(x+2, y+4, z+3, b, ms);
		world.setBlock(x+2, y+4, z+4, b, ms);
		world.setBlock(x+2, y+4, z+5, b, ms);
		world.setBlock(x+2, y+4, z+6, b, ms);
		world.setBlock(x+2, y+4, z+7, b, ms);
		world.setBlock(x+2, y+4, z+8, b, ms);
		world.setBlock(x+2, y+4, z+9, b, ms);
		world.setBlock(x+2, y+4, z+10, b, ms);
		world.setBlock(x+2, y+4, z+11, b, ms);
		world.setBlock(x+2, y+4, z+12, b, ms);
		world.setBlock(x+2, y+4, z+13, b, ms);
		world.setBlock(x+2, y+4, z+14, b, ms);
		world.setBlock(x+2, y+4, z+15, b, ms);
		world.setBlock(x+2, y+4, z+18, b, ms);
		world.setBlock(x+2, y+4, z+23, b, ms);
		world.setBlock(x+2, y+4, z+24, b, ms);
		world.setBlock(x+2, y+4, z+25, b, ms);
		world.setBlock(x+2, y+4, z+32, b, ms);
		world.setBlock(x+2, y+4, z+33, b, ms);
		world.setBlock(x+2, y+4, z+34, b, ms);
		world.setBlock(x+2, y+5, z+1, b, ms);
		world.setBlock(x+2, y+5, z+2, b, ms);
		world.setBlock(x+2, y+5, z+3, b, ms);
		world.setBlock(x+2, y+5, z+4, b, ms);
		world.setBlock(x+2, y+5, z+5, b, ms);
		world.setBlock(x+2, y+5, z+6, b, ms);
		world.setBlock(x+2, y+5, z+7, b, ms);
		world.setBlock(x+2, y+5, z+8, b, ms);
		world.setBlock(x+2, y+5, z+9, b, ms);
		world.setBlock(x+2, y+5, z+10, b, ms);
		world.setBlock(x+2, y+5, z+11, b, ms);
		world.setBlock(x+2, y+5, z+12, b, ms);
		world.setBlock(x+2, y+5, z+13, b, ms);
		world.setBlock(x+2, y+5, z+14, b, ms);
		world.setBlock(x+2, y+5, z+15, b, ms);
		world.setBlock(x+2, y+5, z+18, b, ms);
		world.setBlock(x+2, y+5, z+19, b, ms);
		world.setBlock(x+2, y+5, z+20, b, ms);
		world.setBlock(x+2, y+5, z+21, b, ms);
		world.setBlock(x+2, y+5, z+22, b, ms);
		world.setBlock(x+2, y+5, z+23, b, ms);
		world.setBlock(x+2, y+5, z+24, b, ms);
		world.setBlock(x+2, y+5, z+25, b, ms);
		world.setBlock(x+2, y+5, z+26, b, ms);
		world.setBlock(x+2, y+5, z+27, b, ms);
		world.setBlock(x+2, y+5, z+28, b, ms);
		world.setBlock(x+2, y+5, z+29, b, ms);
		world.setBlock(x+2, y+5, z+30, b, ms);
		world.setBlock(x+2, y+5, z+31, b, ms);
		world.setBlock(x+2, y+5, z+32, b, ms);
		world.setBlock(x+3, y+0, z+0, b, ms);
		world.setBlock(x+3, y+0, z+1, b, ms);
		world.setBlock(x+3, y+0, z+2, b, ms);
		world.setBlock(x+3, y+0, z+3, b, ms);
		world.setBlock(x+3, y+0, z+4, b, ms);
		world.setBlock(x+3, y+0, z+5, b, ms);
		world.setBlock(x+3, y+0, z+6, b, ms);
		world.setBlock(x+3, y+0, z+7, b, ms);
		world.setBlock(x+3, y+0, z+8, b, ms);
		world.setBlock(x+3, y+0, z+9, b, ms);
		world.setBlock(x+3, y+0, z+10, b, ms);
		world.setBlock(x+3, y+0, z+11, b, ms);
		world.setBlock(x+3, y+0, z+12, b, ms);
		world.setBlock(x+3, y+0, z+13, b, ms);
		world.setBlock(x+3, y+0, z+14, b, ms);
		world.setBlock(x+3, y+0, z+15, b, ms);
		world.setBlock(x+3, y+0, z+16, b, ms);
		world.setBlock(x+3, y+0, z+17, b, ms);
		world.setBlock(x+3, y+0, z+18, b, ms);
		world.setBlock(x+3, y+0, z+19, b, ms);
		world.setBlock(x+3, y+0, z+20, b, ms);
		world.setBlock(x+3, y+0, z+21, b, ms);
		world.setBlock(x+3, y+0, z+22, b, ms);
		world.setBlock(x+3, y+0, z+23, b, ms);
		world.setBlock(x+3, y+0, z+24, b, ms);
		world.setBlock(x+3, y+0, z+25, b, ms);
		world.setBlock(x+3, y+0, z+26, b, ms);
		world.setBlock(x+3, y+0, z+27, b, ms);
		world.setBlock(x+3, y+0, z+28, b, ms);
		world.setBlock(x+3, y+0, z+29, b, ms);
		world.setBlock(x+3, y+0, z+30, b, ms);
		world.setBlock(x+3, y+0, z+31, b, ms);
		world.setBlock(x+3, y+0, z+32, b, ms);
		world.setBlock(x+3, y+0, z+33, b, ms);
		world.setBlock(x+3, y+0, z+34, b, ms);
		world.setBlock(x+3, y+1, z+0, b, ms);
		world.setBlock(x+3, y+1, z+1, b, ms);
		world.setBlock(x+3, y+1, z+6, b, ms);
		world.setBlock(x+3, y+1, z+7, b, ms);
		world.setBlock(x+3, y+1, z+8, b, ms);
		world.setBlock(x+3, y+1, z+9, b, ms);
		world.setBlock(x+3, y+1, z+15, b, ms);
		world.setBlock(x+3, y+1, z+16, b, ms);
		world.setBlock(x+3, y+1, z+17, b, ms);
		world.setBlock(x+3, y+1, z+18, b, ms);
		this.generateLock(x+3, y+1, z+24, LockColor.YELLOW);
		this.generateGate(x+3, y+1, z+33);

		this.generateRune(x+5, y, z+28, LockColor.YELLOW);

		world.setBlock(x+3, y+2, z+0, b, ms);
		world.setBlock(x+3, y+2, z+1, b, ml);
		world.setBlock(x+3, y+2, z+6, b, ms);
		world.setBlock(x+3, y+2, z+7, b, ms);
		world.setBlock(x+3, y+2, z+8, b, ms);
		world.setBlock(x+3, y+2, z+9, b, ms);
		world.setBlock(x+3, y+2, z+15, b, ms);
		world.setBlock(x+3, y+2, z+16, b, ms);
		world.setBlock(x+3, y+2, z+17, b, ms);
		world.setBlock(x+3, y+2, z+18, b, ms);
		this.generateLock(x+3, y+2, z+24, LockColor.YELLOW);
		this.generateGate(x+3, y+2, z+33);
		world.setBlock(x+3, y+3, z+0, b, ms);
		world.setBlock(x+3, y+3, z+1, b, ms);
		world.setBlock(x+3, y+3, z+6, b, ms);
		world.setBlock(x+3, y+3, z+7, b, ms);
		world.setBlock(x+3, y+3, z+8, b, ms);
		world.setBlock(x+3, y+3, z+9, b, ms);
		world.setBlock(x+3, y+3, z+15, b, ms);
		world.setBlock(x+3, y+3, z+16, b, ms);
		world.setBlock(x+3, y+3, z+17, b, ms);
		world.setBlock(x+3, y+3, z+18, b, ms);
		this.generateLock(x+3, y+3, z+24, LockColor.YELLOW);
		this.generateGate(x+3, y+3, z+33);
		world.setBlock(x+3, y+4, z+0, b, ms);
		world.setBlock(x+3, y+4, z+1, b, ms);
		world.setBlock(x+3, y+4, z+6, b, ms);
		world.setBlock(x+3, y+4, z+7, b, ms);
		world.setBlock(x+3, y+4, z+8, b, ms);
		world.setBlock(x+3, y+4, z+9, b, ms);
		world.setBlock(x+3, y+4, z+15, b, ms);
		world.setBlock(x+3, y+4, z+18, b, ms);
		world.setBlock(x+3, y+4, z+23, b, ml);
		world.setBlock(x+3, y+4, z+24, b, ms);
		world.setBlock(x+3, y+4, z+25, b, ml);
		world.setBlock(x+3, y+4, z+32, b, ml);
		world.setBlock(x+3, y+4, z+33, b, ms);
		world.setBlock(x+3, y+4, z+34, b, ms);
		world.setBlock(x+3, y+5, z+1, b, ms);
		world.setBlock(x+3, y+5, z+2, b, ms);
		world.setBlock(x+3, y+5, z+3, b, ms);
		world.setBlock(x+3, y+5, z+4, b, ms);
		world.setBlock(x+3, y+5, z+5, b, ms);
		world.setBlock(x+3, y+5, z+6, b, ms);
		world.setBlock(x+3, y+5, z+7, b, ms);
		world.setBlock(x+3, y+5, z+8, b, ms);
		world.setBlock(x+3, y+5, z+9, b, ms);
		world.setBlock(x+3, y+5, z+10, b, ms);
		world.setBlock(x+3, y+5, z+11, b, ms);
		world.setBlock(x+3, y+5, z+12, b, ms);
		world.setBlock(x+3, y+5, z+13, b, ms);
		world.setBlock(x+3, y+5, z+14, b, ms);
		world.setBlock(x+3, y+5, z+15, b, ms);
		world.setBlock(x+3, y+5, z+18, b, ms);
		world.setBlock(x+3, y+5, z+19, b, ms);
		world.setBlock(x+3, y+5, z+20, b, ms);
		world.setBlock(x+3, y+5, z+21, b, ms);
		world.setBlock(x+3, y+5, z+22, b, ms);
		world.setBlock(x+3, y+5, z+23, b, ms);
		world.setBlock(x+3, y+5, z+24, b, ms);
		world.setBlock(x+3, y+5, z+25, b, ms);
		world.setBlock(x+3, y+5, z+26, b, ms);
		world.setBlock(x+3, y+5, z+27, b, ms);
		world.setBlock(x+3, y+5, z+28, b, ms);
		world.setBlock(x+3, y+5, z+29, b, ms);
		world.setBlock(x+3, y+5, z+30, b, ms);
		world.setBlock(x+3, y+5, z+31, b, ms);
		world.setBlock(x+3, y+5, z+32, b, ms);
		world.setBlock(x+4, y+0, z+0, b, ms);
		world.setBlock(x+4, y+0, z+1, b, ms);
		world.setBlock(x+4, y+0, z+2, b, ms);
		world.setBlock(x+4, y+0, z+3, b, ms);
		world.setBlock(x+4, y+0, z+4, b, ms);
		world.setBlock(x+4, y+0, z+5, b, ms);
		world.setBlock(x+4, y+0, z+6, b, ms);
		world.setBlock(x+4, y+0, z+7, b, ms);
		world.setBlock(x+4, y+0, z+8, b, ms);
		world.setBlock(x+4, y+0, z+9, b, ms);
		world.setBlock(x+4, y+0, z+10, b, ms);
		this.generateRune(x+4, y+0, z+11, LockColor.GREEN);
		world.setBlock(x+4, y+0, z+12, b, ms);
		world.setBlock(x+4, y+0, z+13, b, ms);
		world.setBlock(x+4, y+0, z+14, b, ms);
		world.setBlock(x+4, y+0, z+15, b, ms);
		world.setBlock(x+4, y+0, z+16, b, ms);
		world.setBlock(x+4, y+0, z+17, b, ms);
		world.setBlock(x+4, y+0, z+18, b, ms);
		world.setBlock(x+4, y+0, z+19, b, ms);
		world.setBlock(x+4, y+0, z+20, b, ms);
		world.setBlock(x+4, y+0, z+21, b, ms);
		world.setBlock(x+4, y+0, z+22, b, ms);
		world.setBlock(x+4, y+0, z+23, b, ms);
		world.setBlock(x+4, y+0, z+24, b, ms);
		world.setBlock(x+4, y+0, z+25, b, ms);
		world.setBlock(x+4, y+0, z+26, b, ms);
		world.setBlock(x+4, y+0, z+27, b, ms);
		world.setBlock(x+4, y+0, z+28, b, ms);
		world.setBlock(x+4, y+0, z+29, b, ms);
		world.setBlock(x+4, y+0, z+30, b, ms);
		world.setBlock(x+4, y+0, z+31, b, ms);
		world.setBlock(x+4, y+0, z+32, b, ms);
		world.setBlock(x+4, y+0, z+33, b, ms);
		world.setBlock(x+4, y+0, z+34, b, ms);
		world.setBlock(x+4, y+1, z+6, b, ms);
		world.setBlock(x+4, y+1, z+7, b, ms);
		world.setBlock(x+4, y+1, z+8, b, ms);
		world.setBlock(x+4, y+1, z+15, b, ms);
		world.setBlock(x+4, y+1, z+16, b, ms);
		world.setBlock(x+4, y+1, z+17, b, ms);
		this.generateLock(x+4, y+1, z+24, LockColor.YELLOW);
		this.generateGate(x+4, y+1, z+33);
		world.setBlock(x+4, y+2, z+6, b, ms);
		world.setBlock(x+4, y+2, z+7, b, ms);
		world.setBlock(x+4, y+2, z+8, b, ms);
		world.setBlock(x+4, y+2, z+15, b, ms);
		world.setBlock(x+4, y+2, z+16, b, ms);
		world.setBlock(x+4, y+2, z+17, b, ms);
		this.generateLock(x+4, y+2, z+24, LockColor.YELLOW);
		this.generateGate(x+4, y+2, z+33);
		world.setBlock(x+4, y+3, z+6, b, ms);
		world.setBlock(x+4, y+3, z+7, b, ms);
		world.setBlock(x+4, y+3, z+8, b, ms);
		world.setBlock(x+4, y+3, z+15, b, ms);
		world.setBlock(x+4, y+3, z+16, b, ms);
		world.setBlock(x+4, y+3, z+17, b, ms);
		this.generateLock(x+4, y+3, z+24, LockColor.YELLOW);
		this.generateGate(x+4, y+3, z+33);
		world.setBlock(x+4, y+4, z+0, b, ms);
		world.setBlock(x+4, y+4, z+1, b, ms);
		world.setBlock(x+4, y+4, z+6, b, ms);
		world.setBlock(x+4, y+4, z+7, b, ms);
		world.setBlock(x+4, y+4, z+8, b, ms);
		world.setBlock(x+4, y+4, z+15, b, ms);
		world.setBlock(x+4, y+4, z+16, b, ms);
		world.setBlock(x+4, y+4, z+17, b, ms);
		world.setBlock(x+4, y+4, z+23, b, ms);
		world.setBlock(x+4, y+4, z+24, b, ms);
		world.setBlock(x+4, y+4, z+25, b, ms);
		world.setBlock(x+4, y+4, z+32, b, ms);
		world.setBlock(x+4, y+4, z+33, b, ms);
		world.setBlock(x+4, y+4, z+34, b, ms);
		world.setBlock(x+4, y+5, z+1, b, ms);
		world.setBlock(x+4, y+5, z+2, b, ms);
		world.setBlock(x+4, y+5, z+3, b, ms);
		world.setBlock(x+4, y+5, z+4, b, ms);
		world.setBlock(x+4, y+5, z+5, b, ms);
		world.setBlock(x+4, y+5, z+6, b, ms);
		world.setBlock(x+4, y+5, z+7, b, ms);
		world.setBlock(x+4, y+5, z+8, b, ms);
		world.setBlock(x+4, y+5, z+9, b, ms);
		world.setBlock(x+4, y+5, z+10, b, ms);
		world.setBlock(x+4, y+5, z+11, b, ms);
		world.setBlock(x+4, y+5, z+12, b, ms);
		world.setBlock(x+4, y+5, z+13, b, ms);
		world.setBlock(x+4, y+5, z+14, b, ms);
		world.setBlock(x+4, y+5, z+15, b, ms);
		world.setBlock(x+4, y+5, z+16, b, ms);
		world.setBlock(x+4, y+5, z+17, b, ms);
		world.setBlock(x+4, y+5, z+18, b, ms);
		world.setBlock(x+4, y+5, z+19, b, ms);
		world.setBlock(x+4, y+5, z+20, b, ms);
		world.setBlock(x+4, y+5, z+21, b, ms);
		world.setBlock(x+4, y+5, z+22, b, ms);
		world.setBlock(x+4, y+5, z+23, b, ms);
		world.setBlock(x+4, y+5, z+24, b, ms);
		world.setBlock(x+4, y+5, z+25, b, ms);
		world.setBlock(x+4, y+5, z+26, b, ms);
		world.setBlock(x+4, y+5, z+27, b, ms);
		world.setBlock(x+4, y+5, z+28, b, ms);
		world.setBlock(x+4, y+5, z+29, b, ms);
		world.setBlock(x+4, y+5, z+30, b, ms);
		world.setBlock(x+4, y+5, z+31, b, ms);
		world.setBlock(x+4, y+5, z+32, b, ms);
		world.setBlock(x+5, y+0, z+0, b, ms);
		world.setBlock(x+5, y+0, z+1, b, ms);
		world.setBlock(x+5, y+0, z+2, b, ms);
		world.setBlock(x+5, y+0, z+3, b, ms);
		world.setBlock(x+5, y+0, z+4, b, ms);
		world.setBlock(x+5, y+0, z+5, b, ms);
		world.setBlock(x+5, y+0, z+6, b, ms);
		world.setBlock(x+5, y+0, z+7, b, ms);
		world.setBlock(x+5, y+0, z+8, b, ms);
		world.setBlock(x+5, y+0, z+9, b, ms);
		world.setBlock(x+5, y+0, z+10, b, ms);
		world.setBlock(x+5, y+0, z+11, b, ms);
		world.setBlock(x+5, y+0, z+12, b, ms);
		world.setBlock(x+5, y+0, z+13, b, ms);
		world.setBlock(x+5, y+0, z+14, b, ms);
		world.setBlock(x+5, y+0, z+15, b, ms);
		world.setBlock(x+5, y+0, z+16, b, ms);
		world.setBlock(x+5, y+0, z+17, b, ms);
		world.setBlock(x+5, y+0, z+18, b, ms);
		world.setBlock(x+5, y+0, z+19, b, ms);
		world.setBlock(x+5, y+0, z+20, b, ms);
		world.setBlock(x+5, y+0, z+21, b, ms);
		world.setBlock(x+5, y+0, z+22, b, ms);
		world.setBlock(x+5, y+0, z+23, b, ms);
		world.setBlock(x+5, y+0, z+24, b, ms);
		world.setBlock(x+5, y+0, z+25, b, ms);
		world.setBlock(x+5, y+0, z+26, b, ms);
		world.setBlock(x+5, y+0, z+27, b, ms);
		world.setBlock(x+5, y+0, z+28, b, ms);
		world.setBlock(x+5, y+0, z+29, b, ms);
		world.setBlock(x+5, y+0, z+30, b, ms);
		world.setBlock(x+5, y+0, z+31, b, ms);
		world.setBlock(x+5, y+0, z+32, b, ms);
		world.setBlock(x+5, y+0, z+33, b, ms);
		world.setBlock(x+5, y+0, z+34, b, ms);
		this.generateLock(x+5, y+1, z+7, LockColor.RED);
		this.generateLock(x+5, y+1, z+16, LockColor.BLUE, LockColor.GREEN);
		world.setBlock(x+5, y+1, z+23, b, ms);
		world.setBlock(x+5, y+1, z+24, b, ms);
		world.setBlock(x+5, y+1, z+25, b, ms);
		world.setBlock(x+5, y+1, z+32, b, ms);
		world.setBlock(x+5, y+1, z+33, b, ms);
		world.setBlock(x+5, y+1, z+34, b, ms);
		this.generateLock(x+5, y+2, z+7, LockColor.RED);
		this.generateLock(x+5, y+2, z+16, LockColor.BLUE, LockColor.GREEN);
		world.setBlock(x+5, y+2, z+23, b, ms);
		world.setBlock(x+5, y+2, z+24, b, ms);
		world.setBlock(x+5, y+2, z+25, b, ms);
		world.setBlock(x+5, y+2, z+32, b, ms);
		world.setBlock(x+5, y+2, z+33, b, ms);
		world.setBlock(x+5, y+2, z+34, b, ms);
		this.generateLock(x+5, y+3, z+7, LockColor.RED);
		this.generateLock(x+5, y+3, z+16, LockColor.BLUE, LockColor.GREEN);
		world.setBlock(x+5, y+3, z+23, b, ms);
		world.setBlock(x+5, y+3, z+24, b, ms);
		world.setBlock(x+5, y+3, z+25, b, ms);
		world.setBlock(x+5, y+3, z+32, b, ms);
		world.setBlock(x+5, y+3, z+33, b, ms);
		world.setBlock(x+5, y+3, z+34, b, ms);
		world.setBlock(x+5, y+4, z+0, b, ms);
		world.setBlock(x+5, y+4, z+1, b, ms);
		world.setBlock(x+5, y+4, z+6, b, ms);
		world.setBlock(x+5, y+4, z+7, b, ms);
		world.setBlock(x+5, y+4, z+8, b, ms);
		world.setBlock(x+5, y+4, z+15, b, ms);
		world.setBlock(x+5, y+4, z+16, b, ms);
		world.setBlock(x+5, y+4, z+17, b, ms);
		world.setBlock(x+5, y+4, z+23, b, ms);
		world.setBlock(x+5, y+4, z+24, b, ms);
		world.setBlock(x+5, y+4, z+25, b, ms);
		world.setBlock(x+5, y+4, z+32, b, ms);
		world.setBlock(x+5, y+4, z+33, b, ms);
		world.setBlock(x+5, y+4, z+34, b, ms);
		world.setBlock(x+5, y+5, z+1, b, ms);
		world.setBlock(x+5, y+5, z+2, b, ms);
		world.setBlock(x+5, y+5, z+3, b, ms);
		world.setBlock(x+5, y+5, z+4, b, ms);
		world.setBlock(x+5, y+5, z+5, b, ms);
		world.setBlock(x+5, y+5, z+6, b, ms);
		world.setBlock(x+5, y+5, z+7, b, ms);
		world.setBlock(x+5, y+5, z+8, b, ms);
		world.setBlock(x+5, y+5, z+9, b, ms);
		world.setBlock(x+5, y+5, z+10, b, ms);
		world.setBlock(x+5, y+5, z+11, b, ms);
		world.setBlock(x+5, y+5, z+12, b, ms);
		world.setBlock(x+5, y+5, z+13, b, ms);
		world.setBlock(x+5, y+5, z+14, b, ms);
		world.setBlock(x+5, y+5, z+15, b, ms);
		world.setBlock(x+5, y+5, z+16, b, ms);
		world.setBlock(x+5, y+5, z+17, b, ms);
		world.setBlock(x+5, y+5, z+18, b, ms);
		world.setBlock(x+5, y+5, z+19, b, ms);
		world.setBlock(x+5, y+5, z+20, b, ms);
		world.setBlock(x+5, y+5, z+21, b, ms);
		world.setBlock(x+5, y+5, z+22, b, ms);
		world.setBlock(x+5, y+5, z+23, b, ms);
		world.setBlock(x+5, y+5, z+24, b, ms);
		world.setBlock(x+5, y+5, z+25, b, ms);
		world.setBlock(x+5, y+5, z+26, b, ms);
		world.setBlock(x+5, y+5, z+27, b, ms);
		world.setBlock(x+5, y+5, z+28, b, ms);
		world.setBlock(x+5, y+5, z+29, b, ms);
		world.setBlock(x+5, y+5, z+30, b, ms);
		world.setBlock(x+5, y+5, z+31, b, ms);
		world.setBlock(x+5, y+5, z+32, b, ms);
		world.setBlock(x+6, y+0, z+0, b, ms);
		world.setBlock(x+6, y+0, z+1, b, ms);
		world.setBlock(x+6, y+0, z+2, b, ms);
		world.setBlock(x+6, y+0, z+3, b, ms);
		world.setBlock(x+6, y+0, z+4, b, ms);
		world.setBlock(x+6, y+0, z+5, b, ms);
		world.setBlock(x+6, y+0, z+6, b, ms);
		world.setBlock(x+6, y+0, z+7, b, ms);
		world.setBlock(x+6, y+0, z+8, b, ms);
		world.setBlock(x+6, y+0, z+9, b, ms);
		world.setBlock(x+6, y+0, z+10, b, ms);
		world.setBlock(x+6, y+0, z+11, b, ms);
		world.setBlock(x+6, y+0, z+12, b, ms);
		this.generateRune(x+6, y+0, z+13, LockColor.BLUE);
		world.setBlock(x+6, y+0, z+14, b, ms);
		world.setBlock(x+6, y+0, z+15, b, ms);
		world.setBlock(x+6, y+0, z+16, b, ms);
		world.setBlock(x+6, y+0, z+17, b, ms);
		world.setBlock(x+6, y+0, z+18, b, ms);
		world.setBlock(x+6, y+0, z+19, b, ms);
		world.setBlock(x+6, y+0, z+20, b, ms);
		world.setBlock(x+6, y+0, z+21, b, ms);
		world.setBlock(x+6, y+0, z+22, b, ms);
		world.setBlock(x+6, y+0, z+23, b, ms);
		world.setBlock(x+6, y+0, z+24, b, ms);
		world.setBlock(x+6, y+0, z+25, b, ms);
		world.setBlock(x+6, y+0, z+26, b, ms);
		world.setBlock(x+6, y+0, z+27, b, ms);
		world.setBlock(x+6, y+0, z+28, b, ms);
		world.setBlock(x+6, y+0, z+29, b, ms);
		world.setBlock(x+6, y+0, z+30, b, ms);
		world.setBlock(x+6, y+0, z+31, b, ms);
		world.setBlock(x+6, y+0, z+32, b, ms);
		this.generateLock(x+6, y+1, z+7, LockColor.RED);
		this.generateKey(x+6, y+1, z+11);
		this.generateLock(x+6, y+1, z+16, LockColor.BLUE, LockColor.GREEN);
		this.generateKey(x+6, y+1, z+20);
		world.setBlock(x+6, y+1, z+23, b, ms);
		world.setBlock(x+6, y+1, z+24, b, ms);
		world.setBlock(x+6, y+1, z+25, b, ms);
		world.setBlock(x+6, y+1, z+26, b, ms);
		world.setBlock(x+6, y+1, z+30, b, ms);
		world.setBlock(x+6, y+1, z+31, b, ms);
		world.setBlock(x+6, y+1, z+32, b, ms);
		this.generateLock(x+6, y+2, z+7, LockColor.RED);
		this.generateLock(x+6, y+2, z+16, LockColor.BLUE, LockColor.GREEN);
		world.setBlock(x+6, y+2, z+23, b, ms);
		world.setBlock(x+6, y+2, z+24, b, ms);
		world.setBlock(x+6, y+2, z+25, b, ms);
		world.setBlock(x+6, y+2, z+26, b, ms);
		world.setBlock(x+6, y+2, z+30, b, ms);
		world.setBlock(x+6, y+2, z+31, b, ms);
		world.setBlock(x+6, y+2, z+32, b, ms);
		this.generateLock(x+6, y+3, z+7, LockColor.RED);
		this.generateLock(x+6, y+3, z+16, LockColor.BLUE, LockColor.GREEN);
		world.setBlock(x+6, y+3, z+23, b, ms);
		world.setBlock(x+6, y+3, z+24, b, ms);
		world.setBlock(x+6, y+3, z+25, b, ms);
		world.setBlock(x+6, y+3, z+26, b, ms);
		world.setBlock(x+6, y+3, z+30, b, ms);
		world.setBlock(x+6, y+3, z+31, b, ms);
		world.setBlock(x+6, y+3, z+32, b, ms);
		world.setBlock(x+6, y+4, z+0, b, ms);
		world.setBlock(x+6, y+4, z+1, b, ms);
		world.setBlock(x+6, y+4, z+6, b, ml);
		world.setBlock(x+6, y+4, z+7, b, ms);
		world.setBlock(x+6, y+4, z+8, b, ml);
		world.setBlock(x+6, y+4, z+15, b, ml);
		world.setBlock(x+6, y+4, z+16, b, ms);
		world.setBlock(x+6, y+4, z+17, b, ms);
		world.setBlock(x+6, y+4, z+23, b, ms);
		world.setBlock(x+6, y+4, z+26, b, ms);
		world.setBlock(x+6, y+4, z+30, b, ms);
		world.setBlock(x+6, y+4, z+31, b, ms);
		world.setBlock(x+6, y+4, z+32, b, ms);
		world.setBlock(x+6, y+5, z+1, b, ms);
		world.setBlock(x+6, y+5, z+2, b, ms);
		world.setBlock(x+6, y+5, z+3, b, ms);
		world.setBlock(x+6, y+5, z+4, b, ms);
		world.setBlock(x+6, y+5, z+5, b, ms);
		world.setBlock(x+6, y+5, z+6, b, ms);
		world.setBlock(x+6, y+5, z+7, b, ms);
		world.setBlock(x+6, y+5, z+8, b, ms);
		world.setBlock(x+6, y+5, z+9, b, ms);
		world.setBlock(x+6, y+5, z+10, b, ms);
		world.setBlock(x+6, y+5, z+11, b, ms);
		world.setBlock(x+6, y+5, z+12, b, ms);
		world.setBlock(x+6, y+5, z+13, b, ms);
		world.setBlock(x+6, y+5, z+14, b, ms);
		world.setBlock(x+6, y+5, z+15, b, ms);
		world.setBlock(x+6, y+5, z+16, b, ms);
		world.setBlock(x+6, y+5, z+17, b, ms);
		world.setBlock(x+6, y+5, z+18, b, ms);
		world.setBlock(x+6, y+5, z+19, b, ms);
		world.setBlock(x+6, y+5, z+20, b, ms);
		world.setBlock(x+6, y+5, z+21, b, ms);
		world.setBlock(x+6, y+5, z+22, b, ms);
		world.setBlock(x+6, y+5, z+23, b, ms);
		world.setBlock(x+6, y+5, z+26, b, ms);
		world.setBlock(x+6, y+5, z+27, b, ms);
		world.setBlock(x+6, y+5, z+28, b, ms);
		world.setBlock(x+6, y+5, z+29, b, ms);
		world.setBlock(x+6, y+5, z+30, b, ms);
		world.setBlock(x+6, y+5, z+31, b, ms);
		world.setBlock(x+6, y+5, z+32, b, ms);
		world.setBlock(x+7, y+0, z+0, b, ms);
		world.setBlock(x+7, y+0, z+1, b, ms);
		world.setBlock(x+7, y+0, z+2, b, ms);
		world.setBlock(x+7, y+0, z+3, b, ms);
		world.setBlock(x+7, y+0, z+4, b, ms);
		world.setBlock(x+7, y+0, z+5, b, ms);
		world.setBlock(x+7, y+0, z+6, b, ms);
		world.setBlock(x+7, y+0, z+7, b, ms);
		world.setBlock(x+7, y+0, z+8, b, ms);
		world.setBlock(x+7, y+0, z+9, b, ms);
		world.setBlock(x+7, y+0, z+10, b, ms);
		world.setBlock(x+7, y+0, z+11, b, ms);
		world.setBlock(x+7, y+0, z+12, b, ms);
		world.setBlock(x+7, y+0, z+13, b, ms);
		world.setBlock(x+7, y+0, z+14, b, ms);
		world.setBlock(x+7, y+0, z+15, b, ms);
		world.setBlock(x+7, y+0, z+16, b, ms);
		world.setBlock(x+7, y+0, z+17, b, ms);
		world.setBlock(x+7, y+0, z+18, b, ms);
		world.setBlock(x+7, y+0, z+19, b, ms);
		world.setBlock(x+7, y+0, z+20, b, ms);
		world.setBlock(x+7, y+0, z+21, b, ms);
		world.setBlock(x+7, y+0, z+22, b, ms);
		world.setBlock(x+7, y+0, z+23, b, ms);
		world.setBlock(x+7, y+0, z+24, b, ms);
		world.setBlock(x+7, y+0, z+25, b, ms);
		world.setBlock(x+7, y+0, z+26, b, ms);
		world.setBlock(x+7, y+0, z+27, b, ms);
		world.setBlock(x+7, y+0, z+28, b, ml);
		world.setBlock(x+7, y+0, z+29, b, ms);
		world.setBlock(x+7, y+0, z+30, b, ms);
		world.setBlock(x+7, y+0, z+31, b, ms);
		world.setBlock(x+7, y+0, z+32, b, ms);
		world.setBlock(x+7, y+1, z+0, b, ms);
		world.setBlock(x+7, y+1, z+1, b, ms);
		this.generateLock(x+7, y+1, z+7, LockColor.RED);
		this.generateLock(x+7, y+1, z+16, LockColor.BLUE, LockColor.GREEN);
		world.setBlock(x+7, y+1, z+22, b, ms);
		world.setBlock(x+7, y+1, z+23, b, ms);
		world.setBlock(x+7, y+1, z+24, b, ms);
		world.setBlock(x+7, y+1, z+25, b, ms);
		world.setBlock(x+7, y+1, z+26, b, ms);
		world.setBlock(x+7, y+1, z+30, b, ms);
		world.setBlock(x+7, y+1, z+31, b, ms);
		world.setBlock(x+7, y+1, z+32, b, ms);
		world.setBlock(x+7, y+2, z+0, b, ms);
		world.setBlock(x+7, y+2, z+1, b, ms);
		this.generateLock(x+7, y+2, z+7, LockColor.RED);
		this.generateLock(x+7, y+2, z+16, LockColor.BLUE, LockColor.GREEN);
		world.setBlock(x+7, y+2, z+22, b, ml);
		world.setBlock(x+7, y+2, z+23, b, ms);
		world.setBlock(x+7, y+2, z+24, b, ms);
		world.setBlock(x+7, y+2, z+25, b, mc);
		world.setBlock(x+7, y+2, z+31, b, mc);
		world.setBlock(x+7, y+2, z+32, b, ms);
		world.setBlock(x+7, y+3, z+0, b, ms);
		world.setBlock(x+7, y+3, z+1, b, ms);
		this.generateLock(x+7, y+3, z+7, LockColor.RED);
		this.generateLock(x+7, y+3, z+16, LockColor.BLUE, LockColor.GREEN);
		world.setBlock(x+7, y+3, z+22, b, ms);
		world.setBlock(x+7, y+3, z+23, b, ms);
		world.setBlock(x+7, y+3, z+24, b, ms);
		world.setBlock(x+7, y+3, z+25, b, ms);
		world.setBlock(x+7, y+3, z+26, b, ms);
		world.setBlock(x+7, y+3, z+30, b, ms);
		world.setBlock(x+7, y+3, z+31, b, ms);
		world.setBlock(x+7, y+3, z+32, b, ms);
		world.setBlock(x+7, y+4, z+0, b, ms);
		world.setBlock(x+7, y+4, z+1, b, ms);
		world.setBlock(x+7, y+4, z+6, b, ms);
		world.setBlock(x+7, y+4, z+7, b, ms);
		world.setBlock(x+7, y+4, z+8, b, ms);
		world.setBlock(x+7, y+4, z+15, b, ms);
		world.setBlock(x+7, y+4, z+16, b, ms);
		world.setBlock(x+7, y+4, z+17, b, ms);
		world.setBlock(x+7, y+4, z+22, b, ms);
		world.setBlock(x+7, y+4, z+23, b, ms);
		world.setBlock(x+7, y+4, z+26, b, ms);
		world.setBlock(x+7, y+4, z+30, b, ms);
		world.setBlock(x+7, y+5, z+1, b, ms);
		world.setBlock(x+7, y+5, z+2, b, ms);
		world.setBlock(x+7, y+5, z+3, b, ms);
		world.setBlock(x+7, y+5, z+4, b, ms);
		world.setBlock(x+7, y+5, z+5, b, ms);
		world.setBlock(x+7, y+5, z+6, b, ms);
		world.setBlock(x+7, y+5, z+7, b, ms);
		world.setBlock(x+7, y+5, z+8, b, ms);
		world.setBlock(x+7, y+5, z+9, b, ms);
		world.setBlock(x+7, y+5, z+10, b, ms);
		world.setBlock(x+7, y+5, z+11, b, ms);
		world.setBlock(x+7, y+5, z+12, b, ms);
		world.setBlock(x+7, y+5, z+13, b, ms);
		world.setBlock(x+7, y+5, z+14, b, ms);
		world.setBlock(x+7, y+5, z+15, b, ms);
		world.setBlock(x+7, y+5, z+16, b, ms);
		world.setBlock(x+7, y+5, z+17, b, ms);
		world.setBlock(x+7, y+5, z+18, b, ms);
		world.setBlock(x+7, y+5, z+19, b, ms);
		world.setBlock(x+7, y+5, z+20, b, ms);
		world.setBlock(x+7, y+5, z+21, b, ms);
		world.setBlock(x+7, y+5, z+22, b, ms);
		world.setBlock(x+7, y+5, z+23, b, ms);
		world.setBlock(x+7, y+5, z+26, b, ms);
		world.setBlock(x+7, y+5, z+27, b, ms);
		world.setBlock(x+7, y+5, z+28, b, ms);
		world.setBlock(x+7, y+5, z+29, b, ms);
		world.setBlock(x+7, y+5, z+30, b, ms);
		world.setBlock(x+8, y+0, z+1, b, ms);
		world.setBlock(x+8, y+0, z+2, b, ms);
		world.setBlock(x+8, y+0, z+3, b, ms);
		world.setBlock(x+8, y+0, z+4, b, ms);
		world.setBlock(x+8, y+0, z+5, b, ms);
		world.setBlock(x+8, y+0, z+6, b, ms);
		world.setBlock(x+8, y+0, z+7, b, ms);
		world.setBlock(x+8, y+0, z+8, b, ms);
		world.setBlock(x+8, y+0, z+9, b, ms);
		world.setBlock(x+8, y+0, z+10, b, ms);
		this.generateRune(x+8, y+0, z+11, LockColor.RED);
		world.setBlock(x+8, y+0, z+12, b, ms);
		world.setBlock(x+8, y+0, z+13, b, ms);
		world.setBlock(x+8, y+0, z+14, b, ms);
		world.setBlock(x+8, y+0, z+15, b, ms);
		world.setBlock(x+8, y+0, z+16, b, ms);
		world.setBlock(x+8, y+0, z+17, b, ms);
		world.setBlock(x+8, y+0, z+18, b, ms);
		world.setBlock(x+8, y+0, z+19, b, ms);
		world.setBlock(x+8, y+0, z+20, b, ms);
		world.setBlock(x+8, y+0, z+21, b, ms);
		world.setBlock(x+8, y+0, z+22, b, ms);
		world.setBlock(x+8, y+0, z+23, b, ms);
		world.setBlock(x+8, y+0, z+24, b, ms);
		world.setBlock(x+8, y+0, z+25, b, ms);
		world.setBlock(x+8, y+0, z+26, b, ms);
		world.setBlock(x+8, y+0, z+27, b, ms);
		world.setBlock(x+8, y+0, z+28, b, ms);
		world.setBlock(x+8, y+0, z+29, b, ms);
		world.setBlock(x+8, y+0, z+30, b, ms);
		world.setBlock(x+8, y+0, z+31, b, ms);
		world.setBlock(x+8, y+0, z+32, b, ms);
		world.setBlock(x+8, y+1, z+1, b, ms);
		this.generateKey(x+8, y+1, z+4);
		world.setBlock(x+8, y+1, z+6, b, ms);
		world.setBlock(x+8, y+1, z+7, b, ms);
		world.setBlock(x+8, y+1, z+8, b, ms);
		world.setBlock(x+8, y+1, z+15, b, ms);
		world.setBlock(x+8, y+1, z+16, b, ms);
		world.setBlock(x+8, y+1, z+17, b, ms);
		world.setBlock(x+8, y+1, z+21, b, ms);
		world.setBlock(x+8, y+1, z+22, b, ms);
		world.setBlock(x+8, y+1, z+23, b, ms);
		world.setBlock(x+8, y+1, z+24, b, ms);
		world.setBlock(x+8, y+1, z+25, b, ms);
		world.setBlock(x+8, y+1, z+26, b, ms);
		world.setBlock(x+8, y+1, z+30, b, ms);
		world.setBlock(x+8, y+1, z+31, b, ms);
		world.setBlock(x+8, y+1, z+32, b, ms);
		world.setBlock(x+8, y+2, z+1, b, ml);
		world.setBlock(x+8, y+2, z+6, b, ms);
		world.setBlock(x+8, y+2, z+7, b, ms);
		world.setBlock(x+8, y+2, z+8, b, ms);
		world.setBlock(x+8, y+2, z+15, b, ms);
		world.setBlock(x+8, y+2, z+16, b, ms);
		world.setBlock(x+8, y+2, z+17, b, ms);
		world.setBlock(x+8, y+2, z+21, b, ms);
		world.setBlock(x+8, y+2, z+22, b, ms);
		world.setBlock(x+8, y+2, z+23, b, ms);
		world.setBlock(x+8, y+2, z+24, b, ms);
		world.setBlock(x+8, y+2, z+25, b, ms);
		world.setBlock(x+8, y+2, z+26, b, ms);
		world.setBlock(x+8, y+2, z+30, b, ms);
		world.setBlock(x+8, y+2, z+31, b, ms);
		world.setBlock(x+8, y+2, z+32, b, ms);
		world.setBlock(x+8, y+3, z+1, b, ms);
		world.setBlock(x+8, y+3, z+6, b, ms);
		world.setBlock(x+8, y+3, z+7, b, ms);
		world.setBlock(x+8, y+3, z+8, b, ms);
		world.setBlock(x+8, y+3, z+15, b, ms);
		world.setBlock(x+8, y+3, z+16, b, ms);
		world.setBlock(x+8, y+3, z+17, b, ms);
		world.setBlock(x+8, y+3, z+21, b, ms);
		world.setBlock(x+8, y+3, z+22, b, ms);
		world.setBlock(x+8, y+3, z+23, b, ms);
		world.setBlock(x+8, y+3, z+24, b, ms);
		world.setBlock(x+8, y+3, z+25, b, ms);
		world.setBlock(x+8, y+3, z+26, b, ms);
		world.setBlock(x+8, y+3, z+30, b, ms);
		world.setBlock(x+8, y+3, z+31, b, ms);
		world.setBlock(x+8, y+3, z+32, b, ms);
		world.setBlock(x+8, y+4, z+1, b, ms);
		world.setBlock(x+8, y+4, z+6, b, ms);
		world.setBlock(x+8, y+4, z+7, b, ms);
		world.setBlock(x+8, y+4, z+8, b, ms);
		world.setBlock(x+8, y+4, z+15, b, ms);
		world.setBlock(x+8, y+4, z+16, b, ms);
		world.setBlock(x+8, y+4, z+17, b, ms);
		world.setBlock(x+8, y+4, z+21, b, ms);
		world.setBlock(x+8, y+4, z+22, b, ms);
		world.setBlock(x+8, y+4, z+23, b, ms);
		world.setBlock(x+8, y+4, z+26, b, ms);
		world.setBlock(x+8, y+4, z+30, b, ms);
		world.setBlock(x+8, y+5, z+1, b, ms);
		world.setBlock(x+8, y+5, z+2, b, ms);
		world.setBlock(x+8, y+5, z+3, b, ms);
		world.setBlock(x+8, y+5, z+4, b, ms);
		world.setBlock(x+8, y+5, z+5, b, ms);
		world.setBlock(x+8, y+5, z+6, b, ms);
		world.setBlock(x+8, y+5, z+7, b, ms);
		world.setBlock(x+8, y+5, z+8, b, ms);
		world.setBlock(x+8, y+5, z+9, b, ms);
		world.setBlock(x+8, y+5, z+10, b, ms);
		world.setBlock(x+8, y+5, z+11, b, ms);
		world.setBlock(x+8, y+5, z+12, b, ms);
		world.setBlock(x+8, y+5, z+13, b, ms);
		world.setBlock(x+8, y+5, z+14, b, ms);
		world.setBlock(x+8, y+5, z+15, b, ms);
		world.setBlock(x+8, y+5, z+16, b, ms);
		world.setBlock(x+8, y+5, z+17, b, ms);
		world.setBlock(x+8, y+5, z+18, b, ms);
		world.setBlock(x+8, y+5, z+19, b, ms);
		world.setBlock(x+8, y+5, z+20, b, ms);
		world.setBlock(x+8, y+5, z+21, b, ms);
		world.setBlock(x+8, y+5, z+22, b, ms);
		world.setBlock(x+8, y+5, z+23, b, ms);
		world.setBlock(x+8, y+5, z+26, b, ms);
		world.setBlock(x+8, y+5, z+27, b, ms);
		world.setBlock(x+8, y+5, z+28, b, ms);
		world.setBlock(x+8, y+5, z+29, b, ms);
		world.setBlock(x+8, y+5, z+30, b, ms);
		world.setBlock(x+9, y+0, z+1, b, ms);
		world.setBlock(x+9, y+0, z+2, b, ms);
		world.setBlock(x+9, y+0, z+3, b, ms);
		world.setBlock(x+9, y+0, z+4, b, ms);
		world.setBlock(x+9, y+0, z+5, b, ms);
		world.setBlock(x+9, y+0, z+6, b, ms);
		world.setBlock(x+9, y+0, z+7, b, ms);
		world.setBlock(x+9, y+0, z+8, b, ms);
		world.setBlock(x+9, y+0, z+9, b, ms);
		world.setBlock(x+9, y+0, z+10, b, ms);
		world.setBlock(x+9, y+0, z+11, b, ms);
		world.setBlock(x+9, y+0, z+12, b, ms);
		world.setBlock(x+9, y+0, z+13, b, ms);
		world.setBlock(x+9, y+0, z+14, b, ms);
		world.setBlock(x+9, y+0, z+15, b, ms);
		world.setBlock(x+9, y+0, z+18, b, ms);
		world.setBlock(x+9, y+0, z+19, b, ms);
		world.setBlock(x+9, y+0, z+20, b, ms);
		world.setBlock(x+9, y+0, z+21, b, ms);
		world.setBlock(x+9, y+0, z+26, b, ms);
		world.setBlock(x+9, y+0, z+27, b, ms);
		world.setBlock(x+9, y+0, z+28, b, ms);
		world.setBlock(x+9, y+0, z+29, b, ms);
		world.setBlock(x+9, y+0, z+30, b, ms);
		world.setBlock(x+9, y+1, z+1, b, ms);
		world.setBlock(x+9, y+1, z+6, b, ms);
		world.setBlock(x+9, y+1, z+7, b, ms);
		world.setBlock(x+9, y+1, z+8, b, ms);
		world.setBlock(x+9, y+1, z+9, b, ms);
		world.setBlock(x+9, y+1, z+15, b, ms);
		world.setBlock(x+9, y+1, z+18, b, ms);
		world.setBlock(x+9, y+1, z+19, b, ms);
		world.setBlock(x+9, y+1, z+20, b, ms);
		world.setBlock(x+9, y+1, z+21, b, ms);
		world.setBlock(x+9, y+1, z+26, b, ms);
		world.setBlock(x+9, y+1, z+27, b, ms);
		world.setBlock(x+9, y+1, z+28, b, ms);
		world.setBlock(x+9, y+1, z+29, b, ms);
		world.setBlock(x+9, y+1, z+30, b, ms);
		world.setBlock(x+9, y+2, z+1, b, ms);
		world.setBlock(x+9, y+2, z+6, b, ms);
		world.setBlock(x+9, y+2, z+7, b, ms);
		world.setBlock(x+9, y+2, z+8, b, ms);
		world.setBlock(x+9, y+2, z+9, b, ms);
		world.setBlock(x+9, y+2, z+15, b, ms);
		world.setBlock(x+9, y+2, z+18, b, ms);
		world.setBlock(x+9, y+2, z+19, b, ml);
		world.setBlock(x+9, y+2, z+20, b, ms);
		world.setBlock(x+9, y+2, z+21, b, ms);
		world.setBlock(x+9, y+2, z+26, b, ms);
		world.setBlock(x+9, y+2, z+27, b, ms);
		world.setBlock(x+9, y+2, z+29, b, ms);
		world.setBlock(x+9, y+2, z+30, b, ms);
		world.setBlock(x+9, y+3, z+1, b, ms);
		world.setBlock(x+9, y+3, z+6, b, ms);
		world.setBlock(x+9, y+3, z+7, b, ms);
		world.setBlock(x+9, y+3, z+8, b, ms);
		world.setBlock(x+9, y+3, z+9, b, ms);
		world.setBlock(x+9, y+3, z+15, b, ms);
		world.setBlock(x+9, y+3, z+18, b, ms);
		world.setBlock(x+9, y+3, z+19, b, ms);
		world.setBlock(x+9, y+3, z+20, b, ms);
		world.setBlock(x+9, y+3, z+21, b, ms);
		world.setBlock(x+9, y+3, z+26, b, ms);
		world.setBlock(x+9, y+3, z+27, b, ms);
		world.setBlock(x+9, y+3, z+28, b, ms);
		world.setBlock(x+9, y+3, z+29, b, ms);
		world.setBlock(x+9, y+3, z+30, b, ms);
		world.setBlock(x+9, y+4, z+1, b, ms);
		world.setBlock(x+9, y+4, z+6, b, ms);
		world.setBlock(x+9, y+4, z+7, b, ms);
		world.setBlock(x+9, y+4, z+8, b, ms);
		world.setBlock(x+9, y+4, z+9, b, ms);
		world.setBlock(x+9, y+4, z+15, b, ms);
		world.setBlock(x+9, y+4, z+18, b, ms);
		world.setBlock(x+9, y+4, z+19, b, ms);
		world.setBlock(x+9, y+4, z+20, b, ms);
		world.setBlock(x+9, y+4, z+21, b, ms);
		world.setBlock(x+9, y+4, z+26, b, ms);
		world.setBlock(x+9, y+4, z+27, b, ms);
		world.setBlock(x+9, y+4, z+28, b, ms);
		world.setBlock(x+9, y+4, z+29, b, ms);
		world.setBlock(x+9, y+4, z+30, b, ms);
		world.setBlock(x+9, y+5, z+1, b, ms);
		world.setBlock(x+9, y+5, z+2, b, ms);
		world.setBlock(x+9, y+5, z+3, b, ms);
		world.setBlock(x+9, y+5, z+4, b, ms);
		world.setBlock(x+9, y+5, z+5, b, ms);
		world.setBlock(x+9, y+5, z+6, b, ms);
		world.setBlock(x+9, y+5, z+7, b, ms);
		world.setBlock(x+9, y+5, z+8, b, ms);
		world.setBlock(x+9, y+5, z+9, b, ms);
		world.setBlock(x+9, y+5, z+10, b, ms);
		world.setBlock(x+9, y+5, z+11, b, ms);
		world.setBlock(x+9, y+5, z+12, b, ms);
		world.setBlock(x+9, y+5, z+13, b, ms);
		world.setBlock(x+9, y+5, z+14, b, ms);
		world.setBlock(x+9, y+5, z+15, b, ms);
		world.setBlock(x+9, y+5, z+18, b, ms);
		world.setBlock(x+9, y+5, z+19, b, ms);
		world.setBlock(x+9, y+5, z+20, b, ms);
		world.setBlock(x+9, y+5, z+21, b, ms);
		world.setBlock(x+9, y+5, z+26, b, ms);
		world.setBlock(x+9, y+5, z+27, b, ms);
		world.setBlock(x+9, y+5, z+28, b, ms);
		world.setBlock(x+9, y+5, z+29, b, ms);
		world.setBlock(x+9, y+5, z+30, b, ms);
		world.setBlock(x+10, y+0, z+1, b, ms);
		world.setBlock(x+10, y+0, z+2, b, ms);
		world.setBlock(x+10, y+0, z+3, b, ms);
		world.setBlock(x+10, y+0, z+4, b, ms);
		world.setBlock(x+10, y+0, z+5, b, ms);
		world.setBlock(x+10, y+0, z+6, b, ms);
		world.setBlock(x+10, y+0, z+7, b, ms);
		world.setBlock(x+10, y+0, z+8, b, ms);
		world.setBlock(x+10, y+0, z+9, b, ms);
		world.setBlock(x+10, y+0, z+10, b, ms);
		world.setBlock(x+10, y+0, z+11, b, ms);
		world.setBlock(x+10, y+0, z+12, b, ms);
		world.setBlock(x+10, y+0, z+13, b, ms);
		world.setBlock(x+10, y+0, z+14, b, ms);
		world.setBlock(x+10, y+0, z+15, b, ms);
		world.setBlock(x+10, y+0, z+27, b, ms);
		world.setBlock(x+10, y+0, z+28, b, ms);
		world.setBlock(x+10, y+0, z+29, b, ms);
		world.setBlock(x+10, y+1, z+1, b, ms);
		world.setBlock(x+10, y+1, z+2, b, ms);
		world.setBlock(x+10, y+1, z+3, b, ms);
		world.setBlock(x+10, y+1, z+4, b, ms);
		world.setBlock(x+10, y+1, z+5, b, ms);
		world.setBlock(x+10, y+1, z+6, b, ms);
		world.setBlock(x+10, y+1, z+7, b, ms);
		world.setBlock(x+10, y+1, z+8, b, ms);
		world.setBlock(x+10, y+1, z+9, b, ms);
		world.setBlock(x+10, y+1, z+10, b, ms);
		world.setBlock(x+10, y+1, z+11, b, ms);
		world.setBlock(x+10, y+1, z+12, b, ms);
		world.setBlock(x+10, y+1, z+13, b, ms);
		world.setBlock(x+10, y+1, z+14, b, ms);
		world.setBlock(x+10, y+1, z+15, b, ms);
		world.setBlock(x+10, y+1, z+27, b, ms);
		world.setBlock(x+10, y+1, z+28, b, ms);
		world.setBlock(x+10, y+1, z+29, b, ms);
		world.setBlock(x+10, y+2, z+1, b, ms);
		world.setBlock(x+10, y+2, z+2, b, ms);
		world.setBlock(x+10, y+2, z+3, b, ms);
		world.setBlock(x+10, y+2, z+4, b, ms);
		world.setBlock(x+10, y+2, z+5, b, ms);
		world.setBlock(x+10, y+2, z+6, b, ms);
		world.setBlock(x+10, y+2, z+7, b, ms);
		world.setBlock(x+10, y+2, z+8, b, ms);
		world.setBlock(x+10, y+2, z+9, b, ms);
		world.setBlock(x+10, y+2, z+10, b, ms);
		world.setBlock(x+10, y+2, z+11, b, ms);
		world.setBlock(x+10, y+2, z+12, b, ml);
		world.setBlock(x+10, y+2, z+13, b, ms);
		world.setBlock(x+10, y+2, z+14, b, ms);
		world.setBlock(x+10, y+2, z+15, b, ms);
		world.setBlock(x+10, y+2, z+27, b, ms);
		world.setBlock(x+10, y+2, z+28, b, mc);
		world.setBlock(x+10, y+2, z+29, b, ms);
		world.setBlock(x+10, y+3, z+1, b, ms);
		world.setBlock(x+10, y+3, z+2, b, ms);
		world.setBlock(x+10, y+3, z+3, b, ms);
		world.setBlock(x+10, y+3, z+4, b, ms);
		world.setBlock(x+10, y+3, z+5, b, ms);
		world.setBlock(x+10, y+3, z+6, b, ms);
		world.setBlock(x+10, y+3, z+7, b, ms);
		world.setBlock(x+10, y+3, z+8, b, ms);
		world.setBlock(x+10, y+3, z+9, b, ms);
		world.setBlock(x+10, y+3, z+10, b, ms);
		world.setBlock(x+10, y+3, z+11, b, ms);
		world.setBlock(x+10, y+3, z+12, b, ms);
		world.setBlock(x+10, y+3, z+13, b, ms);
		world.setBlock(x+10, y+3, z+14, b, ms);
		world.setBlock(x+10, y+3, z+15, b, ms);
		world.setBlock(x+10, y+3, z+27, b, ms);
		world.setBlock(x+10, y+3, z+28, b, ms);
		world.setBlock(x+10, y+3, z+29, b, ms);
		world.setBlock(x+10, y+4, z+1, b, ms);
		world.setBlock(x+10, y+4, z+2, b, ms);
		world.setBlock(x+10, y+4, z+3, b, ms);
		world.setBlock(x+10, y+4, z+4, b, ms);
		world.setBlock(x+10, y+4, z+5, b, ms);
		world.setBlock(x+10, y+4, z+6, b, ms);
		world.setBlock(x+10, y+4, z+7, b, ms);
		world.setBlock(x+10, y+4, z+8, b, ms);
		world.setBlock(x+10, y+4, z+9, b, ms);
		world.setBlock(x+10, y+4, z+10, b, ms);
		world.setBlock(x+10, y+4, z+11, b, ms);
		world.setBlock(x+10, y+4, z+12, b, ms);
		world.setBlock(x+10, y+4, z+13, b, ms);
		world.setBlock(x+10, y+4, z+14, b, ms);
		world.setBlock(x+10, y+4, z+15, b, ms);
		world.setBlock(x+10, y+5, z+1, b, ms);
		world.setBlock(x+10, y+5, z+2, b, ms);
		world.setBlock(x+10, y+5, z+3, b, ms);
		world.setBlock(x+10, y+5, z+4, b, ms);
		world.setBlock(x+10, y+5, z+5, b, ms);
		world.setBlock(x+10, y+5, z+6, b, ms);
		world.setBlock(x+10, y+5, z+7, b, ms);
		world.setBlock(x+10, y+5, z+8, b, ms);
		world.setBlock(x+10, y+5, z+9, b, ms);
		world.setBlock(x+10, y+5, z+10, b, ms);
		world.setBlock(x+10, y+5, z+11, b, ms);
		world.setBlock(x+10, y+5, z+12, b, ms);
		world.setBlock(x+10, y+5, z+13, b, ms);
		world.setBlock(x+10, y+5, z+14, b, ms);
		world.setBlock(x+10, y+5, z+15, b, ms);
		world.setBlock(x+1, y+1, z+19, STRUCTURE_AIR);
		world.setBlock(x+1, y+1, z+20, STRUCTURE_AIR);
		world.setBlock(x+1, y+1, z+21, STRUCTURE_AIR);
		world.setBlock(x+1, y+1, z+22, STRUCTURE_AIR);
		world.setBlock(x+1, y+2, z+19, STRUCTURE_AIR);
		world.setBlock(x+1, y+2, z+20, STRUCTURE_AIR);
		world.setBlock(x+1, y+2, z+21, STRUCTURE_AIR);
		world.setBlock(x+1, y+2, z+22, STRUCTURE_AIR);
		world.setBlock(x+1, y+3, z+19, STRUCTURE_AIR);
		world.setBlock(x+1, y+3, z+20, STRUCTURE_AIR);
		world.setBlock(x+1, y+3, z+21, STRUCTURE_AIR);
		world.setBlock(x+1, y+3, z+22, STRUCTURE_AIR);
		world.setBlock(x+1, y+4, z+19, STRUCTURE_AIR);
		world.setBlock(x+1, y+4, z+20, STRUCTURE_AIR);
		world.setBlock(x+1, y+4, z+21, STRUCTURE_AIR);
		world.setBlock(x+1, y+4, z+22, STRUCTURE_AIR);
		world.setBlock(x+2, y+1, z+19, STRUCTURE_AIR);
		world.setBlock(x+2, y+1, z+20, STRUCTURE_AIR);
		world.setBlock(x+2, y+1, z+21, STRUCTURE_AIR);
		world.setBlock(x+2, y+1, z+22, STRUCTURE_AIR);
		world.setBlock(x+2, y+1, z+23, STRUCTURE_AIR);
		world.setBlock(x+2, y+1, z+25, STRUCTURE_AIR);
		world.setBlock(x+2, y+1, z+26, STRUCTURE_AIR);
		world.setBlock(x+2, y+1, z+27, STRUCTURE_AIR);
		world.setBlock(x+2, y+1, z+28, STRUCTURE_AIR);
		world.setBlock(x+2, y+1, z+29, STRUCTURE_AIR);
		world.setBlock(x+2, y+1, z+30, STRUCTURE_AIR);
		world.setBlock(x+2, y+1, z+31, STRUCTURE_AIR);
		world.setBlock(x+2, y+1, z+32, STRUCTURE_AIR);
		world.setBlock(x+2, y+1, z+34, STRUCTURE_AIR);
		world.setBlock(x+2, y+2, z+4, STRUCTURE_AIR);
		world.setBlock(x+2, y+2, z+18, STRUCTURE_AIR);
		world.setBlock(x+2, y+2, z+19, STRUCTURE_AIR);
		world.setBlock(x+2, y+2, z+20, STRUCTURE_AIR);
		world.setBlock(x+2, y+2, z+21, STRUCTURE_AIR);
		world.setBlock(x+2, y+2, z+22, STRUCTURE_AIR);
		world.setBlock(x+2, y+2, z+23, STRUCTURE_AIR);
		world.setBlock(x+2, y+2, z+25, STRUCTURE_AIR);
		world.setBlock(x+2, y+2, z+26, STRUCTURE_AIR);
		world.setBlock(x+2, y+2, z+27, STRUCTURE_AIR);
		world.setBlock(x+2, y+2, z+28, STRUCTURE_AIR);
		world.setBlock(x+2, y+2, z+29, STRUCTURE_AIR);
		world.setBlock(x+2, y+2, z+30, STRUCTURE_AIR);
		world.setBlock(x+2, y+2, z+31, STRUCTURE_AIR);
		world.setBlock(x+2, y+2, z+32, STRUCTURE_AIR);
		world.setBlock(x+2, y+2, z+34, STRUCTURE_AIR);
		world.setBlock(x+2, y+3, z+19, STRUCTURE_AIR);
		world.setBlock(x+2, y+3, z+20, STRUCTURE_AIR);
		world.setBlock(x+2, y+3, z+21, STRUCTURE_AIR);
		world.setBlock(x+2, y+3, z+22, STRUCTURE_AIR);
		world.setBlock(x+2, y+3, z+23, STRUCTURE_AIR);
		world.setBlock(x+2, y+3, z+25, STRUCTURE_AIR);
		world.setBlock(x+2, y+3, z+26, STRUCTURE_AIR);
		world.setBlock(x+2, y+3, z+27, STRUCTURE_AIR);
		world.setBlock(x+2, y+3, z+28, STRUCTURE_AIR);
		world.setBlock(x+2, y+3, z+29, STRUCTURE_AIR);
		world.setBlock(x+2, y+3, z+30, STRUCTURE_AIR);
		world.setBlock(x+2, y+3, z+31, STRUCTURE_AIR);
		world.setBlock(x+2, y+3, z+32, STRUCTURE_AIR);
		world.setBlock(x+2, y+3, z+34, STRUCTURE_AIR);
		world.setBlock(x+2, y+4, z+19, STRUCTURE_AIR);
		world.setBlock(x+2, y+4, z+20, STRUCTURE_AIR);
		world.setBlock(x+2, y+4, z+21, STRUCTURE_AIR);
		world.setBlock(x+2, y+4, z+22, STRUCTURE_AIR);
		world.setBlock(x+2, y+4, z+26, STRUCTURE_AIR);
		world.setBlock(x+2, y+4, z+27, STRUCTURE_AIR);
		world.setBlock(x+2, y+4, z+28, STRUCTURE_AIR);
		world.setBlock(x+2, y+4, z+29, STRUCTURE_AIR);
		world.setBlock(x+2, y+4, z+30, STRUCTURE_AIR);
		world.setBlock(x+2, y+4, z+31, STRUCTURE_AIR);
		world.setBlock(x+3, y+1, z+2, STRUCTURE_AIR);
		world.setBlock(x+3, y+1, z+3, STRUCTURE_AIR);
		world.setBlock(x+3, y+1, z+4, STRUCTURE_AIR);
		world.setBlock(x+3, y+1, z+5, STRUCTURE_AIR);
		world.setBlock(x+3, y+1, z+10, STRUCTURE_AIR);
		world.setBlock(x+3, y+1, z+11, STRUCTURE_AIR);
		world.setBlock(x+3, y+1, z+12, STRUCTURE_AIR);
		world.setBlock(x+3, y+1, z+13, STRUCTURE_AIR);
		world.setBlock(x+3, y+1, z+14, STRUCTURE_AIR);
		world.setBlock(x+3, y+1, z+19, STRUCTURE_AIR);
		world.setBlock(x+3, y+1, z+20, STRUCTURE_AIR);
		world.setBlock(x+3, y+1, z+21, STRUCTURE_AIR);
		world.setBlock(x+3, y+1, z+22, STRUCTURE_AIR);
		world.setBlock(x+3, y+1, z+23, STRUCTURE_AIR);
		world.setBlock(x+3, y+1, z+25, STRUCTURE_AIR);
		world.setBlock(x+3, y+1, z+26, STRUCTURE_AIR);
		world.setBlock(x+3, y+1, z+27, STRUCTURE_AIR);
		world.setBlock(x+3, y+1, z+28, STRUCTURE_AIR);
		world.setBlock(x+3, y+1, z+29, STRUCTURE_AIR);
		world.setBlock(x+3, y+1, z+30, STRUCTURE_AIR);
		world.setBlock(x+3, y+1, z+31, STRUCTURE_AIR);
		world.setBlock(x+3, y+1, z+32, STRUCTURE_AIR);
		world.setBlock(x+3, y+1, z+34, STRUCTURE_AIR);
		world.setBlock(x+3, y+2, z+2, STRUCTURE_AIR);
		world.setBlock(x+3, y+2, z+3, STRUCTURE_AIR);
		world.setBlock(x+3, y+2, z+4, STRUCTURE_AIR);
		world.setBlock(x+3, y+2, z+5, STRUCTURE_AIR);
		world.setBlock(x+3, y+2, z+10, STRUCTURE_AIR);
		world.setBlock(x+3, y+2, z+11, STRUCTURE_AIR);
		world.setBlock(x+3, y+2, z+12, STRUCTURE_AIR);
		world.setBlock(x+3, y+2, z+13, STRUCTURE_AIR);
		world.setBlock(x+3, y+2, z+14, STRUCTURE_AIR);
		world.setBlock(x+3, y+2, z+19, STRUCTURE_AIR);
		world.setBlock(x+3, y+2, z+20, STRUCTURE_AIR);
		world.setBlock(x+3, y+2, z+21, STRUCTURE_AIR);
		world.setBlock(x+3, y+2, z+22, STRUCTURE_AIR);
		world.setBlock(x+3, y+2, z+23, STRUCTURE_AIR);
		world.setBlock(x+3, y+2, z+25, STRUCTURE_AIR);
		world.setBlock(x+3, y+2, z+26, STRUCTURE_AIR);
		world.setBlock(x+3, y+2, z+27, STRUCTURE_AIR);
		world.setBlock(x+3, y+2, z+28, STRUCTURE_AIR);
		world.setBlock(x+3, y+2, z+29, STRUCTURE_AIR);
		world.setBlock(x+3, y+2, z+30, STRUCTURE_AIR);
		world.setBlock(x+3, y+2, z+31, STRUCTURE_AIR);
		world.setBlock(x+3, y+2, z+32, STRUCTURE_AIR);
		world.setBlock(x+3, y+2, z+34, STRUCTURE_AIR);
		world.setBlock(x+3, y+3, z+2, STRUCTURE_AIR);
		world.setBlock(x+3, y+3, z+3, STRUCTURE_AIR);
		world.setBlock(x+3, y+3, z+4, STRUCTURE_AIR);
		world.setBlock(x+3, y+3, z+5, STRUCTURE_AIR);
		world.setBlock(x+3, y+3, z+10, STRUCTURE_AIR);
		world.setBlock(x+3, y+3, z+11, STRUCTURE_AIR);
		world.setBlock(x+3, y+3, z+12, STRUCTURE_AIR);
		world.setBlock(x+3, y+3, z+13, STRUCTURE_AIR);
		world.setBlock(x+3, y+3, z+14, STRUCTURE_AIR);
		world.setBlock(x+3, y+3, z+19, STRUCTURE_AIR);
		world.setBlock(x+3, y+3, z+20, STRUCTURE_AIR);
		world.setBlock(x+3, y+3, z+21, STRUCTURE_AIR);
		world.setBlock(x+3, y+3, z+22, STRUCTURE_AIR);
		world.setBlock(x+3, y+3, z+23, STRUCTURE_AIR);
		world.setBlock(x+3, y+3, z+25, STRUCTURE_AIR);
		world.setBlock(x+3, y+3, z+26, STRUCTURE_AIR);
		world.setBlock(x+3, y+3, z+27, STRUCTURE_AIR);
		world.setBlock(x+3, y+3, z+28, STRUCTURE_AIR);
		world.setBlock(x+3, y+3, z+29, STRUCTURE_AIR);
		world.setBlock(x+3, y+3, z+30, STRUCTURE_AIR);
		world.setBlock(x+3, y+3, z+31, STRUCTURE_AIR);
		world.setBlock(x+3, y+3, z+32, STRUCTURE_AIR);
		world.setBlock(x+3, y+3, z+34, STRUCTURE_AIR);
		world.setBlock(x+3, y+4, z+2, STRUCTURE_AIR);
		world.setBlock(x+3, y+4, z+3, STRUCTURE_AIR);
		world.setBlock(x+3, y+4, z+4, STRUCTURE_AIR);
		world.setBlock(x+3, y+4, z+5, STRUCTURE_AIR);
		world.setBlock(x+3, y+4, z+10, STRUCTURE_AIR);
		world.setBlock(x+3, y+4, z+11, STRUCTURE_AIR);
		world.setBlock(x+3, y+4, z+12, STRUCTURE_AIR);
		world.setBlock(x+3, y+4, z+13, STRUCTURE_AIR);
		world.setBlock(x+3, y+4, z+14, STRUCTURE_AIR);
		world.setBlock(x+3, y+4, z+19, STRUCTURE_AIR);
		world.setBlock(x+3, y+4, z+20, STRUCTURE_AIR);
		world.setBlock(x+3, y+4, z+21, STRUCTURE_AIR);
		world.setBlock(x+3, y+4, z+22, STRUCTURE_AIR);
		world.setBlock(x+3, y+4, z+26, STRUCTURE_AIR);
		world.setBlock(x+3, y+4, z+27, STRUCTURE_AIR);
		world.setBlock(x+3, y+4, z+28, STRUCTURE_AIR);
		world.setBlock(x+3, y+4, z+29, STRUCTURE_AIR);
		world.setBlock(x+3, y+4, z+30, STRUCTURE_AIR);
		world.setBlock(x+3, y+4, z+31, STRUCTURE_AIR);
		world.setBlock(x+4, y+1, z+0, STRUCTURE_AIR);
		world.setBlock(x+4, y+1, z+1, STRUCTURE_AIR);
		world.setBlock(x+4, y+1, z+2, STRUCTURE_AIR);
		world.setBlock(x+4, y+1, z+3, STRUCTURE_AIR);
		world.setBlock(x+4, y+1, z+4, STRUCTURE_AIR);
		world.setBlock(x+4, y+1, z+5, STRUCTURE_AIR);
		world.setBlock(x+4, y+1, z+9, STRUCTURE_AIR);
		world.setBlock(x+4, y+1, z+10, STRUCTURE_AIR);
		world.setBlock(x+4, y+1, z+11, STRUCTURE_AIR);
		world.setBlock(x+4, y+1, z+12, STRUCTURE_AIR);
		world.setBlock(x+4, y+1, z+13, STRUCTURE_AIR);
		world.setBlock(x+4, y+1, z+14, STRUCTURE_AIR);
		world.setBlock(x+4, y+1, z+18, STRUCTURE_AIR);
		world.setBlock(x+4, y+1, z+19, STRUCTURE_AIR);
		world.setBlock(x+4, y+1, z+20, STRUCTURE_AIR);
		world.setBlock(x+4, y+1, z+21, STRUCTURE_AIR);
		world.setBlock(x+4, y+1, z+22, STRUCTURE_AIR);
		world.setBlock(x+4, y+1, z+23, STRUCTURE_AIR);
		world.setBlock(x+4, y+1, z+25, STRUCTURE_AIR);
		world.setBlock(x+4, y+1, z+26, STRUCTURE_AIR);
		world.setBlock(x+4, y+1, z+27, STRUCTURE_AIR);
		world.setBlock(x+4, y+1, z+28, STRUCTURE_AIR);
		world.setBlock(x+4, y+1, z+29, STRUCTURE_AIR);
		world.setBlock(x+4, y+1, z+30, STRUCTURE_AIR);
		world.setBlock(x+4, y+1, z+31, STRUCTURE_AIR);
		world.setBlock(x+4, y+1, z+32, STRUCTURE_AIR);
		world.setBlock(x+4, y+1, z+34, STRUCTURE_AIR);
		world.setBlock(x+4, y+2, z+0, STRUCTURE_AIR);
		world.setBlock(x+4, y+2, z+1, STRUCTURE_AIR);
		world.setBlock(x+4, y+2, z+2, STRUCTURE_AIR);
		world.setBlock(x+4, y+2, z+3, STRUCTURE_AIR);
		world.setBlock(x+4, y+2, z+4, STRUCTURE_AIR);
		world.setBlock(x+4, y+2, z+5, STRUCTURE_AIR);
		world.setBlock(x+4, y+2, z+9, STRUCTURE_AIR);
		world.setBlock(x+4, y+2, z+10, STRUCTURE_AIR);
		world.setBlock(x+4, y+2, z+11, STRUCTURE_AIR);
		world.setBlock(x+4, y+2, z+12, STRUCTURE_AIR);
		world.setBlock(x+4, y+2, z+13, STRUCTURE_AIR);
		world.setBlock(x+4, y+2, z+14, STRUCTURE_AIR);
		world.setBlock(x+4, y+2, z+18, STRUCTURE_AIR);
		world.setBlock(x+4, y+2, z+19, STRUCTURE_AIR);
		world.setBlock(x+4, y+2, z+20, STRUCTURE_AIR);
		world.setBlock(x+4, y+2, z+21, STRUCTURE_AIR);
		world.setBlock(x+4, y+2, z+22, STRUCTURE_AIR);
		world.setBlock(x+4, y+2, z+23, STRUCTURE_AIR);
		world.setBlock(x+4, y+2, z+25, STRUCTURE_AIR);
		world.setBlock(x+4, y+2, z+26, STRUCTURE_AIR);
		world.setBlock(x+4, y+2, z+27, STRUCTURE_AIR);
		world.setBlock(x+4, y+2, z+28, STRUCTURE_AIR);
		world.setBlock(x+4, y+2, z+29, STRUCTURE_AIR);
		world.setBlock(x+4, y+2, z+30, STRUCTURE_AIR);
		world.setBlock(x+4, y+2, z+31, STRUCTURE_AIR);
		world.setBlock(x+4, y+2, z+32, STRUCTURE_AIR);
		world.setBlock(x+4, y+2, z+34, STRUCTURE_AIR);
		world.setBlock(x+4, y+3, z+0, STRUCTURE_AIR);
		world.setBlock(x+4, y+3, z+1, STRUCTURE_AIR);
		world.setBlock(x+4, y+3, z+2, STRUCTURE_AIR);
		world.setBlock(x+4, y+3, z+3, STRUCTURE_AIR);
		world.setBlock(x+4, y+3, z+4, STRUCTURE_AIR);
		world.setBlock(x+4, y+3, z+5, STRUCTURE_AIR);
		world.setBlock(x+4, y+3, z+9, STRUCTURE_AIR);
		world.setBlock(x+4, y+3, z+10, STRUCTURE_AIR);
		world.setBlock(x+4, y+3, z+11, STRUCTURE_AIR);
		world.setBlock(x+4, y+3, z+12, STRUCTURE_AIR);
		world.setBlock(x+4, y+3, z+13, STRUCTURE_AIR);
		world.setBlock(x+4, y+3, z+14, STRUCTURE_AIR);
		world.setBlock(x+4, y+3, z+18, STRUCTURE_AIR);
		world.setBlock(x+4, y+3, z+19, STRUCTURE_AIR);
		world.setBlock(x+4, y+3, z+20, STRUCTURE_AIR);
		world.setBlock(x+4, y+3, z+21, STRUCTURE_AIR);
		world.setBlock(x+4, y+3, z+22, STRUCTURE_AIR);
		world.setBlock(x+4, y+3, z+23, STRUCTURE_AIR);
		world.setBlock(x+4, y+3, z+25, STRUCTURE_AIR);
		world.setBlock(x+4, y+3, z+26, STRUCTURE_AIR);
		world.setBlock(x+4, y+3, z+27, STRUCTURE_AIR);
		world.setBlock(x+4, y+3, z+28, STRUCTURE_AIR);
		world.setBlock(x+4, y+3, z+29, STRUCTURE_AIR);
		world.setBlock(x+4, y+3, z+30, STRUCTURE_AIR);
		world.setBlock(x+4, y+3, z+31, STRUCTURE_AIR);
		world.setBlock(x+4, y+3, z+32, STRUCTURE_AIR);
		world.setBlock(x+4, y+3, z+34, STRUCTURE_AIR);
		world.setBlock(x+4, y+4, z+2, STRUCTURE_AIR);
		world.setBlock(x+4, y+4, z+3, STRUCTURE_AIR);
		world.setBlock(x+4, y+4, z+4, STRUCTURE_AIR);
		world.setBlock(x+4, y+4, z+5, STRUCTURE_AIR);
		world.setBlock(x+4, y+4, z+9, STRUCTURE_AIR);
		world.setBlock(x+4, y+4, z+10, STRUCTURE_AIR);
		world.setBlock(x+4, y+4, z+11, STRUCTURE_AIR);
		world.setBlock(x+4, y+4, z+12, STRUCTURE_AIR);
		world.setBlock(x+4, y+4, z+13, STRUCTURE_AIR);
		world.setBlock(x+4, y+4, z+14, STRUCTURE_AIR);
		world.setBlock(x+4, y+4, z+18, STRUCTURE_AIR);
		world.setBlock(x+4, y+4, z+19, STRUCTURE_AIR);
		world.setBlock(x+4, y+4, z+20, STRUCTURE_AIR);
		world.setBlock(x+4, y+4, z+21, STRUCTURE_AIR);
		world.setBlock(x+4, y+4, z+22, STRUCTURE_AIR);
		world.setBlock(x+4, y+4, z+26, STRUCTURE_AIR);
		world.setBlock(x+4, y+4, z+27, STRUCTURE_AIR);
		world.setBlock(x+4, y+4, z+28, STRUCTURE_AIR);
		world.setBlock(x+4, y+4, z+29, STRUCTURE_AIR);
		world.setBlock(x+4, y+4, z+30, STRUCTURE_AIR);
		world.setBlock(x+4, y+4, z+31, STRUCTURE_AIR);
		world.setBlock(x+5, y+1, z+0, STRUCTURE_AIR);
		world.setBlock(x+5, y+1, z+1, STRUCTURE_AIR);
		world.setBlock(x+5, y+1, z+2, STRUCTURE_AIR);
		world.setBlock(x+5, y+1, z+3, STRUCTURE_AIR);
		world.setBlock(x+5, y+1, z+4, STRUCTURE_AIR);
		world.setBlock(x+5, y+1, z+5, STRUCTURE_AIR);
		world.setBlock(x+5, y+1, z+6, STRUCTURE_AIR);
		world.setBlock(x+5, y+1, z+8, STRUCTURE_AIR);
		world.setBlock(x+5, y+1, z+9, STRUCTURE_AIR);
		world.setBlock(x+5, y+1, z+10, STRUCTURE_AIR);
		world.setBlock(x+5, y+1, z+11, STRUCTURE_AIR);
		world.setBlock(x+5, y+1, z+12, STRUCTURE_AIR);
		world.setBlock(x+5, y+1, z+13, STRUCTURE_AIR);
		world.setBlock(x+5, y+1, z+14, STRUCTURE_AIR);
		world.setBlock(x+5, y+1, z+15, STRUCTURE_AIR);
		world.setBlock(x+5, y+1, z+17, STRUCTURE_AIR);
		world.setBlock(x+5, y+1, z+18, STRUCTURE_AIR);
		world.setBlock(x+5, y+1, z+19, STRUCTURE_AIR);
		world.setBlock(x+5, y+1, z+20, STRUCTURE_AIR);
		world.setBlock(x+5, y+1, z+21, STRUCTURE_AIR);
		world.setBlock(x+5, y+1, z+22, STRUCTURE_AIR);
		world.setBlock(x+5, y+1, z+26, STRUCTURE_AIR);
		world.setBlock(x+5, y+1, z+27, STRUCTURE_AIR);
		world.setBlock(x+5, y+1, z+28, STRUCTURE_AIR);
		world.setBlock(x+5, y+1, z+29, STRUCTURE_AIR);
		world.setBlock(x+5, y+1, z+30, STRUCTURE_AIR);
		world.setBlock(x+5, y+1, z+31, STRUCTURE_AIR);
		world.setBlock(x+5, y+2, z+0, STRUCTURE_AIR);
		world.setBlock(x+5, y+2, z+1, STRUCTURE_AIR);
		world.setBlock(x+5, y+2, z+2, STRUCTURE_AIR);
		world.setBlock(x+5, y+2, z+3, STRUCTURE_AIR);
		world.setBlock(x+5, y+2, z+4, STRUCTURE_AIR);
		world.setBlock(x+5, y+2, z+5, STRUCTURE_AIR);
		world.setBlock(x+5, y+2, z+6, STRUCTURE_AIR);
		world.setBlock(x+5, y+2, z+8, STRUCTURE_AIR);
		world.setBlock(x+5, y+2, z+9, STRUCTURE_AIR);
		world.setBlock(x+5, y+2, z+10, STRUCTURE_AIR);
		world.setBlock(x+5, y+2, z+11, STRUCTURE_AIR);
		world.setBlock(x+5, y+2, z+12, STRUCTURE_AIR);
		world.setBlock(x+5, y+2, z+13, STRUCTURE_AIR);
		world.setBlock(x+5, y+2, z+14, STRUCTURE_AIR);
		world.setBlock(x+5, y+2, z+15, STRUCTURE_AIR);
		world.setBlock(x+5, y+2, z+17, STRUCTURE_AIR);
		world.setBlock(x+5, y+2, z+18, STRUCTURE_AIR);
		world.setBlock(x+5, y+2, z+19, STRUCTURE_AIR);
		world.setBlock(x+5, y+2, z+20, STRUCTURE_AIR);
		world.setBlock(x+5, y+2, z+21, STRUCTURE_AIR);
		world.setBlock(x+5, y+2, z+22, STRUCTURE_AIR);
		world.setBlock(x+5, y+2, z+26, STRUCTURE_AIR);
		world.setBlock(x+5, y+2, z+27, STRUCTURE_AIR);
		world.setBlock(x+5, y+2, z+28, STRUCTURE_AIR);
		world.setBlock(x+5, y+2, z+29, STRUCTURE_AIR);
		world.setBlock(x+5, y+2, z+30, STRUCTURE_AIR);
		world.setBlock(x+5, y+2, z+31, STRUCTURE_AIR);
		world.setBlock(x+5, y+3, z+0, STRUCTURE_AIR);
		world.setBlock(x+5, y+3, z+1, STRUCTURE_AIR);
		world.setBlock(x+5, y+3, z+2, STRUCTURE_AIR);
		world.setBlock(x+5, y+3, z+3, STRUCTURE_AIR);
		world.setBlock(x+5, y+3, z+4, STRUCTURE_AIR);
		world.setBlock(x+5, y+3, z+5, STRUCTURE_AIR);
		world.setBlock(x+5, y+3, z+6, STRUCTURE_AIR);
		world.setBlock(x+5, y+3, z+8, STRUCTURE_AIR);
		world.setBlock(x+5, y+3, z+9, STRUCTURE_AIR);
		world.setBlock(x+5, y+3, z+10, STRUCTURE_AIR);
		world.setBlock(x+5, y+3, z+11, STRUCTURE_AIR);
		world.setBlock(x+5, y+3, z+12, STRUCTURE_AIR);
		world.setBlock(x+5, y+3, z+13, STRUCTURE_AIR);
		world.setBlock(x+5, y+3, z+14, STRUCTURE_AIR);
		world.setBlock(x+5, y+3, z+15, STRUCTURE_AIR);
	}

	private void generate2(OriginBlockCache world, int x, int y, int z, Block b, int ms, int ml, int mc) {
		world.setBlock(x+5, y+3, z+17, STRUCTURE_AIR);
		world.setBlock(x+5, y+3, z+18, STRUCTURE_AIR);
		world.setBlock(x+5, y+3, z+19, STRUCTURE_AIR);
		world.setBlock(x+5, y+3, z+20, STRUCTURE_AIR);
		world.setBlock(x+5, y+3, z+21, STRUCTURE_AIR);
		world.setBlock(x+5, y+3, z+22, STRUCTURE_AIR);
		world.setBlock(x+5, y+3, z+26, STRUCTURE_AIR);
		world.setBlock(x+5, y+3, z+27, STRUCTURE_AIR);
		world.setBlock(x+5, y+3, z+28, STRUCTURE_AIR);
		world.setBlock(x+5, y+3, z+29, STRUCTURE_AIR);
		world.setBlock(x+5, y+3, z+30, STRUCTURE_AIR);
		world.setBlock(x+5, y+3, z+31, STRUCTURE_AIR);
		world.setBlock(x+5, y+4, z+2, STRUCTURE_AIR);
		world.setBlock(x+5, y+4, z+3, STRUCTURE_AIR);
		world.setBlock(x+5, y+4, z+4, STRUCTURE_AIR);
		world.setBlock(x+5, y+4, z+5, STRUCTURE_AIR);
		world.setBlock(x+5, y+4, z+9, STRUCTURE_AIR);
		world.setBlock(x+5, y+4, z+10, STRUCTURE_AIR);
		world.setBlock(x+5, y+4, z+11, STRUCTURE_AIR);
		world.setBlock(x+5, y+4, z+12, STRUCTURE_AIR);
		world.setBlock(x+5, y+4, z+13, STRUCTURE_AIR);
		world.setBlock(x+5, y+4, z+14, STRUCTURE_AIR);
		world.setBlock(x+5, y+4, z+18, STRUCTURE_AIR);
		world.setBlock(x+5, y+4, z+19, STRUCTURE_AIR);
		world.setBlock(x+5, y+4, z+20, STRUCTURE_AIR);
		world.setBlock(x+5, y+4, z+21, STRUCTURE_AIR);
		world.setBlock(x+5, y+4, z+22, STRUCTURE_AIR);
		world.setBlock(x+5, y+4, z+26, STRUCTURE_AIR);
		world.setBlock(x+5, y+4, z+27, STRUCTURE_AIR);
		world.setBlock(x+5, y+4, z+28, STRUCTURE_AIR);
		world.setBlock(x+5, y+4, z+29, STRUCTURE_AIR);
		world.setBlock(x+5, y+4, z+30, STRUCTURE_AIR);
		world.setBlock(x+5, y+4, z+31, STRUCTURE_AIR);
		world.setBlock(x+6, y+1, z+0, STRUCTURE_AIR);
		world.setBlock(x+6, y+1, z+1, STRUCTURE_AIR);
		world.setBlock(x+6, y+1, z+2, STRUCTURE_AIR);
		world.setBlock(x+6, y+1, z+3, STRUCTURE_AIR);
		world.setBlock(x+6, y+1, z+4, STRUCTURE_AIR);
		world.setBlock(x+6, y+1, z+5, STRUCTURE_AIR);
		world.setBlock(x+6, y+1, z+6, STRUCTURE_AIR);
		world.setBlock(x+6, y+1, z+8, STRUCTURE_AIR);
		world.setBlock(x+6, y+1, z+9, STRUCTURE_AIR);
		world.setBlock(x+6, y+1, z+10, STRUCTURE_AIR);
		world.setBlock(x+6, y+1, z+12, STRUCTURE_AIR);
		world.setBlock(x+6, y+1, z+13, STRUCTURE_AIR);
		world.setBlock(x+6, y+1, z+14, STRUCTURE_AIR);
		world.setBlock(x+6, y+1, z+15, STRUCTURE_AIR);
		world.setBlock(x+6, y+1, z+17, STRUCTURE_AIR);
		world.setBlock(x+6, y+1, z+18, STRUCTURE_AIR);
		world.setBlock(x+6, y+1, z+19, STRUCTURE_AIR);
		world.setBlock(x+6, y+1, z+21, STRUCTURE_AIR);
		world.setBlock(x+6, y+1, z+22, STRUCTURE_AIR);
		world.setBlock(x+6, y+1, z+27, STRUCTURE_AIR);
		world.setBlock(x+6, y+1, z+28, STRUCTURE_AIR);
		world.setBlock(x+6, y+1, z+29, STRUCTURE_AIR);
		world.setBlock(x+6, y+2, z+0, STRUCTURE_AIR);
		world.setBlock(x+6, y+2, z+1, STRUCTURE_AIR);
		world.setBlock(x+6, y+2, z+2, STRUCTURE_AIR);
		world.setBlock(x+6, y+2, z+3, STRUCTURE_AIR);
		world.setBlock(x+6, y+2, z+4, STRUCTURE_AIR);
		world.setBlock(x+6, y+2, z+5, STRUCTURE_AIR);
		world.setBlock(x+6, y+2, z+6, STRUCTURE_AIR);
		world.setBlock(x+6, y+2, z+8, STRUCTURE_AIR);
		world.setBlock(x+6, y+2, z+9, STRUCTURE_AIR);
		world.setBlock(x+6, y+2, z+10, STRUCTURE_AIR);
		world.setBlock(x+6, y+2, z+11, STRUCTURE_AIR);
		world.setBlock(x+6, y+2, z+12, STRUCTURE_AIR);
		world.setBlock(x+6, y+2, z+13, STRUCTURE_AIR);
		world.setBlock(x+6, y+2, z+14, STRUCTURE_AIR);
		world.setBlock(x+6, y+2, z+15, STRUCTURE_AIR);
		world.setBlock(x+6, y+2, z+17, STRUCTURE_AIR);
		world.setBlock(x+6, y+2, z+18, STRUCTURE_AIR);
		world.setBlock(x+6, y+2, z+19, STRUCTURE_AIR);
		world.setBlock(x+6, y+2, z+20, STRUCTURE_AIR);
		world.setBlock(x+6, y+2, z+21, STRUCTURE_AIR);
		world.setBlock(x+6, y+2, z+22, STRUCTURE_AIR);
		world.setBlock(x+6, y+2, z+27, STRUCTURE_AIR);
		world.setBlock(x+6, y+2, z+28, STRUCTURE_AIR);
		world.setBlock(x+6, y+2, z+29, STRUCTURE_AIR);
		world.setBlock(x+6, y+3, z+0, STRUCTURE_AIR);
		world.setBlock(x+6, y+3, z+1, STRUCTURE_AIR);
		world.setBlock(x+6, y+3, z+2, STRUCTURE_AIR);
		world.setBlock(x+6, y+3, z+3, STRUCTURE_AIR);
		world.setBlock(x+6, y+3, z+4, STRUCTURE_AIR);
		world.setBlock(x+6, y+3, z+5, STRUCTURE_AIR);
		world.setBlock(x+6, y+3, z+6, STRUCTURE_AIR);
		world.setBlock(x+6, y+3, z+8, STRUCTURE_AIR);
		world.setBlock(x+6, y+3, z+9, STRUCTURE_AIR);
		world.setBlock(x+6, y+3, z+10, STRUCTURE_AIR);
		world.setBlock(x+6, y+3, z+11, STRUCTURE_AIR);
		world.setBlock(x+6, y+3, z+12, STRUCTURE_AIR);
		world.setBlock(x+6, y+3, z+13, STRUCTURE_AIR);
		world.setBlock(x+6, y+3, z+14, STRUCTURE_AIR);
		world.setBlock(x+6, y+3, z+15, STRUCTURE_AIR);
		world.setBlock(x+6, y+3, z+17, STRUCTURE_AIR);
		world.setBlock(x+6, y+3, z+18, STRUCTURE_AIR);
		world.setBlock(x+6, y+3, z+19, STRUCTURE_AIR);
		world.setBlock(x+6, y+3, z+20, STRUCTURE_AIR);
		world.setBlock(x+6, y+3, z+21, STRUCTURE_AIR);
		world.setBlock(x+6, y+3, z+22, STRUCTURE_AIR);
		world.setBlock(x+6, y+3, z+27, STRUCTURE_AIR);
		world.setBlock(x+6, y+3, z+28, STRUCTURE_AIR);
		world.setBlock(x+6, y+3, z+29, STRUCTURE_AIR);
		world.setBlock(x+6, y+4, z+2, STRUCTURE_AIR);
		world.setBlock(x+6, y+4, z+3, STRUCTURE_AIR);
		world.setBlock(x+6, y+4, z+4, STRUCTURE_AIR);
		world.setBlock(x+6, y+4, z+5, STRUCTURE_AIR);
		world.setBlock(x+6, y+4, z+9, STRUCTURE_AIR);
		world.setBlock(x+6, y+4, z+10, STRUCTURE_AIR);
		world.setBlock(x+6, y+4, z+11, STRUCTURE_AIR);
		world.setBlock(x+6, y+4, z+12, STRUCTURE_AIR);
		world.setBlock(x+6, y+4, z+13, STRUCTURE_AIR);
		world.setBlock(x+6, y+4, z+14, STRUCTURE_AIR);
		world.setBlock(x+6, y+4, z+18, STRUCTURE_AIR);
		world.setBlock(x+6, y+4, z+19, STRUCTURE_AIR);
		world.setBlock(x+6, y+4, z+20, STRUCTURE_AIR);
		world.setBlock(x+6, y+4, z+21, STRUCTURE_AIR);
		world.setBlock(x+6, y+4, z+22, STRUCTURE_AIR);
		world.setBlock(x+6, y+4, z+27, STRUCTURE_AIR);
		world.setBlock(x+6, y+4, z+28, STRUCTURE_AIR);
		world.setBlock(x+6, y+4, z+29, STRUCTURE_AIR);
		world.setBlock(x+7, y+1, z+2, STRUCTURE_AIR);
		world.setBlock(x+7, y+1, z+3, STRUCTURE_AIR);
		world.setBlock(x+7, y+1, z+4, STRUCTURE_AIR);
		world.setBlock(x+7, y+1, z+5, STRUCTURE_AIR);
		world.setBlock(x+7, y+1, z+6, STRUCTURE_AIR);
		world.setBlock(x+7, y+1, z+8, STRUCTURE_AIR);
		world.setBlock(x+7, y+1, z+9, STRUCTURE_AIR);
		world.setBlock(x+7, y+1, z+10, STRUCTURE_AIR);
		world.setBlock(x+7, y+1, z+11, STRUCTURE_AIR);
		world.setBlock(x+7, y+1, z+12, STRUCTURE_AIR);
		world.setBlock(x+7, y+1, z+13, STRUCTURE_AIR);
		world.setBlock(x+7, y+1, z+14, STRUCTURE_AIR);
		world.setBlock(x+7, y+1, z+15, STRUCTURE_AIR);
		world.setBlock(x+7, y+1, z+17, STRUCTURE_AIR);
		world.setBlock(x+7, y+1, z+18, STRUCTURE_AIR);
		world.setBlock(x+7, y+1, z+19, STRUCTURE_AIR);
		world.setBlock(x+7, y+1, z+20, STRUCTURE_AIR);
		world.setBlock(x+7, y+1, z+21, STRUCTURE_AIR);
		world.setBlock(x+7, y+1, z+27, STRUCTURE_AIR);
		world.setBlock(x+7, y+1, z+28, STRUCTURE_AIR);
		world.setBlock(x+7, y+1, z+29, STRUCTURE_AIR);
		world.setBlock(x+7, y+2, z+2, STRUCTURE_AIR);
		world.setBlock(x+7, y+2, z+3, STRUCTURE_AIR);
		world.setBlock(x+7, y+2, z+4, STRUCTURE_AIR);
		world.setBlock(x+7, y+2, z+5, STRUCTURE_AIR);
		world.setBlock(x+7, y+2, z+6, STRUCTURE_AIR);
		world.setBlock(x+7, y+2, z+8, STRUCTURE_AIR);
		world.setBlock(x+7, y+2, z+9, STRUCTURE_AIR);
		world.setBlock(x+7, y+2, z+10, STRUCTURE_AIR);
		world.setBlock(x+7, y+2, z+11, STRUCTURE_AIR);
		world.setBlock(x+7, y+2, z+12, STRUCTURE_AIR);
		world.setBlock(x+7, y+2, z+13, STRUCTURE_AIR);
		world.setBlock(x+7, y+2, z+14, STRUCTURE_AIR);
		world.setBlock(x+7, y+2, z+15, STRUCTURE_AIR);
		world.setBlock(x+7, y+2, z+17, STRUCTURE_AIR);
		world.setBlock(x+7, y+2, z+18, STRUCTURE_AIR);
		world.setBlock(x+7, y+2, z+19, STRUCTURE_AIR);
		world.setBlock(x+7, y+2, z+20, STRUCTURE_AIR);
		world.setBlock(x+7, y+2, z+21, STRUCTURE_AIR);
		world.setBlock(x+7, y+2, z+26, STRUCTURE_AIR);
		world.setBlock(x+7, y+2, z+27, STRUCTURE_AIR);
		world.setBlock(x+7, y+2, z+28, STRUCTURE_AIR);
		world.setBlock(x+7, y+2, z+29, STRUCTURE_AIR);
		world.setBlock(x+7, y+2, z+30, STRUCTURE_AIR);
		world.setBlock(x+7, y+3, z+2, STRUCTURE_AIR);
		world.setBlock(x+7, y+3, z+3, STRUCTURE_AIR);
		world.setBlock(x+7, y+3, z+4, STRUCTURE_AIR);
		world.setBlock(x+7, y+3, z+5, STRUCTURE_AIR);
		world.setBlock(x+7, y+3, z+6, STRUCTURE_AIR);
		world.setBlock(x+7, y+3, z+8, STRUCTURE_AIR);
		world.setBlock(x+7, y+3, z+9, STRUCTURE_AIR);
		world.setBlock(x+7, y+3, z+10, STRUCTURE_AIR);
		world.setBlock(x+7, y+3, z+11, STRUCTURE_AIR);
		world.setBlock(x+7, y+3, z+12, STRUCTURE_AIR);
		world.setBlock(x+7, y+3, z+13, STRUCTURE_AIR);
		world.setBlock(x+7, y+3, z+14, STRUCTURE_AIR);
		world.setBlock(x+7, y+3, z+15, STRUCTURE_AIR);
		world.setBlock(x+7, y+3, z+17, STRUCTURE_AIR);
		world.setBlock(x+7, y+3, z+18, STRUCTURE_AIR);
		world.setBlock(x+7, y+3, z+19, STRUCTURE_AIR);
		world.setBlock(x+7, y+3, z+20, STRUCTURE_AIR);
		world.setBlock(x+7, y+3, z+21, STRUCTURE_AIR);
		world.setBlock(x+7, y+3, z+27, STRUCTURE_AIR);
		world.setBlock(x+7, y+3, z+28, STRUCTURE_AIR);
		world.setBlock(x+7, y+3, z+29, STRUCTURE_AIR);
		world.setBlock(x+7, y+4, z+2, STRUCTURE_AIR);
		world.setBlock(x+7, y+4, z+3, STRUCTURE_AIR);
		world.setBlock(x+7, y+4, z+4, STRUCTURE_AIR);
		world.setBlock(x+7, y+4, z+5, STRUCTURE_AIR);
		world.setBlock(x+7, y+4, z+9, STRUCTURE_AIR);
		world.setBlock(x+7, y+4, z+10, STRUCTURE_AIR);
		world.setBlock(x+7, y+4, z+11, STRUCTURE_AIR);
		world.setBlock(x+7, y+4, z+12, STRUCTURE_AIR);
		world.setBlock(x+7, y+4, z+13, STRUCTURE_AIR);
		world.setBlock(x+7, y+4, z+14, STRUCTURE_AIR);
		world.setBlock(x+7, y+4, z+18, STRUCTURE_AIR);
		world.setBlock(x+7, y+4, z+19, STRUCTURE_AIR);
		world.setBlock(x+7, y+4, z+20, STRUCTURE_AIR);
		world.setBlock(x+7, y+4, z+21, STRUCTURE_AIR);
		world.setBlock(x+7, y+4, z+27, STRUCTURE_AIR);
		world.setBlock(x+7, y+4, z+28, STRUCTURE_AIR);
		world.setBlock(x+7, y+4, z+29, STRUCTURE_AIR);
		world.setBlock(x+8, y+1, z+2, STRUCTURE_AIR);
		world.setBlock(x+8, y+1, z+3, STRUCTURE_AIR);
		world.setBlock(x+8, y+1, z+5, STRUCTURE_AIR);
		world.setBlock(x+8, y+1, z+9, STRUCTURE_AIR);
		world.setBlock(x+8, y+1, z+10, STRUCTURE_AIR);
		world.setBlock(x+8, y+1, z+11, STRUCTURE_AIR);
		world.setBlock(x+8, y+1, z+12, STRUCTURE_AIR);
		world.setBlock(x+8, y+1, z+13, STRUCTURE_AIR);
		world.setBlock(x+8, y+1, z+14, STRUCTURE_AIR);
		world.setBlock(x+8, y+1, z+18, STRUCTURE_AIR);
		world.setBlock(x+8, y+1, z+19, STRUCTURE_AIR);
		world.setBlock(x+8, y+1, z+20, STRUCTURE_AIR);
		world.setBlock(x+8, y+1, z+27, STRUCTURE_AIR);
		world.setBlock(x+8, y+1, z+28, STRUCTURE_AIR);
		world.setBlock(x+8, y+1, z+29, STRUCTURE_AIR);
		world.setBlock(x+8, y+2, z+2, STRUCTURE_AIR);
		world.setBlock(x+8, y+2, z+3, STRUCTURE_AIR);
		world.setBlock(x+8, y+2, z+4, STRUCTURE_AIR);
		world.setBlock(x+8, y+2, z+5, STRUCTURE_AIR);
		world.setBlock(x+8, y+2, z+9, STRUCTURE_AIR);
		world.setBlock(x+8, y+2, z+10, STRUCTURE_AIR);
		world.setBlock(x+8, y+2, z+11, STRUCTURE_AIR);
		world.setBlock(x+8, y+2, z+12, STRUCTURE_AIR);
		world.setBlock(x+8, y+2, z+13, STRUCTURE_AIR);
		world.setBlock(x+8, y+2, z+14, STRUCTURE_AIR);
		world.setBlock(x+8, y+2, z+18, STRUCTURE_AIR);
		world.setBlock(x+8, y+2, z+19, STRUCTURE_AIR);
		world.setBlock(x+8, y+2, z+20, STRUCTURE_AIR);
		world.setBlock(x+8, y+2, z+27, STRUCTURE_AIR);
		world.setBlock(x+8, y+2, z+28, STRUCTURE_AIR);
		world.setBlock(x+8, y+2, z+29, STRUCTURE_AIR);
		world.setBlock(x+8, y+3, z+2, STRUCTURE_AIR);
		world.setBlock(x+8, y+3, z+3, STRUCTURE_AIR);
		world.setBlock(x+8, y+3, z+4, STRUCTURE_AIR);
		world.setBlock(x+8, y+3, z+5, STRUCTURE_AIR);
		world.setBlock(x+8, y+3, z+9, STRUCTURE_AIR);
		world.setBlock(x+8, y+3, z+10, STRUCTURE_AIR);
		world.setBlock(x+8, y+3, z+11, STRUCTURE_AIR);
		world.setBlock(x+8, y+3, z+12, STRUCTURE_AIR);
		world.setBlock(x+8, y+3, z+13, STRUCTURE_AIR);
		world.setBlock(x+8, y+3, z+14, STRUCTURE_AIR);
		world.setBlock(x+8, y+3, z+18, STRUCTURE_AIR);
		world.setBlock(x+8, y+3, z+19, STRUCTURE_AIR);
		world.setBlock(x+8, y+3, z+20, STRUCTURE_AIR);
		world.setBlock(x+8, y+3, z+27, STRUCTURE_AIR);
		world.setBlock(x+8, y+3, z+28, STRUCTURE_AIR);
		world.setBlock(x+8, y+3, z+29, STRUCTURE_AIR);
		world.setBlock(x+8, y+4, z+2, STRUCTURE_AIR);
		world.setBlock(x+8, y+4, z+3, STRUCTURE_AIR);
		world.setBlock(x+8, y+4, z+4, STRUCTURE_AIR);
		world.setBlock(x+8, y+4, z+5, STRUCTURE_AIR);
		world.setBlock(x+8, y+4, z+9, STRUCTURE_AIR);
		world.setBlock(x+8, y+4, z+10, STRUCTURE_AIR);
		world.setBlock(x+8, y+4, z+11, STRUCTURE_AIR);
		world.setBlock(x+8, y+4, z+12, STRUCTURE_AIR);
		world.setBlock(x+8, y+4, z+13, STRUCTURE_AIR);
		world.setBlock(x+8, y+4, z+14, STRUCTURE_AIR);
		world.setBlock(x+8, y+4, z+18, STRUCTURE_AIR);
		world.setBlock(x+8, y+4, z+19, STRUCTURE_AIR);
		world.setBlock(x+8, y+4, z+20, STRUCTURE_AIR);
		world.setBlock(x+8, y+4, z+27, STRUCTURE_AIR);
		world.setBlock(x+8, y+4, z+28, STRUCTURE_AIR);
		world.setBlock(x+8, y+4, z+29, STRUCTURE_AIR);
		world.setBlock(x+9, y+1, z+2, STRUCTURE_AIR);
		world.setBlock(x+9, y+1, z+3, STRUCTURE_AIR);
		world.setBlock(x+9, y+1, z+4, STRUCTURE_AIR);
		world.setBlock(x+9, y+1, z+5, STRUCTURE_AIR);
		world.setBlock(x+9, y+1, z+10, STRUCTURE_AIR);
		world.setBlock(x+9, y+1, z+11, STRUCTURE_AIR);
		world.setBlock(x+9, y+1, z+12, STRUCTURE_AIR);
		world.setBlock(x+9, y+1, z+13, STRUCTURE_AIR);
		world.setBlock(x+9, y+1, z+14, STRUCTURE_AIR);
		world.setBlock(x+9, y+2, z+2, STRUCTURE_AIR);
		world.setBlock(x+9, y+2, z+3, STRUCTURE_AIR);
		world.setBlock(x+9, y+2, z+4, STRUCTURE_AIR);
		world.setBlock(x+9, y+2, z+5, STRUCTURE_AIR);
		world.setBlock(x+9, y+2, z+10, STRUCTURE_AIR);
		world.setBlock(x+9, y+2, z+11, STRUCTURE_AIR);
		world.setBlock(x+9, y+2, z+12, STRUCTURE_AIR);
		world.setBlock(x+9, y+2, z+13, STRUCTURE_AIR);
		world.setBlock(x+9, y+2, z+14, STRUCTURE_AIR);
		world.setBlock(x+9, y+2, z+28, STRUCTURE_AIR);
		world.setBlock(x+9, y+3, z+2, STRUCTURE_AIR);
		world.setBlock(x+9, y+3, z+3, STRUCTURE_AIR);
		world.setBlock(x+9, y+3, z+4, STRUCTURE_AIR);
		world.setBlock(x+9, y+3, z+5, STRUCTURE_AIR);
		world.setBlock(x+9, y+3, z+10, STRUCTURE_AIR);
		world.setBlock(x+9, y+3, z+11, STRUCTURE_AIR);
		world.setBlock(x+9, y+3, z+12, STRUCTURE_AIR);
		world.setBlock(x+9, y+3, z+13, STRUCTURE_AIR);
		world.setBlock(x+9, y+3, z+14, STRUCTURE_AIR);
		world.setBlock(x+9, y+4, z+2, STRUCTURE_AIR);
		world.setBlock(x+9, y+4, z+3, STRUCTURE_AIR);
		world.setBlock(x+9, y+4, z+4, STRUCTURE_AIR);
		world.setBlock(x+9, y+4, z+5, STRUCTURE_AIR);
		world.setBlock(x+9, y+4, z+10, STRUCTURE_AIR);
		world.setBlock(x+9, y+4, z+11, STRUCTURE_AIR);
		world.setBlock(x+9, y+4, z+12, STRUCTURE_AIR);
		world.setBlock(x+9, y+4, z+13, STRUCTURE_AIR);
		world.setBlock(x+9, y+4, z+14, STRUCTURE_AIR);
	}

	@Override
	public int getWidth() {
		return 11;
	}

	@Override
	public int getLength() {
		return 33;
	}

	@Override
	public int getEnterExitDL() {
		return 35;
	}

	@Override
	public int getEnterExitDT() {
		return 2;
	}

	@Override
	public int getInitialOffset() {
		return 1;
	}

	@Override
	public int getMirroredOffset() {
		return 0;
	}

	@Override
	public int getDifficultyRating() {
		return 1;
	}

	@Override
	public int getFeatureRating() {
		return 2;
	}

}
