/*******************************************************************************
 * @author Reika Kalseki
 * 
 * Copyright 2016
 * 
 * All rights reserved.
 * Distribution of the software in any form is only allowed with
 * explicit, prior permission from the owner.
 ******************************************************************************/
package Reika.ChromatiCraft.World.Dimension.Structure.Locks;

import net.minecraft.block.Block;
import net.minecraft.init.Blocks;
import Reika.ChromatiCraft.Base.LockLevel;
import Reika.ChromatiCraft.Block.Dimension.Structure.Locks.BlockLockKey.LockChannel;
import Reika.ChromatiCraft.Block.Worldgen.BlockStructureShield.BlockType;
import Reika.ChromatiCraft.Registry.ChromaBlocks;
import Reika.ChromatiCraft.World.Dimension.Structure.LocksGenerator;
import Reika.DragonAPI.Instantiable.Worldgen.OriginBlockCache;

public class LocksRoomBig extends LockLevel {

	public LocksRoomBig(LocksGenerator g) {
		super(g, LockChannel.BIG);
	}

	@Override
	public void generate(OriginBlockCache world, int x, int y, int z) {
		Block b = ChromaBlocks.STRUCTSHIELD.getBlockInstance();
		int ms = BlockType.STONE.metadata;
		int ml = BlockType.LIGHT.metadata;
		int mc = BlockType.CLOAK.metadata;
		this.generate1(world, x, y, z, b, ms, ml, mc);
		this.generate2(world, x, y, z, b, ms, ml, mc);
	}

	private void generate1(OriginBlockCache world, int x, int y, int z, Block b, int ms, int ml, int mc) {
		world.setBlock(x+0, y+1, z+13, b, ms);
		world.setBlock(x+0, y+1, z+14, b, ms);
		world.setBlock(x+0, y+1, z+15, b, ms);
		world.setBlock(x+0, y+1, z+16, b, ms);
		world.setBlock(x+0, y+1, z+17, b, ms);
		world.setBlock(x+0, y+1, z+37, b, ms);
		world.setBlock(x+0, y+1, z+38, b, ms);
		world.setBlock(x+0, y+1, z+39, b, ms);
		world.setBlock(x+0, y+1, z+44, b, ms);
		world.setBlock(x+0, y+1, z+45, b, ms);
		world.setBlock(x+0, y+1, z+46, b, ms);
		world.setBlock(x+0, y+1, z+47, b, ms);
		world.setBlock(x+0, y+1, z+48, b, ms);
		world.setBlock(x+0, y+1, z+49, b, ms);
		world.setBlock(x+0, y+1, z+50, b, ms);
		world.setBlock(x+0, y+2, z+13, b, ms);
		world.setBlock(x+0, y+2, z+14, b, ms);
		world.setBlock(x+0, y+2, z+15, b, ms);
		world.setBlock(x+0, y+2, z+16, b, ms);
		world.setBlock(x+0, y+2, z+17, b, ms);
		world.setBlock(x+0, y+2, z+37, b, ms);
		world.setBlock(x+0, y+2, z+38, b, ms);
		world.setBlock(x+0, y+2, z+39, b, ms);
		world.setBlock(x+0, y+2, z+44, b, ms);
		world.setBlock(x+0, y+2, z+45, b, ms);
		world.setBlock(x+0, y+2, z+46, b, ms);
		world.setBlock(x+0, y+2, z+47, b, ms);
		world.setBlock(x+0, y+2, z+48, b, ms);
		world.setBlock(x+0, y+2, z+49, b, ms);
		world.setBlock(x+0, y+2, z+50, b, ms);
		world.setBlock(x+0, y+3, z+13, b, ms);
		world.setBlock(x+0, y+3, z+14, b, ms);
		world.setBlock(x+0, y+3, z+15, b, ms);
		world.setBlock(x+0, y+3, z+16, b, ms);
		world.setBlock(x+0, y+3, z+17, b, ms);
		world.setBlock(x+0, y+3, z+37, b, ms);
		world.setBlock(x+0, y+3, z+38, b, ms);
		world.setBlock(x+0, y+3, z+39, b, ms);
		world.setBlock(x+0, y+3, z+44, b, ms);
		world.setBlock(x+0, y+3, z+45, b, ms);
		world.setBlock(x+0, y+3, z+46, b, ms);
		world.setBlock(x+0, y+3, z+47, b, ms);
		world.setBlock(x+0, y+3, z+48, b, ms);
		world.setBlock(x+0, y+3, z+49, b, ms);
		world.setBlock(x+0, y+3, z+50, b, ms);
		world.setBlock(x+1, y+1, z+13, b, ms);
		world.setBlock(x+1, y+1, z+14, b, ms);
		world.setBlock(x+1, y+1, z+15, b, ms);
		world.setBlock(x+1, y+1, z+16, b, ms);
		world.setBlock(x+1, y+1, z+17, b, ms);
		world.setBlock(x+1, y+1, z+37, b, ms);
		world.setBlock(x+1, y+1, z+38, b, ms);
		world.setBlock(x+1, y+1, z+39, b, ms);
		world.setBlock(x+1, y+1, z+44, b, ms);
		world.setBlock(x+1, y+1, z+45, b, ms);
		world.setBlock(x+1, y+1, z+46, b, ms);
		world.setBlock(x+1, y+1, z+47, b, ms);
		world.setBlock(x+1, y+1, z+48, b, ms);
		world.setBlock(x+1, y+1, z+49, b, ms);
		world.setBlock(x+1, y+1, z+50, b, ms);
		world.setBlock(x+1, y+2, z+13, b, ms);
		this.generateRune(x+1, y+2, z+14, LockColor.RED);
		world.setBlock(x+1, y+2, z+15, b, ms);
		this.generateRune(x+1, y+2, z+16, LockColor.PURPLE);
		world.setBlock(x+1, y+2, z+17, b, ms);
		world.setBlock(x+1, y+2, z+37, b, ms);
		this.generateRune(x+1, y+2, z+38, LockColor.RED);
		world.setBlock(x+1, y+2, z+39, b, ms);
		world.setBlock(x+1, y+2, z+44, b, ms);
		world.setBlock(x+1, y+2, z+45, b, mc);
		world.setBlock(x+1, y+2, z+46, b, ms);
		world.setBlock(x+1, y+2, z+47, b, mc);
		world.setBlock(x+1, y+2, z+48, b, ms);
		world.setBlock(x+1, y+2, z+49, b, mc);
		world.setBlock(x+1, y+2, z+50, b, ms);
		world.setBlock(x+1, y+3, z+13, b, ms);
		world.setBlock(x+1, y+3, z+14, b, ms);
		world.setBlock(x+1, y+3, z+15, b, ms);
		world.setBlock(x+1, y+3, z+16, b, ms);
		world.setBlock(x+1, y+3, z+17, b, ms);
		world.setBlock(x+1, y+3, z+37, b, ms);
		world.setBlock(x+1, y+3, z+38, b, ms);
		world.setBlock(x+1, y+3, z+39, b, ms);
		world.setBlock(x+1, y+3, z+44, b, ms);
		world.setBlock(x+1, y+3, z+45, b, ms);
		world.setBlock(x+1, y+3, z+46, b, ms);
		world.setBlock(x+1, y+3, z+47, b, ms);
		world.setBlock(x+1, y+3, z+48, b, ms);
		world.setBlock(x+1, y+3, z+49, b, ms);
		world.setBlock(x+1, y+3, z+50, b, ms);
		world.setBlock(x+2, y+0, z+1, b, ms);
		world.setBlock(x+2, y+0, z+2, b, ms);
		world.setBlock(x+2, y+0, z+3, b, ms);
		world.setBlock(x+2, y+0, z+4, b, ms);
		world.setBlock(x+2, y+0, z+5, b, ms);
		world.setBlock(x+2, y+0, z+6, b, ms);
		world.setBlock(x+2, y+0, z+7, b, ms);
		world.setBlock(x+2, y+0, z+8, b, ms);
		world.setBlock(x+2, y+0, z+9, b, ms);
		world.setBlock(x+2, y+0, z+11, b, ms);
		world.setBlock(x+2, y+0, z+12, b, ms);
		world.setBlock(x+2, y+0, z+13, b, ms);
		world.setBlock(x+2, y+0, z+14, b, ms);
		world.setBlock(x+2, y+0, z+15, b, ms);
		world.setBlock(x+2, y+0, z+16, b, ms);
		world.setBlock(x+2, y+0, z+17, b, ms);
		world.setBlock(x+2, y+0, z+18, b, ms);
		world.setBlock(x+2, y+0, z+19, b, ms);
		world.setBlock(x+2, y+0, z+20, b, ms);
		world.setBlock(x+2, y+0, z+21, b, ms);
		world.setBlock(x+2, y+0, z+22, b, ms);
		world.setBlock(x+2, y+0, z+23, b, ms);
		world.setBlock(x+2, y+0, z+34, b, ms);
		world.setBlock(x+2, y+0, z+35, b, ms);
		world.setBlock(x+2, y+0, z+36, b, ms);
		world.setBlock(x+2, y+0, z+37, b, ms);
		world.setBlock(x+2, y+0, z+38, b, ms);
		world.setBlock(x+2, y+0, z+39, b, ms);
		world.setBlock(x+2, y+0, z+40, b, ms);
		world.setBlock(x+2, y+0, z+41, b, ms);
		world.setBlock(x+2, y+0, z+42, b, ms);
		world.setBlock(x+2, y+0, z+43, b, ms);
		world.setBlock(x+2, y+0, z+44, b, ms);
		world.setBlock(x+2, y+0, z+45, b, ms);
		world.setBlock(x+2, y+0, z+46, b, ms);
		world.setBlock(x+2, y+0, z+47, b, ms);
		world.setBlock(x+2, y+0, z+48, b, ms);
		world.setBlock(x+2, y+0, z+49, b, ms);
		world.setBlock(x+2, y+0, z+50, b, ms);
		world.setBlock(x+2, y+1, z+1, b, ms);
		world.setBlock(x+2, y+1, z+2, b, ms);
		world.setBlock(x+2, y+1, z+3, b, ms);
		world.setBlock(x+2, y+1, z+4, b, ms);
		world.setBlock(x+2, y+1, z+5, b, ms);
		world.setBlock(x+2, y+1, z+6, b, ms);
		world.setBlock(x+2, y+1, z+7, b, ms);
		world.setBlock(x+2, y+1, z+8, b, ms);
		world.setBlock(x+2, y+1, z+9, b, ms);
		world.setBlock(x+2, y+1, z+11, b, ms);
		world.setBlock(x+2, y+1, z+12, b, ms);
		world.setBlock(x+2, y+1, z+13, b, ms);
		world.setBlock(x+2, y+1, z+14, b, ms);
		world.setBlock(x+2, y+1, z+15, b, ms);
		world.setBlock(x+2, y+1, z+16, b, ms);
		world.setBlock(x+2, y+1, z+17, b, ms);
		world.setBlock(x+2, y+1, z+18, b, ms);
		world.setBlock(x+2, y+1, z+19, b, ms);
		world.setBlock(x+2, y+1, z+20, b, ms);
		world.setBlock(x+2, y+1, z+21, b, ms);
		world.setBlock(x+2, y+1, z+22, b, ms);
		world.setBlock(x+2, y+1, z+23, b, ms);
		world.setBlock(x+2, y+1, z+34, b, ms);
		world.setBlock(x+2, y+1, z+35, b, ms);
		world.setBlock(x+2, y+1, z+36, b, ms);
		world.setBlock(x+2, y+1, z+37, b, ms);
		world.setBlock(x+2, y+1, z+38, b, ms);
		world.setBlock(x+2, y+1, z+39, b, ms);
		world.setBlock(x+2, y+1, z+40, b, ms);
		world.setBlock(x+2, y+1, z+41, b, ms);
		world.setBlock(x+2, y+1, z+42, b, ms);
		world.setBlock(x+2, y+1, z+43, b, ms);
		world.setBlock(x+2, y+1, z+44, b, ms);
		world.setBlock(x+2, y+1, z+45, b, ms);
		world.setBlock(x+2, y+1, z+46, b, ms);
		world.setBlock(x+2, y+1, z+47, b, ms);
		world.setBlock(x+2, y+1, z+48, b, ms);
		world.setBlock(x+2, y+1, z+49, b, ms);
		world.setBlock(x+2, y+1, z+50, b, ms);
		world.setBlock(x+2, y+2, z+1, b, ms);
		world.setBlock(x+2, y+2, z+2, b, ms);
		world.setBlock(x+2, y+2, z+3, b, ml);
		world.setBlock(x+2, y+2, z+4, b, ms);
		world.setBlock(x+2, y+2, z+5, b, ms);
		world.setBlock(x+2, y+2, z+6, b, ms);
		world.setBlock(x+2, y+2, z+7, b, ms);
		world.setBlock(x+2, y+2, z+8, b, ms);
		world.setBlock(x+2, y+2, z+9, b, ms);
		world.setBlock(x+2, y+2, z+11, b, ms);
		world.setBlock(x+2, y+2, z+12, b, ms);
		world.setBlock(x+2, y+2, z+13, b, ms);
		world.setBlock(x+2, y+2, z+15, b, ms);
		world.setBlock(x+2, y+2, z+17, b, ms);
		world.setBlock(x+2, y+2, z+18, b, ms);
		world.setBlock(x+2, y+2, z+19, b, ms);
		world.setBlock(x+2, y+2, z+20, b, ms);
		world.setBlock(x+2, y+2, z+21, b, ms);
		world.setBlock(x+2, y+2, z+22, b, ms);
		world.setBlock(x+2, y+2, z+23, b, ms);
		world.setBlock(x+2, y+2, z+34, b, ms);
		world.setBlock(x+2, y+2, z+35, b, ms);
		world.setBlock(x+2, y+2, z+36, b, ms);
		world.setBlock(x+2, y+2, z+37, b, ms);
		world.setBlock(x+2, y+2, z+39, b, ms);
		world.setBlock(x+2, y+2, z+40, b, ms);
		world.setBlock(x+2, y+2, z+41, b, ms);
		world.setBlock(x+2, y+2, z+42, b, ms);
		world.setBlock(x+2, y+2, z+43, b, ms);
		world.setBlock(x+2, y+2, z+44, b, ms);
		world.setBlock(x+2, y+2, z+46, b, ms);
		world.setBlock(x+2, y+2, z+48, b, ms);
		world.setBlock(x+2, y+2, z+50, b, ms);
		world.setBlock(x+2, y+3, z+1, b, ms);
		world.setBlock(x+2, y+3, z+2, b, ms);
		world.setBlock(x+2, y+3, z+3, b, ms);
		world.setBlock(x+2, y+3, z+4, b, ms);
		world.setBlock(x+2, y+3, z+5, b, ms);
		world.setBlock(x+2, y+3, z+6, b, ms);
		world.setBlock(x+2, y+3, z+7, b, ms);
		world.setBlock(x+2, y+3, z+8, b, ms);
		world.setBlock(x+2, y+3, z+9, b, ms);
		world.setBlock(x+2, y+3, z+11, b, ms);
		world.setBlock(x+2, y+3, z+12, b, ms);
		world.setBlock(x+2, y+3, z+13, b, ms);
		world.setBlock(x+2, y+3, z+14, b, ms);
		world.setBlock(x+2, y+3, z+15, b, ms);
		world.setBlock(x+2, y+3, z+16, b, ms);
		world.setBlock(x+2, y+3, z+17, b, ms);
		world.setBlock(x+2, y+3, z+18, b, ms);
		world.setBlock(x+2, y+3, z+19, b, ms);
		world.setBlock(x+2, y+3, z+20, b, ms);
		world.setBlock(x+2, y+3, z+21, b, ms);
		world.setBlock(x+2, y+3, z+22, b, ms);
		world.setBlock(x+2, y+3, z+23, b, ms);
		world.setBlock(x+2, y+3, z+34, b, ms);
		world.setBlock(x+2, y+3, z+35, b, ms);
		world.setBlock(x+2, y+3, z+36, b, ms);
		world.setBlock(x+2, y+3, z+37, b, ms);
		world.setBlock(x+2, y+3, z+38, b, ms);
		world.setBlock(x+2, y+3, z+39, b, ms);
		world.setBlock(x+2, y+3, z+40, b, ms);
		world.setBlock(x+2, y+3, z+41, b, ms);
		world.setBlock(x+2, y+3, z+42, b, ms);
		world.setBlock(x+2, y+3, z+43, b, ms);
		world.setBlock(x+2, y+3, z+44, b, ms);
		world.setBlock(x+2, y+3, z+45, b, ms);
		world.setBlock(x+2, y+3, z+46, b, ms);
		world.setBlock(x+2, y+3, z+47, b, ms);
		world.setBlock(x+2, y+3, z+48, b, ms);
		world.setBlock(x+2, y+3, z+49, b, ms);
		world.setBlock(x+2, y+3, z+50, b, ms);
		world.setBlock(x+2, y+4, z+1, b, ms);
		world.setBlock(x+2, y+4, z+2, b, ms);
		world.setBlock(x+2, y+4, z+3, b, ms);
		world.setBlock(x+2, y+4, z+4, b, ms);
		world.setBlock(x+2, y+4, z+5, b, ms);
		world.setBlock(x+2, y+4, z+6, b, ms);
		world.setBlock(x+2, y+4, z+7, b, ms);
		world.setBlock(x+2, y+4, z+8, b, ms);
		world.setBlock(x+2, y+4, z+9, b, ms);
		world.setBlock(x+2, y+4, z+11, b, ms);
		world.setBlock(x+2, y+4, z+12, b, ms);
		world.setBlock(x+2, y+4, z+13, b, ms);
		world.setBlock(x+2, y+4, z+14, b, ms);
		world.setBlock(x+2, y+4, z+15, b, ms);
		world.setBlock(x+2, y+4, z+16, b, ms);
		world.setBlock(x+2, y+4, z+17, b, ms);
		world.setBlock(x+2, y+4, z+18, b, ms);
		world.setBlock(x+2, y+4, z+19, b, ms);
		world.setBlock(x+2, y+4, z+20, b, ms);
		world.setBlock(x+2, y+4, z+21, b, ms);
		world.setBlock(x+2, y+4, z+22, b, ms);
		world.setBlock(x+2, y+4, z+23, b, ms);
		world.setBlock(x+2, y+4, z+34, b, ms);
		world.setBlock(x+2, y+4, z+35, b, ms);
		world.setBlock(x+2, y+4, z+36, b, ms);
		world.setBlock(x+2, y+4, z+37, b, ms);
		world.setBlock(x+2, y+4, z+38, b, ms);
		world.setBlock(x+2, y+4, z+39, b, ms);
		world.setBlock(x+2, y+4, z+40, b, ms);
		world.setBlock(x+2, y+4, z+41, b, ms);
		world.setBlock(x+2, y+4, z+43, b, ms);
		world.setBlock(x+2, y+4, z+44, b, ms);
		world.setBlock(x+2, y+4, z+45, b, ms);
		world.setBlock(x+2, y+4, z+46, b, ms);
		world.setBlock(x+2, y+4, z+47, b, ml);
		world.setBlock(x+2, y+4, z+48, b, ms);
		world.setBlock(x+2, y+4, z+49, b, ms);
		world.setBlock(x+2, y+4, z+50, b, ms);
		world.setBlock(x+2, y+5, z+1, b, ms);
		world.setBlock(x+2, y+5, z+2, b, ms);
		world.setBlock(x+2, y+5, z+3, b, ms);
		world.setBlock(x+2, y+5, z+4, b, ms);
		world.setBlock(x+2, y+5, z+5, b, ms);
		world.setBlock(x+2, y+5, z+6, b, ms);
		world.setBlock(x+2, y+5, z+7, b, ms);
		world.setBlock(x+2, y+5, z+8, b, ms);
		world.setBlock(x+2, y+5, z+9, b, ms);
		world.setBlock(x+2, y+5, z+11, b, ms);
		world.setBlock(x+2, y+5, z+12, b, ms);
		world.setBlock(x+2, y+5, z+13, b, ms);
		world.setBlock(x+2, y+5, z+14, b, ms);
		world.setBlock(x+2, y+5, z+15, b, ms);
		world.setBlock(x+2, y+5, z+16, b, ms);
		world.setBlock(x+2, y+5, z+17, b, ms);
		world.setBlock(x+2, y+5, z+18, b, ms);
		world.setBlock(x+2, y+5, z+23, b, ms);
		world.setBlock(x+2, y+5, z+34, b, ms);
		world.setBlock(x+2, y+5, z+35, b, ms);
		world.setBlock(x+2, y+5, z+36, b, ms);
		world.setBlock(x+2, y+5, z+37, b, ms);
		world.setBlock(x+2, y+5, z+38, b, ms);
		world.setBlock(x+2, y+5, z+39, b, ms);
		world.setBlock(x+2, y+5, z+40, b, ms);
		world.setBlock(x+2, y+5, z+41, b, ms);
		world.setBlock(x+2, y+5, z+43, b, ms);
		world.setBlock(x+2, y+5, z+44, b, ms);
		world.setBlock(x+2, y+5, z+45, b, ms);
		world.setBlock(x+2, y+5, z+46, b, ms);
		world.setBlock(x+2, y+5, z+47, b, ms);
		world.setBlock(x+2, y+5, z+48, b, ms);
		world.setBlock(x+2, y+5, z+49, b, ms);
		world.setBlock(x+2, y+5, z+50, b, ms);
		world.setBlock(x+3, y+0, z+1, b, ms);
		world.setBlock(x+3, y+0, z+2, b, ms);
		world.setBlock(x+3, y+0, z+3, b, ms);
		world.setBlock(x+3, y+0, z+4, b, ms);
		world.setBlock(x+3, y+0, z+5, b, ms);
		world.setBlock(x+3, y+0, z+6, b, ms);
		world.setBlock(x+3, y+0, z+7, b, ms);
		world.setBlock(x+3, y+0, z+8, b, ms);
		world.setBlock(x+3, y+0, z+9, b, ms);
		world.setBlock(x+3, y+0, z+11, b, ms);
		world.setBlock(x+3, y+0, z+12, b, ms);
		world.setBlock(x+3, y+0, z+13, b, ms);
		world.setBlock(x+3, y+0, z+14, b, ms);
		world.setBlock(x+3, y+0, z+15, b, ms);
		world.setBlock(x+3, y+0, z+16, b, ms);
		world.setBlock(x+3, y+0, z+17, b, ms);
		world.setBlock(x+3, y+0, z+18, b, ms);
		world.setBlock(x+3, y+0, z+19, b, ms);
		world.setBlock(x+3, y+0, z+20, b, ms);
		world.setBlock(x+3, y+0, z+21, b, ms);
		world.setBlock(x+3, y+0, z+22, b, ms);
		world.setBlock(x+3, y+0, z+23, b, ms);
		world.setBlock(x+3, y+0, z+24, b, ms);
		world.setBlock(x+3, y+0, z+25, b, ms);
		world.setBlock(x+3, y+0, z+26, b, ms);
		world.setBlock(x+3, y+0, z+31, b, ms);
		world.setBlock(x+3, y+0, z+32, b, ms);
		world.setBlock(x+3, y+0, z+33, b, ms);
		world.setBlock(x+3, y+0, z+34, b, ms);
		world.setBlock(x+3, y+0, z+35, b, ms);
		world.setBlock(x+3, y+0, z+36, b, ms);
		world.setBlock(x+3, y+0, z+37, b, ms);
		world.setBlock(x+3, y+0, z+38, b, ms);
		world.setBlock(x+3, y+0, z+39, b, ms);
		world.setBlock(x+3, y+0, z+40, b, ms);
		world.setBlock(x+3, y+0, z+41, b, ms);
		world.setBlock(x+3, y+0, z+42, b, ms);
		world.setBlock(x+3, y+0, z+43, b, ms);
		world.setBlock(x+3, y+0, z+44, b, ms);
		world.setBlock(x+3, y+0, z+45, b, ms);
		world.setBlock(x+3, y+0, z+46, b, ms);
		world.setBlock(x+3, y+0, z+47, b, ms);
		world.setBlock(x+3, y+0, z+48, b, ms);
		world.setBlock(x+3, y+0, z+49, b, ms);
		world.setBlock(x+3, y+0, z+50, b, ms);
		world.setBlock(x+3, y+0, z+51, b, ms);
		world.setBlock(x+3, y+0, z+52, b, ms);
		world.setBlock(x+3, y+0, z+53, b, ms);
		world.setBlock(x+3, y+1, z+1, b, ms);
		world.setBlock(x+3, y+1, z+9, b, ms);
		world.setBlock(x+3, y+1, z+11, b, ms);
		this.generateLock(x+3, y+1, z+19, LockColor.YELLOW);
		world.setBlock(x+3, y+1, z+23, b, ms);
		world.setBlock(x+3, y+1, z+24, b, ms);
		world.setBlock(x+3, y+1, z+25, b, ms);
		world.setBlock(x+3, y+1, z+26, b, ms);
		world.setBlock(x+3, y+1, z+31, b, ms);
		world.setBlock(x+3, y+1, z+32, b, ms);
		world.setBlock(x+3, y+1, z+33, b, ms);
		world.setBlock(x+3, y+1, z+34, b, ms);
		world.setBlock(x+3, y+1, z+35, b, ms);
		world.setBlock(x+3, y+1, z+36, b, ms);
		world.setBlock(x+3, y+1, z+41, b, ms);
		world.setBlock(x+3, y+1, z+42, b, ms);
		world.setBlock(x+3, y+1, z+43, b, ms);
		world.setBlock(x+3, y+1, z+51, b, ms);
		world.setBlock(x+3, y+1, z+52, b, ms);
		world.setBlock(x+3, y+1, z+53, b, ms);
		world.setBlock(x+3, y+2, z+1, b, ms);
		world.setBlock(x+3, y+2, z+9, b, ms);
		world.setBlock(x+3, y+2, z+11, b, ms);
		this.generateLock(x+3, y+2, z+19, LockColor.YELLOW);
		world.setBlock(x+3, y+2, z+23, b, ms);
		world.setBlock(x+3, y+2, z+24, b, ms);
		world.setBlock(x+3, y+2, z+25, b, ms);
		world.setBlock(x+3, y+2, z+26, b, ms);
		world.setBlock(x+3, y+2, z+31, b, ms);
		world.setBlock(x+3, y+2, z+32, b, ms);
		world.setBlock(x+3, y+2, z+33, b, ms);
		world.setBlock(x+3, y+2, z+34, b, ms);
		world.setBlock(x+3, y+2, z+35, b, ms);
		world.setBlock(x+3, y+2, z+36, b, ms);
		world.setBlock(x+3, y+2, z+41, b, ms);
		world.setBlock(x+3, y+2, z+42, b, ms);
		world.setBlock(x+3, y+2, z+43, b, ms);
		world.setBlock(x+3, y+2, z+51, b, ms);
		world.setBlock(x+3, y+2, z+52, b, ms);
		world.setBlock(x+3, y+2, z+53, b, ms);
		world.setBlock(x+3, y+3, z+1, b, ms);
		world.setBlock(x+3, y+3, z+9, b, ms);
		world.setBlock(x+3, y+3, z+11, b, ms);
		this.generateLock(x+3, y+3, z+19, LockColor.YELLOW);
		world.setBlock(x+3, y+3, z+23, b, ms);
		world.setBlock(x+3, y+3, z+24, b, ms);
		world.setBlock(x+3, y+3, z+25, b, ms);
		world.setBlock(x+3, y+3, z+26, b, ms);
		world.setBlock(x+3, y+3, z+31, b, ms);
		world.setBlock(x+3, y+3, z+32, b, ms);
		world.setBlock(x+3, y+3, z+33, b, ms);
		world.setBlock(x+3, y+3, z+34, b, ms);
		world.setBlock(x+3, y+3, z+35, b, ms);
		world.setBlock(x+3, y+3, z+36, b, ms);
		world.setBlock(x+3, y+3, z+41, b, ms);
		world.setBlock(x+3, y+3, z+42, b, ms);
		world.setBlock(x+3, y+3, z+43, b, ms);
		world.setBlock(x+3, y+3, z+51, b, ms);
		world.setBlock(x+3, y+3, z+52, b, ms);
		world.setBlock(x+3, y+3, z+53, b, ms);
		world.setBlock(x+3, y+4, z+1, b, ms);
		world.setBlock(x+3, y+4, z+9, b, ms);
		world.setBlock(x+3, y+4, z+11, b, ms);
		world.setBlock(x+3, y+4, z+18, b, ms);
		world.setBlock(x+3, y+4, z+19, b, ms);
		world.setBlock(x+3, y+4, z+20, b, ms);
		world.setBlock(x+3, y+4, z+21, b, ms);
		world.setBlock(x+3, y+4, z+22, b, ms);
		world.setBlock(x+3, y+4, z+23, b, ms);
		world.setBlock(x+3, y+4, z+31, b, ms);
		world.setBlock(x+3, y+4, z+32, b, ms);
		world.setBlock(x+3, y+4, z+33, b, ms);
		world.setBlock(x+3, y+4, z+34, b, ms);
		world.setBlock(x+3, y+4, z+35, b, ms);
		world.setBlock(x+3, y+4, z+36, b, ms);
		world.setBlock(x+3, y+4, z+41, b, ms);
		world.setBlock(x+3, y+4, z+43, b, ms);
		world.setBlock(x+3, y+4, z+51, b, ms);
		world.setBlock(x+3, y+4, z+52, b, ms);
		world.setBlock(x+3, y+4, z+53, b, ms);
		world.setBlock(x+3, y+5, z+1, b, ms);
		world.setBlock(x+3, y+5, z+2, b, ms);
		world.setBlock(x+3, y+5, z+3, b, ms);
		world.setBlock(x+3, y+5, z+4, b, ms);
		world.setBlock(x+3, y+5, z+5, b, ms);
		world.setBlock(x+3, y+5, z+6, b, ms);
		world.setBlock(x+3, y+5, z+7, b, ms);
		world.setBlock(x+3, y+5, z+8, b, ms);
		world.setBlock(x+3, y+5, z+9, b, ms);
		world.setBlock(x+3, y+5, z+11, b, ms);
		world.setBlock(x+3, y+5, z+12, b, ms);
		world.setBlock(x+3, y+5, z+13, b, ms);
		world.setBlock(x+3, y+5, z+14, b, ms);
		world.setBlock(x+3, y+5, z+15, b, ms);
		world.setBlock(x+3, y+5, z+16, b, ms);
		world.setBlock(x+3, y+5, z+17, b, ms);
		world.setBlock(x+3, y+5, z+18, b, ms);
		world.setBlock(x+3, y+5, z+23, b, ms);
		world.setBlock(x+3, y+5, z+34, b, ms);
		world.setBlock(x+3, y+5, z+35, b, ms);
		world.setBlock(x+3, y+5, z+36, b, ms);
		world.setBlock(x+3, y+5, z+37, b, ms);
		world.setBlock(x+3, y+5, z+38, b, ms);
		world.setBlock(x+3, y+5, z+39, b, ms);
		world.setBlock(x+3, y+5, z+40, b, ms);
		world.setBlock(x+3, y+5, z+41, b, ms);
		world.setBlock(x+3, y+5, z+43, b, ms);
		world.setBlock(x+3, y+5, z+44, b, ms);
		world.setBlock(x+3, y+5, z+45, b, ms);
		world.setBlock(x+3, y+5, z+46, b, ms);
		world.setBlock(x+3, y+5, z+47, b, ms);
		world.setBlock(x+3, y+5, z+48, b, ms);
		world.setBlock(x+3, y+5, z+49, b, ms);
		world.setBlock(x+3, y+5, z+50, b, ms);
		world.setBlock(x+3, y+5, z+51, b, ms);
		world.setBlock(x+4, y+0, z+0, b, ms);
		world.setBlock(x+4, y+0, z+1, b, ms);
		world.setBlock(x+4, y+0, z+2, b, ms);
		world.setBlock(x+4, y+0, z+3, b, ms);
		world.setBlock(x+4, y+0, z+4, b, ms);
		world.setBlock(x+4, y+0, z+5, b, ms);
		world.setBlock(x+4, y+0, z+6, b, ms);
		world.setBlock(x+4, y+0, z+7, b, ms);
		world.setBlock(x+4, y+0, z+8, b, ms);
		world.setBlock(x+4, y+0, z+9, b, ms);
		world.setBlock(x+4, y+0, z+10, b, ms);
		world.setBlock(x+4, y+0, z+11, b, ms);
		world.setBlock(x+4, y+0, z+12, b, ms);
		world.setBlock(x+4, y+0, z+13, b, ms);
		world.setBlock(x+4, y+0, z+14, b, ms);
		world.setBlock(x+4, y+0, z+15, b, ml);
		world.setBlock(x+4, y+0, z+16, b, ms);
		world.setBlock(x+4, y+0, z+17, b, ms);
		world.setBlock(x+4, y+0, z+18, b, ms);
		world.setBlock(x+4, y+0, z+19, b, ms);
		world.setBlock(x+4, y+0, z+20, b, ms);
		world.setBlock(x+4, y+0, z+21, b, ms);
		world.setBlock(x+4, y+0, z+22, b, ms);
		world.setBlock(x+4, y+0, z+23, b, ms);
		world.setBlock(x+4, y+0, z+24, b, ms);
		world.setBlock(x+4, y+0, z+25, b, ms);
		world.setBlock(x+4, y+0, z+26, b, ms);
		world.setBlock(x+4, y+0, z+28, b, ms);
		world.setBlock(x+4, y+0, z+29, b, ms);
		world.setBlock(x+4, y+0, z+30, b, ms);
		world.setBlock(x+4, y+0, z+31, b, ms);
		world.setBlock(x+4, y+0, z+32, b, ms);
		world.setBlock(x+4, y+0, z+33, b, ms);
		world.setBlock(x+4, y+0, z+34, b, ms);
		world.setBlock(x+4, y+0, z+35, b, ms);
		world.setBlock(x+4, y+0, z+36, b, ms);
		world.setBlock(x+4, y+0, z+37, b, ms);
		world.setBlock(x+4, y+0, z+38, b, ms);
		world.setBlock(x+4, y+0, z+39, b, ms);
		world.setBlock(x+4, y+0, z+40, b, ms);
		world.setBlock(x+4, y+0, z+41, b, ms);
		world.setBlock(x+4, y+0, z+42, b, ms);
		world.setBlock(x+4, y+0, z+43, b, ms);
		world.setBlock(x+4, y+0, z+44, b, ms);
		world.setBlock(x+4, y+0, z+45, b, ms);
		world.setBlock(x+4, y+0, z+46, b, ms);
		world.setBlock(x+4, y+0, z+47, b, ms);
		world.setBlock(x+4, y+0, z+48, b, ms);
		world.setBlock(x+4, y+0, z+49, b, ms);
		world.setBlock(x+4, y+0, z+50, b, ms);
		world.setBlock(x+4, y+0, z+51, b, ms);
		world.setBlock(x+4, y+0, z+52, b, ms);
		world.setBlock(x+4, y+0, z+53, b, ms);
		world.setBlock(x+4, y+1, z+0, b, ms);
		this.generateKey(x+4, y+1, z+5);
		world.setBlock(x+4, y+1, z+9, b, ms);
		world.setBlock(x+4, y+1, z+10, b, ms);
		world.setBlock(x+4, y+1, z+11, b, ms);
		this.generateLock(x+4, y+1, z+19, LockColor.YELLOW);
		this.generateKey(x+4, y+1, z+21);
		world.setBlock(x+4, y+1, z+23, b, ms);
		world.setBlock(x+4, y+1, z+24, b, ms);
		world.setBlock(x+4, y+1, z+25, b, ms);
		world.setBlock(x+4, y+1, z+26, b, ms);
		world.setBlock(x+4, y+1, z+28, b, ms);
		world.setBlock(x+4, y+1, z+29, b, ms);
		world.setBlock(x+4, y+1, z+30, b, ms);
		world.setBlock(x+4, y+1, z+34, b, ms);
		world.setBlock(x+4, y+1, z+35, b, ms);
		world.setBlock(x+4, y+1, z+36, b, ms);
		world.setBlock(x+4, y+1, z+41, b, ms);
		world.setBlock(x+4, y+1, z+42, b, ms);
		world.setBlock(x+4, y+1, z+43, b, ms);
		this.generateGate(x+4, y+1, z+52);
		world.setBlock(x+4, y+2, z+0, b, ms);
		world.setBlock(x+4, y+2, z+9, b, ms);
		world.setBlock(x+4, y+2, z+10, b, ms);
		world.setBlock(x+4, y+2, z+11, b, ms);
		this.generateLock(x+4, y+2, z+19, LockColor.YELLOW);
		world.setBlock(x+4, y+2, z+23, b, ms);
		world.setBlock(x+4, y+2, z+24, b, ms);
		this.generateRune(x+4, y+2, z+25, LockColor.BLUE);
		world.setBlock(x+4, y+2, z+26, b, ms);
		world.setBlock(x+4, y+2, z+28, b, ms);
		world.setBlock(x+4, y+2, z+29, b, ms);
		world.setBlock(x+4, y+2, z+30, b, ms);
		world.setBlock(x+4, y+2, z+34, b, ms);
		this.generateRune(x+4, y+2, z+35, LockColor.BLUE);
		this.generateRune(x+4, y+2, z+42, LockColor.PURPLE);
		this.generateGate(x+4, y+2, z+52);
		world.setBlock(x+4, y+3, z+0, b, ms);
		world.setBlock(x+4, y+3, z+9, b, ms);
		world.setBlock(x+4, y+3, z+10, b, ms);
		world.setBlock(x+4, y+3, z+11, b, ms);
		this.generateLock(x+4, y+3, z+19, LockColor.YELLOW);
		world.setBlock(x+4, y+3, z+23, b, ms);
		world.setBlock(x+4, y+3, z+24, b, ms);
		world.setBlock(x+4, y+3, z+25, b, ms);
		world.setBlock(x+4, y+3, z+26, b, ms);
		world.setBlock(x+4, y+3, z+28, b, ms);
		world.setBlock(x+4, y+3, z+29, b, ms);
		world.setBlock(x+4, y+3, z+30, b, ms);
		world.setBlock(x+4, y+3, z+34, b, ms);
		world.setBlock(x+4, y+3, z+35, b, ms);
		world.setBlock(x+4, y+3, z+36, b, ms);
		world.setBlock(x+4, y+3, z+41, b, ms);
		world.setBlock(x+4, y+3, z+42, b, ms);
		world.setBlock(x+4, y+3, z+43, b, ms);
		this.generateGate(x+4, y+3, z+52);
		world.setBlock(x+4, y+4, z+0, b, ms);
		world.setBlock(x+4, y+4, z+9, b, ms);
		world.setBlock(x+4, y+4, z+10, b, ms);
		world.setBlock(x+4, y+4, z+11, b, ms);
		world.setBlock(x+4, y+4, z+18, b, ms);
		world.setBlock(x+4, y+4, z+19, b, ms);
		world.setBlock(x+4, y+4, z+20, b, ms);
		world.setBlock(x+4, y+4, z+21, b, ms);
		world.setBlock(x+4, y+4, z+22, b, ms);
		world.setBlock(x+4, y+4, z+23, b, ms);
		world.setBlock(x+4, y+4, z+30, b, ms);
		world.setBlock(x+4, y+4, z+31, b, ms);
		world.setBlock(x+4, y+4, z+32, b, ms);
		world.setBlock(x+4, y+4, z+33, b, ms);
		world.setBlock(x+4, y+4, z+34, b, ms);
		world.setBlock(x+4, y+4, z+35, b, ms);
		world.setBlock(x+4, y+4, z+36, b, ms);
		world.setBlock(x+4, y+4, z+41, b, ms);
		world.setBlock(x+4, y+4, z+43, b, ms);
		world.setBlock(x+4, y+4, z+51, b, ms);
		world.setBlock(x+4, y+4, z+52, b, ms);
		world.setBlock(x+4, y+4, z+53, b, ms);
		world.setBlock(x+4, y+5, z+1, b, ms);
		world.setBlock(x+4, y+5, z+2, b, ms);
		world.setBlock(x+4, y+5, z+3, b, ms);
		world.setBlock(x+4, y+5, z+4, b, ms);
		world.setBlock(x+4, y+5, z+5, b, ms);
		world.setBlock(x+4, y+5, z+6, b, ms);
		world.setBlock(x+4, y+5, z+7, b, ms);
		world.setBlock(x+4, y+5, z+8, b, ms);
		world.setBlock(x+4, y+5, z+9, b, ms);
		world.setBlock(x+4, y+5, z+11, b, ms);
		world.setBlock(x+4, y+5, z+12, b, ms);
		world.setBlock(x+4, y+5, z+13, b, ms);
		world.setBlock(x+4, y+5, z+14, b, ms);
		world.setBlock(x+4, y+5, z+15, b, ms);
		world.setBlock(x+4, y+5, z+16, b, ms);
		world.setBlock(x+4, y+5, z+17, b, ms);
		world.setBlock(x+4, y+5, z+18, b, ms);
		world.setBlock(x+4, y+5, z+23, b, ms);
		world.setBlock(x+4, y+5, z+34, b, ms);
		world.setBlock(x+4, y+5, z+35, b, ms);
		world.setBlock(x+4, y+5, z+36, b, ms);
		world.setBlock(x+4, y+5, z+37, b, ms);
		world.setBlock(x+4, y+5, z+38, b, ml);
		world.setBlock(x+4, y+5, z+39, b, ms);
		world.setBlock(x+4, y+5, z+40, b, ms);
		world.setBlock(x+4, y+5, z+41, b, ms);
		world.setBlock(x+4, y+5, z+43, b, ms);
		world.setBlock(x+4, y+5, z+44, b, ms);
		world.setBlock(x+4, y+5, z+45, b, ms);
		world.setBlock(x+4, y+5, z+46, b, ms);
		world.setBlock(x+4, y+5, z+47, b, ms);
		world.setBlock(x+4, y+5, z+48, b, ms);
		world.setBlock(x+4, y+5, z+49, b, ms);
		world.setBlock(x+4, y+5, z+50, b, ms);
		world.setBlock(x+4, y+5, z+51, b, ms);
		world.setBlock(x+5, y+0, z+0, b, ms);
		world.setBlock(x+5, y+0, z+1, b, ms);
		world.setBlock(x+5, y+0, z+2, b, ms);
		world.setBlock(x+5, y+0, z+3, b, ms);
		world.setBlock(x+5, y+0, z+4, b, ms);
		world.setBlock(x+5, y+0, z+5, b, ms);
		world.setBlock(x+5, y+0, z+6, b, ms);
		world.setBlock(x+5, y+0, z+7, b, ms);
		world.setBlock(x+5, y+0, z+8, b, ms);
		world.setBlock(x+5, y+0, z+9, b, ms);
		world.setBlock(x+5, y+0, z+10, b, ms);
		world.setBlock(x+5, y+0, z+11, b, ms);
		world.setBlock(x+5, y+0, z+12, b, ms);
		world.setBlock(x+5, y+0, z+13, b, ms);
		world.setBlock(x+5, y+0, z+14, b, ms);
		world.setBlock(x+5, y+0, z+15, b, ms);
		world.setBlock(x+5, y+0, z+16, b, ms);
		world.setBlock(x+5, y+0, z+17, b, ms);
		world.setBlock(x+5, y+0, z+18, b, ms);
		world.setBlock(x+5, y+0, z+19, b, ms);
		world.setBlock(x+5, y+0, z+20, b, ms);
		world.setBlock(x+5, y+0, z+21, b, ms);
		world.setBlock(x+5, y+0, z+22, b, ms);
		world.setBlock(x+5, y+0, z+23, b, ms);
		world.setBlock(x+5, y+0, z+24, b, ms);
		world.setBlock(x+5, y+0, z+25, b, ms);
		world.setBlock(x+5, y+0, z+26, b, ms);
		world.setBlock(x+5, y+0, z+27, b, ms);
		world.setBlock(x+5, y+0, z+28, b, ms);
		world.setBlock(x+5, y+0, z+29, b, ms);
		world.setBlock(x+5, y+0, z+30, b, ms);
		world.setBlock(x+5, y+0, z+31, b, ms);
		world.setBlock(x+5, y+0, z+32, b, ms);
		world.setBlock(x+5, y+0, z+33, b, ms);
		world.setBlock(x+5, y+0, z+34, b, ms);
		world.setBlock(x+5, y+0, z+35, b, ms);
		world.setBlock(x+5, y+0, z+36, b, ms);
		world.setBlock(x+5, y+0, z+37, b, ms);
		world.setBlock(x+5, y+0, z+38, b, ms);
		world.setBlock(x+5, y+0, z+39, b, ms);
		world.setBlock(x+5, y+0, z+40, b, ms);
		world.setBlock(x+5, y+0, z+41, b, ms);
		world.setBlock(x+5, y+0, z+42, b, ms);
		world.setBlock(x+5, y+0, z+43, b, ms);
		world.setBlock(x+5, y+0, z+44, b, ms);
		world.setBlock(x+5, y+0, z+45, b, ms);
		world.setBlock(x+5, y+0, z+46, b, ms);
		world.setBlock(x+5, y+0, z+47, b, ms);
		world.setBlock(x+5, y+0, z+48, b, ms);
		world.setBlock(x+5, y+0, z+49, b, ms);
		world.setBlock(x+5, y+0, z+50, b, ms);
		world.setBlock(x+5, y+0, z+51, b, ms);
		world.setBlock(x+5, y+0, z+52, b, ms);
		world.setBlock(x+5, y+0, z+53, b, ms);
		this.generateLock(x+5, y+1, z+10, LockColor.RED);
		this.generateLock(x+5, y+1, z+19, LockColor.YELLOW);
		world.setBlock(x+5, y+1, z+23, b, ms);
		world.setBlock(x+5, y+1, z+24, b, ms);
		world.setBlock(x+5, y+1, z+25, b, ms);
		world.setBlock(x+5, y+1, z+26, b, ms);
		world.setBlock(x+5, y+1, z+27, b, ms);
		world.setBlock(x+5, y+1, z+28, b, ms);
		world.setBlock(x+5, y+1, z+29, b, ms);
		world.setBlock(x+5, y+1, z+30, b, ms);
		world.setBlock(x+5, y+1, z+34, b, ms);
		world.setBlock(x+5, y+1, z+35, b, ms);
		world.setBlock(x+5, y+1, z+36, b, ms);
		world.setBlock(x+5, y+1, z+41, b, ms);
		world.setBlock(x+5, y+1, z+42, b, ms);
		world.setBlock(x+5, y+1, z+43, b, ms);
		this.generateGate(x+5, y+1, z+52);
		this.generateLock(x+5, y+2, z+10, LockColor.RED);
		this.generateLock(x+5, y+2, z+19, LockColor.YELLOW);
		world.setBlock(x+5, y+2, z+23, b, ms);
		world.setBlock(x+5, y+2, z+24, b, ms);
		world.setBlock(x+5, y+2, z+26, b, ms);
		world.setBlock(x+5, y+2, z+27, b, ms);
		world.setBlock(x+5, y+2, z+28, b, ms);
		this.generateRune(x+5, y+2, z+29, LockColor.BLUE);
		world.setBlock(x+5, y+2, z+34, b, ms);
		world.setBlock(x+5, y+2, z+35, b, ms);
		world.setBlock(x+5, y+2, z+36, b, ms);
		world.setBlock(x+5, y+2, z+41, b, ms);
		world.setBlock(x+5, y+2, z+42, b, ms);
		world.setBlock(x+5, y+2, z+43, b, ms);
		this.generateGate(x+5, y+2, z+52);
		this.generateLock(x+5, y+3, z+10, LockColor.RED);
		this.generateLock(x+5, y+3, z+19, LockColor.YELLOW);
		world.setBlock(x+5, y+3, z+23, b, ms);
		world.setBlock(x+5, y+3, z+24, b, ms);
		world.setBlock(x+5, y+3, z+25, b, ms);
		world.setBlock(x+5, y+3, z+26, b, ms);
		world.setBlock(x+5, y+3, z+27, b, ms);
		world.setBlock(x+5, y+3, z+28, b, ms);
		world.setBlock(x+5, y+3, z+29, b, ms);
		world.setBlock(x+5, y+3, z+30, b, ms);
		world.setBlock(x+5, y+3, z+34, b, ms);
		world.setBlock(x+5, y+3, z+35, b, ms);
		world.setBlock(x+5, y+3, z+36, b, ms);
		world.setBlock(x+5, y+3, z+41, b, ms);
		world.setBlock(x+5, y+3, z+42, b, ms);
		world.setBlock(x+5, y+3, z+43, b, ms);
		this.generateGate(x+5, y+3, z+52);
		world.setBlock(x+5, y+4, z+0, b, ms);
		world.setBlock(x+5, y+4, z+9, b, ms);
		world.setBlock(x+5, y+4, z+10, b, ms);
		world.setBlock(x+5, y+4, z+11, b, ms);
		world.setBlock(x+5, y+4, z+18, b, ms);
		world.setBlock(x+5, y+4, z+19, b, ms);
		world.setBlock(x+5, y+4, z+20, b, ms);
		world.setBlock(x+5, y+4, z+21, b, ms);
		world.setBlock(x+5, y+4, z+22, b, ms);
		world.setBlock(x+5, y+4, z+23, b, ms);
		world.setBlock(x+5, y+4, z+24, b, ms);
		world.setBlock(x+5, y+4, z+25, b, ms);
		world.setBlock(x+5, y+4, z+26, b, ms);
		world.setBlock(x+5, y+4, z+27, b, ms);
		world.setBlock(x+5, y+4, z+30, b, ms);
		world.setBlock(x+5, y+4, z+31, b, ms);
		world.setBlock(x+5, y+4, z+32, b, ml);
		world.setBlock(x+5, y+4, z+33, b, ms);
		world.setBlock(x+5, y+4, z+34, b, ms);
		world.setBlock(x+5, y+4, z+35, b, ms);
		world.setBlock(x+5, y+4, z+36, b, ms);
		world.setBlock(x+5, y+4, z+41, b, ms);
		world.setBlock(x+5, y+4, z+43, b, ms);
		world.setBlock(x+5, y+4, z+51, b, ml);
		world.setBlock(x+5, y+4, z+52, b, ms);
		world.setBlock(x+5, y+4, z+53, b, ms);
		world.setBlock(x+5, y+5, z+1, b, ms);
		world.setBlock(x+5, y+5, z+2, b, ms);
		world.setBlock(x+5, y+5, z+3, b, ms);
		world.setBlock(x+5, y+5, z+4, b, ms);
		world.setBlock(x+5, y+5, z+5, b, ms);
		world.setBlock(x+5, y+5, z+6, b, ms);
		world.setBlock(x+5, y+5, z+7, b, ms);
		world.setBlock(x+5, y+5, z+8, b, ms);
		world.setBlock(x+5, y+5, z+9, b, ms);
		world.setBlock(x+5, y+5, z+11, b, ms);
		world.setBlock(x+5, y+5, z+12, b, ms);
		world.setBlock(x+5, y+5, z+13, b, ms);
		world.setBlock(x+5, y+5, z+14, b, ms);
		world.setBlock(x+5, y+5, z+15, b, ms);
		world.setBlock(x+5, y+5, z+16, b, ms);
		world.setBlock(x+5, y+5, z+17, b, ms);
		world.setBlock(x+5, y+5, z+18, b, ms);
		world.setBlock(x+5, y+5, z+22, b, ms);
		world.setBlock(x+5, y+5, z+23, b, ms);
		world.setBlock(x+5, y+5, z+24, b, ms);
		world.setBlock(x+5, y+5, z+25, b, ms);
		world.setBlock(x+5, y+5, z+26, b, ms);
		world.setBlock(x+5, y+5, z+27, b, ms);
		world.setBlock(x+5, y+5, z+34, b, ms);
		world.setBlock(x+5, y+5, z+35, b, ms);
		world.setBlock(x+5, y+5, z+36, b, ms);
		world.setBlock(x+5, y+5, z+37, b, ms);
		world.setBlock(x+5, y+5, z+38, b, ms);
		world.setBlock(x+5, y+5, z+39, b, ms);
		world.setBlock(x+5, y+5, z+40, b, ms);
		world.setBlock(x+5, y+5, z+41, b, ms);
		world.setBlock(x+5, y+5, z+43, b, ms);
		world.setBlock(x+5, y+5, z+44, b, ms);
		world.setBlock(x+5, y+5, z+45, b, ms);
		world.setBlock(x+5, y+5, z+46, b, ms);
		world.setBlock(x+5, y+5, z+47, b, ms);
		world.setBlock(x+5, y+5, z+48, b, ms);
		world.setBlock(x+5, y+5, z+49, b, ms);
		world.setBlock(x+5, y+5, z+50, b, ms);
		world.setBlock(x+5, y+5, z+51, b, ms);
		world.setBlock(x+6, y+0, z+0, b, ms);
		world.setBlock(x+6, y+0, z+1, b, ms);
		world.setBlock(x+6, y+0, z+2, b, ms);
		world.setBlock(x+6, y+0, z+3, b, ms);
		world.setBlock(x+6, y+0, z+4, b, ms);
		world.setBlock(x+6, y+0, z+5, b, ml);
		world.setBlock(x+6, y+0, z+6, b, ms);
		world.setBlock(x+6, y+0, z+7, b, ms);
		world.setBlock(x+6, y+0, z+8, b, ms);
		world.setBlock(x+6, y+0, z+9, b, ms);
		world.setBlock(x+6, y+0, z+10, b, ms);
		world.setBlock(x+6, y+0, z+11, b, ms);
		world.setBlock(x+6, y+0, z+12, b, ms);
		world.setBlock(x+6, y+0, z+13, b, ms);
		world.setBlock(x+6, y+0, z+14, b, ms);
		world.setBlock(x+6, y+0, z+15, b, ms);
		world.setBlock(x+6, y+0, z+16, b, ms);
		world.setBlock(x+6, y+0, z+17, b, ms);
		world.setBlock(x+6, y+0, z+18, b, ms);
		world.setBlock(x+6, y+0, z+19, b, ms);
		world.setBlock(x+6, y+0, z+20, b, ms);
		world.setBlock(x+6, y+0, z+21, b, ms);
		world.setBlock(x+6, y+0, z+22, b, ms);
		world.setBlock(x+6, y+0, z+23, b, ms);
		world.setBlock(x+6, y+0, z+24, b, ms);
		world.setBlock(x+6, y+0, z+25, b, ms);
		world.setBlock(x+6, y+0, z+26, b, ms);
		world.setBlock(x+6, y+0, z+27, b, ms);
		world.setBlock(x+6, y+0, z+28, b, ms);
		world.setBlock(x+6, y+0, z+29, b, ms);
		world.setBlock(x+6, y+0, z+30, b, ms);
		world.setBlock(x+6, y+0, z+31, b, ms);
		world.setBlock(x+6, y+0, z+32, b, ms);
		world.setBlock(x+6, y+0, z+33, b, ms);
		world.setBlock(x+6, y+0, z+34, b, ms);
		world.setBlock(x+6, y+0, z+35, b, ms);
		world.setBlock(x+6, y+0, z+36, b, ms);
		world.setBlock(x+6, y+0, z+37, b, ms);
		world.setBlock(x+6, y+0, z+38, b, ms);
		world.setBlock(x+6, y+0, z+39, b, ms);
		this.generateRune(x+6, y+0, z+40, LockColor.GREEN);
		world.setBlock(x+6, y+0, z+41, b, ms);
		world.setBlock(x+6, y+0, z+42, b, ms);
		world.setBlock(x+6, y+0, z+43, b, ms);
		world.setBlock(x+6, y+0, z+44, b, ms);
		world.setBlock(x+6, y+0, z+45, b, ms);
		world.setBlock(x+6, y+0, z+46, b, ms);
		world.setBlock(x+6, y+0, z+47, b, ms);
		world.setBlock(x+6, y+0, z+48, b, ms);
		world.setBlock(x+6, y+0, z+49, b, ms);
		world.setBlock(x+6, y+0, z+50, b, ms);
		world.setBlock(x+6, y+0, z+51, b, ms);
		world.setBlock(x+6, y+0, z+52, b, ms);
		world.setBlock(x+6, y+0, z+53, b, ms);
		this.generateLock(x+6, y+1, z+10, LockColor.RED);
		world.setBlock(x+6, y+1, z+18, b, ms);
		world.setBlock(x+6, y+1, z+19, b, ms);
		world.setBlock(x+6, y+1, z+20, b, ms);
		world.setBlock(x+6, y+1, z+21, b, ms);
		world.setBlock(x+6, y+1, z+22, b, ms);
		world.setBlock(x+6, y+1, z+27, b, ms);
		world.setBlock(x+6, y+1, z+28, b, ms);
		world.setBlock(x+6, y+1, z+29, b, ms);
		world.setBlock(x+6, y+1, z+30, b, ms);
		world.setBlock(x+6, y+1, z+34, b, ms);
		world.setBlock(x+6, y+1, z+35, b, ms);
		world.setBlock(x+6, y+1, z+36, b, ms);
		world.setBlock(x+6, y+1, z+41, b, ms);
		world.setBlock(x+6, y+1, z+42, b, ms);
		world.setBlock(x+6, y+1, z+43, b, ms);
		this.generateGate(x+6, y+1, z+52);
		this.generateLock(x+6, y+2, z+10, LockColor.RED);
		world.setBlock(x+6, y+2, z+18, b, ml);
		world.setBlock(x+6, y+2, z+19, b, ms);
		world.setBlock(x+6, y+2, z+20, b, ms);
		world.setBlock(x+6, y+2, z+21, b, ml);
		world.setBlock(x+6, y+2, z+22, b, ms);
		world.setBlock(x+6, y+2, z+27, b, ms);
		world.setBlock(x+6, y+2, z+28, b, ms);
		world.setBlock(x+6, y+2, z+29, b, ms);
		world.setBlock(x+6, y+2, z+30, b, ms);
		world.setBlock(x+6, y+2, z+34, b, ms);
		world.setBlock(x+6, y+2, z+35, b, ms);
		world.setBlock(x+6, y+2, z+36, b, ms);
		world.setBlock(x+6, y+2, z+41, b, ms);
		world.setBlock(x+6, y+2, z+42, b, ms);
		world.setBlock(x+6, y+2, z+43, b, ml);
		this.generateGate(x+6, y+2, z+52);
		this.generateLock(x+6, y+3, z+10, LockColor.RED);
		world.setBlock(x+6, y+3, z+18, b, ms);
		world.setBlock(x+6, y+3, z+19, b, ms);
		world.setBlock(x+6, y+3, z+20, b, ms);
		world.setBlock(x+6, y+3, z+21, b, ms);
		world.setBlock(x+6, y+3, z+22, b, ms);
		world.setBlock(x+6, y+3, z+27, b, ms);
		world.setBlock(x+6, y+3, z+28, b, ms);
		world.setBlock(x+6, y+3, z+29, b, ms);
		world.setBlock(x+6, y+3, z+30, b, ms);
		world.setBlock(x+6, y+3, z+34, b, ms);
		world.setBlock(x+6, y+3, z+35, b, ms);
		world.setBlock(x+6, y+3, z+36, b, ms);
		world.setBlock(x+6, y+3, z+41, b, ms);
		world.setBlock(x+6, y+3, z+42, b, ms);
		world.setBlock(x+6, y+3, z+43, b, ms);
		this.generateGate(x+6, y+3, z+52);
		world.setBlock(x+6, y+4, z+0, b, ms);
		world.setBlock(x+6, y+4, z+9, b, ml);
		world.setBlock(x+6, y+4, z+10, b, ms);
		world.setBlock(x+6, y+4, z+11, b, ml);
		world.setBlock(x+6, y+4, z+18, b, ms);
		world.setBlock(x+6, y+4, z+19, b, ms);
		world.setBlock(x+6, y+4, z+20, b, ms);
		world.setBlock(x+6, y+4, z+21, b, ms);
		world.setBlock(x+6, y+4, z+22, b, ms);
		world.setBlock(x+6, y+4, z+27, b, ms);
		world.setBlock(x+6, y+4, z+30, b, ms);
		world.setBlock(x+6, y+4, z+31, b, ms);
		world.setBlock(x+6, y+4, z+32, b, ms);
		world.setBlock(x+6, y+4, z+33, b, ms);
		world.setBlock(x+6, y+4, z+34, b, ms);
		world.setBlock(x+6, y+4, z+35, b, ms);
		world.setBlock(x+6, y+4, z+36, b, ms);
		world.setBlock(x+6, y+4, z+41, b, ms);
		world.setBlock(x+6, y+4, z+43, b, ms);
		world.setBlock(x+6, y+4, z+51, b, ms);
		world.setBlock(x+6, y+4, z+52, b, ms);
		world.setBlock(x+6, y+4, z+53, b, ms);
		world.setBlock(x+6, y+5, z+1, b, ms);
		world.setBlock(x+6, y+5, z+2, b, ms);
		world.setBlock(x+6, y+5, z+3, b, ms);
		world.setBlock(x+6, y+5, z+4, b, ms);
		this.generateRune(x+6, y+5, z+5, LockColor.RED);
		world.setBlock(x+6, y+5, z+6, b, ms);
		world.setBlock(x+6, y+5, z+7, b, ms);
		world.setBlock(x+6, y+5, z+8, b, ms);
		world.setBlock(x+6, y+5, z+9, b, ms);
		world.setBlock(x+6, y+5, z+11, b, ms);
		world.setBlock(x+6, y+5, z+12, b, ms);
		world.setBlock(x+6, y+5, z+13, b, ms);
		world.setBlock(x+6, y+5, z+14, b, ms);
		world.setBlock(x+6, y+5, z+15, b, ms);
		world.setBlock(x+6, y+5, z+16, b, ms);
		world.setBlock(x+6, y+5, z+17, b, ms);
		world.setBlock(x+6, y+5, z+18, b, ms);
		world.setBlock(x+6, y+5, z+20, b, ms);
		world.setBlock(x+6, y+5, z+21, b, ms);
		world.setBlock(x+6, y+5, z+22, b, ms);
		world.setBlock(x+6, y+5, z+23, b, ms);
		world.setBlock(x+6, y+5, z+24, b, ms);
		world.setBlock(x+6, y+5, z+25, b, ms);
		world.setBlock(x+6, y+5, z+26, b, ms);
		world.setBlock(x+6, y+5, z+27, b, ms);
		world.setBlock(x+6, y+5, z+34, b, ms);
		world.setBlock(x+6, y+5, z+35, b, ms);
		world.setBlock(x+6, y+5, z+36, b, ms);
		world.setBlock(x+6, y+5, z+37, b, ms);
		world.setBlock(x+6, y+5, z+38, b, ms);
		world.setBlock(x+6, y+5, z+39, b, ms);
		world.setBlock(x+6, y+5, z+40, b, ms);
		world.setBlock(x+6, y+5, z+41, b, ms);
		world.setBlock(x+6, y+5, z+43, b, ms);
		world.setBlock(x+6, y+5, z+44, b, ms);
		world.setBlock(x+6, y+5, z+45, b, ms);
		world.setBlock(x+6, y+5, z+46, b, ms);
		world.setBlock(x+6, y+5, z+47, b, ms);
		world.setBlock(x+6, y+5, z+48, b, ms);
		world.setBlock(x+6, y+5, z+49, b, ms);
		world.setBlock(x+6, y+5, z+50, b, ms);
		world.setBlock(x+6, y+5, z+51, b, ms);
		world.setBlock(x+7, y+0, z+0, b, ms);
		world.setBlock(x+7, y+0, z+1, b, ms);
		world.setBlock(x+7, y+0, z+2, b, ms);
		world.setBlock(x+7, y+0, z+3, b, ms);
		world.setBlock(x+7, y+0, z+4, b, ms);
		world.setBlock(x+7, y+0, z+5, b, ms);
		world.setBlock(x+7, y+0, z+6, b, ms);
		world.setBlock(x+7, y+0, z+7, b, ms);
		world.setBlock(x+7, y+0, z+8, b, ms);
		world.setBlock(x+7, y+0, z+9, b, ms);
		world.setBlock(x+7, y+0, z+10, b, ms);
		world.setBlock(x+7, y+0, z+11, b, ms);
		world.setBlock(x+7, y+0, z+12, b, ms);
		world.setBlock(x+7, y+0, z+13, b, ms);
		world.setBlock(x+7, y+0, z+14, b, ms);
		world.setBlock(x+7, y+0, z+15, b, ms);
		world.setBlock(x+7, y+0, z+16, b, ms);
		world.setBlock(x+7, y+0, z+17, b, ms);
		world.setBlock(x+7, y+0, z+18, b, ms);
		world.setBlock(x+7, y+0, z+19, b, ms);
		world.setBlock(x+7, y+0, z+20, b, ms);
		world.setBlock(x+7, y+0, z+21, b, ms);
		world.setBlock(x+7, y+0, z+22, b, ms);
		world.setBlock(x+7, y+0, z+23, b, ms);
		world.setBlock(x+7, y+0, z+24, b, ms);
		world.setBlock(x+7, y+0, z+25, b, ms);
		world.setBlock(x+7, y+0, z+26, b, ms);
		world.setBlock(x+7, y+0, z+27, b, ms);
		world.setBlock(x+7, y+0, z+28, b, ms);
		world.setBlock(x+7, y+0, z+29, b, ms);
		world.setBlock(x+7, y+0, z+30, b, ms);
		world.setBlock(x+7, y+0, z+31, b, ms);
		world.setBlock(x+7, y+0, z+32, b, ms);
		world.setBlock(x+7, y+0, z+33, b, ms);
		world.setBlock(x+7, y+0, z+34, b, ms);
		world.setBlock(x+7, y+0, z+35, b, ms);
		world.setBlock(x+7, y+0, z+36, b, ms);
		world.setBlock(x+7, y+0, z+37, b, ms);
		world.setBlock(x+7, y+0, z+38, b, ms);
		world.setBlock(x+7, y+0, z+39, b, ms);
		world.setBlock(x+7, y+0, z+40, b, ms);
		world.setBlock(x+7, y+0, z+41, b, ms);
		world.setBlock(x+7, y+0, z+42, b, ms);
		world.setBlock(x+7, y+0, z+43, b, ms);
		world.setBlock(x+7, y+0, z+44, b, ms);
		world.setBlock(x+7, y+0, z+45, b, ms);
		world.setBlock(x+7, y+0, z+46, b, ms);
		world.setBlock(x+7, y+0, z+47, b, ms);
		world.setBlock(x+7, y+0, z+48, b, ms);
		world.setBlock(x+7, y+0, z+49, b, ms);
		world.setBlock(x+7, y+0, z+50, b, ms);
		world.setBlock(x+7, y+0, z+51, b, ms);
		world.setBlock(x+7, y+0, z+52, b, ms);
		world.setBlock(x+7, y+0, z+53, b, ms);
		this.generateLock(x+7, y+1, z+10, LockColor.RED);
		this.generateLock(x+7, y+1, z+19, LockColor.PURPLE);
		this.generateKey(x+7, y+1, z+25);
		world.setBlock(x+7, y+1, z+27, b, ms);
		world.setBlock(x+7, y+1, z+28, b, ms);
		world.setBlock(x+7, y+1, z+29, b, ms);
		world.setBlock(x+7, y+1, z+30, b, ms);
		world.setBlock(x+7, y+1, z+31, b, ms);
		world.setBlock(x+7, y+1, z+33, b, ms);
		world.setBlock(x+7, y+1, z+34, b, ms);
		world.setBlock(x+7, y+1, z+35, b, ms);
		world.setBlock(x+7, y+1, z+41, b, ms);
		world.setBlock(x+7, y+1, z+42, b, ms);
		world.setBlock(x+7, y+1, z+43, b, ms);
		world.setBlock(x+7, y+1, z+51, b, ms);
		world.setBlock(x+7, y+1, z+52, b, ms);
		world.setBlock(x+7, y+1, z+53, b, ms);
		this.generateLock(x+7, y+2, z+10, LockColor.RED);
		this.generateLock(x+7, y+2, z+19, LockColor.PURPLE);
		world.setBlock(x+7, y+2, z+27, b, ml);
		world.setBlock(x+7, y+2, z+28, b, ms);
		world.setBlock(x+7, y+2, z+29, b, ms);
		world.setBlock(x+7, y+2, z+30, b, ms);
		world.setBlock(x+7, y+2, z+31, b, ms);
		world.setBlock(x+7, y+2, z+33, b, ms);
		world.setBlock(x+7, y+2, z+34, b, ms);
		world.setBlock(x+7, y+2, z+35, b, ms);
		world.setBlock(x+7, y+2, z+41, b, ms);
		world.setBlock(x+7, y+2, z+42, b, ms);
		world.setBlock(x+7, y+2, z+43, b, ms);
		world.setBlock(x+7, y+2, z+51, b, ms);
		world.setBlock(x+7, y+2, z+52, b, ms);
		world.setBlock(x+7, y+2, z+53, b, ms);
		this.generateLock(x+7, y+3, z+10, LockColor.RED);
		this.generateLock(x+7, y+3, z+19, LockColor.PURPLE);
		world.setBlock(x+7, y+3, z+27, b, ms);
		world.setBlock(x+7, y+3, z+28, b, ms);
		world.setBlock(x+7, y+3, z+29, b, ms);
		world.setBlock(x+7, y+3, z+30, b, ms);
		world.setBlock(x+7, y+3, z+31, b, ms);
		world.setBlock(x+7, y+3, z+32, b, ms);
		world.setBlock(x+7, y+3, z+33, b, ms);
		world.setBlock(x+7, y+3, z+34, b, ms);
		world.setBlock(x+7, y+3, z+35, b, ms);
		world.setBlock(x+7, y+3, z+41, b, ms);
		world.setBlock(x+7, y+3, z+42, b, ms);
		world.setBlock(x+7, y+3, z+43, b, ms);
		world.setBlock(x+7, y+3, z+51, b, ms);
		world.setBlock(x+7, y+3, z+52, b, ms);
		world.setBlock(x+7, y+3, z+53, b, ms);
		world.setBlock(x+7, y+4, z+0, b, ms);
		world.setBlock(x+7, y+4, z+9, b, ms);
		world.setBlock(x+7, y+4, z+10, b, ms);
		world.setBlock(x+7, y+4, z+11, b, ms);
		world.setBlock(x+7, y+4, z+18, b, ms);
		world.setBlock(x+7, y+4, z+19, b, ms);
		world.setBlock(x+7, y+4, z+20, b, ms);
		world.setBlock(x+7, y+4, z+27, b, ms);
		world.setBlock(x+7, y+4, z+28, b, ms);
		world.setBlock(x+7, y+4, z+29, b, ms);
		world.setBlock(x+7, y+4, z+30, b, ms);
		world.setBlock(x+7, y+4, z+31, b, ms);
		world.setBlock(x+7, y+4, z+32, b, ms);
		world.setBlock(x+7, y+4, z+33, b, ms);
		world.setBlock(x+7, y+4, z+34, b, ms);
		world.setBlock(x+7, y+4, z+35, b, ms);
		world.setBlock(x+7, y+4, z+41, b, ms);
		world.setBlock(x+7, y+4, z+42, b, ms);
		world.setBlock(x+7, y+4, z+43, b, ms);
		world.setBlock(x+7, y+4, z+51, b, ms);
		world.setBlock(x+7, y+4, z+52, b, ms);
		world.setBlock(x+7, y+4, z+53, b, ms);
		world.setBlock(x+7, y+5, z+1, b, ms);
		world.setBlock(x+7, y+5, z+2, b, ms);
		world.setBlock(x+7, y+5, z+3, b, ms);
		world.setBlock(x+7, y+5, z+4, b, ms);
		world.setBlock(x+7, y+5, z+5, b, ms);
		world.setBlock(x+7, y+5, z+6, b, ms);
		world.setBlock(x+7, y+5, z+7, b, ms);
		world.setBlock(x+7, y+5, z+8, b, ms);
		world.setBlock(x+7, y+5, z+9, b, ms);
		world.setBlock(x+7, y+5, z+11, b, ms);
		world.setBlock(x+7, y+5, z+12, b, ms);
		world.setBlock(x+7, y+5, z+13, b, ms);
		world.setBlock(x+7, y+5, z+14, b, ms);
		world.setBlock(x+7, y+5, z+15, b, ms);
		world.setBlock(x+7, y+5, z+16, b, ms);
		world.setBlock(x+7, y+5, z+17, b, ms);
		world.setBlock(x+7, y+5, z+18, b, ms);
		world.setBlock(x+7, y+5, z+20, b, ms);
		world.setBlock(x+7, y+5, z+21, b, ms);
		world.setBlock(x+7, y+5, z+22, b, ms);
		world.setBlock(x+7, y+5, z+23, b, ms);
		world.setBlock(x+7, y+5, z+24, b, ms);
		world.setBlock(x+7, y+5, z+25, b, ms);
		world.setBlock(x+7, y+5, z+26, b, ms);
		world.setBlock(x+7, y+5, z+27, b, ms);
		world.setBlock(x+7, y+5, z+34, b, ms);
		world.setBlock(x+7, y+5, z+35, b, ms);
		world.setBlock(x+7, y+5, z+36, b, ms);
		world.setBlock(x+7, y+5, z+37, b, ms);
		world.setBlock(x+7, y+5, z+38, b, ms);
		world.setBlock(x+7, y+5, z+39, b, ms);
		world.setBlock(x+7, y+5, z+40, b, ms);
		world.setBlock(x+7, y+5, z+41, b, ms);
		world.setBlock(x+7, y+5, z+43, b, ms);
		world.setBlock(x+7, y+5, z+44, b, ms);
		world.setBlock(x+7, y+5, z+45, b, ms);
		world.setBlock(x+7, y+5, z+46, b, ms);
		world.setBlock(x+7, y+5, z+47, b, ms);
		world.setBlock(x+7, y+5, z+48, b, ms);
		world.setBlock(x+7, y+5, z+49, b, ms);
		world.setBlock(x+7, y+5, z+50, b, ms);
		world.setBlock(x+7, y+5, z+51, b, ms);
		world.setBlock(x+8, y+0, z+0, b, ms);
		world.setBlock(x+8, y+0, z+1, b, ms);
		world.setBlock(x+8, y+0, z+2, b, ms);
		world.setBlock(x+8, y+0, z+3, b, ms);
		world.setBlock(x+8, y+0, z+4, b, ms);
		world.setBlock(x+8, y+0, z+5, b, ms);
		world.setBlock(x+8, y+0, z+6, b, ms);
		world.setBlock(x+8, y+0, z+7, b, ms);
		world.setBlock(x+8, y+0, z+8, b, ms);
		world.setBlock(x+8, y+0, z+9, b, ms);
		world.setBlock(x+8, y+0, z+10, b, ms);
		world.setBlock(x+8, y+0, z+11, b, ms);
		world.setBlock(x+8, y+0, z+12, b, ms);
		world.setBlock(x+8, y+0, z+13, b, ms);
		world.setBlock(x+8, y+0, z+14, b, ms);
		world.setBlock(x+8, y+0, z+15, b, ml);
		world.setBlock(x+8, y+0, z+16, b, ms);
		world.setBlock(x+8, y+0, z+17, b, ms);
		world.setBlock(x+8, y+0, z+18, b, ms);
		world.setBlock(x+8, y+0, z+19, b, ms);
		world.setBlock(x+8, y+0, z+20, b, ms);
		world.setBlock(x+8, y+0, z+21, b, ms);
		world.setBlock(x+8, y+0, z+22, b, ms);
		world.setBlock(x+8, y+0, z+23, b, ms);
		world.setBlock(x+8, y+0, z+24, b, ms);
		world.setBlock(x+8, y+0, z+25, b, ms);
		world.setBlock(x+8, y+0, z+26, b, ms);
		world.setBlock(x+8, y+0, z+27, b, ms);
		world.setBlock(x+8, y+0, z+28, b, ms);
		world.setBlock(x+8, y+0, z+29, b, ms);
		world.setBlock(x+8, y+0, z+30, b, ms);
		world.setBlock(x+8, y+0, z+31, b, ms);
		world.setBlock(x+8, y+0, z+32, b, ms);
		world.setBlock(x+8, y+0, z+33, b, ms);
		world.setBlock(x+8, y+0, z+34, b, ms);
		world.setBlock(x+8, y+0, z+35, b, ms);
		world.setBlock(x+8, y+0, z+36, b, ms);
		world.setBlock(x+8, y+0, z+37, b, ms);
		world.setBlock(x+8, y+0, z+38, b, ms);
		world.setBlock(x+8, y+0, z+39, b, ms);
		world.setBlock(x+8, y+0, z+40, b, ms);
		world.setBlock(x+8, y+0, z+41, b, ms);
		world.setBlock(x+8, y+0, z+42, b, ms);
		world.setBlock(x+8, y+0, z+43, b, ms);
		world.setBlock(x+8, y+0, z+44, b, ms);
		world.setBlock(x+8, y+0, z+45, b, ms);
		world.setBlock(x+8, y+0, z+46, b, ms);
		world.setBlock(x+8, y+0, z+47, b, ms);
		world.setBlock(x+8, y+0, z+48, b, ms);
		world.setBlock(x+8, y+0, z+49, b, ms);
		world.setBlock(x+8, y+0, z+50, b, ms);
		world.setBlock(x+8, y+0, z+51, b, ms);
		world.setBlock(x+8, y+1, z+0, b, ms);
		this.generateKey(x+8, y+1, z+5);
		world.setBlock(x+8, y+1, z+9, b, ms);
		world.setBlock(x+8, y+1, z+10, b, ms);
		world.setBlock(x+8, y+1, z+11, b, ms);
		this.generateLock(x+8, y+1, z+19, LockColor.PURPLE);
		this.generateLock(x+8, y+1, z+28, LockColor.BLUE);
		this.generateLock(x+8, y+1, z+30, LockColor.GREEN);
		this.generateLock(x+8, y+1, z+34, LockColor.RED);
		this.generateLock(x+8, y+1, z+42, LockColor.PURPLE);
		world.setBlock(x+8, y+1, z+51, b, ms);
		world.setBlock(x+8, y+2, z+0, b, ms);
		world.setBlock(x+8, y+2, z+9, b, ms);
		world.setBlock(x+8, y+2, z+10, b, ms);
		world.setBlock(x+8, y+2, z+11, b, ms);
		this.generateLock(x+8, y+2, z+19, LockColor.PURPLE);
		this.generateLock(x+8, y+2, z+28, LockColor.BLUE);
		this.generateLock(x+8, y+2, z+30, LockColor.GREEN);
		this.generateLock(x+8, y+2, z+34, LockColor.RED);
		this.generateLock(x+8, y+2, z+42, LockColor.PURPLE);
		world.setBlock(x+8, y+2, z+51, b, ms);
		world.setBlock(x+8, y+3, z+0, b, ms);
		world.setBlock(x+8, y+3, z+9, b, ms);
		world.setBlock(x+8, y+3, z+10, b, ms);
		world.setBlock(x+8, y+3, z+11, b, ms);
		this.generateLock(x+8, y+3, z+19, LockColor.PURPLE);
		this.generateLock(x+8, y+3, z+28, LockColor.BLUE);
		this.generateLock(x+8, y+3, z+30, LockColor.GREEN);
		this.generateLock(x+8, y+3, z+34, LockColor.RED);
		this.generateLock(x+8, y+3, z+42, LockColor.PURPLE);
		world.setBlock(x+8, y+3, z+51, b, ms);
		world.setBlock(x+8, y+4, z+0, b, ms);
		world.setBlock(x+8, y+4, z+9, b, ms);
		world.setBlock(x+8, y+4, z+10, b, ms);
		world.setBlock(x+8, y+4, z+11, b, ms);
		world.setBlock(x+8, y+4, z+18, b, ms);
		world.setBlock(x+8, y+4, z+19, b, ms);
		world.setBlock(x+8, y+4, z+20, b, ms);
		world.setBlock(x+8, y+4, z+27, b, ms);
		world.setBlock(x+8, y+4, z+28, b, ms);
		world.setBlock(x+8, y+4, z+29, b, ms);
		world.setBlock(x+8, y+4, z+30, b, ms);
		world.setBlock(x+8, y+4, z+31, b, ms);
		world.setBlock(x+8, y+4, z+32, b, ms);
		world.setBlock(x+8, y+4, z+33, b, ms);
		world.setBlock(x+8, y+4, z+34, b, ms);
		world.setBlock(x+8, y+4, z+35, b, ms);
		world.setBlock(x+8, y+4, z+41, b, ms);
		world.setBlock(x+8, y+4, z+42, b, ms);
		world.setBlock(x+8, y+4, z+43, b, ms);
		world.setBlock(x+8, y+4, z+51, b, ms);
		world.setBlock(x+8, y+5, z+1, b, ms);
		world.setBlock(x+8, y+5, z+2, b, ms);
		world.setBlock(x+8, y+5, z+3, b, ms);
		world.setBlock(x+8, y+5, z+4, b, ms);
		world.setBlock(x+8, y+5, z+5, b, ms);
		world.setBlock(x+8, y+5, z+6, b, ms);
		world.setBlock(x+8, y+5, z+7, b, ms);
		world.setBlock(x+8, y+5, z+8, b, ms);
		world.setBlock(x+8, y+5, z+9, b, ms);
		world.setBlock(x+8, y+5, z+11, b, ms);
		world.setBlock(x+8, y+5, z+12, b, ms);
		world.setBlock(x+8, y+5, z+13, b, ms);
		world.setBlock(x+8, y+5, z+14, b, ms);
		world.setBlock(x+8, y+5, z+15, b, ms);
		world.setBlock(x+8, y+5, z+16, b, ms);
		world.setBlock(x+8, y+5, z+17, b, ms);
		world.setBlock(x+8, y+5, z+18, b, ms);
		world.setBlock(x+8, y+5, z+20, b, ms);
		world.setBlock(x+8, y+5, z+21, b, ms);
		world.setBlock(x+8, y+5, z+22, b, ms);
		world.setBlock(x+8, y+5, z+23, b, ms);
		world.setBlock(x+8, y+5, z+24, b, ms);
		world.setBlock(x+8, y+5, z+25, b, ms);
		world.setBlock(x+8, y+5, z+26, b, ms);
		world.setBlock(x+8, y+5, z+27, b, ms);
		world.setBlock(x+8, y+5, z+35, b, ms);
		world.setBlock(x+8, y+5, z+36, b, ms);
		world.setBlock(x+8, y+5, z+37, b, ms);
		world.setBlock(x+8, y+5, z+38, b, ms);
		world.setBlock(x+8, y+5, z+39, b, ms);
		world.setBlock(x+8, y+5, z+40, b, ms);
		world.setBlock(x+8, y+5, z+41, b, ms);
		world.setBlock(x+8, y+5, z+43, b, ms);
		world.setBlock(x+8, y+5, z+44, b, ms);
		world.setBlock(x+8, y+5, z+45, b, ms);
		world.setBlock(x+8, y+5, z+46, b, ms);
		world.setBlock(x+8, y+5, z+47, b, ms);
		world.setBlock(x+8, y+5, z+48, b, ms);
		world.setBlock(x+8, y+5, z+49, b, ms);
		world.setBlock(x+8, y+5, z+50, b, ms);
		world.setBlock(x+8, y+5, z+51, b, ms);
		world.setBlock(x+9, y+0, z+1, b, ms);
		world.setBlock(x+9, y+0, z+2, b, ms);
		world.setBlock(x+9, y+0, z+3, b, ms);
		world.setBlock(x+9, y+0, z+4, b, ms);
		world.setBlock(x+9, y+0, z+5, b, ms);
		world.setBlock(x+9, y+0, z+6, b, ms);
		world.setBlock(x+9, y+0, z+7, b, ms);
		world.setBlock(x+9, y+0, z+8, b, ms);
		world.setBlock(x+9, y+0, z+9, b, ms);
		world.setBlock(x+9, y+0, z+11, b, ms);
		world.setBlock(x+9, y+0, z+12, b, ms);
		world.setBlock(x+9, y+0, z+13, b, ms);
		world.setBlock(x+9, y+0, z+14, b, ms);
		world.setBlock(x+9, y+0, z+15, b, ms);
		world.setBlock(x+9, y+0, z+16, b, ms);
		world.setBlock(x+9, y+0, z+17, b, ms);
		world.setBlock(x+9, y+0, z+18, b, ms);
		world.setBlock(x+9, y+0, z+19, b, ms);
		world.setBlock(x+9, y+0, z+20, b, ms);
		world.setBlock(x+9, y+0, z+21, b, ms);
		world.setBlock(x+9, y+0, z+22, b, ms);
		world.setBlock(x+9, y+0, z+23, b, ms);
		world.setBlock(x+9, y+0, z+24, b, ms);
		world.setBlock(x+9, y+0, z+25, b, ml);
		world.setBlock(x+9, y+0, z+26, b, ms);
		world.setBlock(x+9, y+0, z+27, b, ms);
		world.setBlock(x+9, y+0, z+28, b, ms);
		world.setBlock(x+9, y+0, z+29, b, ml);
		world.setBlock(x+9, y+0, z+30, b, ms);
		world.setBlock(x+9, y+0, z+31, b, ms);
		world.setBlock(x+9, y+0, z+32, b, ml);
		world.setBlock(x+9, y+0, z+33, b, ms);
		world.setBlock(x+9, y+0, z+34, b, ms);
		world.setBlock(x+9, y+0, z+35, b, ms);
		world.setBlock(x+9, y+0, z+36, b, ms);
		world.setBlock(x+9, y+0, z+37, b, ms);
		world.setBlock(x+9, y+0, z+38, b, ms);
		world.setBlock(x+9, y+0, z+39, b, ms);
		world.setBlock(x+9, y+0, z+40, b, ms);
		world.setBlock(x+9, y+0, z+41, b, ms);
		world.setBlock(x+9, y+0, z+42, b, ms);
		world.setBlock(x+9, y+0, z+43, b, ms);
		world.setBlock(x+9, y+0, z+44, b, ms);
		world.setBlock(x+9, y+0, z+45, b, ms);
		world.setBlock(x+9, y+0, z+46, b, ms);
		world.setBlock(x+9, y+0, z+47, b, ms);
		world.setBlock(x+9, y+0, z+48, b, ms);
		world.setBlock(x+9, y+0, z+49, b, ms);
		world.setBlock(x+9, y+0, z+50, b, ms);
		world.setBlock(x+9, y+1, z+1, b, ms);
		world.setBlock(x+9, y+1, z+9, b, ms);
		world.setBlock(x+9, y+1, z+11, b, ms);
		this.generateLock(x+9, y+1, z+19, LockColor.PURPLE);
		this.generateLock(x+9, y+1, z+28, LockColor.BLUE);
		this.generateLock(x+9, y+1, z+30, LockColor.GREEN);
		this.generateLock(x+9, y+1, z+34, LockColor.RED);
		this.generateLock(x+9, y+1, z+42, LockColor.PURPLE);
		world.setBlock(x+9, y+1, z+50, b, ms);
		world.setBlock(x+9, y+2, z+1, b, ms);
		world.setBlock(x+9, y+2, z+9, b, ms);
		world.setBlock(x+9, y+2, z+11, b, ms);
		this.generateLock(x+9, y+2, z+19, LockColor.PURPLE);
		this.generateLock(x+9, y+2, z+28, LockColor.BLUE);
		this.generateLock(x+9, y+2, z+30, LockColor.GREEN);
		this.generateLock(x+9, y+2, z+34, LockColor.RED);
		this.generateLock(x+9, y+2, z+42, LockColor.PURPLE);
		world.setBlock(x+9, y+2, z+50, b, ms);
		world.setBlock(x+9, y+3, z+1, b, ms);
		world.setBlock(x+9, y+3, z+9, b, ms);
		world.setBlock(x+9, y+3, z+11, b, ms);
		this.generateLock(x+9, y+3, z+19, LockColor.PURPLE);
		this.generateLock(x+9, y+3, z+28, LockColor.BLUE);
		this.generateLock(x+9, y+3, z+30, LockColor.GREEN);
		this.generateLock(x+9, y+3, z+34, LockColor.RED);
		this.generateLock(x+9, y+3, z+42, LockColor.PURPLE);
		world.setBlock(x+9, y+3, z+50, b, ms);
		world.setBlock(x+9, y+4, z+1, b, ms);
		world.setBlock(x+9, y+4, z+9, b, ms);
		world.setBlock(x+9, y+4, z+11, b, ms);
		world.setBlock(x+9, y+4, z+18, b, ms);
		world.setBlock(x+9, y+4, z+19, b, ms);
		world.setBlock(x+9, y+4, z+20, b, ms);
		world.setBlock(x+9, y+4, z+27, b, ms);
		world.setBlock(x+9, y+4, z+28, b, ms);
		world.setBlock(x+9, y+4, z+29, b, ms);
		world.setBlock(x+9, y+4, z+30, b, ms);
		world.setBlock(x+9, y+4, z+31, b, ms);
		world.setBlock(x+9, y+4, z+32, b, ms);
		world.setBlock(x+9, y+4, z+33, b, ms);
		world.setBlock(x+9, y+4, z+34, b, ms);
		world.setBlock(x+9, y+4, z+35, b, ml);
		world.setBlock(x+9, y+4, z+41, b, ml);
		world.setBlock(x+9, y+4, z+42, b, ms);
		world.setBlock(x+9, y+4, z+43, b, ms);
		world.setBlock(x+9, y+4, z+50, b, ms);
		world.setBlock(x+9, y+5, z+1, b, ms);
		world.setBlock(x+9, y+5, z+2, b, ms);
		world.setBlock(x+9, y+5, z+3, b, ms);
		world.setBlock(x+9, y+5, z+4, b, ms);
		world.setBlock(x+9, y+5, z+5, b, ms);
		world.setBlock(x+9, y+5, z+6, b, ms);
		world.setBlock(x+9, y+5, z+7, b, ms);
		world.setBlock(x+9, y+5, z+8, b, ms);
		world.setBlock(x+9, y+5, z+9, b, ms);
		world.setBlock(x+9, y+5, z+11, b, ms);
		world.setBlock(x+9, y+5, z+12, b, ms);
		world.setBlock(x+9, y+5, z+13, b, ms);
		world.setBlock(x+9, y+5, z+14, b, ms);
		world.setBlock(x+9, y+5, z+15, b, ms);
		world.setBlock(x+9, y+5, z+16, b, ms);
		world.setBlock(x+9, y+5, z+17, b, ms);
		world.setBlock(x+9, y+5, z+18, b, ms);
		world.setBlock(x+9, y+5, z+20, b, ms);
		world.setBlock(x+9, y+5, z+21, b, ms);
		world.setBlock(x+9, y+5, z+22, b, ms);
		world.setBlock(x+9, y+5, z+23, b, ms);
		world.setBlock(x+9, y+5, z+24, b, ms);
		world.setBlock(x+9, y+5, z+25, b, ms);
		world.setBlock(x+9, y+5, z+26, b, ms);
		world.setBlock(x+9, y+5, z+27, b, ms);
		world.setBlock(x+9, y+5, z+35, b, ms);
		world.setBlock(x+9, y+5, z+36, b, ms);
		world.setBlock(x+9, y+5, z+37, b, ms);
		world.setBlock(x+9, y+5, z+38, b, ms);
		world.setBlock(x+9, y+5, z+39, b, ms);
		world.setBlock(x+9, y+5, z+40, b, ms);
		world.setBlock(x+9, y+5, z+41, b, ms);
		world.setBlock(x+9, y+5, z+43, b, ms);
		world.setBlock(x+9, y+5, z+44, b, ms);
		world.setBlock(x+9, y+5, z+45, b, ms);
		world.setBlock(x+9, y+5, z+46, b, ms);
		world.setBlock(x+9, y+5, z+47, b, ms);
		world.setBlock(x+9, y+5, z+48, b, ms);
		world.setBlock(x+9, y+5, z+49, b, ms);
		world.setBlock(x+9, y+5, z+50, b, ms);
		world.setBlock(x+10, y+0, z+1, b, ms);
		world.setBlock(x+10, y+0, z+2, b, ms);
		world.setBlock(x+10, y+0, z+3, b, ms);
		world.setBlock(x+10, y+0, z+4, b, ms);
		world.setBlock(x+10, y+0, z+5, b, ms);
		world.setBlock(x+10, y+0, z+6, b, ms);
		world.setBlock(x+10, y+0, z+7, b, ms);
		world.setBlock(x+10, y+0, z+8, b, ms);
		world.setBlock(x+10, y+0, z+9, b, ms);
		world.setBlock(x+10, y+0, z+11, b, ms);
		world.setBlock(x+10, y+0, z+12, b, ms);
		world.setBlock(x+10, y+0, z+13, b, ms);
		world.setBlock(x+10, y+0, z+14, b, ms);
		world.setBlock(x+10, y+0, z+15, b, ms);
		world.setBlock(x+10, y+0, z+16, b, ms);
		world.setBlock(x+10, y+0, z+17, b, ms);
		world.setBlock(x+10, y+0, z+18, b, ms);
		world.setBlock(x+10, y+0, z+19, b, ms);
		world.setBlock(x+10, y+0, z+20, b, ms);
		world.setBlock(x+10, y+0, z+21, b, ms);
		world.setBlock(x+10, y+0, z+22, b, ms);
		world.setBlock(x+10, y+0, z+23, b, ms);
		world.setBlock(x+10, y+0, z+24, b, ms);
		world.setBlock(x+10, y+0, z+25, b, ms);
		world.setBlock(x+10, y+0, z+26, b, ms);
		world.setBlock(x+10, y+0, z+27, b, ms);
		world.setBlock(x+10, y+0, z+28, b, ms);
		world.setBlock(x+10, y+0, z+29, b, ms);
		world.setBlock(x+10, y+0, z+30, b, ms);
		world.setBlock(x+10, y+0, z+31, b, ms);
		world.setBlock(x+10, y+0, z+32, b, ms);
		world.setBlock(x+10, y+0, z+33, b, ms);
		world.setBlock(x+10, y+0, z+34, b, ms);
		world.setBlock(x+10, y+0, z+35, b, ms);
		world.setBlock(x+10, y+0, z+36, b, ms);
		world.setBlock(x+10, y+0, z+37, b, ms);
		world.setBlock(x+10, y+0, z+38, b, ml);
		world.setBlock(x+10, y+0, z+39, b, ms);
		world.setBlock(x+10, y+0, z+40, b, ms);
		world.setBlock(x+10, y+0, z+41, b, ms);
		world.setBlock(x+10, y+0, z+42, b, ms);
		world.setBlock(x+10, y+0, z+43, b, ms);
		world.setBlock(x+10, y+0, z+44, b, ms);
		world.setBlock(x+10, y+0, z+45, b, ms);
		world.setBlock(x+10, y+0, z+46, b, ms);
		world.setBlock(x+10, y+0, z+47, b, ms);
		world.setBlock(x+10, y+0, z+48, b, ms);
		world.setBlock(x+10, y+0, z+49, b, ms);
		world.setBlock(x+10, y+0, z+50, b, ms);
		world.setBlock(x+10, y+1, z+1, b, ms);
		world.setBlock(x+10, y+1, z+2, b, ms);
		world.setBlock(x+10, y+1, z+3, b, ms);
		world.setBlock(x+10, y+1, z+4, b, ms);
		world.setBlock(x+10, y+1, z+5, b, ms);
		world.setBlock(x+10, y+1, z+6, b, ms);
		world.setBlock(x+10, y+1, z+7, b, ms);
		world.setBlock(x+10, y+1, z+8, b, ms);
		world.setBlock(x+10, y+1, z+9, b, ms);
		world.setBlock(x+10, y+1, z+11, b, ms);
		world.setBlock(x+10, y+1, z+12, b, ms);
		world.setBlock(x+10, y+1, z+13, b, ms);
		world.setBlock(x+10, y+1, z+14, b, ms);
		world.setBlock(x+10, y+1, z+15, b, ms);
		world.setBlock(x+10, y+1, z+16, b, ms);
		world.setBlock(x+10, y+1, z+17, b, ms);
		world.setBlock(x+10, y+1, z+18, b, ms);
		world.setBlock(x+10, y+1, z+19, b, ms);
		world.setBlock(x+10, y+1, z+20, b, ms);
		this.generateLock(x+10, y+1, z+28, LockColor.BLUE);
		this.generateLock(x+10, y+1, z+30, LockColor.GREEN);
		this.generateLock(x+10, y+1, z+34, LockColor.RED);
		this.generateLock(x+10, y+1, z+42, LockColor.PURPLE);
		world.setBlock(x+10, y+1, z+47, b, ms);
		world.setBlock(x+10, y+1, z+48, b, ms);
	}

	private void generate2(OriginBlockCache world, int x, int y, int z, Block b, int ms, int ml, int mc) {
		world.setBlock(x+10, y+1, z+49, b, ms);
		world.setBlock(x+10, y+1, z+50, b, ms);
		world.setBlock(x+10, y+2, z+1, b, ms);
		world.setBlock(x+10, y+2, z+2, b, ms);
		world.setBlock(x+10, y+2, z+3, b, ml);
		world.setBlock(x+10, y+2, z+4, b, ms);
		world.setBlock(x+10, y+2, z+5, b, ms);
		world.setBlock(x+10, y+2, z+6, b, ms);
		world.setBlock(x+10, y+2, z+7, b, ms);
		world.setBlock(x+10, y+2, z+8, b, ms);
		world.setBlock(x+10, y+2, z+9, b, ms);
		world.setBlock(x+10, y+2, z+11, b, ms);
		world.setBlock(x+10, y+2, z+12, b, ms);
		world.setBlock(x+10, y+2, z+13, b, ms);
		world.setBlock(x+10, y+2, z+15, b, ms);
		world.setBlock(x+10, y+2, z+17, b, ms);
		world.setBlock(x+10, y+2, z+18, b, ms);
		world.setBlock(x+10, y+2, z+19, b, ms);
		world.setBlock(x+10, y+2, z+20, b, ms);
		this.generateLock(x+10, y+2, z+28, LockColor.BLUE);
		this.generateLock(x+10, y+2, z+30, LockColor.GREEN);
		this.generateLock(x+10, y+2, z+34, LockColor.RED);
		this.generateLock(x+10, y+2, z+42, LockColor.PURPLE);
		world.setBlock(x+10, y+2, z+47, b, ms);
		world.setBlock(x+10, y+2, z+49, b, ms);
		world.setBlock(x+10, y+2, z+50, b, ms);
		world.setBlock(x+10, y+3, z+1, b, ms);
		world.setBlock(x+10, y+3, z+2, b, ms);
		world.setBlock(x+10, y+3, z+3, b, ms);
		world.setBlock(x+10, y+3, z+4, b, ms);
		world.setBlock(x+10, y+3, z+5, b, ms);
		world.setBlock(x+10, y+3, z+6, b, ms);
		world.setBlock(x+10, y+3, z+7, b, ms);
		world.setBlock(x+10, y+3, z+8, b, ms);
		world.setBlock(x+10, y+3, z+9, b, ms);
		world.setBlock(x+10, y+3, z+11, b, ms);
		world.setBlock(x+10, y+3, z+12, b, ms);
		world.setBlock(x+10, y+3, z+13, b, ms);
		world.setBlock(x+10, y+3, z+14, b, ms);
		world.setBlock(x+10, y+3, z+15, b, ms);
		world.setBlock(x+10, y+3, z+16, b, ms);
		world.setBlock(x+10, y+3, z+17, b, ms);
		world.setBlock(x+10, y+3, z+18, b, ms);
		world.setBlock(x+10, y+3, z+19, b, ms);
		world.setBlock(x+10, y+3, z+20, b, ms);
		this.generateLock(x+10, y+3, z+28, LockColor.BLUE);
		this.generateLock(x+10, y+3, z+30, LockColor.GREEN);
		this.generateLock(x+10, y+3, z+34, LockColor.RED);
		this.generateLock(x+10, y+3, z+42, LockColor.PURPLE);
		world.setBlock(x+10, y+3, z+47, b, ms);
		world.setBlock(x+10, y+3, z+48, b, ms);
		world.setBlock(x+10, y+3, z+49, b, ms);
		world.setBlock(x+10, y+3, z+50, b, ms);
		world.setBlock(x+10, y+4, z+1, b, ms);
		world.setBlock(x+10, y+4, z+2, b, ms);
		world.setBlock(x+10, y+4, z+3, b, ms);
		world.setBlock(x+10, y+4, z+4, b, ms);
		world.setBlock(x+10, y+4, z+5, b, ms);
		world.setBlock(x+10, y+4, z+6, b, ms);
		world.setBlock(x+10, y+4, z+7, b, ms);
		world.setBlock(x+10, y+4, z+8, b, ms);
		world.setBlock(x+10, y+4, z+9, b, ms);
		world.setBlock(x+10, y+4, z+11, b, ms);
		world.setBlock(x+10, y+4, z+12, b, ms);
		world.setBlock(x+10, y+4, z+13, b, ms);
		world.setBlock(x+10, y+4, z+14, b, ms);
		world.setBlock(x+10, y+4, z+15, b, ms);
		world.setBlock(x+10, y+4, z+16, b, ms);
		world.setBlock(x+10, y+4, z+17, b, ms);
		world.setBlock(x+10, y+4, z+18, b, ms);
		world.setBlock(x+10, y+4, z+19, b, ms);
		world.setBlock(x+10, y+4, z+20, b, ms);
		world.setBlock(x+10, y+4, z+27, b, ms);
		world.setBlock(x+10, y+4, z+28, b, ms);
		world.setBlock(x+10, y+4, z+29, b, ms);
		world.setBlock(x+10, y+4, z+30, b, ms);
		world.setBlock(x+10, y+4, z+31, b, ms);
		world.setBlock(x+10, y+4, z+32, b, ms);
		world.setBlock(x+10, y+4, z+33, b, ms);
		world.setBlock(x+10, y+4, z+34, b, ms);
		world.setBlock(x+10, y+4, z+35, b, ms);
		world.setBlock(x+10, y+4, z+41, b, ms);
		world.setBlock(x+10, y+4, z+42, b, ms);
		world.setBlock(x+10, y+4, z+43, b, ms);
		world.setBlock(x+10, y+4, z+47, b, ms);
		world.setBlock(x+10, y+4, z+48, b, ms);
		world.setBlock(x+10, y+4, z+49, b, ms);
		world.setBlock(x+10, y+4, z+50, b, ms);
		world.setBlock(x+10, y+5, z+1, b, ms);
		world.setBlock(x+10, y+5, z+2, b, ms);
		world.setBlock(x+10, y+5, z+3, b, ms);
		world.setBlock(x+10, y+5, z+4, b, ms);
		world.setBlock(x+10, y+5, z+5, b, ms);
		world.setBlock(x+10, y+5, z+6, b, ms);
		world.setBlock(x+10, y+5, z+7, b, ms);
		world.setBlock(x+10, y+5, z+8, b, ms);
		world.setBlock(x+10, y+5, z+9, b, ms);
		world.setBlock(x+10, y+5, z+11, b, ms);
		world.setBlock(x+10, y+5, z+12, b, ms);
		world.setBlock(x+10, y+5, z+13, b, ms);
		world.setBlock(x+10, y+5, z+14, b, ms);
		world.setBlock(x+10, y+5, z+15, b, ms);
		world.setBlock(x+10, y+5, z+16, b, ms);
		world.setBlock(x+10, y+5, z+17, b, ms);
		world.setBlock(x+10, y+5, z+18, b, ms);
		world.setBlock(x+10, y+5, z+20, b, ms);
		world.setBlock(x+10, y+5, z+21, b, ms);
		world.setBlock(x+10, y+5, z+22, b, ms);
		world.setBlock(x+10, y+5, z+23, b, ms);
		world.setBlock(x+10, y+5, z+24, b, ms);
		world.setBlock(x+10, y+5, z+25, b, ms);
		world.setBlock(x+10, y+5, z+26, b, ms);
		world.setBlock(x+10, y+5, z+27, b, ms);
		world.setBlock(x+10, y+5, z+35, b, ms);
		world.setBlock(x+10, y+5, z+36, b, ms);
		world.setBlock(x+10, y+5, z+37, b, ms);
		world.setBlock(x+10, y+5, z+38, b, ms);
		world.setBlock(x+10, y+5, z+39, b, ms);
		world.setBlock(x+10, y+5, z+40, b, ms);
		world.setBlock(x+10, y+5, z+41, b, ms);
		world.setBlock(x+10, y+5, z+43, b, ms);
		world.setBlock(x+10, y+5, z+44, b, ms);
		world.setBlock(x+10, y+5, z+45, b, ms);
		world.setBlock(x+10, y+5, z+46, b, ms);
		world.setBlock(x+10, y+5, z+47, b, ms);
		world.setBlock(x+10, y+5, z+48, b, ms);
		world.setBlock(x+10, y+5, z+49, b, ms);
		world.setBlock(x+10, y+5, z+50, b, ms);
		world.setBlock(x+11, y+0, z+20, b, ms);
		world.setBlock(x+11, y+0, z+21, b, ms);
		world.setBlock(x+11, y+0, z+22, b, ms);
		world.setBlock(x+11, y+0, z+23, b, ms);
		world.setBlock(x+11, y+0, z+24, b, ms);
		world.setBlock(x+11, y+0, z+25, b, ms);
		world.setBlock(x+11, y+0, z+26, b, ms);
		world.setBlock(x+11, y+0, z+27, b, ms);
		world.setBlock(x+11, y+0, z+28, b, ms);
		world.setBlock(x+11, y+0, z+29, b, ms);
		world.setBlock(x+11, y+0, z+30, b, ms);
		world.setBlock(x+11, y+0, z+31, b, ms);
		world.setBlock(x+11, y+0, z+32, b, ms);
		world.setBlock(x+11, y+0, z+33, b, ms);
		world.setBlock(x+11, y+0, z+34, b, ms);
		world.setBlock(x+11, y+0, z+35, b, ms);
		world.setBlock(x+11, y+0, z+36, b, ms);
		world.setBlock(x+11, y+0, z+37, b, ms);
		world.setBlock(x+11, y+0, z+38, b, ms);
		world.setBlock(x+11, y+0, z+39, b, ms);
		world.setBlock(x+11, y+0, z+40, b, ms);
		world.setBlock(x+11, y+0, z+41, b, ms);
		world.setBlock(x+11, y+0, z+42, b, ms);
		world.setBlock(x+11, y+0, z+43, b, ms);
		world.setBlock(x+11, y+0, z+44, b, ms);
		world.setBlock(x+11, y+0, z+45, b, ms);
		world.setBlock(x+11, y+0, z+46, b, ms);
		world.setBlock(x+11, y+0, z+47, b, ms);
		world.setBlock(x+11, y+0, z+48, b, ms);
		world.setBlock(x+11, y+0, z+49, b, ms);
		world.setBlock(x+11, y+1, z+13, b, ms);
		world.setBlock(x+11, y+1, z+14, b, ms);
		world.setBlock(x+11, y+1, z+15, b, ms);
		world.setBlock(x+11, y+1, z+16, b, ms);
		world.setBlock(x+11, y+1, z+17, b, ms);
		world.setBlock(x+11, y+1, z+20, b, ms);
		world.setBlock(x+11, y+1, z+21, b, ms);
		world.setBlock(x+11, y+1, z+22, b, ms);
		world.setBlock(x+11, y+1, z+23, b, ms);
		world.setBlock(x+11, y+1, z+24, b, ms);
		world.setBlock(x+11, y+1, z+25, b, ms);
		world.setBlock(x+11, y+1, z+26, b, ms);
		world.setBlock(x+11, y+1, z+27, b, ms);
		world.setBlock(x+11, y+1, z+28, b, ms);
		world.setBlock(x+11, y+1, z+29, b, ms);
		world.setBlock(x+11, y+1, z+30, b, ms);
		world.setBlock(x+11, y+1, z+31, b, ms);
		world.setBlock(x+11, y+1, z+32, b, ms);
		world.setBlock(x+11, y+1, z+33, b, ms);
		world.setBlock(x+11, y+1, z+34, b, ms);
		world.setBlock(x+11, y+1, z+35, b, ms);
		world.setBlock(x+11, y+1, z+41, b, ms);
		world.setBlock(x+11, y+1, z+42, b, ms);
		world.setBlock(x+11, y+1, z+43, b, ms);
		world.setBlock(x+11, y+1, z+46, b, ms);
		world.setBlock(x+11, y+1, z+47, b, ms);
		world.setBlock(x+11, y+1, z+48, b, ms);
		world.setBlock(x+11, y+1, z+49, b, ms);
		world.setBlock(x+11, y+2, z+13, b, ms);
		this.generateRune(x+11, y+2, z+14, LockColor.YELLOW);
		world.setBlock(x+11, y+2, z+15, b, ms);
		this.generateRune(x+11, y+2, z+16, LockColor.BLUE);
		world.setBlock(x+11, y+2, z+17, b, ms);
		world.setBlock(x+11, y+2, z+20, b, ms);
		world.setBlock(x+11, y+2, z+21, b, ms);
		world.setBlock(x+11, y+2, z+22, b, ms);
		world.setBlock(x+11, y+2, z+24, b, ms);
		world.setBlock(x+11, y+2, z+26, b, ms);
		world.setBlock(x+11, y+2, z+27, b, ms);
		world.setBlock(x+11, y+2, z+28, b, ms);
		world.setBlock(x+11, y+2, z+29, b, ms);
		world.setBlock(x+11, y+2, z+30, b, ms);
		world.setBlock(x+11, y+2, z+31, b, ms);
		world.setBlock(x+11, y+2, z+32, b, ms);
		world.setBlock(x+11, y+2, z+33, b, ms);
		world.setBlock(x+11, y+2, z+34, b, ms);
		world.setBlock(x+11, y+2, z+35, b, ms);
		world.setBlock(x+11, y+2, z+41, b, ms);
		world.setBlock(x+11, y+2, z+42, b, ms);
		world.setBlock(x+11, y+2, z+43, b, ms);
		world.setBlock(x+11, y+2, z+46, b, ml);
		world.setBlock(x+11, y+2, z+47, b, ms);
		world.setBlock(x+11, y+2, z+48, b, mc);
		world.setBlock(x+11, y+2, z+49, b, ms);
		world.setBlock(x+11, y+3, z+13, b, ms);
		world.setBlock(x+11, y+3, z+14, b, ms);
		world.setBlock(x+11, y+3, z+15, b, ms);
		world.setBlock(x+11, y+3, z+16, b, ms);
		world.setBlock(x+11, y+3, z+17, b, ms);
		world.setBlock(x+11, y+3, z+20, b, ms);
		world.setBlock(x+11, y+3, z+21, b, ms);
		world.setBlock(x+11, y+3, z+22, b, ms);
		world.setBlock(x+11, y+3, z+23, b, ms);
		world.setBlock(x+11, y+3, z+24, b, ms);
		world.setBlock(x+11, y+3, z+25, b, ms);
		world.setBlock(x+11, y+3, z+26, b, ms);
		world.setBlock(x+11, y+3, z+27, b, ms);
		world.setBlock(x+11, y+3, z+28, b, ms);
		world.setBlock(x+11, y+3, z+29, b, ms);
		world.setBlock(x+11, y+3, z+30, b, ms);
		world.setBlock(x+11, y+3, z+31, b, ms);
		world.setBlock(x+11, y+3, z+32, b, ms);
		world.setBlock(x+11, y+3, z+33, b, ms);
		world.setBlock(x+11, y+3, z+34, b, ms);
		world.setBlock(x+11, y+3, z+35, b, ms);
		world.setBlock(x+11, y+3, z+41, b, ms);
		world.setBlock(x+11, y+3, z+42, b, ms);
		world.setBlock(x+11, y+3, z+43, b, ms);
		world.setBlock(x+11, y+3, z+46, b, ms);
		world.setBlock(x+11, y+3, z+47, b, ms);
		world.setBlock(x+11, y+3, z+48, b, ms);
		world.setBlock(x+11, y+3, z+49, b, ms);
		world.setBlock(x+11, y+4, z+20, b, ms);
		world.setBlock(x+11, y+4, z+21, b, ml);
		world.setBlock(x+11, y+4, z+22, b, ms);
		world.setBlock(x+11, y+4, z+23, b, ms);
		world.setBlock(x+11, y+4, z+24, b, ms);
		world.setBlock(x+11, y+4, z+25, b, ms);
		world.setBlock(x+11, y+4, z+26, b, ms);
		world.setBlock(x+11, y+4, z+27, b, ms);
		world.setBlock(x+11, y+4, z+28, b, ms);
		world.setBlock(x+11, y+4, z+29, b, ms);
		world.setBlock(x+11, y+4, z+30, b, ms);
		world.setBlock(x+11, y+4, z+31, b, ms);
		world.setBlock(x+11, y+4, z+32, b, ms);
		world.setBlock(x+11, y+4, z+33, b, ms);
		world.setBlock(x+11, y+4, z+34, b, ms);
		world.setBlock(x+11, y+4, z+35, b, ms);
		world.setBlock(x+11, y+4, z+41, b, ms);
		world.setBlock(x+11, y+4, z+42, b, ms);
		world.setBlock(x+11, y+4, z+43, b, ms);
		world.setBlock(x+11, y+4, z+46, b, ms);
		world.setBlock(x+11, y+4, z+47, b, ms);
		world.setBlock(x+11, y+4, z+48, b, ms);
		world.setBlock(x+11, y+4, z+49, b, ms);
		world.setBlock(x+11, y+5, z+20, b, ms);
		world.setBlock(x+11, y+5, z+21, b, ms);
		world.setBlock(x+11, y+5, z+22, b, ms);
		world.setBlock(x+11, y+5, z+23, b, ms);
		world.setBlock(x+11, y+5, z+24, b, ms);
		world.setBlock(x+11, y+5, z+25, b, ms);
		world.setBlock(x+11, y+5, z+26, b, ms);
		world.setBlock(x+11, y+5, z+27, b, ms);
		world.setBlock(x+11, y+5, z+35, b, ms);
		world.setBlock(x+11, y+5, z+36, b, ms);
		world.setBlock(x+11, y+5, z+37, b, ms);
		world.setBlock(x+11, y+5, z+38, b, ms);
		world.setBlock(x+11, y+5, z+39, b, ms);
		world.setBlock(x+11, y+5, z+40, b, ms);
		world.setBlock(x+11, y+5, z+41, b, ms);
		world.setBlock(x+11, y+5, z+43, b, ms);
		world.setBlock(x+11, y+5, z+44, b, ms);
		world.setBlock(x+11, y+5, z+45, b, ms);
		world.setBlock(x+11, y+5, z+46, b, ms);
		world.setBlock(x+11, y+5, z+47, b, ms);
		world.setBlock(x+11, y+5, z+48, b, ms);
		world.setBlock(x+11, y+5, z+49, b, ms);
		world.setBlock(x+12, y+0, z+36, b, ms);
		world.setBlock(x+12, y+0, z+37, b, ms);
		world.setBlock(x+12, y+0, z+38, b, ms);
		world.setBlock(x+12, y+0, z+39, b, ms);
		world.setBlock(x+12, y+0, z+40, b, ms);
		world.setBlock(x+12, y+0, z+43, b, ms);
		world.setBlock(x+12, y+0, z+44, b, ms);
		world.setBlock(x+12, y+0, z+45, b, ms);
		world.setBlock(x+12, y+0, z+46, b, ms);
		world.setBlock(x+12, y+0, z+47, b, ms);
		world.setBlock(x+12, y+0, z+48, b, ms);
		world.setBlock(x+12, y+1, z+13, b, ms);
		world.setBlock(x+12, y+1, z+14, b, ms);
		world.setBlock(x+12, y+1, z+15, b, ms);
		world.setBlock(x+12, y+1, z+16, b, ms);
		world.setBlock(x+12, y+1, z+17, b, ms);
		world.setBlock(x+12, y+1, z+22, b, ms);
		world.setBlock(x+12, y+1, z+23, b, ms);
		world.setBlock(x+12, y+1, z+24, b, ms);
		world.setBlock(x+12, y+1, z+25, b, ms);
		world.setBlock(x+12, y+1, z+26, b, ms);
		world.setBlock(x+12, y+1, z+36, b, ms);
		world.setBlock(x+12, y+1, z+37, b, ms);
		world.setBlock(x+12, y+1, z+38, b, ms);
		world.setBlock(x+12, y+1, z+39, b, ms);
		world.setBlock(x+12, y+1, z+40, b, ms);
		world.setBlock(x+12, y+1, z+43, b, ms);
		world.setBlock(x+12, y+1, z+44, b, ms);
		world.setBlock(x+12, y+1, z+45, b, ms);
		world.setBlock(x+12, y+1, z+46, b, ms);
		world.setBlock(x+12, y+1, z+47, b, ms);
		world.setBlock(x+12, y+1, z+48, b, ms);
		world.setBlock(x+12, y+2, z+13, b, ms);
		world.setBlock(x+12, y+2, z+14, b, ms);
		world.setBlock(x+12, y+2, z+15, b, ms);
		world.setBlock(x+12, y+2, z+16, b, ms);
		world.setBlock(x+12, y+2, z+17, b, ms);
		world.setBlock(x+12, y+2, z+22, b, ms);
		this.generateRune(x+12, y+2, z+23, LockColor.GREEN);
		world.setBlock(x+12, y+2, z+24, b, ms);
		this.generateRune(x+12, y+2, z+25, LockColor.PURPLE);
		world.setBlock(x+12, y+2, z+26, b, ms);
		world.setBlock(x+12, y+2, z+36, b, ms);
		world.setBlock(x+12, y+2, z+37, b, ms);
		world.setBlock(x+12, y+2, z+38, b, ms);
		world.setBlock(x+12, y+2, z+39, b, ms);
		world.setBlock(x+12, y+2, z+40, b, ms);
		world.setBlock(x+12, y+2, z+43, b, ms);
		world.setBlock(x+12, y+2, z+44, b, ms);
		world.setBlock(x+12, y+2, z+45, b, ms);
		world.setBlock(x+12, y+2, z+46, b, ms);
		world.setBlock(x+12, y+2, z+47, b, ms);
		world.setBlock(x+12, y+2, z+48, b, ms);
		world.setBlock(x+12, y+3, z+13, b, ms);
		world.setBlock(x+12, y+3, z+14, b, ms);
		world.setBlock(x+12, y+3, z+15, b, ms);
		world.setBlock(x+12, y+3, z+16, b, ms);
		world.setBlock(x+12, y+3, z+17, b, ms);
		world.setBlock(x+12, y+3, z+22, b, ms);
		world.setBlock(x+12, y+3, z+23, b, ms);
		world.setBlock(x+12, y+3, z+24, b, ms);
		world.setBlock(x+12, y+3, z+25, b, ms);
		world.setBlock(x+12, y+3, z+26, b, ms);
		world.setBlock(x+12, y+3, z+36, b, ms);
		world.setBlock(x+12, y+3, z+37, b, ms);
		world.setBlock(x+12, y+3, z+38, b, ms);
		world.setBlock(x+12, y+3, z+39, b, ms);
		world.setBlock(x+12, y+3, z+40, b, ms);
		world.setBlock(x+12, y+3, z+43, b, ms);
		world.setBlock(x+12, y+3, z+44, b, ms);
		world.setBlock(x+12, y+3, z+45, b, ms);
		world.setBlock(x+12, y+3, z+46, b, ms);
		world.setBlock(x+12, y+3, z+47, b, ms);
		world.setBlock(x+12, y+3, z+48, b, ms);
		world.setBlock(x+12, y+4, z+36, b, ms);
		world.setBlock(x+12, y+4, z+37, b, ms);
		world.setBlock(x+12, y+4, z+38, b, ms);
		world.setBlock(x+12, y+4, z+39, b, ms);
		world.setBlock(x+12, y+4, z+40, b, ms);
		world.setBlock(x+12, y+4, z+43, b, ms);
		world.setBlock(x+12, y+4, z+44, b, ms);
		world.setBlock(x+12, y+4, z+45, b, ms);
		world.setBlock(x+12, y+4, z+46, b, ms);
		world.setBlock(x+12, y+4, z+47, b, ms);
		world.setBlock(x+12, y+4, z+48, b, ms);
		world.setBlock(x+12, y+5, z+36, b, ms);
		world.setBlock(x+12, y+5, z+37, b, ms);
		world.setBlock(x+12, y+5, z+38, b, ms);
		world.setBlock(x+12, y+5, z+39, b, ms);
		world.setBlock(x+12, y+5, z+40, b, ms);
		world.setBlock(x+12, y+5, z+43, b, ms);
		world.setBlock(x+12, y+5, z+44, b, ms);
		world.setBlock(x+12, y+5, z+45, b, ms);
		world.setBlock(x+12, y+5, z+46, b, ms);
		world.setBlock(x+12, y+5, z+47, b, ms);
		world.setBlock(x+12, y+5, z+48, b, ms);
		world.setBlock(x+13, y+1, z+22, b, ms);
		world.setBlock(x+13, y+1, z+23, b, ms);
		world.setBlock(x+13, y+1, z+24, b, ms);
		world.setBlock(x+13, y+1, z+25, b, ms);
		world.setBlock(x+13, y+1, z+26, b, ms);
		world.setBlock(x+13, y+2, z+22, b, ms);
		world.setBlock(x+13, y+2, z+23, b, ms);
		world.setBlock(x+13, y+2, z+24, b, ms);
		world.setBlock(x+13, y+2, z+25, b, ms);
		world.setBlock(x+13, y+2, z+26, b, ms);
		world.setBlock(x+13, y+3, z+22, b, ms);
		world.setBlock(x+13, y+3, z+23, b, ms);
		world.setBlock(x+13, y+3, z+24, b, ms);
		world.setBlock(x+13, y+3, z+25, b, ms);
		world.setBlock(x+13, y+3, z+26, b, ms);
		world.setBlock(x+2, y+2, z+14, Blocks.air);
		world.setBlock(x+2, y+2, z+16, Blocks.air);
		world.setBlock(x+2, y+2, z+38, Blocks.air);
		world.setBlock(x+2, y+2, z+45, Blocks.air);
		world.setBlock(x+2, y+2, z+47, Blocks.air);
		world.setBlock(x+2, y+2, z+49, Blocks.air);
		world.setBlock(x+3, y+1, z+2, Blocks.air);
		world.setBlock(x+3, y+1, z+3, Blocks.air);
		world.setBlock(x+3, y+1, z+4, Blocks.air);
		world.setBlock(x+3, y+1, z+5, Blocks.air);
		world.setBlock(x+3, y+1, z+6, Blocks.air);
		world.setBlock(x+3, y+1, z+7, Blocks.air);
		world.setBlock(x+3, y+1, z+8, Blocks.air);
		world.setBlock(x+3, y+1, z+12, Blocks.air);
		world.setBlock(x+3, y+1, z+13, Blocks.air);
		world.setBlock(x+3, y+1, z+14, Blocks.air);
		world.setBlock(x+3, y+1, z+15, Blocks.air);
		world.setBlock(x+3, y+1, z+16, Blocks.air);
		world.setBlock(x+3, y+1, z+17, Blocks.air);
		world.setBlock(x+3, y+1, z+18, Blocks.air);
		world.setBlock(x+3, y+1, z+20, Blocks.air);
		world.setBlock(x+3, y+1, z+21, Blocks.air);
		world.setBlock(x+3, y+1, z+22, Blocks.air);
		world.setBlock(x+3, y+1, z+37, Blocks.air);
		world.setBlock(x+3, y+1, z+38, Blocks.air);
		world.setBlock(x+3, y+1, z+39, Blocks.air);
		world.setBlock(x+3, y+1, z+40, Blocks.air);
		world.setBlock(x+3, y+1, z+44, Blocks.air);
		world.setBlock(x+3, y+1, z+45, Blocks.air);
		world.setBlock(x+3, y+1, z+46, Blocks.air);
		world.setBlock(x+3, y+1, z+47, Blocks.air);
		world.setBlock(x+3, y+1, z+48, Blocks.air);
		world.setBlock(x+3, y+1, z+49, Blocks.air);
		world.setBlock(x+3, y+1, z+50, Blocks.air);
		world.setBlock(x+3, y+2, z+2, Blocks.air);
		world.setBlock(x+3, y+2, z+3, Blocks.air);
		world.setBlock(x+3, y+2, z+4, Blocks.air);
		world.setBlock(x+3, y+2, z+5, Blocks.air);
		world.setBlock(x+3, y+2, z+6, Blocks.air);
		world.setBlock(x+3, y+2, z+7, Blocks.air);
		world.setBlock(x+3, y+2, z+8, Blocks.air);
		world.setBlock(x+3, y+2, z+12, Blocks.air);
		world.setBlock(x+3, y+2, z+13, Blocks.air);
		world.setBlock(x+3, y+2, z+14, Blocks.air);
		world.setBlock(x+3, y+2, z+15, Blocks.air);
		world.setBlock(x+3, y+2, z+16, Blocks.air);
		world.setBlock(x+3, y+2, z+17, Blocks.air);
		world.setBlock(x+3, y+2, z+18, Blocks.air);
		world.setBlock(x+3, y+2, z+20, Blocks.air);
		world.setBlock(x+3, y+2, z+21, Blocks.air);
		world.setBlock(x+3, y+2, z+22, Blocks.air);
		world.setBlock(x+3, y+2, z+37, Blocks.air);
		world.setBlock(x+3, y+2, z+38, Blocks.air);
		world.setBlock(x+3, y+2, z+39, Blocks.air);
		world.setBlock(x+3, y+2, z+40, Blocks.air);
		world.setBlock(x+3, y+2, z+44, Blocks.air);
		world.setBlock(x+3, y+2, z+45, Blocks.air);
		world.setBlock(x+3, y+2, z+46, Blocks.air);
		world.setBlock(x+3, y+2, z+47, Blocks.air);
		world.setBlock(x+3, y+2, z+48, Blocks.air);
		world.setBlock(x+3, y+2, z+49, Blocks.air);
		world.setBlock(x+3, y+2, z+50, Blocks.air);
		world.setBlock(x+3, y+3, z+2, Blocks.air);
		world.setBlock(x+3, y+3, z+3, Blocks.air);
		world.setBlock(x+3, y+3, z+4, Blocks.air);
		world.setBlock(x+3, y+3, z+5, Blocks.air);
		world.setBlock(x+3, y+3, z+6, Blocks.air);
		world.setBlock(x+3, y+3, z+7, Blocks.air);
		world.setBlock(x+3, y+3, z+8, Blocks.air);
		world.setBlock(x+3, y+3, z+12, Blocks.air);
		world.setBlock(x+3, y+3, z+13, Blocks.air);
		world.setBlock(x+3, y+3, z+14, Blocks.air);
		world.setBlock(x+3, y+3, z+15, Blocks.air);
		world.setBlock(x+3, y+3, z+16, Blocks.air);
		world.setBlock(x+3, y+3, z+17, Blocks.air);
		world.setBlock(x+3, y+3, z+18, Blocks.air);
		world.setBlock(x+3, y+3, z+20, Blocks.air);
		world.setBlock(x+3, y+3, z+21, Blocks.air);
		world.setBlock(x+3, y+3, z+22, Blocks.air);
		world.setBlock(x+3, y+3, z+37, Blocks.air);
		world.setBlock(x+3, y+3, z+38, Blocks.air);
		world.setBlock(x+3, y+3, z+39, Blocks.air);
		world.setBlock(x+3, y+3, z+40, Blocks.air);
		world.setBlock(x+3, y+3, z+44, Blocks.air);
		world.setBlock(x+3, y+3, z+45, Blocks.air);
		world.setBlock(x+3, y+3, z+46, Blocks.air);
		world.setBlock(x+3, y+3, z+47, Blocks.air);
		world.setBlock(x+3, y+3, z+48, Blocks.air);
		world.setBlock(x+3, y+3, z+49, Blocks.air);
		world.setBlock(x+3, y+3, z+50, Blocks.air);
		world.setBlock(x+3, y+4, z+2, Blocks.air);
		world.setBlock(x+3, y+4, z+3, Blocks.air);
		world.setBlock(x+3, y+4, z+4, Blocks.air);
		world.setBlock(x+3, y+4, z+5, Blocks.air);
		world.setBlock(x+3, y+4, z+6, Blocks.air);
		world.setBlock(x+3, y+4, z+7, Blocks.air);
		world.setBlock(x+3, y+4, z+8, Blocks.air);
		world.setBlock(x+3, y+4, z+12, Blocks.air);
		world.setBlock(x+3, y+4, z+13, Blocks.air);
		world.setBlock(x+3, y+4, z+14, Blocks.air);
		world.setBlock(x+3, y+4, z+15, Blocks.air);
		world.setBlock(x+3, y+4, z+16, Blocks.air);
		world.setBlock(x+3, y+4, z+17, Blocks.air);
		world.setBlock(x+3, y+4, z+37, Blocks.air);
		world.setBlock(x+3, y+4, z+38, Blocks.air);
		world.setBlock(x+3, y+4, z+39, Blocks.air);
		world.setBlock(x+3, y+4, z+40, Blocks.air);
		world.setBlock(x+3, y+4, z+44, Blocks.air);
		world.setBlock(x+3, y+4, z+45, Blocks.air);
		world.setBlock(x+3, y+4, z+46, Blocks.air);
		world.setBlock(x+3, y+4, z+47, Blocks.air);
		world.setBlock(x+3, y+4, z+48, Blocks.air);
		world.setBlock(x+3, y+4, z+49, Blocks.air);
		world.setBlock(x+3, y+4, z+50, Blocks.air);
		world.setBlock(x+4, y+1, z+1, Blocks.air);
		world.setBlock(x+4, y+1, z+2, Blocks.air);
		world.setBlock(x+4, y+1, z+3, Blocks.air);
		world.setBlock(x+4, y+1, z+4, Blocks.air);
		world.setBlock(x+4, y+1, z+6, Blocks.air);
		world.setBlock(x+4, y+1, z+7, Blocks.air);
		world.setBlock(x+4, y+1, z+8, Blocks.air);
		world.setBlock(x+4, y+1, z+12, Blocks.air);
		world.setBlock(x+4, y+1, z+13, Blocks.air);
		world.setBlock(x+4, y+1, z+14, Blocks.air);
		world.setBlock(x+4, y+1, z+15, Blocks.air);
		world.setBlock(x+4, y+1, z+16, Blocks.air);
		world.setBlock(x+4, y+1, z+17, Blocks.air);
		world.setBlock(x+4, y+1, z+18, Blocks.air);
		world.setBlock(x+4, y+1, z+20, Blocks.air);
		world.setBlock(x+4, y+1, z+22, Blocks.air);
		world.setBlock(x+4, y+1, z+31, Blocks.air);
		world.setBlock(x+4, y+1, z+32, Blocks.air);
		world.setBlock(x+4, y+1, z+33, Blocks.air);
		world.setBlock(x+4, y+1, z+37, Blocks.air);
		world.setBlock(x+4, y+1, z+38, Blocks.air);
		world.setBlock(x+4, y+1, z+39, Blocks.air);
		world.setBlock(x+4, y+1, z+40, Blocks.air);
		world.setBlock(x+4, y+1, z+44, Blocks.air);
		world.setBlock(x+4, y+1, z+45, Blocks.air);
		world.setBlock(x+4, y+1, z+46, Blocks.air);
		world.setBlock(x+4, y+1, z+47, Blocks.air);
		world.setBlock(x+4, y+1, z+48, Blocks.air);
		world.setBlock(x+4, y+1, z+49, Blocks.air);
		world.setBlock(x+4, y+1, z+50, Blocks.air);
		world.setBlock(x+4, y+1, z+51, Blocks.air);
		world.setBlock(x+4, y+1, z+53, Blocks.air);
		world.setBlock(x+4, y+2, z+1, Blocks.air);
		world.setBlock(x+4, y+2, z+2, Blocks.air);
		world.setBlock(x+4, y+2, z+3, Blocks.air);
		world.setBlock(x+4, y+2, z+4, Blocks.air);
		world.setBlock(x+4, y+2, z+5, Blocks.air);
		world.setBlock(x+4, y+2, z+6, Blocks.air);
		world.setBlock(x+4, y+2, z+7, Blocks.air);
		world.setBlock(x+4, y+2, z+8, Blocks.air);
		world.setBlock(x+4, y+2, z+12, Blocks.air);
		world.setBlock(x+4, y+2, z+13, Blocks.air);
		world.setBlock(x+4, y+2, z+14, Blocks.air);
		world.setBlock(x+4, y+2, z+15, Blocks.air);
		world.setBlock(x+4, y+2, z+16, Blocks.air);
		world.setBlock(x+4, y+2, z+17, Blocks.air);
		world.setBlock(x+4, y+2, z+18, Blocks.air);
		world.setBlock(x+4, y+2, z+20, Blocks.air);
		world.setBlock(x+4, y+2, z+21, Blocks.air);
		world.setBlock(x+4, y+2, z+22, Blocks.air);
		world.setBlock(x+4, y+2, z+31, Blocks.air);
		world.setBlock(x+4, y+2, z+32, Blocks.air);
		world.setBlock(x+4, y+2, z+33, Blocks.air);
		world.setBlock(x+4, y+2, z+36, Blocks.air);
		world.setBlock(x+4, y+2, z+37, Blocks.air);
		world.setBlock(x+4, y+2, z+38, Blocks.air);
		world.setBlock(x+4, y+2, z+39, Blocks.air);
		world.setBlock(x+4, y+2, z+40, Blocks.air);
		world.setBlock(x+4, y+2, z+41, Blocks.air);
		world.setBlock(x+4, y+2, z+43, Blocks.air);
		world.setBlock(x+4, y+2, z+44, Blocks.air);
		world.setBlock(x+4, y+2, z+45, Blocks.air);
		world.setBlock(x+4, y+2, z+46, Blocks.air);
		world.setBlock(x+4, y+2, z+47, Blocks.air);
		world.setBlock(x+4, y+2, z+48, Blocks.air);
		world.setBlock(x+4, y+2, z+49, Blocks.air);
		world.setBlock(x+4, y+2, z+50, Blocks.air);
		world.setBlock(x+4, y+2, z+51, Blocks.air);
		world.setBlock(x+4, y+2, z+53, Blocks.air);
		world.setBlock(x+4, y+3, z+1, Blocks.air);
		world.setBlock(x+4, y+3, z+2, Blocks.air);
		world.setBlock(x+4, y+3, z+3, Blocks.air);
		world.setBlock(x+4, y+3, z+4, Blocks.air);
		world.setBlock(x+4, y+3, z+5, Blocks.air);
		world.setBlock(x+4, y+3, z+6, Blocks.air);
		world.setBlock(x+4, y+3, z+7, Blocks.air);
		world.setBlock(x+4, y+3, z+8, Blocks.air);
		world.setBlock(x+4, y+3, z+12, Blocks.air);
		world.setBlock(x+4, y+3, z+13, Blocks.air);
		world.setBlock(x+4, y+3, z+14, Blocks.air);
		world.setBlock(x+4, y+3, z+15, Blocks.air);
		world.setBlock(x+4, y+3, z+16, Blocks.air);
		world.setBlock(x+4, y+3, z+17, Blocks.air);
		world.setBlock(x+4, y+3, z+18, Blocks.air);
		world.setBlock(x+4, y+3, z+20, Blocks.air);
		world.setBlock(x+4, y+3, z+21, Blocks.air);
		world.setBlock(x+4, y+3, z+22, Blocks.air);
		world.setBlock(x+4, y+3, z+31, Blocks.air);
		world.setBlock(x+4, y+3, z+32, Blocks.air);
		world.setBlock(x+4, y+3, z+33, Blocks.air);
		world.setBlock(x+4, y+3, z+37, Blocks.air);
		world.setBlock(x+4, y+3, z+38, Blocks.air);
		world.setBlock(x+4, y+3, z+39, Blocks.air);
		world.setBlock(x+4, y+3, z+40, Blocks.air);
		world.setBlock(x+4, y+3, z+44, Blocks.air);
		world.setBlock(x+4, y+3, z+45, Blocks.air);
		world.setBlock(x+4, y+3, z+46, Blocks.air);
		world.setBlock(x+4, y+3, z+47, Blocks.air);
		world.setBlock(x+4, y+3, z+48, Blocks.air);
		world.setBlock(x+4, y+3, z+49, Blocks.air);
		world.setBlock(x+4, y+3, z+50, Blocks.air);
		world.setBlock(x+4, y+3, z+51, Blocks.air);
		world.setBlock(x+4, y+3, z+53, Blocks.air);
		world.setBlock(x+4, y+4, z+1, Blocks.air);
		world.setBlock(x+4, y+4, z+2, Blocks.air);
		world.setBlock(x+4, y+4, z+3, Blocks.air);
		world.setBlock(x+4, y+4, z+4, Blocks.air);
		world.setBlock(x+4, y+4, z+5, Blocks.air);
		world.setBlock(x+4, y+4, z+6, Blocks.air);
		world.setBlock(x+4, y+4, z+7, Blocks.air);
		world.setBlock(x+4, y+4, z+8, Blocks.air);
		world.setBlock(x+4, y+4, z+12, Blocks.air);
		world.setBlock(x+4, y+4, z+13, Blocks.air);
		world.setBlock(x+4, y+4, z+14, Blocks.air);
		world.setBlock(x+4, y+4, z+15, Blocks.air);
		world.setBlock(x+4, y+4, z+16, Blocks.air);
		world.setBlock(x+4, y+4, z+17, Blocks.air);
		world.setBlock(x+4, y+4, z+37, Blocks.air);
		world.setBlock(x+4, y+4, z+38, Blocks.air);
		world.setBlock(x+4, y+4, z+39, Blocks.air);
		world.setBlock(x+4, y+4, z+40, Blocks.air);
		world.setBlock(x+4, y+4, z+44, Blocks.air);
		world.setBlock(x+4, y+4, z+45, Blocks.air);
		world.setBlock(x+4, y+4, z+46, Blocks.air);
		world.setBlock(x+4, y+4, z+47, Blocks.air);
		world.setBlock(x+4, y+4, z+48, Blocks.air);
		world.setBlock(x+4, y+4, z+49, Blocks.air);
		world.setBlock(x+4, y+4, z+50, Blocks.air);
		world.setBlock(x+5, y+1, z+0, Blocks.air);
		world.setBlock(x+5, y+1, z+1, Blocks.air);
		world.setBlock(x+5, y+1, z+2, Blocks.air);
		world.setBlock(x+5, y+1, z+3, Blocks.air);
		world.setBlock(x+5, y+1, z+4, Blocks.air);
		world.setBlock(x+5, y+1, z+5, Blocks.air);
		world.setBlock(x+5, y+1, z+6, Blocks.air);
		world.setBlock(x+5, y+1, z+7, Blocks.air);
		world.setBlock(x+5, y+1, z+8, Blocks.air);
		world.setBlock(x+5, y+1, z+9, Blocks.air);
		world.setBlock(x+5, y+1, z+11, Blocks.air);
		world.setBlock(x+5, y+1, z+12, Blocks.air);
		world.setBlock(x+5, y+1, z+13, Blocks.air);
		world.setBlock(x+5, y+1, z+14, Blocks.air);
		world.setBlock(x+5, y+1, z+15, Blocks.air);
		world.setBlock(x+5, y+1, z+16, Blocks.air);
		world.setBlock(x+5, y+1, z+17, Blocks.air);
		world.setBlock(x+5, y+1, z+18, Blocks.air);
		world.setBlock(x+5, y+1, z+20, Blocks.air);
		world.setBlock(x+5, y+1, z+21, Blocks.air);
		world.setBlock(x+5, y+1, z+22, Blocks.air);
		world.setBlock(x+5, y+1, z+31, Blocks.air);
		world.setBlock(x+5, y+1, z+32, Blocks.air);
		world.setBlock(x+5, y+1, z+33, Blocks.air);
		world.setBlock(x+5, y+1, z+37, Blocks.air);
		world.setBlock(x+5, y+1, z+38, Blocks.air);
		world.setBlock(x+5, y+1, z+39, Blocks.air);
		world.setBlock(x+5, y+1, z+40, Blocks.air);
		world.setBlock(x+5, y+1, z+44, Blocks.air);
		world.setBlock(x+5, y+1, z+45, Blocks.air);
		world.setBlock(x+5, y+1, z+46, Blocks.air);
		world.setBlock(x+5, y+1, z+47, Blocks.air);
		world.setBlock(x+5, y+1, z+48, Blocks.air);
		world.setBlock(x+5, y+1, z+49, Blocks.air);
		world.setBlock(x+5, y+1, z+50, Blocks.air);
		world.setBlock(x+5, y+1, z+51, Blocks.air);
		world.setBlock(x+5, y+1, z+53, Blocks.air);
		world.setBlock(x+5, y+2, z+0, Blocks.air);
		world.setBlock(x+5, y+2, z+1, Blocks.air);
		world.setBlock(x+5, y+2, z+2, Blocks.air);
		world.setBlock(x+5, y+2, z+3, Blocks.air);
		world.setBlock(x+5, y+2, z+4, Blocks.air);
		world.setBlock(x+5, y+2, z+5, Blocks.air);
		world.setBlock(x+5, y+2, z+6, Blocks.air);
		world.setBlock(x+5, y+2, z+7, Blocks.air);
		world.setBlock(x+5, y+2, z+8, Blocks.air);
		world.setBlock(x+5, y+2, z+9, Blocks.air);
		world.setBlock(x+5, y+2, z+11, Blocks.air);
		world.setBlock(x+5, y+2, z+12, Blocks.air);
		world.setBlock(x+5, y+2, z+13, Blocks.air);
		world.setBlock(x+5, y+2, z+14, Blocks.air);
		world.setBlock(x+5, y+2, z+15, Blocks.air);
		world.setBlock(x+5, y+2, z+16, Blocks.air);
		world.setBlock(x+5, y+2, z+17, Blocks.air);
		world.setBlock(x+5, y+2, z+18, Blocks.air);
		world.setBlock(x+5, y+2, z+20, Blocks.air);
		world.setBlock(x+5, y+2, z+21, Blocks.air);
		world.setBlock(x+5, y+2, z+22, Blocks.air);
		world.setBlock(x+5, y+2, z+25, Blocks.air);
		world.setBlock(x+5, y+2, z+30, Blocks.air);
		world.setBlock(x+5, y+2, z+31, Blocks.air);
		world.setBlock(x+5, y+2, z+32, Blocks.air);
		world.setBlock(x+5, y+2, z+33, Blocks.air);
		world.setBlock(x+5, y+2, z+37, Blocks.air);
		world.setBlock(x+5, y+2, z+38, Blocks.air);
		world.setBlock(x+5, y+2, z+39, Blocks.air);
		world.setBlock(x+5, y+2, z+40, Blocks.air);
		world.setBlock(x+5, y+2, z+44, Blocks.air);
		world.setBlock(x+5, y+2, z+45, Blocks.air);
		world.setBlock(x+5, y+2, z+46, Blocks.air);
		world.setBlock(x+5, y+2, z+47, Blocks.air);
		world.setBlock(x+5, y+2, z+48, Blocks.air);
		world.setBlock(x+5, y+2, z+49, Blocks.air);
		world.setBlock(x+5, y+2, z+50, Blocks.air);
		world.setBlock(x+5, y+2, z+51, Blocks.air);
		world.setBlock(x+5, y+2, z+53, Blocks.air);
		world.setBlock(x+5, y+3, z+0, Blocks.air);
		world.setBlock(x+5, y+3, z+1, Blocks.air);
		world.setBlock(x+5, y+3, z+2, Blocks.air);
		world.setBlock(x+5, y+3, z+3, Blocks.air);
		world.setBlock(x+5, y+3, z+4, Blocks.air);
		world.setBlock(x+5, y+3, z+5, Blocks.air);
		world.setBlock(x+5, y+3, z+6, Blocks.air);
		world.setBlock(x+5, y+3, z+7, Blocks.air);
		world.setBlock(x+5, y+3, z+8, Blocks.air);
		world.setBlock(x+5, y+3, z+9, Blocks.air);
		world.setBlock(x+5, y+3, z+11, Blocks.air);
		world.setBlock(x+5, y+3, z+12, Blocks.air);
		world.setBlock(x+5, y+3, z+13, Blocks.air);
		world.setBlock(x+5, y+3, z+14, Blocks.air);
		world.setBlock(x+5, y+3, z+15, Blocks.air);
		world.setBlock(x+5, y+3, z+16, Blocks.air);
		world.setBlock(x+5, y+3, z+17, Blocks.air);
		world.setBlock(x+5, y+3, z+18, Blocks.air);
		world.setBlock(x+5, y+3, z+20, Blocks.air);
		world.setBlock(x+5, y+3, z+21, Blocks.air);
		world.setBlock(x+5, y+3, z+22, Blocks.air);
		world.setBlock(x+5, y+3, z+31, Blocks.air);
		world.setBlock(x+5, y+3, z+32, Blocks.air);
		world.setBlock(x+5, y+3, z+33, Blocks.air);
		world.setBlock(x+5, y+3, z+37, Blocks.air);
		world.setBlock(x+5, y+3, z+38, Blocks.air);
		world.setBlock(x+5, y+3, z+39, Blocks.air);
		world.setBlock(x+5, y+3, z+40, Blocks.air);
		world.setBlock(x+5, y+3, z+44, Blocks.air);
		world.setBlock(x+5, y+3, z+45, Blocks.air);
		world.setBlock(x+5, y+3, z+46, Blocks.air);
		world.setBlock(x+5, y+3, z+47, Blocks.air);
		world.setBlock(x+5, y+3, z+48, Blocks.air);
		world.setBlock(x+5, y+3, z+49, Blocks.air);
		world.setBlock(x+5, y+3, z+50, Blocks.air);
		world.setBlock(x+5, y+3, z+51, Blocks.air);
		world.setBlock(x+5, y+3, z+53, Blocks.air);
		world.setBlock(x+5, y+4, z+1, Blocks.air);
		world.setBlock(x+5, y+4, z+2, Blocks.air);
		world.setBlock(x+5, y+4, z+3, Blocks.air);
		world.setBlock(x+5, y+4, z+4, Blocks.air);
		world.setBlock(x+5, y+4, z+5, Blocks.air);
		world.setBlock(x+5, y+4, z+6, Blocks.air);
		world.setBlock(x+5, y+4, z+7, Blocks.air);
		world.setBlock(x+5, y+4, z+8, Blocks.air);
		world.setBlock(x+5, y+4, z+12, Blocks.air);
		world.setBlock(x+5, y+4, z+13, Blocks.air);
		world.setBlock(x+5, y+4, z+14, Blocks.air);
		world.setBlock(x+5, y+4, z+15, Blocks.air);
		world.setBlock(x+5, y+4, z+16, Blocks.air);
		world.setBlock(x+5, y+4, z+17, Blocks.air);
		world.setBlock(x+5, y+4, z+37, Blocks.air);
		world.setBlock(x+5, y+4, z+38, Blocks.air);
		world.setBlock(x+5, y+4, z+39, Blocks.air);
		world.setBlock(x+5, y+4, z+40, Blocks.air);
		world.setBlock(x+5, y+4, z+44, Blocks.air);
		world.setBlock(x+5, y+4, z+45, Blocks.air);
		world.setBlock(x+5, y+4, z+46, Blocks.air);
		world.setBlock(x+5, y+4, z+47, Blocks.air);
		world.setBlock(x+5, y+4, z+48, Blocks.air);
		world.setBlock(x+5, y+4, z+49, Blocks.air);
		world.setBlock(x+5, y+4, z+50, Blocks.air);
		world.setBlock(x+6, y+1, z+0, Blocks.air);
		world.setBlock(x+6, y+1, z+1, Blocks.air);
		world.setBlock(x+6, y+1, z+2, Blocks.air);
		world.setBlock(x+6, y+1, z+3, Blocks.air);
		world.setBlock(x+6, y+1, z+4, Blocks.air);
		world.setBlock(x+6, y+1, z+5, Blocks.air);
		world.setBlock(x+6, y+1, z+6, Blocks.air);
		world.setBlock(x+6, y+1, z+7, Blocks.air);
		world.setBlock(x+6, y+1, z+8, Blocks.air);
		world.setBlock(x+6, y+1, z+9, Blocks.air);
		world.setBlock(x+6, y+1, z+11, Blocks.air);
		world.setBlock(x+6, y+1, z+12, Blocks.air);
		world.setBlock(x+6, y+1, z+13, Blocks.air);
		world.setBlock(x+6, y+1, z+14, Blocks.air);
		world.setBlock(x+6, y+1, z+15, Blocks.air);
		world.setBlock(x+6, y+1, z+16, Blocks.air);
		world.setBlock(x+6, y+1, z+17, Blocks.air);
		world.setBlock(x+6, y+1, z+23, Blocks.air);
		world.setBlock(x+6, y+1, z+24, Blocks.air);
		world.setBlock(x+6, y+1, z+25, Blocks.air);
		world.setBlock(x+6, y+1, z+26, Blocks.air);
		world.setBlock(x+6, y+1, z+31, Blocks.air);
		world.setBlock(x+6, y+1, z+32, Blocks.air);
		world.setBlock(x+6, y+1, z+33, Blocks.air);
		world.setBlock(x+6, y+1, z+37, Blocks.air);
		world.setBlock(x+6, y+1, z+38, Blocks.air);
		world.setBlock(x+6, y+1, z+39, Blocks.air);
		world.setBlock(x+6, y+1, z+40, Blocks.air);
		world.setBlock(x+6, y+1, z+44, Blocks.air);
		world.setBlock(x+6, y+1, z+45, Blocks.air);
		world.setBlock(x+6, y+1, z+46, Blocks.air);
		world.setBlock(x+6, y+1, z+47, Blocks.air);
		world.setBlock(x+6, y+1, z+48, Blocks.air);
		world.setBlock(x+6, y+1, z+49, Blocks.air);
		world.setBlock(x+6, y+1, z+50, Blocks.air);
		world.setBlock(x+6, y+1, z+51, Blocks.air);
		world.setBlock(x+6, y+1, z+53, Blocks.air);
		world.setBlock(x+6, y+2, z+0, Blocks.air);
		world.setBlock(x+6, y+2, z+1, Blocks.air);
		world.setBlock(x+6, y+2, z+2, Blocks.air);
		world.setBlock(x+6, y+2, z+3, Blocks.air);
		world.setBlock(x+6, y+2, z+4, Blocks.air);
		world.setBlock(x+6, y+2, z+5, Blocks.air);
		world.setBlock(x+6, y+2, z+6, Blocks.air);
		world.setBlock(x+6, y+2, z+7, Blocks.air);
		world.setBlock(x+6, y+2, z+8, Blocks.air);
		world.setBlock(x+6, y+2, z+9, Blocks.air);
		world.setBlock(x+6, y+2, z+11, Blocks.air);
		world.setBlock(x+6, y+2, z+12, Blocks.air);
