/*******************************************************************************
 * @author Reika Kalseki
 * 
 * Copyright 2015
 * 
 * All rights reserved.
 * Distribution of the software in any form is only allowed with
 * explicit, prior permission from the owner.
 ******************************************************************************/
package Reika.ChromatiCraft.World.Dimension.Structure.Locks;

import net.minecraft.block.Block;
import net.minecraft.init.Blocks;
import Reika.ChromatiCraft.Base.LockLevel;
import Reika.ChromatiCraft.Block.Dimension.Structure.BlockLockKey.LockChannel;
import Reika.ChromatiCraft.Block.Worldgen.BlockStructureShield.BlockType;
import Reika.ChromatiCraft.Registry.ChromaBlocks;
import Reika.ChromatiCraft.World.Dimension.Structure.LocksGenerator;
import Reika.DragonAPI.Instantiable.Worldgen.OriginBlockCache;

public class LocksRoomSpiral extends LockLevel {

	public LocksRoomSpiral(LocksGenerator g) {
		super(g, LockChannel.SPIRAL);
	}

	@Override
	public void generate(OriginBlockCache world, int x, int y, int z) {
		Block b = ChromaBlocks.STRUCTSHIELD.getBlockInstance();
		int ms = BlockType.STONE.metadata;
		int ml = BlockType.LIGHT.metadata;
		int mc = BlockType.CLOAK.metadata;
		this.generate1(world, x, y, z, b, ms, ml, mc);
		this.generate2(world, x, y, z, b, ms, ml, mc);
		this.generate3(world, x, y, z, b, ms, ml, mc);
	}

	private void generate1(OriginBlockCache world, int x, int y, int z, Block b, int ms, int ml, int mc) {
		world.setBlock(x+0, y+0, z+1, b, ms);
		world.setBlock(x+0, y+0, z+2, b, ms);
		world.setBlock(x+0, y+0, z+3, b, ms);
		world.setBlock(x+0, y+0, z+4, b, ms);
		world.setBlock(x+0, y+0, z+5, b, ms);
		world.setBlock(x+0, y+0, z+28, b, ms);
		world.setBlock(x+0, y+0, z+29, b, ms);
		world.setBlock(x+0, y+0, z+30, b, ms);
		world.setBlock(x+0, y+0, z+31, b, ms);
		world.setBlock(x+0, y+0, z+32, b, ms);
		world.setBlock(x+0, y+1, z+1, b, ms);
		world.setBlock(x+0, y+1, z+2, b, ms);
		world.setBlock(x+0, y+1, z+3, b, ms);
		world.setBlock(x+0, y+1, z+4, b, ms);
		world.setBlock(x+0, y+1, z+5, b, ms);
		world.setBlock(x+0, y+1, z+28, b, ms);
		world.setBlock(x+0, y+1, z+29, b, ms);
		world.setBlock(x+0, y+1, z+30, b, ms);
		world.setBlock(x+0, y+1, z+31, b, ms);
		world.setBlock(x+0, y+1, z+32, b, ms);
		world.setBlock(x+0, y+2, z+1, b, ms);
		world.setBlock(x+0, y+2, z+2, b, ms);
		world.setBlock(x+0, y+2, z+3, b, ms);
		world.setBlock(x+0, y+2, z+4, b, ms);
		world.setBlock(x+0, y+2, z+5, b, ms);
		world.setBlock(x+0, y+2, z+28, b, ms);
		world.setBlock(x+0, y+2, z+29, b, ms);
		world.setBlock(x+0, y+2, z+30, b, ms);
		world.setBlock(x+0, y+2, z+31, b, ms);
		world.setBlock(x+0, y+2, z+32, b, ms);
		world.setBlock(x+0, y+3, z+1, b, ms);
		world.setBlock(x+0, y+3, z+2, b, ms);
		world.setBlock(x+0, y+3, z+3, b, ms);
		world.setBlock(x+0, y+3, z+4, b, ms);
		world.setBlock(x+0, y+3, z+5, b, ms);
		world.setBlock(x+0, y+3, z+28, b, ms);
		world.setBlock(x+0, y+3, z+29, b, ms);
		world.setBlock(x+0, y+3, z+30, b, ms);
		world.setBlock(x+0, y+3, z+31, b, ms);
		world.setBlock(x+0, y+3, z+32, b, ms);
		world.setBlock(x+0, y+4, z+1, b, ms);
		world.setBlock(x+0, y+4, z+2, b, ms);
		world.setBlock(x+0, y+4, z+3, b, ms);
		world.setBlock(x+0, y+4, z+4, b, ms);
		world.setBlock(x+0, y+4, z+5, b, ms);
		world.setBlock(x+0, y+4, z+28, b, ms);
		world.setBlock(x+0, y+4, z+29, b, ms);
		world.setBlock(x+0, y+4, z+30, b, ms);
		world.setBlock(x+0, y+4, z+31, b, ms);
		world.setBlock(x+0, y+4, z+32, b, ms);
		world.setBlock(x+0, y+5, z+1, b, ms);
		world.setBlock(x+0, y+5, z+2, b, ms);
		world.setBlock(x+0, y+5, z+3, b, ms);
		world.setBlock(x+0, y+5, z+4, b, ms);
		world.setBlock(x+0, y+5, z+5, b, ms);
		world.setBlock(x+1, y+0, z+1, b, ms);
		world.setBlock(x+1, y+0, z+2, b, ms);
		world.setBlock(x+1, y+0, z+3, b, ms);
		world.setBlock(x+1, y+0, z+4, b, ms);
		world.setBlock(x+1, y+0, z+5, b, ms);
		world.setBlock(x+1, y+0, z+6, b, ms);
		world.setBlock(x+1, y+0, z+7, b, ms);
		world.setBlock(x+1, y+0, z+8, b, ms);
		world.setBlock(x+1, y+0, z+9, b, ms);
		world.setBlock(x+1, y+0, z+10, b, ms);
		world.setBlock(x+1, y+0, z+11, b, ms);
		world.setBlock(x+1, y+0, z+12, b, ms);
		world.setBlock(x+1, y+0, z+13, b, ms);
		world.setBlock(x+1, y+0, z+14, b, ms);
		world.setBlock(x+1, y+0, z+15, b, ms);
		world.setBlock(x+1, y+0, z+16, b, ms);
		world.setBlock(x+1, y+0, z+17, b, ms);
		world.setBlock(x+1, y+0, z+18, b, ms);
		world.setBlock(x+1, y+0, z+19, b, ms);
		world.setBlock(x+1, y+0, z+20, b, ms);
		world.setBlock(x+1, y+0, z+21, b, ms);
		world.setBlock(x+1, y+0, z+22, b, ms);
		world.setBlock(x+1, y+0, z+23, b, ms);
		world.setBlock(x+1, y+0, z+24, b, ms);
		world.setBlock(x+1, y+0, z+25, b, ms);
		world.setBlock(x+1, y+0, z+26, b, ms);
		world.setBlock(x+1, y+0, z+27, b, ms);
		world.setBlock(x+1, y+0, z+28, b, ms);
		world.setBlock(x+1, y+0, z+29, b, ms);
		world.setBlock(x+1, y+0, z+30, b, ms);
		world.setBlock(x+1, y+0, z+31, b, ms);
		world.setBlock(x+1, y+0, z+32, b, ms);
		world.setBlock(x+1, y+0, z+33, b, ms);
		world.setBlock(x+1, y+0, z+34, b, ms);
		world.setBlock(x+1, y+0, z+35, b, ms);
		world.setBlock(x+1, y+0, z+36, b, ms);
		world.setBlock(x+1, y+0, z+37, b, ms);
		world.setBlock(x+1, y+0, z+38, b, ms);
		world.setBlock(x+1, y+0, z+39, b, ms);
		world.setBlock(x+1, y+0, z+40, b, ms);
		world.setBlock(x+1, y+0, z+41, b, ms);
		world.setBlock(x+1, y+0, z+42, b, ms);
		world.setBlock(x+1, y+0, z+43, b, ms);
		world.setBlock(x+1, y+0, z+44, b, ms);
		world.setBlock(x+1, y+0, z+45, b, ms);
		world.setBlock(x+1, y+0, z+46, b, ms);
		world.setBlock(x+1, y+0, z+47, b, ms);
		world.setBlock(x+1, y+0, z+48, b, ms);
		world.setBlock(x+1, y+0, z+49, b, ms);
		world.setBlock(x+1, y+0, z+50, b, ms);
		world.setBlock(x+1, y+0, z+51, b, ms);
		world.setBlock(x+1, y+0, z+52, b, ms);
		world.setBlock(x+1, y+0, z+53, b, ms);
		world.setBlock(x+1, y+0, z+54, b, ms);
		world.setBlock(x+1, y+0, z+55, b, ms);
		world.setBlock(x+1, y+0, z+56, b, ms);
		world.setBlock(x+1, y+0, z+57, b, ms);
		world.setBlock(x+1, y+0, z+58, b, ms);
		world.setBlock(x+1, y+0, z+59, b, ms);
		world.setBlock(x+1, y+0, z+60, b, ms);
		world.setBlock(x+1, y+0, z+61, b, ms);
		world.setBlock(x+1, y+0, z+62, b, ms);
		world.setBlock(x+1, y+0, z+63, b, ms);
		world.setBlock(x+1, y+0, z+64, b, ms);
		world.setBlock(x+1, y+0, z+65, b, ms);
		world.setBlock(x+1, y+0, z+66, b, ms);
		world.setBlock(x+1, y+0, z+67, b, ms);
		world.setBlock(x+1, y+0, z+68, b, ms);
		world.setBlock(x+1, y+0, z+69, b, ms);
		world.setBlock(x+1, y+0, z+70, b, ms);
		world.setBlock(x+1, y+0, z+71, b, ms);
		world.setBlock(x+1, y+0, z+72, b, ms);
		world.setBlock(x+1, y+0, z+73, b, ms);
		world.setBlock(x+1, y+0, z+74, b, ms);
		world.setBlock(x+1, y+0, z+75, b, ms);
		world.setBlock(x+1, y+0, z+76, b, ms);
		world.setBlock(x+1, y+0, z+77, b, ms);
		world.setBlock(x+1, y+0, z+78, b, ms);
		world.setBlock(x+1, y+1, z+1, b, ms);
		world.setBlock(x+1, y+1, z+6, b, ms);
		world.setBlock(x+1, y+1, z+7, b, ms);
		world.setBlock(x+1, y+1, z+8, b, ms);
		world.setBlock(x+1, y+1, z+9, b, ms);
		world.setBlock(x+1, y+1, z+10, b, ms);
		world.setBlock(x+1, y+1, z+11, b, ms);
		world.setBlock(x+1, y+1, z+12, b, ms);
		world.setBlock(x+1, y+1, z+13, b, ms);
		world.setBlock(x+1, y+1, z+14, b, ms);
		world.setBlock(x+1, y+1, z+15, b, ms);
		world.setBlock(x+1, y+1, z+16, b, ms);
		world.setBlock(x+1, y+1, z+17, b, ms);
		world.setBlock(x+1, y+1, z+18, b, ms);
		world.setBlock(x+1, y+1, z+19, b, ms);
		world.setBlock(x+1, y+1, z+20, b, ms);
		world.setBlock(x+1, y+1, z+21, b, ms);
		world.setBlock(x+1, y+1, z+22, b, ms);
		world.setBlock(x+1, y+1, z+23, b, ms);
		world.setBlock(x+1, y+1, z+24, b, ms);
		world.setBlock(x+1, y+1, z+25, b, ms);
		world.setBlock(x+1, y+1, z+26, b, ms);
		world.setBlock(x+1, y+1, z+27, b, ms);
		world.setBlock(x+1, y+1, z+28, b, ms);
		world.setBlock(x+1, y+1, z+32, b, ms);
		world.setBlock(x+1, y+1, z+33, b, ms);
		world.setBlock(x+1, y+1, z+34, b, ms);
		world.setBlock(x+1, y+1, z+35, b, ms);
		world.setBlock(x+1, y+1, z+36, b, ms);
		world.setBlock(x+1, y+1, z+37, b, ms);
		world.setBlock(x+1, y+1, z+38, b, ms);
		world.setBlock(x+1, y+1, z+39, b, ms);
		world.setBlock(x+1, y+1, z+40, b, ms);
		world.setBlock(x+1, y+1, z+41, b, ms);
		world.setBlock(x+1, y+1, z+42, b, ms);
		world.setBlock(x+1, y+1, z+43, b, ms);
		world.setBlock(x+1, y+1, z+44, b, ms);
		world.setBlock(x+1, y+1, z+45, b, ms);
		world.setBlock(x+1, y+1, z+46, b, ms);
		world.setBlock(x+1, y+1, z+47, b, ms);
		world.setBlock(x+1, y+1, z+48, b, ms);
		world.setBlock(x+1, y+1, z+49, b, ms);
		world.setBlock(x+1, y+1, z+50, b, ms);
		world.setBlock(x+1, y+1, z+51, b, ms);
		world.setBlock(x+1, y+1, z+52, b, ms);
		world.setBlock(x+1, y+1, z+53, b, ms);
		world.setBlock(x+1, y+1, z+54, b, ms);
		world.setBlock(x+1, y+1, z+55, b, ms);
		world.setBlock(x+1, y+1, z+56, b, ms);
		world.setBlock(x+1, y+1, z+57, b, ms);
		world.setBlock(x+1, y+1, z+58, b, ms);
		world.setBlock(x+1, y+1, z+59, b, ms);
		world.setBlock(x+1, y+1, z+60, b, ms);
		world.setBlock(x+1, y+1, z+61, b, ms);
		world.setBlock(x+1, y+1, z+62, b, ms);
		world.setBlock(x+1, y+1, z+63, b, ms);
		world.setBlock(x+1, y+1, z+64, b, ms);
		world.setBlock(x+1, y+1, z+65, b, ms);
		world.setBlock(x+1, y+1, z+66, b, ms);
		world.setBlock(x+1, y+1, z+67, b, ms);
		world.setBlock(x+1, y+1, z+68, b, ms);
		world.setBlock(x+1, y+1, z+69, b, ms);
		world.setBlock(x+1, y+1, z+70, b, ms);
		world.setBlock(x+1, y+1, z+71, b, ms);
		world.setBlock(x+1, y+1, z+72, b, ms);
		world.setBlock(x+1, y+1, z+73, b, ms);
		world.setBlock(x+1, y+1, z+74, b, ms);
		world.setBlock(x+1, y+1, z+75, b, ms);
		world.setBlock(x+1, y+1, z+76, b, ms);
		world.setBlock(x+1, y+1, z+77, b, ms);
		world.setBlock(x+1, y+1, z+78, b, ms);
		world.setBlock(x+1, y+2, z+1, b, ml);
		world.setBlock(x+1, y+2, z+6, b, ms);
		world.setBlock(x+1, y+2, z+7, b, ms);
		world.setBlock(x+1, y+2, z+8, b, ms);
		world.setBlock(x+1, y+2, z+9, b, ms);
		world.setBlock(x+1, y+2, z+10, b, ms);
		world.setBlock(x+1, y+2, z+11, b, ml);
		world.setBlock(x+1, y+2, z+12, b, ms);
		world.setBlock(x+1, y+2, z+13, b, ms);
		world.setBlock(x+1, y+2, z+14, b, ms);
		world.setBlock(x+1, y+2, z+15, b, ms);
		world.setBlock(x+1, y+2, z+16, b, ms);
		world.setBlock(x+1, y+2, z+17, b, ml);
		world.setBlock(x+1, y+2, z+18, b, ms);
		world.setBlock(x+1, y+2, z+19, b, ms);
		world.setBlock(x+1, y+2, z+20, b, ms);
		world.setBlock(x+1, y+2, z+21, b, ms);
		world.setBlock(x+1, y+2, z+22, b, ms);
		world.setBlock(x+1, y+2, z+23, b, ms);
		world.setBlock(x+1, y+2, z+24, b, ms);
		world.setBlock(x+1, y+2, z+25, b, ms);
		world.setBlock(x+1, y+2, z+26, b, ms);
		world.setBlock(x+1, y+2, z+27, b, ms);
		world.setBlock(x+1, y+2, z+28, b, ms);
		world.setBlock(x+1, y+2, z+32, b, ml);
		world.setBlock(x+1, y+2, z+33, b, ms);
		world.setBlock(x+1, y+2, z+34, b, ms);
		world.setBlock(x+1, y+2, z+35, b, ms);
		world.setBlock(x+1, y+2, z+36, b, ms);
		world.setBlock(x+1, y+2, z+37, b, ml);
		world.setBlock(x+1, y+2, z+38, b, ms);
		world.setBlock(x+1, y+2, z+39, b, ms);
		world.setBlock(x+1, y+2, z+40, b, ms);
		world.setBlock(x+1, y+2, z+41, b, ms);
		world.setBlock(x+1, y+2, z+42, b, ms);
		world.setBlock(x+1, y+2, z+43, b, ml);
		world.setBlock(x+1, y+2, z+44, b, ms);
		world.setBlock(x+1, y+2, z+45, b, ms);
		world.setBlock(x+1, y+2, z+46, b, ms);
		world.setBlock(x+1, y+2, z+47, b, ms);
		world.setBlock(x+1, y+2, z+48, b, ms);
		world.setBlock(x+1, y+2, z+49, b, ms);
		world.setBlock(x+1, y+2, z+50, b, ms);
		world.setBlock(x+1, y+2, z+51, b, ms);
		world.setBlock(x+1, y+2, z+52, b, ms);
		world.setBlock(x+1, y+2, z+53, b, ms);
		world.setBlock(x+1, y+2, z+54, b, ml);
		world.setBlock(x+1, y+2, z+55, b, ms);
		world.setBlock(x+1, y+2, z+56, b, ms);
		world.setBlock(x+1, y+2, z+57, b, ms);
		world.setBlock(x+1, y+2, z+58, b, ms);
		world.setBlock(x+1, y+2, z+59, b, ms);
		world.setBlock(x+1, y+2, z+60, b, ml);
		world.setBlock(x+1, y+2, z+61, b, ms);
		world.setBlock(x+1, y+2, z+62, b, ms);
		world.setBlock(x+1, y+2, z+63, b, ms);
		world.setBlock(x+1, y+2, z+64, b, ms);
		world.setBlock(x+1, y+2, z+65, b, ms);
		world.setBlock(x+1, y+2, z+66, b, ml);
		world.setBlock(x+1, y+2, z+67, b, ms);
		world.setBlock(x+1, y+2, z+68, b, ms);
		world.setBlock(x+1, y+2, z+69, b, ms);
		world.setBlock(x+1, y+2, z+70, b, ms);
		world.setBlock(x+1, y+2, z+71, b, ms);
		world.setBlock(x+1, y+2, z+72, b, ms);
		world.setBlock(x+1, y+2, z+73, b, ms);
		world.setBlock(x+1, y+2, z+74, b, ms);
		world.setBlock(x+1, y+2, z+75, b, ml);
		world.setBlock(x+1, y+2, z+76, b, ms);
		world.setBlock(x+1, y+2, z+77, b, ms);
		world.setBlock(x+1, y+2, z+78, b, ms);
		world.setBlock(x+1, y+3, z+1, b, ms);
		world.setBlock(x+1, y+3, z+6, b, ms);
		world.setBlock(x+1, y+3, z+7, b, ms);
		world.setBlock(x+1, y+3, z+8, b, ms);
		world.setBlock(x+1, y+3, z+9, b, ms);
		world.setBlock(x+1, y+3, z+10, b, ms);
		world.setBlock(x+1, y+3, z+11, b, ms);
		world.setBlock(x+1, y+3, z+12, b, ms);
		world.setBlock(x+1, y+3, z+13, b, ms);
		world.setBlock(x+1, y+3, z+14, b, ms);
		world.setBlock(x+1, y+3, z+15, b, ms);
		world.setBlock(x+1, y+3, z+16, b, ms);
		world.setBlock(x+1, y+3, z+17, b, ms);
		world.setBlock(x+1, y+3, z+18, b, ms);
		world.setBlock(x+1, y+3, z+19, b, ms);
		world.setBlock(x+1, y+3, z+20, b, ms);
		world.setBlock(x+1, y+3, z+21, b, ms);
		world.setBlock(x+1, y+3, z+22, b, ms);
		world.setBlock(x+1, y+3, z+23, b, ms);
		world.setBlock(x+1, y+3, z+24, b, ms);
		world.setBlock(x+1, y+3, z+25, b, ms);
		world.setBlock(x+1, y+3, z+26, b, ms);
		world.setBlock(x+1, y+3, z+27, b, ms);
		world.setBlock(x+1, y+3, z+28, b, ms);
		world.setBlock(x+1, y+3, z+32, b, ms);
		world.setBlock(x+1, y+3, z+33, b, ms);
		world.setBlock(x+1, y+3, z+34, b, ms);
		world.setBlock(x+1, y+3, z+35, b, ms);
		world.setBlock(x+1, y+3, z+36, b, ms);
		world.setBlock(x+1, y+3, z+37, b, ms);
		world.setBlock(x+1, y+3, z+38, b, ms);
		world.setBlock(x+1, y+3, z+39, b, ms);
		world.setBlock(x+1, y+3, z+40, b, ms);
		world.setBlock(x+1, y+3, z+41, b, ms);
		world.setBlock(x+1, y+3, z+42, b, ms);
		world.setBlock(x+1, y+3, z+43, b, ms);
		world.setBlock(x+1, y+3, z+44, b, ms);
		world.setBlock(x+1, y+3, z+45, b, ms);
		world.setBlock(x+1, y+3, z+46, b, ms);
		world.setBlock(x+1, y+3, z+47, b, ms);
		world.setBlock(x+1, y+3, z+48, b, ms);
		world.setBlock(x+1, y+3, z+49, b, ms);
		world.setBlock(x+1, y+3, z+50, b, ms);
		world.setBlock(x+1, y+3, z+51, b, ms);
		world.setBlock(x+1, y+3, z+52, b, ms);
		world.setBlock(x+1, y+3, z+53, b, ms);
		world.setBlock(x+1, y+3, z+54, b, ms);
		world.setBlock(x+1, y+3, z+55, b, ms);
		world.setBlock(x+1, y+3, z+56, b, ms);
		world.setBlock(x+1, y+3, z+57, b, ms);
		world.setBlock(x+1, y+3, z+58, b, ms);
		world.setBlock(x+1, y+3, z+59, b, ms);
		world.setBlock(x+1, y+3, z+60, b, ms);
		world.setBlock(x+1, y+3, z+61, b, ms);
		world.setBlock(x+1, y+3, z+62, b, ms);
		world.setBlock(x+1, y+3, z+63, b, ms);
		world.setBlock(x+1, y+3, z+64, b, ms);
		world.setBlock(x+1, y+3, z+65, b, ms);
		world.setBlock(x+1, y+3, z+66, b, ms);
		world.setBlock(x+1, y+3, z+67, b, ms);
		world.setBlock(x+1, y+3, z+68, b, ms);
		world.setBlock(x+1, y+3, z+69, b, ms);
		world.setBlock(x+1, y+3, z+70, b, ms);
		world.setBlock(x+1, y+3, z+71, b, ms);
		world.setBlock(x+1, y+3, z+72, b, ms);
		world.setBlock(x+1, y+3, z+73, b, ms);
		world.setBlock(x+1, y+3, z+74, b, ms);
		world.setBlock(x+1, y+3, z+75, b, ms);
		world.setBlock(x+1, y+3, z+76, b, ms);
		world.setBlock(x+1, y+3, z+77, b, ms);
		world.setBlock(x+1, y+3, z+78, b, ms);
		world.setBlock(x+1, y+4, z+1, b, ms);
		world.setBlock(x+1, y+4, z+6, b, ms);
		world.setBlock(x+1, y+4, z+7, b, ms);
		world.setBlock(x+1, y+4, z+8, b, ms);
		world.setBlock(x+1, y+4, z+9, b, ms);
		world.setBlock(x+1, y+4, z+10, b, ms);
		world.setBlock(x+1, y+4, z+11, b, ms);
		world.setBlock(x+1, y+4, z+12, b, ms);
		world.setBlock(x+1, y+4, z+13, b, ms);
		world.setBlock(x+1, y+4, z+14, b, ms);
		world.setBlock(x+1, y+4, z+15, b, ms);
		world.setBlock(x+1, y+4, z+16, b, ms);
		world.setBlock(x+1, y+4, z+17, b, ms);
		world.setBlock(x+1, y+4, z+18, b, ms);
		world.setBlock(x+1, y+4, z+19, b, ms);
		world.setBlock(x+1, y+4, z+20, b, ms);
		world.setBlock(x+1, y+4, z+21, b, ms);
		world.setBlock(x+1, y+4, z+22, b, ms);
		world.setBlock(x+1, y+4, z+23, b, ms);
		world.setBlock(x+1, y+4, z+24, b, ms);
		world.setBlock(x+1, y+4, z+25, b, ms);
		world.setBlock(x+1, y+4, z+26, b, ms);
		world.setBlock(x+1, y+4, z+27, b, ms);
		world.setBlock(x+1, y+4, z+28, b, ms);
		world.setBlock(x+1, y+4, z+32, b, ms);
		world.setBlock(x+1, y+4, z+33, b, ms);
		world.setBlock(x+1, y+4, z+34, b, ms);
		world.setBlock(x+1, y+4, z+35, b, ms);
		world.setBlock(x+1, y+4, z+36, b, ms);
		world.setBlock(x+1, y+4, z+37, b, ms);
		world.setBlock(x+1, y+4, z+38, b, ms);
		world.setBlock(x+1, y+4, z+39, b, ms);
		world.setBlock(x+1, y+4, z+40, b, ms);
		world.setBlock(x+1, y+4, z+41, b, ms);
		world.setBlock(x+1, y+4, z+42, b, ms);
		world.setBlock(x+1, y+4, z+43, b, ms);
		world.setBlock(x+1, y+4, z+44, b, ms);
		world.setBlock(x+1, y+4, z+45, b, ms);
		world.setBlock(x+1, y+4, z+46, b, ms);
		world.setBlock(x+1, y+4, z+47, b, ms);
		world.setBlock(x+1, y+4, z+48, b, ms);
		world.setBlock(x+1, y+4, z+49, b, ms);
		world.setBlock(x+1, y+4, z+50, b, ms);
		world.setBlock(x+1, y+4, z+51, b, ms);
		world.setBlock(x+1, y+4, z+52, b, ms);
		world.setBlock(x+1, y+4, z+53, b, ms);
		world.setBlock(x+1, y+4, z+54, b, ms);
		world.setBlock(x+1, y+4, z+55, b, ms);
		world.setBlock(x+1, y+4, z+56, b, ms);
		world.setBlock(x+1, y+4, z+57, b, ms);
		world.setBlock(x+1, y+4, z+58, b, ms);
		world.setBlock(x+1, y+4, z+59, b, ms);
		world.setBlock(x+1, y+4, z+60, b, ms);
		world.setBlock(x+1, y+4, z+61, b, ms);
		world.setBlock(x+1, y+4, z+62, b, ms);
		world.setBlock(x+1, y+4, z+63, b, ms);
		world.setBlock(x+1, y+4, z+64, b, ms);
		world.setBlock(x+1, y+4, z+65, b, ms);
		world.setBlock(x+1, y+4, z+66, b, ms);
		world.setBlock(x+1, y+4, z+67, b, ms);
		world.setBlock(x+1, y+4, z+68, b, ms);
		world.setBlock(x+1, y+4, z+69, b, ms);
		world.setBlock(x+1, y+4, z+70, b, ms);
		world.setBlock(x+1, y+4, z+71, b, ms);
		world.setBlock(x+1, y+4, z+72, b, ms);
		world.setBlock(x+1, y+4, z+73, b, ms);
		world.setBlock(x+1, y+4, z+74, b, ms);
		world.setBlock(x+1, y+4, z+75, b, ms);
		world.setBlock(x+1, y+4, z+76, b, ms);
		world.setBlock(x+1, y+4, z+77, b, ms);
		world.setBlock(x+1, y+4, z+78, b, ms);
		world.setBlock(x+1, y+5, z+1, b, ms);
		world.setBlock(x+1, y+5, z+2, b, ms);
		world.setBlock(x+1, y+5, z+3, b, ms);
		world.setBlock(x+1, y+5, z+4, b, ms);
		world.setBlock(x+1, y+5, z+5, b, ms);
		world.setBlock(x+1, y+5, z+6, b, ms);
		world.setBlock(x+1, y+5, z+28, b, ms);
		world.setBlock(x+1, y+5, z+29, b, ms);
		world.setBlock(x+1, y+5, z+30, b, ms);
		world.setBlock(x+1, y+5, z+31, b, ms);
		world.setBlock(x+1, y+5, z+32, b, ms);
		world.setBlock(x+1, y+5, z+33, b, ms);
		world.setBlock(x+1, y+5, z+34, b, ms);
		world.setBlock(x+1, y+5, z+35, b, ms);
		world.setBlock(x+1, y+5, z+36, b, ms);
		world.setBlock(x+1, y+5, z+37, b, ms);
		world.setBlock(x+1, y+5, z+38, b, ms);
		world.setBlock(x+1, y+5, z+39, b, ms);
		world.setBlock(x+1, y+5, z+40, b, ms);
		world.setBlock(x+1, y+5, z+41, b, ms);
		world.setBlock(x+1, y+5, z+42, b, ms);
		world.setBlock(x+1, y+5, z+43, b, ms);
		world.setBlock(x+1, y+5, z+44, b, ms);
		world.setBlock(x+1, y+5, z+45, b, ms);
		world.setBlock(x+1, y+5, z+46, b, ms);
		world.setBlock(x+1, y+5, z+47, b, ms);
		world.setBlock(x+1, y+5, z+48, b, ms);
		world.setBlock(x+1, y+5, z+49, b, ms);
		world.setBlock(x+1, y+5, z+50, b, ms);
		world.setBlock(x+1, y+5, z+51, b, ms);
		world.setBlock(x+1, y+5, z+52, b, ms);
		world.setBlock(x+1, y+5, z+53, b, ms);
		world.setBlock(x+1, y+5, z+54, b, ms);
		world.setBlock(x+1, y+5, z+55, b, ms);
		world.setBlock(x+1, y+5, z+56, b, ms);
		world.setBlock(x+1, y+5, z+57, b, ms);
		world.setBlock(x+1, y+5, z+58, b, ms);
		world.setBlock(x+1, y+5, z+59, b, ms);
		world.setBlock(x+1, y+5, z+60, b, ms);
		world.setBlock(x+1, y+5, z+61, b, ms);
		world.setBlock(x+1, y+5, z+62, b, ms);
		world.setBlock(x+1, y+5, z+63, b, ms);
		world.setBlock(x+1, y+5, z+64, b, ms);
		world.setBlock(x+1, y+5, z+65, b, ms);
		world.setBlock(x+1, y+5, z+66, b, ms);
		world.setBlock(x+1, y+5, z+67, b, ms);
		world.setBlock(x+1, y+5, z+68, b, ms);
		world.setBlock(x+1, y+5, z+69, b, ms);
		world.setBlock(x+1, y+5, z+70, b, ms);
		world.setBlock(x+1, y+5, z+71, b, ms);
		world.setBlock(x+1, y+5, z+72, b, ms);
		world.setBlock(x+1, y+5, z+73, b, ms);
		world.setBlock(x+1, y+5, z+74, b, ms);
		world.setBlock(x+1, y+5, z+75, b, ms);
		world.setBlock(x+1, y+5, z+76, b, ms);
		world.setBlock(x+1, y+5, z+77, b, ms);
		world.setBlock(x+1, y+5, z+78, b, ms);
		world.setBlock(x+2, y+0, z+0, b, ms);
		world.setBlock(x+2, y+0, z+1, b, ms);
		world.setBlock(x+2, y+0, z+2, b, ms);
		world.setBlock(x+2, y+0, z+3, b, ms);
		this.generateRune(x+2, y+0, z+4, LockColor.RED);
		world.setBlock(x+2, y+0, z+5, b, ms);
		world.setBlock(x+2, y+0, z+6, b, ms);
		world.setBlock(x+2, y+0, z+7, b, ms);
		world.setBlock(x+2, y+0, z+8, b, ms);
		world.setBlock(x+2, y+0, z+9, b, ms);
		world.setBlock(x+2, y+0, z+10, b, ms);
		world.setBlock(x+2, y+0, z+11, b, ms);
		world.setBlock(x+2, y+0, z+12, b, ms);
		world.setBlock(x+2, y+0, z+13, b, ms);
		world.setBlock(x+2, y+0, z+14, b, ms);
		world.setBlock(x+2, y+0, z+15, b, ms);
		world.setBlock(x+2, y+0, z+16, b, ms);
		world.setBlock(x+2, y+0, z+17, b, ms);
		world.setBlock(x+2, y+0, z+18, b, ms);
		world.setBlock(x+2, y+0, z+19, b, ms);
		world.setBlock(x+2, y+0, z+20, b, ms);
		world.setBlock(x+2, y+0, z+21, b, ms);
		world.setBlock(x+2, y+0, z+22, b, ms);
		world.setBlock(x+2, y+0, z+23, b, ms);
		world.setBlock(x+2, y+0, z+24, b, ms);
		world.setBlock(x+2, y+0, z+25, b, ms);
		world.setBlock(x+2, y+0, z+26, b, ms);
		world.setBlock(x+2, y+0, z+27, b, ms);
		world.setBlock(x+2, y+0, z+28, b, ms);
		world.setBlock(x+2, y+0, z+29, b, ms);
		this.generateRune(x+2, y+0, z+30, LockColor.PURPLE);
		world.setBlock(x+2, y+0, z+31, b, ms);
		world.setBlock(x+2, y+0, z+32, b, ms);
		world.setBlock(x+2, y+0, z+33, b, ms);
		world.setBlock(x+2, y+0, z+34, b, ms);
		world.setBlock(x+2, y+0, z+35, b, ms);
		world.setBlock(x+2, y+0, z+36, b, ms);
		world.setBlock(x+2, y+0, z+37, b, ms);
		world.setBlock(x+2, y+0, z+38, b, ms);
		world.setBlock(x+2, y+0, z+39, b, ms);
		world.setBlock(x+2, y+0, z+40, b, ms);
		world.setBlock(x+2, y+0, z+41, b, ms);
		world.setBlock(x+2, y+0, z+42, b, ms);
		world.setBlock(x+2, y+0, z+43, b, ms);
		world.setBlock(x+2, y+0, z+44, b, ms);
		world.setBlock(x+2, y+0, z+45, b, ms);
		world.setBlock(x+2, y+0, z+46, b, ms);
		world.setBlock(x+2, y+0, z+47, b, ms);
		world.setBlock(x+2, y+0, z+48, b, ms);
		world.setBlock(x+2, y+0, z+49, b, ms);
		world.setBlock(x+2, y+0, z+50, b, ms);
		world.setBlock(x+2, y+0, z+51, b, ms);
		world.setBlock(x+2, y+0, z+52, b, ms);
		world.setBlock(x+2, y+0, z+53, b, ms);
		world.setBlock(x+2, y+0, z+54, b, ms);
		world.setBlock(x+2, y+0, z+55, b, ms);
		world.setBlock(x+2, y+0, z+56, b, ms);
		world.setBlock(x+2, y+0, z+57, b, ms);
		world.setBlock(x+2, y+0, z+58, b, ms);
		world.setBlock(x+2, y+0, z+59, b, ms);
		world.setBlock(x+2, y+0, z+60, b, ms);
		world.setBlock(x+2, y+0, z+61, b, ms);
		world.setBlock(x+2, y+0, z+62, b, ms);
		world.setBlock(x+2, y+0, z+63, b, ms);
		world.setBlock(x+2, y+0, z+64, b, ms);
		world.setBlock(x+2, y+0, z+65, b, ms);
		world.setBlock(x+2, y+0, z+66, b, ms);
		world.setBlock(x+2, y+0, z+67, b, ms);
		world.setBlock(x+2, y+0, z+68, b, ms);
		world.setBlock(x+2, y+0, z+69, b, ms);
		world.setBlock(x+2, y+0, z+70, b, ms);
		world.setBlock(x+2, y+0, z+71, b, ms);
		world.setBlock(x+2, y+0, z+72, b, ms);
		world.setBlock(x+2, y+0, z+73, b, ms);
		world.setBlock(x+2, y+0, z+74, b, ms);
		world.setBlock(x+2, y+0, z+75, b, ms);
		world.setBlock(x+2, y+0, z+76, b, ms);
		world.setBlock(x+2, y+0, z+77, b, ms);
		world.setBlock(x+2, y+0, z+78, b, ms);
		world.setBlock(x+2, y+0, z+79, b, ms);
		world.setBlock(x+2, y+0, z+80, b, ms);
		world.setBlock(x+2, y+1, z+0, b, ms);
		world.setBlock(x+2, y+1, z+7, b, ms);
		world.setBlock(x+2, y+1, z+8, b, ms);
		world.setBlock(x+2, y+1, z+9, b, ms);
		world.setBlock(x+2, y+1, z+13, b, ms);
		world.setBlock(x+2, y+1, z+14, b, ms);
		world.setBlock(x+2, y+1, z+15, b, ms);
		this.generateKey(x+2, y+1, z+17);
		world.setBlock(x+2, y+1, z+19, b, ms);
		world.setBlock(x+2, y+1, z+20, b, ms);
		world.setBlock(x+2, y+1, z+21, b, ms);
		world.setBlock(x+2, y+1, z+25, b, ms);
		world.setBlock(x+2, y+1, z+26, b, ms);
		world.setBlock(x+2, y+1, z+27, b, ms);
		world.setBlock(x+2, y+1, z+33, b, ms);
		world.setBlock(x+2, y+1, z+34, b, ms);
		world.setBlock(x+2, y+1, z+35, b, ms);
		world.setBlock(x+2, y+1, z+39, b, ms);
		world.setBlock(x+2, y+1, z+40, b, ms);
		world.setBlock(x+2, y+1, z+41, b, ms);
		world.setBlock(x+2, y+1, z+45, b, ms);
		world.setBlock(x+2, y+1, z+46, b, ms);
		world.setBlock(x+2, y+1, z+47, b, ms);
		world.setBlock(x+2, y+1, z+56, b, ms);
		world.setBlock(x+2, y+1, z+57, b, ms);
		world.setBlock(x+2, y+1, z+58, b, ms);
		world.setBlock(x+2, y+1, z+62, b, ms);
		world.setBlock(x+2, y+1, z+63, b, ms);
		world.setBlock(x+2, y+1, z+64, b, ms);
		world.setBlock(x+2, y+1, z+68, b, ms);
		world.setBlock(x+2, y+1, z+69, b, ms);
		world.setBlock(x+2, y+1, z+70, b, ms);
		world.setBlock(x+2, y+1, z+78, b, ms);
		world.setBlock(x+2, y+1, z+79, b, ms);
		world.setBlock(x+2, y+1, z+80, b, ms);
		world.setBlock(x+2, y+2, z+0, b, ms);
		world.setBlock(x+2, y+2, z+7, b, ms);
		world.setBlock(x+2, y+2, z+8, b, ms);
		world.setBlock(x+2, y+2, z+9, b, ms);
		world.setBlock(x+2, y+2, z+13, b, ms);
		world.setBlock(x+2, y+2, z+14, b, ms);
		world.setBlock(x+2, y+2, z+15, b, ms);
		world.setBlock(x+2, y+2, z+19, b, ms);
		world.setBlock(x+2, y+2, z+20, b, ms);
		world.setBlock(x+2, y+2, z+21, b, ms);
		world.setBlock(x+2, y+2, z+25, b, ms);
		world.setBlock(x+2, y+2, z+26, b, ms);
		world.setBlock(x+2, y+2, z+27, b, ms);
		world.setBlock(x+2, y+2, z+33, b, ms);
		world.setBlock(x+2, y+2, z+34, b, ms);
		world.setBlock(x+2, y+2, z+35, b, ms);
		world.setBlock(x+2, y+2, z+39, b, ms);
		world.setBlock(x+2, y+2, z+40, b, ms);
		world.setBlock(x+2, y+2, z+41, b, ms);
		world.setBlock(x+2, y+2, z+45, b, ms);
		world.setBlock(x+2, y+2, z+46, b, ms);
		world.setBlock(x+2, y+2, z+47, b, ms);
		world.setBlock(x+2, y+2, z+56, b, ms);
		world.setBlock(x+2, y+2, z+57, b, ms);
		world.setBlock(x+2, y+2, z+58, b, ms);
		world.setBlock(x+2, y+2, z+62, b, ms);
		world.setBlock(x+2, y+2, z+63, b, ms);
		world.setBlock(x+2, y+2, z+64, b, ms);
		world.setBlock(x+2, y+2, z+68, b, ms);
		world.setBlock(x+2, y+2, z+69, b, ms);
		world.setBlock(x+2, y+2, z+70, b, ms);
		world.setBlock(x+2, y+2, z+78, b, ms);
		world.setBlock(x+2, y+2, z+79, b, ms);
		world.setBlock(x+2, y+2, z+80, b, ms);
		world.setBlock(x+2, y+3, z+0, b, ms);
		world.setBlock(x+2, y+3, z+7, b, ms);
		world.setBlock(x+2, y+3, z+8, b, ms);
		world.setBlock(x+2, y+3, z+9, b, ms);
		world.setBlock(x+2, y+3, z+13, b, ms);
		world.setBlock(x+2, y+3, z+14, b, ms);
		world.setBlock(x+2, y+3, z+15, b, ms);
		world.setBlock(x+2, y+3, z+19, b, ms);
		world.setBlock(x+2, y+3, z+20, b, ms);
		world.setBlock(x+2, y+3, z+21, b, ms);
		world.setBlock(x+2, y+3, z+25, b, ms);
		world.setBlock(x+2, y+3, z+26, b, ms);
		world.setBlock(x+2, y+3, z+27, b, ms);
		world.setBlock(x+2, y+3, z+33, b, ms);
		world.setBlock(x+2, y+3, z+34, b, ms);
		world.setBlock(x+2, y+3, z+35, b, ms);
		world.setBlock(x+2, y+3, z+39, b, ms);
		world.setBlock(x+2, y+3, z+40, b, ms);
		world.setBlock(x+2, y+3, z+41, b, ms);
		world.setBlock(x+2, y+3, z+45, b, ms);
		world.setBlock(x+2, y+3, z+46, b, ms);
		world.setBlock(x+2, y+3, z+47, b, ms);
		world.setBlock(x+2, y+3, z+56, b, ms);
		world.setBlock(x+2, y+3, z+57, b, ms);
		world.setBlock(x+2, y+3, z+58, b, ms);
		world.setBlock(x+2, y+3, z+62, b, ms);
		world.setBlock(x+2, y+3, z+63, b, ms);
		world.setBlock(x+2, y+3, z+64, b, ms);
		world.setBlock(x+2, y+3, z+68, b, ms);
		world.setBlock(x+2, y+3, z+69, b, ms);
		world.setBlock(x+2, y+3, z+70, b, ms);
		world.setBlock(x+2, y+3, z+78, b, ms);
		world.setBlock(x+2, y+3, z+79, b, ms);
		world.setBlock(x+2, y+3, z+80, b, ms);
		world.setBlock(x+2, y+4, z+0, b, ms);
		world.setBlock(x+2, y+4, z+7, b, ms);
		world.setBlock(x+2, y+4, z+8, b, ms);
		world.setBlock(x+2, y+4, z+9, b, ms);
		world.setBlock(x+2, y+4, z+10, b, ms);
		world.setBlock(x+2, y+4, z+11, b, ms);
		world.setBlock(x+2, y+4, z+12, b, ms);
		world.setBlock(x+2, y+4, z+13, b, ms);
		world.setBlock(x+2, y+4, z+14, b, ms);
		world.setBlock(x+2, y+4, z+15, b, ms);
		world.setBlock(x+2, y+4, z+19, b, ms);
		world.setBlock(x+2, y+4, z+20, b, ms);
		world.setBlock(x+2, y+4, z+21, b, ms);
		world.setBlock(x+2, y+4, z+25, b, ms);
		world.setBlock(x+2, y+4, z+26, b, ms);
		world.setBlock(x+2, y+4, z+27, b, ms);
		world.setBlock(x+2, y+4, z+33, b, ms);
		world.setBlock(x+2, y+4, z+34, b, ms);
		world.setBlock(x+2, y+4, z+35, b, ms);
		world.setBlock(x+2, y+4, z+39, b, ms);
		world.setBlock(x+2, y+4, z+40, b, ms);
		world.setBlock(x+2, y+4, z+41, b, ms);
		world.setBlock(x+2, y+4, z+45, b, ms);
		world.setBlock(x+2, y+4, z+46, b, ms);
		world.setBlock(x+2, y+4, z+47, b, ms);
		world.setBlock(x+2, y+4, z+56, b, ms);
		world.setBlock(x+2, y+4, z+57, b, ms);
		world.setBlock(x+2, y+4, z+58, b, ms);
		world.setBlock(x+2, y+4, z+62, b, ms);
		world.setBlock(x+2, y+4, z+63, b, ms);
		world.setBlock(x+2, y+4, z+64, b, ms);
		world.setBlock(x+2, y+4, z+68, b, ms);
		world.setBlock(x+2, y+4, z+69, b, ms);
		world.setBlock(x+2, y+4, z+70, b, ms);
		world.setBlock(x+2, y+4, z+78, b, ms);
		world.setBlock(x+2, y+4, z+79, b, ms);
		world.setBlock(x+2, y+4, z+80, b, ms);
		world.setBlock(x+2, y+5, z+1, b, ms);
		world.setBlock(x+2, y+5, z+2, b, ms);
		world.setBlock(x+2, y+5, z+3, b, ms);
		world.setBlock(x+2, y+5, z+4, b, ms);
		world.setBlock(x+2, y+5, z+5, b, ms);
		world.setBlock(x+2, y+5, z+6, b, ms);
		world.setBlock(x+2, y+5, z+7, b, ms);
		world.setBlock(x+2, y+5, z+8, b, ms);
		world.setBlock(x+2, y+5, z+9, b, ms);
		world.setBlock(x+2, y+5, z+10, b, ms);
		world.setBlock(x+2, y+5, z+11, b, ms);
		world.setBlock(x+2, y+5, z+12, b, ms);
		world.setBlock(x+2, y+5, z+13, b, ms);
		world.setBlock(x+2, y+5, z+14, b, ms);
		world.setBlock(x+2, y+5, z+15, b, ms);
		world.setBlock(x+2, y+5, z+16, b, ms);
		world.setBlock(x+2, y+5, z+17, b, ms);
		world.setBlock(x+2, y+5, z+18, b, ms);
		world.setBlock(x+2, y+5, z+19, b, ms);
		world.setBlock(x+2, y+5, z+20, b, ms);
		world.setBlock(x+2, y+5, z+21, b, ms);
		world.setBlock(x+2, y+5, z+22, b, ms);
		world.setBlock(x+2, y+5, z+23, b, ms);
		world.setBlock(x+2, y+5, z+24, b, ms);
		world.setBlock(x+2, y+5, z+25, b, ms);
		world.setBlock(x+2, y+5, z+26, b, ms);
		world.setBlock(x+2, y+5, z+27, b, ms);
		world.setBlock(x+2, y+5, z+28, b, ms);
		world.setBlock(x+2, y+5, z+29, b, ms);
		world.setBlock(x+2, y+5, z+30, b, ms);
		world.setBlock(x+2, y+5, z+31, b, ms);
		world.setBlock(x+2, y+5, z+32, b, ms);
		world.setBlock(x+2, y+5, z+33, b, ms);
		world.setBlock(x+2, y+5, z+34, b, ms);
		world.setBlock(x+2, y+5, z+35, b, ms);
		world.setBlock(x+2, y+5, z+36, b, ms);
		world.setBlock(x+2, y+5, z+37, b, ms);
		world.setBlock(x+2, y+5, z+38, b, ms);
		world.setBlock(x+2, y+5, z+39, b, ms);
		world.setBlock(x+2, y+5, z+40, b, ms);
		world.setBlock(x+2, y+5, z+41, b, ms);
		world.setBlock(x+2, y+5, z+42, b, ms);
		world.setBlock(x+2, y+5, z+43, b, ms);
		world.setBlock(x+2, y+5, z+44, b, ms);
		world.setBlock(x+2, y+5, z+45, b, ms);
		world.setBlock(x+2, y+5, z+46, b, ms);
		world.setBlock(x+2, y+5, z+47, b, ms);
		world.setBlock(x+2, y+5, z+48, b, ms);
		world.setBlock(x+2, y+5, z+49, b, ms);
		world.setBlock(x+2, y+5, z+50, b, ms);
		world.setBlock(x+2, y+5, z+51, b, ms);
		world.setBlock(x+2, y+5, z+52, b, ms);
		world.setBlock(x+2, y+5, z+53, b, ms);
		world.setBlock(x+2, y+5, z+54, b, ms);
		world.setBlock(x+2, y+5, z+55, b, ms);
		world.setBlock(x+2, y+5, z+56, b, ms);
		world.setBlock(x+2, y+5, z+57, b, ms);
		world.setBlock(x+2, y+5, z+58, b, ms);
		world.setBlock(x+2, y+5, z+59, b, ms);
		world.setBlock(x+2, y+5, z+60, b, ms);
		world.setBlock(x+2, y+5, z+61, b, ms);
		world.setBlock(x+2, y+5, z+62, b, ms);
		world.setBlock(x+2, y+5, z+63, b, ms);
		world.setBlock(x+2, y+5, z+64, b, ms);
		world.setBlock(x+2, y+5, z+65, b, ms);
		world.setBlock(x+2, y+5, z+66, b, ms);
		world.setBlock(x+2, y+5, z+67, b, ms);
		world.setBlock(x+2, y+5, z+68, b, ms);
		world.setBlock(x+2, y+5, z+69, b, ms);
		world.setBlock(x+2, y+5, z+70, b, ms);
		world.setBlock(x+2, y+5, z+71, b, ms);
		world.setBlock(x+2, y+5, z+72, b, ms);
		world.setBlock(x+2, y+5, z+73, b, ms);
		world.setBlock(x+2, y+5, z+74, b, ms);
		world.setBlock(x+2, y+5, z+75, b, ms);
		world.setBlock(x+2, y+5, z+76, b, ms);
		world.setBlock(x+2, y+5, z+77, b, ms);
		world.setBlock(x+2, y+5, z+78, b, ms);
		world.setBlock(x+3, y+0, z+0, b, ms);
		world.setBlock(x+3, y+0, z+1, b, ms);
		world.setBlock(x+3, y+0, z+2, b, ms);
		world.setBlock(x+3, y+0, z+3, b, ms);
		world.setBlock(x+3, y+0, z+4, b, ms);
		world.setBlock(x+3, y+0, z+5, b, ms);
		world.setBlock(x+3, y+0, z+6, b, ms);
		world.setBlock(x+3, y+0, z+7, b, ms);
		world.setBlock(x+3, y+0, z+8, b, ms);
		world.setBlock(x+3, y+0, z+9, b, ms);
		world.setBlock(x+3, y+0, z+10, b, ms);
		world.setBlock(x+3, y+0, z+11, b, ms);
		world.setBlock(x+3, y+0, z+12, b, ms);
		world.setBlock(x+3, y+0, z+13, b, ms);
		world.setBlock(x+3, y+0, z+14, b, ms);
		world.setBlock(x+3, y+0, z+15, b, ms);
		world.setBlock(x+3, y+0, z+16, b, ms);
		world.setBlock(x+3, y+0, z+17, b, ms);
		world.setBlock(x+3, y+0, z+18, b, ms);
		world.setBlock(x+3, y+0, z+19, b, ms);
		world.setBlock(x+3, y+0, z+20, b, ms);
		world.setBlock(x+3, y+0, z+21, b, ms);
		world.setBlock(x+3, y+0, z+22, b, ms);
		world.setBlock(x+3, y+0, z+23, b, ms);
		world.setBlock(x+3, y+0, z+24, b, ms);
		world.setBlock(x+3, y+0, z+25, b, ms);
		world.setBlock(x+3, y+0, z+26, b, ms);
		world.setBlock(x+3, y+0, z+27, b, ms);
		world.setBlock(x+3, y+0, z+28, b, ms);
		world.setBlock(x+3, y+0, z+29, b, ms);
		world.setBlock(x+3, y+0, z+30, b, ms);
		world.setBlock(x+3, y+0, z+31, b, ms);
		world.setBlock(x+3, y+0, z+32, b, ms);
		world.setBlock(x+3, y+0, z+33, b, ms);
		world.setBlock(x+3, y+0, z+34, b, ms);
		world.setBlock(x+3, y+0, z+35, b, ms);
		world.setBlock(x+3, y+0, z+36, b, ms);
		world.setBlock(x+3, y+0, z+37, b, ms);
		world.setBlock(x+3, y+0, z+38, b, ms);
		world.setBlock(x+3, y+0, z+39, b, ms);
		world.setBlock(x+3, y+0, z+40, b, ms);
		world.setBlock(x+3, y+0, z+41, b, ms);
		world.setBlock(x+3, y+0, z+42, b, ms);
		world.setBlock(x+3, y+0, z+43, b, ms);
		world.setBlock(x+3, y+0, z+44, b, ms);
		world.setBlock(x+3, y+0, z+45, b, ms);
		world.setBlock(x+3, y+0, z+46, b, ms);
		world.setBlock(x+3, y+0, z+47, b, ms);
		world.setBlock(x+3, y+0, z+48, b, ms);
		world.setBlock(x+3, y+0, z+49, b, ms);
		world.setBlock(x+3, y+0, z+50, b, ms);
		world.setBlock(x+3, y+0, z+51, b, ms);
		world.setBlock(x+3, y+0, z+52, b, ms);
		world.setBlock(x+3, y+0, z+53, b, ms);
		world.setBlock(x+3, y+0, z+54, b, ms);
		world.setBlock(x+3, y+0, z+55, b, ms);
		world.setBlock(x+3, y+0, z+56, b, ms);
		world.setBlock(x+3, y+0, z+57, b, ms);
		world.setBlock(x+3, y+0, z+58, b, ms);
		world.setBlock(x+3, y+0, z+59, b, ms);
		world.setBlock(x+3, y+0, z+60, b, ms);
		world.setBlock(x+3, y+0, z+61, b, ms);
		world.setBlock(x+3, y+0, z+62, b, ms);
		world.setBlock(x+3, y+0, z+63, b, ms);
		world.setBlock(x+3, y+0, z+64, b, ms);
		world.setBlock(x+3, y+0, z+65, b, ms);
		world.setBlock(x+3, y+0, z+66, b, ms);
		world.setBlock(x+3, y+0, z+67, b, ms);
		world.setBlock(x+3, y+0, z+68, b, ms);
		world.setBlock(x+3, y+0, z+69, b, ms);
		world.setBlock(x+3, y+0, z+70, b, ms);
		world.setBlock(x+3, y+0, z+71, b, ms);
		this.generateRune(x+3, y+0, z+72, LockColor.RED);
		world.setBlock(x+3, y+0, z+73, b, ms);
		world.setBlock(x+3, y+0, z+74, b, mc);
		world.setBlock(x+3, y+0, z+75, b, ms);
		world.setBlock(x+3, y+0, z+76, b, mc);
		world.setBlock(x+3, y+0, z+77, b, ms);
		world.setBlock(x+3, y+0, z+78, b, ms);
		world.setBlock(x+3, y+0, z+79, b, ms);
		world.setBlock(x+3, y+0, z+80, b, ms);
		this.generateKey(x+3, y+1, z+5);
		this.generateLock(x+3, y+1, z+8, LockColor.RED);
		this.generateLock(x+3, y+1, z+14, LockColor.BLUE);
		this.generateLock(x+3, y+1, z+20, LockColor.GREEN);
		this.generateLock(x+3, y+1, z+26, LockColor.YELLOW);
		this.generateLock(x+3, y+1, z+34, LockColor.RED);
		this.generateLock(x+3, y+1, z+40, LockColor.BLUE);
		this.generateLock(x+3, y+1, z+46, LockColor.PURPLE);
		this.generateLock(x+3, y+1, z+57, LockColor.BLUE);
		this.generateLock(x+3, y+1, z+63, LockColor.RED, LockColor.YELLOW);
		this.generateLock(x+3, y+1, z+69, LockColor.PURPLE);
		this.generateGate(x+3, y+1, z+79);
		this.generateLock(x+3, y+2, z+8, LockColor.RED);
		this.generateLock(x+3, y+2, z+14, LockColor.BLUE);
		this.generateLock(x+3, y+2, z+20, LockColor.GREEN);
		this.generateLock(x+3, y+2, z+26, LockColor.YELLOW);
		this.generateLock(x+3, y+2, z+34, LockColor.RED);
		this.generateLock(x+3, y+2, z+40, LockColor.BLUE);
		this.generateLock(x+3, y+2, z+46, LockColor.PURPLE);
		this.generateLock(x+3, y+2, z+57, LockColor.BLUE);
		this.generateLock(x+3, y+2, z+63, LockColor.RED, LockColor.YELLOW);
		this.generateLock(x+3, y+2, z+69, LockColor.PURPLE);
		this.generateGate(x+3, y+2, z+79);
		this.generateLock(x+3, y+3, z+8, LockColor.RED);
		this.generateLock(x+3, y+3, z+14, LockColor.BLUE);
		this.generateLock(x+3, y+3, z+20, LockColor.GREEN);
		this.generateLock(x+3, y+3, z+26, LockColor.YELLOW);
		this.generateLock(x+3, y+3, z+34, LockColor.RED);
		this.generateLock(x+3, y+3, z+40, LockColor.BLUE);
		this.generateLock(x+3, y+3, z+46, LockColor.PURPLE);
		this.generateLock(x+3, y+3, z+57, LockColor.BLUE);
		this.generateLock(x+3, y+3, z+63, LockColor.RED, LockColor.YELLOW);
		this.generateLock(x+3, y+3, z+69, LockColor.PURPLE);
		this.generateGate(x+3, y+3, z+79);
		world.setBlock(x+3, y+4, z+0, b, ms);
		world.setBlock(x+3, y+4, z+7, b, ms);
		world.setBlock(x+3, y+4, z+8, b, ms);
		world.setBlock(x+3, y+4, z+9, b, ms);
		world.setBlock(x+3, y+4, z+13, b, ms);
		world.setBlock(x+3, y+4, z+14, b, ms);
		world.setBlock(x+3, y+4, z+15, b, ms);
		world.setBlock(x+3, y+4, z+19, b, ms);
		world.setBlock(x+3, y+4, z+20, b, ms);
		world.setBlock(x+3, y+4, z+21, b, ms);
		world.setBlock(x+3, y+4, z+25, b, ms);
		world.setBlock(x+3, y+4, z+26, b, ms);
		world.setBlock(x+3, y+4, z+27, b, ms);
		world.setBlock(x+3, y+4, z+33, b, ms);
		world.setBlock(x+3, y+4, z+34, b, ms);
		world.setBlock(x+3, y+4, z+35, b, ms);
		world.setBlock(x+3, y+4, z+39, b, ms);
		world.setBlock(x+3, y+4, z+40, b, ms);
		world.setBlock(x+3, y+4, z+41, b, ms);
		world.setBlock(x+3, y+4, z+45, b, ms);
		world.setBlock(x+3, y+4, z+46, b, ms);
		world.setBlock(x+3, y+4, z+47, b, ms);
		world.setBlock(x+3, y+4, z+56, b, ms);
		world.setBlock(x+3, y+4, z+57, b, ms);
		world.setBlock(x+3, y+4, z+58, b, ms);
		world.setBlock(x+3, y+4, z+62, b, ms);
		world.setBlock(x+3, y+4, z+63, b, ms);
		world.setBlock(x+3, y+4, z+64, b, ms);
		world.setBlock(x+3, y+4, z+68, b, ms);
		world.setBlock(x+3, y+4, z+69, b, ms);
		world.setBlock(x+3, y+4, z+70, b, ms);
		world.setBlock(x+3, y+4, z+78, b, ms);
		world.setBlock(x+3, y+4, z+79, b, ms);
		world.setBlock(x+3, y+4, z+80, b, ms);
		world.setBlock(x+3, y+5, z+1, b, ms);
		world.setBlock(x+3, y+5, z+2, b, ms);
		world.setBlock(x+3, y+5, z+3, b, ms);
		world.setBlock(x+3, y+5, z+4, b, ms);
		world.setBlock(x+3, y+5, z+5, b, ms);
		world.setBlock(x+3, y+5, z+6, b, ms);
		world.setBlock(x+3, y+5, z+7, b, ms);
		world.setBlock(x+3, y+5, z+8, b, ms);
		world.setBlock(x+3, y+5, z+9, b, ms);
		world.setBlock(x+3, y+5, z+10, b, ms);
		world.setBlock(x+3, y+5, z+11, b, ms);
		world.setBlock(x+3, y+5, z+12, b, ms);
		world.setBlock(x+3, y+5, z+13, b, ms);
		world.setBlock(x+3, y+5, z+14, b, ms);
		world.setBlock(x+3, y+5, z+15, b, ms);
		world.setBlock(x+3, y+5, z+16, b, ms);
		world.setBlock(x+3, y+5, z+17, b, ms);
		world.setBlock(x+3, y+5, z+18, b, ms);
		world.setBlock(x+3, y+5, z+19, b, ms);
		world.setBlock(x+3, y+5, z+20, b, ms);
		world.setBlock(x+3, y+5, z+21, b, ms);
		world.setBlock(x+3, y+5, z+22, b, ms);
		world.setBlock(x+3, y+5, z+23, b, ms);
		world.setBlock(x+3, y+5, z+24, b, ms);
		world.setBlock(x+3, y+5, z+25, b, ms);
		world.setBlock(x+3, y+5, z+26, b, ms);
		world.setBlock(x+3, y+5, z+27, b, ms);
		world.setBlock(x+3, y+5, z+28, b, ms);
		world.setBlock(x+3, y+5, z+29, b, ms);
		world.setBlock(x+3, y+5, z+30, b, ms);
		world.setBlock(x+3, y+5, z+31, b, ms);
		world.setBlock(x+3, y+5, z+32, b, ms);
		world.setBlock(x+3, y+5, z+33, b, ms);
		world.setBlock(x+3, y+5, z+34, b, ms);
		world.setBlock(x+3, y+5, z+35, b, ms);
		world.setBlock(x+3, y+5, z+36, b, ms);
		world.setBlock(x+3, y+5, z+37, b, ms);
		world.setBlock(x+3, y+5, z+38, b, ms);
		world.setBlock(x+3, y+5, z+39, b, ms);
		world.setBlock(x+3, y+5, z+40, b, ms);
		world.setBlock(x+3, y+5, z+41, b, ms);
		world.setBlock(x+3, y+5, z+42, b, ms);
		world.setBlock(x+3, y+5, z+43, b, ms);
		world.setBlock(x+3, y+5, z+44, b, ms);
		world.setBlock(x+3, y+5, z+45, b, ms);
		world.setBlock(x+3, y+5, z+46, b, ms);
		world.setBlock(x+3, y+5, z+47, b, ms);
		world.setBlock(x+3, y+5, z+48, b, ms);
		world.setBlock(x+3, y+5, z+49, b, ms);
		world.setBlock(x+3, y+5, z+50, b, ms);
		world.setBlock(x+3, y+5, z+51, b, ms);
		world.setBlock(x+3, y+5, z+52, b, ms);
		world.setBlock(x+3, y+5, z+53, b, ms);
		world.setBlock(x+3, y+5, z+54, b, ms);
		world.setBlock(x+3, y+5, z+55, b, ms);
		world.setBlock(x+3, y+5, z+56, b, ms);
		world.setBlock(x+3, y+5, z+57, b, ms);
		world.setBlock(x+3, y+5, z+58, b, ms);
		world.setBlock(x+3, y+5, z+59, b, ms);
		world.setBlock(x+3, y+5, z+60, b, ms);
		world.setBlock(x+3, y+5, z+61, b, ms);
		world.setBlock(x+3, y+5, z+62, b, ms);
		world.setBlock(x+3, y+5, z+63, b, ms);
		world.setBlock(x+3, y+5, z+64, b, ms);
		world.setBlock(x+3, y+5, z+65, b, ms);
		world.setBlock(x+3, y+5, z+66, b, ms);
		world.setBlock(x+3, y+5, z+67, b, ms);
		world.setBlock(x+3, y+5, z+68, b, ms);
		world.setBlock(x+3, y+5, z+69, b, ms);
		world.setBlock(x+3, y+5, z+70, b, ms);
		world.setBlock(x+3, y+5, z+71, b, ms);
		world.setBlock(x+3, y+5, z+72, b, ms);
		world.setBlock(x+3, y+5, z+73, b, ms);
		world.setBlock(x+3, y+5, z+74, b, ms);
		world.setBlock(x+3, y+5, z+75, b, ms);
		world.setBlock(x+3, y+5, z+76, b, ms);
		world.setBlock(x+3, y+5, z+77, b, ms);
		world.setBlock(x+3, y+5, z+78, b, ms);
		world.setBlock(x+4, y+0, z+0, b, ms);
		world.setBlock(x+4, y+0, z+1, b, ms);
		world.setBlock(x+4, y+0, z+2, b, ms);
		world.setBlock(x+4, y+0, z+3, b, ms);
		world.setBlock(x+4, y+0, z+4, b, ml);
		world.setBlock(x+4, y+0, z+5, b, ms);
		world.setBlock(x+4, y+0, z+6, b, ms);
		world.setBlock(x+4, y+0, z+7, b, ms);
		world.setBlock(x+4, y+0, z+8, b, ms);
		world.setBlock(x+4, y+0, z+9, b, ms);
		world.setBlock(x+4, y+0, z+10, b, ms);
		this.generateRune(x+4, y+0, z+11, LockColor.YELLOW);
		world.setBlock(x+4, y+0, z+12, b, ms);
		world.setBlock(x+4, y+0, z+13, b, ms);
		world.setBlock(x+4, y+0, z+14, b, ms);
		world.setBlock(x+4, y+0, z+15, b, ms);
		world.setBlock(x+4, y+0, z+16, b, ms);
		this.generateRune(x+4, y+0, z+17, LockColor.GREEN);
		world.setBlock(x+4, y+0, z+18, b, ms);
		world.setBlock(x+4, y+0, z+19, b, ms);
		world.setBlock(x+4, y+0, z+20, b, ms);
		world.setBlock(x+4, y+0, z+21, b, ms);
		world.setBlock(x+4, y+0, z+22, b, ms);
		this.generateRune(x+4, y+0, z+23, LockColor.RED);
		world.setBlock(x+4, y+0, z+24, b, ms);
		world.setBlock(x+4, y+0, z+25, b, ms);
		world.setBlock(x+4, y+0, z+26, b, ms);
		world.setBlock(x+4, y+0, z+27, b, ms);
		world.setBlock(x+4, y+0, z+28, b, ms);
		world.setBlock(x+4, y+0, z+29, b, ms);
		world.setBlock(x+4, y+0, z+30, b, ml);
		world.setBlock(x+4, y+0, z+31, b, ms);
		world.setBlock(x+4, y+0, z+32, b, ms);
		world.setBlock(x+4, y+0, z+33, b, ms);
		world.setBlock(x+4, y+0, z+34, b, ms);
		world.setBlock(x+4, y+0, z+35, b, ms);
		world.setBlock(x+4, y+0, z+36, b, ms);
		this.generateRune(x+4, y+0, z+37, LockColor.GREEN);
		world.setBlock(x+4, y+0, z+38, b, ms);
		world.setBlock(x+4, y+0, z+39, b, ms);
		world.setBlock(x+4, y+0, z+40, b, ms);
		world.setBlock(x+4, y+0, z+41, b, ms);
		world.setBlock(x+4, y+0, z+42, b, ms);
		this.generateRune(x+4, y+0, z+43, LockColor.BLUE);
		world.setBlock(x+4, y+0, z+44, b, ms);
		world.setBlock(x+4, y+0, z+45, b, ms);
		world.setBlock(x+4, y+0, z+46, b, ms);
		world.setBlock(x+4, y+0, z+47, b, ms);
		world.setBlock(x+4, y+0, z+48, b, ms);
		world.setBlock(x+4, y+0, z+49, b, ms);
		world.setBlock(x+4, y+0, z+50, b, ms);
		world.setBlock(x+4, y+0, z+51, b, ms);
		world.setBlock(x+4, y+0, z+52, b, ms);
		world.setBlock(x+4, y+0, z+53, b, ms);
		this.generateWhiteRune(x+4, y+0, z+54);
		world.setBlock(x+4, y+0, z+55, b, ms);
		world.setBlock(x+4, y+0, z+56, b, ms);
		world.setBlock(x+4, y+0, z+57, b, ms);
		world.setBlock(x+4, y+0, z+58, b, ms);
		world.setBlock(x+4, y+0, z+59, b, ms);
		this.generateRune(x+4, y+0, z+60, LockColor.PURPLE);
		world.setBlock(x+4, y+0, z+61, b, ms);
		world.setBlock(x+4, y+0, z+62, b, ms);
		world.setBlock(x+4, y+0, z+63, b, ms);
		world.setBlock(x+4, y+0, z+64, b, ms);
		world.setBlock(x+4, y+0, z+65, b, ms);
		this.generateRune(x+4, y+0, z+66, LockColor.YELLOW);
		world.setBlock(x+4, y+0, z+67, b, ms);
		world.setBlock(x+4, y+0, z+68, b, ms);
		world.setBlock(x+4, y+0, z+69, b, ms);
		world.setBlock(x+4, y+0, z+70, b, ms);
		world.setBlock(x+4, y+0, z+71, b, ms);
		world.setBlock(x+4, y+0, z+72, b, ms);
		world.setBlock(x+4, y+0, z+73, b, ms);
		world.setBlock(x+4, y+0, z+74, b, ms);
		world.setBlock(x+4, y+0, z+75, b, mc);
		world.setBlock(x+4, y+0, z+76, b, ms);
		world.setBlock(x+4, y+0, z+77, b, ms);
		world.setBlock(x+4, y+0, z+78, b, ms);
		world.setBlock(x+4, y+0, z+79, b, ms);
		world.setBlock(x+4, y+0, z+80, b, ms);
		this.generateKey(x+4, y+1, z+3);
		this.generateLock(x+4, y+1, z+8, LockColor.RED);
		this.generateLock(x+4, y+1, z+14, LockColor.BLUE);
		this.generateLock(x+4, y+1, z+20, LockColor.GREEN);
		this.generateLock(x+4, y+1, z+26, LockColor.YELLOW);
		this.generateLock(x+4, y+1, z+34, LockColor.RED);
		this.generateLock(x+4, y+1, z+40, LockColor.BLUE);
		this.generateLock(x+4, y+1, z+46, LockColor.PURPLE);
		world.setBlock(x+4, y+1, z+50, b, ms);
		world.setBlock(x+4, y+1, z+51, b, ms);
		world.setBlock(x+4, y+1, z+52, b, ms);
		this.generateLock(x+4, y+1, z+57, LockColor.BLUE);
		this.generateLock(x+4, y+1, z+63, LockColor.RED, LockColor.YELLOW);
		this.generateLock(x+4, y+1, z+69, LockColor.PURPLE);
		this.generateGate(x+4, y+1, z+79);
		this.generateLock(x+4, y+2, z+8, LockColor.RED);
		this.generateLock(x+4, y+2, z+14, LockColor.BLUE);
		this.generateLock(x+4, y+2, z+20, LockColor.GREEN);
		this.generateLock(x+4, y+2, z+26, LockColor.YELLOW);
		this.generateLock(x+4, y+2, z+34, LockColor.RED);
		this.generateLock(x+4, y+2, z+40, LockColor.BLUE);
		this.generateLock(x+4, y+2, z+46, LockColor.PURPLE);
		world.setBlock(x+4, y+2, z+50, b, ms);
		this.generateTimer(x+4, y+2, z+51);
		world.setBlock(x+4, y+2, z+52, b, ms);
		this.generateLock(x+4, y+2, z+57, LockColor.BLUE);
		this.generateLock(x+4, y+2, z+63, LockColor.RED, LockColor.YELLOW);
		this.generateLock(x+4, y+2, z+69, LockColor.PURPLE);
		this.generateGate(x+4, y+2, z+79);
		this.generateLock(x+4, y+3, z+8, LockColor.RED);
		this.generateLock(x+4, y+3, z+14, LockColor.BLUE);
		this.generateLock(x+4, y+3, z+20, LockColor.GREEN);
		this.generateLock(x+4, y+3, z+26, LockColor.YELLOW);
		this.generateLock(x+4, y+3, z+34, LockColor.RED);
		this.generateLock(x+4, y+3, z+40, LockColor.BLUE);
		this.generateLock(x+4, y+3, z+46, LockColor.PURPLE);
		world.setBlock(x+4, y+3, z+50, b, ms);
		world.setBlock(x+4, y+3, z+51, b, ms);
		world.setBlock(x+4, y+3, z+52, b, ms);
		this.generateLock(x+4, y+3, z+57, LockColor.BLUE);
		this.generateLock(x+4, y+3, z+63, LockColor.RED, LockColor.YELLOW);
		this.generateLock(x+4, y+3, z+69, LockColor.PURPLE);
		this.generateGate(x+4, y+3, z+79);
		world.setBlock(x+4, y+4, z+0, b, ms);
		world.setBlock(x+4, y+4, z+7, b, ml);
		world.setBlock(x+4, y+4, z+8, b, ms);
		world.setBlock(x+4, y+4, z+9, b, ms);
		world.setBlock(x+4, y+4, z+13, b, ms);
		world.setBlock(x+4, y+4, z+14, b, ms);
		world.setBlock(x+4, y+4, z+15, b, ml);
		world.setBlock(x+4, y+4, z+19, b, ms);
		world.setBlock(x+4, y+4, z+20, b, ms);
		world.setBlock(x+4, y+4, z+21, b, ml);
		world.setBlock(x+4, y+4, z+25, b, ml);
		world.setBlock(x+4, y+4, z+26, b, ms);
		world.setBlock(x+4, y+4, z+27, b, ml);
		world.setBlock(x+4, y+4, z+33, b, ms);
		world.setBlock(x+4, y+4, z+34, b, ms);
		world.setBlock(x+4, y+4, z+35, b, ms);
		world.setBlock(x+4, y+4, z+39, b, ms);
		world.setBlock(x+4, y+4, z+40, b, ms);
		world.setBlock(x+4, y+4, z+41, b, ms);
		world.setBlock(x+4, y+4, z+45, b, ms);
		world.setBlock(x+4, y+4, z+46, b, ms);
		world.setBlock(x+4, y+4, z+47, b, ml);
		world.setBlock(x+4, y+4, z+50, b, ms);
		world.setBlock(x+4, y+4, z+51, b, ms);
		world.setBlock(x+4, y+4, z+52, b, ms);
		world.setBlock(x+4, y+4, z+56, b, ms);
		world.setBlock(x+4, y+4, z+57, b, ms);
		world.setBlock(x+4, y+4, z+58, b, ms);
		world.setBlock(x+4, y+4, z+62, b, ms);
		world.setBlock(x+4, y+4, z+63, b, ms);
		world.setBlock(x+4, y+4, z+64, b, ms);
		world.setBlock(x+4, y+4, z+68, b, ms);
		world.setBlock(x+4, y+4, z+69, b, ms);
		world.setBlock(x+4, y+4, z+70, b, ml);
		world.setBlock(x+4, y+4, z+78, b, ml);
		world.setBlock(x+4, y+4, z+79, b, ms);
		world.setBlock(x+4, y+4, z+80, b, ms);
		world.setBlock(x+4, y+5, z+1, b, ms);
		world.setBlock(x+4, y+5, z+2, b, ms);
		world.setBlock(x+4, y+5, z+3, b, ms);
		world.setBlock(x+4, y+5, z+4, b, ms);
		world.setBlock(x+4, y+5, z+5, b, ms);
		world.setBlock(x+4, y+5, z+6, b, ms);
		world.setBlock(x+4, y+5, z+7, b, ms);
		world.setBlock(x+4, y+5, z+8, b, ms);
		world.setBlock(x+4, y+5, z+9, b, ms);
		world.setBlock(x+4, y+5, z+10, b, ms);
		world.setBlock(x+4, y+5, z+11, b, ms);
		world.setBlock(x+4, y+5, z+12, b, ms);
		world.setBlock(x+4, y+5, z+13, b, ms);
		world.setBlock(x+4, y+5, z+14, b, ms);
		world.setBlock(x+4, y+5, z+15, b, ms);
		world.setBlock(x+4, y+5, z+16, b, ms);
		world.setBlock(x+4, y+5, z+17, b, ms);
		world.setBlock(x+4, y+5, z+18, b, ms);
		world.setBlock(x+4, y+5, z+19, b, ms);
		world.setBlock(x+4, y+5, z+20, b, ms);
		world.setBlock(x+4, y+5, z+21, b, ms);
		world.setBlock(x+4, y+5, z+22, b, ms);
		world.setBlock(x+4, y+5, z+23, b, ms);
		world.setBlock(x+4, y+5, z+24, b, ms);
		world.setBlock(x+4, y+5, z+25, b, ms);
		world.setBlock(x+4, y+5, z+26, b, ms);
		world.setBlock(x+4, y+5, z+27, b, ms);
		world.setBlock(x+4, y+5, z+28, b, ms);
		world.setBlock(x+4, y+5, z+29, b, ms);
		world.setBlock(x+4, y+5, z+30, b, ms);
		world.setBlock(x+4, y+5, z+31, b, ms);
		world.setBlock(x+4, y+5, z+32, b, ms);
		world.setBlock(x+4, y+5, z+33, b, ms);
		world.setBlock(x+4, y+5, z+34, b, ms);
		world.setBlock(x+4, y+5, z+35, b, ms);
		world.setBlock(x+4, y+5, z+36, b, ms);
		world.setBlock(x+4, y+5, z+37, b, ms);
		world.setBlock(x+4, y+5, z+38, b, ms);
		world.setBlock(x+4, y+5, z+39, b, ms);
		world.setBlock(x+4, y+5, z+40, b, ms);
		world.setBlock(x+4, y+5, z+41, b, ms);
		world.setBlock(x+4, y+5, z+42, b, ms);
		world.setBlock(x+4, y+5, z+43, b, ms);
		world.setBlock(x+4, y+5, z+44, b, ms);
		world.setBlock(x+4, y+5, z+45, b, ms);
		world.setBlock(x+4, y+5, z+46, b, ms);
		world.setBlock(x+4, y+5, z+47, b, ms);
		world.setBlock(x+4, y+5, z+48, b, ms);
		world.setBlock(x+4, y+5, z+49, b, ms);
		world.setBlock(x+4, y+5, z+50, b, ms);
		world.setBlock(x+4, y+5, z+51, b, ms);
		world.setBlock(x+4, y+5, z+52, b, ms);
		world.setBlock(x+4, y+5, z+53, b, ms);
		world.setBlock(x+4, y+5, z+54, b, ms);
		world.setBlock(x+4, y+5, z+55, b, ms);
		world.setBlock(x+4, y+5, z+56, b, ms);
		world.setBlock(x+4, y+5, z+57, b, ms);
		world.setBlock(x+4, y+5, z+58, b, ms);
		world.setBlock(x+4, y+5, z+59, b, ms);
		world.setBlock(x+4, y+5, z+60, b, ms);
		world.setBlock(x+4, y+5, z+61, b, ms);
		world.setBlock(x+4, y+5, z+62, b, ms);
		world.setBlock(x+4, y+5, z+63, b, ms);
		world.setBlock(x+4, y+5, z+64, b, ms);
		world.setBlock(x+4, y+5, z+65, b, ms);
		world.setBlock(x+4, y+5, z+66, b, ms);
		world.setBlock(x+4, y+5, z+67, b, ms);
		world.setBlock(x+4, y+5, z+68, b, ms);
		world.setBlock(x+4, y+5, z+69, b, ms);
		world.setBlock(x+4, y+5, z+70, b, ms);
		world.setBlock(x+4, y+5, z+71, b, ms);
		world.setBlock(x+4, y+5, z+72, b, ms);
		world.setBlock(x+4, y+5, z+73, b, ms);
		world.setBlock(x+4, y+5, z+74, b, ms);
		world.setBlock(x+4, y+5, z+75, b, ms);
		world.setBlock(x+4, y+5, z+76, b, ms);
		world.setBlock(x+4, y+5, z+77, b, ms);
		world.setBlock(x+4, y+5, z+78, b, ms);
		world.setBlock(x+5, y+0, z+0, b, ms);
		world.setBlock(x+5, y+0, z+1, b, ms);
		world.setBlock(x+5, y+0, z+2, b, ms);
		world.setBlock(x+5, y+0, z+3, b, ms);
		world.setBlock(x+5, y+0, z+4, b, ms);
		world.setBlock(x+5, y+0, z+5, b, ms);
		world.setBlock(x+5, y+0, z+6, b, ms);
		world.setBlock(x+5, y+0, z+7, b, ms);
		world.setBlock(x+5, y+0, z+8, b, ms);
		world.setBlock(x+5, y+0, z+9, b, ms);
		world.setBlock(x+5, y+0, z+10, b, ms);
		world.setBlock(x+5, y+0, z+11, b, ms);
		world.setBlock(x+5, y+0, z+12, b, ms);
		world.setBlock(x+5, y+0, z+13, b, ms);
		world.setBlock(x+5, y+0, z+14, b, ms);
		world.setBlock(x+5, y+0, z+15, b, ms);
		world.setBlock(x+5, y+0, z+16, b, ms);
		world.setBlock(x+5, y+0, z+17, b, ms);
		world.setBlock(x+5, y+0, z+18, b, ms);
		world.setBlock(x+5, y+0, z+19, b, ms);
		world.setBlock(x+5, y+0, z+20, b, ms);
		world.setBlock(x+5, y+0, z+21, b, ms);
		world.setBlock(x+5, y+0, z+22, b, ms);
		world.setBlock(x+5, y+0, z+23, b, ms);
		world.setBlock(x+5, y+0, z+24, b, ms);
		world.setBlock(x+5, y+0, z+25, b, ms);
		world.setBlock(x+5, y+0, z+26, b, ms);
		world.setBlock(x+5, y+0, z+27, b, ms);
		world.setBlock(x+5, y+0, z+28, b, ms);
		world.setBlock(x+5, y+0, z+29, b, ms);
		world.setBlock(x+5, y+0, z+30, b, ms);
		world.setBlock(x+5, y+0, z+31, b, ms);
		world.setBlock(x+5, y+0, z+32, b, ms);
		world.setBlock(x+5, y+0, z+33, b, ms);
		world.setBlock(x+5, y+0, z+34, b, ms);
		world.setBlock(x+5, y+0, z+35, b, ms);
		world.setBlock(x+5, y+0, z+36, b, ms);
		world.setBlock(x+5, y+0, z+37, b, ms);
		world.setBlock(x+5, y+0, z+38, b, ms);
		world.setBlock(x+5, y+0, z+39, b, ms);
		world.setBlock(x+5, y+0, z+40, b, ms);
		world.setBlock(x+5, y+0, z+41, b, ms);
		world.setBlock(x+5, y+0, z+42, b, ms);
		world.setBlock(x+5, y+0, z+43, b, ms);
		world.setBlock(x+5, y+0, z+44, b, ms);
		world.setBlock(x+5, y+0, z+45, b, ms);
		world.setBlock(x+5, y+0, z+46, b, ms);
		world.setBlock(x+5, y+0, z+47, b, ms);
		world.setBlock(x+5, y+0, z+48, b, ms);
		world.setBlock(x+5, y+0, z+49, b, ms);
		world.setBlock(x+5, y+0, z+50, b, ms);
		world.setBlock(x+5, y+0, z+51, b, ms);
		world.setBlock(x+5, y+0, z+52, b, ms);
		world.setBlock(x+5, y+0, z+53, b, ms);
		world.setBlock(x+5, y+0, z+54, b, ms);
		world.setBlock(x+5, y+0, z+55, b, ms);
		world.setBlock(x+5, y+0, z+56, b, ms);
		world.setBlock(x+5, y+0, z+57, b, ms);
		world.setBlock(x+5, y+0, z+58, b, ms);
		world.setBlock(x+5, y+0, z+59, b, ms);
		world.setBlock(x+5, y+0, z+60, b, ms);
		world.setBlock(x+5, y+0, z+61, b, ms);
		world.setBlock(x+5, y+0, z+62, b, ms);
		world.setBlock(x+5, y+0, z+63, b, ms);
		world.setBlock(x+5, y+0, z+64, b, ms);
		world.setBlock(x+5, y+0, z+65, b, ms);
		world.setBlock(x+5, y+0, z+66, b, ms);
		world.setBlock(x+5, y+0, z+67, b, ms);
		world.setBlock(x+5, y+0, z+68, b, ms);
		world.setBlock(x+5, y+0, z+69, b, ms);
		world.setBlock(x+5, y+0, z+70, b, ms);
		world.setBlock(x+5, y+0, z+71, b, ms);
		this.generateRune(x+5, y+0, z+72, LockColor.BLUE);
		world.setBlock(x+5, y+0, z+73, b, ms);
		world.setBlock(x+5, y+0, z+74, b, mc);
		world.setBlock(x+5, y+0, z+75, b, ms);
		world.setBlock(x+5, y+0, z+76, b, mc);
		world.setBlock(x+5, y+0, z+77, b, ms);
		world.setBlock(x+5, y+0, z+78, b, ms);
		world.setBlock(x+5, y+0, z+79, b, ms);
		world.setBlock(x+5, y+0, z+80, b, ms);
		this.generateKey(x+5, y+1, z+5);
		this.generateLock(x+5, y+1, z+8, LockColor.RED);
		this.generateLock(x+5, y+1, z+14, LockColor.BLUE);
		this.generateLock(x+5, y+1, z+20, LockColor.GREEN);
		this.generateLock(x+5, y+1, z+26, LockColor.YELLOW);
		this.generateLock(x+5, y+1, z+34, LockColor.RED);
		this.generateLock(x+5, y+1, z+40, LockColor.BLUE);
		this.generateLock(x+5, y+1, z+46, LockColor.PURPLE);
		this.generateLock(x+5, y+1, z+57, LockColor.BLUE);
		this.generateLock(x+5, y+1, z+63, LockColor.RED, LockColor.YELLOW);
		this.generateLock(x+5, y+1, z+69, LockColor.PURPLE);
		this.generateGate(x+5, y+1, z+79);
		this.generateLock(x+5, y+2, z+8, LockColor.RED);
		this.generateLock(x+5, y+2, z+14, LockColor.BLUE);
		this.generateLock(x+5, y+2, z+20, LockColor.GREEN);
		this.generateLock(x+5, y+2, z+26, LockColor.YELLOW);
		this.generateLock(x+5, y+2, z+34, LockColor.RED);
		this.generateLock(x+5, y+2, z+40, LockColor.BLUE);
		this.generateLock(x+5, y+2, z+46, LockColor.PURPLE);
		this.generateLock(x+5, y+2, z+57, LockColor.BLUE);
		this.generateLock(x+5, y+2, z+63, LockColor.RED, LockColor.YELLOW);
		this.generateLock(x+5, y+2, z+69, LockColor.PURPLE);
		this.generateGate(x+5, y+2, z+79);
		this.generateLock(x+5, y+3, z+8, LockColor.RED);
		this.generateLock(x+5, y+3, z+14, LockColor.BLUE);
		this.generateLock(x+5, y+3, z+20, LockColor.GREEN);
		this.generateLock(x+5, y+3, z+26, LockColor.YELLOW);
		this.generateLock(x+5, y+3, z+34, LockColor.RED);
		this.generateLock(x+5, y+3, z+40, LockColor.BLUE);
		this.generateLock(x+5, y+3, z+46, LockColor.PURPLE);
		this.generateLock(x+5, y+3, z+57, LockColor.BLUE);
		this.generateLock(x+5, y+3, z+63, LockColor.RED, LockColor.YELLOW);
		this.generateLock(x+5, y+3, z+69, LockColor.PURPLE);
		this.generateGate(x+5, y+3, z+79);
		world.setBlock(x+5, y+4, z+0, b, ms);
		world.setBlock(x+5, y+4, z+7, b, ms);
		world.setBlock(x+5, y+4, z+8, b, ms);
		world.setBlock(x+5, y+4, z+9, b, ms);
		world.setBlock(x+5, y+4, z+13, b, ms);
		world.setBlock(x+5, y+4, z+14, b, ms);
		world.setBlock(x+5, y+4, z+15, b, ms);
		world.setBlock(x+5, y+4, z+19, b, ms);
		world.setBlock(x+5, y+4, z+20, b, ms);
		world.setBlock(x+5, y+4, z+21, b, ms);
		world.setBlock(x+5, y+4, z+25, b, ms);
		world.setBlock(x+5, y+4, z+26, b, ms);
		world.setBlock(x+5, y+4, z+27, b, ms);
		world.setBlock(x+5, y+4, z+33, b, ms);
		world.setBlock(x+5, y+4, z+34, b, ms);
		world.setBlock(x+5, y+4, z+35, b, ms);
		world.setBlock(x+5, y+4, z+39, b, ms);
		world.setBlock(x+5, y+4, z+40, b, ms);
		world.setBlock(x+5, y+4, z+41, b, ms);
		world.setBlock(x+5, y+4, z+45, b, ms);
		world.setBlock(x+5, y+4, z+46, b, ms);
		world.setBlock(x+5, y+4, z+47, b, ms);
		world.setBlock(x+5, y+4, z+56, b, ms);
		world.setBlock(x+5, y+4, z+57, b, ms);
		world.setBlock(x+5, y+4, z+58, b, ms);
		world.setBlock(x+5, y+4, z+62, b, ms);
		world.setBlock(x+5, y+4, z+63, b, ms);
		world.setBlock(x+5, y+4, z+64, b, ms);
		world.setBlock(x+5, y+4, z+68, b, ms);
		world.setBlock(x+5, y+4, z+69, b, ms);
		world.setBlock(x+5, y+4, z+70, b, ms);
		world.setBlock(x+5, y+4, z+78, b, ms);
		world.setBlock(x+5, y+4, z+79, b, ms);
		world.setBlock(x+5, y+4, z+80, b, ms);
		world.setBlock(x+5, y+5, z+1, b, ms);
		world.setBlock(x+5, y+5, z+2, b, ms);
		world.setBlock(x+5, y+5, z+3, b, ms);
		world.setBlock(x+5, y+5, z+4, b, ms);
		world.setBlock(x+5, y+5, z+5, b, ms);
		world.setBlock(x+5, y+5, z+6, b, ms);
		world.setBlock(x+5, y+5, z+7, b, ms);
		world.setBlock(x+5, y+5, z+8, b, ms);
		world.setBlock(x+5, y+5, z+9, b, ms);
		world.setBlock(x+5, y+5, z+10, b, ms);
		world.setBlock(x+5, y+5, z+11, b, ms);
		world.setBlock(x+5, y+5, z+12, b, ms);
		world.setBlock(x+5, y+5, z+13, b, ms);
		world.setBlock(x+5, y+5, z+14, b, ms);
		world.setBlock(x+5, y+5, z+15, b, ms);
		world.setBlock(x+5, y+5, z+16, b, ms);
		world.setBlock(x+5, y+5, z+17, b, ms);
		world.setBlock(x+5, y+5, z+18, b, ms);
		world.setBlock(x+5, y+5, z+19, b, ms);
		world.setBlock(x+5, y+5, z+20, b, ms);
		world.setBlock(x+5, y+5, z+21, b, ms);
		world.setBlock(x+5, y+5, z+22, b, ms);
		world.setBlock(x+5, y+5, z+23, b, ms);
		world.setBlock(x+5, y+5, z+24, b, ms);
		world.setBlock(x+5, y+5, z+25, b, ms);
		world.setBlock(x+5, y+5, z+26, b, ms);
		world.setBlock(x+5, y+5, z+27, b, ms);
		world.setBlock(x+5, y+5, z+28, b, ms);
		world.setBlock(x+5, y+5, z+29, b, ms);
		world.setBlock(x+5, y+5, z+30, b, ms);
		world.setBlock(x+5, y+5, z+31, b, ms);
		world.setBlock(x+5, y+5, z+32, b, ms);
		world.setBlock(x+5, y+5, z+33, b, ms);
		world.setBlock(x+5, y+5, z+34, b, ms);
		world.setBlock(x+5, y+5, z+35, b, ms);
		world.setBlock(x+5, y+5, z+36, b, ms);
		world.setBlock(x+5, y+5, z+37, b, ms);
		world.setBlock(x+5, y+5, z+38, b, ms);
		world.setBlock(x+5, y+5, z+39, b, ms);
		world.setBlock(x+5, y+5, z+40, b, ms);
		world.setBlock(x+5, y+5, z+41, b, ms);
		world.setBlock(x+5, y+5, z+42, b, ms);
		world.setBlock(x+5, y+5, z+43, b, ms);
		world.setBlock(x+5, y+5, z+44, b, ms);
		world.setBlock(x+5, y+5, z+45, b, ms);
		world.setBlock(x+5, y+5, z+46, b, ms);
		world.setBlock(x+5, y+5, z+47, b, ms);
		world.setBlock(x+5, y+5, z+48, b, ms);
		world.setBlock(x+5, y+5, z+49, b, ms);
		world.setBlock(x+5, y+5, z+50, b, ms);
		world.setBlock(x+5, y+5, z+51, b, ms);
		world.setBlock(x+5, y+5, z+52, b, ms);
		world.setBlock(x+5, y+5, z+53, b, ms);
		world.setBlock(x+5, y+5, z+54, b, ms);
		world.setBlock(x+5, y+5, z+55, b, ms);
		world.setBlock(x+5, y+5, z+56, b, ms);
		world.setBlock(x+5, y+5, z+57, b, ms);
		world.setBlock(x+5, y+5, z+58, b, ms);
		world.setBlock(x+5, y+5, z+59, b, ms);
		world.setBlock(x+5, y+5, z+60, b, ms);
		world.setBlock(x+5, y+5, z+61, b, ms);
		world.setBlock(x+5, y+5, z+62, b, ms);
		world.setBlock(x+5, y+5, z+63, b, ms);
		world.setBlock(x+5, y+5, z+64, b, ms);
		world.setBlock(x+5, y+5, z+65, b, ms);
		world.setBlock(x+5, y+5, z+66, b, ms);
		world.setBlock(x+5, y+5, z+67, b, ms);
		world.setBlock(x+5, y+5, z+68, b, ms);
		world.setBlock(x+5, y+5, z+69, b, ms);
		world.setBlock(x+5, y+5, z+70, b, ms);
		world.setBlock(x+5, y+5, z+71, b, ms);
		world.setBlock(x+5, y+5, z+72, b, ms);
		world.setBlock(x+5, y+5, z+73, b, ms);
		world.setBlock(x+5, y+5, z+74, b, ms);
		world.setBlock(x+5, y+5, z+75, b, ms);
		world.setBlock(x+5, y+5, z+76, b, ms);
		world.setBlock(x+5, y+5, z+77, b, ms);
		world.setBlock(x+5, y+5, z+78, b, ms);
		world.setBlock(x+6, y+0, z+0, b, ms);
		world.setBlock(x+6, y+0, z+1, b, ms);
		world.setBlock(x+6, y+0, z+2, b, ms);
		world.setBlock(x+6, y+0, z+3, b, ms);
		this.generateRune(x+6, y+0, z+4, LockColor.BLUE);
		world.setBlock(x+6, y+0, z+5, b, ms);
		world.setBlock(x+6, y+0, z+6, b, ms);
		world.setBlock(x+6, y+0, z+7, b, ms);
		world.setBlock(x+6, y+0, z+8, b, ms);
		world.setBlock(x+6, y+0, z+9, b, ms);
		world.setBlock(x+6, y+0, z+10, b, ms);
		world.setBlock(x+6, y+0, z+11, b, ms);
		world.setBlock(x+6, y+0, z+12, b, ms);
		world.setBlock(x+6, y+0, z+13, b, ms);
		world.setBlock(x+6, y+0, z+14, b, ms);
		world.setBlock(x+6, y+0, z+15, b, ms);
		world.setBlock(x+6, y+0, z+16, b, ms);
		world.setBlock(x+6, y+0, z+17, b, ms);
		world.setBlock(x+6, y+0, z+18, b, ms);
		world.setBlock(x+6, y+0, z+19, b, ms);
		world.setBlock(x+6, y+0, z+20, b, ms);
		world.setBlock(x+6, y+0, z+21, b, ms);
		world.setBlock(x+6, y+0, z+22, b, ms);
		world.setBlock(x+6, y+0, z+23, b, ms);
		world.setBlock(x+6, y+0, z+24, b, ms);
		world.setBlock(x+6, y+0, z+25, b, ms);
		world.setBlock(x+6, y+0, z+26, b, ms);
		world.setBlock(x+6, y+0, z+27, b, ms);
		world.setBlock(x+6, y+0, z+28, b, ms);
		world.setBlock(x+6, y+0, z+29, b, ms);
		this.generateRune(x+6, y+0, z+30, LockColor.YELLOW);
		world.setBlock(x+6, y+0, z+31, b, ms);
		world.setBlock(x+6, y+0, z+32, b, ms);
		world.setBlock(x+6, y+0, z+33, b, ms);
	}

	private void generate2(OriginBlockCache world, int x, int y, int z, Block b, int ms, int ml, int mc) {
		world.setBlock(x+6, y+0, z+34, b, ms);
		world.setBlock(x+6, y+0, z+35, b, ms);
		world.setBlock(x+6, y+0, z+36, b, ms);
		world.setBlock(x+6, y+0, z+37, b, ms);
		world.setBlock(x+6, y+0, z+38, b, ms);
		world.setBlock(x+6, y+0, z+39, b, ms);
		world.setBlock(x+6, y+0, z+40, b, ms);
		world.setBlock(x+6, y+0, z+41, b, ms);
		world.setBlock(x+6, y+0, z+42, b, ms);
		world.setBlock(x+6, y+0, z+43, b, ms);
		world.setBlock(x+6, y+0, z+44, b, ms);
		world.setBlock(x+6, y+0, z+45, b, ms);
		world.setBlock(x+6, y+0, z+46, b, ms);
		world.setBlock(x+6, y+0, z+47, b, ms);
		world.setBlock(x+6, y+0, z+48, b, ms);
		world.setBlock(x+6, y+0, z+49, b, ms);
		world.setBlock(x+6, y+0, z+50, b, ms);
		world.setBlock(x+6, y+0, z+51, b, ms);
		world.setBlock(x+6, y+0, z+52, b, ms);
		world.setBlock(x+6, y+0, z+53, b, ms);
		world.setBlock(x+6, y+0, z+54, b, ms);
		world.setBlock(x+6, y+0, z+55, b, ms);
		world.setBlock(x+6, y+0, z+56, b, ms);
		world.setBlock(x+6, y+0, z+57, b, ms);
		world.setBlock(x+6, y+0, z+58, b, ms);
		world.setBlock(x+6, y+0, z+59, b, ms);
		world.setBlock(x+6, y+0, z+60, b, ms);
		world.setBlock(x+6, y+0, z+61, b, ms);
		world.setBlock(x+6, y+0, z+62, b, ms);
		world.setBlock(x+6, y+0, z+63, b, ms);
		world.setBlock(x+6, y+0, z+64, b, ms);
		world.setBlock(x+6, y+0, z+65, b, ms);
		world.setBlock(x+6, y+0, z+66, b, ms);
		world.setBlock(x+6, y+0, z+67, b, ms);
		world.setBlock(x+6, y+0, z+68, b, ms);
		world.setBlock(x+6, y+0, z+69, b, ms);
		world.setBlock(x+6, y+0, z+70, b, ms);
		world.setBlock(x+6, y+0, z+71, b, ms);
		world.setBlock(x+6, y+0, z+72, b, ms);
		world.setBlock(x+6, y+0, z+73, b, ms);
		world.setBlock(x+6, y+0, z+74, b, ms);
		world.setBlock(x+6, y+0, z+75, b, ms);
		world.setBlock(x+6, y+0, z+76, b, ms);
		world.setBlock(x+6, y+0, z+77, b, ms);
		world.setBlock(x+6, y+0, z+78, b, ms);
		world.setBlock(x+6, y+0, z+79, b, ms);
		world.setBlock(x+6, y+0, z+80, b, ms);
		world.setBlock(x+6, y+1, z+0, b, ms);
		world.setBlock(x+6, y+1, z+7, b, ms);
		world.setBlock(x+6, y+1, z+8, b, ms);
		world.setBlock(x+6, y+1, z+9, b, ms);
		world.setBlock(x+6, y+1, z+13, b, ms);
		world.setBlock(x+6, y+1, z+14, b, ms);
		world.setBlock(x+6, y+1, z+15, b, ms);
		world.setBlock(x+6, y+1, z+19, b, ms);
		world.setBlock(x+6, y+1, z+20, b, ms);
		world.setBlock(x+6, y+1, z+21, b, ms);
		world.setBlock(x+6, y+1, z+25, b, ms);
		world.setBlock(x+6, y+1, z+26, b, ms);
		world.setBlock(x+6, y+1, z+27, b, ms);
		world.setBlock(x+6, y+1, z+33, b, ms);
		world.setBlock(x+6, y+1, z+34, b, ms);
		world.setBlock(x+6, y+1, z+35, b, ms);
		this.generateKey(x+6, y+1, z+37);
		world.setBlock(x+6, y+1, z+39, b, ms);
		world.setBlock(x+6, y+1, z+40, b, ms);
		world.setBlock(x+6, y+1, z+41, b, ms);
		world.setBlock(x+6, y+1, z+45, b, ms);
		world.setBlock(x+6, y+1, z+46, b, ms);
		world.setBlock(x+6, y+1, z+47, b, ms);
		world.setBlock(x+6, y+1, z+56, b, ms);
		world.setBlock(x+6, y+1, z+57, b, ms);
		world.setBlock(x+6, y+1, z+58, b, ms);
		world.setBlock(x+6, y+1, z+62, b, ms);
		world.setBlock(x+6, y+1, z+63, b, ms);
		world.setBlock(x+6, y+1, z+64, b, ms);
		world.setBlock(x+6, y+1, z+68, b, ms);
		world.setBlock(x+6, y+1, z+69, b, ms);
		world.setBlock(x+6, y+1, z+70, b, ms);
		world.setBlock(x+6, y+1, z+78, b, ms);
		world.setBlock(x+6, y+1, z+79, b, ms);
		world.setBlock(x+6, y+1, z+80, b, ms);
		world.setBlock(x+6, y+2, z+0, b, ms);
		world.setBlock(x+6, y+2, z+7, b, ms);
		world.setBlock(x+6, y+2, z+8, b, ms);
		world.setBlock(x+6, y+2, z+9, b, ms);
		world.setBlock(x+6, y+2, z+13, b, ms);
		world.setBlock(x+6, y+2, z+14, b, ms);
		world.setBlock(x+6, y+2, z+15, b, ms);
		world.setBlock(x+6, y+2, z+19, b, ms);
		world.setBlock(x+6, y+2, z+20, b, ms);
		world.setBlock(x+6, y+2, z+21, b, ms);
		world.setBlock(x+6, y+2, z+25, b, ms);
		world.setBlock(x+6, y+2, z+26, b, ms);
		world.setBlock(x+6, y+2, z+27, b, ms);
		world.setBlock(x+6, y+2, z+33, b, ms);
		world.setBlock(x+6, y+2, z+34, b, ms);
		world.setBlock(x+6, y+2, z+35, b, ms);
		world.setBlock(x+6, y+2, z+39, b, ms);
		world.setBlock(x+6, y+2, z+40, b, ms);
		world.setBlock(x+6, y+2, z+41, b, ms);
		world.setBlock(x+6, y+2, z+45, b, ms);
		world.setBlock(x+6, y+2, z+46, b, ms);
		world.setBlock(x+6, y+2, z+47, b, ms);
		world.setBlock(x+6, y+2, z+56, b, ms);
		world.setBlock(x+6, y+2, z+57, b, ms);
		world.setBlock(x+6, y+2, z+58, b, ms);
		world.setBlock(x+6, y+2, z+62, b, ms);
		world.setBlock(x+6, y+2, z+63, b, ms);
		world.setBlock(x+6, y+2, z+64, b, ms);
		world.setBlock(x+6, y+2, z+68, b, ms);
		world.setBlock(x+6, y+2, z+69, b, ms);
		world.setBlock(x+6, y+2, z+70, b, ms);
		world.setBlock(x+6, y+2, z+78, b, ms);
		world.setBlock(x+6, y+2, z+79, b, ms);
		world.setBlock(x+6, y+2, z+80, b, ms);
		world.setBlock(x+6, y+3, z+0, b, ms);
		world.setBlock(x+6, y+3, z+7, b, ms);
		world.setBlock(x+6, y+3, z+8, b, ms);
		world.setBlock(x+6, y+3, z+9, b, ms);
		world.setBlock(x+6, y+3, z+13, b, ms);
		world.setBlock(x+6, y+3, z+14, b, ms);
		world.setBlock(x+6, y+3, z+15, b, ms);
		world.setBlock(x+6, y+3, z+19, b, ms);
		world.setBlock(x+6, y+3, z+20, b, ms);
		world.setBlock(x+6, y+3, z+21, b, ms);
		world.setBlock(x+6, y+3, z+25, b, ms);
		world.setBlock(x+6, y+3, z+26, b, ms);
		world.setBlock(x+6, y+3, z+27, b, ms);
		world.setBlock(x+6, y+3, z+33, b, ms);
		world.setBlock(x+6, y+3, z+34, b, ms);
		world.setBlock(x+6, y+3, z+35, b, ms);
		world.setBlock(x+6, y+3, z+39, b, ms);
		world.setBlock(x+6, y+3, z+40, b, ms);
		world.setBlock(x+6, y+3, z+41, b, ms);
		world.setBlock(x+6, y+3, z+45, b, ms);
		world.setBlock(x+6, y+3, z+46, b, ms);
		world.setBlock(x+6, y+3, z+47, b, ms);
		world.setBlock(x+6, y+3, z+56, b, ms);
		world.setBlock(x+6, y+3, z+57, b, ms);
		world.setBlock(x+6, y+3, z+58, b, ms);
		world.setBlock(x+6, y+3, z+62, b, ms);
		world.setBlock(x+6, y+3, z+63, b, ms);
		world.setBlock(x+6, y+3, z+64, b, ms);
		world.setBlock(x+6, y+3, z+68, b, ms);
		world.setBlock(x+6, y+3, z+69, b, ms);
		world.setBlock(x+6, y+3, z+70, b, ms);
		world.setBlock(x+6, y+3, z+78, b, ms);
		world.setBlock(x+6, y+3, z+79, b, ms);
		world.setBlock(x+6, y+3, z+80, b, ms);
		world.setBlock(x+6, y+4, z+0, b, ms);
		world.setBlock(x+6, y+4, z+7, b, ms);
		world.setBlock(x+6, y+4, z+8, b, ms);
		world.setBlock(x+6, y+4, z+9, b, ms);
		world.setBlock(x+6, y+4, z+10, b, ms);
		world.setBlock(x+6, y+4, z+11, b, ms);
		world.setBlock(x+6, y+4, z+12, b, ms);
		world.setBlock(x+6, y+4, z+13, b, ms);
		world.setBlock(x+6, y+4, z+14, b, ms);
		world.setBlock(x+6, y+4, z+15, b, ms);
		world.setBlock(x+6, y+4, z+19, b, ms);
		world.setBlock(x+6, y+4, z+20, b, ms);
		world.setBlock(x+6, y+4, z+21, b, ms);
		world.setBlock(x+6, y+4, z+25, b, ms);
		world.setBlock(x+6, y+4, z+26, b, ms);
		world.setBlock(x+6, y+4, z+27, b, ms);
		world.setBlock(x+6, y+4, z+33, b, ms);
		world.setBlock(x+6, y+4, z+34, b, ms);
		world.setBlock(x+6, y+4, z+35, b, ms);
		world.setBlock(x+6, y+4, z+39, b, ms);
		world.setBlock(x+6, y+4, z+40, b, ms);
		world.setBlock(x+6, y+4, z+41, b, ms);
		world.setBlock(x+6, y+4, z+45, b, ms);
		world.setBlock(x+6, y+4, z+46, b, ms);
		world.setBlock(x+6, y+4, z+47, b, ms);
		world.setBlock(x+6, y+4, z+56, b, ms);
		world.setBlock(x+6, y+4, z+57, b, ms);
		world.setBlock(x+6, y+4, z+58, b, ms);
		world.setBlock(x+6, y+4, z+62, b, ms);
		world.setBlock(x+6, y+4, z+63, b, ms);
		world.setBlock(x+6, y+4, z+64, b, ms);
		world.setBlock(x+6, y+4, z+68, b, ms);
		world.setBlock(x+6, y+4, z+69, b, ms);
		world.setBlock(x+6, y+4, z+70, b, ms);
		world.setBlock(x+6, y+4, z+78, b, ms);
		world.setBlock(x+6, y+4, z+79, b, ms);
		world.setBlock(x+6, y+4, z+80, b, ms);
		world.setBlock(x+6, y+5, z+1, b, ms);
		world.setBlock(x+6, y+5, z+2, b, ms);
		world.setBlock(x+6, y+5, z+3, b, ms);
		world.setBlock(x+6, y+5, z+4, b, ms);
		world.setBlock(x+6, y+5, z+5, b, ms);
		world.setBlock(x+6, y+5, z+6, b, ms);
		world.setBlock(x+6, y+5, z+7, b, ms);
		world.setBlock(x+6, y+5, z+8, b, ms);
		world.setBlock(x+6, y+5, z+9, b, ms);
		world.setBlock(x+6, y+5, z+10, b, ms);
		world.setBlock(x+6, y+5, z+11, b, ms);
		world.setBlock(x+6, y+5, z+12, b, ms);
		world.setBlock(x+6, y+5, z+13, b, ms);
		world.setBlock(x+6, y+5, z+14, b, ms);
		world.setBlock(x+6, y+5, z+15, b, ms);
		world.setBlock(x+6, y+5, z+16, b, ms);
		world.setBlock(x+6, y+5, z+17, b, ms);
		world.setBlock(x+6, y+5, z+18, b, ms);
		world.setBlock(x+6, y+5, z+19, b, ms);
		world.setBlock(x+6, y+5, z+20, b, ms);
		world.setBlock(x+6, y+5, z+21, b, ms);
		world.setBlock(x+6, y+5, z+22, b, ms);
		world.setBlock(x+6, y+5, z+23, b, ms);
		world.setBlock(x+6, y+5, z+24, b, ms);
		world.setBlock(x+6, y+5, z+25, b, ms);
		world.setBlock(x+6, y+5, z+26, b, ms);
		world.setBlock(x+6, y+5, z+27, b, ms);
		world.setBlock(x+6, y+5, z+28, b, ms);
		world.setBlock(x+6, y+5, z+29, b, ms);
		world.setBlock(x+6, y+5, z+30, b, ms);
		world.setBlock(x+6, y+5, z+31, b, ms);
		world.setBlock(x+6, y+5, z+32, b, ms);
		world.setBlock(x+6, y+5, z+33, b, ms);
		world.setBlock(x+6, y+5, z+34, b, ms);
		world.setBlock(x+6, y+5, z+35, b, ms);
		world.setBlock(x+6, y+5, z+36, b, ms);
		world.setBlock(x+6, y+5, z+37, b, ms);
		world.setBlock(x+6, y+5, z+38, b, ms);
		world.setBlock(x+6, y+5, z+39, b, ms);
		world.setBlock(x+6, y+5, z+40, b, ms);
		world.setBlock(x+6, y+5, z+41, b, ms);
		world.setBlock(x+6, y+5, z+42, b, ms);
		world.setBlock(x+6, y+5, z+43, b, ms);
		world.setBlock(x+6, y+5, z+44, b, ms);
		world.setBlock(x+6, y+5, z+45, b, ms);
		world.setBlock(x+6, y+5, z+46, b, ms);
		world.setBlock(x+6, y+5, z+47, b, ms);
		world.setBlock(x+6, y+5, z+48, b, ms);
		world.setBlock(x+6, y+5, z+49, b, ms);
		world.setBlock(x+6, y+5, z+50, b, ms);
		world.setBlock(x+6, y+5, z+51, b, ms);
		world.setBlock(x+6, y+5, z+52, b, ms);
		world.setBlock(x+6, y+5, z+53, b, ms);
		world.setBlock(x+6, y+5, z+54, b, ms);
		world.setBlock(x+6, y+5, z+55, b, ms);
		world.setBlock(x+6, y+5, z+56, b, ms);
		world.setBlock(x+6, y+5, z+57, b, ms);
		world.setBlock(x+6, y+5, z+58, b, ms);
		world.setBlock(x+6, y+5, z+59, b, ms);
		world.setBlock(x+6, y+5, z+60, b, ms);
		world.setBlock(x+6, y+5, z+61, b, ms);
		world.setBlock(x+6, y+5, z+62, b, ms);
		world.setBlock(x+6, y+5, z+63, b, ms);
		world.setBlock(x+6, y+5, z+64, b, ms);
		world.setBlock(x+6, y+5, z+65, b, ms);
		world.setBlock(x+6, y+5, z+66, b, ms);
		world.setBlock(x+6, y+5, z+67, b, ms);
		world.setBlock(x+6, y+5, z+68, b, ms);
		world.setBlock(x+6, y+5, z+69, b, ms);
		world.setBlock(x+6, y+5, z+70, b, ms);
		world.setBlock(x+6, y+5, z+71, b, ms);
		world.setBlock(x+6, y+5, z+72, b, ms);
		world.setBlock(x+6, y+5, z+73, b, ms);
		world.setBlock(x+6, y+5, z+74, b, ms);
		world.setBlock(x+6, y+5, z+75, b, ms);
		world.setBlock(x+6, y+5, z+76, b, ms);
		world.setBlock(x+6, y+5, z+77, b, ms);
		world.setBlock(x+6, y+5, z+78, b, ms);
		world.setBlock(x+7, y+0, z+1, b, ms);
		world.setBlock(x+7, y+0, z+2, b, ms);
		world.setBlock(x+7, y+0, z+3, b, ms);
		world.setBlock(x+7, y+0, z+4, b, ms);
		world.setBlock(x+7, y+0, z+5, b, ms);
		world.setBlock(x+7, y+0, z+6, b, ms);
		world.setBlock(x+7, y+0, z+7, b, ms);
		world.setBlock(x+7, y+0, z+8, b, ms);
		world.setBlock(x+7, y+0, z+9, b, ms);
		world.setBlock(x+7, y+0, z+10, b, ms);
		world.setBlock(x+7, y+0, z+11, b, ms);
		world.setBlock(x+7, y+0, z+12, b, ms);
		world.setBlock(x+7, y+0, z+13, b, ms);
		world.setBlock(x+7, y+0, z+14, b, ms);
		world.setBlock(x+7, y+0, z+15, b, ms);
		world.setBlock(x+7, y+0, z+16, b, ms);
		world.setBlock(x+7, y+0, z+17, b, ms);
		world.setBlock(x+7, y+0, z+18, b, ms);
		world.setBlock(x+7, y+0, z+19, b, ms);
		world.setBlock(x+7, y+0, z+20, b, ms);
		world.setBlock(x+7, y+0, z+21, b, ms);
		world.setBlock(x+7, y+0, z+22, b, ms);
		world.setBlock(x+7, y+0, z+23, b, ms);
		world.setBlock(x+7, y+0, z+24, b, ms);
		world.setBlock(x+7, y+0, z+25, b, ms);
		world.setBlock(x+7, y+0, z+26, b, ms);
		world.setBlock(x+7, y+0, z+27, b, ms);
		world.setBlock(x+7, y+0, z+28, b, ms);
		world.setBlock(x+7, y+0, z+29, b, ms);
		world.setBlock(x+7, y+0, z+30, b, ms);
		world.setBlock(x+7, y+0, z+31, b, ms);
		world.setBlock(x+7, y+0, z+32, b, ms);
		world.setBlock(x+7, y+0, z+33, b, ms);
		world.setBlock(x+7, y+0, z+34, b, ms);
		world.setBlock(x+7, y+0, z+35, b, ms);
		world.setBlock(x+7, y+0, z+36, b, ms);
		world.setBlock(x+7, y+0, z+37, b, ms);
		world.setBlock(x+7, y+0, z+38, b, ms);
		world.setBlock(x+7, y+0, z+39, b, ms);
		world.setBlock(x+7, y+0, z+40, b, ms);
		world.setBlock(x+7, y+0, z+41, b, ms);
		world.setBlock(x+7, y+0, z+42, b, ms);
		world.setBlock(x+7, y+0, z+43, b, ms);
		world.setBlock(x+7, y+0, z+44, b, ms);
		world.setBlock(x+7, y+0, z+45, b, ms);
		world.setBlock(x+7, y+0, z+46, b, ms);
		world.setBlock(x+7, y+0, z+47, b, ms);
		world.setBlock(x+7, y+0, z+48, b, ms);
		world.setBlock(x+7, y+0, z+49, b, ms);
		world.setBlock(x+7, y+0, z+50, b, ms);
		world.setBlock(x+7, y+0, z+51, b, ms);
		world.setBlock(x+7, y+0, z+52, b, ms);
		world.setBlock(x+7, y+0, z+53, b, ms);
		world.setBlock(x+7, y+0, z+54, b, ms);
		world.setBlock(x+7, y+0, z+55, b, ms);
		world.setBlock(x+7, y+0, z+56, b, ms);
		world.setBlock(x+7, y+0, z+57, b, ms);
		world.setBlock(x+7, y+0, z+58, b, ms);
		world.setBlock(x+7, y+0, z+59, b, ms);
		world.setBlock(x+7, y+0, z+60, b, ms);
		world.setBlock(x+7, y+0, z+61, b, ms);
		world.setBlock(x+7, y+0, z+62, b, ms);
		world.setBlock(x+7, y+0, z+63, b, ms);
		world.setBlock(x+7, y+0, z+64, b, ms);
		world.setBlock(x+7, y+0, z+65, b, ms);
		world.setBlock(x+7, y+0, z+66, b, ms);
		world.setBlock(x+7, y+0, z+67, b, ms);
		world.setBlock(x+7, y+0, z+68, b, ms);
		world.setBlock(x+7, y+0, z+69, b, ms);
		world.setBlock(x+7, y+0, z+70, b, ms);
		world.setBlock(x+7, y+0, z+71, b, ms);
		world.setBlock(x+7, y+0, z+72, b, ms);
		world.setBlock(x+7, y+0, z+73, b, ms);
		world.setBlock(x+7, y+0, z+74, b, ms);
		world.setBlock(x+7, y+0, z+75, b, ms);
		world.setBlock(x+7, y+0, z+76, b, ms);
		world.setBlock(x+7, y+0, z+77, b, ms);
		world.setBlock(x+7, y+0, z+78, b, ms);
		world.setBlock(x+7, y+1, z+1, b, ms);
		world.setBlock(x+7, y+1, z+6, b, ms);
		world.setBlock(x+7, y+1, z+7, b, ms);
		world.setBlock(x+7, y+1, z+8, b, ms);
		world.setBlock(x+7, y+1, z+9, b, ms);
		world.setBlock(x+7, y+1, z+10, b, ms);
		world.setBlock(x+7, y+1, z+11, b, ms);
		world.setBlock(x+7, y+1, z+12, b, ms);
		world.setBlock(x+7, y+1, z+13, b, ms);
		world.setBlock(x+7, y+1, z+14, b, ms);
		world.setBlock(x+7, y+1, z+15, b, ms);
		world.setBlock(x+7, y+1, z+16, b, ms);
		world.setBlock(x+7, y+1, z+17, b, ms);
		world.setBlock(x+7, y+1, z+18, b, ms);
		world.setBlock(x+7, y+1, z+19, b, ms);
		world.setBlock(x+7, y+1, z+20, b, ms);
		world.setBlock(x+7, y+1, z+21, b, ms);
		world.setBlock(x+7, y+1, z+22, b, ms);
		world.setBlock(x+7, y+1, z+23, b, ms);
		world.setBlock(x+7, y+1, z+24, b, ms);
		world.setBlock(x+7, y+1, z+25, b, ms);
		world.setBlock(x+7, y+1, z+26, b, ms);
		world.setBlock(x+7, y+1, z+27, b, ms);
		world.setBlock(x+7, y+1, z+28, b, ms);
		world.setBlock(x+7, y+1, z+32, b, ms);
		world.setBlock(x+7, y+1, z+33, b, ms);
		world.setBlock(x+7, y+1, z+34, b, ms);
		world.setBlock(x+7, y+1, z+35, b, ms);
		world.setBlock(x+7, y+1, z+36, b, ms);
		world.setBlock(x+7, y+1, z+37, b, ms);
		world.setBlock(x+7, y+1, z+38, b, ms);
		world.setBlock(x+7, y+1, z+39, b, ms);
		world.setBlock(x+7, y+1, z+40, b, ms);
		world.setBlock(x+7, y+1, z+41, b, ms);
		world.setBlock(x+7, y+1, z+42, b, ms);
		world.setBlock(x+7, y+1, z+43, b, ms);
		world.setBlock(x+7, y+1, z+44, b, ms);
		world.setBlock(x+7, y+1, z+45, b, ms);
		world.setBlock(x+7, y+1, z+46, b, ms);
		world.setBlock(x+7, y+1, z+47, b, ms);
		world.setBlock(x+7, y+1, z+48, b, ms);
		world.setBlock(x+7, y+1, z+49, b, ms);
		world.setBlock(x+7, y+1, z+50, b, ms);
		world.setBlock(x+7, y+1, z+51, b, ms);
		world.setBlock(x+7, y+1, z+52, b, ms);
		world.setBlock(x+7, y+1, z+53, b, ms);
		world.setBlock(x+7, y+1, z+54, b, ms);
		world.setBlock(x+7, y+1, z+55, b, ms);
		world.setBlock(x+7, y+1, z+56, b, ms);
		world.setBlock(x+7, y+1, z+57, b, ms);
		world.setBlock(x+7, y+1, z+58, b, ms);
		world.setBlock(x+7, y+1, z+59, b, ms);
		world.setBlock(x+7, y+1, z+60, b, ms);
		world.setBlock(x+7, y+1, z+61, b, ms);
		world.setBlock(x+7, y+1, z+62, b, ms);
		world.setBlock(x+7, y+1, z+63, b, ms);
		world.setBlock(x+7, y+1, z+64, b, ms);
		world.setBlock(x+7, y+1, z+65, b, ms);
		world.setBlock(x+7, y+1, z+66, b, ms);
		world.setBlock(x+7, y+1, z+67, b, ms);
		world.setBlock(x+7, y+1, z+68, b, ms);
		world.setBlock(x+7, y+1, z+69, b, ms);
		world.setBlock(x+7, y+1, z+70, b, ms);
		world.setBlock(x+7, y+1, z+71, b, ms);
		world.setBlock(x+7, y+1, z+72, b, ms);
		world.setBlock(x+7, y+1, z+73, b, ms);
		world.setBlock(x+7, y+1, z+74, b, ms);
		world.setBlock(x+7, y+1, z+75, b, ms);
		world.setBlock(x+7, y+1, z+76, b, ms);
		world.setBlock(x+7, y+1, z+77, b, ms);
		world.setBlock(x+7, y+1, z+78, b, ms);
		world.setBlock(x+7, y+2, z+1, b, ml);
		world.setBlock(x+7, y+2, z+6, b, ms);
		world.setBlock(x+7, y+2, z+7, b, ms);
		world.setBlock(x+7, y+2, z+8, b, ms);
		world.setBlock(x+7, y+2, z+9, b, ms);
		world.setBlock(x+7, y+2, z+10, b, ms);
		world.setBlock(x+7, y+2, z+11, b, ml);
		world.setBlock(x+7, y+2, z+12, b, ms);
		world.setBlock(x+7, y+2, z+13, b, ms);
		world.setBlock(x+7, y+2, z+14, b, ms);
		world.setBlock(x+7, y+2, z+15, b, ms);
		world.setBlock(x+7, y+2, z+16, b, ms);
		world.setBlock(x+7, y+2, z+17, b, ml);
		world.setBlock(x+7, y+2, z+18, b, ms);
		world.setBlock(x+7, y+2, z+19, b, ms);
		world.setBlock(x+7, y+2, z+20, b, ms);
		world.setBlock(x+7, y+2, z+21, b, ms);
		world.setBlock(x+7, y+2, z+22, b, ms);
		world.setBlock(x+7, y+2, z+23, b, ms);
		world.setBlock(x+7, y+2, z+24, b, ms);
		world.setBlock(x+7, y+2, z+25, b, ms);
		world.setBlock(x+7, y+2, z+26, b, ms);
		world.setBlock(x+7, y+2, z+27, b, ms);
		world.setBlock(x+7, y+2, z+28, b, ms);
		world.setBlock(x+7, y+2, z+32, b, ml);
		world.setBlock(x+7, y+2, z+33, b, ms);
		world.setBlock(x+7, y+2, z+34, b, ms);
		world.setBlock(x+7, y+2, z+35, b, ms);
		world.setBlock(x+7, y+2, z+36, b, ms);
		world.setBlock(x+7, y+2, z+37, b, ml);
		world.setBlock(x+7, y+2, z+38, b, ms);
		world.setBlock(x+7, y+2, z+39, b, ms);
		world.setBlock(x+7, y+2, z+40, b, ms);
		world.setBlock(x+7, y+2, z+41, b, ms);
		world.setBlock(x+7, y+2, z+42, b, ms);
		world.setBlock(x+7, y+2, z+43, b, ml);
		world.setBlock(x+7, y+2, z+44, b, ms);
		world.setBlock(x+7, y+2, z+45, b, ms);
		world.setBlock(x+7, y+2, z+46, b, ms);
		world.setBlock(x+7, y+2, z+47, b, ms);
		world.setBlock(x+7, y+2, z+48, b, ms);
		world.setBlock(x+7, y+2, z+49, b, ms);
		world.setBlock(x+7, y+2, z+50, b, ms);
		world.setBlock(x+7, y+2, z+51, b, ms);
		world.setBlock(x+7, y+2, z+52, b, ms);
		world.setBlock(x+7, y+2, z+53, b, ms);
		world.setBlock(x+7, y+2, z+54, b, ml);
		world.setBlock(x+7, y+2, z+55, b, ms);
		world.setBlock(x+7, y+2, z+56, b, ms);
		world.setBlock(x+7, y+2, z+57, b, ms);
		world.setBlock(x+7, y+2, z+58, b, ms);
		world.setBlock(x+7, y+2, z+59, b, ms);
		world.setBlock(x+7, y+2, z+60, b, ml);
		world.setBlock(x+7, y+2, z+61, b, ms);
		world.setBlock(x+7, y+2, z+62, b, ms);
		world.setBlock(x+7, y+2, z+63, b, ms);
		world.setBlock(x+7, y+2, z+64, b, ms);
		world.setBlock(x+7, y+2, z+65, b, ms);
		world.setBlock(x+7, y+2, z+66, b, ml);
		world.setBlock(x+7, y+2, z+67, b, ms);
		world.setBlock(x+7, y+2, z+68, b, ms);
		world.setBlock(x+7, y+2, z+69, b, ms);
		world.setBlock(x+7, y+2, z+70, b, ms);
		world.setBlock(x+7, y+2, z+71, b, ms);
		world.setBlock(x+7, y+2, z+72, b, ms);
		world.setBlock(x+7, y+2, z+73, b, ms);
		world.setBlock(x+7, y+2, z+74, b, ms);
		world.setBlock(x+7, y+2, z+75, b, ml);
		world.setBlock(x+7, y+2, z+76, b, ms);
		world.setBlock(x+7, y+2, z+77, b, ms);
		world.setBlock(x+7, y+2, z+78, b, ms);
		world.setBlock(x+7, y+3, z+1, b, ms);
		world.setBlock(x+7, y+3, z+6, b, ms);
		world.setBlock(x+7, y+3, z+7, b, ms);
		world.setBlock(x+7, y+3, z+8, b, ms);
		world.setBlock(x+7, y+3, z+9, b, ms);
		world.setBlock(x+7, y+3, z+10, b, ms);
		world.setBlock(x+7, y+3, z+11, b, ms);
		world.setBlock(x+7, y+3, z+12, b, ms);
		world.setBlock(x+7, y+3, z+13, b, ms);
		world.setBlock(x+7, y+3, z+14, b, ms);
		world.setBlock(x+7, y+3, z+15, b, ms);
		world.setBlock(x+7, y+3, z+16, b, ms);
		world.setBlock(x+7, y+3, z+17, b, ms);
		world.setBlock(x+7, y+3, z+18, b, ms);
		world.setBlock(x+7, y+3, z+19, b, ms);
		world.setBlock(x+7, y+3, z+20, b, ms);
		world.setBlock(x+7, y+3, z+21, b, ms);
		world.setBlock(x+7, y+3, z+22, b, ms);
		world.setBlock(x+7, y+3, z+23, b, ms);
		world.setBlock(x+7, y+3, z+24, b, ms);
		world.setBlock(x+7, y+3, z+25, b, ms);
		world.setBlock(x+7, y+3, z+26, b, ms);
		world.setBlock(x+7, y+3, z+27, b, ms);
		world.setBlock(x+7, y+3, z+28, b, ms);
		world.setBlock(x+7, y+3, z+32, b, ms);
		world.setBlock(x+7, y+3, z+33, b, ms);
		world.setBlock(x+7, y+3, z+34, b, ms);
		world.setBlock(x+7, y+3, z+35, b, ms);
		world.setBlock(x+7, y+3, z+36, b, ms);
		world.setBlock(x+7, y+3, z+37, b, ms);
		world.setBlock(x+7, y+3, z+38, b, ms);
		world.setBlock(x+7, y+3, z+39, b, ms);
		world.setBlock(x+7, y+3, z+40, b, ms);
		world.setBlock(x+7, y+3, z+41, b, ms);
		world.setBlock(x+7, y+3, z+42, b, ms);
		world.setBlock(x+7, y+3, z+43, b, ms);
		world.setBlock(x+7, y+3, z+44, b, ms);
		world.setBlock(x+7, y+3, z+45, b, ms);
		world.setBlock(x+7, y+3, z+46, b, ms);
		world.setBlock(x+7, y+3, z+47, b, ms);
		world.setBlock(x+7, y+3, z+48, b, ms);
		world.setBlock(x+7, y+3, z+49, b, ms);
		world.setBlock(x+7, y+3, z+50, b, ms);
		world.setBlock(x+7, y+3, z+51, b, ms);
		world.setBlock(x+7, y+3, z+52, b, ms);
		world.setBlock(x+7, y+3, z+53, b, ms);
		world.setBlock(x+7, y+3, z+54, b, ms);
		world.setBlock(x+7, y+3, z+55, b, ms);
		world.setBlock(x+7, y+3, z+56, b, ms);
		world.setBlock(x+7, y+3, z+57, b, ms);
		world.setBlock(x+7, y+3, z+58, b, ms);
		world.setBlock(x+7, y+3, z+59, b, ms);
		world.setBlock(x+7, y+3, z+60, b, ms);
		world.setBlock(x+7, y+3, z+61, b, ms);
		world.setBlock(x+7, y+3, z+62, b, ms);
		world.setBlock(x+7, y+3, z+63, b, ms);
		world.setBlock(x+7, y+3, z+64, b, ms);
		world.setBlock(x+7, y+3, z+65, b, ms);
		world.setBlock(x+7, y+3, z+66, b, ms);
		world.setBlock(x+7, y+3, z+67, b, ms);
		world.setBlock(x+7, y+3, z+68, b, ms);
		world.setBlock(x+7, y+3, z+69, b, ms);
		world.setBlock(x+7, y+3, z+70, b, ms);
		world.setBlock(x+7, y+3, z+71, b, ms);
		world.setBlock(x+7, y+3, z+72, b, ms);
		world.setBlock(x+7, y+3, z+73, b, ms);
		world.setBlock(x+7, y+3, z+74, b, ms);
		world.setBlock(x+7, y+3, z+75, b, ms);
		world.setBlock(x+7, y+3, z+76, b, ms);
		world.setBlock(x+7, y+3, z+77, b, ms);
		world.setBlock(x+7, y+3, z+78, b, ms);
		world.setBlock(x+7, y+4, z+1, b, ms);
		world.setBlock(x+7, y+4, z+6, b, ms);
		world.setBlock(x+7, y+4, z+7, b, ms);
		world.setBlock(x+7, y+4, z+8, b, ms);
		world.setBlock(x+7, y+4, z+9, b, ms);
		world.setBlock(x+7, y+4, z+10, b, ms);
		world.setBlock(x+7, y+4, z+11, b, ms);
		world.setBlock(x+7, y+4, z+12, b, ms);
		world.setBlock(x+7, y+4, z+13, b, ms);
		world.setBlock(x+7, y+4, z+14, b, ms);
		world.setBlock(x+7, y+4, z+15, b, ms);
		world.setBlock(x+7, y+4, z+16, b, ms);
		world.setBlock(x+7, y+4, z+17, b, ms);
		world.setBlock(x+7, y+4, z+18, b, ms);
		world.setBlock(x+7, y+4, z+19, b, ms);
		world.setBlock(x+7, y+4, z+20, b, ms);
		world.setBlock(x+7, y+4, z+21, b, ms);
		world.setBlock(x+7, y+4, z+22, b, ms);
		world.setBlock(x+7, y+4, z+23, b, ms);
		world.setBlock(x+7, y+4, z+24, b, ms);
		world.setBlock(x+7, y+4, z+25, b, ms);
		world.setBlock(x+7, y+4, z+26, b, ms);
		world.setBlock(x+7, y+4, z+27, b, ms);
		world.setBlock(x+7, y+4, z+28, b, ms);
		world.setBlock(x+7, y+4, z+32, b, ms);
		world.setBlock(x+7, y+4, z+33, b, ms);
		world.setBlock(x+7, y+4, z+34, b, ms);
		world.setBlock(x+7, y+4, z+35, b, ms);
		world.setBlock(x+7, y+4, z+36, b, ms);
		world.setBlock(x+7, y+4, z+37, b, ms);
		world.setBlock(x+7, y+4, z+38, b, ms);
		world.setBlock(x+7, y+4, z+39, b, ms);
		world.setBlock(x+7, y+4, z+40, b, ms);
		world.setBlock(x+7, y+4, z+41, b, ms);
		world.setBlock(x+7, y+4, z+42, b, ms);
		world.setBlock(x+7, y+4, z+43, b, ms);
		world.setBlock(x+7, y+4, z+44, b, ms);
		world.setBlock(x+7, y+4, z+45, b, ms);
		world.setBlock(x+7, y+4, z+46, b, ms);
		world.setBlock(x+7, y+4, z+47, b, ms);
		world.setBlock(x+7, y+4, z+48, b, ms);
		world.setBlock(x+7, y+4, z+49, b, ms);
		world.setBlock(x+7, y+4, z+50, b, ms);
		world.setBlock(x+7, y+4, z+51, b, ms);
		world.setBlock(x+7, y+4, z+52, b, ms);
		world.setBlock(x+7, y+4, z+53, b, ms);
		world.setBlock(x+7, y+4, z+54, b, ms);
		world.setBlock(x+7, y+4, z+55, b, ms);
		world.setBlock(x+7, y+4, z+56, b, ms);
		world.setBlock(x+7, y+4, z+57, b, ms);
		world.setBlock(x+7, y+4, z+58, b, ms);
		world.setBlock(x+7, y+4, z+59, b, ms);
		world.setBlock(x+7, y+4, z+60, b, ms);
		world.setBlock(x+7, y+4, z+61, b, ms);
		world.setBlock(x+7, y+4, z+62, b, ms);
		world.setBlock(x+7, y+4, z+63, b, ms);
		world.setBlock(x+7, y+4, z+64, b, ms);
		world.setBlock(x+7, y+4, z+65, b, ms);
		world.setBlock(x+7, y+4, z+66, b, ms);
		world.setBlock(x+7, y+4, z+67, b, ms);
		world.setBlock(x+7, y+4, z+68, b, ms);
		world.setBlock(x+7, y+4, z+69, b, ms);
		world.setBlock(x+7, y+4, z+70, b, ms);
		world.setBlock(x+7, y+4, z+71, b, ms);
		world.setBlock(x+7, y+4, z+72, b, ms);
		world.setBlock(x+7, y+4, z+73, b, ms);
		world.setBlock(x+7, y+4, z+74, b, ms);
		world.setBlock(x+7, y+4, z+75, b, ms);
		world.setBlock(x+7, y+4, z+76, b, ms);
		world.setBlock(x+7, y+4, z+77, b, ms);
		world.setBlock(x+7, y+4, z+78, b, ms);
		world.setBlock(x+7, y+5, z+1, b, ms);
		world.setBlock(x+7, y+5, z+2, b, ms);
		world.setBlock(x+7, y+5, z+3, b, ms);
		world.setBlock(x+7, y+5, z+4, b, ms);
		world.setBlock(x+7, y+5, z+5, b, ms);
		world.setBlock(x+7, y+5, z+6, b, ms);
		world.setBlock(x+7, y+5, z+28, b, ms);
		world.setBlock(x+7, y+5, z+29, b, ms);
		world.setBlock(x+7, y+5, z+30, b, ms);
		world.setBlock(x+7, y+5, z+31, b, ms);
		world.setBlock(x+7, y+5, z+32, b, ms);
		world.setBlock(x+7, y+5, z+33, b, ms);
		world.setBlock(x+7, y+5, z+34, b, ms);
		world.setBlock(x+7, y+5, z+35, b, ms);
		world.setBlock(x+7, y+5, z+36, b, ms);
		world.setBlock(x+7, y+5, z+37, b, ms);
		world.setBlock(x+7, y+5, z+38, b, ms);
		world.setBlock(x+7, y+5, z+39, b, ms);
		world.setBlock(x+7, y+5, z+40, b, ms);
		world.setBlock(x+7, y+5, z+41, b, ms);
		world.setBlock(x+7, y+5, z+42, b, ms);
		world.setBlock(x+7, y+5, z+43, b, ms);
		world.setBlock(x+7, y+5, z+44, b, ms);
		world.setBlock(x+7, y+5, z+45, b, ms);
		world.setBlock(x+7, y+5, z+46, b, ms);
		world.setBlock(x+7, y+5, z+47, b, ms);
		world.setBlock(x+7, y+5, z+48, b, ms);
		world.setBlock(x+7, y+5, z+49, b, ms);
		world.setBlock(x+7, y+5, z+50, b, ms);
		world.setBlock(x+7, y+5, z+51, b, ms);
		world.setBlock(x+7, y+5, z+52, b, ms);
		world.setBlock(x+7, y+5, z+53, b, ms);
		world.setBlock(x+7, y+5, z+54, b, ms);
		world.setBlock(x+7, y+5, z+55, b, ms);
		world.setBlock(x+7, y+5, z+56, b, ms);
		world.setBlock(x+7, y+5, z+57, b, ms);
		world.setBlock(x+7, y+5, z+58, b, ms);
		world.setBlock(x+7, y+5, z+59, b, ms);
		world.setBlock(x+7, y+5, z+60, b, ms);
		world.setBlock(x+7, y+5, z+61, b, ms);
		world.setBlock(x+7, y+5, z+62, b, ms);
		world.setBlock(x+7, y+5, z+63, b, ms);
		world.setBlock(x+7, y+5, z+64, b, ms);
		world.setBlock(x+7, y+5, z+65, b, ms);
		world.setBlock(x+7, y+5, z+66, b, ms);
		world.setBlock(x+7, y+5, z+67, b, ms);
		world.setBlock(x+7, y+5, z+68, b, ms);
		world.setBlock(x+7, y+5, z+69, b, ms);
		world.setBlock(x+7, y+5, z+70, b, ms);
		world.setBlock(x+7, y+5, z+71, b, ms);
		world.setBlock(x+7, y+5, z+72, b, ms);
		world.setBlock(x+7, y+5, z+73, b, ms);
		world.setBlock(x+7, y+5, z+74, b, ms);
		world.setBlock(x+7, y+5, z+75, b, ms);
		world.setBlock(x+7, y+5, z+76, b, ms);
		world.setBlock(x+7, y+5, z+77, b, ms);
		world.setBlock(x+7, y+5, z+78, b, ms);
		world.setBlock(x+8, y+0, z+1, b, ms);
		world.setBlock(x+8, y+0, z+2, b, ms);
		world.setBlock(x+8, y+0, z+3, b, ms);
		world.setBlock(x+8, y+0, z+4, b, ms);
		world.setBlock(x+8, y+0, z+5, b, ms);
		world.setBlock(x+8, y+0, z+28, b, ms);
		world.setBlock(x+8, y+0, z+29, b, ms);
		world.setBlock(x+8, y+0, z+30, b, ms);
		world.setBlock(x+8, y+0, z+31, b, ms);
		world.setBlock(x+8, y+0, z+32, b, ms);
		world.setBlock(x+8, y+1, z+1, b, ms);
		world.setBlock(x+8, y+1, z+2, b, ms);
		world.setBlock(x+8, y+1, z+3, b, ms);
		world.setBlock(x+8, y+1, z+4, b, ms);
		world.setBlock(x+8, y+1, z+5, b, ms);
		world.setBlock(x+8, y+1, z+28, b, ms);
		world.setBlock(x+8, y+1, z+29, b, ms);
		world.setBlock(x+8, y+1, z+30, b, ms);
		world.setBlock(x+8, y+1, z+31, b, ms);
		world.setBlock(x+8, y+1, z+32, b, ms);
		world.setBlock(x+8, y+2, z+1, b, ms);
		world.setBlock(x+8, y+2, z+2, b, ms);
		world.setBlock(x+8, y+2, z+3, b, ms);
		world.setBlock(x+8, y+2, z+4, b, ms);
		world.setBlock(x+8, y+2, z+5, b, ms);
		world.setBlock(x+8, y+2, z+28, b, ms);
		world.setBlock(x+8, y+2, z+29, b, ms);
		world.setBlock(x+8, y+2, z+30, b, ms);
		world.setBlock(x+8, y+2, z+31, b, ms);
		world.setBlock(x+8, y+2, z+32, b, ms);
		world.setBlock(x+8, y+3, z+1, b, ms);
		world.setBlock(x+8, y+3, z+2, b, ms);
		world.setBlock(x+8, y+3, z+3, b, ms);
		world.setBlock(x+8, y+3, z+4, b, ms);
		world.setBlock(x+8, y+3, z+5, b, ms);
		world.setBlock(x+8, y+3, z+28, b, ms);
		world.setBlock(x+8, y+3, z+29, b, ms);
		world.setBlock(x+8, y+3, z+30, b, ms);
		world.setBlock(x+8, y+3, z+31, b, ms);
		world.setBlock(x+8, y+3, z+32, b, ms);
		world.setBlock(x+8, y+4, z+1, b, ms);
		world.setBlock(x+8, y+4, z+2, b, ms);
		world.setBlock(x+8, y+4, z+3, b, ms);
		world.setBlock(x+8, y+4, z+4, b, ms);
		world.setBlock(x+8, y+4, z+5, b, ms);
		world.setBlock(x+8, y+4, z+28, b, ms);
		world.setBlock(x+8, y+4, z+29, b, ms);
		world.setBlock(x+8, y+4, z+30, b, ms);
		world.setBlock(x+8, y+4, z+31, b, ms);
		world.setBlock(x+8, y+4, z+32, b, ms);
		world.setBlock(x+8, y+5, z+1, b, ms);
		world.setBlock(x+8, y+5, z+2, b, ms);
		world.setBlock(x+8, y+5, z+3, b, ms);
		world.setBlock(x+8, y+5, z+4, b, ms);
		world.setBlock(x+8, y+5, z+5, b, ms);
		world.setBlock(x+1, y+1, z+2, Blocks.air);
		world.setBlock(x+1, y+1, z+3, Blocks.air);
		world.setBlock(x+1, y+1, z+4, Blocks.air);
		world.setBlock(x+1, y+1, z+5, Blocks.air);
		world.setBlock(x+1, y+1, z+29, Blocks.air);
		world.setBlock(x+1, y+1, z+30, Blocks.air);
		world.setBlock(x+1, y+1, z+31, Blocks.air);
		world.setBlock(x+1, y+2, z+2, Blocks.air);
		world.setBlock(x+1, y+2, z+3, Blocks.air);
		world.setBlock(x+1, y+2, z+4, Blocks.air);
		world.setBlock(x+1, y+2, z+5, Blocks.air);
		world.setBlock(x+1, y+2, z+29, Blocks.air);
		world.setBlock(x+1, y+2, z+30, Blocks.air);
		world.setBlock(x+1, y+2, z+31, Blocks.air);
		world.setBlock(x+1, y+3, z+2, Blocks.air);
		world.setBlock(x+1, y+3, z+3, Blocks.air);
		world.setBlock(x+1, y+3, z+4, Blocks.air);
		world.setBlock(x+1, y+3, z+5, Blocks.air);
		world.setBlock(x+1, y+3, z+29, Blocks.air);
		world.setBlock(x+1, y+3, z+30, Blocks.air);
		world.setBlock(x+1, y+3, z+31, Blocks.air);
		world.setBlock(x+1, y+4, z+2, Blocks.air);
		world.setBlock(x+1, y+4, z+3, Blocks.air);
		world.setBlock(x+1, y+4, z+4, Blocks.air);
		world.setBlock(x+1, y+4, z+5, Blocks.air);
		world.setBlock(x+1, y+4, z+29, Blocks.air);
		world.setBlock(x+1, y+4, z+30, Blocks.air);
		world.setBlock(x+1, y+4, z+31, Blocks.air);
		world.setBlock(x+2, y+1, z+1, Blocks.air);
		world.setBlock(x+2, y+1, z+2, Blocks.air);
		world.setBlock(x+2, y+1, z+3, Blocks.air);
		world.setBlock(x+2, y+1, z+4, Blocks.air);
		world.setBlock(x+2, y+1, z+5, Blocks.air);
		world.setBlock(x+2, y+1, z+6, Blocks.air);
		world.setBlock(x+2, y+1, z+10, Blocks.air);
		world.setBlock(x+2, y+1, z+11, Blocks.air);
		world.setBlock(x+2, y+1, z+12, Blocks.air);
		world.setBlock(x+2, y+1, z+16, Blocks.air);
		world.setBlock(x+2, y+1, z+18, Blocks.air);
		world.setBlock(x+2, y+1, z+22, Blocks.air);
		world.setBlock(x+2, y+1, z+23, Blocks.air);
		world.setBlock(x+2, y+1, z+24, Blocks.air);
		world.setBlock(x+2, y+1, z+28, Blocks.air);
		world.setBlock(x+2, y+1, z+29, Blocks.air);
		world.setBlock(x+2, y+1, z+30, Blocks.air);
		world.setBlock(x+2, y+1, z+31, Blocks.air);
		world.setBlock(x+2, y+1, z+32, Blocks.air);
		world.setBlock(x+2, y+1, z+36, Blocks.air);
		world.setBlock(x+2, y+1, z+37, Blocks.air);
		world.setBlock(x+2, y+1, z+38, Blocks.air);
		world.setBlock(x+2, y+1, z+42, Blocks.air);
		world.setBlock(x+2, y+1, z+43, Blocks.air);
		world.setBlock(x+2, y+1, z+44, Blocks.air);
		world.setBlock(x+2, y+1, z+48, Blocks.air);
		world.setBlock(x+2, y+1, z+49, Blocks.air);
		world.setBlock(x+2, y+1, z+50, Blocks.air);
		world.setBlock(x+2, y+1, z+51, Blocks.air);
		world.setBlock(x+2, y+1, z+52, Blocks.air);
		world.setBlock(x+2, y+1, z+53, Blocks.air);
		world.setBlock(x+2, y+1, z+54, Blocks.air);
		world.setBlock(x+2, y+1, z+55, Blocks.air);
		world.setBlock(x+2, y+1, z+59, Blocks.air);
		world.setBlock(x+2, y+1, z+60, Blocks.air);
		world.setBlock(x+2, y+1, z+61, Blocks.air);
		world.setBlock(x+2, y+1, z+65, Blocks.air);
		world.setBlock(x+2, y+1, z+66, Blocks.air);
		world.setBlock(x+2, y+1, z+67, Blocks.air);
		world.setBlock(x+2, y+1, z+71, Blocks.air);
		world.setBlock(x+2, y+1, z+72, Blocks.air);
		world.setBlock(x+2, y+1, z+73, Blocks.air);
		world.setBlock(x+2, y+1, z+74, Blocks.air);
		world.setBlock(x+2, y+1, z+75, Blocks.air);
		world.setBlock(x+2, y+1, z+76, Blocks.air);
		world.setBlock(x+2, y+1, z+77, Blocks.air);
		world.setBlock(x+2, y+2, z+1, Blocks.air);
		world.setBlock(x+2, y+2, z+2, Blocks.air);
		world.setBlock(x+2, y+2, z+3, Blocks.air);
		world.setBlock(x+2, y+2, z+4, Blocks.air);
		world.setBlock(x+2, y+2, z+5, Blocks.air);
		world.setBlock(x+2, y+2, z+6, Blocks.air);
		world.setBlock(x+2, y+2, z+10, Blocks.air);
		world.setBlock(x+2, y+2, z+11, Blocks.air);
		world.setBlock(x+2, y+2, z+12, Blocks.air);
		world.setBlock(x+2, y+2, z+16, Blocks.air);
		world.setBlock(x+2, y+2, z+17, Blocks.air);
		world.setBlock(x+2, y+2, z+18, Blocks.air);
		world.setBlock(x+2, y+2, z+22, Blocks.air);
		world.setBlock(x+2, y+2, z+23, Blocks.air);
		world.setBlock(x+2, y+2, z+24, Blocks.air);
		world.setBlock(x+2, y+2, z+28, Blocks.air);
		world.setBlock(x+2, y+2, z+29, Blocks.air);
		world.setBlock(x+2, y+2, z+30, Blocks.air);
		world.setBlock(x+2, y+2, z+31, Blocks.air);
		world.setBlock(x+2, y+2, z+32, Blocks.air);
		world.setBlock(x+2, y+2, z+36, Blocks.air);
		world.setBlock(x+2, y+2, z+37, Blocks.air);
		world.setBlock(x+2, y+2, z+38, Blocks.air);
		world.setBlock(x+2, y+2, z+42, Blocks.air);
		world.setBlock(x+2, y+2, z+43, Blocks.air);
		world.setBlock(x+2, y+2, z+44, Blocks.air);
		world.setBlock(x+2, y+2, z+48, Blocks.air);
		world.setBlock(x+2, y+2, z+49, Blocks.air);
		world.setBlock(x+2, y+2, z+50, Blocks.air);
		world.setBlock(x+2, y+2, z+51, Blocks.air);
		world.setBlock(x+2, y+2, z+52, Blocks.air);
		world.setBlock(x+2, y+2, z+53, Blocks.air);
		world.setBlock(x+2, y+2, z+54, Blocks.air);
		world.setBlock(x+2, y+2, z+55, Blocks.air);
		world.setBlock(x+2, y+2, z+59, Blocks.air);
		world.setBlock(x+2, y+2, z+60, Blocks.air);
		world.setBlock(x+2, y+2, z+61, Blocks.air);
		world.setBlock(x+2, y+2, z+65, Blocks.air);
		world.setBlock(x+2, y+2, z+66, Blocks.air);
		world.setBlock(x+2, y+2, z+67, Blocks.air);
		world.setBlock(x+2, y+2, z+71, Blocks.air);
		world.setBlock(x+2, y+2, z+72, Blocks.air);
		world.setBlock(x+2, y+2, z+73, Blocks.air);
		world.setBlock(x+2, y+2, z+74, Blocks.air);
		world.setBlock(x+2, y+2, z+75, Blocks.air);
		world.setBlock(x+2, y+2, z+76, Blocks.air);
