/*******************************************************************************
 * @author Reika Kalseki
 * 
 * Copyright 2015
 * 
 * All rights reserved.
 * Distribution of the software in any form is only allowed with
 * explicit, prior permission from the owner.
 ******************************************************************************/
package Reika.ChromatiCraft.World.Dimension.Structure.ShiftMaze;

import java.util.Random;

import net.minecraft.block.Block;
import net.minecraft.init.Blocks;
import Reika.ChromatiCraft.Base.DimensionStructureGenerator;
import Reika.ChromatiCraft.Base.StructurePiece;
import Reika.ChromatiCraft.Block.Worldgen.BlockStructureShield.BlockType;
import Reika.ChromatiCraft.Registry.ChromaBlocks;
import Reika.DragonAPI.Instantiable.Worldgen.ChunkSplicedGenerationCache;


public class FixedMaze extends StructurePiece {

	private final Random rand;

	private final Block b = ChromaBlocks.STRUCTSHIELD.getBlockInstance();
	private final int ms = BlockType.STONE.metadata;
	private final int mg = BlockType.GLASS.metadata;
	private final int ml = BlockType.LIGHT.metadata;

	private static final boolean[][] lightPattern = new boolean[8][8];

	static {
		lightPattern[0][0] = true;
		lightPattern[0][5] = true;
		lightPattern[1][1] = true;
		lightPattern[1][3] = true;
		lightPattern[1][6] = true;
		lightPattern[2][0] = true;
		lightPattern[2][4] = true;
		lightPattern[3][2] = true;
		lightPattern[3][6] = true;
		lightPattern[4][1] = true;
		lightPattern[4][5] = true;
		lightPattern[5][3] = true;
		lightPattern[5][7] = true;
		lightPattern[6][1] = true;
		lightPattern[6][4] = true;
		lightPattern[6][6] = true;
		lightPattern[7][2] = true;
		lightPattern[7][7] = true;
	}

	public FixedMaze(DimensionStructureGenerator s, Random r) {
		super(s);
		rand = r;
	}

	@Override
	public void generate(ChunkSplicedGenerationCache world, int x, int y, int z) {
		this.doGenerate(world, x, y, z);
		this.doGenerate2(world, x, y, z);
		this.doGenerate3(world, x, y, z);

		for (int i = -1; i <= 25; i++) {
			for (int k = 0; k <= 8; k++) {
				world.setBlock(x+i, y+k, z-1, b, ms);
				world.setBlock(x+i, y+k, z+25, b, ms);
				world.setBlock(x-1, y+k, z+i, b, ms);
				world.setBlock(x+25, y+k, z+i, b, ms);
			}
		}

		for (int i = 0; i <= 24; i++) {
			for (int k = 3; k <= 8; k++) {
				int m = k == 3 && i%2 == 0 ? ml : ms;
				world.setBlock(x+i, y+k, z+0, b, m);
				world.setBlock(x+i, y+k, z+24, b, m);
				world.setBlock(x+0, y+k, z+i, b, m);
				world.setBlock(x+24, y+k, z+i, b, m);
			}
		}

		for (int i = 1; i < 24; i++) {
			for (int k = 1; k < 24; k++) {
				int dx = x+i;
				int dz = z+k;
				world.setBlock(dx, y+3, dz, ChromaBlocks.SPECIALSHIELD.getBlockInstance(), mg);

				//ReikaJavaLibrary.pConsole(((8+dx%8)%8)+":"+((8+dz%8)%8)+" > "+lightPattern[(8+dx%8)%8][(8+dz%8)%8]);

				world.setBlock(dx, y+0, dz, b, /*rand.nextInt(4) == 0*/lightPattern[(8+(dx+4)%8)%8][(8+(dz+4)%8)%8] ? ml : ms);
				world.setBlock(dx, y+6, dz, Blocks.air);
				world.setBlock(dx, y+7, dz, b, /*rand.nextInt(4) == 0*/lightPattern[(8+dx%8)%8][(8+dz%8)%8] ? ml : ms);
				world.setBlock(dx, y+8, dz, b, ms);
			}
		}

		world.setBlock(x+25, y+5, z+11, b, ml);

		world.setBlock(x+25, y+1, z+11, Blocks.air);
		world.setBlock(x+25, y+2, z+11, Blocks.air);

		world.setBlock(x+25, y+4, z+14, Blocks.air);
		world.setBlock(x+25, y+5, z+14, Blocks.air);
		world.setBlock(x+25, y+4, z+8, Blocks.air);
		world.setBlock(x+25, y+5, z+8, Blocks.air);

		world.setBlock(x+24, y+4, z+14, Blocks.air);
		world.setBlock(x+24, y+5, z+14, Blocks.air);
		world.setBlock(x+24, y+4, z+8, Blocks.air);
		world.setBlock(x+24, y+5, z+8, Blocks.air);
	}

	private void doGenerate(ChunkSplicedGenerationCache world, int x, int y, int z) {
		world.setBlock(x+0, y+0, z+0, b, ms);
		world.setBlock(x+0, y+0, z+1, b, ms);
		world.setBlock(x+0, y+0, z+2, b, ms);
		world.setBlock(x+0, y+0, z+3, b, ms);
		world.setBlock(x+0, y+0, z+4, b, ms);
		world.setBlock(x+0, y+0, z+5, b, ms);
		world.setBlock(x+0, y+0, z+6, b, ms);
		world.setBlock(x+0, y+0, z+7, b, ms);
		world.setBlock(x+0, y+0, z+8, b, ms);
		world.setBlock(x+0, y+0, z+9, b, ms);
		world.setBlock(x+0, y+0, z+10, b, ms);
		world.setBlock(x+0, y+0, z+11, b, ms);
		world.setBlock(x+0, y+0, z+12, b, ms);
		world.setBlock(x+0, y+0, z+13, b, ms);
		world.setBlock(x+0, y+0, z+14, b, ms);
		world.setBlock(x+0, y+0, z+15, b, ms);
		world.setBlock(x+0, y+0, z+16, b, ms);
		world.setBlock(x+0, y+0, z+17, b, ms);
		world.setBlock(x+0, y+0, z+18, b, ms);
		world.setBlock(x+0, y+0, z+19, b, ms);
		world.setBlock(x+0, y+0, z+20, b, ms);
		world.setBlock(x+0, y+0, z+21, b, ms);
		world.setBlock(x+0, y+0, z+22, b, ms);
		world.setBlock(x+0, y+0, z+23, b, ms);
		world.setBlock(x+0, y+0, z+24, b, ms);
		world.setBlock(x+0, y+1, z+0, b, ms);
		world.setBlock(x+0, y+1, z+1, b, ms);
		world.setBlock(x+0, y+1, z+2, b, ms);
		world.setBlock(x+0, y+1, z+3, b, ms);
		world.setBlock(x+0, y+1, z+4, b, ms);
		world.setBlock(x+0, y+1, z+5, b, ms);
		world.setBlock(x+0, y+1, z+6, b, ms);
		world.setBlock(x+0, y+1, z+7, b, ms);
		world.setBlock(x+0, y+1, z+8, b, ms);
		world.setBlock(x+0, y+1, z+9, Blocks.air);
		world.setBlock(x+0, y+1, z+10, b, ms);
		world.setBlock(x+0, y+1, z+11, b, ms);
		world.setBlock(x+0, y+1, z+12, b, ms);
		world.setBlock(x+0, y+1, z+13, b, ms);
		world.setBlock(x+0, y+1, z+14, b, ms);
		world.setBlock(x+0, y+1, z+15, b, ms);
		world.setBlock(x+0, y+1, z+16, b, ms);
		world.setBlock(x+0, y+1, z+17, b, ms);
		world.setBlock(x+0, y+1, z+18, b, ms);
		world.setBlock(x+0, y+1, z+19, b, ms);
		world.setBlock(x+0, y+1, z+20, b, ms);
		world.setBlock(x+0, y+1, z+21, b, ms);
		world.setBlock(x+0, y+1, z+22, b, ms);
		world.setBlock(x+0, y+1, z+23, b, ms);
		world.setBlock(x+0, y+1, z+24, b, ms);
		world.setBlock(x+0, y+2, z+0, b, ms);
		world.setBlock(x+0, y+2, z+1, b, ms);
		world.setBlock(x+0, y+2, z+2, b, ms);
		world.setBlock(x+0, y+2, z+3, b, ms);
		world.setBlock(x+0, y+2, z+4, b, ms);
		world.setBlock(x+0, y+2, z+5, b, ms);
		world.setBlock(x+0, y+2, z+6, b, ms);
		world.setBlock(x+0, y+2, z+7, b, ms);
		world.setBlock(x+0, y+2, z+8, b, ms);
		world.setBlock(x+0, y+2, z+9, Blocks.air);
		world.setBlock(x+0, y+2, z+10, b, ms);
		world.setBlock(x+0, y+2, z+11, b, ms);
		world.setBlock(x+0, y+2, z+12, b, ms);
		world.setBlock(x+0, y+2, z+13, b, ms);
		world.setBlock(x+0, y+2, z+14, b, ms);
		world.setBlock(x+0, y+2, z+15, b, ms);
		world.setBlock(x+0, y+2, z+16, b, ms);
		world.setBlock(x+0, y+2, z+17, b, ms);
		world.setBlock(x+0, y+2, z+18, b, ms);
		world.setBlock(x+0, y+2, z+19, b, ms);
		world.setBlock(x+0, y+2, z+20, b, ms);
		world.setBlock(x+0, y+2, z+21, b, ms);
		world.setBlock(x+0, y+2, z+22, b, ms);
		world.setBlock(x+0, y+2, z+23, b, ms);
		world.setBlock(x+0, y+2, z+24, b, ms);
		world.setBlock(x+0, y+3, z+0, b, ms);
		world.setBlock(x+0, y+3, z+1, b, ms);
		world.setBlock(x+0, y+3, z+2, b, ms);
		world.setBlock(x+0, y+3, z+3, b, ms);
		world.setBlock(x+0, y+3, z+4, b, ms);
		world.setBlock(x+0, y+3, z+5, b, ms);
		world.setBlock(x+0, y+3, z+6, b, ms);
		world.setBlock(x+0, y+3, z+7, b, ms);
		world.setBlock(x+0, y+3, z+8, b, ms);
		world.setBlock(x+0, y+3, z+9, b, ms);
		world.setBlock(x+0, y+3, z+10, b, ms);
		world.setBlock(x+0, y+3, z+11, b, ms);
		world.setBlock(x+0, y+3, z+12, b, ms);
		world.setBlock(x+0, y+3, z+13, b, ms);
		world.setBlock(x+0, y+3, z+14, b, ms);
		world.setBlock(x+0, y+3, z+15, b, ms);
		world.setBlock(x+0, y+3, z+16, b, ms);
		world.setBlock(x+0, y+3, z+17, b, ms);
		world.setBlock(x+0, y+3, z+18, b, ms);
		world.setBlock(x+0, y+3, z+19, b, ms);
		world.setBlock(x+0, y+3, z+20, b, ms);
		world.setBlock(x+0, y+3, z+21, b, ms);
		world.setBlock(x+0, y+3, z+22, b, ms);
		world.setBlock(x+0, y+3, z+23, b, ms);
		world.setBlock(x+0, y+3, z+24, b, ms);
		world.setBlock(x+0, y+4, z+0, b, ms);
		world.setBlock(x+0, y+4, z+1, b, ms);
		world.setBlock(x+0, y+4, z+2, b, ms);
		world.setBlock(x+0, y+4, z+3, b, ms);
		world.setBlock(x+0, y+4, z+4, b, ms);
		world.setBlock(x+0, y+4, z+5, b, ms);
		world.setBlock(x+0, y+4, z+6, b, ms);
		world.setBlock(x+0, y+4, z+7, b, ms);
		world.setBlock(x+0, y+4, z+8, b, ms);
		world.setBlock(x+0, y+4, z+9, b, ms);
		world.setBlock(x+0, y+4, z+10, b, ms);
		world.setBlock(x+0, y+4, z+11, b, ms);
		world.setBlock(x+0, y+4, z+12, b, ms);
		world.setBlock(x+0, y+4, z+13, b, ms);
		world.setBlock(x+0, y+4, z+14, b, ms);
		world.setBlock(x+0, y+4, z+15, b, ms);
		world.setBlock(x+0, y+4, z+16, b, ms);
		world.setBlock(x+0, y+4, z+17, b, ms);
		world.setBlock(x+0, y+4, z+18, b, ms);
		world.setBlock(x+0, y+4, z+19, b, ms);
		world.setBlock(x+0, y+4, z+20, b, ms);
		world.setBlock(x+0, y+4, z+21, b, ms);
		world.setBlock(x+0, y+4, z+22, b, ms);
		world.setBlock(x+0, y+4, z+23, b, ms);
		world.setBlock(x+0, y+4, z+24, b, ms);
		world.setBlock(x+0, y+5, z+0, b, ms);
		world.setBlock(x+0, y+5, z+1, b, ms);
		world.setBlock(x+0, y+5, z+2, b, ms);
		world.setBlock(x+0, y+5, z+3, b, ms);
		world.setBlock(x+0, y+5, z+4, b, ms);
		world.setBlock(x+0, y+5, z+5, b, ms);
		world.setBlock(x+0, y+5, z+6, b, ms);
		world.setBlock(x+0, y+5, z+7, b, ms);
		world.setBlock(x+0, y+5, z+8, b, ms);
		world.setBlock(x+0, y+5, z+9, b, ms);
		world.setBlock(x+0, y+5, z+10, b, ms);
		world.setBlock(x+0, y+5, z+11, b, ms);
		world.setBlock(x+0, y+5, z+12, b, ms);
		world.setBlock(x+0, y+5, z+13, b, ms);
		world.setBlock(x+0, y+5, z+14, b, ms);
		world.setBlock(x+0, y+5, z+15, b, ms);
		world.setBlock(x+0, y+5, z+16, b, ms);
		world.setBlock(x+0, y+5, z+17, b, ms);
		world.setBlock(x+0, y+5, z+18, b, ms);
		world.setBlock(x+0, y+5, z+19, b, ms);
		world.setBlock(x+0, y+5, z+20, b, ms);
		world.setBlock(x+0, y+5, z+21, b, ms);
		world.setBlock(x+0, y+5, z+22, b, ms);
		world.setBlock(x+0, y+5, z+23, b, ms);
		world.setBlock(x+0, y+5, z+24, b, ms);
		world.setBlock(x+1, y+0, z+0, b, ms);
		world.setBlock(x+1, y+0, z+1, b, ms);
		world.setBlock(x+1, y+0, z+2, b, ms);
		world.setBlock(x+1, y+0, z+3, b, ms);
		world.setBlock(x+1, y+0, z+4, b, ms);
		world.setBlock(x+1, y+0, z+5, b, ms);
		world.setBlock(x+1, y+0, z+6, b, ms);
		world.setBlock(x+1, y+0, z+7, b, ms);
		world.setBlock(x+1, y+0, z+8, b, ms);
		world.setBlock(x+1, y+0, z+9, b, ms);
		world.setBlock(x+1, y+0, z+10, b, ms);
		world.setBlock(x+1, y+0, z+11, b, ms);
		world.setBlock(x+1, y+0, z+12, b, ms);
		world.setBlock(x+1, y+0, z+13, b, ms);
		world.setBlock(x+1, y+0, z+14, b, ms);
		world.setBlock(x+1, y+0, z+15, b, ms);
		world.setBlock(x+1, y+0, z+16, b, ms);
		world.setBlock(x+1, y+0, z+17, b, ms);
		world.setBlock(x+1, y+0, z+18, b, ms);
		world.setBlock(x+1, y+0, z+19, b, ms);
		world.setBlock(x+1, y+0, z+20, b, ms);
		world.setBlock(x+1, y+0, z+21, b, ms);
		world.setBlock(x+1, y+0, z+22, b, ms);
		world.setBlock(x+1, y+0, z+23, b, ms);
		world.setBlock(x+1, y+0, z+24, b, ms);
		world.setBlock(x+1, y+1, z+0, b, ms);
		world.setBlock(x+1, y+1, z+1, Blocks.air);
		world.setBlock(x+1, y+1, z+2, Blocks.air);
		world.setBlock(x+1, y+1, z+3, Blocks.air);
		world.setBlock(x+1, y+1, z+4, Blocks.air);
		world.setBlock(x+1, y+1, z+5, Blocks.air);
		world.setBlock(x+1, y+1, z+6, b, ms);
		world.setBlock(x+1, y+1, z+7, Blocks.air);
		world.setBlock(x+1, y+1, z+8, Blocks.air);
		world.setBlock(x+1, y+1, z+9, Blocks.air);
		world.setBlock(x+1, y+1, z+10, b, ms);
		world.setBlock(x+1, y+1, z+11, Blocks.air);
		world.setBlock(x+1, y+1, z+12, Blocks.air);
		world.setBlock(x+1, y+1, z+13, Blocks.air);
		world.setBlock(x+1, y+1, z+14, Blocks.air);
		world.setBlock(x+1, y+1, z+15, Blocks.air);
		world.setBlock(x+1, y+1, z+16, Blocks.air);
		world.setBlock(x+1, y+1, z+17, Blocks.air);
		world.setBlock(x+1, y+1, z+18, Blocks.air);
		world.setBlock(x+1, y+1, z+19, Blocks.air);
		world.setBlock(x+1, y+1, z+20, Blocks.air);
		world.setBlock(x+1, y+1, z+21, Blocks.air);
		world.setBlock(x+1, y+1, z+23, Blocks.air);
		world.setBlock(x+1, y+1, z+24, b, ms);
		world.setBlock(x+1, y+2, z+0, b, ms);
		world.setBlock(x+1, y+2, z+1, Blocks.air);
		world.setBlock(x+1, y+2, z+2, Blocks.air);
		world.setBlock(x+1, y+2, z+3, Blocks.air);
		world.setBlock(x+1, y+2, z+4, Blocks.air);
		world.setBlock(x+1, y+2, z+5, Blocks.air);
		world.setBlock(x+1, y+2, z+6, b, ms);
		world.setBlock(x+1, y+2, z+7, Blocks.air);
		world.setBlock(x+1, y+2, z+8, Blocks.air);
		world.setBlock(x+1, y+2, z+9, Blocks.air);
		world.setBlock(x+1, y+2, z+10, b, ms);
		world.setBlock(x+1, y+2, z+11, Blocks.air);
		world.setBlock(x+1, y+2, z+12, Blocks.air);
		world.setBlock(x+1, y+2, z+13, Blocks.air);
		world.setBlock(x+1, y+2, z+14, Blocks.air);
		world.setBlock(x+1, y+2, z+15, Blocks.air);
		world.setBlock(x+1, y+2, z+16, Blocks.air);
		world.setBlock(x+1, y+2, z+17, Blocks.air);
		world.setBlock(x+1, y+2, z+18, Blocks.air);
		world.setBlock(x+1, y+2, z+19, Blocks.air);
		world.setBlock(x+1, y+2, z+20, Blocks.air);
		world.setBlock(x+1, y+2, z+21, Blocks.air);
		world.setBlock(x+1, y+2, z+23, Blocks.air);
		world.setBlock(x+1, y+2, z+24, b, ms);
		world.setBlock(x+1, y+3, z+0, b, ms);
		world.setBlock(x+1, y+3, z+1, Blocks.air);
		world.setBlock(x+1, y+3, z+2, Blocks.air);
		world.setBlock(x+1, y+3, z+3, Blocks.air);
		world.setBlock(x+1, y+3, z+4, Blocks.air);
		world.setBlock(x+1, y+3, z+5, Blocks.air);
		world.setBlock(x+1, y+3, z+6, Blocks.air);
		world.setBlock(x+1, y+3, z+7, Blocks.air);
		world.setBlock(x+1, y+3, z+8, Blocks.air);
		world.setBlock(x+1, y+3, z+9, Blocks.air);
		world.setBlock(x+1, y+3, z+10, Blocks.air);
		world.setBlock(x+1, y+3, z+11, Blocks.air);
		world.setBlock(x+1, y+3, z+12, Blocks.air);
		world.setBlock(x+1, y+3, z+13, Blocks.air);
		world.setBlock(x+1, y+3, z+14, Blocks.air);
		world.setBlock(x+1, y+3, z+15, Blocks.air);
		world.setBlock(x+1, y+3, z+16, Blocks.air);
		world.setBlock(x+1, y+3, z+17, Blocks.air);
		world.setBlock(x+1, y+3, z+18, Blocks.air);
		world.setBlock(x+1, y+3, z+19, Blocks.air);
		world.setBlock(x+1, y+3, z+20, Blocks.air);
		world.setBlock(x+1, y+3, z+21, Blocks.air);
		world.setBlock(x+1, y+3, z+22, Blocks.air);
		world.setBlock(x+1, y+3, z+23, Blocks.air);
		world.setBlock(x+1, y+3, z+24, b, ms);
		world.setBlock(x+1, y+4, z+0, b, ms);
		world.setBlock(x+1, y+4, z+1, Blocks.air);
		world.setBlock(x+1, y+4, z+2, Blocks.air);
		world.setBlock(x+1, y+4, z+3, Blocks.air);
		world.setBlock(x+1, y+4, z+4, Blocks.air);
		world.setBlock(x+1, y+4, z+5, Blocks.air);
		world.setBlock(x+1, y+4, z+6, Blocks.air);
		world.setBlock(x+1, y+4, z+7, Blocks.air);
		world.setBlock(x+1, y+4, z+8, Blocks.air);
		world.setBlock(x+1, y+4, z+9, Blocks.air);
		world.setBlock(x+1, y+4, z+10, Blocks.air);
		world.setBlock(x+1, y+4, z+11, Blocks.air);
		world.setBlock(x+1, y+4, z+12, Blocks.air);
		world.setBlock(x+1, y+4, z+13, Blocks.air);
		world.setBlock(x+1, y+4, z+14, Blocks.air);
		world.setBlock(x+1, y+4, z+15, Blocks.air);
		world.setBlock(x+1, y+4, z+16, Blocks.air);
		world.setBlock(x+1, y+4, z+17, Blocks.air);
		world.setBlock(x+1, y+4, z+18, Blocks.air);
		world.setBlock(x+1, y+4, z+19, Blocks.air);
		world.setBlock(x+1, y+4, z+20, Blocks.air);
		world.setBlock(x+1, y+4, z+21, Blocks.air);
		world.setBlock(x+1, y+4, z+22, Blocks.air);
		world.setBlock(x+1, y+4, z+23, Blocks.air);
		world.setBlock(x+1, y+4, z+24, b, ms);
		world.setBlock(x+1, y+5, z+0, b, ms);
		world.setBlock(x+1, y+5, z+1, Blocks.air);
		world.setBlock(x+1, y+5, z+2, Blocks.air);
		world.setBlock(x+1, y+5, z+3, Blocks.air);
		world.setBlock(x+1, y+5, z+4, Blocks.air);
		world.setBlock(x+1, y+5, z+5, Blocks.air);
		world.setBlock(x+1, y+5, z+6, Blocks.air);
		world.setBlock(x+1, y+5, z+7, Blocks.air);
		world.setBlock(x+1, y+5, z+8, Blocks.air);
		world.setBlock(x+1, y+5, z+9, Blocks.air);
		world.setBlock(x+1, y+5, z+10, Blocks.air);
		world.setBlock(x+1, y+5, z+11, Blocks.air);
		world.setBlock(x+1, y+5, z+12, Blocks.air);
		world.setBlock(x+1, y+5, z+13, Blocks.air);
		world.setBlock(x+1, y+5, z+14, Blocks.air);
		world.setBlock(x+1, y+5, z+15, Blocks.air);
		world.setBlock(x+1, y+5, z+16, Blocks.air);
		world.setBlock(x+1, y+5, z+17, Blocks.air);
		world.setBlock(x+1, y+5, z+18, Blocks.air);
		world.setBlock(x+1, y+5, z+19, Blocks.air);
		world.setBlock(x+1, y+5, z+20, Blocks.air);
		world.setBlock(x+1, y+5, z+21, Blocks.air);
		world.setBlock(x+1, y+5, z+22, Blocks.air);
		world.setBlock(x+1, y+5, z+23, Blocks.air);
		world.setBlock(x+1, y+5, z+24, b, ms);
		world.setBlock(x+2, y+0, z+0, b, ms);
		world.setBlock(x+2, y+0, z+1, b, ms);
		world.setBlock(x+2, y+0, z+2, b, ms);
		world.setBlock(x+2, y+0, z+3, b, ms);
		world.setBlock(x+2, y+0, z+4, b, ms);
		world.setBlock(x+2, y+0, z+5, b, ms);
		world.setBlock(x+2, y+0, z+6, b, ms);
		world.setBlock(x+2, y+0, z+7, b, ms);
		world.setBlock(x+2, y+0, z+8, b, ms);
		world.setBlock(x+2, y+0, z+9, b, ms);
		world.setBlock(x+2, y+0, z+10, b, ms);
		world.setBlock(x+2, y+0, z+11, b, ms);
		world.setBlock(x+2, y+0, z+12, b, ms);
		world.setBlock(x+2, y+0, z+13, b, ms);
		world.setBlock(x+2, y+0, z+14, b, ms);
		world.setBlock(x+2, y+0, z+15, b, ms);
		world.setBlock(x+2, y+0, z+16, b, ms);
		world.setBlock(x+2, y+0, z+17, b, ms);
		world.setBlock(x+2, y+0, z+18, b, ms);
		world.setBlock(x+2, y+0, z+19, b, ms);
		world.setBlock(x+2, y+0, z+20, b, ms);
		world.setBlock(x+2, y+0, z+21, b, ms);
		world.setBlock(x+2, y+0, z+22, b, ms);
		world.setBlock(x+2, y+0, z+23, b, ms);
		world.setBlock(x+2, y+0, z+24, b, ms);
		world.setBlock(x+2, y+1, z+0, b, ms);
		world.setBlock(x+2, y+1, z+1, Blocks.air);
		world.setBlock(x+2, y+1, z+2, b, ms);
		world.setBlock(x+2, y+1, z+3, b, ms);
		world.setBlock(x+2, y+1, z+4, b, ms);
		world.setBlock(x+2, y+1, z+5, Blocks.air);
		world.setBlock(x+2, y+1, z+6, b, ms);
		world.setBlock(x+2, y+1, z+7, Blocks.air);
		world.setBlock(x+2, y+1, z+8, b, ms);
		world.setBlock(x+2, y+1, z+9, Blocks.air);
		world.setBlock(x+2, y+1, z+10, b, ms);
		world.setBlock(x+2, y+1, z+11, Blocks.air);
		world.setBlock(x+2, y+1, z+12, b, ms);
		world.setBlock(x+2, y+1, z+13, b, ms);
		world.setBlock(x+2, y+1, z+14, b, ms);
		world.setBlock(x+2, y+1, z+15, b, ms);
		world.setBlock(x+2, y+1, z+16, b, ms);
		world.setBlock(x+2, y+1, z+17, b, ms);
		world.setBlock(x+2, y+1, z+18, b, ms);
		world.setBlock(x+2, y+1, z+19, b, ms);
		world.setBlock(x+2, y+1, z+20, b, ms);
		world.setBlock(x+2, y+1, z+21, Blocks.air);
		world.setBlock(x+2, y+1, z+22, b, ms);
		world.setBlock(x+2, y+1, z+23, Blocks.air);
		world.setBlock(x+2, y+1, z+24, b, ms);
		world.setBlock(x+2, y+2, z+0, b, ms);
		world.setBlock(x+2, y+2, z+1, Blocks.air);
		world.setBlock(x+2, y+2, z+2, b, ms);
		world.setBlock(x+2, y+2, z+3, b, ms);
		world.setBlock(x+2, y+2, z+4, b, ms);
		world.setBlock(x+2, y+2, z+5, Blocks.air);
		world.setBlock(x+2, y+2, z+6, b, ms);
		world.setBlock(x+2, y+2, z+7, Blocks.air);
		world.setBlock(x+2, y+2, z+8, b, ms);
		world.setBlock(x+2, y+2, z+9, Blocks.air);
		world.setBlock(x+2, y+2, z+10, b, ms);
		world.setBlock(x+2, y+2, z+11, Blocks.air);
		world.setBlock(x+2, y+2, z+12, b, ms);
		world.setBlock(x+2, y+2, z+13, b, ms);
		world.setBlock(x+2, y+2, z+14, b, ms);
		world.setBlock(x+2, y+2, z+15, b, ms);
		world.setBlock(x+2, y+2, z+16, b, ms);
		world.setBlock(x+2, y+2, z+17, b, ms);
		world.setBlock(x+2, y+2, z+18, b, ms);
		world.setBlock(x+2, y+2, z+19, b, ms);
		world.setBlock(x+2, y+2, z+20, b, ms);
		world.setBlock(x+2, y+2, z+21, Blocks.air);
		world.setBlock(x+2, y+2, z+22, b, ms);
		world.setBlock(x+2, y+2, z+23, Blocks.air);
		world.setBlock(x+2, y+2, z+24, b, ms);
		world.setBlock(x+2, y+3, z+0, b, ms);
		world.setBlock(x+2, y+3, z+1, Blocks.air);
		world.setBlock(x+2, y+3, z+2, Blocks.air);
		world.setBlock(x+2, y+3, z+3, Blocks.air);
		world.setBlock(x+2, y+3, z+4, Blocks.air);
		world.setBlock(x+2, y+3, z+5, Blocks.air);
		world.setBlock(x+2, y+3, z+6, Blocks.air);
		world.setBlock(x+2, y+3, z+7, Blocks.air);
		world.setBlock(x+2, y+3, z+8, Blocks.air);
		world.setBlock(x+2, y+3, z+9, Blocks.air);
		world.setBlock(x+2, y+3, z+10, Blocks.air);
		world.setBlock(x+2, y+3, z+11, Blocks.air);
		world.setBlock(x+2, y+3, z+12, Blocks.air);
		world.setBlock(x+2, y+3, z+13, Blocks.air);
		world.setBlock(x+2, y+3, z+14, Blocks.air);
		world.setBlock(x+2, y+3, z+15, Blocks.air);
		world.setBlock(x+2, y+3, z+16, Blocks.air);
		world.setBlock(x+2, y+3, z+17, Blocks.air);
		world.setBlock(x+2, y+3, z+18, Blocks.air);
		world.setBlock(x+2, y+3, z+19, Blocks.air);
		world.setBlock(x+2, y+3, z+20, Blocks.air);
		world.setBlock(x+2, y+3, z+21, Blocks.air);
		world.setBlock(x+2, y+3, z+22, Blocks.air);
		world.setBlock(x+2, y+3, z+23, Blocks.air);
		world.setBlock(x+2, y+3, z+24, b, ms);
		world.setBlock(x+2, y+4, z+0, b, ms);
		world.setBlock(x+2, y+4, z+1, Blocks.air);
		world.setBlock(x+2, y+4, z+2, Blocks.air);
		world.setBlock(x+2, y+4, z+3, Blocks.air);
		world.setBlock(x+2, y+4, z+4, Blocks.air);
		world.setBlock(x+2, y+4, z+5, Blocks.air);
		world.setBlock(x+2, y+4, z+6, Blocks.air);
		world.setBlock(x+2, y+4, z+7, Blocks.air);
		world.setBlock(x+2, y+4, z+8, Blocks.air);
		world.setBlock(x+2, y+4, z+9, Blocks.air);
		world.setBlock(x+2, y+4, z+10, Blocks.air);
		world.setBlock(x+2, y+4, z+11, Blocks.air);
		world.setBlock(x+2, y+4, z+12, Blocks.air);
		world.setBlock(x+2, y+4, z+13, Blocks.air);
		world.setBlock(x+2, y+4, z+14, Blocks.air);
		world.setBlock(x+2, y+4, z+15, Blocks.air);
		world.setBlock(x+2, y+4, z+16, Blocks.air);
		world.setBlock(x+2, y+4, z+17, Blocks.air);
		world.setBlock(x+2, y+4, z+18, Blocks.air);
		world.setBlock(x+2, y+4, z+19, Blocks.air);
		world.setBlock(x+2, y+4, z+20, Blocks.air);
		world.setBlock(x+2, y+4, z+21, Blocks.air);
		world.setBlock(x+2, y+4, z+22, Blocks.air);
		world.setBlock(x+2, y+4, z+23, Blocks.air);
		world.setBlock(x+2, y+4, z+24, b, ms);
		world.setBlock(x+2, y+5, z+0, b, ms);
		world.setBlock(x+2, y+5, z+1, Blocks.air);
		world.setBlock(x+2, y+5, z+2, Blocks.air);
		world.setBlock(x+2, y+5, z+3, Blocks.air);
		world.setBlock(x+2, y+5, z+4, Blocks.air);
		world.setBlock(x+2, y+5, z+5, Blocks.air);
		world.setBlock(x+2, y+5, z+6, Blocks.air);
		world.setBlock(x+2, y+5, z+7, Blocks.air);
		world.setBlock(x+2, y+5, z+8, Blocks.air);
		world.setBlock(x+2, y+5, z+9, Blocks.air);
		world.setBlock(x+2, y+5, z+10, Blocks.air);
		world.setBlock(x+2, y+5, z+11, Blocks.air);
		world.setBlock(x+2, y+5, z+12, Blocks.air);
		world.setBlock(x+2, y+5, z+13, Blocks.air);
		world.setBlock(x+2, y+5, z+14, Blocks.air);
		world.setBlock(x+2, y+5, z+15, Blocks.air);
		world.setBlock(x+2, y+5, z+16, Blocks.air);
		world.setBlock(x+2, y+5, z+17, Blocks.air);
		world.setBlock(x+2, y+5, z+18, Blocks.air);
		world.setBlock(x+2, y+5, z+19, Blocks.air);
		world.setBlock(x+2, y+5, z+20, Blocks.air);
		world.setBlock(x+2, y+5, z+21, Blocks.air);
		world.setBlock(x+2, y+5, z+22, Blocks.air);
		world.setBlock(x+2, y+5, z+23, Blocks.air);
		world.setBlock(x+2, y+5, z+24, b, ms);
		world.setBlock(x+3, y+0, z+0, b, ms);
		world.setBlock(x+3, y+0, z+1, b, ms);
		world.setBlock(x+3, y+0, z+2, b, ms);
		world.setBlock(x+3, y+0, z+3, b, ms);
		world.setBlock(x+3, y+0, z+4, b, ms);
		world.setBlock(x+3, y+0, z+5, b, ms);
		world.setBlock(x+3, y+0, z+6, b, ms);
		world.setBlock(x+3, y+0, z+7, b, ms);
		world.setBlock(x+3, y+0, z+8, b, ms);
		world.setBlock(x+3, y+0, z+9, b, ms);
		world.setBlock(x+3, y+0, z+10, b, ms);
		world.setBlock(x+3, y+0, z+11, b, ms);
		world.setBlock(x+3, y+0, z+12, b, ms);
		world.setBlock(x+3, y+0, z+13, b, ms);
		world.setBlock(x+3, y+0, z+14, b, ms);
		world.setBlock(x+3, y+0, z+15, b, ms);
		world.setBlock(x+3, y+0, z+16, b, ms);
		world.setBlock(x+3, y+0, z+17, b, ms);
		world.setBlock(x+3, y+0, z+18, b, ms);
		world.setBlock(x+3, y+0, z+19, b, ms);
		world.setBlock(x+3, y+0, z+20, b, ms);
		world.setBlock(x+3, y+0, z+21, b, ms);
		world.setBlock(x+3, y+0, z+22, b, ms);
		world.setBlock(x+3, y+0, z+23, b, ms);
		world.setBlock(x+3, y+0, z+24, b, ms);
		world.setBlock(x+3, y+1, z+0, b, ms);
		world.setBlock(x+3, y+1, z+1, Blocks.air);
		world.setBlock(x+3, y+1, z+2, b, ms);
		world.setBlock(x+3, y+1, z+3, Blocks.air);
		world.setBlock(x+3, y+1, z+5, Blocks.air);
		world.setBlock(x+3, y+1, z+7, Blocks.air);
		world.setBlock(x+3, y+1, z+8, b, ms);
		world.setBlock(x+3, y+1, z+9, Blocks.air);
		world.setBlock(x+3, y+1, z+10, b, ms);
		world.setBlock(x+3, y+1, z+11, Blocks.air);
		world.setBlock(x+3, y+1, z+12, Blocks.air);
		world.setBlock(x+3, y+1, z+13, Blocks.air);
		world.setBlock(x+3, y+1, z+14, Blocks.air);
		world.setBlock(x+3, y+1, z+15, Blocks.air);
		world.setBlock(x+3, y+1, z+16, b, ms);
		world.setBlock(x+3, y+1, z+17, Blocks.air);
		world.setBlock(x+3, y+1, z+18, Blocks.air);
		world.setBlock(x+3, y+1, z+19, Blocks.air);
		world.setBlock(x+3, y+1, z+20, b, ms);
		world.setBlock(x+3, y+1, z+21, Blocks.air);
		world.setBlock(x+3, y+1, z+22, b, ms);
		world.setBlock(x+3, y+1, z+23, Blocks.air);
		world.setBlock(x+3, y+1, z+24, b, ms);
		world.setBlock(x+3, y+2, z+0, b, ms);
		world.setBlock(x+3, y+2, z+1, Blocks.air);
		world.setBlock(x+3, y+2, z+2, b, ms);
		world.setBlock(x+3, y+2, z+3, Blocks.air);
		world.setBlock(x+3, y+2, z+5, Blocks.air);
		world.setBlock(x+3, y+2, z+7, Blocks.air);
		world.setBlock(x+3, y+2, z+8, b, ms);
		world.setBlock(x+3, y+2, z+9, Blocks.air);
		world.setBlock(x+3, y+2, z+10, b, ms);
		world.setBlock(x+3, y+2, z+11, Blocks.air);
		world.setBlock(x+3, y+2, z+12, Blocks.air);
		world.setBlock(x+3, y+2, z+13, Blocks.air);
		world.setBlock(x+3, y+2, z+14, Blocks.air);
		world.setBlock(x+3, y+2, z+15, Blocks.air);
		world.setBlock(x+3, y+2, z+16, b, ms);
		world.setBlock(x+3, y+2, z+17, Blocks.air);
		world.setBlock(x+3, y+2, z+18, Blocks.air);
		world.setBlock(x+3, y+2, z+19, Blocks.air);
		world.setBlock(x+3, y+2, z+20, b, ms);
		world.setBlock(x+3, y+2, z+21, Blocks.air);
		world.setBlock(x+3, y+2, z+22, b, ms);
		world.setBlock(x+3, y+2, z+23, Blocks.air);
		world.setBlock(x+3, y+2, z+24, b, ms);
		world.setBlock(x+3, y+3, z+0, b, ms);
		world.setBlock(x+3, y+3, z+1, Blocks.air);
		world.setBlock(x+3, y+3, z+2, Blocks.air);
		world.setBlock(x+3, y+3, z+3, Blocks.air);
		world.setBlock(x+3, y+3, z+4, Blocks.air);
		world.setBlock(x+3, y+3, z+5, Blocks.air);
		world.setBlock(x+3, y+3, z+6, Blocks.air);
		world.setBlock(x+3, y+3, z+7, Blocks.air);
		world.setBlock(x+3, y+3, z+8, Blocks.air);
		world.setBlock(x+3, y+3, z+9, Blocks.air);
		world.setBlock(x+3, y+3, z+10, Blocks.air);
		world.setBlock(x+3, y+3, z+11, Blocks.air);
		world.setBlock(x+3, y+3, z+12, Blocks.air);
		world.setBlock(x+3, y+3, z+13, Blocks.air);
		world.setBlock(x+3, y+3, z+14, Blocks.air);
		world.setBlock(x+3, y+3, z+15, Blocks.air);
		world.setBlock(x+3, y+3, z+16, Blocks.air);
		world.setBlock(x+3, y+3, z+17, Blocks.air);
		world.setBlock(x+3, y+3, z+18, Blocks.air);
		world.setBlock(x+3, y+3, z+19, Blocks.air);
		world.setBlock(x+3, y+3, z+20, Blocks.air);
		world.setBlock(x+3, y+3, z+21, Blocks.air);
		world.setBlock(x+3, y+3, z+22, Blocks.air);
		world.setBlock(x+3, y+3, z+23, Blocks.air);
		world.setBlock(x+3, y+3, z+24, b, ms);
		world.setBlock(x+3, y+4, z+0, b, ms);
		world.setBlock(x+3, y+4, z+1, Blocks.air);
		world.setBlock(x+3, y+4, z+2, Blocks.air);
		world.setBlock(x+3, y+4, z+3, Blocks.air);
		world.setBlock(x+3, y+4, z+4, Blocks.air);
		world.setBlock(x+3, y+4, z+5, Blocks.air);
		world.setBlock(x+3, y+4, z+6, Blocks.air);
		world.setBlock(x+3, y+4, z+7, Blocks.air);
		world.setBlock(x+3, y+4, z+8, Blocks.air);
		world.setBlock(x+3, y+4, z+9, Blocks.air);
		world.setBlock(x+3, y+4, z+10, Blocks.air);
		world.setBlock(x+3, y+4, z+11, Blocks.air);
		world.setBlock(x+3, y+4, z+12, Blocks.air);
		world.setBlock(x+3, y+4, z+13, Blocks.air);
		world.setBlock(x+3, y+4, z+14, Blocks.air);
		world.setBlock(x+3, y+4, z+15, Blocks.air);
		world.setBlock(x+3, y+4, z+16, Blocks.air);
		world.setBlock(x+3, y+4, z+17, Blocks.air);
		world.setBlock(x+3, y+4, z+18, Blocks.air);
		world.setBlock(x+3, y+4, z+19, Blocks.air);
		world.setBlock(x+3, y+4, z+20, Blocks.air);
		world.setBlock(x+3, y+4, z+21, Blocks.air);
		world.setBlock(x+3, y+4, z+22, Blocks.air);
		world.setBlock(x+3, y+4, z+23, Blocks.air);
		world.setBlock(x+3, y+4, z+24, b, ms);
		world.setBlock(x+3, y+5, z+0, b, ms);
		world.setBlock(x+3, y+5, z+1, Blocks.air);
		world.setBlock(x+3, y+5, z+2, Blocks.air);
		world.setBlock(x+3, y+5, z+3, Blocks.air);
		world.setBlock(x+3, y+5, z+4, Blocks.air);
		world.setBlock(x+3, y+5, z+5, Blocks.air);
		world.setBlock(x+3, y+5, z+6, Blocks.air);
		world.setBlock(x+3, y+5, z+7, Blocks.air);
		world.setBlock(x+3, y+5, z+8, Blocks.air);
		world.setBlock(x+3, y+5, z+9, Blocks.air);
		world.setBlock(x+3, y+5, z+10, Blocks.air);
		world.setBlock(x+3, y+5, z+11, Blocks.air);
		world.setBlock(x+3, y+5, z+12, Blocks.air);
		world.setBlock(x+3, y+5, z+13, Blocks.air);
		world.setBlock(x+3, y+5, z+14, Blocks.air);
		world.setBlock(x+3, y+5, z+15, Blocks.air);
		world.setBlock(x+3, y+5, z+16, Blocks.air);
		world.setBlock(x+3, y+5, z+17, Blocks.air);
		world.setBlock(x+3, y+5, z+18, Blocks.air);
		world.setBlock(x+3, y+5, z+19, Blocks.air);
		world.setBlock(x+3, y+5, z+20, Blocks.air);
		world.setBlock(x+3, y+5, z+21, Blocks.air);
		world.setBlock(x+3, y+5, z+22, Blocks.air);
		world.setBlock(x+3, y+5, z+23, Blocks.air);
		world.setBlock(x+3, y+5, z+24, b, ms);
		world.setBlock(x+4, y+0, z+0, b, ms);
		world.setBlock(x+4, y+0, z+1, b, ms);
		world.setBlock(x+4, y+0, z+2, b, ms);
		world.setBlock(x+4, y+0, z+3, b, ms);
		world.setBlock(x+4, y+0, z+4, b, ms);
		world.setBlock(x+4, y+0, z+5, b, ms);
		world.setBlock(x+4, y+0, z+6, b, ms);
		world.setBlock(x+4, y+0, z+7, b, ms);
		world.setBlock(x+4, y+0, z+8, b, ms);
		world.setBlock(x+4, y+0, z+9, b, ms);
		world.setBlock(x+4, y+0, z+10, b, ms);
		world.setBlock(x+4, y+0, z+11, b, ms);
		world.setBlock(x+4, y+0, z+12, b, ms);
		world.setBlock(x+4, y+0, z+13, b, ms);
		world.setBlock(x+4, y+0, z+14, b, ms);
		world.setBlock(x+4, y+0, z+15, b, ms);
		world.setBlock(x+4, y+0, z+16, b, ms);
		world.setBlock(x+4, y+0, z+17, b, ms);
		world.setBlock(x+4, y+0, z+18, b, ms);
		world.setBlock(x+4, y+0, z+19, b, ms);
		world.setBlock(x+4, y+0, z+20, b, ms);
		world.setBlock(x+4, y+0, z+21, b, ms);
		world.setBlock(x+4, y+0, z+22, b, ms);
		world.setBlock(x+4, y+0, z+23, b, ms);
		world.setBlock(x+4, y+0, z+24, b, ms);
		world.setBlock(x+4, y+1, z+0, b, ms);
		world.setBlock(x+4, y+1, z+1, Blocks.air);
		world.setBlock(x+4, y+1, z+2, b, ms);
		world.setBlock(x+4, y+1, z+3, Blocks.air);
		world.setBlock(x+4, y+1, z+4, b, ms);
		world.setBlock(x+4, y+1, z+5, b, ms);
		world.setBlock(x+4, y+1, z+6, b, ms);
		world.setBlock(x+4, y+1, z+7, b, ms);
		world.setBlock(x+4, y+1, z+8, b, ms);
		world.setBlock(x+4, y+1, z+9, b, ms);
		world.setBlock(x+4, y+1, z+10, b, ms);
		world.setBlock(x+4, y+1, z+11, b, ms);
		world.setBlock(x+4, y+1, z+12, b, ms);
		world.setBlock(x+4, y+1, z+13, b, ms);
		world.setBlock(x+4, y+1, z+14, b, ms);
		world.setBlock(x+4, y+1, z+15, Blocks.air);
		world.setBlock(x+4, y+1, z+16, b, ms);
		world.setBlock(x+4, y+1, z+17, Blocks.air);
		world.setBlock(x+4, y+1, z+18, b, ms);
		world.setBlock(x+4, y+1, z+19, Blocks.air);
		world.setBlock(x+4, y+1, z+20, b, ms);
		world.setBlock(x+4, y+1, z+21, Blocks.air);
		world.setBlock(x+4, y+1, z+22, b, ms);
		world.setBlock(x+4, y+1, z+23, Blocks.air);
		world.setBlock(x+4, y+1, z+24, b, ms);
		world.setBlock(x+4, y+2, z+0, b, ms);
		world.setBlock(x+4, y+2, z+1, Blocks.air);
		world.setBlock(x+4, y+2, z+2, b, ms);
		world.setBlock(x+4, y+2, z+3, Blocks.air);
		world.setBlock(x+4, y+2, z+4, b, ms);
		world.setBlock(x+4, y+2, z+5, b, ms);
		world.setBlock(x+4, y+2, z+6, b, ms);
		world.setBlock(x+4, y+2, z+7, b, ms);
		world.setBlock(x+4, y+2, z+8, b, ms);
		world.setBlock(x+4, y+2, z+9, b, ms);
		world.setBlock(x+4, y+2, z+10, b, ms);
		world.setBlock(x+4, y+2, z+11, b, ms);
		world.setBlock(x+4, y+2, z+12, b, ms);
		world.setBlock(x+4, y+2, z+13, b, ms);
		world.setBlock(x+4, y+2, z+14, b, ms);
		world.setBlock(x+4, y+2, z+15, Blocks.air);
		world.setBlock(x+4, y+2, z+16, b, ms);
		world.setBlock(x+4, y+2, z+17, Blocks.air);
		world.setBlock(x+4, y+2, z+18, b, ms);
		world.setBlock(x+4, y+2, z+19, Blocks.air);
		world.setBlock(x+4, y+2, z+20, b, ms);
		world.setBlock(x+4, y+2, z+21, Blocks.air);
		world.setBlock(x+4, y+2, z+22, b, ms);
		world.setBlock(x+4, y+2, z+23, Blocks.air);
		world.setBlock(x+4, y+2, z+24, b, ms);
		world.setBlock(x+4, y+3, z+0, b, ms);
		world.setBlock(x+4, y+3, z+1, Blocks.air);
		world.setBlock(x+4, y+3, z+2, Blocks.air);
		world.setBlock(x+4, y+3, z+3, Blocks.air);
		world.setBlock(x+4, y+3, z+4, Blocks.air);
		world.setBlock(x+4, y+3, z+5, Blocks.air);
		world.setBlock(x+4, y+3, z+6, Blocks.air);
		world.setBlock(x+4, y+3, z+7, Blocks.air);
		world.setBlock(x+4, y+3, z+8, Blocks.air);
		world.setBlock(x+4, y+3, z+9, Blocks.air);
		world.setBlock(x+4, y+3, z+10, Blocks.air);
		world.setBlock(x+4, y+3, z+11, Blocks.air);
		world.setBlock(x+4, y+3, z+12, Blocks.air);
		world.setBlock(x+4, y+3, z+13, Blocks.air);
		world.setBlock(x+4, y+3, z+14, Blocks.air);
		world.setBlock(x+4, y+3, z+15, Blocks.air);
		world.setBlock(x+4, y+3, z+16, Blocks.air);
		world.setBlock(x+4, y+3, z+17, Blocks.air);
		world.setBlock(x+4, y+3, z+18, Blocks.air);
		world.setBlock(x+4, y+3, z+19, Blocks.air);
		world.setBlock(x+4, y+3, z+20, Blocks.air);
		world.setBlock(x+4, y+3, z+21, Blocks.air);
		world.setBlock(x+4, y+3, z+22, Blocks.air);
		world.setBlock(x+4, y+3, z+23, Blocks.air);
		world.setBlock(x+4, y+3, z+24, b, ms);
		world.setBlock(x+4, y+4, z+0, b, ms);
		world.setBlock(x+4, y+4, z+1, Blocks.air);
		world.setBlock(x+4, y+4, z+2, Blocks.air);
		world.setBlock(x+4, y+4, z+3, Blocks.air);
		world.setBlock(x+4, y+4, z+4, Blocks.air);
		world.setBlock(x+4, y+4, z+5, Blocks.air);
		world.setBlock(x+4, y+4, z+6, Blocks.air);
		world.setBlock(x+4, y+4, z+7, Blocks.air);
		world.setBlock(x+4, y+4, z+8, Blocks.air);
		world.setBlock(x+4, y+4, z+9, Blocks.air);
		world.setBlock(x+4, y+4, z+10, Blocks.air);
		world.setBlock(x+4, y+4, z+11, Blocks.air);
		world.setBlock(x+4, y+4, z+12, Blocks.air);
		world.setBlock(x+4, y+4, z+13, Blocks.air);
		world.setBlock(x+4, y+4, z+14, Blocks.air);
		world.setBlock(x+4, y+4, z+15, Blocks.air);
		world.setBlock(x+4, y+4, z+16, Blocks.air);
		world.setBlock(x+4, y+4, z+17, Blocks.air);
		world.setBlock(x+4, y+4, z+18, Blocks.air);
		world.setBlock(x+4, y+4, z+19, Blocks.air);
		world.setBlock(x+4, y+4, z+20, Blocks.air);
		world.setBlock(x+4, y+4, z+21, Blocks.air);
		world.setBlock(x+4, y+4, z+22, Blocks.air);
		world.setBlock(x+4, y+4, z+23, Blocks.air);
		world.setBlock(x+4, y+4, z+24, b, ms);
		world.setBlock(x+4, y+5, z+0, b, ms);
		world.setBlock(x+4, y+5, z+1, Blocks.air);
		world.setBlock(x+4, y+5, z+2, Blocks.air);
		world.setBlock(x+4, y+5, z+3, Blocks.air);
		world.setBlock(x+4, y+5, z+4, Blocks.air);
		world.setBlock(x+4, y+5, z+5, Blocks.air);
		world.setBlock(x+4, y+5, z+6, Blocks.air);
		world.setBlock(x+4, y+5, z+7, Blocks.air);
		world.setBlock(x+4, y+5, z+8, Blocks.air);
		world.setBlock(x+4, y+5, z+9, Blocks.air);
		world.setBlock(x+4, y+5, z+10, Blocks.air);
		world.setBlock(x+4, y+5, z+11, Blocks.air);
		world.setBlock(x+4, y+5, z+12, Blocks.air);
		world.setBlock(x+4, y+5, z+13, Blocks.air);
		world.setBlock(x+4, y+5, z+14, Blocks.air);
		world.setBlock(x+4, y+5, z+15, Blocks.air);
		world.setBlock(x+4, y+5, z+16, Blocks.air);
		world.setBlock(x+4, y+5, z+17, Blocks.air);
		world.setBlock(x+4, y+5, z+18, Blocks.air);
		world.setBlock(x+4, y+5, z+19, Blocks.air);
		world.setBlock(x+4, y+5, z+20, Blocks.air);
		world.setBlock(x+4, y+5, z+21, Blocks.air);
		world.setBlock(x+4, y+5, z+22, Blocks.air);
		world.setBlock(x+4, y+5, z+23, Blocks.air);
		world.setBlock(x+4, y+5, z+24, b, ms);
		world.setBlock(x+5, y+0, z+0, b, ms);
		world.setBlock(x+5, y+0, z+1, b, ms);
		world.setBlock(x+5, y+0, z+2, b, ms);
		world.setBlock(x+5, y+0, z+3, b, ms);
		world.setBlock(x+5, y+0, z+4, b, ms);
		world.setBlock(x+5, y+0, z+5, b, ms);
		world.setBlock(x+5, y+0, z+6, b, ms);
		world.setBlock(x+5, y+0, z+7, b, ms);
		world.setBlock(x+5, y+0, z+8, b, ms);
		world.setBlock(x+5, y+0, z+9, b, ms);
		world.setBlock(x+5, y+0, z+10, b, ms);
		world.setBlock(x+5, y+0, z+11, b, ms);
		world.setBlock(x+5, y+0, z+12, b, ms);
		world.setBlock(x+5, y+0, z+13, b, ms);
		world.setBlock(x+5, y+0, z+14, b, ms);
		world.setBlock(x+5, y+0, z+15, b, ms);
		world.setBlock(x+5, y+0, z+16, b, ms);
		world.setBlock(x+5, y+0, z+17, b, ms);
		world.setBlock(x+5, y+0, z+18, b, ms);
		world.setBlock(x+5, y+0, z+19, b, ms);
		world.setBlock(x+5, y+0, z+20, b, ms);
		world.setBlock(x+5, y+0, z+21, b, ms);
		world.setBlock(x+5, y+0, z+22, b, ms);
		world.setBlock(x+5, y+0, z+23, b, ms);
		world.setBlock(x+5, y+0, z+24, b, ms);
		world.setBlock(x+5, y+1, z+0, b, ms);
		world.setBlock(x+5, y+1, z+1, Blocks.air);
		world.setBlock(x+5, y+1, z+2, b, ms);
		world.setBlock(x+5, y+1, z+3, Blocks.air);
		world.setBlock(x+5, y+1, z+4, b, ms);
		world.setBlock(x+5, y+1, z+5, Blocks.air);
		world.setBlock(x+5, y+1, z+6, Blocks.air);
		world.setBlock(x+5, y+1, z+7, Blocks.air);
		world.setBlock(x+5, y+1, z+8, b, ms);
		world.setBlock(x+5, y+1, z+9, Blocks.air);
		world.setBlock(x+5, y+1, z+10, Blocks.air);
		world.setBlock(x+5, y+1, z+11, Blocks.air);
		world.setBlock(x+5, y+1, z+12, Blocks.air);
		world.setBlock(x+5, y+1, z+13, Blocks.air);
		world.setBlock(x+5, y+1, z+14, b, ms);
		world.setBlock(x+5, y+1, z+15, Blocks.air);
		world.setBlock(x+5, y+1, z+16, Blocks.air);
		world.setBlock(x+5, y+1, z+17, Blocks.air);
		world.setBlock(x+5, y+1, z+18, b, ms);
		world.setBlock(x+5, y+1, z+19, Blocks.air);
		world.setBlock(x+5, y+1, z+20, b, ms);
		world.setBlock(x+5, y+1, z+21, Blocks.air);
		world.setBlock(x+5, y+1, z+22, b, ms);
		world.setBlock(x+5, y+1, z+23, Blocks.air);
		world.setBlock(x+5, y+1, z+24, b, ms);
		world.setBlock(x+5, y+2, z+0, b, ms);
		world.setBlock(x+5, y+2, z+1, Blocks.air);
		world.setBlock(x+5, y+2, z+2, b, ms);
		world.setBlock(x+5, y+2, z+3, Blocks.air);
		world.setBlock(x+5, y+2, z+4, b, ms);
		world.setBlock(x+5, y+2, z+5, Blocks.air);
		world.setBlock(x+5, y+2, z+6, Blocks.air);
		world.setBlock(x+5, y+2, z+7, Blocks.air);
		world.setBlock(x+5, y+2, z+8, b, ms);
		world.setBlock(x+5, y+2, z+9, Blocks.air);
		world.setBlock(x+5, y+2, z+10, Blocks.air);
		world.setBlock(x+5, y+2, z+11, Blocks.air);
		world.setBlock(x+5, y+2, z+12, Blocks.air);
		world.setBlock(x+5, y+2, z+13, Blocks.air);
		world.setBlock(x+5, y+2, z+14, b, ms);
		world.setBlock(x+5, y+2, z+15, Blocks.air);
		world.setBlock(x+5, y+2, z+16, Blocks.air);
		world.setBlock(x+5, y+2, z+17, Blocks.air);
		world.setBlock(x+5, y+2, z+18, b, ms);
		world.setBlock(x+5, y+2, z+19, Blocks.air);
		world.setBlock(x+5, y+2, z+20, b, ms);
		world.setBlock(x+5, y+2, z+21, Blocks.air);
		world.setBlock(x+5, y+2, z+22, b, ms);
		world.setBlock(x+5, y+2, z+23, Blocks.air);
		world.setBlock(x+5, y+2, z+24, b, ms);
		world.setBlock(x+5, y+3, z+0, b, ms);
		world.setBlock(x+5, y+3, z+1, Blocks.air);
		world.setBlock(x+5, y+3, z+2, Blocks.air);
		world.setBlock(x+5, y+3, z+3, Blocks.air);
		world.setBlock(x+5, y+3, z+4, Blocks.air);
		world.setBlock(x+5, y+3, z+5, Blocks.air);
		world.setBlock(x+5, y+3, z+6, Blocks.air);
		world.setBlock(x+5, y+3, z+7, Blocks.air);
		world.setBlock(x+5, y+3, z+8, Blocks.air);
		world.setBlock(x+5, y+3, z+9, Blocks.air);
		world.setBlock(x+5, y+3, z+10, Blocks.air);
		world.setBlock(x+5, y+3, z+11, Blocks.air);
		world.setBlock(x+5, y+3, z+12, Blocks.air);
		world.setBlock(x+5, y+3, z+13, Blocks.air);
		world.setBlock(x+5, y+3, z+14, Blocks.air);
		world.setBlock(x+5, y+3, z+15, Blocks.air);
		world.setBlock(x+5, y+3, z+16, Blocks.air);
		world.setBlock(x+5, y+3, z+17, Blocks.air);
		world.setBlock(x+5, y+3, z+18, Blocks.air);
		world.setBlock(x+5, y+3, z+19, Blocks.air);
		world.setBlock(x+5, y+3, z+20, Blocks.air);
		world.setBlock(x+5, y+3, z+21, Blocks.air);
		world.setBlock(x+5, y+3, z+22, Blocks.air);
		world.setBlock(x+5, y+3, z+23, Blocks.air);
		world.setBlock(x+5, y+3, z+24, b, ms);
		world.setBlock(x+5, y+4, z+0, b, ms);
		world.setBlock(x+5, y+4, z+1, Blocks.air);
		world.setBlock(x+5, y+4, z+2, Blocks.air);
		world.setBlock(x+5, y+4, z+3, Blocks.air);
		world.setBlock(x+5, y+4, z+4, Blocks.air);
		world.setBlock(x+5, y+4, z+5, Blocks.air);
		world.setBlock(x+5, y+4, z+6, Blocks.air);
		world.setBlock(x+5, y+4, z+7, Blocks.air);
		world.setBlock(x+5, y+4, z+8, Blocks.air);
		world.setBlock(x+5, y+4, z+9, Blocks.air);
		world.setBlock(x+5, y+4, z+10, Blocks.air);
		world.setBlock(x+5, y+4, z+11, Blocks.air);
		world.setBlock(x+5, y+4, z+12, Blocks.air);
		world.setBlock(x+5, y+4, z+13, Blocks.air);
		world.setBlock(x+5, y+4, z+14, Blocks.air);
		world.setBlock(x+5, y+4, z+15, Blocks.air);
		world.setBlock(x+5, y+4, z+16, Blocks.air);
		world.setBlock(x+5, y+4, z+17, Blocks.air);
		world.setBlock(x+5, y+4, z+18, Blocks.air);
		world.setBlock(x+5, y+4, z+19, Blocks.air);
		world.setBlock(x+5, y+4, z+20, Blocks.air);
		world.setBlock(x+5, y+4, z+21, Blocks.air);
		world.setBlock(x+5, y+4, z+22, Blocks.air);
		world.setBlock(x+5, y+4, z+23, Blocks.air);
		world.setBlock(x+5, y+4, z+24, b, ms);
		world.setBlock(x+5, y+5, z+0, b, ms);
		world.setBlock(x+5, y+5, z+1, Blocks.air);
		world.setBlock(x+5, y+5, z+2, Blocks.air);
		world.setBlock(x+5, y+5, z+3, Blocks.air);
		world.setBlock(x+5, y+5, z+4, Blocks.air);
		world.setBlock(x+5, y+5, z+5, Blocks.air);
		world.setBlock(x+5, y+5, z+6, Blocks.air);
		world.setBlock(x+5, y+5, z+7, Blocks.air);
		world.setBlock(x+5, y+5, z+8, Blocks.air);
		world.setBlock(x+5, y+5, z+9, Blocks.air);
		world.setBlock(x+5, y+5, z+10, Blocks.air);
		world.setBlock(x+5, y+5, z+11, Blocks.air);
		world.setBlock(x+5, y+5, z+12, Blocks.air);
		world.setBlock(x+5, y+5, z+13, Blocks.air);
		world.setBlock(x+5, y+5, z+14, Blocks.air);
		world.setBlock(x+5, y+5, z+15, Blocks.air);
		world.setBlock(x+5, y+5, z+16, Blocks.air);
		world.setBlock(x+5, y+5, z+17, Blocks.air);
		world.setBlock(x+5, y+5, z+18, Blocks.air);
		world.setBlock(x+5, y+5, z+19, Blocks.air);
		world.setBlock(x+5, y+5, z+20, Blocks.air);
		world.setBlock(x+5, y+5, z+21, Blocks.air);
		world.setBlock(x+5, y+5, z+22, Blocks.air);
		world.setBlock(x+5, y+5, z+23, Blocks.air);
		world.setBlock(x+5, y+5, z+24, b, ms);
		world.setBlock(x+6, y+0, z+0, b, ms);
		world.setBlock(x+6, y+0, z+1, b, ms);
		world.setBlock(x+6, y+0, z+2, b, ms);
		world.setBlock(x+6, y+0, z+3, b, ms);
		world.setBlock(x+6, y+0, z+4, b, ms);
		world.setBlock(x+6, y+0, z+5, b, ms);
		world.setBlock(x+6, y+0, z+6, b, ms);
		world.setBlock(x+6, y+0, z+7, b, ms);
		world.setBlock(x+6, y+0, z+8, b, ms);
		world.setBlock(x+6, y+0, z+9, b, ms);
		world.setBlock(x+6, y+0, z+10, b, ms);
		world.setBlock(x+6, y+0, z+11, b, ms);
		world.setBlock(x+6, y+0, z+12, b, ms);
		world.setBlock(x+6, y+0, z+13, b, ms);
		world.setBlock(x+6, y+0, z+14, b, ms);
		world.setBlock(x+6, y+0, z+15, b, ms);
		world.setBlock(x+6, y+0, z+16, b, ms);
		world.setBlock(x+6, y+0, z+17, b, ms);
		world.setBlock(x+6, y+0, z+18, b, ms);
		world.setBlock(x+6, y+0, z+19, b, ms);
		world.setBlock(x+6, y+0, z+20, b, ms);
		world.setBlock(x+6, y+0, z+21, b, ms);
		world.setBlock(x+6, y+0, z+22, b, ms);
		world.setBlock(x+6, y+0, z+23, b, ms);
		world.setBlock(x+6, y+0, z+24, b, ms);
		world.setBlock(x+6, y+1, z+0, b, ms);
		world.setBlock(x+6, y+1, z+1, Blocks.air);
		world.setBlock(x+6, y+1, z+2, b, ms);
		world.setBlock(x+6, y+1, z+3, b, ms);
		world.setBlock(x+6, y+1, z+4, b, ms);
		world.setBlock(x+6, y+1, z+5, Blocks.air);
		world.setBlock(x+6, y+1, z+6, b, ms);
		world.setBlock(x+6, y+1, z+7, Blocks.air);
		world.setBlock(x+6, y+1, z+8, b, ms);
		world.setBlock(x+6, y+1, z+9, Blocks.air);
		world.setBlock(x+6, y+1, z+10, b, ms);
		world.setBlock(x+6, y+1, z+12, b, ms);
		world.setBlock(x+6, y+1, z+13, b, ms);
		world.setBlock(x+6, y+1, z+14, b, ms);
		world.setBlock(x+6, y+1, z+15, b, ms);
		world.setBlock(x+6, y+1, z+16, b, ms);
		world.setBlock(x+6, y+1, z+17, b, ms);
		world.setBlock(x+6, y+1, z+18, b, ms);
		world.setBlock(x+6, y+1, z+19, Blocks.air);
		world.setBlock(x+6, y+1, z+20, b, ms);
		world.setBlock(x+6, y+1, z+21, Blocks.air);
		world.setBlock(x+6, y+1, z+22, b, ms);
		world.setBlock(x+6, y+1, z+23, Blocks.air);
		world.setBlock(x+6, y+1, z+24, b, ms);
		world.setBlock(x+6, y+2, z+0, b, ms);
		world.setBlock(x+6, y+2, z+1, Blocks.air);
		world.setBlock(x+6, y+2, z+2, b, ms);
		world.setBlock(x+6, y+2, z+3, b, ms);
		world.setBlock(x+6, y+2, z+4, b, ms);
		world.setBlock(x+6, y+2, z+5, Blocks.air);
		world.setBlock(x+6, y+2, z+6, b, ms);
		world.setBlock(x+6, y+2, z+7, Blocks.air);
		world.setBlock(x+6, y+2, z+8, b, ms);
		world.setBlock(x+6, y+2, z+9, Blocks.air);
		world.setBlock(x+6, y+2, z+10, b, ms);
		world.setBlock(x+6, y+2, z+12, b, ms);
		world.setBlock(x+6, y+2, z+13, b, ms);
		world.setBlock(x+6, y+2, z+14, b, ms);
		world.setBlock(x+6, y+2, z+15, b, ms);
		world.setBlock(x+6, y+2, z+16, b, ms);
		world.setBlock(x+6, y+2, z+17, b, ms);
		world.setBlock(x+6, y+2, z+18, b, ms);
		world.setBlock(x+6, y+2, z+19, Blocks.air);
		world.setBlock(x+6, y+2, z+20, b, ms);
		world.setBlock(x+6, y+2, z+21, Blocks.air);
		world.setBlock(x+6, y+2, z+22, b, ms);
		world.setBlock(x+6, y+2, z+23, Blocks.air);
		world.setBlock(x+6, y+2, z+24, b, ms);
		world.setBlock(x+6, y+3, z+0, b, ms);
		world.setBlock(x+6, y+3, z+1, Blocks.air);
		world.setBlock(x+6, y+3, z+2, Blocks.air);
		world.setBlock(x+6, y+3, z+3, Blocks.air);
		world.setBlock(x+6, y+3, z+4, Blocks.air);
		world.setBlock(x+6, y+3, z+5, Blocks.air);
		world.setBlock(x+6, y+3, z+6, Blocks.air);
		world.setBlock(x+6, y+3, z+7, Blocks.air);
		world.setBlock(x+6, y+3, z+8, Blocks.air);
		world.setBlock(x+6, y+3, z+9, Blocks.air);
		world.setBlock(x+6, y+3, z+10, Blocks.air);
		world.setBlock(x+6, y+3, z+11, Blocks.air);
		world.setBlock(x+6, y+3, z+12, Blocks.air);
		world.setBlock(x+6, y+3, z+13, Blocks.air);
		world.setBlock(x+6, y+3, z+14, Blocks.air);
		world.setBlock(x+6, y+3, z+15, Blocks.air);
		world.setBlock(x+6, y+3, z+16, Blocks.air);
		world.setBlock(x+6, y+3, z+17, Blocks.air);
		world.setBlock(x+6, y+3, z+18, Blocks.air);
		world.setBlock(x+6, y+3, z+19, Blocks.air);
		world.setBlock(x+6, y+3, z+20, Blocks.air);
		world.setBlock(x+6, y+3, z+21, Blocks.air);
		world.setBlock(x+6, y+3, z+22, Blocks.air);
		world.setBlock(x+6, y+3, z+23, Blocks.air);
		world.setBlock(x+6, y+3, z+24, b, ms);
		world.setBlock(x+6, y+4, z+0, b, ms);
		world.setBlock(x+6, y+4, z+1, Blocks.air);
		world.setBlock(x+6, y+4, z+2, Blocks.air);
		world.setBlock(x+6, y+4, z+3, Blocks.air);
		world.setBlock(x+6, y+4, z+4, Blocks.air);
		world.setBlock(x+6, y+4, z+5, Blocks.air);
		world.setBlock(x+6, y+4, z+6, Blocks.air);
		world.setBlock(x+6, y+4, z+7, Blocks.air);
		world.setBlock(x+6, y+4, z+8, Blocks.air);
		world.setBlock(x+6, y+4, z+9, Blocks.air);
		world.setBlock(x+6, y+4, z+10, Blocks.air);
		world.setBlock(x+6, y+4, z+11, Blocks.air);
		world.setBlock(x+6, y+4, z+12, Blocks.air);
		world.setBlock(x+6, y+4, z+13, Blocks.air);
		world.setBlock(x+6, y+4, z+14, Blocks.air);
		world.setBlock(x+6, y+4, z+15, Blocks.air);
		world.setBlock(x+6, y+4, z+16, Blocks.air);
		world.setBlock(x+6, y+4, z+17, Blocks.air);
		world.setBlock(x+6, y+4, z+18, Blocks.air);
		world.setBlock(x+6, y+4, z+19, Blocks.air);
		world.setBlock(x+6, y+4, z+20, Blocks.air);
		world.setBlock(x+6, y+4, z+21, Blocks.air);
		world.setBlock(x+6, y+4, z+22, Blocks.air);
		world.setBlock(x+6, y+4, z+23, Blocks.air);
		world.setBlock(x+6, y+4, z+24, b, ms);
		world.setBlock(x+6, y+5, z+0, b, ms);
		world.setBlock(x+6, y+5, z+1, Blocks.air);
		world.setBlock(x+6, y+5, z+2, Blocks.air);
		world.setBlock(x+6, y+5, z+3, Blocks.air);
		world.setBlock(x+6, y+5, z+4, Blocks.air);
		world.setBlock(x+6, y+5, z+5, Blocks.air);
		world.setBlock(x+6, y+5, z+6, Blocks.air);
		world.setBlock(x+6, y+5, z+7, Blocks.air);
		world.setBlock(x+6, y+5, z+8, Blocks.air);
		world.setBlock(x+6, y+5, z+9, Blocks.air);
		world.setBlock(x+6, y+5, z+10, Blocks.air);
		world.setBlock(x+6, y+5, z+11, Blocks.air);
		world.setBlock(x+6, y+5, z+12, Blocks.air);
		world.setBlock(x+6, y+5, z+13, Blocks.air);
		world.setBlock(x+6, y+5, z+14, Blocks.air);
		world.setBlock(x+6, y+5, z+15, Blocks.air);
		world.setBlock(x+6, y+5, z+16, Blocks.air);
		world.setBlock(x+6, y+5, z+17, Blocks.air);
		world.setBlock(x+6, y+5, z+18, Blocks.air);
		world.setBlock(x+6, y+5, z+19, Blocks.air);
		world.setBlock(x+6, y+5, z+20, Blocks.air);
		world.setBlock(x+6, y+5, z+21, Blocks.air);
		world.setBlock(x+6, y+5, z+22, Blocks.air);
		world.setBlock(x+6, y+5, z+23, Blocks.air);
		world.setBlock(x+6, y+5, z+24, b, ms);
		world.setBlock(x+7, y+0, z+0, b, ms);
		world.setBlock(x+7, y+0, z+1, b, ms);
		world.setBlock(x+7, y+0, z+2, b, ms);
		world.setBlock(x+7, y+0, z+3, b, ms);
		world.setBlock(x+7, y+0, z+4, b, ms);
		world.setBlock(x+7, y+0, z+5, b, ms);
		world.setBlock(x+7, y+0, z+6, b, ms);
		world.setBlock(x+7, y+0, z+7, b, ms);
		world.setBlock(x+7, y+0, z+8, b, ms);
		world.setBlock(x+7, y+0, z+9, b, ms);
		world.setBlock(x+7, y+0, z+10, b, ms);
		world.setBlock(x+7, y+0, z+11, b, ms);
		world.setBlock(x+7, y+0, z+12, b, ms);
		world.setBlock(x+7, y+0, z+13, b, ms);
		world.setBlock(x+7, y+0, z+14, b, ms);
		world.setBlock(x+7, y+0, z+15, b, ms);
		world.setBlock(x+7, y+0, z+16, b, ms);
		world.setBlock(x+7, y+0, z+17, b, ms);
		world.setBlock(x+7, y+0, z+18, b, ms);
		world.setBlock(x+7, y+0, z+19, b, ms);
		world.setBlock(x+7, y+0, z+20, b, ms);
		world.setBlock(x+7, y+0, z+21, b, ms);
		world.setBlock(x+7, y+0, z+22, b, ms);
		world.setBlock(x+7, y+0, z+23, b, ms);
		world.setBlock(x+7, y+0, z+24, b, ms);
		world.setBlock(x+7, y+1, z+0, b, ms);
		world.setBlock(x+7, y+1, z+1, Blocks.air);
		world.setBlock(x+7, y+1, z+2, Blocks.air);
		world.setBlock(x+7, y+1, z+3, Blocks.air);
		world.setBlock(x+7, y+1, z+4, Blocks.air);
		world.setBlock(x+7, y+1, z+5, Blocks.air);
		world.setBlock(x+7, y+1, z+6, b, ms);
		world.setBlock(x+7, y+1, z+7, Blocks.air);
		world.setBlock(x+7, y+1, z+8, b, ms);
		world.setBlock(x+7, y+1, z+9, Blocks.air);
		world.setBlock(x+7, y+1, z+10, b, ms);
		world.setBlock(x+7, y+1, z+11, Blocks.air);
		world.setBlock(x+7, y+1, z+12, Blocks.air);
		world.setBlock(x+7, y+1, z+13, Blocks.air);
		world.setBlock(x+7, y+1, z+14, Blocks.air);
		world.setBlock(x+7, y+1, z+15, Blocks.air);
		world.setBlock(x+7, y+1, z+17, Blocks.air);
		world.setBlock(x+7, y+1, z+18, b, ms);
		world.setBlock(x+7, y+1, z+19, Blocks.air);
		world.setBlock(x+7, y+1, z+20, b, ms);
		world.setBlock(x+7, y+1, z+21, Blocks.air);
		world.setBlock(x+7, y+1, z+22, b, ms);
		world.setBlock(x+7, y+1, z+23, Blocks.air);
		world.setBlock(x+7, y+1, z+24, b, ms);
		world.setBlock(x+7, y+2, z+0, b, ms);
		world.setBlock(x+7, y+2, z+1, Blocks.air);
		world.setBlock(x+7, y+2, z+2, Blocks.air);
		world.setBlock(x+7, y+2, z+3, Blocks.air);
		world.setBlock(x+7, y+2, z+4, Blocks.air);
		world.setBlock(x+7, y+2, z+5, Blocks.air);
		world.setBlock(x+7, y+2, z+6, b, ms);
		world.setBlock(x+7, y+2, z+7, Blocks.air);
		world.setBlock(x+7, y+2, z+8, b, ms);
		world.setBlock(x+7, y+2, z+9, Blocks.air);
		world.setBlock(x+7, y+2, z+10, b, ms);
		world.setBlock(x+7, y+2, z+11, Blocks.air);
		world.setBlock(x+7, y+2, z+12, Blocks.air);
		world.setBlock(x+7, y+2, z+13, Blocks.air);
		world.setBlock(x+7, y+2, z+14, Blocks.air);
		world.setBlock(x+7, y+2, z+15, Blocks.air);
		world.setBlock(x+7, y+2, z+17, Blocks.air);
		world.setBlock(x+7, y+2, z+18, b, ms);
		world.setBlock(x+7, y+2, z+19, Blocks.air);
		world.setBlock(x+7, y+2, z+20, b, ms);
		world.setBlock(x+7, y+2, z+21, Blocks.air);
		world.setBlock(x+7, y+2, z+22, b, ms);
		world.setBlock(x+7, y+2, z+23, Blocks.air);
		world.setBlock(x+7, y+2, z+24, b, ms);
		world.setBlock(x+7, y+3, z+0, b, ms);
		world.setBlock(x+7, y+3, z+1, Blocks.air);
		world.setBlock(x+7, y+3, z+2, Blocks.air);
		world.setBlock(x+7, y+3, z+3, Blocks.air);
		world.setBlock(x+7, y+3, z+4, Blocks.air);
		world.setBlock(x+7, y+3, z+5, Blocks.air);
		world.setBlock(x+7, y+3, z+6, Blocks.air);
		world.setBlock(x+7, y+3, z+7, Blocks.air);
		world.setBlock(x+7, y+3, z+8, Blocks.air);
		world.setBlock(x+7, y+3, z+9, Blocks.air);
		world.setBlock(x+7, y+3, z+10, Blocks.air);
		world.setBlock(x+7, y+3, z+11, Blocks.air);
		world.setBlock(x+7, y+3, z+12, Blocks.air);
		world.setBlock(x+7, y+3, z+13, Blocks.air);
		world.setBlock(x+7, y+3, z+14, Blocks.air);
		world.setBlock(x+7, y+3, z+15, Blocks.air);
		world.setBlock(x+7, y+3, z+16, Blocks.air);
		world.setBlock(x+7, y+3, z+17, Blocks.air);
		world.setBlock(x+7, y+3, z+18, Blocks.air);
		world.setBlock(x+7, y+3, z+19, Blocks.air);
		world.setBlock(x+7, y+3, z+20, Blocks.air);
		world.setBlock(x+7, y+3, z+21, Blocks.air);
		world.setBlock(x+7, y+3, z+22, Blocks.air);
		world.setBlock(x+7, y+3, z+23, Blocks.air);
		world.setBlock(x+7, y+3, z+24, b, ms);
		world.setBlock(x+7, y+4, z+0, b, ms);
		world.setBlock(x+7, y+4, z+1, Blocks.air);
		world.setBlock(x+7, y+4, z+2, Blocks.air);
		world.setBlock(x+7, y+4, z+3, Blocks.air);
		world.setBlock(x+7, y+4, z+4, Blocks.air);
		world.setBlock(x+7, y+4, z+5, Blocks.air);
		world.setBlock(x+7, y+4, z+6, Blocks.air);
		world.setBlock(x+7, y+4, z+7, Blocks.air);
		world.setBlock(x+7, y+4, z+8, Blocks.air);
		world.setBlock(x+7, y+4, z+9, Blocks.air);
		world.setBlock(x+7, y+4, z+10, Blocks.air);
		world.setBlock(x+7, y+4, z+11, Blocks.air);
		world.setBlock(x+7, y+4, z+12, Blocks.air);
		world.setBlock(x+7, y+4, z+13, Blocks.air);
		world.setBlock(x+7, y+4, z+14, Blocks.air);
		world.setBlock(x+7, y+4, z+15, Blocks.air);
		world.setBlock(x+7, y+4, z+16, Blocks.air);
		world.setBlock(x+7, y+4, z+17, Blocks.air);
		world.setBlock(x+7, y+4, z+18, Blocks.air);
		world.setBlock(x+7, y+4, z+19, Blocks.air);
		world.setBlock(x+7, y+4, z+20, Blocks.air);
		world.setBlock(x+7, y+4, z+21, Blocks.air);
		world.setBlock(x+7, y+4, z+22, Blocks.air);
		world.setBlock(x+7, y+4, z+23, Blocks.air);
		world.setBlock(x+7, y+4, z+24, b, ms);
		world.setBlock(x+7, y+5, z+0, b, ms);
		world.setBlock(x+7, y+5, z+1, Blocks.air);
		world.setBlock(x+7, y+5, z+2, Blocks.air);
		world.setBlock(x+7, y+5, z+3, Blocks.air);
		world.setBlock(x+7, y+5, z+4, Blocks.air);
		world.setBlock(x+7, y+5, z+5, Blocks.air);
		world.setBlock(x+7, y+5, z+6, Blocks.air);
		world.setBlock(x+7, y+5, z+7, Blocks.air);
		world.setBlock(x+7, y+5, z+8, Blocks.air);
		world.setBlock(x+7, y+5, z+9, Blocks.air);
		world.setBlock(x+7, y+5, z+10, Blocks.air);
		world.setBlock(x+7, y+5, z+11, Blocks.air);
		world.setBlock(x+7, y+5, z+12, Blocks.air);
		world.setBlock(x+7, y+5, z+13, Blocks.air);
		world.setBlock(x+7, y+5, z+14, Blocks.air);
		world.setBlock(x+7, y+5, z+15, Blocks.air);
		world.setBlock(x+7, y+5, z+16, Blocks.air);
		world.setBlock(x+7, y+5, z+17, Blocks.air);
		world.setBlock(x+7, y+5, z+18, Blocks.air);
		world.setBlock(x+7, y+5, z+19, Blocks.air);
		world.setBlock(x+7, y+5, z+20, Blocks.air);
		world.setBlock(x+7, y+5, z+21, Blocks.air);
		world.setBlock(x+7, y+5, z+22, Blocks.air);
		world.setBlock(x+7, y+5, z+23, Blocks.air);
		world.setBlock(x+7, y+5, z+24, b, ms);
		world.setBlock(x+8, y+0, z+0, b, ms);
		world.setBlock(x+8, y+0, z+1, b, ms);
		world.setBlock(x+8, y+0, z+2, b, ms);
		world.setBlock(x+8, y+0, z+3, b, ms);
		world.setBlock(x+8, y+0, z+4, b, ms);
		world.setBlock(x+8, y+0, z+5, b, ms);
		world.setBlock(x+8, y+0, z+6, b, ms);
		world.setBlock(x+8, y+0, z+7, b, ms);
		world.setBlock(x+8, y+0, z+8, b, ms);
		world.setBlock(x+8, y+0, z+9, b, ms);
		world.setBlock(x+8, y+0, z+10, b, ms);
		world.setBlock(x+8, y+0, z+11, b, ms);
		world.setBlock(x+8, y+0, z+12, b, ms);
		world.setBlock(x+8, y+0, z+13, b, ms);
		world.setBlock(x+8, y+0, z+14, b, ms);
		world.setBlock(x+8, y+0, z+15, b, ms);
		world.setBlock(x+8, y+0, z+16, b, ms);
		world.setBlock(x+8, y+0, z+17, b, ms);
		world.setBlock(x+8, y+0, z+18, b, ms);
		world.setBlock(x+8, y+0, z+19, b, ms);
		world.setBlock(x+8, y+0, z+20, b, ms);
		world.setBlock(x+8, y+0, z+21, b, ms);
		world.setBlock(x+8, y+0, z+22, b, ms);
		world.setBlock(x+8, y+0, z+23, b, ms);
		world.setBlock(x+8, y+0, z+24, b, ms);
		world.setBlock(x+8, y+1, z+0, b, ms);
		world.setBlock(x+8, y+1, z+1, b, ms);
		world.setBlock(x+8, y+1, z+2, b, ms);
		world.setBlock(x+8, y+1, z+4, b, ms);
		world.setBlock(x+8, y+1, z+5, b, ms);
		world.setBlock(x+8, y+1, z+6, b, ms);
		world.setBlock(x+8, y+1, z+7, Blocks.air);
		world.setBlock(x+8, y+1, z+8, b, ms);
		world.setBlock(x+8, y+1, z+9, Blocks.air);
		world.setBlock(x+8, y+1, z+10, b, ms);
		world.setBlock(x+8, y+1, z+11, b, ms);
		world.setBlock(x+8, y+1, z+12, b, ms);
		world.setBlock(x+8, y+1, z+13, b, ms);
		world.setBlock(x+8, y+1, z+14, b, ms);
		world.setBlock(x+8, y+1, z+15, Blocks.air);
		world.setBlock(x+8, y+1, z+16, b, ms);
		world.setBlock(x+8, y+1, z+17, Blocks.air);
		world.setBlock(x+8, y+1, z+18, b, ms);
		world.setBlock(x+8, y+1, z+19, Blocks.air);
		world.setBlock(x+8, y+1, z+20, b, ms);
		world.setBlock(x+8, y+1, z+21, Blocks.air);
		world.setBlock(x+8, y+1, z+22, b, ms);
		world.setBlock(x+8, y+1, z+23, Blocks.air);
		world.setBlock(x+8, y+1, z+24, b, ms);
		world.setBlock(x+8, y+2, z+0, b, ms);
		world.setBlock(x+8, y+2, z+1, b, ms);
		world.setBlock(x+8, y+2, z+2, b, ms);
		world.setBlock(x+8, y+2, z+4, b, ms);
		world.setBlock(x+8, y+2, z+5, b, ms);
		world.setBlock(x+8, y+2, z+6, b, ms);
		world.setBlock(x+8, y+2, z+7, Blocks.air);
		world.setBlock(x+8, y+2, z+8, b, ms);
		world.setBlock(x+8, y+2, z+9, Blocks.air);
		world.setBlock(x+8, y+2, z+10, b, ms);
		world.setBlock(x+8, y+2, z+11, b, ms);
		world.setBlock(x+8, y+2, z+12, b, ms);
		world.setBlock(x+8, y+2, z+13, b, ms);
		world.setBlock(x+8, y+2, z+14, b, ms);
		world.setBlock(x+8, y+2, z+15, Blocks.air);
		world.setBlock(x+8, y+2, z+16, b, ms);
		world.setBlock(x+8, y+2, z+17, Blocks.air);
		world.setBlock(x+8, y+2, z+18, b, ms);
		world.setBlock(x+8, y+2, z+19, Blocks.air);
		world.setBlock(x+8, y+2, z+20, b, ms);
		world.setBlock(x+8, y+2, z+21, Blocks.air);
		world.setBlock(x+8, y+2, z+22, b, ms);
		world.setBlock(x+8, y+2, z+23, Blocks.air);
		world.setBlock(x+8, y+2, z+24, b, ms);
		world.setBlock(x+8, y+3, z+0, b, ms);
		world.setBlock(x+8, y+3, z+1, Blocks.air);
		world.setBlock(x+8, y+3, z+2, Blocks.air);
		world.setBlock(x+8, y+3, z+3, Blocks.air);
		world.setBlock(x+8, y+3, z+4, Blocks.air);
		world.setBlock(x+8, y+3, z+5, Blocks.air);
		world.setBlock(x+8, y+3, z+6, Blocks.air);
		world.setBlock(x+8, y+3, z+7, Blocks.air);
		world.setBlock(x+8, y+3, z+8, Blocks.air);
		world.setBlock(x+8, y+3, z+9, Blocks.air);
		world.setBlock(x+8, y+3, z+10, Blocks.air);
		world.setBlock(x+8, y+3, z+11, Blocks.air);
		world.setBlock(x+8, y+3, z+12, Blocks.air);
		world.setBlock(x+8, y+3, z+13, Blocks.air);
		world.setBlock(x+8, y+3, z+14, Blocks.air);
		world.setBlock(x+8, y+3, z+15, Blocks.air);
		world.setBlock(x+8, y+3, z+16, Blocks.air);
		world.setBlock(x+8, y+3, z+17, Blocks.air);
		world.setBlock(x+8, y+3, z+18, Blocks.air);
		world.setBlock(x+8, y+3, z+19, Blocks.air);
		world.setBlock(x+8, y+3, z+20, Blocks.air);
		world.setBlock(x+8, y+3, z+21, Blocks.air);
		world.setBlock(x+8, y+3, z+22, Blocks.air);
		world.setBlock(x+8, y+3, z+23, Blocks.air);
		world.setBlock(x+8, y+3, z+24, b, ms);
		world.setBlock(x+8, y+4, z+0, b, ms);
		world.setBlock(x+8, y+4, z+1, Blocks.air);
		world.setBlock(x+8, y+4, z+2, Blocks.air);
		world.setBlock(x+8, y+4, z+3, Blocks.air);
		world.setBlock(x+8, y+4, z+4, Blocks.air);
		world.setBlock(x+8, y+4, z+5, Blocks.air);
		world.setBlock(x+8, y+4, z+6, Blocks.air);
		world.setBlock(x+8, y+4, z+7, Blocks.air);
		world.setBlock(x+8, y+4, z+8, Blocks.air);
		world.setBlock(x+8, y+4, z+9, Blocks.air);
		world.setBlock(x+8, y+4, z+10, Blocks.air);
		world.setBlock(x+8, y+4, z+11, Blocks.air);
		world.setBlock(x+8, y+4, z+12, Blocks.air);
		world.setBlock(x+8, y+4, z+13, Blocks.air);
		world.setBlock(x+8, y+4, z+14, Blocks.air);
		world.setBlock(x+8, y+4, z+15, Blocks.air);
		world.setBlock(x+8, y+4, z+16, Blocks.air);
		world.setBlock(x+8, y+4, z+17, Blocks.air);
		world.setBlock(x+8, y+4, z+18, Blocks.air);
		world.setBlock(x+8, y+4, z+19, Blocks.air);
		world.setBlock(x+8, y+4, z+20, Blocks.air);
		world.setBlock(x+8, y+4, z+21, Blocks.air);
		world.setBlock(x+8, y+4, z+22, Blocks.air);
		world.setBlock(x+8, y+4, z+23, Blocks.air);
		world.setBlock(x+8, y+4, z+24, b, ms);
		world.setBlock(x+8, y+5, z+0, b, ms);
		world.setBlock(x+8, y+5, z+1, Blocks.air);
		world.setBlock(x+8, y+5, z+2, Blocks.air);
		world.setBlock(x+8, y+5, z+3, Blocks.air);
		world.setBlock(x+8, y+5, z+4, Blocks.air);
		world.setBlock(x+8, y+5, z+5, Blocks.air);
		world.setBlock(x+8, y+5, z+6, Blocks.air);
		world.setBlock(x+8, y+5, z+7, Blocks.air);
		world.setBlock(x+8, y+5, z+8, Blocks.air);
		world.setBlock(x+8, y+5, z+9, Blocks.air);
		world.setBlock(x+8, y+5, z+10, Blocks.air);
		world.setBlock(x+8, y+5, z+11, Blocks.air);
		world.setBlock(x+8, y+5, z+12, Blocks.air);
		world.setBlock(x+8, y+5, z+13, Blocks.air);
		world.setBlock(x+8, y+5, z+14, Blocks.air);
		world.setBlock(x+8, y+5, z+15, Blocks.air);
		world.setBlock(x+8, y+5, z+16, Blocks.air);
		world.setBlock(x+8, y+5, z+17, Blocks.air);
		world.setBlock(x+8, y+5, z+18, Blocks.air);
		world.setBlock(x+8, y+5, z+19, Blocks.air);
		world.setBlock(x+8, y+5, z+20, Blocks.air);
		world.setBlock(x+8, y+5, z+21, Blocks.air);
		world.setBlock(x+8, y+5, z+22, Blocks.air);
		world.setBlock(x+8, y+5, z+23, Blocks.air);
		world.setBlock(x+8, y+5, z+24, b, ms);
		world.setBlock(x+9, y+0, z+0, b, ms);
		world.setBlock(x+9, y+0, z+1, b, ms);
		world.setBlock(x+9, y+0, z+2, b, ms);
		world.setBlock(x+9, y+0, z+3, b, ms);
		world.setBlock(x+9, y+0, z+4, b, ms);
		world.setBlock(x+9, y+0, z+5, b, ms);
		world.setBlock(x+9, y+0, z+6, b, ms);
		world.setBlock(x+9, y+0, z+7, b, ms);
		world.setBlock(x+9, y+0, z+8, b, ms);
		world.setBlock(x+9, y+0, z+9, b, ms);
		world.setBlock(x+9, y+0, z+10, b, ms);
		world.setBlock(x+9, y+0, z+11, b, ms);
		world.setBlock(x+9, y+0, z+12, b, ms);
		world.setBlock(x+9, y+0, z+13, b, ms);
		world.setBlock(x+9, y+0, z+14, b, ms);
		world.setBlock(x+9, y+0, z+15, b, ms);
		world.setBlock(x+9, y+0, z+16, b, ms);
		world.setBlock(x+9, y+0, z+17, b, ms);
		world.setBlock(x+9, y+0, z+18, b, ms);
		world.setBlock(x+9, y+0, z+19, b, ms);
		world.setBlock(x+9, y+0, z+20, b, ms);
		world.setBlock(x+9, y+0, z+21, b, ms);
		world.setBlock(x+9, y+0, z+22, b, ms);
		world.setBlock(x+9, y+0, z+23, b, ms);
		world.setBlock(x+9, y+0, z+24, b, ms);
		world.setBlock(x+9, y+1, z+0, b, ms);
		world.setBlock(x+9, y+1, z+1, Blocks.air);
		world.setBlock(x+9, y+1, z+2, Blocks.air);
		world.setBlock(x+9, y+1, z+3, Blocks.air);
		world.setBlock(x+9, y+1, z+4, Blocks.air);
		world.setBlock(x+9, y+1, z+5, Blocks.air);
		world.setBlock(x+9, y+1, z+6, b, ms);
		world.setBlock(x+9, y+1, z+7, Blocks.air);
		world.setBlock(x+9, y+1, z+8, Blocks.air);
		world.setBlock(x+9, y+1, z+9, Blocks.air);
		world.setBlock(x+9, y+1, z+10, b, ms);
		world.setBlock(x+9, y+1, z+11, Blocks.air);
		world.setBlock(x+9, y+1, z+12, Blocks.air);
		world.setBlock(x+9, y+1, z+13, Blocks.air);
		world.setBlock(x+9, y+1, z+14, b, ms);
		world.setBlock(x+9, y+1, z+15, Blocks.air);
		world.setBlock(x+9, y+1, z+16, b, ms);
		world.setBlock(x+9, y+1, z+18, b, ms);
		world.setBlock(x+9, y+1, z+19, Blocks.air);
		world.setBlock(x+9, y+1, z+20, b, ms);
		world.setBlock(x+9, y+1, z+21, Blocks.air);
		world.setBlock(x+9, y+1, z+22, b, ms);
		world.setBlock(x+9, y+1, z+23, Blocks.air);
		world.setBlock(x+9, y+1, z+24, b, ms);
		world.setBlock(x+9, y+2, z+0, b, ms);
		world.setBlock(x+9, y+2, z+1, Blocks.air);
		world.setBlock(x+9, y+2, z+2, Blocks.air);
		world.setBlock(x+9, y+2, z+3, Blocks.air);
		world.setBlock(x+9, y+2, z+4, Blocks.air);
		world.setBlock(x+9, y+2, z+5, Blocks.air);
		world.setBlock(x+9, y+2, z+6, b, ms);
		world.setBlock(x+9, y+2, z+7, Blocks.air);
		world.setBlock(x+9, y+2, z+8, Blocks.air);
		world.setBlock(x+9, y+2, z+9, Blocks.air);
		world.setBlock(x+9, y+2, z+10, b, ms);
		world.setBlock(x+9, y+2, z+11, Blocks.air);
		world.setBlock(x+9, y+2, z+12, Blocks.air);
		world.setBlock(x+9, y+2, z+13, Blocks.air);
		world.setBlock(x+9, y+2, z+14, b, ms);
		world.setBlock(x+9, y+2, z+15, Blocks.air);
		world.setBlock(x+9, y+2, z+16, b, ms);
		world.setBlock(x+9, y+2, z+17, Blocks.air);
		world.setBlock(x+9, y+2, z+18, b, ms);
		world.setBlock(x+9, y+2, z+19, Blocks.air);
		world.setBlock(x+9, y+2, z+20, b, ms);
		world.setBlock(x+9, y+2, z+21, Blocks.air);
		world.setBlock(x+9, y+2, z+22, b, ms);
		world.setBlock(x+9, y+2, z+23, Blocks.air);
		world.setBlock(x+9, y+2, z+24, b, ms);
		world.setBlock(x+9, y+3, z+0, b, ms);
		world.setBlock(x+9, y+3, z+1, Blocks.air);
		world.setBlock(x+9, y+3, z+2, Blocks.air);
		world.setBlock(x+9, y+3, z+3, Blocks.air);
		world.setBlock(x+9, y+3, z+4, Blocks.air);
		world.setBlock(x+9, y+3, z+5, Blocks.air);
		world.setBlock(x+9, y+3, z+6, Blocks.air);
		world.setBlock(x+9, y+3, z+7, Blocks.air);
		world.setBlock(x+9, y+3, z+8, Blocks.air);
		world.setBlock(x+9, y+3, z+9, Blocks.air);
		world.setBlock(x+9, y+3, z+10, Blocks.air);
		world.setBlock(x+9, y+3, z+11, Blocks.air);
		world.setBlock(x+9, y+3, z+12, Blocks.air);
		world.setBlock(x+9, y+3, z+13, Blocks.air);
		world.setBlock(x+9, y+3, z+14, Blocks.air);
		world.setBlock(x+9, y+3, z+15, Blocks.air);
		world.setBlock(x+9, y+3, z+16, Blocks.air);
		world.setBlock(x+9, y+3, z+17, Blocks.air);
		world.setBlock(x+9, y+3, z+18, Blocks.air);
		world.setBlock(x+9, y+3, z+19, Blocks.air);
		world.setBlock(x+9, y+3, z+20, Blocks.air);
		world.setBlock(x+9, y+3, z+21, Blocks.air);
		world.setBlock(x+9, y+3, z+22, Blocks.air);
		world.setBlock(x+9, y+3, z+23, Blocks.air);
		world.setBlock(x+9, y+3, z+24, b, ms);
		world.setBlock(x+9, y+4, z+0, b, ms);
		world.setBlock(x+9, y+4, z+1, Blocks.air);
		world.setBlock(x+9, y+4, z+2, Blocks.air);
		world.setBlock(x+9, y+4, z+3, Blocks.air);
		world.setBlock(x+9, y+4, z+4, Blocks.air);
		world.setBlock(x+9, y+4, z+5, Blocks.air);
		world.setBlock(x+9, y+4, z+6, Blocks.air);
		world.setBlock(x+9, y+4, z+7, Blocks.air);
		world.setBlock(x+9, y+4, z+8, Blocks.air);
		world.setBlock(x+9, y+4, z+9, Blocks.air);
		world.setBlock(x+9, y+4, z+10, Blocks.air);
		world.setBlock(x+9, y+4, z+11, Blocks.air);
		world.setBlock(x+9, y+4, z+12, Blocks.air);
		world.setBlock(x+9, y+4, z+13, Blocks.air);
		world.setBlock(x+9, y+4, z+14, Blocks.air);
		world.setBlock(x+9, y+4, z+15, Blocks.air);
		world.setBlock(x+9, y+4, z+16, Blocks.air);
		world.setBlock(x+9, y+4, z+17, Blocks.air);
		world.setBlock(x+9, y+4, z+18, Blocks.air);
		world.setBlock(x+9, y+4, z+19, Blocks.air);
		world.setBlock(x+9, y+4, z+20, Blocks.air);
		world.setBlock(x+9, y+4, z+21, Blocks.air);
		world.setBlock(x+9, y+4, z+22, Blocks.air);
		world.setBlock(x+9, y+4, z+23, Blocks.air);
		world.setBlock(x+9, y+4, z+24, b, ms);
		world.setBlock(x+9, y+5, z+0, b, ms);
		world.setBlock(x+9, y+5, z+1, Blocks.air);
		world.setBlock(x+9, y+5, z+2, Blocks.air);
		world.setBlock(x+9, y+5, z+3, Blocks.air);
		world.setBlock(x+9, y+5, z+4, Blocks.air);
		world.setBlock(x+9, y+5, z+5, Blocks.air);
		world.setBlock(x+9, y+5, z+6, Blocks.air);
		world.setBlock(x+9, y+5, z+7, Blocks.air);
		world.setBlock(x+9, y+5, z+8, Blocks.air);
		world.setBlock(x+9, y+5, z+9, Blocks.air);
		world.setBlock(x+9, y+5, z+10, Blocks.air);
		world.setBlock(x+9, y+5, z+11, Blocks.air);
		world.setBlock(x+9, y+5, z+12, Blocks.air);
		world.setBlock(x+9, y+5, z+13, Blocks.air);
		world.setBlock(x+9, y+5, z+14, Blocks.air);
		world.setBlock(x+9, y+5, z+15, Blocks.air);
		world.setBlock(x+9, y+5, z+16, Blocks.air);
		world.setBlock(x+9, y+5, z+17, Blocks.air);
		world.setBlock(x+9, y+5, z+18, Blocks.air);
		world.setBlock(x+9, y+5, z+19, Blocks.air);
		world.setBlock(x+9, y+5, z+20, Blocks.air);
		world.setBlock(x+9, y+5, z+21, Blocks.air);
		world.setBlock(x+9, y+5, z+22, Blocks.air);
		world.setBlock(x+9, y+5, z+23, Blocks.air);
		world.setBlock(x+9, y+5, z+24, b, ms);
		world.setBlock(x+10, y+0, z+0, b, ms);
		world.setBlock(x+10, y+0, z+1, b, ms);
		world.setBlock(x+10, y+0, z+2, b, ms);
		world.setBlock(x+10, y+0, z+3, b, ms);
		world.setBlock(x+10, y+0, z+4, b, ms);
		world.setBlock(x+10, y+0, z+5, b, ms);
		world.setBlock(x+10, y+0, z+6, b, ms);
		world.setBlock(x+10, y+0, z+7, b, ms);
		world.setBlock(x+10, y+0, z+8, b, ms);
		world.setBlock(x+10, y+0, z+9, b, ms);
		world.setBlock(x+10, y+0, z+10, b, ms);
		world.setBlock(x+10, y+0, z+11, b, ms);
	}

	private void doGenerate2(ChunkSplicedGenerationCache world, int x, int y, int z) {
		world.setBlock(x+10, y+0, z+12, b, ms);
		world.setBlock(x+10, y+0, z+13, b, ms);
		world.setBlock(x+10, y+0, z+14, b, ms);
		world.setBlock(x+10, y+0, z+15, b, ms);
		world.setBlock(x+10, y+0, z+16, b, ms);
		world.setBlock(x+10, y+0, z+17, b, ms);
		world.setBlock(x+10, y+0, z+18, b, ms);
		world.setBlock(x+10, y+0, z+19, b, ms);
		world.setBlock(x+10, y+0, z+20, b, ms);
		world.setBlock(x+10, y+0, z+21, b, ms);
		world.setBlock(x+10, y+0, z+22, b, ms);
		world.setBlock(x+10, y+0, z+23, b, ms);
		world.setBlock(x+10, y+0, z+24, b, ms);
		world.setBlock(x+10, y+1, z+0, b, ms);
		world.setBlock(x+10, y+1, z+1, Blocks.air);
		world.setBlock(x+10, y+1, z+2, b, ms);
		world.setBlock(x+10, y+1, z+3, b, ms);
		world.setBlock(x+10, y+1, z+4, b, ms);
		world.setBlock(x+10, y+1, z+5, Blocks.air);
		world.setBlock(x+10, y+1, z+6, b, ms);
		world.setBlock(x+10, y+1, z+8, b, ms);
		world.setBlock(x+10, y+1, z+9, b, ms);
		world.setBlock(x+10, y+1, z+10, b, ms);
		world.setBlock(x+10, y+1, z+11, Blocks.air);
		world.setBlock(x+10, y+1, z+12, b, ms);
		world.setBlock(x+10, y+1, z+13, Blocks.air);
		world.setBlock(x+10, y+1, z+14, b, ms);
		world.setBlock(x+10, y+1, z+16, b, ms);
		world.setBlock(x+10, y+1, z+17, b, ms);
		world.setBlock(x+10, y+1, z+18, b, ms);
		world.setBlock(x+10, y+1, z+19, Blocks.air);
		world.setBlock(x+10, y+1, z+20, b, ms);
		world.setBlock(x+10, y+1, z+21, Blocks.air);
		world.setBlock(x+10, y+1, z+22, b, ms);
		world.setBlock(x+10, y+1, z+23, Blocks.air);
		world.setBlock(x+10, y+1, z+24, b, ms);
		world.setBlock(x+10, y+2, z+0, b, ms);
		world.setBlock(x+10, y+2, z+1, Blocks.air);
		world.setBlock(x+10, y+2, z+2, b, ms);
		world.setBlock(x+10, y+2, z+3, b, ms);
		world.setBlock(x+10, y+2, z+4, b, ms);
		world.setBlock(x+10, y+2, z+5, Blocks.air);
		world.setBlock(x+10, y+2, z+6, b, ms);
		world.setBlock(x+10, y+2, z+8, b, ms);
		world.setBlock(x+10, y+2, z+9, b, ms);
		world.setBlock(x+10, y+2, z+10, b, ms);
		world.setBlock(x+10, y+2, z+11, Blocks.air);
		world.setBlock(x+10, y+2, z+12, b, ms);
		world.setBlock(x+10, y+2, z+13, Blocks.air);
		world.setBlock(x+10, y+2, z+14, b, ms);
		world.setBlock(x+10, y+2, z+16, b, ms);
		world.setBlock(x+10, y+2, z+17, b, ms);
		world.setBlock(x+10, y+2, z+18, b, ms);
		world.setBlock(x+10, y+2, z+19, Blocks.air);
		world.setBlock(x+10, y+2, z+20, b, ms);
		world.setBlock(x+10, y+2, z+21, Blocks.air);
		world.setBlock(x+10, y+2, z+22, b, ms);
		world.setBlock(x+10, y+2, z+23, Blocks.air);
		world.setBlock(x+10, y+2, z+24, b, ms);
		world.setBlock(x+10, y+3, z+0, b, ms);
		world.setBlock(x+10, y+3, z+1, Blocks.air);
		world.setBlock(x+10, y+3, z+2, Blocks.air);
		world.setBlock(x+10, y+3, z+3, Blocks.air);
		world.setBlock(x+10, y+3, z+4, Blocks.air);
		world.setBlock(x+10, y+3, z+5, Blocks.air);
		world.setBlock(x+10, y+3, z+6, Blocks.air);
		world.setBlock(x+10, y+3, z+7, Blocks.air);
		world.setBlock(x+10, y+3, z+8, Blocks.air);
		world.setBlock(x+10, y+3, z+9, Blocks.air);
		world.setBlock(x+10, y+3, z+10, Blocks.air);
		world.setBlock(x+10, y+3, z+11, Blocks.air);
		world.setBlock(x+10, y+3, z+12, Blocks.air);
		world.setBlock(x+10, y+3, z+13, Blocks.air);
		world.setBlock(x+10, y+3, z+14, Blocks.air);
		world.setBlock(x+10, y+3, z+15, Blocks.air);
		world.setBlock(x+10, y+3, z+16, Blocks.air);
		world.setBlock(x+10, y+3, z+17, Blocks.air);
		world.setBlock(x+10, y+3, z+18, Blocks.air);
		world.setBlock(x+10, y+3, z+19, Blocks.air);
		world.setBlock(x+10, y+3, z+20, Blocks.air);
		world.setBlock(x+10, y+3, z+21, Blocks.air);
		world.setBlock(x+10, y+3, z+22, Blocks.air);
		world.setBlock(x+10, y+3, z+23, Blocks.air);
		world.setBlock(x+10, y+3, z+24, b, ms);
		world.setBlock(x+10, y+4, z+0, b, ms);
		world.setBlock(x+10, y+4, z+1, Blocks.air);
		world.setBlock(x+10, y+4, z+2, Blocks.air);
		world.setBlock(x+10, y+4, z+3, Blocks.air);
		world.setBlock(x+10, y+4, z+4, Blocks.air);
		world.setBlock(x+10, y+4, z+5, Blocks.air);
		world.setBlock(x+10, y+4, z+6, Blocks.air);
		world.setBlock(x+10, y+4, z+7, Blocks.air);
		world.setBlock(x+10, y+4, z+8, Blocks.air);
		world.setBlock(x+10, y+4, z+9, Blocks.air);
		world.setBlock(x+10, y+4, z+10, Blocks.air);
		world.setBlock(x+10, y+4, z+11, Blocks.air);
		world.setBlock(x+10, y+4, z+12, Blocks.air);
		world.setBlock(x+10, y+4, z+13, Blocks.air);
		world.setBlock(x+10, y+4, z+14, Blocks.air);
		world.setBlock(x+10, y+4, z+15, Blocks.air);
		world.setBlock(x+10, y+4, z+16, Blocks.air);
		world.setBlock(x+10, y+4, z+17, Blocks.air);
		world.setBlock(x+10, y+4, z+18, Blocks.air);
		world.setBlock(x+10, y+4, z+19, Blocks.air);
		world.setBlock(x+10, y+4, z+20, Blocks.air);
		world.setBlock(x+10, y+4, z+21, Blocks.air);
		world.setBlock(x+10, y+4, z+22, Blocks.air);
		world.setBlock(x+10, y+4, z+23, Blocks.air);
		world.setBlock(x+10, y+4, z+24, b, ms);
		world.setBlock(x+10, y+5, z+0, b, ms);
		world.setBlock(x+10, y+5, z+1, Blocks.air);
		world.setBlock(x+10, y+5, z+2, Blocks.air);
		world.setBlock(x+10, y+5, z+3, Blocks.air);
		world.setBlock(x+10, y+5, z+4, Blocks.air);
		world.setBlock(x+10, y+5, z+5, Blocks.air);
		world.setBlock(x+10, y+5, z+6, Blocks.air);
		world.setBlock(x+10, y+5, z+7, Blocks.air);
		world.setBlock(x+10, y+5, z+8, Blocks.air);
		world.setBlock(x+10, y+5, z+9, Blocks.air);
		world.setBlock(x+10, y+5, z+10, Blocks.air);
		world.setBlock(x+10, y+5, z+11, Blocks.air);
		world.setBlock(x+10, y+5, z+12, Blocks.air);
		world.setBlock(x+10, y+5, z+13, Blocks.air);
		world.setBlock(x+10, y+5, z+14, Blocks.air);
		world.setBlock(x+10, y+5, z+15, Blocks.air);
		world.setBlock(x+10, y+5, z+16, Blocks.air);
		world.setBlock(x+10, y+5, z+17, Blocks.air);
		world.setBlock(x+10, y+5, z+18, Blocks.air);
		world.setBlock(x+10, y+5, z+19, Blocks.air);
		world.setBlock(x+10, y+5, z+20, Blocks.air);
		world.setBlock(x+10, y+5, z+21, Blocks.air);
		world.setBlock(x+10, y+5, z+22, Blocks.air);
		world.setBlock(x+10, y+5, z+23, Blocks.air);
		world.setBlock(x+10, y+5, z+24, b, ms);
		world.setBlock(x+11, y+0, z+0, b, ms);
		world.setBlock(x+11, y+0, z+1, b, ms);
		world.setBlock(x+11, y+0, z+2, b, ms);
		world.setBlock(x+11, y+0, z+3, b, ms);
		world.setBlock(x+11, y+0, z+4, b, ms);
		world.setBlock(x+11, y+0, z+5, b, ms);
		world.setBlock(x+11, y+0, z+6, b, ms);
		world.setBlock(x+11, y+0, z+7, b, ms);
		world.setBlock(x+11, y+0, z+8, b, ms);
		world.setBlock(x+11, y+0, z+9, b, ms);
		world.setBlock(x+11, y+0, z+10, b, ms);
		world.setBlock(x+11, y+0, z+11, b, ms);
		world.setBlock(x+11, y+0, z+12, b, ms);
		world.setBlock(x+11, y+0, z+13, b, ms);
		world.setBlock(x+11, y+0, z+14, b, ms);
		world.setBlock(x+11, y+0, z+15, b, ms);
		world.setBlock(x+11, y+0, z+16, b, ms);
		world.setBlock(x+11, y+0, z+17, b, ms);
		world.setBlock(x+11, y+0, z+18, b, ms);
		world.setBlock(x+11, y+0, z+19, b, ms);
		world.setBlock(x+11, y+0, z+20, b, ms);
		world.setBlock(x+11, y+0, z+21, b, ms);
		world.setBlock(x+11, y+0, z+22, b, ms);
		world.setBlock(x+11, y+0, z+23, b, ms);
		world.setBlock(x+11, y+0, z+24, b, ms);
		world.setBlock(x+11, y+1, z+0, b, ms);
		world.setBlock(x+11, y+1, z+1, Blocks.air);
		world.setBlock(x+11, y+1, z+2, b, ms);
		world.setBlock(x+11, y+1, z+4, b, ms);
		world.setBlock(x+11, y+1, z+5, Blocks.air);
		world.setBlock(x+11, y+1, z+6, b, ms);
		world.setBlock(x+11, y+1, z+7, Blocks.air);
		world.setBlock(x+11, y+1, z+8, Blocks.air);
		world.setBlock(x+11, y+1, z+9, Blocks.air);
		world.setBlock(x+11, y+1, z+10, b, ms);
		world.setBlock(x+11, y+1, z+11, Blocks.air);
		world.setBlock(x+11, y+1, z+12, b, ms);
		world.setBlock(x+11, y+1, z+13, Blocks.air);
		world.setBlock(x+11, y+1, z+14, b, ms);
		world.setBlock(x+11, y+1, z+15, Blocks.air);
		world.setBlock(x+11, y+1, z+16, Blocks.air);
		world.setBlock(x+11, y+1, z+17, Blocks.air);
		world.setBlock(x+11, y+1, z+18, Blocks.air);
		world.setBlock(x+11, y+1, z+19, Blocks.air);
		world.setBlock(x+11, y+1, z+21, Blocks.air);
		world.setBlock(x+11, y+1, z+22, b, ms);
		world.setBlock(x+11, y+1, z+23, Blocks.air);
		world.setBlock(x+11, y+1, z+24, b, ms);
		world.setBlock(x+11, y+2, z+0, b, ms);
		world.setBlock(x+11, y+2, z+1, Blocks.air);
		world.setBlock(x+11, y+2, z+2, b, ms);
		world.setBlock(x+11, y+2, z+3, Blocks.air);
		world.setBlock(x+11, y+2, z+4, b, ms);
		world.setBlock(x+11, y+2, z+5, Blocks.air);
		world.setBlock(x+11, y+2, z+6, b, ms);
		world.setBlock(x+11, y+2, z+7, Blocks.air);
		world.setBlock(x+11, y+2, z+8, Blocks.air);
		world.setBlock(x+11, y+2, z+9, Blocks.air);
		world.setBlock(x+11, y+2, z+10, b, ms);
		world.setBlock(x+11, y+2, z+11, Blocks.air);
		world.setBlock(x+11, y+2, z+12, b, ms);
		world.setBlock(x+11, y+2, z+13, Blocks.air);
		world.setBlock(x+11, y+2, z+14, b, ms);
		world.setBlock(x+11, y+2, z+15, Blocks.air);
		world.setBlock(x+11, y+2, z+16, Blocks.air);
		world.setBlock(x+11, y+2, z+17, Blocks.air);
		world.setBlock(x+11, y+2, z+18, Blocks.air);
		world.setBlock(x+11, y+2, z+19, Blocks.air);
		world.setBlock(x+11, y+2, z+21, Blocks.air);
		world.setBlock(x+11, y+2, z+22, b, ms);
		world.setBlock(x+11, y+2, z+23, Blocks.air);
		world.setBlock(x+11, y+2, z+24, b, ms);
		world.setBlock(x+11, y+3, z+0, b, ms);
		world.setBlock(x+11, y+3, z+1, Blocks.air);
		world.setBlock(x+11, y+3, z+2, Blocks.air);
		world.setBlock(x+11, y+3, z+3, Blocks.air);
		world.setBlock(x+11, y+3, z+4, Blocks.air);
		world.setBlock(x+11, y+3, z+5, Blocks.air);
		world.setBlock(x+11, y+3, z+6, Blocks.air);
		world.setBlock(x+11, y+3, z+7, Blocks.air);
		world.setBlock(x+11, y+3, z+8, Blocks.air);
		world.setBlock(x+11, y+3, z+9, Blocks.air);
		world.setBlock(x+11, y+3, z+10, Blocks.air);
		world.setBlock(x+11, y+3, z+11, Blocks.air);
		world.setBlock(x+11, y+3, z+12, Blocks.air);
		world.setBlock(x+11, y+3, z+13, Blocks.air);
		world.setBlock(x+11, y+3, z+14, Blocks.air);
		world.setBlock(x+11, y+3, z+15, Blocks.air);
		world.setBlock(x+11, y+3, z+16, Blocks.air);
		world.setBlock(x+11, y+3, z+17, Blocks.air);
		world.setBlock(x+11, y+3, z+18, Blocks.air);
		world.setBlock(x+11, y+3, z+19, Blocks.air);
		world.setBlock(x+11, y+3, z+20, Blocks.air);
		world.setBlock(x+11, y+3, z+21, Blocks.air);
		world.setBlock(x+11, y+3, z+22, Blocks.air);
		world.setBlock(x+11, y+3, z+23, Blocks.air);
		world.setBlock(x+11, y+3, z+24, b, ms);
		world.setBlock(x+11, y+4, z+0, b, ms);
		world.setBlock(x+11, y+4, z+1, Blocks.air);
		world.setBlock(x+11, y+4, z+2, Blocks.air);
		world.setBlock(x+11, y+4, z+3, Blocks.air);
		world.setBlock(x+11, y+4, z+4, Blocks.air);
		world.setBlock(x+11, y+4, z+5, Blocks.air);
		world.setBlock(x+11, y+4, z+6, Blocks.air);
		world.setBlock(x+11, y+4, z+7, Blocks.air);
		world.setBlock(x+11, y+4, z+8, Blocks.air);
		world.setBlock(x+11, y+4, z+9, Blocks.air);
		world.setBlock(x+11, y+4, z+10, Blocks.air);
		world.setBlock(x+11, y+4, z+11, Blocks.air);
		world.setBlock(x+11, y+4, z+12, Blocks.air);
		world.setBlock(x+11, y+4, z+13, Blocks.air);
		world.setBlock(x+11, y+4, z+14, Blocks.air);
		world.setBlock(x+11, y+4, z+15, Blocks.air);
		world.setBlock(x+11, y+4, z+16, Blocks.air);
		world.setBlock(x+11, y+4, z+17, Blocks.air);
		world.setBlock(x+11, y+4, z+18, Blocks.air);
		world.setBlock(x+11, y+4, z+19, Blocks.air);
		world.setBlock(x+11, y+4, z+20, Blocks.air);
		world.setBlock(x+11, y+4, z+21, Blocks.air);
		world.setBlock(x+11, y+4, z+22, Blocks.air);
		world.setBlock(x+11, y+4, z+23, Blocks.air);
		world.setBlock(x+11, y+4, z+24, b, ms);
		world.setBlock(x+11, y+5, z+0, b, ms);
		world.setBlock(x+11, y+5, z+1, Blocks.air);
		world.setBlock(x+11, y+5, z+2, Blocks.air);
		world.setBlock(x+11, y+5, z+3, Blocks.air);
		world.setBlock(x+11, y+5, z+4, Blocks.air);
		world.setBlock(x+11, y+5, z+5, Blocks.air);
		world.setBlock(x+11, y+5, z+6, Blocks.air);
		world.setBlock(x+11, y+5, z+7, Blocks.air);
		world.setBlock(x+11, y+5, z+8, Blocks.air);
		world.setBlock(x+11, y+5, z+9, Blocks.air);
		world.setBlock(x+11, y+5, z+10, Blocks.air);
		world.setBlock(x+11, y+5, z+11, Blocks.air);
		world.setBlock(x+11, y+5, z+12, Blocks.air);
		world.setBlock(x+11, y+5, z+13, Blocks.air);
		world.setBlock(x+11, y+5, z+14, Blocks.air);
		world.setBlock(x+11, y+5, z+15, Blocks.air);
		world.setBlock(x+11, y+5, z+16, Blocks.air);
		world.setBlock(x+11, y+5, z+17, Blocks.air);
		world.setBlock(x+11, y+5, z+18, Blocks.air);
		world.setBlock(x+11, y+5, z+19, Blocks.air);
		world.setBlock(x+11, y+5, z+20, Blocks.air);
		world.setBlock(x+11, y+5, z+21, Blocks.air);
		world.setBlock(x+11, y+5, z+22, Blocks.air);
		world.setBlock(x+11, y+5, z+23, Blocks.air);
		world.setBlock(x+11, y+5, z+24, b, ms);
		world.setBlock(x+12, y+0, z+0, b, ms);
		world.setBlock(x+12, y+0, z+1, b, ms);
		world.setBlock(x+12, y+0, z+2, b, ms);
		world.setBlock(x+12, y+0, z+3, b, ms);
		world.setBlock(x+12, y+0, z+4, b, ms);
		world.setBlock(x+12, y+0, z+5, b, ms);
		world.setBlock(x+12, y+0, z+6, b, ms);
		world.setBlock(x+12, y+0, z+7, b, ms);
		world.setBlock(x+12, y+0, z+8, b, ms);
		world.setBlock(x+12, y+0, z+9, b, ms);
		world.setBlock(x+12, y+0, z+10, b, ms);
		world.setBlock(x+12, y+0, z+11, b, ms);
		world.setBlock(x+12, y+0, z+12, b, ms);
		world.setBlock(x+12, y+0, z+13, b, ms);
		world.setBlock(x+12, y+0, z+14, b, ms);
		world.setBlock(x+12, y+0, z+15, b, ms);
		world.setBlock(x+12, y+0, z+16, b, ms);
		world.setBlock(x+12, y+0, z+17, b, ms);
		world.setBlock(x+12, y+0, z+18, b, ms);
		world.setBlock(x+12, y+0, z+19, b, ms);
		world.setBlock(x+12, y+0, z+20, b, ms);
		world.setBlock(x+12, y+0, z+21, b, ms);
		world.setBlock(x+12, y+0, z+22, b, ms);
		world.setBlock(x+12, y+0, z+23, b, ms);
		world.setBlock(x+12, y+0, z+24, b, ms);
		world.setBlock(x+12, y+1, z+0, b, ms);
		world.setBlock(x+12, y+1, z+1, Blocks.air);
		world.setBlock(x+12, y+1, z+2, b, ms);
		world.setBlock(x+12, y+1, z+3, Blocks.air);
		world.setBlock(x+12, y+1, z+4, b, ms);
		world.setBlock(x+12, y+1, z+5, Blocks.air);
		world.setBlock(x+12, y+1, z+6, b, ms);
		world.setBlock(x+12, y+1, z+7, b, ms);
		world.setBlock(x+12, y+1, z+8, b, ms);
		world.setBlock(x+12, y+1, z+9, Blocks.air);
		world.setBlock(x+12, y+1, z+10, b, ms);
		world.setBlock(x+12, y+1, z+11, Blocks.air);
		world.setBlock(x+12, y+1, z+12, b, ms);
		world.setBlock(x+12, y+1, z+13, Blocks.air);
		world.setBlock(x+12, y+1, z+14, b, ms);
		world.setBlock(x+12, y+1, z+15, Blocks.air);
		world.setBlock(x+12, y+1, z+16, b, ms);
		world.setBlock(x+12, y+1, z+17, b, ms);
		world.setBlock(x+12, y+1, z+18, b, ms);
		world.setBlock(x+12, y+1, z+19, b, ms);
		world.setBlock(x+12, y+1, z+20, b, ms);
		world.setBlock(x+12, y+1, z+21, Blocks.air);
		world.setBlock(x+12, y+1, z+22, b, ms);
		world.setBlock(x+12, y+1, z+23, Blocks.air);
		world.setBlock(x+12, y+1, z+24, b, ms);
		world.setBlock(x+12, y+2, z+0, b, ms);
		world.setBlock(x+12, y+2, z+1, Blocks.air);
		world.setBlock(x+12, y+2, z+2, b, ms);
		world.setBlock(x+12, y+2, z+3, Blocks.air);
		world.setBlock(x+12, y+2, z+4, b, ms);
		world.setBlock(x+12, y+2, z+5, Blocks.air);
		world.setBlock(x+12, y+2, z+6, b, ms);
		world.setBlock(x+12, y+2, z+7, b, ms);
		world.setBlock(x+12, y+2, z+8, b, ms);
		world.setBlock(x+12, y+2, z+9, Blocks.air);
		world.setBlock(x+12, y+2, z+10, b, ms);
		world.setBlock(x+12, y+2, z+11, Blocks.air);
		world.setBlock(x+12, y+2, z+12, b, ms);
		world.setBlock(x+12, y+2, z+13, Blocks.air);
		world.setBlock(x+12, y+2, z+14, b, ms);
		world.setBlock(x+12, y+2, z+15, Blocks.air);
		world.setBlock(x+12, y+2, z+16, b, ms);
		world.setBlock(x+12, y+2, z+17, b, ms);
		world.setBlock(x+12, y+2, z+18, b, ms);
		world.setBlock(x+12, y+2, z+19, b, ms);
		world.setBlock(x+12, y+2, z+20, b, ms);
		world.setBlock(x+12, y+2, z+21, Blocks.air);
		world.setBlock(x+12, y+2, z+22, b, ms);
		world.setBlock(x+12, y+2, z+23, Blocks.air);
		world.setBlock(x+12, y+2, z+24, b, ms);
		world.setBlock(x+12, y+3, z+0, b, ms);
		world.setBlock(x+12, y+3, z+1, Blocks.air);
		world.setBlock(x+12, y+3, z+2, Blocks.air);
		world.setBlock(x+12, y+3, z+3, Blocks.air);
		world.setBlock(x+12, y+3, z+4, Blocks.air);
		world.setBlock(x+12, y+3, z+5, Blocks.air);
		world.setBlock(x+12, y+3, z+6, Blocks.air);
		world.setBlock(x+12, y+3, z+7, Blocks.air);
		world.setBlock(x+12, y+3, z+8, Blocks.air);
		world.setBlock(x+12, y+3, z+9, Blocks.air);
		world.setBlock(x+12, y+3, z+10, Blocks.air);
		world.setBlock(x+12, y+3, z+11, Blocks.air);
		world.setBlock(x+12, y+3, z+12, Blocks.air);
		world.setBlock(x+12, y+3, z+13, Blocks.air);
		world.setBlock(x+12, y+3, z+14, Blocks.air);
		world.setBlock(x+12, y+3, z+15, Blocks.air);
		world.setBlock(x+12, y+3, z+16, Blocks.air);
		world.setBlock(x+12, y+3, z+17, Blocks.air);
		world.setBlock(x+12, y+3, z+18, Blocks.air);
		world.setBlock(x+12, y+3, z+19, Blocks.air);
		world.setBlock(x+12, y+3, z+20, Blocks.air);
		world.setBlock(x+12, y+3, z+21, Blocks.air);
		world.setBlock(x+12, y+3, z+22, Blocks.air);
		world.setBlock(x+12, y+3, z+23, Blocks.air);
		world.setBlock(x+12, y+3, z+24, b, ms);
		world.setBlock(x+12, y+4, z+0, b, ms);
		world.setBlock(x+12, y+4, z+1, Blocks.air);
		world.setBlock(x+12, y+4, z+2, Blocks.air);
		world.setBlock(x+12, y+4, z+3, Blocks.air);
		world.setBlock(x+12, y+4, z+4, Blocks.air);
		world.setBlock(x+12, y+4, z+5, Blocks.air);
		world.setBlock(x+12, y+4, z+6, Blocks.air);
		world.setBlock(x+12, y+4, z+7, Blocks.air);
		world.setBlock(x+12, y+4, z+8, Blocks.air);
		world.setBlock(x+12, y+4, z+9, Blocks.air);
		world.setBlock(x+12, y+4, z+10, Blocks.air);
		world.setBlock(x+12, y+4, z+11, Blocks.air);
		world.setBlock(x+12, y+4, z+12, Blocks.air);
		world.setBlock(x+12, y+4, z+13, Blocks.air);
		world.setBlock(x+12, y+4, z+14, Blocks.air);
		world.setBlock(x+12, y+4, z+15, Blocks.air);
		world.setBlock(x+12, y+4, z+16, Blocks.air);
		world.setBlock(x+12, y+4, z+17, Blocks.air);
		world.setBlock(x+12, y+4, z+18, Blocks.air);
		world.setBlock(x+12, y+4, z+19, Blocks.air);
		world.setBlock(x+12, y+4, z+20, Blocks.air);
		world.setBlock(x+12, y+4, z+21, Blocks.air);
		world.setBlock(x+12, y+4, z+22, Blocks.air);
		world.setBlock(x+12, y+4, z+23, Blocks.air);
		world.setBlock(x+12, y+4, z+24, b, ms);
		world.setBlock(x+12, y+5, z+0, b, ms);
		world.setBlock(x+12, y+5, z+1, Blocks.air);
		world.setBlock(x+12, y+5, z+2, Blocks.air);
		world.setBlock(x+12, y+5, z+3, Blocks.air);
		world.setBlock(x+12, y+5, z+4, Blocks.air);
		world.setBlock(x+12, y+5, z+5, Blocks.air);
		world.setBlock(x+12, y+5, z+6, Blocks.air);
		world.setBlock(x+12, y+5, z+7, Blocks.air);
		world.setBlock(x+12, y+5, z+8, Blocks.air);
		world.setBlock(x+12, y+5, z+9, Blocks.air);
		world.setBlock(x+12, y+5, z+10, Blocks.air);
		world.setBlock(x+12, y+5, z+11, Blocks.air);
		world.setBlock(x+12, y+5, z+12, Blocks.air);
		world.setBlock(x+12, y+5, z+13, Blocks.air);
		world.setBlock(x+12, y+5, z+14, Blocks.air);
		world.setBlock(x+12, y+5, z+15, Blocks.air);
		world.setBlock(x+12, y+5, z+16, Blocks.air);
		world.setBlock(x+12, y+5, z+17, Blocks.air);
		world.setBlock(x+12, y+5, z+18, Blocks.air);
		world.setBlock(x+12, y+5, z+19, Blocks.air);
		world.setBlock(x+12, y+5, z+20, Blocks.air);
		world.setBlock(x+12, y+5, z+21, Blocks.air);
		world.setBlock(x+12, y+5, z+22, Blocks.air);
		world.setBlock(x+12, y+5, z+23, Blocks.air);
		world.setBlock(x+12, y+5, z+24, b, ms);
		world.setBlock(x+13, y+0, z+0, b, ms);
		world.setBlock(x+13, y+0, z+1, b, ms);
		world.setBlock(x+13, y+0, z+2, b, ms);
		world.setBlock(x+13, y+0, z+3, b, ms);
		world.setBlock(x+13, y+0, z+4, b, ms);
		world.setBlock(x+13, y+0, z+5, b, ms);
		world.setBlock(x+13, y+0, z+6, b, ms);
		world.setBlock(x+13, y+0, z+7, b, ms);
		world.setBlock(x+13, y+0, z+8, b, ms);
		world.setBlock(x+13, y+0, z+9, b, ms);
		world.setBlock(x+13, y+0, z+10, b, ms);
		world.setBlock(x+13, y+0, z+11, b, ms);
		world.setBlock(x+13, y+0, z+12, b, ms);
		world.setBlock(x+13, y+0, z+13, b, ms);
		world.setBlock(x+13, y+0, z+14, b, ms);
		world.setBlock(x+13, y+0, z+15, b, ms);
		world.setBlock(x+13, y+0, z+16, b, ms);
		world.setBlock(x+13, y+0, z+17, b, ms);
		world.setBlock(x+13, y+0, z+18, b, ms);
		world.setBlock(x+13, y+0, z+19, b, ms);
		world.setBlock(x+13, y+0, z+20, b, ms);
		world.setBlock(x+13, y+0, z+21, b, ms);
		world.setBlock(x+13, y+0, z+22, b, ms);
		world.setBlock(x+13, y+0, z+23, b, ms);
		world.setBlock(x+13, y+0, z+24, b, ms);
		world.setBlock(x+13, y+1, z+0, b, ms);
		world.setBlock(x+13, y+1, z+1, Blocks.air);
		world.setBlock(x+13, y+1, z+2, b, ms);
		world.setBlock(x+13, y+1, z+3, Blocks.air);
		world.setBlock(x+13, y+1, z+4, b, ms);
		world.setBlock(x+13, y+1, z+5, Blocks.air);
		world.setBlock(x+13, y+1, z+6, Blocks.air);
		world.setBlock(x+13, y+1, z+7, Blocks.air);
		world.setBlock(x+13, y+1, z+8, b, ms);
		world.setBlock(x+13, y+1, z+10, b, ms);
		world.setBlock(x+13, y+1, z+11, Blocks.air);
		world.setBlock(x+13, y+1, z+12, b, ms);
		world.setBlock(x+13, y+1, z+13, Blocks.air);
		world.setBlock(x+13, y+1, z+14, b, ms);
		world.setBlock(x+13, y+1, z+15, Blocks.air);
		world.setBlock(x+13, y+1, z+16, b, ms);
		world.setBlock(x+13, y+1, z+17, Blocks.air);
		world.setBlock(x+13, y+1, z+18, Blocks.air);
		world.setBlock(x+13, y+1, z+19, Blocks.air);
		world.setBlock(x+13, y+1, z+20, b, ms);
		world.setBlock(x+13, y+1, z+21, Blocks.air);
		world.setBlock(x+13, y+1, z+22, b, ms);
		world.setBlock(x+13, y+1, z+23, Blocks.air);
		world.setBlock(x+13, y+2, z+0, b, ms);
		world.setBlock(x+13, y+2, z+1, Blocks.air);
		world.setBlock(x+13, y+2, z+2, b, ms);
		world.setBlock(x+13, y+2, z+3, Blocks.air);
		world.setBlock(x+13, y+2, z+4, b, ms);
		world.setBlock(x+13, y+2, z+5, Blocks.air);
		world.setBlock(x+13, y+2, z+6, Blocks.air);
		world.setBlock(x+13, y+2, z+7, Blocks.air);
		world.setBlock(x+13, y+2, z+8, b, ms);
		world.setBlock(x+13, y+2, z+9, Blocks.air);
		world.setBlock(x+13, y+2, z+10, b, ms);
		world.setBlock(x+13, y+2, z+11, Blocks.air);
		world.setBlock(x+13, y+2, z+12, b, ms);
		world.setBlock(x+13, y+2, z+13, Blocks.air);
		world.setBlock(x+13, y+2, z+14, b, ms);
		world.setBlock(x+13, y+2, z+15, Blocks.air);
		world.setBlock(x+13, y+2, z+16, b, ms);
		world.setBlock(x+13, y+2, z+17, Blocks.air);
		world.setBlock(x+13, y+2, z+18, Blocks.air);
		world.setBlock(x+13, y+2, z+19, Blocks.air);
		world.setBlock(x+13, y+2, z+20, b, ms);
		world.setBlock(x+13, y+2, z+21, Blocks.air);
		world.setBlock(x+13, y+2, z+22, b, ms);
		world.setBlock(x+13, y+2, z+23, Blocks.air);
		world.setBlock(x+13, y+2, z+24, Blocks.air);
		world.setBlock(x+13, y+3, z+0, b, ms);
		world.setBlock(x+13, y+3, z+1, Blocks.air);
		world.setBlock(x+13, y+3, z+2, Blocks.air);
		world.setBlock(x+13, y+3, z+3, Blocks.air);
		world.setBlock(x+13, y+3, z+4, Blocks.air);
		world.setBlock(x+13, y+3, z+5, Blocks.air);
		world.setBlock(x+13, y+3, z+6, Blocks.air);
		world.setBlock(x+13, y+3, z+7, Blocks.air);
		world.setBlock(x+13, y+3, z+8, Blocks.air);
		world.setBlock(x+13, y+3, z+9, Blocks.air);
		world.setBlock(x+13, y+3, z+10, Blocks.air);
		world.setBlock(x+13, y+3, z+11, Blocks.air);
		world.setBlock(x+13, y+3, z+12, Blocks.air);
		world.setBlock(x+13, y+3, z+13, Blocks.air);
		world.setBlock(x+13, y+3, z+14, Blocks.air);
		world.setBlock(x+13, y+3, z+15, Blocks.air);
		world.setBlock(x+13, y+3, z+16, Blocks.air);
		world.setBlock(x+13, y+3, z+17, Blocks.air);
		world.setBlock(x+13, y+3, z+18, Blocks.air);
		world.setBlock(x+13, y+3, z+19, Blocks.air);
		world.setBlock(x+13, y+3, z+20, Blocks.air);
		world.setBlock(x+13, y+3, z+21, Blocks.air);
		world.setBlock(x+13, y+3, z+22, Blocks.air);
		world.setBlock(x+13, y+3, z+23, Blocks.air);
		world.setBlock(x+13, y+3, z+24, b, ms);
		world.setBlock(x+13, y+4, z+0, b, ms);
		world.setBlock(x+13, y+4, z+1, Blocks.air);
		world.setBlock(x+13, y+4, z+2, Blocks.air);
		world.setBlock(x+13, y+4, z+3, Blocks.air);
		world.setBlock(x+13, y+4, z+4, Blocks.air);
		world.setBlock(x+13, y+4, z+5, Blocks.air);
		world.setBlock(x+13, y+4, z+6, Blocks.air);
		world.setBlock(x+13, y+4, z+7, Blocks.air);
		world.setBlock(x+13, y+4, z+8, Blocks.air);
		world.setBlock(x+13, y+4, z+9, Blocks.air);
		world.setBlock(x+13, y+4, z+10, Blocks.air);
		world.setBlock(x+13, y+4, z+11, Blocks.air);
		world.setBlock(x+13, y+4, z+12, Blocks.air);
		world.setBlock(x+13, y+4, z+13, Blocks.air);
		world.setBlock(x+13, y+4, z+14, Blocks.air);
		world.setBlock(x+13, y+4, z+15, Blocks.air);
		world.setBlock(x+13, y+4, z+16, Blocks.air);
		world.setBlock(x+13, y+4, z+17, Blocks.air);
		world.setBlock(x+13, y+4, z+18, Blocks.air);
		world.setBlock(x+13, y+4, z+19, Blocks.air);
		world.setBlock(x+13, y+4, z+20, Blocks.air);
		world.setBlock(x+13, y+4, z+21, Blocks.air);
		world.setBlock(x+13, y+4, z+22, Blocks.air);
		world.setBlock(x+13, y+4, z+23, Blocks.air);
		world.setBlock(x+13, y+4, z+24, b, ms);
		world.setBlock(x+13, y+5, z+0, b, ms);
		world.setBlock(x+13, y+5, z+1, Blocks.air);
		world.setBlock(x+13, y+5, z+2, Blocks.air);
		world.setBlock(x+13, y+5, z+3, Blocks.air);
		world.setBlock(x+13, y+5, z+4, Blocks.air);
		world.setBlock(x+13, y+5, z+5, Blocks.air);
		world.setBlock(x+13, y+5, z+6, Blocks.air);
		world.setBlock(x+13, y+5, z+7, Blocks.air);
		world.setBlock(x+13, y+5, z+8, Blocks.air);
		world.setBlock(x+13, y+5, z+9, Blocks.air);
		world.setBlock(x+13, y+5, z+10, Blocks.air);
		world.setBlock(x+13, y+5, z+11, Blocks.air);
		world.setBlock(x+13, y+5, z+12, Blocks.air);
		world.setBlock(x+13, y+5, z+13, Blocks.air);
		world.setBlock(x+13, y+5, z+14, Blocks.air);
		world.setBlock(x+13, y+5, z+15, Blocks.air);
		world.setBlock(x+13, y+5, z+16, Blocks.air);
		world.setBlock(x+13, y+5, z+17, Blocks.air);
		world.setBlock(x+13, y+5, z+18, Blocks.air);
		world.setBlock(x+13, y+5, z+19, Blocks.air);
		world.setBlock(x+13, y+5, z+20, Blocks.air);
		world.setBlock(x+13, y+5, z+21, Blocks.air);
		world.setBlock(x+13, y+5, z+22, Blocks.air);
		world.setBlock(x+13, y+5, z+23, Blocks.air);
		world.setBlock(x+13, y+5, z+24, b, ms);
		world.setBlock(x+14, y+0, z+0, b, ms);
		world.setBlock(x+14, y+0, z+1, b, ms);
		world.setBlock(x+14, y+0, z+2, b, ms);
		world.setBlock(x+14, y+0, z+3, b, ms);
		world.setBlock(x+14, y+0, z+4, b, ms);
		world.setBlock(x+14, y+0, z+5, b, ms);
		world.setBlock(x+14, y+0, z+6, b, ms);
		world.setBlock(x+14, y+0, z+7, b, ms);
		world.setBlock(x+14, y+0, z+8, b, ms);
		world.setBlock(x+14, y+0, z+9, b, ms);
		world.setBlock(x+14, y+0, z+10, b, ms);
		world.setBlock(x+14, y+0, z+11, b, ms);
		world.setBlock(x+14, y+0, z+12, b, ms);
		world.setBlock(x+14, y+0, z+13, b, ms);
		world.setBlock(x+14, y+0, z+14, b, ms);
		world.setBlock(x+14, y+0, z+15, b, ms);
		world.setBlock(x+14, y+0, z+16, b, ms);
		world.setBlock(x+14, y+0, z+17, b, ms);
		world.setBlock(x+14, y+0, z+18, b, ms);
		world.setBlock(x+14, y+0, z+19, b, ms);
		world.setBlock(x+14, y+0, z+20, b, ms);
		world.setBlock(x+14, y+0, z+21, b, ms);
		world.setBlock(x+14, y+0, z+22, b, ms);
		world.setBlock(x+14, y+0, z+23, b, ms);
		world.setBlock(x+14, y+0, z+24, b, ms);
		world.setBlock(x+14, y+1, z+0, b, ms);
		world.setBlock(x+14, y+1, z+1, Blocks.air);
		world.setBlock(x+14, y+1, z+2, b, ms);
		world.setBlock(x+14, y+1, z+3, Blocks.air);
		world.setBlock(x+14, y+1, z+4, b, ms);
		world.setBlock(x+14, y+1, z+5, b, ms);
		world.setBlock(x+14, y+1, z+6, b, ms);
		world.setBlock(x+14, y+1, z+7, Blocks.air);
		world.setBlock(x+14, y+1, z+8, b, ms);
		world.setBlock(x+14, y+1, z+9, b, ms);
		world.setBlock(x+14, y+1, z+10, b, ms);
		world.setBlock(x+14, y+1, z+11, Blocks.air);
		world.setBlock(x+14, y+1, z+12, b, ms);
		world.setBlock(x+14, y+1, z+13, Blocks.air);
		world.setBlock(x+14, y+1, z+14, b, ms);
		world.setBlock(x+14, y+1, z+15, Blocks.air);
		world.setBlock(x+14, y+1, z+16, b, ms);
		world.setBlock(x+14, y+1, z+17, Blocks.air);
		world.setBlock(x+14, y+1, z+18, b, ms);
		world.setBlock(x+14, y+1, z+19, Blocks.air);
		world.setBlock(x+14, y+1, z+20, b, ms);
		world.setBlock(x+14, y+1, z+21, Blocks.air);
		world.setBlock(x+14, y+1, z+22, b, ms);
		world.setBlock(x+14, y+1, z+23, b, ms);
		world.setBlock(x+14, y+1, z+24, b, ms);
		world.setBlock(x+14, y+2, z+0, b, ms);
		world.setBlock(x+14, y+2, z+1, Blocks.air);
		world.setBlock(x+14, y+2, z+2, b, ms);
		world.setBlock(x+14, y+2, z+3, Blocks.air);
		world.setBlock(x+14, y+2, z+4, b, ms);
		world.setBlock(x+14, y+2, z+5, b, ms);
		world.setBlock(x+14, y+2, z+6, b, ms);
		world.setBlock(x+14, y+2, z+7, Blocks.air);
		world.setBlock(x+14, y+2, z+8, b, ms);
		world.setBlock(x+14, y+2, z+9, b, ms);
		world.setBlock(x+14, y+2, z+10, b, ms);
		world.setBlock(x+14, y+2, z+11, Blocks.air);
		world.setBlock(x+14, y+2, z+12, b, ms);
		world.setBlock(x+14, y+2, z+13, Blocks.air);
		world.setBlock(x+14, y+2, z+14, b, ms);
		world.setBlock(x+14, y+2, z+15, Blocks.air);
		world.setBlock(x+14, y+2, z+16, b, ms);
		world.setBlock(x+14, y+2, z+17, Blocks.air);
		world.setBlock(x+14, y+2, z+18, b, ms);
		world.setBlock(x+14, y+2, z+19, Blocks.air);
		world.setBlock(x+14, y+2, z+20, b, ms);
		world.setBlock(x+14, y+2, z+21, Blocks.air);
		world.setBlock(x+14, y+2, z+22, b, ms);
		world.setBlock(x+14, y+2, z+23, b, ms);
		world.setBlock(x+14, y+2, z+24, b, ms);
		world.setBlock(x+14, y+3, z+0, b, ms);
		world.setBlock(x+14, y+3, z+1, Blocks.air);
		world.setBlock(x+14, y+3, z+2, Blocks.air);
		world.setBlock(x+14, y+3, z+3, Blocks.air);
		world.setBlock(x+14, y+3, z+4, Blocks.air);
		world.setBlock(x+14, y+3, z+5, Blocks.air);
		world.setBlock(x+14, y+3, z+6, Blocks.air);
		world.setBlock(x+14, y+3, z+7, Blocks.air);
		world.setBlock(x+14, y+3, z+8, Blocks.air);
		world.setBlock(x+14, y+3, z+9, Blocks.air);
		world.setBlock(x+14, y+3, z+10, Blocks.air);
		world.setBlock(x+14, y+3, z+11, Blocks.air);
		world.setBlock(x+14, y+3, z+12, Blocks.air);
		world.setBlock(x+14, y+3, z+13, Blocks.air);
		world.setBlock(x+14, y+3, z+14, Blocks.air);
		world.setBlock(x+14, y+3, z+15, Blocks.air);
		world.setBlock(x+14, y+3, z+16, Blocks.air);
		world.setBlock(x+14, y+3, z+17, Blocks.air);
		world.setBlock(x+14, y+3, z+18, Blocks.air);
		world.setBlock(x+14, y+3, z+19, Blocks.air);
		world.setBlock(x+14, y+3, z+20, Blocks.air);
		world.setBlock(x+14, y+3, z+21, Blocks.air);
		world.setBlock(x+14, y+3, z+22, Blocks.air);
		world.setBlock(x+14, y+3, z+23, Blocks.air);
		world.setBlock(x+14, y+3, z+24, b, ms);
		world.setBlock(x+14, y+4, z+0, b, ms);
		world.setBlock(x+14, y+4, z+1, Blocks.air);
		world.setBlock(x+14, y+4, z+2, Blocks.air);
		world.setBlock(x+14, y+4, z+3, Blocks.air);
		world.setBlock(x+14, y+4, z+4, Blocks.air);
		world.setBlock(x+14, y+4, z+5, Blocks.air);
		world.setBlock(x+14, y+4, z+6, Blocks.air);
		world.setBlock(x+14, y+4, z+7, Blocks.air);
		world.setBlock(x+14, y+4, z+8, Blocks.air);
		world.setBlock(x+14, y+4, z+9, Blocks.air);
		world.setBlock(x+14, y+4, z+10, Blocks.air);
		world.setBlock(x+14, y+4, z+11, Blocks.air);
		world.setBlock(x+14, y+4, z+12, Blocks.air);
		world.setBlock(x+14, y+4, z+13, Blocks.air);
		world.setBlock(x+14, y+4, z+14, Blocks.air);
		world.setBlock(x+14, y+4, z+15, Blocks.air);
		world.setBlock(x+14, y+4, z+16, Blocks.air);
