/*******************************************************************************
 * @author Reika Kalseki
 * 
 * Copyright 2016
 * 
 * All rights reserved.
 * Distribution of the software in any form is only allowed with
 * explicit, prior permission from the owner.
 ******************************************************************************/
package Reika.ChromatiCraft.World.Dimension.Structure.ShiftMaze;


import net.minecraft.block.Block;
import net.minecraft.init.Blocks;
import Reika.ChromatiCraft.Base.DimensionStructureGenerator;
import Reika.ChromatiCraft.Base.StructurePiece;
import Reika.ChromatiCraft.Block.Worldgen.BlockStructureShield.BlockType;
import Reika.ChromatiCraft.Registry.ChromaBlocks;
import Reika.DragonAPI.Instantiable.Worldgen.ChunkSplicedGenerationCache;


public class ShiftMazeLoot extends StructurePiece {

	public ShiftMazeLoot(DimensionStructureGenerator s) {
		super(s);
	}

	@Override
	public void generate(ChunkSplicedGenerationCache world, int x, int y, int z) {

		Block b = ChromaBlocks.STRUCTSHIELD.getBlockInstance();
		int ms = BlockType.STONE.metadata;
		int ml = BlockType.LIGHT.metadata;
		int mg = BlockType.GLASS.metadata;

		world.setBlock(x+0, y+0, z+2, b, ms);
		world.setBlock(x+0, y+0, z+3, b, ms);
		world.setBlock(x+0, y+0, z+4, b, ms);
		world.setBlock(x+0, y+0, z+5, b, ms);
		world.setBlock(x+0, y+0, z+6, b, ms);
		world.setBlock(x+0, y+1, z+2, b, ms);
		world.setBlock(x+0, y+1, z+6, b, ms);
		world.setBlock(x+0, y+2, z+2, b, ms);
		world.setBlock(x+0, y+2, z+6, b, ms);
		world.setBlock(x+0, y+3, z+2, b, ms);
		world.setBlock(x+0, y+3, z+6, b, ms);
		world.setBlock(x+0, y+4, z+2, b, ms);
		world.setBlock(x+0, y+4, z+3, b, ms);
		world.setBlock(x+0, y+4, z+4, b, ms);
		world.setBlock(x+0, y+4, z+5, b, ms);
		world.setBlock(x+0, y+4, z+6, b, ms);
		world.setBlock(x+1, y+0, z+1, b, ms);
		world.setBlock(x+1, y+0, z+2, b, ms);
		world.setBlock(x+1, y+0, z+3, b, ms);
		world.setBlock(x+1, y+0, z+4, b, ms);
		world.setBlock(x+1, y+0, z+5, b, ms);
		world.setBlock(x+1, y+0, z+6, b, ms);
		world.setBlock(x+1, y+0, z+7, b, ms);
		world.setBlock(x+1, y+1, z+1, b, ms);
		world.setBlock(x+1, y+1, z+2, b, ms);
		world.setBlock(x+1, y+1, z+6, b, ms);
		world.setBlock(x+1, y+1, z+7, b, ms);
		world.setBlock(x+1, y+2, z+1, b, ms);
		world.setBlock(x+1, y+2, z+2, b, ms);
		world.setBlock(x+1, y+2, z+6, b, ms);
		world.setBlock(x+1, y+2, z+7, b, ms);
		world.setBlock(x+1, y+3, z+1, b, ms);
		world.setBlock(x+1, y+3, z+2, b, ms);
		world.setBlock(x+1, y+3, z+6, b, ms);
		world.setBlock(x+1, y+3, z+7, b, ms);
		world.setBlock(x+1, y+4, z+1, b, ms);
		world.setBlock(x+1, y+4, z+2, b, ms);
		world.setBlock(x+1, y+4, z+3, b, ms);
		world.setBlock(x+1, y+4, z+4, b, ms);
		world.setBlock(x+1, y+4, z+5, b, ms);
		world.setBlock(x+1, y+4, z+6, b, ms);
		world.setBlock(x+1, y+4, z+7, b, ms);
		world.setBlock(x+1, y+5, z+3, b, ms);
		world.setBlock(x+1, y+5, z+4, b, ms);
		world.setBlock(x+1, y+5, z+5, b, ms);
		world.setBlock(x+2, y+0, z+0, b, ms);
		world.setBlock(x+2, y+0, z+1, b, ms);
		world.setBlock(x+2, y+0, z+2, b, ms);
		world.setBlock(x+2, y+0, z+3, b, ms);
		world.setBlock(x+2, y+0, z+4, b, ml);
		world.setBlock(x+2, y+0, z+5, b, ms);
		world.setBlock(x+2, y+0, z+6, b, ms);
		world.setBlock(x+2, y+0, z+7, b, ms);
		world.setBlock(x+2, y+0, z+8, b, ms);
		world.setBlock(x+2, y+1, z+0, b, ms);
		world.setBlock(x+2, y+1, z+1, b, ms);
		world.setBlock(x+2, y+1, z+7, b, ms);
		world.setBlock(x+2, y+1, z+8, b, ms);
		world.setBlock(x+2, y+2, z+0, b, ms);
		world.setBlock(x+2, y+2, z+1, b, ms);
		world.setBlock(x+2, y+2, z+7, b, ms);
		world.setBlock(x+2, y+2, z+8, b, ms);
		world.setBlock(x+2, y+3, z+0, b, ms);
		world.setBlock(x+2, y+3, z+1, b, ms);
		world.setBlock(x+2, y+3, z+7, b, ms);
		world.setBlock(x+2, y+3, z+8, b, ms);
		world.setBlock(x+2, y+4, z+0, b, ms);
		world.setBlock(x+2, y+4, z+1, b, ms);
		world.setBlock(x+2, y+4, z+2, b, ms);
		world.setBlock(x+2, y+4, z+6, b, ms);
		world.setBlock(x+2, y+4, z+7, b, ms);
		world.setBlock(x+2, y+4, z+8, b, ms);
		world.setBlock(x+2, y+5, z+2, b, ms);
		world.setBlock(x+2, y+5, z+3, b, ms);
		world.setBlock(x+2, y+5, z+4, b, ms);
		world.setBlock(x+2, y+5, z+5, b, ms);
		world.setBlock(x+2, y+5, z+6, b, ms);
		world.setBlock(x+3, y+0, z+0, b, ms);
		world.setBlock(x+3, y+0, z+1, b, ms);
		world.setBlock(x+3, y+0, z+2, b, ms);
		world.setBlock(x+3, y+0, z+3, b, ms);
		world.setBlock(x+3, y+0, z+4, b, ms);
		world.setBlock(x+3, y+0, z+5, b, ms);
		world.setBlock(x+3, y+0, z+6, b, ms);
		world.setBlock(x+3, y+0, z+7, b, ms);
		world.setBlock(x+3, y+0, z+8, b, ms);
		world.setBlock(x+3, y+4, z+0, b, ms);
		world.setBlock(x+3, y+4, z+1, b, ms);
		world.setBlock(x+3, y+4, z+7, b, ms);
		world.setBlock(x+3, y+4, z+8, b, ms);
		world.setBlock(x+3, y+5, z+1, b, ms);
		world.setBlock(x+3, y+5, z+2, b, ms);
		world.setBlock(x+3, y+5, z+3, b, ms);
		world.setBlock(x+3, y+5, z+4, b, ms);
		world.setBlock(x+3, y+5, z+5, b, ms);
		world.setBlock(x+3, y+5, z+6, b, ms);
		world.setBlock(x+3, y+5, z+7, b, ms);
		world.setBlock(x+4, y+0, z+0, b, ms);
		world.setBlock(x+4, y+0, z+1, b, ms);
		world.setBlock(x+4, y+0, z+2, b, ms);
		world.setBlock(x+4, y+0, z+3, b, ms);
		world.setBlock(x+4, y+0, z+4, b, ms);
		world.setBlock(x+4, y+0, z+5, b, ms);
		world.setBlock(x+4, y+0, z+6, b, ms);
		world.setBlock(x+4, y+0, z+7, b, ms);
		world.setBlock(x+4, y+0, z+8, b, ms);
		world.setBlock(x+4, y+4, z+0, b, ms);
		world.setBlock(x+4, y+4, z+1, b, ms);
		world.setBlock(x+4, y+4, z+7, b, ms);
		world.setBlock(x+4, y+4, z+8, b, ms);
		world.setBlock(x+4, y+5, z+1, b, ms);
		world.setBlock(x+4, y+5, z+2, b, ms);
		world.setBlock(x+4, y+5, z+3, b, ms);
		world.setBlock(x+4, y+5, z+4, b, ms);
		world.setBlock(x+4, y+5, z+5, b, ms);
		world.setBlock(x+4, y+5, z+6, b, ms);
		world.setBlock(x+4, y+5, z+7, b, ms);
		world.setBlock(x+5, y+0, z+0, b, ms);
		world.setBlock(x+5, y+0, z+1, b, ms);
		world.setBlock(x+5, y+0, z+2, b, ms);
		world.setBlock(x+5, y+0, z+3, b, ms);
		world.setBlock(x+5, y+0, z+4, b, ms);
		world.setBlock(x+5, y+0, z+5, b, ms);
		world.setBlock(x+5, y+0, z+6, b, ms);
		world.setBlock(x+5, y+0, z+7, b, ms);
		world.setBlock(x+5, y+0, z+8, b, ms);
		world.setBlock(x+5, y+1, z+3, b, ms);
		world.setBlock(x+5, y+1, z+4, b, mg);
		world.setBlock(x+5, y+1, z+5, b, ms);
		world.setBlock(x+5, y+2, z+3, b, ms);
		world.setBlock(x+5, y+2, z+4, b, mg);
		world.setBlock(x+5, y+2, z+5, b, ms);
		world.setBlock(x+5, y+3, z+3, b, ms);
		world.setBlock(x+5, y+3, z+4, b, mg);
		world.setBlock(x+5, y+3, z+5, b, ms);
		world.setBlock(x+5, y+4, z+0, b, ms);
		world.setBlock(x+5, y+4, z+1, b, ms);
		world.setBlock(x+5, y+4, z+3, b, ms);
		world.setBlock(x+5, y+4, z+4, b, mg);
		world.setBlock(x+5, y+4, z+5, b, ms);
		world.setBlock(x+5, y+4, z+7, b, ms);
		world.setBlock(x+5, y+4, z+8, b, ms);
		world.setBlock(x+5, y+5, z+1, b, ms);
		world.setBlock(x+5, y+5, z+2, b, ms);
		world.setBlock(x+5, y+5, z+3, b, ms);
		world.setBlock(x+5, y+5, z+4, b, ms);
		world.setBlock(x+5, y+5, z+5, b, ms);
		world.setBlock(x+5, y+5, z+6, b, ms);
		world.setBlock(x+5, y+5, z+7, b, ms);
		world.setBlock(x+6, y+0, z+0, b, ms);
		world.setBlock(x+6, y+0, z+1, b, ms);
		world.setBlock(x+6, y+0, z+2, b, ms);
		world.setBlock(x+6, y+0, z+3, b, ms);
		world.setBlock(x+6, y+0, z+4, b, ms);
		world.setBlock(x+6, y+0, z+5, b, ms);
		world.setBlock(x+6, y+0, z+6, b, ms);
		world.setBlock(x+6, y+0, z+7, b, ms);
		world.setBlock(x+6, y+0, z+8, b, ms);
		world.setBlock(x+6, y+4, z+0, b, ms);
		world.setBlock(x+6, y+4, z+1, b, ms);
		world.setBlock(x+6, y+4, z+7, b, ms);
		world.setBlock(x+6, y+4, z+8, b, ms);
		world.setBlock(x+6, y+5, z+1, b, ms);
		world.setBlock(x+6, y+5, z+2, b, ms);
		world.setBlock(x+6, y+5, z+3, b, ms);
		world.setBlock(x+6, y+5, z+4, b, ms);
		world.setBlock(x+6, y+5, z+5, b, ms);
		world.setBlock(x+6, y+5, z+6, b, ms);
		world.setBlock(x+6, y+5, z+7, b, ms);
		world.setBlock(x+7, y+0, z+0, b, ms);
		world.setBlock(x+7, y+0, z+1, b, ms);
		world.setBlock(x+7, y+0, z+2, b, ms);
		world.setBlock(x+7, y+0, z+3, b, ms);
		world.setBlock(x+7, y+0, z+4, b, ml);
		world.setBlock(x+7, y+0, z+5, b, ms);
		world.setBlock(x+7, y+0, z+6, b, ms);
		world.setBlock(x+7, y+0, z+7, b, ms);
		world.setBlock(x+7, y+0, z+8, b, ms);
		world.setBlock(x+7, y+1, z+0, b, ms);
		world.setBlock(x+7, y+1, z+1, b, ms);
		world.setBlock(x+7, y+1, z+7, b, ms);
		world.setBlock(x+7, y+1, z+8, b, ms);
		world.setBlock(x+7, y+2, z+0, b, ms);
		world.setBlock(x+7, y+2, z+1, b, ms);
		world.setBlock(x+7, y+2, z+7, b, ms);
		world.setBlock(x+7, y+2, z+8, b, ms);
		world.setBlock(x+7, y+3, z+0, b, ms);
		world.setBlock(x+7, y+3, z+1, b, ms);
		world.setBlock(x+7, y+3, z+7, b, ms);
		world.setBlock(x+7, y+3, z+8, b, ms);
		world.setBlock(x+7, y+4, z+0, b, ms);
		world.setBlock(x+7, y+4, z+1, b, ms);
		world.setBlock(x+7, y+4, z+2, b, ms);
		world.setBlock(x+7, y+4, z+6, b, ms);
		world.setBlock(x+7, y+4, z+7, b, ms);
		world.setBlock(x+7, y+4, z+8, b, ms);
		world.setBlock(x+7, y+5, z+2, b, ms);
		world.setBlock(x+7, y+5, z+3, b, ms);
		world.setBlock(x+7, y+5, z+4, b, ms);
		world.setBlock(x+7, y+5, z+5, b, ms);
		world.setBlock(x+7, y+5, z+6, b, ms);
		world.setBlock(x+8, y+0, z+1, b, ms);
		world.setBlock(x+8, y+0, z+2, b, ms);
		world.setBlock(x+8, y+0, z+3, b, ms);
		world.setBlock(x+8, y+0, z+4, b, ms);
		world.setBlock(x+8, y+0, z+5, b, ms);
		world.setBlock(x+8, y+0, z+6, b, ms);
		world.setBlock(x+8, y+0, z+7, b, ms);
		world.setBlock(x+8, y+1, z+1, b, ms);
		world.setBlock(x+8, y+1, z+2, b, ms);
		world.setBlock(x+8, y+1, z+6, b, ms);
		world.setBlock(x+8, y+1, z+7, b, ms);
		world.setBlock(x+8, y+2, z+1, b, ms);
		world.setBlock(x+8, y+2, z+2, b, ms);
		world.setBlock(x+8, y+2, z+6, b, ms);
		world.setBlock(x+8, y+2, z+7, b, ms);
		world.setBlock(x+8, y+3, z+1, b, ms);
		world.setBlock(x+8, y+3, z+2, b, ms);
		world.setBlock(x+8, y+3, z+6, b, ms);
		world.setBlock(x+8, y+3, z+7, b, ms);
		world.setBlock(x+8, y+4, z+1, b, ms);
		world.setBlock(x+8, y+4, z+2, b, ms);
		world.setBlock(x+8, y+4, z+3, b, ms);
		world.setBlock(x+8, y+4, z+5, b, ms);
		world.setBlock(x+8, y+4, z+6, b, ms);
		world.setBlock(x+8, y+4, z+7, b, ms);
		world.setBlock(x+8, y+5, z+3, b, ms);
		world.setBlock(x+8, y+5, z+4, b, ms);
		world.setBlock(x+8, y+5, z+5, b, ms);
		world.setBlock(x+9, y+0, z+2, b, ms);
		world.setBlock(x+9, y+0, z+3, b, ms);
		world.setBlock(x+9, y+0, z+4, b, ms);
		world.setBlock(x+9, y+0, z+5, b, ms);
		world.setBlock(x+9, y+0, z+6, b, ms);
		world.setBlock(x+9, y+1, z+2, b, ms);
		world.setBlock(x+9, y+1, z+6, b, ms);
		world.setBlock(x+9, y+2, z+2, b, ms);
		world.setBlock(x+9, y+2, z+6, b, ms);
		world.setBlock(x+9, y+3, z+2, b, ms);
		world.setBlock(x+9, y+3, z+6, b, ms);
		world.setBlock(x+9, y+4, z+2, b, ms);
		world.setBlock(x+9, y+4, z+3, b, ms);
		world.setBlock(x+9, y+4, z+4, b, ms);
		world.setBlock(x+9, y+4, z+5, b, ms);
		world.setBlock(x+9, y+4, z+6, b, ms);

		this.addBreakable(world, x+6, y+1, z+0);
		this.addBreakable(world, x+6, y+1, z+8);
		this.addBreakable(world, x+6, y+2, z+0);
		this.addBreakable(world, x+6, y+2, z+8);
		this.addBreakable(world, x+6, y+3, z+0);
		this.addBreakable(world, x+6, y+3, z+8);
		this.addBreakable(world, x+5, y+2, z+8);
		this.addBreakable(world, x+5, y+3, z+0);
		this.addBreakable(world, x+5, y+3, z+8);
		this.addBreakable(world, x+5, y+1, z+8);
		this.addBreakable(world, x+5, y+2, z+0);
		this.addBreakable(world, x+5, y+1, z+0);
		this.addBreakable(world, x+4, y+1, z+0);
		this.addBreakable(world, x+4, y+1, z+8);
		this.addBreakable(world, x+4, y+2, z+0);
		this.addBreakable(world, x+4, y+2, z+8);
		this.addBreakable(world, x+4, y+3, z+0);
		this.addBreakable(world, x+4, y+3, z+8);
		this.addBreakable(world, x+3, y+1, z+0);
		this.addBreakable(world, x+3, y+1, z+8);
		this.addBreakable(world, x+3, y+2, z+0);
		this.addBreakable(world, x+3, y+2, z+8);
		this.addBreakable(world, x+3, y+3, z+0);
		this.addBreakable(world, x+3, y+3, z+8);
		this.addBreakable(world, x+0, y+1, z+3);
		this.addBreakable(world, x+0, y+1, z+4);
		this.addBreakable(world, x+0, y+1, z+5);
		this.addBreakable(world, x+0, y+2, z+3);
		this.addBreakable(world, x+0, y+2, z+4);
		this.addBreakable(world, x+0, y+2, z+5);
		this.addBreakable(world, x+0, y+3, z+3);
		this.addBreakable(world, x+0, y+3, z+4);
		this.addBreakable(world, x+0, y+3, z+5);

		world.setBlock(x+1, y+1, z+3, Blocks.air);
		world.setBlock(x+1, y+1, z+4, Blocks.air);
		world.setBlock(x+1, y+1, z+5, Blocks.air);
		world.setBlock(x+1, y+2, z+3, Blocks.air);
		world.setBlock(x+1, y+2, z+4, Blocks.air);
		world.setBlock(x+1, y+2, z+5, Blocks.air);
		world.setBlock(x+1, y+3, z+3, Blocks.air);
		world.setBlock(x+1, y+3, z+4, Blocks.air);
		world.setBlock(x+1, y+3, z+5, Blocks.air);
		world.setBlock(x+2, y+1, z+2, Blocks.air);
		world.setBlock(x+2, y+1, z+3, Blocks.air);
		world.setBlock(x+2, y+1, z+4, Blocks.air);
		world.setBlock(x+2, y+1, z+5, Blocks.air);
		world.setBlock(x+2, y+1, z+6, Blocks.air);
		world.setBlock(x+2, y+2, z+2, Blocks.air);
		world.setBlock(x+2, y+2, z+3, Blocks.air);
		world.setBlock(x+2, y+2, z+4, Blocks.air);
		world.setBlock(x+2, y+2, z+5, Blocks.air);
		world.setBlock(x+2, y+2, z+6, Blocks.air);
		world.setBlock(x+2, y+3, z+2, Blocks.air);
		world.setBlock(x+2, y+3, z+3, Blocks.air);
		world.setBlock(x+2, y+3, z+4, Blocks.air);
		world.setBlock(x+2, y+3, z+5, Blocks.air);
		world.setBlock(x+2, y+3, z+6, Blocks.air);
		world.setBlock(x+2, y+4, z+3, Blocks.air);
		world.setBlock(x+2, y+4, z+4, Blocks.air);
		world.setBlock(x+2, y+4, z+5, Blocks.air);
		world.setBlock(x+3, y+1, z+1, Blocks.air);
		world.setBlock(x+3, y+1, z+2, Blocks.air);
		world.setBlock(x+3, y+1, z+3, Blocks.air);
		world.setBlock(x+3, y+1, z+4, Blocks.air);
		world.setBlock(x+3, y+1, z+5, Blocks.air);
		world.setBlock(x+3, y+1, z+6, Blocks.air);
		world.setBlock(x+3, y+1, z+7, Blocks.air);
		world.setBlock(x+3, y+2, z+1, Blocks.air);
		world.setBlock(x+3, y+2, z+2, Blocks.air);
		world.setBlock(x+3, y+2, z+3, Blocks.air);
		world.setBlock(x+3, y+2, z+4, Blocks.air);
		world.setBlock(x+3, y+2, z+5, Blocks.air);
		world.setBlock(x+3, y+2, z+6, Blocks.air);
		world.setBlock(x+3, y+2, z+7, Blocks.air);
		world.setBlock(x+3, y+3, z+1, Blocks.air);
		world.setBlock(x+3, y+3, z+2, Blocks.air);
		world.setBlock(x+3, y+3, z+3, Blocks.air);
		world.setBlock(x+3, y+3, z+4, Blocks.air);
		world.setBlock(x+3, y+3, z+5, Blocks.air);
		world.setBlock(x+3, y+3, z+6, Blocks.air);
		world.setBlock(x+3, y+3, z+7, Blocks.air);
		world.setBlock(x+3, y+4, z+2, Blocks.air);
		world.setBlock(x+3, y+4, z+3, Blocks.air);
		world.setBlock(x+3, y+4, z+4, Blocks.air);
		world.setBlock(x+3, y+4, z+5, Blocks.air);
		world.setBlock(x+3, y+4, z+6, Blocks.air);
		world.setBlock(x+4, y+1, z+1, Blocks.air);
		world.setBlock(x+4, y+1, z+2, Blocks.air);
		world.setBlock(x+4, y+1, z+3, Blocks.air);
		world.setBlock(x+4, y+1, z+4, Blocks.air);
		world.setBlock(x+4, y+1, z+5, Blocks.air);
		world.setBlock(x+4, y+1, z+6, Blocks.air);
		world.setBlock(x+4, y+1, z+7, Blocks.air);
		world.setBlock(x+4, y+2, z+1, Blocks.air);
		world.setBlock(x+4, y+2, z+2, Blocks.air);
		world.setBlock(x+4, y+2, z+3, Blocks.air);
		world.setBlock(x+4, y+2, z+4, Blocks.air);
		world.setBlock(x+4, y+2, z+5, Blocks.air);
		world.setBlock(x+4, y+2, z+6, Blocks.air);
		world.setBlock(x+4, y+2, z+7, Blocks.air);
		world.setBlock(x+4, y+3, z+1, Blocks.air);
		world.setBlock(x+4, y+3, z+2, Blocks.air);
		world.setBlock(x+4, y+3, z+3, Blocks.air);
		world.setBlock(x+4, y+3, z+4, Blocks.air);
		world.setBlock(x+4, y+3, z+5, Blocks.air);
		world.setBlock(x+4, y+3, z+6, Blocks.air);
		world.setBlock(x+4, y+3, z+7, Blocks.air);
		world.setBlock(x+4, y+4, z+2, Blocks.air);
		world.setBlock(x+4, y+4, z+3, Blocks.air);
		world.setBlock(x+4, y+4, z+4, Blocks.air);
		world.setBlock(x+4, y+4, z+5, Blocks.air);
		world.setBlock(x+4, y+4, z+6, Blocks.air);
		world.setBlock(x+5, y+1, z+1, Blocks.air);
		world.setBlock(x+5, y+1, z+2, Blocks.air);
		world.setBlock(x+5, y+1, z+6, Blocks.air);
		world.setBlock(x+5, y+1, z+7, Blocks.air);
		world.setBlock(x+5, y+2, z+1, Blocks.air);
		world.setBlock(x+5, y+2, z+2, Blocks.air);
		world.setBlock(x+5, y+2, z+6, Blocks.air);
		world.setBlock(x+5, y+2, z+7, Blocks.air);
		world.setBlock(x+5, y+3, z+1, Blocks.air);
		world.setBlock(x+5, y+3, z+2, Blocks.air);
		world.setBlock(x+5, y+3, z+6, Blocks.air);
		world.setBlock(x+5, y+3, z+7, Blocks.air);
		world.setBlock(x+5, y+4, z+2, Blocks.air);
		world.setBlock(x+5, y+4, z+6, Blocks.air);
		world.setBlock(x+6, y+1, z+1, Blocks.air);
		world.setBlock(x+6, y+1, z+2, Blocks.air);
		world.setBlock(x+6, y+1, z+3, Blocks.air);
		world.setBlock(x+6, y+1, z+4, Blocks.air);
		world.setBlock(x+6, y+1, z+5, Blocks.air);
		world.setBlock(x+6, y+1, z+6, Blocks.air);
		world.setBlock(x+6, y+1, z+7, Blocks.air);
		world.setBlock(x+6, y+2, z+1, Blocks.air);
		world.setBlock(x+6, y+2, z+2, Blocks.air);
		world.setBlock(x+6, y+2, z+3, Blocks.air);
		world.setBlock(x+6, y+2, z+4, Blocks.air);
		world.setBlock(x+6, y+2, z+5, Blocks.air);
		world.setBlock(x+6, y+2, z+6, Blocks.air);
		world.setBlock(x+6, y+2, z+7, Blocks.air);
		world.setBlock(x+6, y+3, z+1, Blocks.air);
		world.setBlock(x+6, y+3, z+2, Blocks.air);
		world.setBlock(x+6, y+3, z+3, Blocks.air);
		world.setBlock(x+6, y+3, z+4, Blocks.air);
		world.setBlock(x+6, y+3, z+5, Blocks.air);
		world.setBlock(x+6, y+3, z+6, Blocks.air);
		world.setBlock(x+6, y+3, z+7, Blocks.air);
		world.setBlock(x+6, y+4, z+2, Blocks.air);
		world.setBlock(x+6, y+4, z+3, Blocks.air);
		world.setBlock(x+6, y+4, z+4, Blocks.air);
		world.setBlock(x+6, y+4, z+5, Blocks.air);
		world.setBlock(x+6, y+4, z+6, Blocks.air);
		world.setBlock(x+7, y+1, z+2, Blocks.air);
		world.setBlock(x+7, y+1, z+3, Blocks.air);
		world.setBlock(x+7, y+1, z+4, Blocks.air);
		world.setBlock(x+7, y+1, z+5, Blocks.air);
		world.setBlock(x+7, y+1, z+6, Blocks.air);
		world.setBlock(x+7, y+2, z+2, Blocks.air);
		world.setBlock(x+7, y+2, z+3, Blocks.air);
		world.setBlock(x+7, y+2, z+4, Blocks.air);
		world.setBlock(x+7, y+2, z+5, Blocks.air);
		world.setBlock(x+7, y+2, z+6, Blocks.air);
		world.setBlock(x+7, y+3, z+2, Blocks.air);
		world.setBlock(x+7, y+3, z+3, Blocks.air);
		world.setBlock(x+7, y+3, z+4, Blocks.air);
		world.setBlock(x+7, y+3, z+5, Blocks.air);
		world.setBlock(x+7, y+3, z+6, Blocks.air);
		world.setBlock(x+7, y+4, z+3, Blocks.air);
		world.setBlock(x+7, y+4, z+4, Blocks.air);
		world.setBlock(x+7, y+4, z+5, Blocks.air);
		world.setBlock(x+8, y+1, z+3, Blocks.air);
		world.setBlock(x+8, y+1, z+4, Blocks.air);
		world.setBlock(x+8, y+1, z+5, Blocks.air);
		world.setBlock(x+8, y+2, z+3, Blocks.air);
		world.setBlock(x+8, y+2, z+4, Blocks.air);
		world.setBlock(x+8, y+2, z+5, Blocks.air);
		world.setBlock(x+8, y+3, z+3, Blocks.air);
		world.setBlock(x+8, y+3, z+4, Blocks.air);
		world.setBlock(x+8, y+3, z+5, Blocks.air);
		world.setBlock(x+8, y+4, z+4, Blocks.air);
		world.setBlock(x+9, y+1, z+3, Blocks.air);
		world.setBlock(x+9, y+1, z+4, Blocks.air);
		world.setBlock(x+9, y+1, z+5, Blocks.air);
		world.setBlock(x+9, y+2, z+3, Blocks.air);
		world.setBlock(x+9, y+2, z+4, Blocks.air);
		world.setBlock(x+9, y+2, z+5, Blocks.air);
		world.setBlock(x+9, y+3, z+3, Blocks.air);
		world.setBlock(x+9, y+3, z+4, Blocks.air);
		world.setBlock(x+9, y+3, z+5, Blocks.air);

		this.placeCore(x+4, y+2, z+4);
	}

	private void addBreakable(ChunkSplicedGenerationCache world, int x, int y, int z) {
		parent.addBreakable(x, y, z);
		world.setBlock(x, y, z, ChromaBlocks.STRUCTSHIELD.getBlockInstance(), BlockType.STONE.metadata);
	}

}
