/*******************************************************************************
 * @author Reika Kalseki
 * 
 * Copyright 2015
 * 
 * All rights reserved.
 * Distribution of the software in any form is only allowed with
 * explicit, prior permission from the owner.
 ******************************************************************************/
package Reika.ChromatiCraft.World.Dimension.Structure;

import java.util.Random;

import net.minecraft.block.Block;
import net.minecraft.init.Blocks;
import Reika.ChromatiCraft.Auxiliary.Interfaces.StructureData;
import Reika.ChromatiCraft.Base.DimensionStructureGenerator;
import Reika.ChromatiCraft.Registry.ChromaBlocks;
import Reika.ChromatiCraft.Registry.CrystalElement;

public class NonEuclideanGenerator extends DimensionStructureGenerator {

	@Override
	protected void calculate(int chunkX, int chunkZ, CrystalElement e, Random rand) {
		Block b = ChromaBlocks.SPECIALSHIELD.getBlockInstance();
		int x = chunkX;
		int y = 200;
		int z = chunkZ;

		this.generate(rand, x, y, z, b);
		this.generate2(rand, x, y, z, b);
		this.generate3(rand, x, y, z, b);
		this.generate4(rand, x, y, z, b);
		this.generate5(rand, x, y, z, b);
		this.generate6(rand, x, y, z, b);
	}

	private void generate(Random rand, int i, int j, int k, Block b) {
		world.setBlock(i + 11, j + 0, k + 56, b, 1);
		world.setBlock(i + 11, j + 0, k + 57, b, 1);
		world.setBlock(i + 11, j + 0, k + 58, b, 1);
		world.setBlock(i + 11, j + 0, k + 59, b, 1);
		world.setBlock(i + 11, j + 0, k + 60, b, 1);
		world.setBlock(i + 11, j + 0, k + 61, b, 1);
		world.setBlock(i + 11, j + 0, k + 62, b, 1);
		world.setBlock(i + 11, j + 0, k + 63, b, 1);
		world.setBlock(i + 11, j + 0, k + 64, b, 1);
		world.setBlock(i + 11, j + 0, k + 65, b, 1);
		world.setBlock(i + 11, j + 0, k + 66, b, 1);
		world.setBlock(i + 11, j + 0, k + 67, b, 1);
		world.setBlock(i + 11, j + 0, k + 68, b, 1);
		world.setBlock(i + 11, j + 1, k + 56, b, 1);
		world.setBlock(i + 11, j + 1, k + 57, b, 1);
		world.setBlock(i + 11, j + 1, k + 58, b, 1);
		world.setBlock(i + 11, j + 1, k + 59, b, 1);
		world.setBlock(i + 11, j + 1, k + 60, b, 1);
		world.setBlock(i + 11, j + 1, k + 61, b, 1);
		world.setBlock(i + 11, j + 1, k + 62, b, 1);
		world.setBlock(i + 11, j + 1, k + 63, b, 1);
		world.setBlock(i + 11, j + 1, k + 64, b, 1);
		world.setBlock(i + 11, j + 1, k + 65, b, 1);
		world.setBlock(i + 11, j + 1, k + 66, b, 1);
		world.setBlock(i + 11, j + 1, k + 67, b, 1);
		world.setBlock(i + 11, j + 1, k + 68, b, 1);
		world.setBlock(i + 11, j + 2, k + 56, b, 1);
		world.setBlock(i + 11, j + 2, k + 57, b, 1);
		world.setBlock(i + 11, j + 2, k + 58, b, 1);
		world.setBlock(i + 11, j + 2, k + 59, b, 1);
		world.setBlock(i + 11, j + 2, k + 60, b, 1);
		world.setBlock(i + 11, j + 2, k + 61, b, 1);
		world.setBlock(i + 11, j + 2, k + 62, b, 1);
		world.setBlock(i + 11, j + 2, k + 63, b, 1);
		world.setBlock(i + 11, j + 2, k + 64, b, 1);
		world.setBlock(i + 11, j + 2, k + 65, b, 1);
		world.setBlock(i + 11, j + 2, k + 66, b, 1);
		world.setBlock(i + 11, j + 2, k + 67, b, 1);
		world.setBlock(i + 11, j + 2, k + 68, b, 1);
		world.setBlock(i + 11, j + 3, k + 56, b, 1);
		world.setBlock(i + 11, j + 3, k + 57, b, 1);
		world.setBlock(i + 11, j + 3, k + 58, b, 1);
		world.setBlock(i + 11, j + 3, k + 59, b, 1);
		world.setBlock(i + 11, j + 3, k + 60, b, 1);
		world.setBlock(i + 11, j + 3, k + 61, b, 1);
		world.setBlock(i + 11, j + 3, k + 62, b, 1);
		world.setBlock(i + 11, j + 3, k + 63, b, 1);
		world.setBlock(i + 11, j + 3, k + 64, b, 1);
		world.setBlock(i + 11, j + 3, k + 65, b, 1);
		world.setBlock(i + 11, j + 3, k + 66, b, 1);
		world.setBlock(i + 11, j + 3, k + 67, b, 1);
		world.setBlock(i + 11, j + 3, k + 68, b, 1);
		world.setBlock(i + 11, j + 4, k + 56, b, 1);
		world.setBlock(i + 11, j + 4, k + 57, b, 1);
		world.setBlock(i + 11, j + 4, k + 58, b, 1);
		world.setBlock(i + 11, j + 4, k + 59, b, 1);
		world.setBlock(i + 11, j + 4, k + 60, b, 1);
		world.setBlock(i + 11, j + 4, k + 61, b, 1);
		world.setBlock(i + 11, j + 4, k + 62, b, 1);
		world.setBlock(i + 11, j + 4, k + 63, b, 1);
		world.setBlock(i + 11, j + 4, k + 64, b, 1);
		world.setBlock(i + 11, j + 4, k + 65, b, 1);
		world.setBlock(i + 11, j + 4, k + 66, b, 1);
		world.setBlock(i + 11, j + 4, k + 67, b, 1);
		world.setBlock(i + 11, j + 4, k + 68, b, 1);
		world.setBlock(i + 12, j + 0, k + 54, b, 1);
		world.setBlock(i + 12, j + 0, k + 55, b, 1);
		world.setBlock(i + 12, j + 0, k + 56, b, 1);
		world.setBlock(i + 12, j + 0, k + 57, b, 0);
		world.setBlock(i + 12, j + 0, k + 58, b, 0);
		world.setBlock(i + 12, j + 0, k + 59, b, 0);
		world.setBlock(i + 12, j + 0, k + 60, b, 0);
		world.setBlock(i + 12, j + 0, k + 61, b, 0);
		world.setBlock(i + 12, j + 0, k + 62, b, 0);
		world.setBlock(i + 12, j + 0, k + 63, b, 0);
		world.setBlock(i + 12, j + 0, k + 64, b, 0);
		world.setBlock(i + 12, j + 0, k + 65, b, 0);
		world.setBlock(i + 12, j + 0, k + 66, b, 0);
		world.setBlock(i + 12, j + 0, k + 67, b, 0);
		world.setBlock(i + 12, j + 0, k + 68, b, 1);
		world.setBlock(i + 12, j + 1, k + 54, b, 1);
		world.setBlock(i + 12, j + 1, k + 55, b, 1);
		world.setBlock(i + 12, j + 1, k + 56, b, 1);
		world.setBlock(i + 12, j + 1, k + 60, Blocks.glass);
		world.setBlock(i + 12, j + 1, k + 68, b, 1);
		world.setBlock(i + 12, j + 2, k + 54, b, 1);
		world.setBlock(i + 12, j + 2, k + 55, b, 1);
		world.setBlock(i + 12, j + 2, k + 56, b, 1);
		world.setBlock(i + 12, j + 2, k + 60, Blocks.glass);
		world.setBlock(i + 12, j + 2, k + 68, b, 1);
		world.setBlock(i + 12, j + 3, k + 54, b, 1);
		world.setBlock(i + 12, j + 3, k + 55, b, 1);
		world.setBlock(i + 12, j + 3, k + 56, b, 1);
		world.setBlock(i + 12, j + 3, k + 60, Blocks.glass);
		world.setBlock(i + 12, j + 3, k + 68, b, 1);
		world.setBlock(i + 12, j + 4, k + 54, b, 1);
		world.setBlock(i + 12, j + 4, k + 55, b, 1);
		world.setBlock(i + 12, j + 4, k + 56, b, 1);
		world.setBlock(i + 12, j + 4, k + 57, b, 1);
		world.setBlock(i + 12, j + 4, k + 58, b, 1);
		world.setBlock(i + 12, j + 4, k + 59, b, 1);
		world.setBlock(i + 12, j + 4, k + 60, b, 1);
		world.setBlock(i + 12, j + 4, k + 61, b, 1);
		world.setBlock(i + 12, j + 4, k + 62, b, 1);
		world.setBlock(i + 12, j + 4, k + 63, b, 1);
		world.setBlock(i + 12, j + 4, k + 64, b, 1);
		world.setBlock(i + 12, j + 4, k + 65, b, 1);
		world.setBlock(i + 12, j + 4, k + 66, b, 1);
		world.setBlock(i + 12, j + 4, k + 67, b, 1);
		world.setBlock(i + 12, j + 4, k + 68, b, 1);
		world.setBlock(i + 13, j + 0, k + 45, b, 1);
		world.setBlock(i + 13, j + 0, k + 46, b, 1);
		world.setBlock(i + 13, j + 0, k + 47, b, 1);
		world.setBlock(i + 13, j + 0, k + 48, b, 1);
		world.setBlock(i + 13, j + 0, k + 49, b, 1);
		world.setBlock(i + 13, j + 0, k + 50, b, 1);
		world.setBlock(i + 13, j + 0, k + 51, b, 1);
		world.setBlock(i + 13, j + 0, k + 52, b, 1);
		world.setBlock(i + 13, j + 0, k + 53, b, 1);
		world.setBlock(i + 13, j + 0, k + 54, b, 1);
		world.setBlock(i + 13, j + 0, k + 55, b, 0);
		world.setBlock(i + 13, j + 0, k + 56, b, 0);
		world.setBlock(i + 13, j + 0, k + 57, b, 0);
		world.setBlock(i + 13, j + 0, k + 58, b, 0);
		world.setBlock(i + 13, j + 0, k + 59, b, 0);
		world.setBlock(i + 13, j + 0, k + 60, b, 0);
		world.setBlock(i + 13, j + 0, k + 61, b, 0);
		world.setBlock(i + 13, j + 0, k + 62, b, 0);
		world.setBlock(i + 13, j + 0, k + 63, b, 0);
		world.setBlock(i + 13, j + 0, k + 64, b, 0);
		world.setBlock(i + 13, j + 0, k + 65, b, 0);
		world.setBlock(i + 13, j + 0, k + 66, b, 0);
		world.setBlock(i + 13, j + 0, k + 67, b, 0);
		world.setBlock(i + 13, j + 0, k + 68, b, 1);
		world.setBlock(i + 13, j + 1, k + 45, b, 1);
		world.setBlock(i + 13, j + 1, k + 46, b, 1);
		world.setBlock(i + 13, j + 1, k + 47, b, 1);
		world.setBlock(i + 13, j + 1, k + 48, b, 1);
		world.setBlock(i + 13, j + 1, k + 49, b, 1);
		world.setBlock(i + 13, j + 1, k + 50, b, 1);
		world.setBlock(i + 13, j + 1, k + 51, b, 1);
		world.setBlock(i + 13, j + 1, k + 52, b, 1);
		world.setBlock(i + 13, j + 1, k + 53, b, 1);
		world.setBlock(i + 13, j + 1, k + 54, b, 1);
		world.setBlock(i + 13, j + 1, k + 60, Blocks.glass);
		world.setBlock(i + 13, j + 1, k + 68, b, 1);
		world.setBlock(i + 13, j + 2, k + 45, b, 1);
		world.setBlock(i + 13, j + 2, k + 46, b, 1);
		world.setBlock(i + 13, j + 2, k + 47, b, 1);
		world.setBlock(i + 13, j + 2, k + 48, b, 1);
		world.setBlock(i + 13, j + 2, k + 49, b, 1);
		world.setBlock(i + 13, j + 2, k + 50, b, 1);
		world.setBlock(i + 13, j + 2, k + 51, b, 1);
		world.setBlock(i + 13, j + 2, k + 52, b, 1);
		world.setBlock(i + 13, j + 2, k + 53, b, 1);
		world.setBlock(i + 13, j + 2, k + 54, b, 1);
		world.setBlock(i + 13, j + 2, k + 60, Blocks.glass);
		world.setBlock(i + 13, j + 2, k + 68, b, 1);
		world.setBlock(i + 13, j + 3, k + 45, b, 1);
		world.setBlock(i + 13, j + 3, k + 46, b, 1);
		world.setBlock(i + 13, j + 3, k + 47, b, 1);
		world.setBlock(i + 13, j + 3, k + 48, b, 1);
		world.setBlock(i + 13, j + 3, k + 49, b, 1);
		world.setBlock(i + 13, j + 3, k + 50, b, 1);
		world.setBlock(i + 13, j + 3, k + 51, b, 1);
		world.setBlock(i + 13, j + 3, k + 52, b, 1);
		world.setBlock(i + 13, j + 3, k + 53, b, 1);
		world.setBlock(i + 13, j + 3, k + 54, b, 1);
		world.setBlock(i + 13, j + 3, k + 60, Blocks.glass);
		world.setBlock(i + 13, j + 3, k + 68, b, 1);
		world.setBlock(i + 13, j + 4, k + 45, b, 1);
		world.setBlock(i + 13, j + 4, k + 46, b, 1);
		world.setBlock(i + 13, j + 4, k + 47, b, 1);
		world.setBlock(i + 13, j + 4, k + 48, b, 1);
		world.setBlock(i + 13, j + 4, k + 49, b, 1);
		world.setBlock(i + 13, j + 4, k + 50, b, 1);
		world.setBlock(i + 13, j + 4, k + 51, b, 1);
		world.setBlock(i + 13, j + 4, k + 52, b, 1);
		world.setBlock(i + 13, j + 4, k + 53, b, 1);
		world.setBlock(i + 13, j + 4, k + 54, b, 1);
		world.setBlock(i + 13, j + 4, k + 55, b, 1);
		world.setBlock(i + 13, j + 4, k + 56, b, 1);
		world.setBlock(i + 13, j + 4, k + 57, b, 1);
		world.setBlock(i + 13, j + 4, k + 58, b, 1);
		world.setBlock(i + 13, j + 4, k + 59, b, 1);
		world.setBlock(i + 13, j + 4, k + 60, b, 1);
		world.setBlock(i + 13, j + 4, k + 61, b, 1);
		world.setBlock(i + 13, j + 4, k + 62, b, 1);
		world.setBlock(i + 13, j + 4, k + 63, b, 1);
		world.setBlock(i + 13, j + 4, k + 64, b, 1);
		world.setBlock(i + 13, j + 4, k + 65, b, 1);
		world.setBlock(i + 13, j + 4, k + 66, b, 1);
		world.setBlock(i + 13, j + 4, k + 67, b, 1);
		world.setBlock(i + 13, j + 4, k + 68, b, 1);
		world.setBlock(i + 14, j + 0, k + 12, b, 1);
		world.setBlock(i + 14, j + 0, k + 13, b, 1);
		world.setBlock(i + 14, j + 0, k + 14, b, 1);
		world.setBlock(i + 14, j + 0, k + 15, b, 1);
		world.setBlock(i + 14, j + 0, k + 16, b, 1);
		world.setBlock(i + 14, j + 0, k + 17, b, 1);
		world.setBlock(i + 14, j + 0, k + 18, b, 1);
		world.setBlock(i + 14, j + 0, k + 19, b, 1);
		world.setBlock(i + 14, j + 0, k + 20, b, 1);
		world.setBlock(i + 14, j + 0, k + 21, b, 1);
		world.setBlock(i + 14, j + 0, k + 22, b, 1);
		world.setBlock(i + 14, j + 0, k + 45, b, 1);
		world.setBlock(i + 14, j + 0, k + 46, b, 0);
		world.setBlock(i + 14, j + 0, k + 47, b, 0);
		world.setBlock(i + 14, j + 0, k + 48, b, 0);
		world.setBlock(i + 14, j + 0, k + 49, b, 0);
		world.setBlock(i + 14, j + 0, k + 50, b, 0);
		world.setBlock(i + 14, j + 0, k + 51, b, 0);
		world.setBlock(i + 14, j + 0, k + 52, b, 0);
		world.setBlock(i + 14, j + 0, k + 53, b, 0);
		world.setBlock(i + 14, j + 0, k + 54, b, 0);
		world.setBlock(i + 14, j + 0, k + 55, b, 0);
		world.setBlock(i + 14, j + 0, k + 56, b, 0);
		world.setBlock(i + 14, j + 0, k + 57, b, 0);
		world.setBlock(i + 14, j + 0, k + 58, b, 0);
		world.setBlock(i + 14, j + 0, k + 59, b, 0);
		world.setBlock(i + 14, j + 0, k + 60, b, 0);
		world.setBlock(i + 14, j + 0, k + 61, b, 0);
		world.setBlock(i + 14, j + 0, k + 62, b, 0);
		world.setBlock(i + 14, j + 0, k + 63, b, 0);
		world.setBlock(i + 14, j + 0, k + 64, b, 0);
		world.setBlock(i + 14, j + 0, k + 65, b, 0);
		world.setBlock(i + 14, j + 0, k + 66, b, 0);
		world.setBlock(i + 14, j + 0, k + 67, b, 0);
		world.setBlock(i + 14, j + 0, k + 68, b, 1);
		world.setBlock(i + 14, j + 1, k + 12, b, 1);
		world.setBlock(i + 14, j + 1, k + 13, b, 1);
		world.setBlock(i + 14, j + 1, k + 14, b, 1);
		world.setBlock(i + 14, j + 1, k + 15, b, 1);
		world.setBlock(i + 14, j + 1, k + 16, b, 1);
		world.setBlock(i + 14, j + 1, k + 17, b, 1);
		world.setBlock(i + 14, j + 1, k + 18, b, 1);
		world.setBlock(i + 14, j + 1, k + 19, b, 1);
		world.setBlock(i + 14, j + 1, k + 20, b, 1);
		world.setBlock(i + 14, j + 1, k + 21, b, 1);
		world.setBlock(i + 14, j + 1, k + 22, b, 1);
		world.setBlock(i + 14, j + 1, k + 45, b, 1);
		world.setBlock(i + 14, j + 1, k + 60, Blocks.glass);
		world.setBlock(i + 14, j + 1, k + 63, Blocks.bedrock);
		world.setBlock(i + 14, j + 1, k + 64, Blocks.bedrock);
		world.setBlock(i + 14, j + 1, k + 65, Blocks.bedrock);
		world.setBlock(i + 14, j + 1, k + 68, b, 1);
		world.setBlock(i + 14, j + 2, k + 12, b, 1);
		world.setBlock(i + 14, j + 2, k + 13, b, 1);
		world.setBlock(i + 14, j + 2, k + 14, b, 1);
		world.setBlock(i + 14, j + 2, k + 15, b, 1);
		world.setBlock(i + 14, j + 2, k + 16, b, 1);
		world.setBlock(i + 14, j + 2, k + 17, b, 1);
		world.setBlock(i + 14, j + 2, k + 18, b, 1);
		world.setBlock(i + 14, j + 2, k + 19, b, 1);
		world.setBlock(i + 14, j + 2, k + 20, b, 1);
		world.setBlock(i + 14, j + 2, k + 21, b, 1);
		world.setBlock(i + 14, j + 2, k + 22, b, 1);
		world.setBlock(i + 14, j + 2, k + 45, b, 1);
		world.setBlock(i + 14, j + 2, k + 60, Blocks.glass);
		world.setBlock(i + 14, j + 2, k + 63, Blocks.bedrock);
		world.setBlock(i + 14, j + 2, k + 64, -33, 6);
		world.setBlock(i + 14, j + 2, k + 65, Blocks.bedrock);
		world.setBlock(i + 14, j + 2, k + 68, b, 1);
		world.setBlock(i + 14, j + 3, k + 12, b, 1);
		world.setBlock(i + 14, j + 3, k + 13, b, 1);
		world.setBlock(i + 14, j + 3, k + 14, b, 1);
		world.setBlock(i + 14, j + 3, k + 15, b, 1);
		world.setBlock(i + 14, j + 3, k + 16, b, 1);
		world.setBlock(i + 14, j + 3, k + 17, b, 1);
		world.setBlock(i + 14, j + 3, k + 18, b, 1);
		world.setBlock(i + 14, j + 3, k + 19, b, 1);
		world.setBlock(i + 14, j + 3, k + 20, b, 1);
		world.setBlock(i + 14, j + 3, k + 21, b, 1);
		world.setBlock(i + 14, j + 3, k + 22, b, 1);
		world.setBlock(i + 14, j + 3, k + 45, b, 1);
		world.setBlock(i + 14, j + 3, k + 60, Blocks.glass);
		world.setBlock(i + 14, j + 3, k + 63, Blocks.bedrock);
		world.setBlock(i + 14, j + 3, k + 64, Blocks.bedrock);
		world.setBlock(i + 14, j + 3, k + 65, Blocks.bedrock);
		world.setBlock(i + 14, j + 3, k + 68, b, 1);
		world.setBlock(i + 14, j + 4, k + 12, b, 1);
		world.setBlock(i + 14, j + 4, k + 13, b, 1);
		world.setBlock(i + 14, j + 4, k + 14, b, 1);
		world.setBlock(i + 14, j + 4, k + 15, b, 1);
		world.setBlock(i + 14, j + 4, k + 16, b, 1);
		world.setBlock(i + 14, j + 4, k + 17, b, 1);
		world.setBlock(i + 14, j + 4, k + 18, b, 1);
		world.setBlock(i + 14, j + 4, k + 19, b, 1);
		world.setBlock(i + 14, j + 4, k + 20, b, 1);
		world.setBlock(i + 14, j + 4, k + 21, b, 1);
		world.setBlock(i + 14, j + 4, k + 22, b, 1);
		world.setBlock(i + 14, j + 4, k + 45, b, 1);
		world.setBlock(i + 14, j + 4, k + 46, b, 1);
		world.setBlock(i + 14, j + 4, k + 47, b, 1);
		world.setBlock(i + 14, j + 4, k + 48, b, 1);
		world.setBlock(i + 14, j + 4, k + 49, b, 1);
		world.setBlock(i + 14, j + 4, k + 50, b, 1);
		world.setBlock(i + 14, j + 4, k + 51, b, 1);
		world.setBlock(i + 14, j + 4, k + 52, b, 1);
		world.setBlock(i + 14, j + 4, k + 53, b, 1);
		world.setBlock(i + 14, j + 4, k + 54, b, 1);
		world.setBlock(i + 14, j + 4, k + 55, b, 1);
		world.setBlock(i + 14, j + 4, k + 56, b, 1);
		world.setBlock(i + 14, j + 4, k + 57, b, 1);
		world.setBlock(i + 14, j + 4, k + 58, b, 1);
		world.setBlock(i + 14, j + 4, k + 59, b, 1);
		world.setBlock(i + 14, j + 4, k + 60, b, 1);
		world.setBlock(i + 14, j + 4, k + 61, b, 1);
		world.setBlock(i + 14, j + 4, k + 62, b, 1);
		world.setBlock(i + 14, j + 4, k + 63, b, 1);
		world.setBlock(i + 14, j + 4, k + 64, b, 1);
		world.setBlock(i + 14, j + 4, k + 65, b, 1);
		world.setBlock(i + 14, j + 4, k + 66, b, 1);
		world.setBlock(i + 14, j + 4, k + 67, b, 1);
		world.setBlock(i + 14, j + 4, k + 68, b, 1);
		world.setBlock(i + 15, j + 0, k + 12, b, 1);
		world.setBlock(i + 15, j + 0, k + 13, b, 0);
		world.setBlock(i + 15, j + 0, k + 14, b, 0);
		world.setBlock(i + 15, j + 0, k + 15, b, 0);
		world.setBlock(i + 15, j + 0, k + 16, b, 0);
		world.setBlock(i + 15, j + 0, k + 17, b, 0);
		world.setBlock(i + 15, j + 0, k + 18, b, 0);
		world.setBlock(i + 15, j + 0, k + 19, b, 0);
		world.setBlock(i + 15, j + 0, k + 20, b, 0);
		world.setBlock(i + 15, j + 0, k + 21, b, 0);
		world.setBlock(i + 15, j + 0, k + 22, b, 1);
		world.setBlock(i + 15, j + 0, k + 30, b, 1);
		world.setBlock(i + 15, j + 0, k + 31, b, 1);
		world.setBlock(i + 15, j + 0, k + 32, b, 1);
		world.setBlock(i + 15, j + 0, k + 33, b, 1);
		world.setBlock(i + 15, j + 0, k + 34, b, 1);
		world.setBlock(i + 15, j + 0, k + 35, b, 1);
		world.setBlock(i + 15, j + 0, k + 36, b, 1);
		world.setBlock(i + 15, j + 0, k + 37, b, 1);
		world.setBlock(i + 15, j + 0, k + 38, b, 1);
		world.setBlock(i + 15, j + 0, k + 39, b, 1);
		world.setBlock(i + 15, j + 0, k + 40, b, 1);
		world.setBlock(i + 15, j + 0, k + 41, b, 1);
		world.setBlock(i + 15, j + 0, k + 42, b, 1);
		world.setBlock(i + 15, j + 0, k + 43, b, 1);
		world.setBlock(i + 15, j + 0, k + 45, b, 1);
		world.setBlock(i + 15, j + 0, k + 46, b, 0);
		world.setBlock(i + 15, j + 0, k + 47, b, 0);
		world.setBlock(i + 15, j + 0, k + 48, b, 0);
		world.setBlock(i + 15, j + 0, k + 49, b, 0);
		world.setBlock(i + 15, j + 0, k + 50, b, 0);
		world.setBlock(i + 15, j + 0, k + 51, b, 0);
		world.setBlock(i + 15, j + 0, k + 52, b, 0);
		world.setBlock(i + 15, j + 0, k + 53, b, 0);
		world.setBlock(i + 15, j + 0, k + 54, b, 0);
		world.setBlock(i + 15, j + 0, k + 55, b, 0);
		world.setBlock(i + 15, j + 0, k + 56, b, 0);
		world.setBlock(i + 15, j + 0, k + 57, b, 0);
		world.setBlock(i + 15, j + 0, k + 58, b, 0);
		world.setBlock(i + 15, j + 0, k + 59, b, 0);
		world.setBlock(i + 15, j + 0, k + 60, b, 0);
		world.setBlock(i + 15, j + 0, k + 61, b, 0);
		world.setBlock(i + 15, j + 0, k + 62, b, 0);
		world.setBlock(i + 15, j + 0, k + 63, b, 0);
		world.setBlock(i + 15, j + 0, k + 64, b, 0);
		world.setBlock(i + 15, j + 0, k + 65, b, 0);
		world.setBlock(i + 15, j + 0, k + 66, b, 0);
		world.setBlock(i + 15, j + 0, k + 67, b, 0);
		world.setBlock(i + 15, j + 0, k + 68, b, 1);
		world.setBlock(i + 15, j + 1, k + 12, b, 1);
		world.setBlock(i + 15, j + 1, k + 22, b, 1);
		world.setBlock(i + 15, j + 1, k + 30, b, 1);
		world.setBlock(i + 15, j + 1, k + 31, b, 1);
		world.setBlock(i + 15, j + 1, k + 32, b, 1);
		world.setBlock(i + 15, j + 1, k + 33, b, 1);
		world.setBlock(i + 15, j + 1, k + 34, b, 1);
		world.setBlock(i + 15, j + 1, k + 35, b, 1);
		world.setBlock(i + 15, j + 1, k + 36, b, 1);
		world.setBlock(i + 15, j + 1, k + 37, b, 1);
		world.setBlock(i + 15, j + 1, k + 38, b, 1);
		world.setBlock(i + 15, j + 1, k + 39, b, 1);
		world.setBlock(i + 15, j + 1, k + 40, b, 1);
		world.setBlock(i + 15, j + 1, k + 41, b, 1);
		world.setBlock(i + 15, j + 1, k + 42, b, 1);
		world.setBlock(i + 15, j + 1, k + 43, b, 1);
		world.setBlock(i + 15, j + 1, k + 45, b, 1);
		world.setBlock(i + 15, j + 1, k + 60, Blocks.glass);
		world.setBlock(i + 15, j + 1, k + 68, b, 1);
		world.setBlock(i + 15, j + 2, k + 12, b, 1);
		world.setBlock(i + 15, j + 2, k + 22, b, 1);
		world.setBlock(i + 15, j + 2, k + 30, b, 1);
		world.setBlock(i + 15, j + 2, k + 31, b, 1);
		world.setBlock(i + 15, j + 2, k + 32, b, 1);
		world.setBlock(i + 15, j + 2, k + 33, b, 1);
		world.setBlock(i + 15, j + 2, k + 34, b, 1);
		world.setBlock(i + 15, j + 2, k + 35, b, 1);
		world.setBlock(i + 15, j + 2, k + 36, b, 1);
		world.setBlock(i + 15, j + 2, k + 37, b, 1);
		world.setBlock(i + 15, j + 2, k + 38, b, 1);
		world.setBlock(i + 15, j + 2, k + 39, b, 1);
		world.setBlock(i + 15, j + 2, k + 40, b, 1);
		world.setBlock(i + 15, j + 2, k + 41, b, 1);
		world.setBlock(i + 15, j + 2, k + 42, b, 1);
		world.setBlock(i + 15, j + 2, k + 43, b, 1);
		world.setBlock(i + 15, j + 2, k + 45, b, 1);
		world.setBlock(i + 15, j + 2, k + 60, Blocks.glass);
		world.setBlock(i + 15, j + 2, k + 68, b, 1);
		world.setBlock(i + 15, j + 3, k + 12, b, 1);
		world.setBlock(i + 15, j + 3, k + 22, b, 1);
		world.setBlock(i + 15, j + 3, k + 30, b, 1);
		world.setBlock(i + 15, j + 3, k + 31, b, 1);
		world.setBlock(i + 15, j + 3, k + 32, b, 1);
		world.setBlock(i + 15, j + 3, k + 33, b, 1);
		world.setBlock(i + 15, j + 3, k + 34, b, 1);
		world.setBlock(i + 15, j + 3, k + 35, b, 1);
		world.setBlock(i + 15, j + 3, k + 36, b, 1);
		world.setBlock(i + 15, j + 3, k + 37, b, 1);
		world.setBlock(i + 15, j + 3, k + 38, b, 1);
		world.setBlock(i + 15, j + 3, k + 39, b, 1);
		world.setBlock(i + 15, j + 3, k + 40, b, 1);
		world.setBlock(i + 15, j + 3, k + 41, b, 1);
		world.setBlock(i + 15, j + 3, k + 42, b, 1);
		world.setBlock(i + 15, j + 3, k + 43, b, 1);
		world.setBlock(i + 15, j + 3, k + 45, b, 1);
		world.setBlock(i + 15, j + 3, k + 60, Blocks.glass);
		world.setBlock(i + 15, j + 3, k + 68, b, 1);
		world.setBlock(i + 15, j + 4, k + 12, b, 1);
		world.setBlock(i + 15, j + 4, k + 13, b, 1);
		world.setBlock(i + 15, j + 4, k + 14, b, 1);
		world.setBlock(i + 15, j + 4, k + 15, b, 1);
		world.setBlock(i + 15, j + 4, k + 16, b, 1);
		world.setBlock(i + 15, j + 4, k + 17, b, 1);
		world.setBlock(i + 15, j + 4, k + 18, b, 1);
		world.setBlock(i + 15, j + 4, k + 19, b, 1);
		world.setBlock(i + 15, j + 4, k + 20, b, 1);
		world.setBlock(i + 15, j + 4, k + 21, b, 1);
		world.setBlock(i + 15, j + 4, k + 22, b, 1);
		world.setBlock(i + 15, j + 4, k + 30, b, 1);
		world.setBlock(i + 15, j + 4, k + 31, b, 1);
		world.setBlock(i + 15, j + 4, k + 32, b, 1);
		world.setBlock(i + 15, j + 4, k + 33, b, 1);
		world.setBlock(i + 15, j + 4, k + 34, b, 1);
		world.setBlock(i + 15, j + 4, k + 35, b, 1);
		world.setBlock(i + 15, j + 4, k + 36, b, 1);
		world.setBlock(i + 15, j + 4, k + 37, b, 1);
		world.setBlock(i + 15, j + 4, k + 38, b, 1);
		world.setBlock(i + 15, j + 4, k + 39, b, 1);
		world.setBlock(i + 15, j + 4, k + 40, b, 1);
		world.setBlock(i + 15, j + 4, k + 41, b, 1);
		world.setBlock(i + 15, j + 4, k + 42, b, 1);
		world.setBlock(i + 15, j + 4, k + 43, b, 1);
		world.setBlock(i + 15, j + 4, k + 45, b, 1);
		world.setBlock(i + 15, j + 4, k + 46, b, 1);
		world.setBlock(i + 15, j + 4, k + 47, b, 1);
		world.setBlock(i + 15, j + 4, k + 48, b, 1);
		world.setBlock(i + 15, j + 4, k + 49, b, 1);
		world.setBlock(i + 15, j + 4, k + 50, b, 1);
		world.setBlock(i + 15, j + 4, k + 51, b, 1);
		world.setBlock(i + 15, j + 4, k + 52, b, 1);
		world.setBlock(i + 15, j + 4, k + 53, b, 1);
		world.setBlock(i + 15, j + 4, k + 54, b, 1);
		world.setBlock(i + 15, j + 4, k + 55, b, 1);
		world.setBlock(i + 15, j + 4, k + 56, b, 1);
		world.setBlock(i + 15, j + 4, k + 57, b, 1);
		world.setBlock(i + 15, j + 4, k + 58, b, 1);
		world.setBlock(i + 15, j + 4, k + 59, b, 1);
		world.setBlock(i + 15, j + 4, k + 60, b, 1);
		world.setBlock(i + 15, j + 4, k + 61, b, 1);
		world.setBlock(i + 15, j + 4, k + 62, b, 1);
		world.setBlock(i + 15, j + 4, k + 63, b, 1);
		world.setBlock(i + 15, j + 4, k + 64, b, 1);
		world.setBlock(i + 15, j + 4, k + 65, b, 1);
		world.setBlock(i + 15, j + 4, k + 66, b, 1);
		world.setBlock(i + 15, j + 4, k + 67, b, 1);
		world.setBlock(i + 15, j + 4, k + 68, b, 1);
		world.setBlock(i + 16, j + 0, k + 12, b, 1);
		world.setBlock(i + 16, j + 0, k + 13, b, 0);
		world.setBlock(i + 16, j + 0, k + 14, b, 0);
		world.setBlock(i + 16, j + 0, k + 15, b, 0);
		world.setBlock(i + 16, j + 0, k + 16, b, 0);
		world.setBlock(i + 16, j + 0, k + 17, b, 0);
		world.setBlock(i + 16, j + 0, k + 18, b, 0);
		world.setBlock(i + 16, j + 0, k + 19, b, 0);
		world.setBlock(i + 16, j + 0, k + 20, b, 0);
		world.setBlock(i + 16, j + 0, k + 21, b, 0);
		world.setBlock(i + 16, j + 0, k + 22, b, 1);
		world.setBlock(i + 16, j + 0, k + 30, b, 1);
		world.setBlock(i + 16, j + 0, k + 31, b, 0);
		world.setBlock(i + 16, j + 0, k + 32, b, 0);
		world.setBlock(i + 16, j + 0, k + 33, b, 0);
		world.setBlock(i + 16, j + 0, k + 34, b, 0);
		world.setBlock(i + 16, j + 0, k + 35, b, 0);
		world.setBlock(i + 16, j + 0, k + 36, b, 0);
		world.setBlock(i + 16, j + 0, k + 37, b, 0);
		world.setBlock(i + 16, j + 0, k + 38, b, 0);
		world.setBlock(i + 16, j + 0, k + 39, b, 0);
		world.setBlock(i + 16, j + 0, k + 40, b, 0);
		world.setBlock(i + 16, j + 0, k + 41, b, 0);
		world.setBlock(i + 16, j + 0, k + 42, b, 0);
		world.setBlock(i + 16, j + 0, k + 43, b, 1);
		world.setBlock(i + 16, j + 0, k + 45, b, 1);
		world.setBlock(i + 16, j + 0, k + 46, b, 0);
		world.setBlock(i + 16, j + 0, k + 47, b, 0);
		world.setBlock(i + 16, j + 0, k + 48, b, 0);
		world.setBlock(i + 16, j + 0, k + 49, b, 0);
		world.setBlock(i + 16, j + 0, k + 50, b, 0);
		world.setBlock(i + 16, j + 0, k + 51, b, 0);
		world.setBlock(i + 16, j + 0, k + 52, b, 0);
		world.setBlock(i + 16, j + 0, k + 53, b, 0);
		world.setBlock(i + 16, j + 0, k + 54, b, 0);
		world.setBlock(i + 16, j + 0, k + 55, b, 0);
		world.setBlock(i + 16, j + 0, k + 56, b, 0);
		world.setBlock(i + 16, j + 0, k + 57, b, 0);
		world.setBlock(i + 16, j + 0, k + 58, b, 0);
		world.setBlock(i + 16, j + 0, k + 59, b, 0);
		world.setBlock(i + 16, j + 0, k + 60, b, 0);
		world.setBlock(i + 16, j + 0, k + 61, b, 0);
		world.setBlock(i + 16, j + 0, k + 62, b, 0);
		world.setBlock(i + 16, j + 0, k + 63, b, 0);
		world.setBlock(i + 16, j + 0, k + 64, b, 0);
		world.setBlock(i + 16, j + 0, k + 65, b, 0);
		world.setBlock(i + 16, j + 0, k + 66, b, 0);
		world.setBlock(i + 16, j + 0, k + 67, b, 0);
		world.setBlock(i + 16, j + 0, k + 68, b, 1);
		world.setBlock(i + 16, j + 1, k + 12, b, 1);
		world.setBlock(i + 16, j + 1, k + 22, b, 1);
		world.setBlock(i + 16, j + 1, k + 30, b, 1);
		world.setBlock(i + 16, j + 1, k + 43, b, 1);
		world.setBlock(i + 16, j + 1, k + 45, b, 1);
		world.setBlock(i + 16, j + 1, k + 60, Blocks.glass);
		world.setBlock(i + 16, j + 1, k + 68, b, 1);
		world.setBlock(i + 16, j + 2, k + 12, b, 1);
		world.setBlock(i + 16, j + 2, k + 22, b, 1);
		world.setBlock(i + 16, j + 2, k + 30, b, 1);
		world.setBlock(i + 16, j + 2, k + 43, b, 1);
		world.setBlock(i + 16, j + 2, k + 45, b, 1);
		world.setBlock(i + 16, j + 2, k + 60, Blocks.glass);
		world.setBlock(i + 16, j + 2, k + 68, b, 1);
		world.setBlock(i + 16, j + 3, k + 12, b, 1);
		world.setBlock(i + 16, j + 3, k + 22, b, 1);
		world.setBlock(i + 16, j + 3, k + 30, b, 1);
		world.setBlock(i + 16, j + 3, k + 43, b, 1);
		world.setBlock(i + 16, j + 3, k + 45, b, 1);
		world.setBlock(i + 16, j + 3, k + 60, Blocks.glass);
		world.setBlock(i + 16, j + 3, k + 68, b, 1);
		world.setBlock(i + 16, j + 4, k + 12, b, 1);
		world.setBlock(i + 16, j + 4, k + 13, b, 1);
		world.setBlock(i + 16, j + 4, k + 14, b, 1);
		world.setBlock(i + 16, j + 4, k + 15, b, 1);
		world.setBlock(i + 16, j + 4, k + 16, b, 1);
		world.setBlock(i + 16, j + 4, k + 17, b, 1);
		world.setBlock(i + 16, j + 4, k + 18, b, 1);
		world.setBlock(i + 16, j + 4, k + 19, b, 1);
		world.setBlock(i + 16, j + 4, k + 20, b, 1);
		world.setBlock(i + 16, j + 4, k + 21, b, 1);
		world.setBlock(i + 16, j + 4, k + 22, b, 1);
		world.setBlock(i + 16, j + 4, k + 30, b, 1);
		world.setBlock(i + 16, j + 4, k + 31, b, 1);
		world.setBlock(i + 16, j + 4, k + 32, b, 1);
		world.setBlock(i + 16, j + 4, k + 33, b, 1);
		world.setBlock(i + 16, j + 4, k + 34, b, 1);
		world.setBlock(i + 16, j + 4, k + 35, b, 1);
		world.setBlock(i + 16, j + 4, k + 36, b, 1);
		world.setBlock(i + 16, j + 4, k + 37, b, 1);
		world.setBlock(i + 16, j + 4, k + 38, b, 1);
		world.setBlock(i + 16, j + 4, k + 39, b, 1);
		world.setBlock(i + 16, j + 4, k + 40, b, 1);
		world.setBlock(i + 16, j + 4, k + 41, b, 1);
		world.setBlock(i + 16, j + 4, k + 42, b, 1);
		world.setBlock(i + 16, j + 4, k + 43, b, 1);
		world.setBlock(i + 16, j + 4, k + 45, b, 1);
		world.setBlock(i + 16, j + 4, k + 46, b, 1);
		world.setBlock(i + 16, j + 4, k + 47, b, 1);
		world.setBlock(i + 16, j + 4, k + 48, b, 1);
		world.setBlock(i + 16, j + 4, k + 49, b, 1);
		world.setBlock(i + 16, j + 4, k + 50, b, 1);
		world.setBlock(i + 16, j + 4, k + 51, b, 1);
		world.setBlock(i + 16, j + 4, k + 52, b, 1);
		world.setBlock(i + 16, j + 4, k + 53, b, 1);
		world.setBlock(i + 16, j + 4, k + 54, b, 1);
		world.setBlock(i + 16, j + 4, k + 55, b, 1);
		world.setBlock(i + 16, j + 4, k + 56, b, 1);
		world.setBlock(i + 16, j + 4, k + 57, b, 1);
		world.setBlock(i + 16, j + 4, k + 58, b, 1);
		world.setBlock(i + 16, j + 4, k + 59, b, 1);
		world.setBlock(i + 16, j + 4, k + 60, b, 1);
		world.setBlock(i + 16, j + 4, k + 61, b, 1);
		world.setBlock(i + 16, j + 4, k + 62, b, 1);
		world.setBlock(i + 16, j + 4, k + 63, b, 1);
		world.setBlock(i + 16, j + 4, k + 64, b, 1);
		world.setBlock(i + 16, j + 4, k + 65, b, 1);
		world.setBlock(i + 16, j + 4, k + 66, b, 1);
		world.setBlock(i + 16, j + 4, k + 67, b, 1);
		world.setBlock(i + 16, j + 4, k + 68, b, 1);
		world.setBlock(i + 17, j + 0, k + 12, b, 1);
		world.setBlock(i + 17, j + 0, k + 13, b, 0);
		world.setBlock(i + 17, j + 0, k + 14, b, 0);
		world.setBlock(i + 17, j + 0, k + 15, b, 0);
		world.setBlock(i + 17, j + 0, k + 16, b, 0);
		world.setBlock(i + 17, j + 0, k + 17, b, 0);
		world.setBlock(i + 17, j + 0, k + 18, b, 0);
		world.setBlock(i + 17, j + 0, k + 19, b, 0);
		world.setBlock(i + 17, j + 0, k + 20, b, 0);
		world.setBlock(i + 17, j + 0, k + 21, b, 0);
		world.setBlock(i + 17, j + 0, k + 22, b, 1);
		world.setBlock(i + 17, j + 0, k + 30, b, 1);
		world.setBlock(i + 17, j + 0, k + 31, b, 0);
		world.setBlock(i + 17, j + 0, k + 32, b, 0);
		world.setBlock(i + 17, j + 0, k + 33, b, 0);
		world.setBlock(i + 17, j + 0, k + 34, b, 0);
		world.setBlock(i + 17, j + 0, k + 35, b, 0);
		world.setBlock(i + 17, j + 0, k + 36, b, 0);
		world.setBlock(i + 17, j + 0, k + 37, b, 0);
		world.setBlock(i + 17, j + 0, k + 38, b, 0);
		world.setBlock(i + 17, j + 0, k + 39, b, 0);
		world.setBlock(i + 17, j + 0, k + 40, b, 0);
		world.setBlock(i + 17, j + 0, k + 41, b, 0);
		world.setBlock(i + 17, j + 0, k + 42, b, 0);
		world.setBlock(i + 17, j + 0, k + 43, b, 1);
		world.setBlock(i + 17, j + 0, k + 45, b, 1);
		world.setBlock(i + 17, j + 0, k + 46, b, 0);
		world.setBlock(i + 17, j + 0, k + 47, b, 0);
		world.setBlock(i + 17, j + 0, k + 48, b, 0);
		world.setBlock(i + 17, j + 0, k + 49, b, 1);
		world.setBlock(i + 17, j + 0, k + 50, b, 1);
		world.setBlock(i + 17, j + 0, k + 51, b, 1);
		world.setBlock(i + 17, j + 0, k + 52, b, 1);
		world.setBlock(i + 17, j + 0, k + 53, b, 0);
		world.setBlock(i + 17, j + 0, k + 54, b, 0);
		world.setBlock(i + 17, j + 0, k + 55, b, 0);
		world.setBlock(i + 17, j + 0, k + 56, b, 0);
		world.setBlock(i + 17, j + 0, k + 57, b, 0);
		world.setBlock(i + 17, j + 0, k + 58, b, 0);
		world.setBlock(i + 17, j + 0, k + 59, b, 0);
		world.setBlock(i + 17, j + 0, k + 60, b, 0);
		world.setBlock(i + 17, j + 0, k + 61, b, 0);
		world.setBlock(i + 17, j + 0, k + 62, b, 0);
		world.setBlock(i + 17, j + 0, k + 63, b, 0);
		world.setBlock(i + 17, j + 0, k + 64, b, 0);
		world.setBlock(i + 17, j + 0, k + 65, b, 0);
		world.setBlock(i + 17, j + 0, k + 66, b, 0);
		world.setBlock(i + 17, j + 0, k + 67, b, 0);
		world.setBlock(i + 17, j + 0, k + 68, b, 1);
		world.setBlock(i + 17, j + 0, k + 69, b, 1);
		world.setBlock(i + 17, j + 0, k + 70, b, 1);
		world.setBlock(i + 17, j + 0, k + 71, b, 1);
		world.setBlock(i + 17, j + 0, k + 72, b, 1);
		world.setBlock(i + 17, j + 0, k + 73, b, 1);
		world.setBlock(i + 17, j + 0, k + 74, b, 1);
		world.setBlock(i + 17, j + 0, k + 75, b, 1);
		world.setBlock(i + 17, j + 1, k + 12, b, 1);
		world.setBlock(i + 17, j + 1, k + 22, b, 1);
		world.setBlock(i + 17, j + 1, k + 30, b, 1);
		world.setBlock(i + 17, j + 1, k + 43, b, 1);
		world.setBlock(i + 17, j + 1, k + 45, b, 1);
		world.setBlock(i + 17, j + 1, k + 49, b, 1);
		world.setBlock(i + 17, j + 1, k + 50, b, 1);
		world.setBlock(i + 17, j + 1, k + 51, b, 1);
		world.setBlock(i + 17, j + 1, k + 52, b, 1);
		world.setBlock(i + 17, j + 1, k + 60, Blocks.glass);
		world.setBlock(i + 17, j + 1, k + 68, b, 1);
		world.setBlock(i + 17, j + 1, k + 69, b, 1);
		world.setBlock(i + 17, j + 1, k + 70, b, 1);
		world.setBlock(i + 17, j + 1, k + 71, b, 1);
		world.setBlock(i + 17, j + 1, k + 72, b, 1);
		world.setBlock(i + 17, j + 1, k + 73, b, 1);
		world.setBlock(i + 17, j + 1, k + 74, b, 1);
		world.setBlock(i + 17, j + 1, k + 75, b, 1);
		world.setBlock(i + 17, j + 2, k + 12, b, 1);
		world.setBlock(i + 17, j + 2, k + 22, b, 1);
		world.setBlock(i + 17, j + 2, k + 30, b, 1);
		world.setBlock(i + 17, j + 2, k + 43, b, 1);
		world.setBlock(i + 17, j + 2, k + 45, b, 1);
		world.setBlock(i + 17, j + 2, k + 49, b, 1);
		world.setBlock(i + 17, j + 2, k + 50, b, 1);
		world.setBlock(i + 17, j + 2, k + 51, b, 1);
		world.setBlock(i + 17, j + 2, k + 52, b, 1);
		world.setBlock(i + 17, j + 2, k + 60, Blocks.glass);
		world.setBlock(i + 17, j + 2, k + 68, b, 1);
		world.setBlock(i + 17, j + 2, k + 69, b, 1);
		world.setBlock(i + 17, j + 2, k + 70, b, 1);
		world.setBlock(i + 17, j + 2, k + 71, b, 1);
		world.setBlock(i + 17, j + 2, k + 72, b, 1);
		world.setBlock(i + 17, j + 2, k + 73, b, 1);
		world.setBlock(i + 17, j + 2, k + 74, b, 1);
		world.setBlock(i + 17, j + 2, k + 75, b, 1);
		world.setBlock(i + 17, j + 3, k + 12, b, 1);
		world.setBlock(i + 17, j + 3, k + 22, b, 1);
		world.setBlock(i + 17, j + 3, k + 30, b, 1);
		world.setBlock(i + 17, j + 3, k + 43, b, 1);
		world.setBlock(i + 17, j + 3, k + 45, b, 1);
		world.setBlock(i + 17, j + 3, k + 49, b, 1);
		world.setBlock(i + 17, j + 3, k + 50, b, 1);
		world.setBlock(i + 17, j + 3, k + 51, b, 1);
		world.setBlock(i + 17, j + 3, k + 52, b, 1);
		world.setBlock(i + 17, j + 3, k + 60, Blocks.glass);
		world.setBlock(i + 17, j + 3, k + 68, b, 1);
		world.setBlock(i + 17, j + 3, k + 69, b, 1);
		world.setBlock(i + 17, j + 3, k + 70, b, 1);
		world.setBlock(i + 17, j + 3, k + 71, b, 1);
		world.setBlock(i + 17, j + 3, k + 72, b, 1);
		world.setBlock(i + 17, j + 3, k + 73, b, 1);
		world.setBlock(i + 17, j + 3, k + 74, b, 1);
		world.setBlock(i + 17, j + 3, k + 75, b, 1);
		world.setBlock(i + 17, j + 4, k + 12, b, 1);
		world.setBlock(i + 17, j + 4, k + 13, b, 1);
		world.setBlock(i + 17, j + 4, k + 14, b, 1);
		world.setBlock(i + 17, j + 4, k + 15, b, 1);
		world.setBlock(i + 17, j + 4, k + 16, b, 1);
		world.setBlock(i + 17, j + 4, k + 17, b, 1);
		world.setBlock(i + 17, j + 4, k + 18, b, 1);
		world.setBlock(i + 17, j + 4, k + 19, b, 1);
		world.setBlock(i + 17, j + 4, k + 20, b, 1);
		world.setBlock(i + 17, j + 4, k + 21, b, 1);
		world.setBlock(i + 17, j + 4, k + 22, b, 1);
		world.setBlock(i + 17, j + 4, k + 30, b, 1);
		world.setBlock(i + 17, j + 4, k + 31, b, 1);
		world.setBlock(i + 17, j + 4, k + 32, b, 1);
		world.setBlock(i + 17, j + 4, k + 33, b, 1);
		world.setBlock(i + 17, j + 4, k + 34, b, 1);
		world.setBlock(i + 17, j + 4, k + 35, b, 1);
		world.setBlock(i + 17, j + 4, k + 36, b, 1);
		world.setBlock(i + 17, j + 4, k + 37, b, 1);
		world.setBlock(i + 17, j + 4, k + 38, b, 1);
		world.setBlock(i + 17, j + 4, k + 39, b, 1);
		world.setBlock(i + 17, j + 4, k + 40, b, 1);
		world.setBlock(i + 17, j + 4, k + 41, b, 1);
		world.setBlock(i + 17, j + 4, k + 42, b, 1);
		world.setBlock(i + 17, j + 4, k + 43, b, 1);
		world.setBlock(i + 17, j + 4, k + 45, b, 1);
		world.setBlock(i + 17, j + 4, k + 46, b, 1);
		world.setBlock(i + 17, j + 4, k + 47, b, 1);
		world.setBlock(i + 17, j + 4, k + 48, b, 1);
		world.setBlock(i + 17, j + 4, k + 49, b, 1);
		world.setBlock(i + 17, j + 4, k + 50, b, 1);
		world.setBlock(i + 17, j + 4, k + 51, b, 1);
		world.setBlock(i + 17, j + 4, k + 52, b, 1);
		world.setBlock(i + 17, j + 4, k + 53, b, 1);
		world.setBlock(i + 17, j + 4, k + 54, b, 1);
		world.setBlock(i + 17, j + 4, k + 55, b, 1);
		world.setBlock(i + 17, j + 4, k + 56, b, 1);
		world.setBlock(i + 17, j + 4, k + 57, b, 1);
		world.setBlock(i + 17, j + 4, k + 58, b, 1);
		world.setBlock(i + 17, j + 4, k + 59, b, 1);
		world.setBlock(i + 17, j + 4, k + 60, b, 1);
		world.setBlock(i + 17, j + 4, k + 61, b, 1);
		world.setBlock(i + 17, j + 4, k + 62, b, 1);
		world.setBlock(i + 17, j + 4, k + 63, b, 1);
		world.setBlock(i + 17, j + 4, k + 64, b, 1);
		world.setBlock(i + 17, j + 4, k + 65, b, 1);
		world.setBlock(i + 17, j + 4, k + 66, b, 1);
		world.setBlock(i + 17, j + 4, k + 67, b, 1);
		world.setBlock(i + 17, j + 4, k + 68, b, 1);
		world.setBlock(i + 17, j + 4, k + 69, b, 1);
		world.setBlock(i + 17, j + 4, k + 70, b, 1);
		world.setBlock(i + 17, j + 4, k + 71, b, 1);
		world.setBlock(i + 17, j + 4, k + 72, b, 1);
		world.setBlock(i + 17, j + 4, k + 73, b, 1);
		world.setBlock(i + 17, j + 4, k + 74, b, 1);
		world.setBlock(i + 17, j + 4, k + 75, b, 1);
		world.setBlock(i + 18, j + 0, k + 12, b, 1);
		world.setBlock(i + 18, j + 0, k + 13, b, 0);
		world.setBlock(i + 18, j + 0, k + 14, b, 0);
		world.setBlock(i + 18, j + 0, k + 15, b, 0);
		world.setBlock(i + 18, j + 0, k + 16, b, 1);
		world.setBlock(i + 18, j + 0, k + 17, b, 1);
		world.setBlock(i + 18, j + 0, k + 18, b, 1);
		world.setBlock(i + 18, j + 0, k + 19, b, 0);
		world.setBlock(i + 18, j + 0, k + 20, b, 0);
		world.setBlock(i + 18, j + 0, k + 21, b, 0);
		world.setBlock(i + 18, j + 0, k + 22, b, 1);
		world.setBlock(i + 18, j + 0, k + 23, b, 1);
		world.setBlock(i + 18, j + 0, k + 24, b, 1);
		world.setBlock(i + 18, j + 0, k + 25, b, 1);
		world.setBlock(i + 18, j + 0, k + 26, b, 1);
		world.setBlock(i + 18, j + 0, k + 27, b, 1);
		world.setBlock(i + 18, j + 0, k + 28, b, 1);
		world.setBlock(i + 18, j + 0, k + 29, b, 1);
		world.setBlock(i + 18, j + 0, k + 30, b, 1);
		world.setBlock(i + 18, j + 0, k + 31, b, 0);
		world.setBlock(i + 18, j + 0, k + 32, b, 0);
		world.setBlock(i + 18, j + 0, k + 33, b, 0);
		world.setBlock(i + 18, j + 0, k + 34, b, 0);
		world.setBlock(i + 18, j + 0, k + 35, b, 0);
		world.setBlock(i + 18, j + 0, k + 36, b, 0);
		world.setBlock(i + 18, j + 0, k + 37, b, 0);
		world.setBlock(i + 18, j + 0, k + 38, b, 0);
		world.setBlock(i + 18, j + 0, k + 39, b, 0);
		world.setBlock(i + 18, j + 0, k + 40, b, 0);
		world.setBlock(i + 18, j + 0, k + 41, b, 0);
		world.setBlock(i + 18, j + 0, k + 42, b, 0);
		world.setBlock(i + 18, j + 0, k + 43, b, 1);
		world.setBlock(i + 18, j + 0, k + 45, b, 1);
		world.setBlock(i + 18, j + 0, k + 46, b, 0);
		world.setBlock(i + 18, j + 0, k + 47, b, 0);
		world.setBlock(i + 18, j + 0, k + 48, b, 0);
		world.setBlock(i + 18, j + 0, k + 49, b, 1);
		world.setBlock(i + 18, j + 0, k + 52, b, 1);
		world.setBlock(i + 18, j + 0, k + 53, b, 0);
		world.setBlock(i + 18, j + 0, k + 54, b, 0);
		world.setBlock(i + 18, j + 0, k + 55, b, 0);
		world.setBlock(i + 18, j + 0, k + 56, b, 0);
		world.setBlock(i + 18, j + 0, k + 57, b, 0);
		world.setBlock(i + 18, j + 0, k + 58, b, 0);
		world.setBlock(i + 18, j + 0, k + 59, b, 0);
		world.setBlock(i + 18, j + 0, k + 60, b, 0);
		world.setBlock(i + 18, j + 0, k + 61, b, 0);
		world.setBlock(i + 18, j + 0, k + 62, b, 0);
		world.setBlock(i + 18, j + 0, k + 63, b, 0);
		world.setBlock(i + 18, j + 0, k + 64, b, 0);
		world.setBlock(i + 18, j + 0, k + 65, b, 0);
		world.setBlock(i + 18, j + 0, k + 66, b, 0);
		world.setBlock(i + 18, j + 0, k + 67, b, 0);
		world.setBlock(i + 18, j + 0, k + 68, b, 0);
		world.setBlock(i + 18, j + 0, k + 69, b, 0);
		world.setBlock(i + 18, j + 0, k + 70, b, 0);
		world.setBlock(i + 18, j + 0, k + 71, b, 0);
		world.setBlock(i + 18, j + 0, k + 72, b, 0);
		world.setBlock(i + 18, j + 0, k + 73, b, 0);
		world.setBlock(i + 18, j + 0, k + 74, b, 0);
		world.setBlock(i + 18, j + 0, k + 75, b, 1);
		world.setBlock(i + 18, j + 1, k + 12, b, 1);
		world.setBlock(i + 18, j + 1, k + 16, b, 1);
		world.setBlock(i + 18, j + 1, k + 17, b, 1);
		world.setBlock(i + 18, j + 1, k + 18, b, 1);
		world.setBlock(i + 18, j + 1, k + 22, b, 1);
		world.setBlock(i + 18, j + 1, k + 23, b, 1);
		world.setBlock(i + 18, j + 1, k + 24, b, 1);
		world.setBlock(i + 18, j + 1, k + 25, b, 1);
		world.setBlock(i + 18, j + 1, k + 26, b, 1);
		world.setBlock(i + 18, j + 1, k + 27, b, 1);
		world.setBlock(i + 18, j + 1, k + 28, b, 1);
		world.setBlock(i + 18, j + 1, k + 29, b, 1);
		world.setBlock(i + 18, j + 1, k + 30, b, 1);
		world.setBlock(i + 18, j + 1, k + 43, b, 1);
		world.setBlock(i + 18, j + 1, k + 45, b, 1);
		world.setBlock(i + 18, j + 1, k + 47, -5);
		world.setBlock(i + 18, j + 1, k + 49, b, 1);
		world.setBlock(i + 18, j + 1, k + 52, b, 1);
		world.setBlock(i + 18, j + 1, k + 60, Blocks.glass);
		world.setBlock(i + 18, j + 1, k + 75, b, 1);
		world.setBlock(i + 18, j + 2, k + 12, b, 1);
		world.setBlock(i + 18, j + 2, k + 16, b, 1);
		world.setBlock(i + 18, j + 2, k + 17, b, 1);
		world.setBlock(i + 18, j + 2, k + 18, b, 1);
		world.setBlock(i + 18, j + 2, k + 22, b, 1);
		world.setBlock(i + 18, j + 2, k + 23, b, 1);
		world.setBlock(i + 18, j + 2, k + 24, b, 1);
		world.setBlock(i + 18, j + 2, k + 25, b, 1);
		world.setBlock(i + 18, j + 2, k + 26, b, 1);
		world.setBlock(i + 18, j + 2, k + 27, b, 1);
		world.setBlock(i + 18, j + 2, k + 28, b, 1);
		world.setBlock(i + 18, j + 2, k + 29, b, 1);
		world.setBlock(i + 18, j + 2, k + 30, b, 1);
		world.setBlock(i + 18, j + 2, k + 43, b, 1);
		world.setBlock(i + 18, j + 2, k + 45, b, 1);
		world.setBlock(i + 18, j + 2, k + 49, b, 1);
		world.setBlock(i + 18, j + 2, k + 52, b, 1);
		world.setBlock(i + 18, j + 2, k + 60, Blocks.glass);
		world.setBlock(i + 18, j + 2, k + 75, b, 1);
		world.setBlock(i + 18, j + 3, k + 12, b, 1);
		world.setBlock(i + 18, j + 3, k + 16, b, 1);
		world.setBlock(i + 18, j + 3, k + 17, b, 1);
		world.setBlock(i + 18, j + 3, k + 18, b, 1);
		world.setBlock(i + 18, j + 3, k + 22, b, 1);
		world.setBlock(i + 18, j + 3, k + 23, b, 1);
		world.setBlock(i + 18, j + 3, k + 24, b, 1);
		world.setBlock(i + 18, j + 3, k + 25, b, 1);
		world.setBlock(i + 18, j + 3, k + 26, b, 1);
		world.setBlock(i + 18, j + 3, k + 27, b, 1);
		world.setBlock(i + 18, j + 3, k + 28, b, 1);
		world.setBlock(i + 18, j + 3, k + 29, b, 1);
		world.setBlock(i + 18, j + 3, k + 30, b, 1);
		world.setBlock(i + 18, j + 3, k + 43, b, 1);
		world.setBlock(i + 18, j + 3, k + 45, b, 1);
		world.setBlock(i + 18, j + 3, k + 49, b, 1);
		world.setBlock(i + 18, j + 3, k + 52, b, 1);
		world.setBlock(i + 18, j + 3, k + 60, Blocks.glass);
		world.setBlock(i + 18, j + 3, k + 75, b, 1);
		world.setBlock(i + 18, j + 4, k + 12, b, 1);
		world.setBlock(i + 18, j + 4, k + 13, b, 1);
		world.setBlock(i + 18, j + 4, k + 14, b, 1);
		world.setBlock(i + 18, j + 4, k + 15, b, 1);
		world.setBlock(i + 18, j + 4, k + 16, b, 1);
		world.setBlock(i + 18, j + 4, k + 17, b, 1);
		world.setBlock(i + 18, j + 4, k + 18, b, 1);
		world.setBlock(i + 18, j + 4, k + 19, b, 1);
		world.setBlock(i + 18, j + 4, k + 20, b, 1);
		world.setBlock(i + 18, j + 4, k + 21, b, 1);
		world.setBlock(i + 18, j + 4, k + 22, b, 1);
		world.setBlock(i + 18, j + 4, k + 23, b, 1);
		world.setBlock(i + 18, j + 4, k + 24, b, 1);
		world.setBlock(i + 18, j + 4, k + 25, b, 1);
		world.setBlock(i + 18, j + 4, k + 26, b, 1);
		world.setBlock(i + 18, j + 4, k + 27, b, 1);
		world.setBlock(i + 18, j + 4, k + 28, b, 1);
		world.setBlock(i + 18, j + 4, k + 29, b, 1);
		world.setBlock(i + 18, j + 4, k + 30, b, 1);
		world.setBlock(i + 18, j + 4, k + 31, b, 1);
		world.setBlock(i + 18, j + 4, k + 32, b, 1);
		world.setBlock(i + 18, j + 4, k + 33, b, 1);
		world.setBlock(i + 18, j + 4, k + 34, b, 1);
		world.setBlock(i + 18, j + 4, k + 35, b, 1);
		world.setBlock(i + 18, j + 4, k + 36, b, 1);
		world.setBlock(i + 18, j + 4, k + 37, b, 1);
		world.setBlock(i + 18, j + 4, k + 38, b, 1);
		world.setBlock(i + 18, j + 4, k + 39, b, 1);
		world.setBlock(i + 18, j + 4, k + 40, b, 1);
		world.setBlock(i + 18, j + 4, k + 41, b, 1);
		world.setBlock(i + 18, j + 4, k + 42, b, 1);
		world.setBlock(i + 18, j + 4, k + 43, b, 1);
		world.setBlock(i + 18, j + 4, k + 45, b, 1);
		world.setBlock(i + 18, j + 4, k + 46, b, 1);
		world.setBlock(i + 18, j + 4, k + 47, b, 1);
		world.setBlock(i + 18, j + 4, k + 48, b, 1);
		world.setBlock(i + 18, j + 4, k + 49, b, 1);
		world.setBlock(i + 18, j + 4, k + 50, b, 1);
		world.setBlock(i + 18, j + 4, k + 51, b, 1);
		world.setBlock(i + 18, j + 4, k + 52, b, 1);
		world.setBlock(i + 18, j + 4, k + 53, b, 1);
		world.setBlock(i + 18, j + 4, k + 54, b, 1);
		world.setBlock(i + 18, j + 4, k + 55, b, 1);
		world.setBlock(i + 18, j + 4, k + 56, b, 1);
		world.setBlock(i + 18, j + 4, k + 57, b, 1);
		world.setBlock(i + 18, j + 4, k + 58, b, 1);
		world.setBlock(i + 18, j + 4, k + 59, b, 1);
		world.setBlock(i + 18, j + 4, k + 60, b, 1);
		world.setBlock(i + 18, j + 4, k + 61, b, 1);
		world.setBlock(i + 18, j + 4, k + 62, b, 1);
		world.setBlock(i + 18, j + 4, k + 63, b, 1);
		world.setBlock(i + 18, j + 4, k + 64, b, 1);
		world.setBlock(i + 18, j + 4, k + 65, b, 1);
		world.setBlock(i + 18, j + 4, k + 66, b, 1);
		world.setBlock(i + 18, j + 4, k + 67, b, 1);
		world.setBlock(i + 18, j + 4, k + 68, b, 1);
		world.setBlock(i + 18, j + 4, k + 69, b, 1);
		world.setBlock(i + 18, j + 4, k + 70, b, 1);
		world.setBlock(i + 18, j + 4, k + 71, b, 1);
		world.setBlock(i + 18, j + 4, k + 72, b, 1);
		world.setBlock(i + 18, j + 4, k + 73, b, 1);
		world.setBlock(i + 18, j + 4, k + 74, b, 1);
		world.setBlock(i + 18, j + 4, k + 75, b, 1);
		world.setBlock(i + 19, j + 0, k + 12, b, 1);
		world.setBlock(i + 19, j + 0, k + 13, b, 0);
		world.setBlock(i + 19, j + 0, k + 14, b, 0);
		world.setBlock(i + 19, j + 0, k + 15, b, 0);
		world.setBlock(i + 19, j + 0, k + 16, b, 0);
		world.setBlock(i + 19, j + 0, k + 17, b, 0);
		world.setBlock(i + 19, j + 0, k + 18, b, 0);
		world.setBlock(i + 19, j + 0, k + 19, b, 0);
		world.setBlock(i + 19, j + 0, k + 20, b, 0);
		world.setBlock(i + 19, j + 0, k + 21, b, 0);
		world.setBlock(i + 19, j + 0, k + 22, b, 0);
		world.setBlock(i + 19, j + 0, k + 23, b, 0);
		world.setBlock(i + 19, j + 0, k + 24, b, 0);
		world.setBlock(i + 19, j + 0, k + 25, b, 0);
		world.setBlock(i + 19, j + 0, k + 26, b, 0);
		world.setBlock(i + 19, j + 0, k + 27, b, 0);
		world.setBlock(i + 19, j + 0, k + 28, b, 0);
		world.setBlock(i + 19, j + 0, k + 29, b, 0);
		world.setBlock(i + 19, j + 0, k + 30, b, 1);
		world.setBlock(i + 19, j + 0, k + 31, b, 0);
		world.setBlock(i + 19, j + 0, k + 32, b, 0);
		world.setBlock(i + 19, j + 0, k + 33, b, 0);
		world.setBlock(i + 19, j + 0, k + 34, b, 1);
		world.setBlock(i + 19, j + 0, k + 35, b, 1);
		world.setBlock(i + 19, j + 0, k + 36, b, 1);
		world.setBlock(i + 19, j + 0, k + 37, b, 1);
		world.setBlock(i + 19, j + 0, k + 38, b, 1);
		world.setBlock(i + 19, j + 0, k + 39, b, 1);
		world.setBlock(i + 19, j + 0, k + 40, b, 0);
		world.setBlock(i + 19, j + 0, k + 41, b, 0);
		world.setBlock(i + 19, j + 0, k + 42, b, 0);
		world.setBlock(i + 19, j + 0, k + 43, b, 1);
		world.setBlock(i + 19, j + 0, k + 45, b, 1);
		world.setBlock(i + 19, j + 0, k + 46, b, 0);
		world.setBlock(i + 19, j + 0, k + 47, b, 0);
		world.setBlock(i + 19, j + 0, k + 48, b, 0);
		world.setBlock(i + 19, j + 0, k + 49, b, 1);
		world.setBlock(i + 19, j + 0, k + 50, b, 1);
		world.setBlock(i + 19, j + 0, k + 51, b, 1);
		world.setBlock(i + 19, j + 0, k + 52, b, 1);
		world.setBlock(i + 19, j + 0, k + 53, b, 0);
		world.setBlock(i + 19, j + 0, k + 54, b, 0);
		world.setBlock(i + 19, j + 0, k + 55, b, 0);
		world.setBlock(i + 19, j + 0, k + 56, b, 0);
		world.setBlock(i + 19, j + 0, k + 57, b, 0);
		world.setBlock(i + 19, j + 0, k + 58, b, 0);
		world.setBlock(i + 19, j + 0, k + 59, b, 0);
		world.setBlock(i + 19, j + 0, k + 60, b, 0);
		world.setBlock(i + 19, j + 0, k + 61, b, 0);
		world.setBlock(i + 19, j + 0, k + 62, b, 0);
		world.setBlock(i + 19, j + 0, k + 63, b, 0);
		world.setBlock(i + 19, j + 0, k + 64, b, 0);
		world.setBlock(i + 19, j + 0, k + 65, b, 0);
		world.setBlock(i + 19, j + 0, k + 66, b, 0);
		world.setBlock(i + 19, j + 0, k + 67, b, 0);
		world.setBlock(i + 19, j + 0, k + 68, b, 0);
		world.setBlock(i + 19, j + 0, k + 69, b, 0);
		world.setBlock(i + 19, j + 0, k + 70, b, 0);
		world.setBlock(i + 19, j + 0, k + 71, b, 0);
		world.setBlock(i + 19, j + 0, k + 72, b, 0);
		world.setBlock(i + 19, j + 0, k + 73, b, 0);
		world.setBlock(i + 19, j + 0, k + 74, b, 0);
		world.setBlock(i + 19, j + 0, k + 75, b, 1);
		world.setBlock(i + 19, j + 1, k + 12, b, 1);
		world.setBlock(i + 19, j + 1, k + 30, b, 1);
		world.setBlock(i + 19, j + 1, k + 34, b, 1);
		world.setBlock(i + 19, j + 1, k + 35, b, 1);
		world.setBlock(i + 19, j + 1, k + 36, b, 1);
		world.setBlock(i + 19, j + 1, k + 37, b, 1);
		world.setBlock(i + 19, j + 1, k + 38, b, 1);
		world.setBlock(i + 19, j + 1, k + 39, b, 1);
		world.setBlock(i + 19, j + 1, k + 43, b, 1);
		world.setBlock(i + 19, j + 1, k + 45, b, 1);
		world.setBlock(i + 19, j + 1, k + 49, b, 1);
		world.setBlock(i + 19, j + 1, k + 50, b, 1);
		world.setBlock(i + 19, j + 1, k + 51, b, 1);
		world.setBlock(i + 19, j + 1, k + 52, b, 1);
		world.setBlock(i + 19, j + 1, k + 60, Blocks.glass);
		world.setBlock(i + 19, j + 1, k + 75, b, 1);
		world.setBlock(i + 19, j + 2, k + 12, b, 1);
		world.setBlock(i + 19, j + 2, k + 30, b, 1);
		world.setBlock(i + 19, j + 2, k + 34, b, 1);
		world.setBlock(i + 19, j + 2, k + 35, b, 1);
		world.setBlock(i + 19, j + 2, k + 36, b, 1);
		world.setBlock(i + 19, j + 2, k + 37, b, 1);
		world.setBlock(i + 19, j + 2, k + 38, b, 1);
		world.setBlock(i + 19, j + 2, k + 39, b, 1);
		world.setBlock(i + 19, j + 2, k + 43, b, 1);
		world.setBlock(i + 19, j + 2, k + 45, b, 1);
		world.setBlock(i + 19, j + 2, k + 49, b, 1);
		world.setBlock(i + 19, j + 2, k + 50, b, 1);
		world.setBlock(i + 19, j + 2, k + 51, b, 1);
		world.setBlock(i + 19, j + 2, k + 52, b, 1);
		world.setBlock(i + 19, j + 2, k + 60, Blocks.glass);
		world.setBlock(i + 19, j + 2, k + 75, b, 1);
		world.setBlock(i + 19, j + 3, k + 12, b, 1);
		world.setBlock(i + 19, j + 3, k + 30, b, 1);
		world.setBlock(i + 19, j + 3, k + 34, b, 1);
		world.setBlock(i + 19, j + 3, k + 35, b, 1);
		world.setBlock(i + 19, j + 3, k + 36, b, 1);
		world.setBlock(i + 19, j + 3, k + 37, b, 1);
		world.setBlock(i + 19, j + 3, k + 38, b, 1);
		world.setBlock(i + 19, j + 3, k + 39, b, 1);
		world.setBlock(i + 19, j + 3, k + 43, b, 1);
		world.setBlock(i + 19, j + 3, k + 45, b, 1);
		world.setBlock(i + 19, j + 3, k + 49, b, 1);
		world.setBlock(i + 19, j + 3, k + 50, b, 1);
		world.setBlock(i + 19, j + 3, k + 51, b, 1);
		world.setBlock(i + 19, j + 3, k + 52, b, 1);
		world.setBlock(i + 19, j + 3, k + 60, Blocks.glass);
		world.setBlock(i + 19, j + 3, k + 75, b, 1);
		world.setBlock(i + 19, j + 4, k + 12, b, 1);
		world.setBlock(i + 19, j + 4, k + 13, b, 1);
		world.setBlock(i + 19, j + 4, k + 14, b, 1);
		world.setBlock(i + 19, j + 4, k + 15, b, 1);
		world.setBlock(i + 19, j + 4, k + 16, b, 1);
		world.setBlock(i + 19, j + 4, k + 17, b, 1);
		world.setBlock(i + 19, j + 4, k + 18, b, 1);
		world.setBlock(i + 19, j + 4, k + 19, b, 1);
		world.setBlock(i + 19, j + 4, k + 20, b, 1);
		world.setBlock(i + 19, j + 4, k + 21, b, 1);
		world.setBlock(i + 19, j + 4, k + 22, b, 1);
		world.setBlock(i + 19, j + 4, k + 23, b, 1);
		world.setBlock(i + 19, j + 4, k + 24, b, 1);
		world.setBlock(i + 19, j + 4, k + 25, b, 1);
		world.setBlock(i + 19, j + 4, k + 26, b, 1);
		world.setBlock(i + 19, j + 4, k + 27, b, 1);
		world.setBlock(i + 19, j + 4, k + 28, b, 1);
		world.setBlock(i + 19, j + 4, k + 29, b, 1);
		world.setBlock(i + 19, j + 4, k + 30, b, 1);
		world.setBlock(i + 19, j + 4, k + 31, b, 1);
		world.setBlock(i + 19, j + 4, k + 32, b, 1);
		world.setBlock(i + 19, j + 4, k + 33, b, 1);
		world.setBlock(i + 19, j + 4, k + 34, b, 1);
		world.setBlock(i + 19, j + 4, k + 35, b, 1);
		world.setBlock(i + 19, j + 4, k + 36, b, 1);
		world.setBlock(i + 19, j + 4, k + 37, b, 1);
		world.setBlock(i + 19, j + 4, k + 38, b, 1);
		world.setBlock(i + 19, j + 4, k + 39, b, 1);
		world.setBlock(i + 19, j + 4, k + 40, b, 1);
		world.setBlock(i + 19, j + 4, k + 41, b, 1);
		world.setBlock(i + 19, j + 4, k + 42, b, 1);
		world.setBlock(i + 19, j + 4, k + 43, b, 1);
		world.setBlock(i + 19, j + 4, k + 45, b, 1);
		world.setBlock(i + 19, j + 4, k + 46, b, 1);
		world.setBlock(i + 19, j + 4, k + 47, b, 1);
		world.setBlock(i + 19, j + 4, k + 48, b, 1);
		world.setBlock(i + 19, j + 4, k + 49, b, 1);
		world.setBlock(i + 19, j + 4, k + 50, b, 1);
		world.setBlock(i + 19, j + 4, k + 51, b, 1);
		world.setBlock(i + 19, j + 4, k + 52, b, 1);
		world.setBlock(i + 19, j + 4, k + 53, b, 1);
		world.setBlock(i + 19, j + 4, k + 54, b, 1);
		world.setBlock(i + 19, j + 4, k + 55, b, 1);
		world.setBlock(i + 19, j + 4, k + 56, b, 1);
		world.setBlock(i + 19, j + 4, k + 57, b, 1);
		world.setBlock(i + 19, j + 4, k + 58, b, 1);
		world.setBlock(i + 19, j + 4, k + 59, b, 1);
		world.setBlock(i + 19, j + 4, k + 60, b, 1);
		world.setBlock(i + 19, j + 4, k + 61, b, 1);
		world.setBlock(i + 19, j + 4, k + 62, b, 1);
		world.setBlock(i + 19, j + 4, k + 63, b, 1);
		world.setBlock(i + 19, j + 4, k + 64, b, 1);
		world.setBlock(i + 19, j + 4, k + 65, b, 1);
		world.setBlock(i + 19, j + 4, k + 66, b, 1);
		world.setBlock(i + 19, j + 4, k + 67, b, 1);
		world.setBlock(i + 19, j + 4, k + 68, b, 1);
		world.setBlock(i + 19, j + 4, k + 69, b, 1);
		world.setBlock(i + 19, j + 4, k + 70, b, 1);
		world.setBlock(i + 19, j + 4, k + 71, b, 1);
		world.setBlock(i + 19, j + 4, k + 72, b, 1);
		world.setBlock(i + 19, j + 4, k + 73, b, 1);
		world.setBlock(i + 19, j + 4, k + 74, b, 1);
		world.setBlock(i + 19, j + 4, k + 75, b, 1);
		world.setBlock(i + 20, j + 0, k + 12, b, 1);
		world.setBlock(i + 20, j + 0, k + 13, b, 0);
		world.setBlock(i + 20, j + 0, k + 14, b, 0);
		world.setBlock(i + 20, j + 0, k + 15, b, 0);
		world.setBlock(i + 20, j + 0, k + 16, b, 0);
		world.setBlock(i + 20, j + 0, k + 17, b, 0);
		world.setBlock(i + 20, j + 0, k + 18, b, 0);
		world.setBlock(i + 20, j + 0, k + 19, b, 0);
		world.setBlock(i + 20, j + 0, k + 20, b, 0);
		world.setBlock(i + 20, j + 0, k + 21, b, 0);
		world.setBlock(i + 20, j + 0, k + 22, b, 0);
		world.setBlock(i + 20, j + 0, k + 23, b, 0);
		world.setBlock(i + 20, j + 0, k + 24, b, 0);
		world.setBlock(i + 20, j + 0, k + 25, b, 0);
		world.setBlock(i + 20, j + 0, k + 26, b, 0);
		world.setBlock(i + 20, j + 0, k + 27, b, 0);
		world.setBlock(i + 20, j + 0, k + 28, b, 0);
		world.setBlock(i + 20, j + 0, k + 29, b, 0);
		world.setBlock(i + 20, j + 0, k + 30, b, 1);
		world.setBlock(i + 20, j + 0, k + 31, b, 0);
		world.setBlock(i + 20, j + 0, k + 32, b, 0);
		world.setBlock(i + 20, j + 0, k + 33, b, 0);
		world.setBlock(i + 20, j + 0, k + 34, b, 1);
		world.setBlock(i + 20, j + 0, k + 39, b, 1);
		world.setBlock(i + 20, j + 0, k + 40, b, 0);
		world.setBlock(i + 20, j + 0, k + 41, b, 0);
		world.setBlock(i + 20, j + 0, k + 42, b, 0);
		world.setBlock(i + 20, j + 0, k + 43, b, 1);
		world.setBlock(i + 20, j + 0, k + 45, b, 1);
		world.setBlock(i + 20, j + 0, k + 46, b, 0);
		world.setBlock(i + 20, j + 0, k + 47, b, 0);
		world.setBlock(i + 20, j + 0, k + 48, b, 0);
		world.setBlock(i + 20, j + 0, k + 49, b, 0);
		world.setBlock(i + 20, j + 0, k + 50, b, 0);
		world.setBlock(i + 20, j + 0, k + 51, b, 0);
		world.setBlock(i + 20, j + 0, k + 52, b, 1);
		world.setBlock(i + 20, j + 0, k + 53, b, 0);
		world.setBlock(i + 20, j + 0, k + 54, b, 0);
		world.setBlock(i + 20, j + 0, k + 55, b, 0);
		world.setBlock(i + 20, j + 0, k + 56, b, 0);
		world.setBlock(i + 20, j + 0, k + 57, b, 0);
		world.setBlock(i + 20, j + 0, k + 58, b, 0);
		world.setBlock(i + 20, j + 0, k + 59, b, 0);
		world.setBlock(i + 20, j + 0, k + 60, b, 0);
		world.setBlock(i + 20, j + 0, k + 61, b, 0);
		world.setBlock(i + 20, j + 0, k + 62, b, 0);
		world.setBlock(i + 20, j + 0, k + 63, b, 0);
		world.setBlock(i + 20, j + 0, k + 64, b, 0);
		world.setBlock(i + 20, j + 0, k + 65, b, 0);
		world.setBlock(i + 20, j + 0, k + 66, b, 0);
		world.setBlock(i + 20, j + 0, k + 67, b, 0);
		world.setBlock(i + 20, j + 0, k + 68, b, 0);
		world.setBlock(i + 20, j + 0, k + 69, b, 0);
		world.setBlock(i + 20, j + 0, k + 70, b, 0);
		world.setBlock(i + 20, j + 0, k + 71, b, 0);
		world.setBlock(i + 20, j + 0, k + 72, b, 0);
		world.setBlock(i + 20, j + 0, k + 73, b, 0);
		world.setBlock(i + 20, j + 0, k + 74, b, 0);
		world.setBlock(i + 20, j + 0, k + 75, b, 1);
		world.setBlock(i + 20, j + 1, k + 12, b, 1);
		world.setBlock(i + 20, j + 1, k + 16, -5);
		world.setBlock(i + 20, j + 1, k + 24, -5);
		world.setBlock(i + 20, j + 1, k + 30, b, 1);
		world.setBlock(i + 20, j + 1, k + 34, b, 1);
		world.setBlock(i + 20, j + 1, k + 39, b, 1);
		world.setBlock(i + 20, j + 1, k + 43, b, 1);
		world.setBlock(i + 20, j + 1, k + 45, b, 1);
		world.setBlock(i + 20, j + 1, k + 52, b, 1);
		world.setBlock(i + 20, j + 1, k + 55, Blocks.bedrock);
		world.setBlock(i + 20, j + 1, k + 56, Blocks.bedrock);
		world.setBlock(i + 20, j + 1, k + 57, Blocks.bedrock);
		world.setBlock(i + 20, j + 1, k + 60, Blocks.glass);
		world.setBlock(i + 20, j + 1, k + 75, b, 1);
		world.setBlock(i + 20, j + 2, k + 12, b, 1);
		world.setBlock(i + 20, j + 2, k + 30, b, 1);
		world.setBlock(i + 20, j + 2, k + 34, b, 1);
		world.setBlock(i + 20, j + 2, k + 39, b, 1);
		world.setBlock(i + 20, j + 2, k + 43, b, 1);
		world.setBlock(i + 20, j + 2, k + 45, b, 1);
		world.setBlock(i + 20, j + 2, k + 52, b, 1);
		world.setBlock(i + 20, j + 2, k + 55, Blocks.bedrock);
		world.setBlock(i + 20, j + 2, k + 56, -33, 6);
		world.setBlock(i + 20, j + 2, k + 57, Blocks.bedrock);
		world.setBlock(i + 20, j + 2, k + 60, Blocks.glass);
		world.setBlock(i + 20, j + 2, k + 75, b, 1);
		world.setBlock(i + 20, j + 3, k + 12, b, 1);
		world.setBlock(i + 20, j + 3, k + 30, b, 1);
		world.setBlock(i + 20, j + 3, k + 34, b, 1);
		world.setBlock(i + 20, j + 3, k + 39, b, 1);
		world.setBlock(i + 20, j + 3, k + 43, b, 1);
		world.setBlock(i + 20, j + 3, k + 45, b, 1);
		world.setBlock(i + 20, j + 3, k + 52, b, 1);
		world.setBlock(i + 20, j + 3, k + 55, Blocks.bedrock);
		world.setBlock(i + 20, j + 3, k + 56, Blocks.bedrock);
		world.setBlock(i + 20, j + 3, k + 57, Blocks.bedrock);
		world.setBlock(i + 20, j + 3, k + 60, Blocks.glass);
		world.setBlock(i + 20, j + 3, k + 75, b, 1);
		world.setBlock(i + 20, j + 4, k + 12, b, 1);
		world.setBlock(i + 20, j + 4, k + 13, b, 1);
		world.setBlock(i + 20, j + 4, k + 14, b, 1);
		world.setBlock(i + 20, j + 4, k + 15, b, 1);
		world.setBlock(i + 20, j + 4, k + 16, b, 1);
		world.setBlock(i + 20, j + 4, k + 17, b, 1);
		world.setBlock(i + 20, j + 4, k + 18, b, 1);
		world.setBlock(i + 20, j + 4, k + 19, b, 1);
		world.setBlock(i + 20, j + 4, k + 20, b, 1);
		world.setBlock(i + 20, j + 4, k + 21, b, 1);
		world.setBlock(i + 20, j + 4, k + 22, b, 1);
		world.setBlock(i + 20, j + 4, k + 23, b, 1);
		world.setBlock(i + 20, j + 4, k + 24, b, 1);
		world.setBlock(i + 20, j + 4, k + 25, b, 1);
		world.setBlock(i + 20, j + 4, k + 26, b, 1);
		world.setBlock(i + 20, j + 4, k + 27, b, 1);
		world.setBlock(i + 20, j + 4, k + 28, b, 1);
		world.setBlock(i + 20, j + 4, k + 29, b, 1);
		world.setBlock(i + 20, j + 4, k + 30, b, 1);
		world.setBlock(i + 20, j + 4, k + 31, b, 1);
		world.setBlock(i + 20, j + 4, k + 32, b, 1);
		world.setBlock(i + 20, j + 4, k + 33, b, 1);
		world.setBlock(i + 20, j + 4, k + 34, b, 1);
		world.setBlock(i + 20, j + 4, k + 39, b, 1);
		world.setBlock(i + 20, j + 4, k + 40, b, 1);
		world.setBlock(i + 20, j + 4, k + 41, b, 1);
		world.setBlock(i + 20, j + 4, k + 42, b, 1);
		world.setBlock(i + 20, j + 4, k + 43, b, 1);
		world.setBlock(i + 20, j + 4, k + 45, b, 1);
		world.setBlock(i + 20, j + 4, k + 46, b, 1);
		world.setBlock(i + 20, j + 4, k + 47, b, 1);
		world.setBlock(i + 20, j + 4, k + 48, b, 1);
		world.setBlock(i + 20, j + 4, k + 49, b, 1);
		world.setBlock(i + 20, j + 4, k + 50, b, 1);
		world.setBlock(i + 20, j + 4, k + 51, b, 1);
		world.setBlock(i + 20, j + 4, k + 52, b, 1);
		world.setBlock(i + 20, j + 4, k + 53, b, 1);
		world.setBlock(i + 20, j + 4, k + 54, b, 1);
		world.setBlock(i + 20, j + 4, k + 55, b, 1);
		world.setBlock(i + 20, j + 4, k + 56, b, 1);
		world.setBlock(i + 20, j + 4, k + 57, b, 1);
		world.setBlock(i + 20, j + 4, k + 58, b, 1);
		world.setBlock(i + 20, j + 4, k + 59, b, 1);
		world.setBlock(i + 20, j + 4, k + 60, b, 1);
		world.setBlock(i + 20, j + 4, k + 61, b, 1);
		world.setBlock(i + 20, j + 4, k + 62, b, 1);
		world.setBlock(i + 20, j + 4, k + 63, b, 1);
		world.setBlock(i + 20, j + 4, k + 64, b, 1);
		world.setBlock(i + 20, j + 4, k + 65, b, 1);
		world.setBlock(i + 20, j + 4, k + 66, b, 1);
		world.setBlock(i + 20, j + 4, k + 67, b, 1);
		world.setBlock(i + 20, j + 4, k + 68, b, 1);
		world.setBlock(i + 20, j + 4, k + 69, b, 1);
		world.setBlock(i + 20, j + 4, k + 70, b, 1);
		world.setBlock(i + 20, j + 4, k + 71, b, 1);
		world.setBlock(i + 20, j + 4, k + 72, b, 1);
		world.setBlock(i + 20, j + 4, k + 73, b, 1);
		world.setBlock(i + 20, j + 4, k + 74, b, 1);
		world.setBlock(i + 20, j + 4, k + 75, b, 1);
		world.setBlock(i + 21, j + 0, k + 12, b, 1);
		world.setBlock(i + 21, j + 0, k + 13, b, 0);
		world.setBlock(i + 21, j + 0, k + 14, b, 0);
		world.setBlock(i + 21, j + 0, k + 15, b, 0);
		world.setBlock(i + 21, j + 0, k + 16, b, 0);
		world.setBlock(i + 21, j + 0, k + 17, b, 0);
		world.setBlock(i + 21, j + 0, k + 18, b, 0);
		world.setBlock(i + 21, j + 0, k + 19, b, 0);
		world.setBlock(i + 21, j + 0, k + 20, b, 0);
		world.setBlock(i + 21, j + 0, k + 21, b, 0);
		world.setBlock(i + 21, j + 0, k + 22, b, 0);
		world.setBlock(i + 21, j + 0, k + 23, b, 0);
		world.setBlock(i + 21, j + 0, k + 24, b, 0);
		world.setBlock(i + 21, j + 0, k + 25, b, 0);
		world.setBlock(i + 21, j + 0, k + 26, b, 0);
		world.setBlock(i + 21, j + 0, k + 27, b, 0);
		world.setBlock(i + 21, j + 0, k + 28, b, 0);
		world.setBlock(i + 21, j + 0, k + 29, b, 0);
		world.setBlock(i + 21, j + 0, k + 30, b, 1);
		world.setBlock(i + 21, j + 0, k + 31, b, 0);
		world.setBlock(i + 21, j + 0, k + 32, b, 0);
		world.setBlock(i + 21, j + 0, k + 33, b, 0);
		world.setBlock(i + 21, j + 0, k + 34, b, 1);
		world.setBlock(i + 21, j + 0, k + 39, b, 1);
		world.setBlock(i + 21, j + 0, k + 40, b, 0);
		world.setBlock(i + 21, j + 0, k + 41, b, 0);
		world.setBlock(i + 21, j + 0, k + 42, b, 0);
		world.setBlock(i + 21, j + 0, k + 43, b, 1);
		world.setBlock(i + 21, j + 0, k + 45, b, 1);
		world.setBlock(i + 21, j + 0, k + 46, b, 0);
		world.setBlock(i + 21, j + 0, k + 47, b, 0);
		world.setBlock(i + 21, j + 0, k + 48, b, 0);
		world.setBlock(i + 21, j + 0, k + 49, b, 0);
		world.setBlock(i + 21, j + 0, k + 50, b, 0);
		world.setBlock(i + 21, j + 0, k + 51, b, 0);
		world.setBlock(i + 21, j + 0, k + 52, b, 1);
		world.setBlock(i + 21, j + 0, k + 53, b, 0);
		world.setBlock(i + 21, j + 0, k + 54, b, 0);
		world.setBlock(i + 21, j + 0, k + 55, b, 0);
		world.setBlock(i + 21, j + 0, k + 56, b, 0);
		world.setBlock(i + 21, j + 0, k + 57, b, 0);
		world.setBlock(i + 21, j + 0, k + 58, b, 0);
		world.setBlock(i + 21, j + 0, k + 59, b, 0);
		world.setBlock(i + 21, j + 0, k + 60, b, 0);
		world.setBlock(i + 21, j + 0, k + 61, b, 0);
		world.setBlock(i + 21, j + 0, k + 62, b, 0);
		world.setBlock(i + 21, j + 0, k + 63, b, 0);
		world.setBlock(i + 21, j + 0, k + 64, b, 0);
		world.setBlock(i + 21, j + 0, k + 65, b, 0);
		world.setBlock(i + 21, j + 0, k + 66, b, 1);
		world.setBlock(i + 21, j + 0, k + 67, b, 1);
		world.setBlock(i + 21, j + 0, k + 68, b, 1);
		world.setBlock(i + 21, j + 0, k + 69, b, 1);
		world.setBlock(i + 21, j + 0, k + 70, b, 1);
		world.setBlock(i + 21, j + 0, k + 71, b, 1);
		world.setBlock(i + 21, j + 0, k + 72, b, 0);
		world.setBlock(i + 21, j + 0, k + 73, b, 0);
		world.setBlock(i + 21, j + 0, k + 74, b, 0);
		world.setBlock(i + 21, j + 0, k + 75, b, 1);
		world.setBlock(i + 21, j + 1, k + 12, b, 1);
		world.setBlock(i + 21, j + 1, k + 30, b, 1);
		world.setBlock(i + 21, j + 1, k + 32, -5);
		world.setBlock(i + 21, j + 1, k + 34, b, 1);
		world.setBlock(i + 21, j + 1, k + 39, b, 1);
		world.setBlock(i + 21, j + 1, k + 43, b, 1);
		world.setBlock(i + 21, j + 1, k + 45, b, 1);
		world.setBlock(i + 21, j + 1, k + 52, b, 1);
		world.setBlock(i + 21, j + 1, k + 60, Blocks.glass);
		world.setBlock(i + 21, j + 1, k + 66, b, 1);
		world.setBlock(i + 21, j + 1, k + 67, b, 1);
		world.setBlock(i + 21, j + 1, k + 68, b, 1);
		world.setBlock(i + 21, j + 1, k + 69, b, 1);
		world.setBlock(i + 21, j + 1, k + 70, b, 1);
		world.setBlock(i + 21, j + 1, k + 71, b, 1);
		world.setBlock(i + 21, j + 1, k + 75, b, 1);
		world.setBlock(i + 21, j + 2, k + 12, b, 1);
		world.setBlock(i + 21, j + 2, k + 30, b, 1);
		world.setBlock(i + 21, j + 2, k + 34, b, 1);
		world.setBlock(i + 21, j + 2, k + 39, b, 1);
		world.setBlock(i + 21, j + 2, k + 43, b, 1);
		world.setBlock(i + 21, j + 2, k + 45, b, 1);
		world.setBlock(i + 21, j + 2, k + 52, b, 1);
		world.setBlock(i + 21, j + 2, k + 60, Blocks.glass);
		world.setBlock(i + 21, j + 2, k + 66, b, 1);
		world.setBlock(i + 21, j + 2, k + 67, b, 1);
		world.setBlock(i + 21, j + 2, k + 68, b, 1);
		world.setBlock(i + 21, j + 2, k + 69, b, 1);
		world.setBlock(i + 21, j + 2, k + 70, b, 1);
		world.setBlock(i + 21, j + 2, k + 71, b, 1);
		world.setBlock(i + 21, j + 2, k + 75, b, 1);
		world.setBlock(i + 21, j + 3, k + 12, b, 1);
		world.setBlock(i + 21, j + 3, k + 30, b, 1);
		world.setBlock(i + 21, j + 3, k + 34, b, 1);
		world.setBlock(i + 21, j + 3, k + 39, b, 1);
		world.setBlock(i + 21, j + 3, k + 43, b, 1);
		world.setBlock(i + 21, j + 3, k + 45, b, 1);
		world.setBlock(i + 21, j + 3, k + 52, b, 1);
		world.setBlock(i + 21, j + 3, k + 60, Blocks.glass);
		world.setBlock(i + 21, j + 3, k + 66, b, 1);
		world.setBlock(i + 21, j + 3, k + 67, b, 1);
		world.setBlock(i + 21, j + 3, k + 68, b, 1);
		world.setBlock(i + 21, j + 3, k + 69, b, 1);
		world.setBlock(i + 21, j + 3, k + 70, b, 1);
		world.setBlock(i + 21, j + 3, k + 71, b, 1);
		world.setBlock(i + 21, j + 3, k + 75, b, 1);
		world.setBlock(i + 21, j + 4, k + 12, b, 1);
		world.setBlock(i + 21, j + 4, k + 13, b, 1);
		world.setBlock(i + 21, j + 4, k + 14, b, 1);
		world.setBlock(i + 21, j + 4, k + 15, b, 1);
		world.setBlock(i + 21, j + 4, k + 16, b, 1);
		world.setBlock(i + 21, j + 4, k + 17, b, 1);
		world.setBlock(i + 21, j + 4, k + 18, b, 1);
		world.setBlock(i + 21, j + 4, k + 19, b, 1);
		world.setBlock(i + 21, j + 4, k + 20, b, 1);
		world.setBlock(i + 21, j + 4, k + 21, b, 1);
		world.setBlock(i + 21, j + 4, k + 22, b, 1);
		world.setBlock(i + 21, j + 4, k + 23, b, 1);
		world.setBlock(i + 21, j + 4, k + 24, b, 1);
		world.setBlock(i + 21, j + 4, k + 25, b, 1);
		world.setBlock(i + 21, j + 4, k + 26, b, 1);
		world.setBlock(i + 21, j + 4, k + 27, b, 1);
		world.setBlock(i + 21, j + 4, k + 28, b, 1);
		world.setBlock(i + 21, j + 4, k + 29, b, 1);
		world.setBlock(i + 21, j + 4, k + 30, b, 1);
		world.setBlock(i + 21, j + 4, k + 31, b, 1);
		world.setBlock(i + 21, j + 4, k + 32, b, 1);
		world.setBlock(i + 21, j + 4, k + 33, b, 1);
		world.setBlock(i + 21, j + 4, k + 34, b, 1);
		world.setBlock(i + 21, j + 4, k + 39, b, 1);
		world.setBlock(i + 21, j + 4, k + 40, b, 1);
		world.setBlock(i + 21, j + 4, k + 41, b, 1);
		world.setBlock(i + 21, j + 4, k + 42, b, 1);
		world.setBlock(i + 21, j + 4, k + 43, b, 1);
		world.setBlock(i + 21, j + 4, k + 45, b, 1);
		world.setBlock(i + 21, j + 4, k + 46, b, 1);
		world.setBlock(i + 21, j + 4, k + 47, b, 1);
		world.setBlock(i + 21, j + 4, k + 48, b, 1);
		world.setBlock(i + 21, j + 4, k + 49, b, 1);
		world.setBlock(i + 21, j + 4, k + 50, b, 1);
		world.setBlock(i + 21, j + 4, k + 51, b, 1);
		world.setBlock(i + 21, j + 4, k + 52, b, 1);
		world.setBlock(i + 21, j + 4, k + 53, b, 1);
		world.setBlock(i + 21, j + 4, k + 54, b, 1);
		world.setBlock(i + 21, j + 4, k + 55, b, 1);
		world.setBlock(i + 21, j + 4, k + 56, b, 1);
		world.setBlock(i + 21, j + 4, k + 57, b, 1);
		world.setBlock(i + 21, j + 4, k + 58, b, 1);
		world.setBlock(i + 21, j + 4, k + 59, b, 1);
		world.setBlock(i + 21, j + 4, k + 60, b, 1);
		world.setBlock(i + 21, j + 4, k + 61, b, 1);
		world.setBlock(i + 21, j + 4, k + 62, b, 1);
		world.setBlock(i + 21, j + 4, k + 63, b, 1);
		world.setBlock(i + 21, j + 4, k + 64, b, 1);
		world.setBlock(i + 21, j + 4, k + 65, b, 1);
		world.setBlock(i + 21, j + 4, k + 66, b, 1);
		world.setBlock(i + 21, j + 4, k + 67, b, 1);
		world.setBlock(i + 21, j + 4, k + 68, b, 1);
		world.setBlock(i + 21, j + 4, k + 69, b, 1);
		world.setBlock(i + 21, j + 4, k + 70, b, 1);
		world.setBlock(i + 21, j + 4, k + 71, b, 1);
		world.setBlock(i + 21, j + 4, k + 72, b, 1);
		world.setBlock(i + 21, j + 4, k + 73, b, 1);
		world.setBlock(i + 21, j + 4, k + 74, b, 1);
		world.setBlock(i + 21, j + 4, k + 75, b, 1);
		world.setBlock(i + 22, j + 0, k + 12, b, 1);
		world.setBlock(i + 22, j + 0, k + 13, b, 0);
		world.setBlock(i + 22, j + 0, k + 14, b, 0);
		world.setBlock(i + 22, j + 0, k + 15, b, 0);
		world.setBlock(i + 22, j + 0, k + 16, b, 1);
		world.setBlock(i + 22, j + 0, k + 17, b, 1);
		world.setBlock(i + 22, j + 0, k + 18, b, 1);
		world.setBlock(i + 22, j + 0, k + 19, b, 0);
		world.setBlock(i + 22, j + 0, k + 20, b, 0);
		world.setBlock(i + 22, j + 0, k + 21, b, 0);
		world.setBlock(i + 22, j + 0, k + 22, b, 1);
		world.setBlock(i + 22, j + 0, k + 23, b, 1);
		world.setBlock(i + 22, j + 0, k + 24, b, 1);
		world.setBlock(i + 22, j + 0, k + 25, b, 1);
		world.setBlock(i + 22, j + 0, k + 26, b, 1);
		world.setBlock(i + 22, j + 0, k + 27, b, 0);
		world.setBlock(i + 22, j + 0, k + 28, b, 0);
		world.setBlock(i + 22, j + 0, k + 29, b, 0);
		world.setBlock(i + 22, j + 0, k + 30, b, 1);
		world.setBlock(i + 22, j + 0, k + 31, b, 0);
		world.setBlock(i + 22, j + 0, k + 32, b, 0);
		world.setBlock(i + 22, j + 0, k + 33, b, 0);
		world.setBlock(i + 22, j + 0, k + 34, b, 1);
		world.setBlock(i + 22, j + 0, k + 39, b, 1);
		world.setBlock(i + 22, j + 0, k + 40, b, 0);
		world.setBlock(i + 22, j + 0, k + 41, b, 0);
		world.setBlock(i + 22, j + 0, k + 42, b, 0);
		world.setBlock(i + 22, j + 0, k + 43, b, 1);
		world.setBlock(i + 22, j + 0, k + 45, b, 1);
		world.setBlock(i + 22, j + 0, k + 46, b, 0);
		world.setBlock(i + 22, j + 0, k + 47, b, 0);
		world.setBlock(i + 22, j + 0, k + 48, b, 0);
		world.setBlock(i + 22, j + 0, k + 49, b, 0);
		world.setBlock(i + 22, j + 0, k + 50, b, 0);
		world.setBlock(i + 22, j + 0, k + 51, b, 0);
		world.setBlock(i + 22, j + 0, k + 52, b, 1);
		world.setBlock(i + 22, j + 0, k + 53, b, 0);
		world.setBlock(i + 22, j + 0, k + 54, b, 0);
		world.setBlock(i + 22, j + 0, k + 55, b, 0);
		world.setBlock(i + 22, j + 0, k + 56, b, 0);
		world.setBlock(i + 22, j + 0, k + 57, b, 0);
		world.setBlock(i + 22, j + 0, k + 58, b, 0);
		world.setBlock(i + 22, j + 0, k + 59, b, 0);
		world.setBlock(i + 22, j + 0, k + 60, b, 0);
		world.setBlock(i + 22, j + 0, k + 61, b, 0);
		world.setBlock(i + 22, j + 0, k + 62, b, 0);
		world.setBlock(i + 22, j + 0, k + 63, b, 0);
		world.setBlock(i + 22, j + 0, k + 64, b, 1);
		world.setBlock(i + 22, j + 0, k + 65, b, 1);
		world.setBlock(i + 22, j + 0, k + 66, b, 1);
		world.setBlock(i + 22, j + 0, k + 71, b, 1);
		world.setBlock(i + 22, j + 0, k + 72, b, 0);
		world.setBlock(i + 22, j + 0, k + 73, b, 0);
		world.setBlock(i + 22, j + 0, k + 74, b, 0);
		world.setBlock(i + 22, j + 0, k + 75, b, 1);
		world.setBlock(i + 22, j + 1, k + 12, b, 1);
		world.setBlock(i + 22, j + 1, k + 16, b, 1);
		world.setBlock(i + 22, j + 1, k + 17, b, 1);
		world.setBlock(i + 22, j + 1, k + 18, b, 1);
		world.setBlock(i + 22, j + 1, k + 22, b, 1);
		world.setBlock(i + 22, j + 1, k + 23, b, 1);
		world.setBlock(i + 22, j + 1, k + 24, b, 1);
		world.setBlock(i + 22, j + 1, k + 25, b, 1);
		world.setBlock(i + 22, j + 1, k + 26, b, 1);
		world.setBlock(i + 22, j + 1, k + 30, b, 1);
		world.setBlock(i + 22, j + 1, k + 34, b, 1);
		world.setBlock(i + 22, j + 1, k + 39, b, 1);
		world.setBlock(i + 22, j + 1, k + 43, b, 1);
		world.setBlock(i + 22, j + 1, k + 45, b, 1);
	}

	private void generate2(Random rand, int i, int j, int k, Block b) {
		world.setBlock(i + 22, j + 1, k + 52, b, 1);
		world.setBlock(i + 22, j + 1, k + 60, Blocks.glass);
		world.setBlock(i + 22, j + 1, k + 64, b, 1);
		world.setBlock(i + 22, j + 1, k + 65, b, 1);
		world.setBlock(i + 22, j + 1, k + 66, b, 1);
		world.setBlock(i + 22, j + 1, k + 71, b, 1);
		world.setBlock(i + 22, j + 1, k + 75, b, 1);
		world.setBlock(i + 22, j + 2, k + 12, b, 1);
		world.setBlock(i + 22, j + 2, k + 16, b, 1);
		world.setBlock(i + 22, j + 2, k + 17, b, 1);
		world.setBlock(i + 22, j + 2, k + 18, b, 1);
		world.setBlock(i + 22, j + 2, k + 22, b, 1);
		world.setBlock(i + 22, j + 2, k + 23, b, 1);
		world.setBlock(i + 22, j + 2, k + 24, b, 1);
		world.setBlock(i + 22, j + 2, k + 25, b, 1);
		world.setBlock(i + 22, j + 2, k + 26, b, 1);
		world.setBlock(i + 22, j + 2, k + 30, b, 1);
		world.setBlock(i + 22, j + 2, k + 34, b, 1);
		world.setBlock(i + 22, j + 2, k + 39, b, 1);
		world.setBlock(i + 22, j + 2, k + 43, b, 1);
		world.setBlock(i + 22, j + 2, k + 45, b, 1);
		world.setBlock(i + 22, j + 2, k + 52, b, 1);
		world.setBlock(i + 22, j + 2, k + 60, Blocks.glass);
		world.setBlock(i + 22, j + 2, k + 64, b, 1);
		world.setBlock(i + 22, j + 2, k + 65, b, 1);
		world.setBlock(i + 22, j + 2, k + 66, b, 1);
		world.setBlock(i + 22, j + 2, k + 71, b, 1);
		world.setBlock(i + 22, j + 2, k + 75, b, 1);
		world.setBlock(i + 22, j + 3, k + 12, b, 1);
		world.setBlock(i + 22, j + 3, k + 16, b, 1);
		world.setBlock(i + 22, j + 3, k + 17, b, 1);
		world.setBlock(i + 22, j + 3, k + 18, b, 1);
		world.setBlock(i + 22, j + 3, k + 22, b, 1);
		world.setBlock(i + 22, j + 3, k + 23, b, 1);
		world.setBlock(i + 22, j + 3, k + 24, b, 1);
		world.setBlock(i + 22, j + 3, k + 25, b, 1);
		world.setBlock(i + 22, j + 3, k + 26, b, 1);
		world.setBlock(i + 22, j + 3, k + 30, b, 1);
		world.setBlock(i + 22, j + 3, k + 34, b, 1);
		world.setBlock(i + 22, j + 3, k + 39, b, 1);
		world.setBlock(i + 22, j + 3, k + 43, b, 1);
		world.setBlock(i + 22, j + 3, k + 45, b, 1);
		world.setBlock(i + 22, j + 3, k + 52, b, 1);
		world.setBlock(i + 22, j + 3, k + 60, Blocks.glass);
		world.setBlock(i + 22, j + 3, k + 64, b, 1);
		world.setBlock(i + 22, j + 3, k + 65, b, 1);
		world.setBlock(i + 22, j + 3, k + 66, b, 1);
		world.setBlock(i + 22, j + 3, k + 71, b, 1);
		world.setBlock(i + 22, j + 3, k + 75, b, 1);
		world.setBlock(i + 22, j + 4, k + 12, b, 1);
		world.setBlock(i + 22, j + 4, k + 13, b, 1);
		world.setBlock(i + 22, j + 4, k + 14, b, 1);
		world.setBlock(i + 22, j + 4, k + 15, b, 1);
		world.setBlock(i + 22, j + 4, k + 16, b, 1);
		world.setBlock(i + 22, j + 4, k + 17, b, 1);
		world.setBlock(i + 22, j + 4, k + 18, b, 1);
		world.setBlock(i + 22, j + 4, k + 19, b, 1);
		world.setBlock(i + 22, j + 4, k + 20, b, 1);
		world.setBlock(i + 22, j + 4, k + 21, b, 1);
		world.setBlock(i + 22, j + 4, k + 22, b, 1);
		world.setBlock(i + 22, j + 4, k + 23, b, 1);
		world.setBlock(i + 22, j + 4, k + 24, b, 1);
		world.setBlock(i + 22, j + 4, k + 25, b, 1);
		world.setBlock(i + 22, j + 4, k + 26, b, 1);
		world.setBlock(i + 22, j + 4, k + 27, b, 1);
		world.setBlock(i + 22, j + 4, k + 28, b, 1);
		world.setBlock(i + 22, j + 4, k + 29, b, 1);
		world.setBlock(i + 22, j + 4, k + 30, b, 1);
		world.setBlock(i + 22, j + 4, k + 31, b, 1);
		world.setBlock(i + 22, j + 4, k + 32, b, 1);
		world.setBlock(i + 22, j + 4, k + 33, b, 1);
		world.setBlock(i + 22, j + 4, k + 34, b, 1);
		world.setBlock(i + 22, j + 4, k + 39, b, 1);
		world.setBlock(i + 22, j + 4, k + 40, b, 1);
		world.setBlock(i + 22, j + 4, k + 41, b, 1);
		world.setBlock(i + 22, j + 4, k + 42, b, 1);
		world.setBlock(i + 22, j + 4, k + 43, b, 1);
		world.setBlock(i + 22, j + 4, k + 45, b, 1);
		world.setBlock(i + 22, j + 4, k + 46, b, 1);
		world.setBlock(i + 22, j + 4, k + 47, b, 1);
		world.setBlock(i + 22, j + 4, k + 48, b, 1);
		world.setBlock(i + 22, j + 4, k + 49, b, 1);
		world.setBlock(i + 22, j + 4, k + 50, b, 1);
		world.setBlock(i + 22, j + 4, k + 51, b, 1);
		world.setBlock(i + 22, j + 4, k + 52, b, 1);
		world.setBlock(i + 22, j + 4, k + 53, b, 1);
		world.setBlock(i + 22, j + 4, k + 54, b, 1);
		world.setBlock(i + 22, j + 4, k + 55, b, 1);
		world.setBlock(i + 22, j + 4, k + 56, b, 1);
		world.setBlock(i + 22, j + 4, k + 57, b, 1);
		world.setBlock(i + 22, j + 4, k + 58, b, 1);
		world.setBlock(i + 22, j + 4, k + 59, b, 1);
		world.setBlock(i + 22, j + 4, k + 60, b, 1);
		world.setBlock(i + 22, j + 4, k + 61, b, 1);
		world.setBlock(i + 22, j + 4, k + 62, b, 1);
		world.setBlock(i + 22, j + 4, k + 63, b, 1);
		world.setBlock(i + 22, j + 4, k + 64, b, 1);
		world.setBlock(i + 22, j + 4, k + 65, b, 1);
		world.setBlock(i + 22, j + 4, k + 66, b, 1);
		world.setBlock(i + 22, j + 4, k + 71, b, 1);
		world.setBlock(i + 22, j + 4, k + 72, b, 1);
		world.setBlock(i + 22, j + 4, k + 73, b, 1);
		world.setBlock(i + 22, j + 4, k + 74, b, 1);
		world.setBlock(i + 22, j + 4, k + 75, b, 1);
		world.setBlock(i + 23, j + 0, k + 12, b, 1);
		world.setBlock(i + 23, j + 0, k + 13, b, 0);
		world.setBlock(i + 23, j + 0, k + 14, b, 0);
		world.setBlock(i + 23, j + 0, k + 15, b, 0);
		world.setBlock(i + 23, j + 0, k + 16, b, 0);
		world.setBlock(i + 23, j + 0, k + 17, b, 0);
		world.setBlock(i + 23, j + 0, k + 18, b, 0);
		world.setBlock(i + 23, j + 0, k + 19, b, 0);
		world.setBlock(i + 23, j + 0, k + 20, b, 0);
		world.setBlock(i + 23, j + 0, k + 21, b, 0);
		world.setBlock(i + 23, j + 0, k + 22, b, 1);
		world.setBlock(i + 23, j + 0, k + 23, b, 0);
		world.setBlock(i + 23, j + 0, k + 24, b, 0);
		world.setBlock(i + 23, j + 0, k + 25, b, 0);
		world.setBlock(i + 23, j + 0, k + 26, b, 1);
		world.setBlock(i + 23, j + 0, k + 27, b, 0);
		world.setBlock(i + 23, j + 0, k + 28, b, 0);
		world.setBlock(i + 23, j + 0, k + 29, b, 0);
		world.setBlock(i + 23, j + 0, k + 30, b, 1);
		world.setBlock(i + 23, j + 0, k + 31, b, 0);
		world.setBlock(i + 23, j + 0, k + 32, b, 0);
		world.setBlock(i + 23, j + 0, k + 33, b, 0);
		world.setBlock(i + 23, j + 0, k + 34, b, 1);
		world.setBlock(i + 23, j + 0, k + 35, b, 1);
		world.setBlock(i + 23, j + 0, k + 36, b, 1);
		world.setBlock(i + 23, j + 0, k + 37, b, 1);
		world.setBlock(i + 23, j + 0, k + 38, b, 1);
		world.setBlock(i + 23, j + 0, k + 39, b, 1);
		world.setBlock(i + 23, j + 0, k + 40, b, 0);
		world.setBlock(i + 23, j + 0, k + 41, b, 0);
		world.setBlock(i + 23, j + 0, k + 42, b, 0);
		world.setBlock(i + 23, j + 0, k + 43, b, 1);
		world.setBlock(i + 23, j + 0, k + 45, b, 1);
		world.setBlock(i + 23, j + 0, k + 46, b, 1);
		world.setBlock(i + 23, j + 0, k + 47, b, 1);
		world.setBlock(i + 23, j + 0, k + 48, b, 1);
		world.setBlock(i + 23, j + 0, k + 49, b, 1);
		world.setBlock(i + 23, j + 0, k + 50, b, 1);
		world.setBlock(i + 23, j + 0, k + 51, b, 1);
		world.setBlock(i + 23, j + 0, k + 52, b, 1);
		world.setBlock(i + 23, j + 0, k + 53, b, 1);
		world.setBlock(i + 23, j + 0, k + 54, b, 1);
		world.setBlock(i + 23, j + 0, k + 55, b, 1);
		world.setBlock(i + 23, j + 0, k + 56, b, 1);
		world.setBlock(i + 23, j + 0, k + 57, b, 1);
		world.setBlock(i + 23, j + 0, k + 58, b, 1);
		world.setBlock(i + 23, j + 0, k + 59, b, 1);
		world.setBlock(i + 23, j + 0, k + 60, b, 1);
		world.setBlock(i + 23, j + 0, k + 61, b, 1);
		world.setBlock(i + 23, j + 0, k + 62, b, 1);
		world.setBlock(i + 23, j + 0, k + 63, b, 1);
		world.setBlock(i + 23, j + 0, k + 64, b, 1);
		world.setBlock(i + 23, j + 0, k + 65, b, 1);
		world.setBlock(i + 23, j + 0, k + 66, b, 1);
		world.setBlock(i + 23, j + 0, k + 67, b, 1);
		world.setBlock(i + 23, j + 0, k + 68, b, 1);
		world.setBlock(i + 23, j + 0, k + 69, b, 1);
		world.setBlock(i + 23, j + 0, k + 70, b, 1);
		world.setBlock(i + 23, j + 0, k + 71, b, 1);
		world.setBlock(i + 23, j + 0, k + 72, b, 0);
		world.setBlock(i + 23, j + 0, k + 73, b, 0);
		world.setBlock(i + 23, j + 0, k + 74, b, 0);
		world.setBlock(i + 23, j + 0, k + 75, b, 1);
		world.setBlock(i + 23, j + 1, k + 12, b, 1);
		world.setBlock(i + 23, j + 1, k + 22, b, 1);
		world.setBlock(i + 23, j + 1, k + 26, b, 1);
		world.setBlock(i + 23, j + 1, k + 30, b, 1);
		world.setBlock(i + 23, j + 1, k + 34, b, 1);
		world.setBlock(i + 23, j + 1, k + 35, b, 1);
		world.setBlock(i + 23, j + 1, k + 36, b, 1);
		world.setBlock(i + 23, j + 1, k + 37, b, 1);
		world.setBlock(i + 23, j + 1, k + 38, b, 1);
		world.setBlock(i + 23, j + 1, k + 39, b, 1);
		world.setBlock(i + 23, j + 1, k + 43, b, 1);
		world.setBlock(i + 23, j + 1, k + 45, b, 1);
		world.setBlock(i + 23, j + 1, k + 46, b, 1);
		world.setBlock(i + 23, j + 1, k + 47, b, 1);
		world.setBlock(i + 23, j + 1, k + 48, b, 1);
		world.setBlock(i + 23, j + 1, k + 49, b, 1);
		world.setBlock(i + 23, j + 1, k + 50, b, 1);
		world.setBlock(i + 23, j + 1, k + 51, b, 1);
		world.setBlock(i + 23, j + 1, k + 52, b, 1);
		world.setBlock(i + 23, j + 1, k + 53, b, 1);
		world.setBlock(i + 23, j + 1, k + 54, b, 1);
		world.setBlock(i + 23, j + 1, k + 55, b, 1);
		world.setBlock(i + 23, j + 1, k + 56, b, 1);
		world.setBlock(i + 23, j + 1, k + 57, b, 1);
		world.setBlock(i + 23, j + 1, k + 58, b, 1);
		world.setBlock(i + 23, j + 1, k + 59, b, 1);
		world.setBlock(i + 23, j + 1, k + 60, b, 1);
		world.setBlock(i + 23, j + 1, k + 61, b, 1);
		world.setBlock(i + 23, j + 1, k + 62, b, 1);
		world.setBlock(i + 23, j + 1, k + 63, b, 1);
		world.setBlock(i + 23, j + 1, k + 64, b, 1);
		world.setBlock(i + 23, j + 1, k + 65, b, 1);
		world.setBlock(i + 23, j + 1, k + 66, b, 1);
		world.setBlock(i + 23, j + 1, k + 67, b, 1);
		world.setBlock(i + 23, j + 1, k + 68, b, 1);
		world.setBlock(i + 23, j + 1, k + 69, b, 1);
		world.setBlock(i + 23, j + 1, k + 70, b, 1);
		world.setBlock(i + 23, j + 1, k + 71, b, 1);
		world.setBlock(i + 23, j + 1, k + 75, b, 1);
		world.setBlock(i + 23, j + 2, k + 12, b, 1);
		world.setBlock(i + 23, j + 2, k + 22, b, 1);
		world.setBlock(i + 23, j + 2, k + 26, b, 1);
		world.setBlock(i + 23, j + 2, k + 30, b, 1);
		world.setBlock(i + 23, j + 2, k + 34, b, 1);
		world.setBlock(i + 23, j + 2, k + 35, b, 1);
		world.setBlock(i + 23, j + 2, k + 36, b, 1);
		world.setBlock(i + 23, j + 2, k + 37, b, 1);
		world.setBlock(i + 23, j + 2, k + 38, b, 1);
		world.setBlock(i + 23, j + 2, k + 39, b, 1);
		world.setBlock(i + 23, j + 2, k + 43, b, 1);
		world.setBlock(i + 23, j + 2, k + 45, b, 1);
		world.setBlock(i + 23, j + 2, k + 46, b, 1);
		world.setBlock(i + 23, j + 2, k + 47, b, 1);
		world.setBlock(i + 23, j + 2, k + 48, b, 1);
		world.setBlock(i + 23, j + 2, k + 49, b, 1);
		world.setBlock(i + 23, j + 2, k + 50, b, 1);
		world.setBlock(i + 23, j + 2, k + 51, b, 1);
		world.setBlock(i + 23, j + 2, k + 52, b, 1);
		world.setBlock(i + 23, j + 2, k + 53, b, 1);
		world.setBlock(i + 23, j + 2, k + 54, b, 1);
		world.setBlock(i + 23, j + 2, k + 55, b, 1);
		world.setBlock(i + 23, j + 2, k + 56, b, 1);
		world.setBlock(i + 23, j + 2, k + 57, b, 1);
		world.setBlock(i + 23, j + 2, k + 58, b, 1);
		world.setBlock(i + 23, j + 2, k + 59, b, 1);
		world.setBlock(i + 23, j + 2, k + 60, b, 1);
		world.setBlock(i + 23, j + 2, k + 61, b, 1);
		world.setBlock(i + 23, j + 2, k + 62, b, 1);
		world.setBlock(i + 23, j + 2, k + 63, b, 1);
		world.setBlock(i + 23, j + 2, k + 64, b, 1);
		world.setBlock(i + 23, j + 2, k + 65, b, 1);
		world.setBlock(i + 23, j + 2, k + 66, b, 1);
		world.setBlock(i + 23, j + 2, k + 67, b, 1);
		world.setBlock(i + 23, j + 2, k + 68, b, 1);
		world.setBlock(i + 23, j + 2, k + 69, b, 1);
		world.setBlock(i + 23, j + 2, k + 70, b, 1);
		world.setBlock(i + 23, j + 2, k + 71, b, 1);
		world.setBlock(i + 23, j + 2, k + 75, b, 1);
		world.setBlock(i + 23, j + 3, k + 12, b, 1);
		world.setBlock(i + 23, j + 3, k + 22, b, 1);
		world.setBlock(i + 23, j + 3, k + 26, b, 1);
		world.setBlock(i + 23, j + 3, k + 30, b, 1);
		world.setBlock(i + 23, j + 3, k + 34, b, 1);
		world.setBlock(i + 23, j + 3, k + 35, b, 1);
		world.setBlock(i + 23, j + 3, k + 36, b, 1);
		world.setBlock(i + 23, j + 3, k + 37, b, 1);
		world.setBlock(i + 23, j + 3, k + 38, b, 1);
		world.setBlock(i + 23, j + 3, k + 39, b, 1);
		world.setBlock(i + 23, j + 3, k + 43, b, 1);
		world.setBlock(i + 23, j + 3, k + 45, b, 1);
		world.setBlock(i + 23, j + 3, k + 46, b, 1);
		world.setBlock(i + 23, j + 3, k + 47, b, 1);
		world.setBlock(i + 23, j + 3, k + 48, b, 1);
		world.setBlock(i + 23, j + 3, k + 49, b, 1);
		world.setBlock(i + 23, j + 3, k + 50, b, 1);
		world.setBlock(i + 23, j + 3, k + 51, b, 1);
		world.setBlock(i + 23, j + 3, k + 52, b, 1);
		world.setBlock(i + 23, j + 3, k + 53, b, 1);
		world.setBlock(i + 23, j + 3, k + 54, b, 1);
		world.setBlock(i + 23, j + 3, k + 55, b, 1);
		world.setBlock(i + 23, j + 3, k + 56, b, 1);
		world.setBlock(i + 23, j + 3, k + 57, b, 1);
		world.setBlock(i + 23, j + 3, k + 58, b, 1);
		world.setBlock(i + 23, j + 3, k + 59, b, 1);
		world.setBlock(i + 23, j + 3, k + 60, b, 1);
		world.setBlock(i + 23, j + 3, k + 61, b, 1);
		world.setBlock(i + 23, j + 3, k + 62, b, 1);
		world.setBlock(i + 23, j + 3, k + 63, b, 1);
		world.setBlock(i + 23, j + 3, k + 64, b, 1);
		world.setBlock(i + 23, j + 3, k + 65, b, 1);
		world.setBlock(i + 23, j + 3, k + 66, b, 1);
		world.setBlock(i + 23, j + 3, k + 67, b, 1);
		world.setBlock(i + 23, j + 3, k + 68, b, 1);
		world.setBlock(i + 23, j + 3, k + 69, b, 1);
		world.setBlock(i + 23, j + 3, k + 70, b, 1);
		world.setBlock(i + 23, j + 3, k + 71, b, 1);
		world.setBlock(i + 23, j + 3, k + 75, b, 1);
		world.setBlock(i + 23, j + 4, k + 12, b, 1);
		world.setBlock(i + 23, j + 4, k + 13, b, 1);
		world.setBlock(i + 23, j + 4, k + 14, b, 1);
		world.setBlock(i + 23, j + 4, k + 15, b, 1);
		world.setBlock(i + 23, j + 4, k + 16, b, 1);
		world.setBlock(i + 23, j + 4, k + 17, b, 1);
		world.setBlock(i + 23, j + 4, k + 18, b, 1);
		world.setBlock(i + 23, j + 4, k + 19, b, 1);
		world.setBlock(i + 23, j + 4, k + 20, b, 1);
		world.setBlock(i + 23, j + 4, k + 21, b, 1);
		world.setBlock(i + 23, j + 4, k + 22, b, 1);
		world.setBlock(i + 23, j + 4, k + 23, b, 1);
		world.setBlock(i + 23, j + 4, k + 24, b, 1);
		world.setBlock(i + 23, j + 4, k + 25, b, 1);
		world.setBlock(i + 23, j + 4, k + 26, b, 1);
		world.setBlock(i + 23, j + 4, k + 27, b, 1);
		world.setBlock(i + 23, j + 4, k + 28, b, 1);
		world.setBlock(i + 23, j + 4, k + 29, b, 1);
		world.setBlock(i + 23, j + 4, k + 30, b, 1);
		world.setBlock(i + 23, j + 4, k + 31, b, 1);
		world.setBlock(i + 23, j + 4, k + 32, b, 1);
		world.setBlock(i + 23, j + 4, k + 33, b, 1);
		world.setBlock(i + 23, j + 4, k + 34, b, 1);
		world.setBlock(i + 23, j + 4, k + 35, b, 1);
		world.setBlock(i + 23, j + 4, k + 36, b, 1);
		world.setBlock(i + 23, j + 4, k + 37, b, 1);
		world.setBlock(i + 23, j + 4, k + 38, b, 1);
		world.setBlock(i + 23, j + 4, k + 39, b, 1);
		world.setBlock(i + 23, j + 4, k + 40, b, 1);
		world.setBlock(i + 23, j + 4, k + 41, b, 1);
		world.setBlock(i + 23, j + 4, k + 42, b, 1);
		world.setBlock(i + 23, j + 4, k + 43, b, 1);
		world.setBlock(i + 23, j + 4, k + 45, b, 1);
		world.setBlock(i + 23, j + 4, k + 46, b, 1);
		world.setBlock(i + 23, j + 4, k + 47, b, 1);
		world.setBlock(i + 23, j + 4, k + 48, b, 1);
		world.setBlock(i + 23, j + 4, k + 49, b, 1);
		world.setBlock(i + 23, j + 4, k + 50, b, 1);
		world.setBlock(i + 23, j + 4, k + 51, b, 1);
		world.setBlock(i + 23, j + 4, k + 52, b, 1);
		world.setBlock(i + 23, j + 4, k + 53, b, 1);
		world.setBlock(i + 23, j + 4, k + 54, b, 1);
		world.setBlock(i + 23, j + 4, k + 55, b, 1);
		world.setBlock(i + 23, j + 4, k + 56, b, 1);
		world.setBlock(i + 23, j + 4, k + 57, b, 1);
		world.setBlock(i + 23, j + 4, k + 58, b, 1);
		world.setBlock(i + 23, j + 4, k + 59, b, 1);
		world.setBlock(i + 23, j + 4, k + 60, b, 1);
		world.setBlock(i + 23, j + 4, k + 61, b, 1);
		world.setBlock(i + 23, j + 4, k + 62, b, 1);
		world.setBlock(i + 23, j + 4, k + 63, b, 1);
		world.setBlock(i + 23, j + 4, k + 64, b, 1);
		world.setBlock(i + 23, j + 4, k + 65, b, 1);
		world.setBlock(i + 23, j + 4, k + 66, b, 1);
		world.setBlock(i + 23, j + 4, k + 67, b, 1);
		world.setBlock(i + 23, j + 4, k + 68, b, 1);
		world.setBlock(i + 23, j + 4, k + 69, b, 1);
		world.setBlock(i + 23, j + 4, k + 70, b, 1);
		world.setBlock(i + 23, j + 4, k + 71, b, 1);
		world.setBlock(i + 23, j + 4, k + 72, b, 1);
		world.setBlock(i + 23, j + 4, k + 73, b, 1);
		world.setBlock(i + 23, j + 4, k + 74, b, 1);
		world.setBlock(i + 23, j + 4, k + 75, b, 1);
		world.setBlock(i + 24, j + 0, k + 12, b, 1);
		world.setBlock(i + 24, j + 0, k + 13, b, 0);
		world.setBlock(i + 24, j + 0, k + 14, b, 0);
		world.setBlock(i + 24, j + 0, k + 15, b, 0);
		world.setBlock(i + 24, j + 0, k + 16, b, 0);
		world.setBlock(i + 24, j + 0, k + 17, b, 0);
		world.setBlock(i + 24, j + 0, k + 18, b, 0);
		world.setBlock(i + 24, j + 0, k + 19, b, 0);
		world.setBlock(i + 24, j + 0, k + 20, b, 0);
		world.setBlock(i + 24, j + 0, k + 21, b, 0);
		world.setBlock(i + 24, j + 0, k + 22, b, 1);
		world.setBlock(i + 24, j + 0, k + 23, b, 0);
		world.setBlock(i + 24, j + 0, k + 24, b, 0);
		world.setBlock(i + 24, j + 0, k + 25, b, 0);
		world.setBlock(i + 24, j + 0, k + 26, b, 1);
		world.setBlock(i + 24, j + 0, k + 27, b, 0);
		world.setBlock(i + 24, j + 0, k + 28, b, 0);
		world.setBlock(i + 24, j + 0, k + 29, b, 0);
		world.setBlock(i + 24, j + 0, k + 30, b, 1);
		world.setBlock(i + 24, j + 0, k + 31, b, 0);
		world.setBlock(i + 24, j + 0, k + 32, b, 0);
		world.setBlock(i + 24, j + 0, k + 33, b, 0);
		world.setBlock(i + 24, j + 0, k + 34, b, 0);
		world.setBlock(i + 24, j + 0, k + 35, b, 0);
		world.setBlock(i + 24, j + 0, k + 36, b, 0);
		world.setBlock(i + 24, j + 0, k + 37, b, 0);
		world.setBlock(i + 24, j + 0, k + 38, b, 0);
		world.setBlock(i + 24, j + 0, k + 39, b, 1);
		world.setBlock(i + 24, j + 0, k + 40, b, 0);
		world.setBlock(i + 24, j + 0, k + 41, b, 0);
		world.setBlock(i + 24, j + 0, k + 42, b, 0);
		world.setBlock(i + 24, j + 0, k + 43, b, 1);
		world.setBlock(i + 24, j + 0, k + 59, b, 1);
		world.setBlock(i + 24, j + 0, k + 60, b, 0);
		world.setBlock(i + 24, j + 0, k + 61, b, 0);
		world.setBlock(i + 24, j + 0, k + 62, b, 0);
		world.setBlock(i + 24, j + 0, k + 63, b, 0);
		world.setBlock(i + 24, j + 0, k + 64, b, 0);
		world.setBlock(i + 24, j + 0, k + 65, b, 0);
		world.setBlock(i + 24, j + 0, k + 66, b, 0);
		world.setBlock(i + 24, j + 0, k + 67, b, 0);
		world.setBlock(i + 24, j + 0, k + 68, b, 0);
		world.setBlock(i + 24, j + 0, k + 69, b, 0);
		world.setBlock(i + 24, j + 0, k + 70, b, 0);
		world.setBlock(i + 24, j + 0, k + 71, b, 0);
		world.setBlock(i + 24, j + 0, k + 72, b, 0);
		world.setBlock(i + 24, j + 0, k + 73, b, 0);
		world.setBlock(i + 24, j + 0, k + 74, b, 0);
		world.setBlock(i + 24, j + 0, k + 75, b, 1);
		world.setBlock(i + 24, j + 1, k + 12, b, 1);
		world.setBlock(i + 24, j + 1, k + 22, b, 1);
		world.setBlock(i + 24, j + 1, k + 26, b, 1);
		world.setBlock(i + 24, j + 1, k + 28, -5);
		world.setBlock(i + 24, j + 1, k + 30, b, 1);
		world.setBlock(i + 24, j + 1, k + 39, b, 1);
		world.setBlock(i + 24, j + 1, k + 43, b, 1);
		world.setBlock(i + 24, j + 1, k + 59, b, 1);
		world.setBlock(i + 24, j + 1, k + 75, b, 1);
		world.setBlock(i + 24, j + 2, k + 12, b, 1);
		world.setBlock(i + 24, j + 2, k + 22, b, 1);
		world.setBlock(i + 24, j + 2, k + 26, b, 1);
		world.setBlock(i + 24, j + 2, k + 30, b, 1);
		world.setBlock(i + 24, j + 2, k + 39, b, 1);
		world.setBlock(i + 24, j + 2, k + 43, b, 1);
		world.setBlock(i + 24, j + 2, k + 59, b, 1);
		world.setBlock(i + 24, j + 2, k + 75, b, 1);
		world.setBlock(i + 24, j + 3, k + 12, b, 1);
		world.setBlock(i + 24, j + 3, k + 22, b, 1);
		world.setBlock(i + 24, j + 3, k + 26, b, 1);
		world.setBlock(i + 24, j + 3, k + 30, b, 1);
		world.setBlock(i + 24, j + 3, k + 39, b, 1);
		world.setBlock(i + 24, j + 3, k + 43, b, 1);
		world.setBlock(i + 24, j + 3, k + 59, b, 1);
		world.setBlock(i + 24, j + 3, k + 75, b, 1);
		world.setBlock(i + 24, j + 4, k + 12, b, 1);
		world.setBlock(i + 24, j + 4, k + 13, b, 1);
		world.setBlock(i + 24, j + 4, k + 14, b, 1);
		world.setBlock(i + 24, j + 4, k + 15, b, 1);
		world.setBlock(i + 24, j + 4, k + 16, b, 1);
		world.setBlock(i + 24, j + 4, k + 17, b, 1);
		world.setBlock(i + 24, j + 4, k + 18, b, 1);
		world.setBlock(i + 24, j + 4, k + 19, b, 1);
		world.setBlock(i + 24, j + 4, k + 20, b, 1);
		world.setBlock(i + 24, j + 4, k + 21, b, 1);
		world.setBlock(i + 24, j + 4, k + 22, b, 1);
		world.setBlock(i + 24, j + 4, k + 23, b, 1);
		world.setBlock(i + 24, j + 4, k + 24, b, 1);
		world.setBlock(i + 24, j + 4, k + 25, b, 1);
		world.setBlock(i + 24, j + 4, k + 26, b, 1);
		world.setBlock(i + 24, j + 4, k + 27, b, 1);
		world.setBlock(i + 24, j + 4, k + 28, b, 1);
		world.setBlock(i + 24, j + 4, k + 29, b, 1);
		world.setBlock(i + 24, j + 4, k + 30, b, 1);
		world.setBlock(i + 24, j + 4, k + 31, b, 1);
		world.setBlock(i + 24, j + 4, k + 32, b, 1);
		world.setBlock(i + 24, j + 4, k + 33, b, 1);
		world.setBlock(i + 24, j + 4, k + 34, b, 1);
		world.setBlock(i + 24, j + 4, k + 35, b, 1);
		world.setBlock(i + 24, j + 4, k + 36, b, 1);
		world.setBlock(i + 24, j + 4, k + 37, b, 1);
		world.setBlock(i + 24, j + 4, k + 38, b, 1);
		world.setBlock(i + 24, j + 4, k + 39, b, 1);
		world.setBlock(i + 24, j + 4, k + 40, b, 1);
		world.setBlock(i + 24, j + 4, k + 41, b, 1);
		world.setBlock(i + 24, j + 4, k + 42, b, 1);
		world.setBlock(i + 24, j + 4, k + 43, b, 1);
		world.setBlock(i + 24, j + 4, k + 59, b, 1);
		world.setBlock(i + 24, j + 4, k + 60, b, 1);
		world.setBlock(i + 24, j + 4, k + 61, b, 1);
		world.setBlock(i + 24, j + 4, k + 62, b, 1);
		world.setBlock(i + 24, j + 4, k + 63, b, 1);
		world.setBlock(i + 24, j + 4, k + 64, b, 1);
		world.setBlock(i + 24, j + 4, k + 65, b, 1);
		world.setBlock(i + 24, j + 4, k + 66, b, 1);
		world.setBlock(i + 24, j + 4, k + 67, b, 1);
		world.setBlock(i + 24, j + 4, k + 68, b, 1);
		world.setBlock(i + 24, j + 4, k + 69, b, 1);
		world.setBlock(i + 24, j + 4, k + 70, b, 1);
		world.setBlock(i + 24, j + 4, k + 71, b, 1);
		world.setBlock(i + 24, j + 4, k + 72, b, 1);
		world.setBlock(i + 24, j + 4, k + 73, b, 1);
		world.setBlock(i + 24, j + 4, k + 74, b, 1);
		world.setBlock(i + 24, j + 4, k + 75, b, 1);
		world.setBlock(i + 25, j + 0, k + 12, b, 1);
		world.setBlock(i + 25, j + 0, k + 13, b, 0);
		world.setBlock(i + 25, j + 0, k + 14, b, 0);
		world.setBlock(i + 25, j + 0, k + 15, b, 0);
		world.setBlock(i + 25, j + 0, k + 16, b, 0);
		world.setBlock(i + 25, j + 0, k + 17, b, 0);
		world.setBlock(i + 25, j + 0, k + 18, b, 0);
		world.setBlock(i + 25, j + 0, k + 19, b, 0);
		world.setBlock(i + 25, j + 0, k + 20, b, 0);
		world.setBlock(i + 25, j + 0, k + 21, b, 0);
		world.setBlock(i + 25, j + 0, k + 22, b, 1);
		world.setBlock(i + 25, j + 0, k + 23, b, 0);
		world.setBlock(i + 25, j + 0, k + 24, b, 0);
		world.setBlock(i + 25, j + 0, k + 25, b, 0);
		world.setBlock(i + 25, j + 0, k + 26, b, 1);
		world.setBlock(i + 25, j + 0, k + 27, b, 0);
		world.setBlock(i + 25, j + 0, k + 28, b, 0);
		world.setBlock(i + 25, j + 0, k + 29, b, 0);
		world.setBlock(i + 25, j + 0, k + 30, b, 1);
		world.setBlock(i + 25, j + 0, k + 31, b, 0);
		world.setBlock(i + 25, j + 0, k + 32, b, 0);
		world.setBlock(i + 25, j + 0, k + 33, b, 0);
		world.setBlock(i + 25, j + 0, k + 34, b, 0);
		world.setBlock(i + 25, j + 0, k + 35, b, 0);
		world.setBlock(i + 25, j + 0, k + 36, b, 0);
		world.setBlock(i + 25, j + 0, k + 37, b, 0);
		world.setBlock(i + 25, j + 0, k + 38, b, 0);
		world.setBlock(i + 25, j + 0, k + 39, b, 1);
		world.setBlock(i + 25, j + 0, k + 40, b, 0);
		world.setBlock(i + 25, j + 0, k + 41, b, 0);
		world.setBlock(i + 25, j + 0, k + 42, b, 0);
		world.setBlock(i + 25, j + 0, k + 43, b, 1);
		world.setBlock(i + 25, j + 0, k + 44, b, 1);
		world.setBlock(i + 25, j + 0, k + 45, b, 1);
		world.setBlock(i + 25, j + 0, k + 46, b, 1);
		world.setBlock(i + 25, j + 0, k + 47, b, 1);
		world.setBlock(i + 25, j + 0, k + 48, b, 1);
		world.setBlock(i + 25, j + 0, k + 49, b, 1);
		world.setBlock(i + 25, j + 0, k + 50, b, 1);
		world.setBlock(i + 25, j + 0, k + 51, b, 1);
		world.setBlock(i + 25, j + 0, k + 52, b, 1);
		world.setBlock(i + 25, j + 0, k + 53, b, 1);
		world.setBlock(i + 25, j + 0, k + 54, b, 1);
		world.setBlock(i + 25, j + 0, k + 55, b, 1);
		world.setBlock(i + 25, j + 0, k + 56, b, 1);
		world.setBlock(i + 25, j + 0, k + 57, b, 1);
		world.setBlock(i + 25, j + 0, k + 58, b, 1);
		world.setBlock(i + 25, j + 0, k + 59, b, 1);
		world.setBlock(i + 25, j + 0, k + 60, b, 0);
		world.setBlock(i + 25, j + 0, k + 61, b, 0);
		world.setBlock(i + 25, j + 0, k + 62, b, 0);
		world.setBlock(i + 25, j + 0, k + 63, b, 0);
		world.setBlock(i + 25, j + 0, k + 64, b, 0);
		world.setBlock(i + 25, j + 0, k + 65, b, 0);
		world.setBlock(i + 25, j + 0, k + 66, b, 0);
		world.setBlock(i + 25, j + 0, k + 67, b, 0);
		world.setBlock(i + 25, j + 0, k + 68, b, 0);
		world.setBlock(i + 25, j + 0, k + 69, b, 0);
		world.setBlock(i + 25, j + 0, k + 70, b, 0);
		world.setBlock(i + 25, j + 0, k + 71, b, 0);
		world.setBlock(i + 25, j + 0, k + 72, b, 0);
		world.setBlock(i + 25, j + 0, k + 73, b, 0);
		world.setBlock(i + 25, j + 0, k + 74, b, 0);
		world.setBlock(i + 25, j + 0, k + 75, b, 1);
		world.setBlock(i + 25, j + 1, k + 12, b, 1);
		world.setBlock(i + 25, j + 1, k + 22, b, 1);
		world.setBlock(i + 25, j + 1, k + 26, b, 1);
		world.setBlock(i + 25, j + 1, k + 30, b, 1);
		world.setBlock(i + 25, j + 1, k + 39, b, 1);
		world.setBlock(i + 25, j + 1, k + 43, b, 1);
		world.setBlock(i + 25, j + 1, k + 44, b, 1);
		world.setBlock(i + 25, j + 1, k + 45, b, 1);
		world.setBlock(i + 25, j + 1, k + 46, b, 1);
		world.setBlock(i + 25, j + 1, k + 47, b, 1);
		world.setBlock(i + 25, j + 1, k + 48, b, 1);
		world.setBlock(i + 25, j + 1, k + 49, b, 1);
		world.setBlock(i + 25, j + 1, k + 50, b, 1);
		world.setBlock(i + 25, j + 1, k + 51, b, 1);
		world.setBlock(i + 25, j + 1, k + 52, b, 1);
		world.setBlock(i + 25, j + 1, k + 53, b, 1);
		world.setBlock(i + 25, j + 1, k + 54, b, 1);
		world.setBlock(i + 25, j + 1, k + 55, b, 1);
		world.setBlock(i + 25, j + 1, k + 56, b, 1);
		world.setBlock(i + 25, j + 1, k + 57, b, 1);
		world.setBlock(i + 25, j + 1, k + 58, b, 1);
		world.setBlock(i + 25, j + 1, k + 59, b, 1);
		world.setBlock(i + 25, j + 1, k + 75, b, 1);
		world.setBlock(i + 25, j + 2, k + 12, b, 1);
		world.setBlock(i + 25, j + 2, k + 22, b, 1);
		world.setBlock(i + 25, j + 2, k + 26, b, 1);
		world.setBlock(i + 25, j + 2, k + 30, b, 1);
		world.setBlock(i + 25, j + 2, k + 39, b, 1);
		world.setBlock(i + 25, j + 2, k + 43, b, 1);
		world.setBlock(i + 25, j + 2, k + 44, b, 1);
		world.setBlock(i + 25, j + 2, k + 45, b, 1);
		world.setBlock(i + 25, j + 2, k + 46, b, 1);
		world.setBlock(i + 25, j + 2, k + 47, b, 1);
		world.setBlock(i + 25, j + 2, k + 48, b, 1);
		world.setBlock(i + 25, j + 2, k + 49, b, 1);
		world.setBlock(i + 25, j + 2, k + 50, b, 1);
		world.setBlock(i + 25, j + 2, k + 51, b, 1);
		world.setBlock(i + 25, j + 2, k + 52, b, 1);
		world.setBlock(i + 25, j + 2, k + 53, b, 1);
		world.setBlock(i + 25, j + 2, k + 54, b, 1);
		world.setBlock(i + 25, j + 2, k + 55, b, 1);
		world.setBlock(i + 25, j + 2, k + 56, b, 1);
		world.setBlock(i + 25, j + 2, k + 57, b, 1);
		world.setBlock(i + 25, j + 2, k + 58, b, 1);
		world.setBlock(i + 25, j + 2, k + 59, b, 1);
		world.setBlock(i + 25, j + 2, k + 75, b, 1);
		world.setBlock(i + 25, j + 3, k + 12, b, 1);
		world.setBlock(i + 25, j + 3, k + 22, b, 1);
		world.setBlock(i + 25, j + 3, k + 26, b, 1);
		world.setBlock(i + 25, j + 3, k + 30, b, 1);
		world.setBlock(i + 25, j + 3, k + 39, b, 1);
		world.setBlock(i + 25, j + 3, k + 43, b, 1);
		world.setBlock(i + 25, j + 3, k + 44, b, 1);
		world.setBlock(i + 25, j + 3, k + 45, b, 1);
		world.setBlock(i + 25, j + 3, k + 46, b, 1);
