/*******************************************************************************
 * @author Reika Kalseki
 * 
 * Copyright 2015
 * 
 * All rights reserved.
 * Distribution of the software in any form is only allowed with
 * explicit, prior permission from the owner.
 ******************************************************************************/
package Reika.ChromatiCraft.World.Dimension.Structure.TDMaze;

import java.util.Random;

import net.minecraft.block.Block;
import net.minecraft.init.Blocks;
import Reika.ChromatiCraft.Base.DimensionStructureGenerator;
import Reika.ChromatiCraft.Base.StructurePiece;
import Reika.ChromatiCraft.Block.Worldgen.BlockStructureShield.BlockType;
import Reika.ChromatiCraft.Registry.ChromaBlocks;
import Reika.DragonAPI.Instantiable.Worldgen.ChunkSplicedGenerationCache;

public class LootRoom extends StructurePiece {

	private final Random rand;

	public LootRoom(DimensionStructureGenerator g, Random r) {
		super(g);
		rand = r;
	}

	@Override
	public void generate(ChunkSplicedGenerationCache world, int i, int j, int k) {
		i -= 5;
		j -= 5;
		k -= 5;
		Block sh = ChromaBlocks.STRUCTSHIELD.getBlockInstance();
		int ml = BlockType.LIGHT.metadata;
		int ms = BlockType.STONE.metadata;
		Block b = ChromaBlocks.PYLONSTRUCT.getBlockInstance();

		this.placeCore(i+5, j+2, k+5);

		world.setBlock(i+0, j+0, k+0, sh, ms);
		world.setBlock(i+0, j+0, k+1, sh, ms);
		world.setBlock(i+0, j+0, k+2, sh, ms);
		world.setBlock(i+0, j+0, k+3, sh, ms);
		world.setBlock(i+0, j+0, k+4, sh, ms);
		world.setBlock(i+0, j+0, k+5, sh, ms);
		world.setBlock(i+0, j+0, k+6, sh, ms);
		world.setBlock(i+0, j+0, k+7, sh, ms);
		world.setBlock(i+0, j+0, k+8, sh, ms);
		world.setBlock(i+0, j+0, k+9, sh, ms);
		world.setBlock(i+0, j+0, k+10, sh, ms);
		world.setBlock(i+0, j+1, k+0, sh, ms);
		world.setBlock(i+0, j+1, k+1, sh, ms);
		world.setBlock(i+0, j+1, k+2, sh, ms);
		world.setBlock(i+0, j+1, k+3, sh, ms);
		world.setBlock(i+0, j+1, k+4, sh, ms);
		world.setBlock(i+0, j+1, k+5, sh, ms);
		world.setBlock(i+0, j+1, k+6, sh, ms);
		world.setBlock(i+0, j+1, k+7, sh, ms);
		world.setBlock(i+0, j+1, k+8, sh, ms);
		world.setBlock(i+0, j+1, k+9, sh, ms);
		world.setBlock(i+0, j+1, k+10, sh, ms);
		world.setBlock(i+0, j+2, k+0, sh, ms);
		world.setBlock(i+0, j+2, k+1, sh, ms);
		world.setBlock(i+0, j+2, k+2, sh, ms);
		world.setBlock(i+0, j+2, k+3, sh, ms);
		world.setBlock(i+0, j+2, k+4, sh, ms);
		world.setBlock(i+0, j+2, k+5, sh, ms);
		world.setBlock(i+0, j+2, k+6, sh, ms);
		world.setBlock(i+0, j+2, k+7, sh, ms);
		world.setBlock(i+0, j+2, k+8, sh, ms);
		world.setBlock(i+0, j+2, k+9, sh, ms);
		world.setBlock(i+0, j+2, k+10, sh, ms);
		world.setBlock(i+0, j+3, k+0, sh, ms);
		world.setBlock(i+0, j+3, k+1, sh, ms);
		world.setBlock(i+0, j+3, k+2, sh, ms);
		world.setBlock(i+0, j+3, k+3, sh, ms);
		world.setBlock(i+0, j+3, k+4, sh, ms);
		world.setBlock(i+0, j+3, k+5, sh, ms);
		world.setBlock(i+0, j+3, k+6, sh, ms);
		world.setBlock(i+0, j+3, k+7, sh, ms);
		world.setBlock(i+0, j+3, k+8, sh, ms);
		world.setBlock(i+0, j+3, k+9, sh, ms);
		world.setBlock(i+0, j+3, k+10, sh, ms);
		world.setBlock(i+0, j+4, k+0, sh, ms);
		world.setBlock(i+0, j+4, k+1, sh, ms);
		world.setBlock(i+0, j+4, k+2, sh, ms);
		world.setBlock(i+0, j+4, k+3, sh, ms);
		world.setBlock(i+0, j+4, k+4, sh, ms);
		world.setBlock(i+0, j+4, k+5, sh, ms);
		world.setBlock(i+0, j+4, k+6, sh, ms);
		world.setBlock(i+0, j+4, k+7, sh, ms);
		world.setBlock(i+0, j+4, k+8, sh, ms);
		world.setBlock(i+0, j+4, k+9, sh, ms);
		world.setBlock(i+0, j+4, k+10, sh, ms);
		world.setBlock(i+0, j+5, k+0, sh, ms);
		world.setBlock(i+0, j+5, k+1, sh, ms);
		world.setBlock(i+0, j+5, k+2, sh, ms);
		world.setBlock(i+0, j+5, k+3, sh, ms);
		world.setBlock(i+0, j+5, k+4, sh, ms);
		world.setBlock(i+0, j+5, k+5, sh, ms);
		world.setBlock(i+0, j+5, k+6, sh, ms);
		world.setBlock(i+0, j+5, k+7, sh, ms);
		world.setBlock(i+0, j+5, k+8, sh, ms);
		world.setBlock(i+0, j+5, k+9, sh, ms);
		world.setBlock(i+0, j+5, k+10, sh, ms);
		world.setBlock(i+0, j+6, k+0, sh, ms);
		world.setBlock(i+0, j+6, k+1, sh, ms);
		world.setBlock(i+0, j+6, k+2, sh, ms);
		world.setBlock(i+0, j+6, k+3, sh, ms);
		world.setBlock(i+0, j+6, k+4, sh, ms);
		world.setBlock(i+0, j+6, k+5, sh, ms);
		world.setBlock(i+0, j+6, k+6, sh, ms);
		world.setBlock(i+0, j+6, k+7, sh, ms);
		world.setBlock(i+0, j+6, k+8, sh, ms);
		world.setBlock(i+0, j+6, k+9, sh, ms);
		world.setBlock(i+0, j+6, k+10, sh, ms);
		world.setBlock(i+1, j+0, k+0, sh, ms);
		world.setBlock(i+1, j+0, k+1, sh, ms);
		world.setBlock(i+1, j+0, k+2, sh, ms);
		world.setBlock(i+1, j+0, k+3, sh, ms);
		world.setBlock(i+1, j+0, k+4, sh, ms);
		world.setBlock(i+1, j+0, k+5, sh, ms);
		world.setBlock(i+1, j+0, k+6, sh, ms);
		world.setBlock(i+1, j+0, k+7, sh, ms);
		world.setBlock(i+1, j+0, k+8, sh, ms);
		world.setBlock(i+1, j+0, k+9, sh, ms);
		world.setBlock(i+1, j+0, k+10, sh, ms);
		world.setBlock(i+1, j+1, k+0, sh, ms);
		world.setBlock(i+1, j+1, k+1, sh, ms);
		world.setBlock(i+1, j+1, k+2, Blocks.air);
		world.setBlock(i+1, j+1, k+3, Blocks.air);
		world.setBlock(i+1, j+1, k+4, Blocks.air);
		world.setBlock(i+1, j+1, k+5, Blocks.air);
		world.setBlock(i+1, j+1, k+6, Blocks.air);
		world.setBlock(i+1, j+1, k+7, Blocks.air);
		world.setBlock(i+1, j+1, k+8, Blocks.air);
		world.setBlock(i+1, j+1, k+9, sh, ms);
		world.setBlock(i+1, j+1, k+10, sh, ms);
		world.setBlock(i+1, j+2, k+0, sh, ms);
		world.setBlock(i+1, j+2, k+1, sh, ml);
		world.setBlock(i+1, j+2, k+2, Blocks.air);
		world.setBlock(i+1, j+2, k+3, Blocks.air);
		world.setBlock(i+1, j+2, k+4, Blocks.air);
		world.setBlock(i+1, j+2, k+5, Blocks.air);
		world.setBlock(i+1, j+2, k+6, Blocks.air);
		world.setBlock(i+1, j+2, k+7, Blocks.air);
		world.setBlock(i+1, j+2, k+8, Blocks.air);
		world.setBlock(i+1, j+2, k+9, sh, ml);
		world.setBlock(i+1, j+2, k+10, sh, ms);
		world.setBlock(i+1, j+3, k+0, sh, ms);
		world.setBlock(i+1, j+3, k+1, sh, ms);
		world.setBlock(i+1, j+3, k+2, sh, ms);
		world.setBlock(i+1, j+3, k+3, sh, ms);
		world.setBlock(i+1, j+3, k+4, sh, ms);
		world.setBlock(i+1, j+3, k+5, sh, ms);
		world.setBlock(i+1, j+3, k+6, sh, ms);
		world.setBlock(i+1, j+3, k+7, sh, ms);
		world.setBlock(i+1, j+3, k+8, sh, ms);
		world.setBlock(i+1, j+3, k+9, sh, ms);
		world.setBlock(i+1, j+3, k+10, sh, ms);
		world.setBlock(i+1, j+4, k+0, sh, ms);
		world.setBlock(i+1, j+4, k+1, Blocks.air);
		world.setBlock(i+1, j+4, k+2, Blocks.air);
		world.setBlock(i+1, j+4, k+3, Blocks.air);
		world.setBlock(i+1, j+4, k+4, Blocks.air);
		world.setBlock(i+1, j+4, k+5, Blocks.air);
		world.setBlock(i+1, j+4, k+6, Blocks.air);
		world.setBlock(i+1, j+4, k+7, Blocks.air);
		world.setBlock(i+1, j+4, k+8, Blocks.air);
		world.setBlock(i+1, j+4, k+9, Blocks.air);
		world.setBlock(i+1, j+4, k+10, sh, ms);
		world.setBlock(i+1, j+5, k+0, sh, ms);
		world.setBlock(i+1, j+5, k+1, Blocks.air);
		world.setBlock(i+1, j+5, k+2, Blocks.air);
		world.setBlock(i+1, j+5, k+3, Blocks.air);
		world.setBlock(i+1, j+5, k+4, Blocks.air);
		world.setBlock(i+1, j+5, k+5, Blocks.air);
		world.setBlock(i+1, j+5, k+6, Blocks.air);
		world.setBlock(i+1, j+5, k+7, Blocks.air);
		world.setBlock(i+1, j+5, k+8, Blocks.air);
		world.setBlock(i+1, j+5, k+9, Blocks.air);
		world.setBlock(i+1, j+5, k+10, sh, ms);
		world.setBlock(i+1, j+6, k+0, sh, ms);
		world.setBlock(i+1, j+6, k+1, sh, ms);
		world.setBlock(i+1, j+6, k+2, sh, ms);
		world.setBlock(i+1, j+6, k+3, sh, ms);
		world.setBlock(i+1, j+6, k+4, sh, ms);
		world.setBlock(i+1, j+6, k+5, sh, ms);
		world.setBlock(i+1, j+6, k+6, sh, ms);
		world.setBlock(i+1, j+6, k+7, sh, ms);
		world.setBlock(i+1, j+6, k+8, sh, ms);
		world.setBlock(i+1, j+6, k+9, sh, ms);
		world.setBlock(i+1, j+6, k+10, sh, ms);
		world.setBlock(i+2, j+0, k+0, sh, ms);
		world.setBlock(i+2, j+0, k+1, sh, ms);
		world.setBlock(i+2, j+0, k+2, sh, ms);
		world.setBlock(i+2, j+0, k+3, sh, ms);
		world.setBlock(i+2, j+0, k+4, sh, ms);
		world.setBlock(i+2, j+0, k+5, sh, ms);
		world.setBlock(i+2, j+0, k+6, sh, ms);
		world.setBlock(i+2, j+0, k+7, sh, ms);
		world.setBlock(i+2, j+0, k+8, sh, ms);
		world.setBlock(i+2, j+0, k+9, sh, ms);
		world.setBlock(i+2, j+0, k+10, sh, ms);
		world.setBlock(i+2, j+1, k+0, sh, ms);
		world.setBlock(i+2, j+1, k+1, Blocks.air);
		world.setBlock(i+2, j+1, k+2, Blocks.air);
		world.setBlock(i+2, j+1, k+3, Blocks.air);
		world.setBlock(i+2, j+1, k+4, Blocks.air);
		world.setBlock(i+2, j+1, k+5, Blocks.air);
		world.setBlock(i+2, j+1, k+6, Blocks.air);
		world.setBlock(i+2, j+1, k+7, Blocks.air);
		world.setBlock(i+2, j+1, k+8, Blocks.air);
		world.setBlock(i+2, j+1, k+9, Blocks.air);
		world.setBlock(i+2, j+1, k+10, sh, ms);
		world.setBlock(i+2, j+2, k+0, sh, ms);
		world.setBlock(i+2, j+2, k+1, Blocks.air);
		world.setBlock(i+2, j+2, k+2, Blocks.air);
		world.setBlock(i+2, j+2, k+3, Blocks.air);
		world.setBlock(i+2, j+2, k+4, Blocks.air);
		world.setBlock(i+2, j+2, k+5, Blocks.air);
		world.setBlock(i+2, j+2, k+6, Blocks.air);
		world.setBlock(i+2, j+2, k+7, Blocks.air);
		world.setBlock(i+2, j+2, k+8, Blocks.air);
		world.setBlock(i+2, j+2, k+9, Blocks.air);
		world.setBlock(i+2, j+2, k+10, sh, ms);
		world.setBlock(i+2, j+3, k+0, sh, ms);
		world.setBlock(i+2, j+3, k+1, sh, ms);
		world.setBlock(i+2, j+3, k+2, sh, ms);
		world.setBlock(i+2, j+3, k+3, sh, ms);
		world.setBlock(i+2, j+3, k+4, sh, ms);
		world.setBlock(i+2, j+3, k+5, sh, ms);
		world.setBlock(i+2, j+3, k+6, sh, ms);
		world.setBlock(i+2, j+3, k+7, sh, ms);
		world.setBlock(i+2, j+3, k+8, sh, ms);
		world.setBlock(i+2, j+3, k+9, sh, ms);
		world.setBlock(i+2, j+3, k+10, sh, ms);
		world.setBlock(i+2, j+4, k+0, sh, ms);
		world.setBlock(i+2, j+4, k+1, Blocks.air);
		world.setBlock(i+2, j+4, k+2, Blocks.air);
		world.setBlock(i+2, j+4, k+3, Blocks.air);
		world.setBlock(i+2, j+4, k+4, Blocks.air);
		world.setBlock(i+2, j+4, k+5, Blocks.air);
		world.setBlock(i+2, j+4, k+6, Blocks.air);
		world.setBlock(i+2, j+4, k+7, Blocks.air);
		world.setBlock(i+2, j+4, k+8, Blocks.air);
		world.setBlock(i+2, j+4, k+9, Blocks.air);
		world.setBlock(i+2, j+4, k+10, sh, ms);
		world.setBlock(i+2, j+5, k+0, sh, ms);
		world.setBlock(i+2, j+5, k+1, Blocks.air);
		world.setBlock(i+2, j+5, k+2, Blocks.air);
		world.setBlock(i+2, j+5, k+3, Blocks.air);
		world.setBlock(i+2, j+5, k+4, Blocks.air);
		world.setBlock(i+2, j+5, k+5, Blocks.air);
		world.setBlock(i+2, j+5, k+6, Blocks.air);
		world.setBlock(i+2, j+5, k+7, Blocks.air);
		world.setBlock(i+2, j+5, k+8, Blocks.air);
		world.setBlock(i+2, j+5, k+9, Blocks.air);
		world.setBlock(i+2, j+5, k+10, sh, ms);
		world.setBlock(i+2, j+6, k+0, sh, ms);
		world.setBlock(i+2, j+6, k+1, sh, ms);
		world.setBlock(i+2, j+6, k+2, sh, ms);
		world.setBlock(i+2, j+6, k+3, sh, ms);
		world.setBlock(i+2, j+6, k+4, sh, ms);
		world.setBlock(i+2, j+6, k+5, sh, ms);
		world.setBlock(i+2, j+6, k+6, sh, ms);
		world.setBlock(i+2, j+6, k+7, sh, ms);
		world.setBlock(i+2, j+6, k+8, sh, ms);
		world.setBlock(i+2, j+6, k+9, sh, ms);
		world.setBlock(i+2, j+6, k+10, sh, ms);
		world.setBlock(i+3, j+0, k+0, sh, ms);
		world.setBlock(i+3, j+0, k+1, sh, ms);
		world.setBlock(i+3, j+0, k+2, sh, ms);
		world.setBlock(i+3, j+0, k+3, sh, ms);
		world.setBlock(i+3, j+0, k+4, sh, ms);
		world.setBlock(i+3, j+0, k+5, sh, ms);
		world.setBlock(i+3, j+0, k+6, sh, ms);
		world.setBlock(i+3, j+0, k+7, sh, ms);
		world.setBlock(i+3, j+0, k+8, sh, ms);
		world.setBlock(i+3, j+0, k+9, sh, ms);
		world.setBlock(i+3, j+0, k+10, sh, ms);
		world.setBlock(i+3, j+1, k+0, sh, ms);
		world.setBlock(i+3, j+1, k+1, Blocks.air);
		world.setBlock(i+3, j+1, k+2, Blocks.air);
		world.setBlock(i+3, j+1, k+3, sh, ms);
		world.setBlock(i+3, j+1, k+4, sh, ms);
		world.setBlock(i+3, j+1, k+5, sh, ms);
		world.setBlock(i+3, j+1, k+6, sh, ms);
		world.setBlock(i+3, j+1, k+7, sh, ms);
		world.setBlock(i+3, j+1, k+8, Blocks.air);
		world.setBlock(i+3, j+1, k+9, Blocks.air);
		world.setBlock(i+3, j+1, k+10, sh, ms);
		world.setBlock(i+3, j+2, k+0, sh, ms);
		world.setBlock(i+3, j+2, k+1, Blocks.air);
		world.setBlock(i+3, j+2, k+2, Blocks.air);
		world.setBlock(i+3, j+2, k+3, sh, ms);
		world.setBlock(i+3, j+2, k+4, sh, ms);
		world.setBlock(i+3, j+2, k+5, sh, 5);
		world.setBlock(i+3, j+2, k+6, sh, ms);
		world.setBlock(i+3, j+2, k+7, sh, ms);
		world.setBlock(i+3, j+2, k+8, Blocks.air);
		world.setBlock(i+3, j+2, k+9, Blocks.air);
		world.setBlock(i+3, j+2, k+10, sh, ms);
		world.setBlock(i+3, j+3, k+0, sh, ms);
		world.setBlock(i+3, j+3, k+1, sh, ms);
		world.setBlock(i+3, j+3, k+2, sh, ms);
		world.setBlock(i+3, j+3, k+3, sh, ms);
		world.setBlock(i+3, j+3, k+4, sh, ms);
		world.setBlock(i+3, j+3, k+5, sh, ms);
		world.setBlock(i+3, j+3, k+6, sh, ms);
		world.setBlock(i+3, j+3, k+7, sh, ms);
		world.setBlock(i+3, j+3, k+8, sh, ms);
		world.setBlock(i+3, j+3, k+9, sh, ms);
		world.setBlock(i+3, j+3, k+10, sh, ms);
		world.setBlock(i+3, j+4, k+0, sh, ms);
		world.setBlock(i+3, j+4, k+1, Blocks.air);
		world.setBlock(i+3, j+4, k+2, Blocks.air);
		world.setBlock(i+3, j+4, k+3, sh, ms);
		world.setBlock(i+3, j+4, k+4, sh, ms);
		world.setBlock(i+3, j+4, k+5, sh, ms);
		world.setBlock(i+3, j+4, k+6, sh, ms);
		world.setBlock(i+3, j+4, k+7, sh, ms);
		world.setBlock(i+3, j+4, k+8, Blocks.air);
		world.setBlock(i+3, j+4, k+9, Blocks.air);
		world.setBlock(i+3, j+4, k+10, sh, ms);
		world.setBlock(i+3, j+5, k+0, sh, ms);
		world.setBlock(i+3, j+5, k+1, Blocks.air);
		world.setBlock(i+3, j+5, k+2, Blocks.air);
		world.setBlock(i+3, j+5, k+3, sh, ms);
		world.setBlock(i+3, j+5, k+4, sh, ms);
		world.setBlock(i+3, j+5, k+5, sh, ms);
		world.setBlock(i+3, j+5, k+6, sh, ms);
		world.setBlock(i+3, j+5, k+7, sh, ms);
		world.setBlock(i+3, j+5, k+8, Blocks.air);
		world.setBlock(i+3, j+5, k+9, Blocks.air);
		world.setBlock(i+3, j+5, k+10, sh, ms);
		world.setBlock(i+3, j+6, k+0, sh, ms);
		world.setBlock(i+3, j+6, k+1, sh, ms);
		world.setBlock(i+3, j+6, k+2, sh, ms);
		world.setBlock(i+3, j+6, k+3, sh, ms);
		world.setBlock(i+3, j+6, k+4, sh, ms);
		world.setBlock(i+3, j+6, k+5, sh, ms);
		world.setBlock(i+3, j+6, k+6, sh, ms);
		world.setBlock(i+3, j+6, k+7, sh, ms);
		world.setBlock(i+3, j+6, k+8, sh, ms);
		world.setBlock(i+3, j+6, k+9, sh, ms);
		world.setBlock(i+3, j+6, k+10, sh, ms);
		world.setBlock(i+4, j+0, k+0, sh, ms);
		world.setBlock(i+4, j+0, k+1, sh, ms);
		world.setBlock(i+4, j+0, k+2, sh, ms);
		world.setBlock(i+4, j+0, k+3, sh, ms);
		world.setBlock(i+4, j+0, k+4, sh, ms);
		world.setBlock(i+4, j+0, k+5, sh, ms);
		world.setBlock(i+4, j+0, k+6, sh, ms);
		world.setBlock(i+4, j+0, k+7, sh, ms);
		world.setBlock(i+4, j+0, k+8, sh, ms);
		world.setBlock(i+4, j+0, k+9, sh, ms);
		world.setBlock(i+4, j+0, k+10, sh, ms);
		world.setBlock(i+4, j+1, k+0, sh, ms);
		world.setBlock(i+4, j+1, k+1, Blocks.air);
		world.setBlock(i+4, j+1, k+2, Blocks.air);
		world.setBlock(i+4, j+1, k+3, sh, ms);
		world.setBlock(i+4, j+1, k+4, Blocks.air);
		world.setBlock(i+4, j+1, k+5, Blocks.air);
		world.setBlock(i+4, j+1, k+6, Blocks.air);
		world.setBlock(i+4, j+1, k+7, sh, ms);
		world.setBlock(i+4, j+1, k+8, Blocks.air);
		world.setBlock(i+4, j+1, k+9, Blocks.air);
		world.setBlock(i+4, j+1, k+10, sh, ms);
		world.setBlock(i+4, j+2, k+0, sh, ms);
		world.setBlock(i+4, j+2, k+1, Blocks.air);
		world.setBlock(i+4, j+2, k+2, Blocks.air);
		world.setBlock(i+4, j+2, k+3, sh, ms);
		world.setBlock(i+4, j+2, k+4, Blocks.air);
		world.setBlock(i+4, j+2, k+5, Blocks.air);
		world.setBlock(i+4, j+2, k+6, Blocks.air);
		world.setBlock(i+4, j+2, k+7, sh, ms);
		world.setBlock(i+4, j+2, k+8, Blocks.air);
		world.setBlock(i+4, j+2, k+9, Blocks.air);
		world.setBlock(i+4, j+2, k+10, sh, ms);
		world.setBlock(i+4, j+3, k+0, sh, ms);
		world.setBlock(i+4, j+3, k+1, sh, ms);
		world.setBlock(i+4, j+3, k+2, sh, ms);
		world.setBlock(i+4, j+3, k+3, sh, ms);
		world.setBlock(i+4, j+3, k+4, sh, ms);
		world.setBlock(i+4, j+3, k+5, sh, ms);
		world.setBlock(i+4, j+3, k+6, sh, ms);
		world.setBlock(i+4, j+3, k+7, sh, ms);
		world.setBlock(i+4, j+3, k+8, sh, ms);
		world.setBlock(i+4, j+3, k+9, sh, ms);
		world.setBlock(i+4, j+3, k+10, sh, ms);
		world.setBlock(i+4, j+4, k+0, sh, ms);
		world.setBlock(i+4, j+4, k+1, Blocks.air);
		world.setBlock(i+4, j+4, k+2, Blocks.air);
		world.setBlock(i+4, j+4, k+3, sh, ms);
		world.setBlock(i+4, j+4, k+4, Blocks.air);
		world.setBlock(i+4, j+4, k+5, Blocks.air);
		world.setBlock(i+4, j+4, k+6, Blocks.air);
		world.setBlock(i+4, j+4, k+7, sh, ms);
		world.setBlock(i+4, j+4, k+8, Blocks.air);
		world.setBlock(i+4, j+4, k+9, Blocks.air);
		world.setBlock(i+4, j+4, k+10, sh, ms);
		world.setBlock(i+4, j+5, k+0, sh, ms);
		world.setBlock(i+4, j+5, k+1, Blocks.air);
		world.setBlock(i+4, j+5, k+2, Blocks.air);
		world.setBlock(i+4, j+5, k+3, sh, ms);
		world.setBlock(i+4, j+5, k+4, Blocks.air);
		world.setBlock(i+4, j+5, k+5, Blocks.air);
		world.setBlock(i+4, j+5, k+6, Blocks.air);
		world.setBlock(i+4, j+5, k+7, sh, ms);
		world.setBlock(i+4, j+5, k+8, Blocks.air);
		world.setBlock(i+4, j+5, k+9, Blocks.air);
		world.setBlock(i+4, j+5, k+10, sh, ms);
		world.setBlock(i+4, j+6, k+0, sh, ms);
		world.setBlock(i+4, j+6, k+1, sh, ms);
		world.setBlock(i+4, j+6, k+2, sh, ms);
		world.setBlock(i+4, j+6, k+3, sh, ms);
		world.setBlock(i+4, j+6, k+4, Blocks.air);
		world.setBlock(i+4, j+6, k+5, Blocks.air);
		world.setBlock(i+4, j+6, k+6, Blocks.air);
		world.setBlock(i+4, j+6, k+7, sh, ms);
		world.setBlock(i+4, j+6, k+8, sh, ms);
		world.setBlock(i+4, j+6, k+9, sh, ms);
		world.setBlock(i+4, j+6, k+10, sh, ms);
		world.setBlock(i+5, j+0, k+0, sh, ms);
		world.setBlock(i+5, j+0, k+1, sh, ms);
		world.setBlock(i+5, j+0, k+2, sh, ms);
		world.setBlock(i+5, j+0, k+3, sh, ms);
		world.setBlock(i+5, j+0, k+4, sh, ms);
		world.setBlock(i+5, j+0, k+5, sh, ms);
		world.setBlock(i+5, j+0, k+6, sh, ms);
		world.setBlock(i+5, j+0, k+7, sh, ms);
		world.setBlock(i+5, j+0, k+8, sh, ms);
		world.setBlock(i+5, j+0, k+9, sh, ms);
		world.setBlock(i+5, j+0, k+10, sh, ms);
		world.setBlock(i+5, j+1, k+0, sh, ms);
		world.setBlock(i+5, j+1, k+1, Blocks.air);
		world.setBlock(i+5, j+1, k+2, Blocks.air);
		world.setBlock(i+5, j+1, k+3, sh, ms);
		world.setBlock(i+5, j+1, k+4, Blocks.air);
		world.setBlock(i+5, j+1, k+5, Blocks.air);
		world.setBlock(i+5, j+1, k+6, Blocks.air);
		world.setBlock(i+5, j+1, k+7, sh, ms);
		world.setBlock(i+5, j+1, k+8, Blocks.air);
		world.setBlock(i+5, j+1, k+9, Blocks.air);
		world.setBlock(i+5, j+1, k+10, sh, ms);
		world.setBlock(i+5, j+2, k+0, sh, ms);
		world.setBlock(i+5, j+2, k+1, Blocks.air);
		world.setBlock(i+5, j+2, k+2, Blocks.air);
		world.setBlock(i+5, j+2, k+3, sh, 5);
		world.setBlock(i+5, j+2, k+4, Blocks.air);
		world.setBlock(i+5, j+2, k+6, Blocks.air);
		world.setBlock(i+5, j+2, k+7, sh, 5);
		world.setBlock(i+5, j+2, k+8, Blocks.air);
		world.setBlock(i+5, j+2, k+9, Blocks.air);
		world.setBlock(i+5, j+2, k+10, sh, ms);
		world.setBlock(i+5, j+3, k+0, sh, ms);
		world.setBlock(i+5, j+3, k+1, sh, ms);
		world.setBlock(i+5, j+3, k+2, sh, ms);
		world.setBlock(i+5, j+3, k+3, sh, ms);
		world.setBlock(i+5, j+3, k+4, sh, ms);
		world.setBlock(i+5, j+3, k+5, sh, ms);
		world.setBlock(i+5, j+3, k+6, sh, ms);
		world.setBlock(i+5, j+3, k+7, sh, ms);
		world.setBlock(i+5, j+3, k+8, sh, ms);
		world.setBlock(i+5, j+3, k+9, sh, ms);
		world.setBlock(i+5, j+3, k+10, sh, ms);
		world.setBlock(i+5, j+4, k+0, sh, ms);
		world.setBlock(i+5, j+4, k+1, Blocks.air);
		world.setBlock(i+5, j+4, k+2, Blocks.air);
		world.setBlock(i+5, j+4, k+3, sh, ms);
		world.setBlock(i+5, j+4, k+4, Blocks.air);
		world.setBlock(i+5, j+4, k+5, Blocks.air);
		world.setBlock(i+5, j+4, k+6, Blocks.air);
		world.setBlock(i+5, j+4, k+7, sh, ms);
		world.setBlock(i+5, j+4, k+8, Blocks.air);
		world.setBlock(i+5, j+4, k+9, Blocks.air);
		world.setBlock(i+5, j+4, k+10, sh, ms);
		world.setBlock(i+5, j+5, k+0, sh, ms);
		world.setBlock(i+5, j+5, k+1, Blocks.air);
		world.setBlock(i+5, j+5, k+2, Blocks.air);
		world.setBlock(i+5, j+5, k+3, sh, ms);
		world.setBlock(i+5, j+5, k+4, Blocks.air);
		world.setBlock(i+5, j+5, k+5, Blocks.air);
		world.setBlock(i+5, j+5, k+6, Blocks.air);
		world.setBlock(i+5, j+5, k+7, sh, ms);
		world.setBlock(i+5, j+5, k+8, Blocks.air);
		world.setBlock(i+5, j+5, k+9, Blocks.air);
		world.setBlock(i+5, j+5, k+10, sh, ms);
		world.setBlock(i+5, j+6, k+0, sh, ms);
		world.setBlock(i+5, j+6, k+1, sh, ms);
		world.setBlock(i+5, j+6, k+2, sh, ms);
		world.setBlock(i+5, j+6, k+3, sh, ms);
		world.setBlock(i+5, j+6, k+4, Blocks.air);
		world.setBlock(i+5, j+6, k+5, Blocks.air);
		world.setBlock(i+5, j+6, k+6, Blocks.air);
		world.setBlock(i+5, j+6, k+7, sh, ms);
		world.setBlock(i+5, j+6, k+8, sh, ms);
		world.setBlock(i+5, j+6, k+9, sh, ms);
		world.setBlock(i+5, j+6, k+10, sh, ms);
		world.setBlock(i+6, j+0, k+0, sh, ms);
		world.setBlock(i+6, j+0, k+1, sh, ms);
		world.setBlock(i+6, j+0, k+2, sh, ms);
		world.setBlock(i+6, j+0, k+3, sh, ms);
		world.setBlock(i+6, j+0, k+4, sh, ms);
		world.setBlock(i+6, j+0, k+5, sh, ms);
		world.setBlock(i+6, j+0, k+6, sh, ms);
		world.setBlock(i+6, j+0, k+7, sh, ms);
		world.setBlock(i+6, j+0, k+8, sh, ms);
		world.setBlock(i+6, j+0, k+9, sh, ms);
		world.setBlock(i+6, j+0, k+10, sh, ms);
		world.setBlock(i+6, j+1, k+0, sh, ms);
		world.setBlock(i+6, j+1, k+1, Blocks.air);
		world.setBlock(i+6, j+1, k+2, Blocks.air);
		world.setBlock(i+6, j+1, k+3, sh, ms);
		world.setBlock(i+6, j+1, k+4, Blocks.air);
		world.setBlock(i+6, j+1, k+5, Blocks.air);
		world.setBlock(i+6, j+1, k+6, Blocks.air);
		world.setBlock(i+6, j+1, k+7, sh, ms);
		world.setBlock(i+6, j+1, k+8, Blocks.air);
		world.setBlock(i+6, j+1, k+9, Blocks.air);
		world.setBlock(i+6, j+1, k+10, sh, ms);
		world.setBlock(i+6, j+2, k+0, sh, ms);
		world.setBlock(i+6, j+2, k+1, Blocks.air);
		world.setBlock(i+6, j+2, k+2, Blocks.air);
		world.setBlock(i+6, j+2, k+3, sh, ms);
		world.setBlock(i+6, j+2, k+4, Blocks.air);
		world.setBlock(i+6, j+2, k+5, Blocks.air);
		world.setBlock(i+6, j+2, k+6, Blocks.air);
		world.setBlock(i+6, j+2, k+7, sh, ms);
		world.setBlock(i+6, j+2, k+8, Blocks.air);
		world.setBlock(i+6, j+2, k+9, Blocks.air);
		world.setBlock(i+6, j+2, k+10, sh, ms);
		world.setBlock(i+6, j+3, k+0, sh, ms);
		world.setBlock(i+6, j+3, k+1, sh, ms);
		world.setBlock(i+6, j+3, k+2, sh, ms);
		world.setBlock(i+6, j+3, k+3, sh, ms);
		world.setBlock(i+6, j+3, k+4, sh, ms);
		world.setBlock(i+6, j+3, k+5, sh, ms);
		world.setBlock(i+6, j+3, k+6, sh, ms);
		world.setBlock(i+6, j+3, k+7, sh, ms);
		world.setBlock(i+6, j+3, k+8, sh, ms);
		world.setBlock(i+6, j+3, k+9, sh, ms);
		world.setBlock(i+6, j+3, k+10, sh, ms);
		world.setBlock(i+6, j+4, k+0, sh, ms);
		world.setBlock(i+6, j+4, k+1, Blocks.air);
		world.setBlock(i+6, j+4, k+2, Blocks.air);
		world.setBlock(i+6, j+4, k+3, sh, ms);
		world.setBlock(i+6, j+4, k+4, Blocks.air);
		world.setBlock(i+6, j+4, k+5, Blocks.air);
		world.setBlock(i+6, j+4, k+6, Blocks.air);
		world.setBlock(i+6, j+4, k+7, sh, ms);
		world.setBlock(i+6, j+4, k+8, Blocks.air);
		world.setBlock(i+6, j+4, k+9, Blocks.air);
		world.setBlock(i+6, j+4, k+10, sh, ms);
		world.setBlock(i+6, j+5, k+0, sh, ms);
		world.setBlock(i+6, j+5, k+1, Blocks.air);
		world.setBlock(i+6, j+5, k+2, Blocks.air);
		world.setBlock(i+6, j+5, k+3, sh, ms);
		world.setBlock(i+6, j+5, k+4, Blocks.air);
		world.setBlock(i+6, j+5, k+5, Blocks.air);
		world.setBlock(i+6, j+5, k+6, Blocks.air);
		world.setBlock(i+6, j+5, k+7, sh, ms);
		world.setBlock(i+6, j+5, k+8, Blocks.air);
		world.setBlock(i+6, j+5, k+9, Blocks.air);
		world.setBlock(i+6, j+5, k+10, sh, ms);
		world.setBlock(i+6, j+6, k+0, sh, ms);
		world.setBlock(i+6, j+6, k+1, sh, ms);
		world.setBlock(i+6, j+6, k+2, sh, ms);
		world.setBlock(i+6, j+6, k+3, sh, ms);
		world.setBlock(i+6, j+6, k+4, Blocks.air);
		world.setBlock(i+6, j+6, k+5, Blocks.air);
		world.setBlock(i+6, j+6, k+6, Blocks.air);
		world.setBlock(i+6, j+6, k+7, sh, ms);
		world.setBlock(i+6, j+6, k+8, sh, ms);
		world.setBlock(i+6, j+6, k+9, sh, ms);
		world.setBlock(i+6, j+6, k+10, sh, ms);
		world.setBlock(i+7, j+0, k+0, sh, ms);
		world.setBlock(i+7, j+0, k+1, sh, ms);
		world.setBlock(i+7, j+0, k+2, sh, ms);
		world.setBlock(i+7, j+0, k+3, sh, ms);
		world.setBlock(i+7, j+0, k+4, sh, ms);
		world.setBlock(i+7, j+0, k+5, sh, ms);
		world.setBlock(i+7, j+0, k+6, sh, ms);
		world.setBlock(i+7, j+0, k+7, sh, ms);
		world.setBlock(i+7, j+0, k+8, sh, ms);
		world.setBlock(i+7, j+0, k+9, sh, ms);
		world.setBlock(i+7, j+0, k+10, sh, ms);
		world.setBlock(i+7, j+1, k+0, sh, ms);
		world.setBlock(i+7, j+1, k+1, Blocks.air);
		world.setBlock(i+7, j+1, k+2, Blocks.air);
		world.setBlock(i+7, j+1, k+3, sh, ms);
		world.setBlock(i+7, j+1, k+4, sh, ms);
		world.setBlock(i+7, j+1, k+5, sh, ms);
		world.setBlock(i+7, j+1, k+6, sh, ms);
		world.setBlock(i+7, j+1, k+7, sh, ms);
		world.setBlock(i+7, j+1, k+8, Blocks.air);
		world.setBlock(i+7, j+1, k+9, Blocks.air);
		world.setBlock(i+7, j+1, k+10, sh, ms);
		world.setBlock(i+7, j+2, k+0, sh, ms);
		world.setBlock(i+7, j+2, k+1, Blocks.air);
		world.setBlock(i+7, j+2, k+2, Blocks.air);
		world.setBlock(i+7, j+2, k+3, sh, ms);
		world.setBlock(i+7, j+2, k+4, sh, ms);
		world.setBlock(i+7, j+2, k+5, sh, 5);
		world.setBlock(i+7, j+2, k+6, sh, ms);
		world.setBlock(i+7, j+2, k+7, sh, ms);
		world.setBlock(i+7, j+2, k+8, Blocks.air);
		world.setBlock(i+7, j+2, k+9, Blocks.air);
		world.setBlock(i+7, j+2, k+10, sh, ms);
		world.setBlock(i+7, j+3, k+0, sh, ms);
		world.setBlock(i+7, j+3, k+1, sh, ms);
		world.setBlock(i+7, j+3, k+2, sh, ms);
		world.setBlock(i+7, j+3, k+3, sh, ms);
		world.setBlock(i+7, j+3, k+4, sh, ms);
		world.setBlock(i+7, j+3, k+5, sh, ms);
		world.setBlock(i+7, j+3, k+6, sh, ms);
		world.setBlock(i+7, j+3, k+7, sh, ms);
		world.setBlock(i+7, j+3, k+8, sh, ms);
		world.setBlock(i+7, j+3, k+9, sh, ms);
		world.setBlock(i+7, j+3, k+10, sh, ms);
		world.setBlock(i+7, j+4, k+0, sh, ms);
		world.setBlock(i+7, j+4, k+1, Blocks.air);
		world.setBlock(i+7, j+4, k+2, Blocks.air);
		world.setBlock(i+7, j+4, k+3, sh, ms);
		world.setBlock(i+7, j+4, k+4, sh, ms);
		world.setBlock(i+7, j+4, k+5, sh, ms);
		world.setBlock(i+7, j+4, k+6, sh, ms);
		world.setBlock(i+7, j+4, k+7, sh, ms);
		world.setBlock(i+7, j+4, k+8, Blocks.air);
		world.setBlock(i+7, j+4, k+9, Blocks.air);
		world.setBlock(i+7, j+4, k+10, sh, ms);
		world.setBlock(i+7, j+5, k+0, sh, ms);
		world.setBlock(i+7, j+5, k+1, Blocks.air);
		world.setBlock(i+7, j+5, k+2, Blocks.air);
		world.setBlock(i+7, j+5, k+3, sh, ms);
		world.setBlock(i+7, j+5, k+4, sh, ms);
		world.setBlock(i+7, j+5, k+5, sh, ms);
		world.setBlock(i+7, j+5, k+6, sh, ms);
		world.setBlock(i+7, j+5, k+7, sh, ms);
		world.setBlock(i+7, j+5, k+8, Blocks.air);
		world.setBlock(i+7, j+5, k+9, Blocks.air);
		world.setBlock(i+7, j+5, k+10, sh, ms);
		world.setBlock(i+7, j+6, k+0, sh, ms);
		world.setBlock(i+7, j+6, k+1, sh, ms);
		world.setBlock(i+7, j+6, k+2, sh, ms);
		world.setBlock(i+7, j+6, k+3, sh, ms);
		world.setBlock(i+7, j+6, k+4, sh, ms);
		world.setBlock(i+7, j+6, k+5, sh, ms);
		world.setBlock(i+7, j+6, k+6, sh, ms);
		world.setBlock(i+7, j+6, k+7, sh, ms);
		world.setBlock(i+7, j+6, k+8, sh, ms);
		world.setBlock(i+7, j+6, k+9, sh, ms);
		world.setBlock(i+7, j+6, k+10, sh, ms);
		world.setBlock(i+8, j+0, k+0, sh, ms);
		world.setBlock(i+8, j+0, k+1, sh, ms);
		world.setBlock(i+8, j+0, k+2, sh, ms);
		world.setBlock(i+8, j+0, k+3, sh, ms);
		world.setBlock(i+8, j+0, k+4, sh, ms);
		world.setBlock(i+8, j+0, k+5, sh, ms);
		world.setBlock(i+8, j+0, k+6, sh, ms);
		world.setBlock(i+8, j+0, k+7, sh, ms);
		world.setBlock(i+8, j+0, k+8, sh, ms);
		world.setBlock(i+8, j+0, k+9, sh, ms);
		world.setBlock(i+8, j+0, k+10, sh, ms);
		world.setBlock(i+8, j+1, k+0, sh, ms);
		world.setBlock(i+8, j+1, k+1, Blocks.air);
		world.setBlock(i+8, j+1, k+2, Blocks.air);
		world.setBlock(i+8, j+1, k+3, Blocks.air);
		world.setBlock(i+8, j+1, k+4, Blocks.air);
		world.setBlock(i+8, j+1, k+5, Blocks.air);
		world.setBlock(i+8, j+1, k+6, Blocks.air);
		world.setBlock(i+8, j+1, k+7, Blocks.air);
		world.setBlock(i+8, j+1, k+8, Blocks.air);
		world.setBlock(i+8, j+1, k+9, Blocks.air);
		world.setBlock(i+8, j+1, k+10, sh, ms);
		world.setBlock(i+8, j+2, k+0, sh, ms);
		world.setBlock(i+8, j+2, k+1, Blocks.air);
		world.setBlock(i+8, j+2, k+2, Blocks.air);
		world.setBlock(i+8, j+2, k+3, Blocks.air);
		world.setBlock(i+8, j+2, k+4, Blocks.air);
		world.setBlock(i+8, j+2, k+5, Blocks.air);
		world.setBlock(i+8, j+2, k+6, Blocks.air);
		world.setBlock(i+8, j+2, k+7, Blocks.air);
		world.setBlock(i+8, j+2, k+8, Blocks.air);
		world.setBlock(i+8, j+2, k+9, Blocks.air);
		world.setBlock(i+8, j+2, k+10, sh, ms);
		world.setBlock(i+8, j+3, k+0, sh, ms);
		world.setBlock(i+8, j+3, k+1, sh, ms);
		world.setBlock(i+8, j+3, k+2, sh, ms);
		world.setBlock(i+8, j+3, k+3, sh, ms);
		world.setBlock(i+8, j+3, k+4, sh, ms);
		world.setBlock(i+8, j+3, k+5, sh, ms);
		world.setBlock(i+8, j+3, k+6, sh, ms);
		world.setBlock(i+8, j+3, k+7, sh, ms);
		world.setBlock(i+8, j+3, k+8, sh, ms);
		world.setBlock(i+8, j+3, k+9, sh, ms);
		world.setBlock(i+8, j+3, k+10, sh, ms);
		world.setBlock(i+8, j+4, k+0, sh, ms);
		world.setBlock(i+8, j+4, k+1, Blocks.air);
		world.setBlock(i+8, j+4, k+2, Blocks.air);
		world.setBlock(i+8, j+4, k+3, Blocks.air);
		world.setBlock(i+8, j+4, k+4, Blocks.air);
		world.setBlock(i+8, j+4, k+5, Blocks.air);
		world.setBlock(i+8, j+4, k+6, Blocks.air);
		world.setBlock(i+8, j+4, k+7, Blocks.air);
		world.setBlock(i+8, j+4, k+8, Blocks.air);
		world.setBlock(i+8, j+4, k+9, Blocks.air);
		world.setBlock(i+8, j+4, k+10, sh, ms);
		world.setBlock(i+8, j+5, k+0, sh, ms);
		world.setBlock(i+8, j+5, k+1, Blocks.air);
		world.setBlock(i+8, j+5, k+2, Blocks.air);
		world.setBlock(i+8, j+5, k+3, Blocks.air);
		world.setBlock(i+8, j+5, k+4, Blocks.air);
		world.setBlock(i+8, j+5, k+5, Blocks.air);
		world.setBlock(i+8, j+5, k+6, Blocks.air);
		world.setBlock(i+8, j+5, k+7, Blocks.air);
		world.setBlock(i+8, j+5, k+8, Blocks.air);
		world.setBlock(i+8, j+5, k+9, Blocks.air);
		world.setBlock(i+8, j+5, k+10, sh, ms);
		world.setBlock(i+8, j+6, k+0, sh, ms);
		world.setBlock(i+8, j+6, k+1, sh, ms);
		world.setBlock(i+8, j+6, k+2, sh, ms);
		world.setBlock(i+8, j+6, k+4, sh, ms);
		world.setBlock(i+8, j+6, k+5, sh, ms);
		world.setBlock(i+8, j+6, k+6, sh, ms);
		world.setBlock(i+8, j+6, k+7, sh, ms);
		world.setBlock(i+8, j+6, k+8, sh, ms);
		world.setBlock(i+8, j+6, k+9, sh, ms);
		world.setBlock(i+8, j+6, k+10, sh, ms);
		world.setBlock(i+9, j+0, k+0, sh, ms);
		world.setBlock(i+9, j+0, k+1, sh, ms);
		world.setBlock(i+9, j+0, k+2, sh, ms);
		world.setBlock(i+9, j+0, k+3, sh, ms);
		world.setBlock(i+9, j+0, k+4, sh, ms);
		world.setBlock(i+9, j+0, k+5, sh, ms);
		world.setBlock(i+9, j+0, k+6, sh, ms);
		world.setBlock(i+9, j+0, k+7, sh, ms);
		world.setBlock(i+9, j+0, k+8, sh, ms);
		world.setBlock(i+9, j+0, k+9, sh, ms);
		world.setBlock(i+9, j+0, k+10, sh, ms);
		world.setBlock(i+9, j+1, k+0, sh, ms);
		world.setBlock(i+9, j+1, k+1, sh, ms);
		world.setBlock(i+9, j+1, k+2, Blocks.air);
		world.setBlock(i+9, j+1, k+3, Blocks.air);
		world.setBlock(i+9, j+1, k+4, Blocks.air);
		world.setBlock(i+9, j+1, k+5, Blocks.air);
		world.setBlock(i+9, j+1, k+6, Blocks.air);
		world.setBlock(i+9, j+1, k+7, Blocks.air);
		world.setBlock(i+9, j+1, k+8, Blocks.air);
		world.setBlock(i+9, j+1, k+9, sh, ms);
		world.setBlock(i+9, j+1, k+10, sh, ms);
		world.setBlock(i+9, j+2, k+0, sh, ms);
		world.setBlock(i+9, j+2, k+1, sh, ml);
		world.setBlock(i+9, j+2, k+2, Blocks.air);
		world.setBlock(i+9, j+2, k+3, Blocks.air);
		world.setBlock(i+9, j+2, k+4, Blocks.air);
		world.setBlock(i+9, j+2, k+5, Blocks.air);
		world.setBlock(i+9, j+2, k+6, Blocks.air);
		world.setBlock(i+9, j+2, k+7, Blocks.air);
		world.setBlock(i+9, j+2, k+8, Blocks.air);
		world.setBlock(i+9, j+2, k+9, sh, ml);
		world.setBlock(i+9, j+2, k+10, sh, ms);
		world.setBlock(i+9, j+3, k+0, sh, ms);
		world.setBlock(i+9, j+3, k+1, sh, ms);
		world.setBlock(i+9, j+3, k+2, sh, ms);
		world.setBlock(i+9, j+3, k+3, sh, ms);
		world.setBlock(i+9, j+3, k+4, sh, ms);
		world.setBlock(i+9, j+3, k+5, sh, ms);
		world.setBlock(i+9, j+3, k+6, sh, ms);
		world.setBlock(i+9, j+3, k+7, sh, ms);
		world.setBlock(i+9, j+3, k+8, sh, ms);
		world.setBlock(i+9, j+3, k+9, sh, ms);
		world.setBlock(i+9, j+3, k+10, sh, ms);
		world.setBlock(i+9, j+4, k+0, sh, ms);
		world.setBlock(i+9, j+4, k+1, Blocks.air);
		world.setBlock(i+9, j+4, k+2, Blocks.air);
		world.setBlock(i+9, j+4, k+3, Blocks.air);
		world.setBlock(i+9, j+4, k+4, Blocks.air);
		world.setBlock(i+9, j+4, k+5, Blocks.air);
		world.setBlock(i+9, j+4, k+6, Blocks.air);
		world.setBlock(i+9, j+4, k+7, Blocks.air);
		world.setBlock(i+9, j+4, k+8, Blocks.air);
		world.setBlock(i+9, j+4, k+9, Blocks.air);
		world.setBlock(i+9, j+4, k+10, sh, ms);
		world.setBlock(i+9, j+5, k+0, sh, ms);
		world.setBlock(i+9, j+5, k+1, Blocks.air);
		world.setBlock(i+9, j+5, k+2, Blocks.air);
		world.setBlock(i+9, j+5, k+3, Blocks.air);
		world.setBlock(i+9, j+5, k+4, Blocks.air);
		world.setBlock(i+9, j+5, k+5, Blocks.air);
		world.setBlock(i+9, j+5, k+6, Blocks.air);
		world.setBlock(i+9, j+5, k+7, Blocks.air);
		world.setBlock(i+9, j+5, k+8, Blocks.air);
		world.setBlock(i+9, j+5, k+9, Blocks.air);
		world.setBlock(i+9, j+5, k+10, sh, ms);
		world.setBlock(i+9, j+6, k+0, sh, ms);
		world.setBlock(i+9, j+6, k+1, sh, ms);
		world.setBlock(i+9, j+6, k+2, sh, ms);
		world.setBlock(i+9, j+6, k+3, sh, ms);
		world.setBlock(i+9, j+6, k+4, sh, ms);
		world.setBlock(i+9, j+6, k+5, sh, ms);
		world.setBlock(i+9, j+6, k+6, sh, ms);
		world.setBlock(i+9, j+6, k+7, sh, ms);
		world.setBlock(i+9, j+6, k+8, sh, ms);
		world.setBlock(i+9, j+6, k+9, sh, ms);
		world.setBlock(i+9, j+6, k+10, sh, ms);
		world.setBlock(i+10, j+0, k+0, sh, ms);
		world.setBlock(i+10, j+0, k+1, sh, ms);
		world.setBlock(i+10, j+0, k+2, sh, ms);
		world.setBlock(i+10, j+0, k+3, sh, ms);
		world.setBlock(i+10, j+0, k+4, sh, ms);
		world.setBlock(i+10, j+0, k+5, sh, ms);
		world.setBlock(i+10, j+0, k+6, sh, ms);
		world.setBlock(i+10, j+0, k+7, sh, ms);
		world.setBlock(i+10, j+0, k+8, sh, ms);
		world.setBlock(i+10, j+0, k+9, sh, ms);
		world.setBlock(i+10, j+0, k+10, sh, ms);
		world.setBlock(i+10, j+1, k+0, sh, ms);
		world.setBlock(i+10, j+1, k+1, sh, ms);
		world.setBlock(i+10, j+1, k+2, sh, ms);
		world.setBlock(i+10, j+1, k+3, sh, ms);
		world.setBlock(i+10, j+1, k+4, sh, ms);
		world.setBlock(i+10, j+1, k+5, sh, ms);
		world.setBlock(i+10, j+1, k+6, sh, ms);
		world.setBlock(i+10, j+1, k+7, sh, ms);
		world.setBlock(i+10, j+1, k+8, sh, ms);
		world.setBlock(i+10, j+1, k+9, sh, ms);
		world.setBlock(i+10, j+1, k+10, sh, ms);
		world.setBlock(i+10, j+2, k+0, sh, ms);
		world.setBlock(i+10, j+2, k+1, sh, ms);
		world.setBlock(i+10, j+2, k+2, sh, ms);
		world.setBlock(i+10, j+2, k+3, sh, ms);
		world.setBlock(i+10, j+2, k+4, sh, ms);
		world.setBlock(i+10, j+2, k+5, sh, ms);
		world.setBlock(i+10, j+2, k+6, sh, ms);
		world.setBlock(i+10, j+2, k+7, sh, ms);
		world.setBlock(i+10, j+2, k+8, sh, ms);
		world.setBlock(i+10, j+2, k+9, sh, ms);
		world.setBlock(i+10, j+2, k+10, sh, ms);
		world.setBlock(i+10, j+3, k+0, sh, ms);
		world.setBlock(i+10, j+3, k+1, sh, ms);
		world.setBlock(i+10, j+3, k+2, sh, ms);
		world.setBlock(i+10, j+3, k+3, sh, ms);
		world.setBlock(i+10, j+3, k+4, sh, ms);
		world.setBlock(i+10, j+3, k+5, sh, ms);
		world.setBlock(i+10, j+3, k+6, sh, ms);
		world.setBlock(i+10, j+3, k+7, sh, ms);
		world.setBlock(i+10, j+3, k+8, sh, ms);
		world.setBlock(i+10, j+3, k+9, sh, ms);
		world.setBlock(i+10, j+3, k+10, sh, ms);
		world.setBlock(i+10, j+4, k+0, sh, ms);
		world.setBlock(i+10, j+4, k+1, sh, ms);
		world.setBlock(i+10, j+4, k+2, sh, ms);
		world.setBlock(i+10, j+4, k+3, sh, ms);
		world.setBlock(i+10, j+4, k+4, sh, ms);
		world.setBlock(i+10, j+4, k+5, sh, ms);
		world.setBlock(i+10, j+4, k+6, sh, ms);
		world.setBlock(i+10, j+4, k+7, sh, ms);
		world.setBlock(i+10, j+4, k+8, sh, ms);
		world.setBlock(i+10, j+4, k+9, sh, ms);
		world.setBlock(i+10, j+4, k+10, sh, ms);
		world.setBlock(i+10, j+5, k+0, sh, ms);
		world.setBlock(i+10, j+5, k+1, sh, ms);
		world.setBlock(i+10, j+5, k+2, sh, ms);
		world.setBlock(i+10, j+5, k+3, sh, ms);
		world.setBlock(i+10, j+5, k+4, sh, ms);
		world.setBlock(i+10, j+5, k+5, sh, ms);
		world.setBlock(i+10, j+5, k+6, sh, ms);
		world.setBlock(i+10, j+5, k+7, sh, ms);
		world.setBlock(i+10, j+5, k+8, sh, ms);
		world.setBlock(i+10, j+5, k+9, sh, ms);
		world.setBlock(i+10, j+5, k+10, sh, ms);
		world.setBlock(i+10, j+6, k+0, sh, ms);
		world.setBlock(i+10, j+6, k+1, sh, ms);
		world.setBlock(i+10, j+6, k+2, sh, ms);
		world.setBlock(i+10, j+6, k+3, sh, ms);
		world.setBlock(i+10, j+6, k+4, sh, ms);
		world.setBlock(i+10, j+6, k+5, sh, ms);
		world.setBlock(i+10, j+6, k+6, sh, ms);
		world.setBlock(i+10, j+6, k+7, sh, ms);
		world.setBlock(i+10, j+6, k+8, sh, ms);
		world.setBlock(i+10, j+6, k+9, sh, ms);
		world.setBlock(i+10, j+6, k+10, sh, ms);
	}

}
