/*******************************************************************************
 * @author Reika Kalseki
 * 
 * Copyright 2016
 * 
 * All rights reserved.
 * Distribution of the software in any form is only allowed with
 * explicit, prior permission from the owner.
 ******************************************************************************/
package Reika.ChromatiCraft.World.Dimension.Structure.LightPanel;

import net.minecraft.block.Block;
import net.minecraft.init.Blocks;
import net.minecraft.world.World;
import Reika.ChromatiCraft.Base.DimensionStructureGenerator;
import Reika.ChromatiCraft.Base.StructureElement.BasicStructurePiece;
import Reika.ChromatiCraft.Block.Worldgen.BlockStructureShield.BlockType;
import Reika.ChromatiCraft.Registry.ChromaBlocks;


public class LightPanelStairSection extends BasicStructurePiece {

	public static final int HEIGHT = 16;

	LightPanelStairSection(DimensionStructureGenerator s) {
		super(s);
	}

	@Override
	public void generate(World world, int x, int y, int z) {
		Block b = ChromaBlocks.STRUCTSHIELD.getBlockInstance();
		int mc = BlockType.CLOAK.metadata;
		int ms = BlockType.STONE.metadata;
		int ml = BlockType.LIGHT.metadata;

		x -= 8;
		z -= 8;

		for (int i = 0; i <= 16; i++) {
			for (int j = 0; j <= HEIGHT; j++) {
				for (int k = 0; k <= 16; k++) {
					world.setBlock(x+i, y+j, z+k, Blocks.air);
				}
			}
		}

		world.setBlock(x + 0, y + 0, z + 0, b, ms, 3);
		world.setBlock(x + 0, y + 0, z + 1, b, ms, 3);
		world.setBlock(x + 0, y + 0, z + 2, b, ms, 3);
		world.setBlock(x + 0, y + 0, z + 3, b, ms, 3);
		world.setBlock(x + 0, y + 0, z + 4, b, ms, 3);
		world.setBlock(x + 0, y + 0, z + 5, b, ms, 3);
		world.setBlock(x + 0, y + 0, z + 6, b, ms, 3);
		world.setBlock(x + 0, y + 0, z + 7, b, ms, 3);
		world.setBlock(x + 0, y + 0, z + 8, b, ms, 3);
		world.setBlock(x + 0, y + 0, z + 9, b, ms, 3);
		world.setBlock(x + 0, y + 0, z + 10, b, ms, 3);
		world.setBlock(x + 0, y + 0, z + 11, b, ms, 3);
		world.setBlock(x + 0, y + 0, z + 12, b, ms, 3);
		world.setBlock(x + 0, y + 0, z + 13, b, ms, 3);
		world.setBlock(x + 0, y + 0, z + 14, b, ms, 3);
		world.setBlock(x + 0, y + 0, z + 15, b, ms, 3);
		world.setBlock(x + 0, y + 0, z + 16, b, ms, 3);
		world.setBlock(x + 0, y + 1, z + 0, b, ms, 3);
		world.setBlock(x + 0, y + 1, z + 1, b, ms, 3);
		world.setBlock(x + 0, y + 1, z + 2, b, ms, 3);
		world.setBlock(x + 0, y + 1, z + 3, b, ms, 3);
		world.setBlock(x + 0, y + 1, z + 4, b, ms, 3);
		world.setBlock(x + 0, y + 1, z + 5, b, ms, 3);
		world.setBlock(x + 0, y + 1, z + 6, b, ms, 3);
		world.setBlock(x + 0, y + 1, z + 7, b, ms, 3);
		world.setBlock(x + 0, y + 1, z + 8, b, ms, 3);
		world.setBlock(x + 0, y + 1, z + 9, b, ms, 3);
		world.setBlock(x + 0, y + 1, z + 10, b, ms, 3);
		world.setBlock(x + 0, y + 1, z + 11, b, ms, 3);
		world.setBlock(x + 0, y + 1, z + 12, b, ms, 3);
		world.setBlock(x + 0, y + 1, z + 13, b, ms, 3);
		world.setBlock(x + 0, y + 1, z + 14, b, ms, 3);
		world.setBlock(x + 0, y + 1, z + 15, b, ms, 3);
		world.setBlock(x + 0, y + 1, z + 16, b, ms, 3);
		world.setBlock(x + 0, y + 2, z + 0, b, ms, 3);
		world.setBlock(x + 0, y + 2, z + 1, b, ms, 3);
		world.setBlock(x + 0, y + 2, z + 2, b, ms, 3);
		world.setBlock(x + 0, y + 2, z + 3, b, ms, 3);
		world.setBlock(x + 0, y + 2, z + 4, b, ms, 3);
		world.setBlock(x + 0, y + 2, z + 5, b, ms, 3);
		world.setBlock(x + 0, y + 2, z + 6, b, ms, 3);
		world.setBlock(x + 0, y + 2, z + 7, b, ms, 3);
		world.setBlock(x + 0, y + 2, z + 8, b, ms, 3);
		world.setBlock(x + 0, y + 2, z + 9, b, ms, 3);
		world.setBlock(x + 0, y + 2, z + 10, b, ms, 3);
		world.setBlock(x + 0, y + 2, z + 11, b, ms, 3);
		world.setBlock(x + 0, y + 2, z + 12, b, ms, 3);
		world.setBlock(x + 0, y + 2, z + 13, b, ms, 3);
		world.setBlock(x + 0, y + 2, z + 14, b, ms, 3);
		world.setBlock(x + 0, y + 2, z + 15, b, ms, 3);
		world.setBlock(x + 0, y + 2, z + 16, b, ms, 3);
		world.setBlock(x + 0, y + 3, z + 0, b, ms, 3);
		world.setBlock(x + 0, y + 3, z + 1, b, ms, 3);
		world.setBlock(x + 0, y + 3, z + 2, b, ms, 3);
		world.setBlock(x + 0, y + 3, z + 3, b, ms, 3);
		world.setBlock(x + 0, y + 3, z + 4, b, ms, 3);
		world.setBlock(x + 0, y + 3, z + 5, b, ms, 3);
		world.setBlock(x + 0, y + 3, z + 6, b, ms, 3);
		world.setBlock(x + 0, y + 3, z + 7, b, ms, 3);
		world.setBlock(x + 0, y + 3, z + 8, b, ms, 3);
		world.setBlock(x + 0, y + 3, z + 9, b, ms, 3);
		world.setBlock(x + 0, y + 3, z + 10, b, ms, 3);
		world.setBlock(x + 0, y + 3, z + 11, b, ms, 3);
		world.setBlock(x + 0, y + 3, z + 12, b, ms, 3);
		world.setBlock(x + 0, y + 3, z + 13, b, ms, 3);
		world.setBlock(x + 0, y + 3, z + 14, b, ms, 3);
		world.setBlock(x + 0, y + 3, z + 15, b, ms, 3);
		world.setBlock(x + 0, y + 3, z + 16, b, ms, 3);
		world.setBlock(x + 0, y + 4, z + 0, b, ms, 3);
		world.setBlock(x + 0, y + 4, z + 1, b, ms, 3);
		world.setBlock(x + 0, y + 4, z + 2, b, ms, 3);
		world.setBlock(x + 0, y + 4, z + 3, b, ms, 3);
		world.setBlock(x + 0, y + 4, z + 4, b, ms, 3);
		world.setBlock(x + 0, y + 4, z + 5, b, ms, 3);
		world.setBlock(x + 0, y + 4, z + 6, b, ms, 3);
		world.setBlock(x + 0, y + 4, z + 7, b, ms, 3);
		world.setBlock(x + 0, y + 4, z + 8, b, ms, 3);
		world.setBlock(x + 0, y + 4, z + 9, b, ms, 3);
		world.setBlock(x + 0, y + 4, z + 10, b, ms, 3);
		world.setBlock(x + 0, y + 4, z + 11, b, ms, 3);
		world.setBlock(x + 0, y + 4, z + 12, b, ms, 3);
		world.setBlock(x + 0, y + 4, z + 13, b, ms, 3);
		world.setBlock(x + 0, y + 4, z + 14, b, ms, 3);
		world.setBlock(x + 0, y + 4, z + 15, b, ms, 3);
		world.setBlock(x + 0, y + 4, z + 16, b, ms, 3);
		world.setBlock(x + 0, y + 5, z + 0, b, ms, 3);
		world.setBlock(x + 0, y + 5, z + 1, b, ms, 3);
		world.setBlock(x + 0, y + 5, z + 2, b, ms, 3);
		world.setBlock(x + 0, y + 5, z + 3, b, ms, 3);
		world.setBlock(x + 0, y + 5, z + 4, b, ms, 3);
		world.setBlock(x + 0, y + 5, z + 5, b, ms, 3);
		world.setBlock(x + 0, y + 5, z + 6, b, ms, 3);
		world.setBlock(x + 0, y + 5, z + 7, b, ms, 3);
		world.setBlock(x + 0, y + 5, z + 8, b, ms, 3);
		world.setBlock(x + 0, y + 5, z + 9, b, ms, 3);
		world.setBlock(x + 0, y + 5, z + 10, b, ms, 3);
		world.setBlock(x + 0, y + 5, z + 11, b, ms, 3);
		world.setBlock(x + 0, y + 5, z + 12, b, ms, 3);
		world.setBlock(x + 0, y + 5, z + 13, b, ms, 3);
		world.setBlock(x + 0, y + 5, z + 14, b, ms, 3);
		world.setBlock(x + 0, y + 5, z + 15, b, ms, 3);
		world.setBlock(x + 0, y + 5, z + 16, b, ms, 3);
		world.setBlock(x + 0, y + 6, z + 0, b, ms, 3);
		world.setBlock(x + 0, y + 6, z + 1, b, ms, 3);
		world.setBlock(x + 0, y + 6, z + 2, b, ml, 3);
		world.setBlock(x + 0, y + 6, z + 3, b, ms, 3);
		world.setBlock(x + 0, y + 6, z + 4, b, ms, 3);
		world.setBlock(x + 0, y + 6, z + 5, b, ms, 3);
		world.setBlock(x + 0, y + 6, z + 6, b, ms, 3);
		world.setBlock(x + 0, y + 6, z + 7, b, ms, 3);
		world.setBlock(x + 0, y + 6, z + 8, b, ms, 3);
		world.setBlock(x + 0, y + 6, z + 9, b, ms, 3);
		world.setBlock(x + 0, y + 6, z + 10, b, ms, 3);
		world.setBlock(x + 0, y + 6, z + 11, b, ms, 3);
		world.setBlock(x + 0, y + 6, z + 12, b, ms, 3);
		world.setBlock(x + 0, y + 6, z + 13, b, ms, 3);
		world.setBlock(x + 0, y + 6, z + 14, b, ms, 3);
		world.setBlock(x + 0, y + 6, z + 15, b, ms, 3);
		world.setBlock(x + 0, y + 6, z + 16, b, ms, 3);
		world.setBlock(x + 0, y + 7, z + 0, b, ms, 3);
		world.setBlock(x + 0, y + 7, z + 1, b, ms, 3);
		world.setBlock(x + 0, y + 7, z + 2, b, ms, 3);
		world.setBlock(x + 0, y + 7, z + 3, b, ms, 3);
		world.setBlock(x + 0, y + 7, z + 4, b, ms, 3);
		world.setBlock(x + 0, y + 7, z + 5, b, ms, 3);
		world.setBlock(x + 0, y + 7, z + 6, b, ms, 3);
		world.setBlock(x + 0, y + 7, z + 7, b, ms, 3);
		world.setBlock(x + 0, y + 7, z + 8, b, ms, 3);
		world.setBlock(x + 0, y + 7, z + 9, b, ms, 3);
		world.setBlock(x + 0, y + 7, z + 10, b, ms, 3);
		world.setBlock(x + 0, y + 7, z + 11, b, ms, 3);
		world.setBlock(x + 0, y + 7, z + 12, b, ms, 3);
		world.setBlock(x + 0, y + 7, z + 13, b, ms, 3);
		world.setBlock(x + 0, y + 7, z + 14, b, ms, 3);
		world.setBlock(x + 0, y + 7, z + 15, b, ms, 3);
		world.setBlock(x + 0, y + 7, z + 16, b, ms, 3);
		world.setBlock(x + 0, y + 8, z + 0, b, ms, 3);
		world.setBlock(x + 0, y + 8, z + 1, b, ms, 3);
		world.setBlock(x + 0, y + 8, z + 2, b, ms, 3);
		world.setBlock(x + 0, y + 8, z + 3, b, ms, 3);
		world.setBlock(x + 0, y + 8, z + 4, b, ms, 3);
		world.setBlock(x + 0, y + 8, z + 5, b, ms, 3);
		world.setBlock(x + 0, y + 8, z + 6, b, ms, 3);
		world.setBlock(x + 0, y + 8, z + 7, b, ms, 3);
		world.setBlock(x + 0, y + 8, z + 8, b, ms, 3);
		world.setBlock(x + 0, y + 8, z + 9, b, ms, 3);
		world.setBlock(x + 0, y + 8, z + 10, b, ms, 3);
		world.setBlock(x + 0, y + 8, z + 11, b, ms, 3);
		world.setBlock(x + 0, y + 8, z + 12, b, ms, 3);
		world.setBlock(x + 0, y + 8, z + 13, b, ms, 3);
		world.setBlock(x + 0, y + 8, z + 14, b, ms, 3);
		world.setBlock(x + 0, y + 8, z + 15, b, ms, 3);
		world.setBlock(x + 0, y + 8, z + 16, b, ms, 3);
		world.setBlock(x + 0, y + 9, z + 0, b, ms, 3);
		world.setBlock(x + 0, y + 9, z + 1, b, ms, 3);
		world.setBlock(x + 0, y + 9, z + 2, b, ms, 3);
		world.setBlock(x + 0, y + 9, z + 3, b, ms, 3);
		world.setBlock(x + 0, y + 9, z + 4, b, ms, 3);
		world.setBlock(x + 0, y + 9, z + 5, b, ms, 3);
		world.setBlock(x + 0, y + 9, z + 6, b, ms, 3);
		world.setBlock(x + 0, y + 9, z + 7, b, ms, 3);
		world.setBlock(x + 0, y + 9, z + 8, b, ms, 3);
		world.setBlock(x + 0, y + 9, z + 9, b, ms, 3);
		world.setBlock(x + 0, y + 9, z + 10, b, ms, 3);
		world.setBlock(x + 0, y + 9, z + 11, b, ms, 3);
		world.setBlock(x + 0, y + 9, z + 12, b, ms, 3);
		world.setBlock(x + 0, y + 9, z + 13, b, ms, 3);
		world.setBlock(x + 0, y + 9, z + 14, b, ms, 3);
		world.setBlock(x + 0, y + 9, z + 15, b, ms, 3);
		world.setBlock(x + 0, y + 9, z + 16, b, ms, 3);
		world.setBlock(x + 0, y + 10, z + 0, b, ms, 3);
		world.setBlock(x + 0, y + 10, z + 1, b, ms, 3);
		world.setBlock(x + 0, y + 10, z + 2, b, ms, 3);
		world.setBlock(x + 0, y + 10, z + 3, b, ms, 3);
		world.setBlock(x + 0, y + 10, z + 4, b, ms, 3);
		world.setBlock(x + 0, y + 10, z + 5, b, ms, 3);
		world.setBlock(x + 0, y + 10, z + 6, b, ms, 3);
		world.setBlock(x + 0, y + 10, z + 7, b, ms, 3);
		world.setBlock(x + 0, y + 10, z + 8, b, ms, 3);
		world.setBlock(x + 0, y + 10, z + 9, b, ms, 3);
		world.setBlock(x + 0, y + 10, z + 10, b, ms, 3);
		world.setBlock(x + 0, y + 10, z + 11, b, ms, 3);
		world.setBlock(x + 0, y + 10, z + 12, b, ms, 3);
		world.setBlock(x + 0, y + 10, z + 13, b, ms, 3);
		world.setBlock(x + 0, y + 10, z + 14, b, ml, 3);
		world.setBlock(x + 0, y + 10, z + 15, b, ms, 3);
		world.setBlock(x + 0, y + 10, z + 16, b, ms, 3);
		world.setBlock(x + 0, y + 11, z + 0, b, ms, 3);
		world.setBlock(x + 0, y + 11, z + 1, b, ms, 3);
		world.setBlock(x + 0, y + 11, z + 2, b, ms, 3);
		world.setBlock(x + 0, y + 11, z + 3, b, ms, 3);
		world.setBlock(x + 0, y + 11, z + 4, b, ms, 3);
		world.setBlock(x + 0, y + 11, z + 5, b, ms, 3);
		world.setBlock(x + 0, y + 11, z + 6, b, ms, 3);
		world.setBlock(x + 0, y + 11, z + 7, b, ms, 3);
		world.setBlock(x + 0, y + 11, z + 8, b, ms, 3);
		world.setBlock(x + 0, y + 11, z + 9, b, ms, 3);
		world.setBlock(x + 0, y + 11, z + 10, b, ms, 3);
		world.setBlock(x + 0, y + 11, z + 11, b, ms, 3);
		world.setBlock(x + 0, y + 11, z + 12, b, ms, 3);
		world.setBlock(x + 0, y + 11, z + 13, b, ms, 3);
		world.setBlock(x + 0, y + 11, z + 14, b, ms, 3);
		world.setBlock(x + 0, y + 11, z + 15, b, ms, 3);
		world.setBlock(x + 0, y + 11, z + 16, b, ms, 3);
		world.setBlock(x + 0, y + 12, z + 0, b, ms, 3);
		world.setBlock(x + 0, y + 12, z + 1, b, ms, 3);
		world.setBlock(x + 0, y + 12, z + 2, b, ms, 3);
		world.setBlock(x + 0, y + 12, z + 3, b, ms, 3);
		world.setBlock(x + 0, y + 12, z + 4, b, ms, 3);
		world.setBlock(x + 0, y + 12, z + 5, b, ms, 3);
		world.setBlock(x + 0, y + 12, z + 6, b, ms, 3);
		world.setBlock(x + 0, y + 12, z + 7, b, ms, 3);
		world.setBlock(x + 0, y + 12, z + 8, b, ms, 3);
		world.setBlock(x + 0, y + 12, z + 9, b, ms, 3);
		world.setBlock(x + 0, y + 12, z + 10, b, ms, 3);
		world.setBlock(x + 0, y + 12, z + 11, b, ms, 3);
		world.setBlock(x + 0, y + 12, z + 12, b, ms, 3);
		world.setBlock(x + 0, y + 12, z + 13, b, ms, 3);
		world.setBlock(x + 0, y + 12, z + 14, b, ms, 3);
		world.setBlock(x + 0, y + 12, z + 15, b, ms, 3);
		world.setBlock(x + 0, y + 12, z + 16, b, ms, 3);
		world.setBlock(x + 0, y + 13, z + 0, b, ms, 3);
		world.setBlock(x + 0, y + 13, z + 1, b, ms, 3);
		world.setBlock(x + 0, y + 13, z + 2, b, ms, 3);
		world.setBlock(x + 0, y + 13, z + 3, b, ms, 3);
		world.setBlock(x + 0, y + 13, z + 4, b, ms, 3);
		world.setBlock(x + 0, y + 13, z + 5, b, ms, 3);
		world.setBlock(x + 0, y + 13, z + 6, b, ms, 3);
		world.setBlock(x + 0, y + 13, z + 7, b, ms, 3);
		world.setBlock(x + 0, y + 13, z + 8, b, ms, 3);
		world.setBlock(x + 0, y + 13, z + 9, b, ms, 3);
		world.setBlock(x + 0, y + 13, z + 10, b, ms, 3);
		world.setBlock(x + 0, y + 13, z + 11, b, ms, 3);
		world.setBlock(x + 0, y + 13, z + 12, b, ms, 3);
		world.setBlock(x + 0, y + 13, z + 13, b, ms, 3);
		world.setBlock(x + 0, y + 13, z + 14, b, ms, 3);
		world.setBlock(x + 0, y + 13, z + 15, b, ms, 3);
		world.setBlock(x + 0, y + 13, z + 16, b, ms, 3);
		world.setBlock(x + 0, y + 14, z + 0, b, ms, 3);
		world.setBlock(x + 0, y + 14, z + 1, b, ms, 3);
		world.setBlock(x + 0, y + 14, z + 2, b, ms, 3);
		world.setBlock(x + 0, y + 14, z + 3, b, ms, 3);
		world.setBlock(x + 0, y + 14, z + 4, b, ms, 3);
		world.setBlock(x + 0, y + 14, z + 5, b, ms, 3);
		world.setBlock(x + 0, y + 14, z + 6, b, ms, 3);
		world.setBlock(x + 0, y + 14, z + 7, b, ms, 3);
		world.setBlock(x + 0, y + 14, z + 8, b, ms, 3);
		world.setBlock(x + 0, y + 14, z + 9, b, ms, 3);
		world.setBlock(x + 0, y + 14, z + 10, b, ms, 3);
		world.setBlock(x + 0, y + 14, z + 11, b, ms, 3);
		world.setBlock(x + 0, y + 14, z + 12, b, ms, 3);
		world.setBlock(x + 0, y + 14, z + 13, b, ms, 3);
		world.setBlock(x + 0, y + 14, z + 14, b, ms, 3);
		world.setBlock(x + 0, y + 14, z + 15, b, ms, 3);
		world.setBlock(x + 0, y + 14, z + 16, b, ms, 3);
		world.setBlock(x + 0, y + 15, z + 0, b, ms, 3);
		world.setBlock(x + 0, y + 15, z + 1, b, ms, 3);
		world.setBlock(x + 0, y + 15, z + 2, b, ms, 3);
		world.setBlock(x + 0, y + 15, z + 3, b, ms, 3);
		world.setBlock(x + 0, y + 15, z + 4, b, ms, 3);
		world.setBlock(x + 0, y + 15, z + 5, b, ms, 3);
		world.setBlock(x + 0, y + 15, z + 6, b, ms, 3);
		world.setBlock(x + 0, y + 15, z + 7, b, ms, 3);
		world.setBlock(x + 0, y + 15, z + 8, b, ms, 3);
		world.setBlock(x + 0, y + 15, z + 9, b, ms, 3);
		world.setBlock(x + 0, y + 15, z + 10, b, ms, 3);
		world.setBlock(x + 0, y + 15, z + 11, b, ms, 3);
		world.setBlock(x + 0, y + 15, z + 12, b, ms, 3);
		world.setBlock(x + 0, y + 15, z + 13, b, ms, 3);
		world.setBlock(x + 0, y + 15, z + 14, b, ms, 3);
		world.setBlock(x + 0, y + 15, z + 15, b, ms, 3);
		world.setBlock(x + 0, y + 15, z + 16, b, ms, 3);
		world.setBlock(x + 1, y + 0, z + 0, b, ms, 3);
		world.setBlock(x + 1, y + 0, z + 1, b, ms, 3);
		world.setBlock(x + 1, y + 0, z + 2, b, ms, 3);
		world.setBlock(x + 1, y + 0, z + 3, b, ms, 3);
		world.setBlock(x + 1, y + 0, z + 4, b, ms, 3);
		world.setBlock(x + 1, y + 0, z + 5, b, ms, 3);
		world.setBlock(x + 1, y + 0, z + 6, b, ms, 3);
		world.setBlock(x + 1, y + 0, z + 7, b, ms, 3);
		world.setBlock(x + 1, y + 0, z + 8, b, ms, 3);
		world.setBlock(x + 1, y + 0, z + 9, b, ms, 3);
		world.setBlock(x + 1, y + 0, z + 10, b, ms, 3);
		world.setBlock(x + 1, y + 0, z + 11, b, ms, 3);
		world.setBlock(x + 1, y + 0, z + 12, b, ms, 3);
		world.setBlock(x + 1, y + 0, z + 13, b, ms, 3);
		world.setBlock(x + 1, y + 0, z + 14, b, ms, 3);
		world.setBlock(x + 1, y + 0, z + 15, b, ms, 3);
		world.setBlock(x + 1, y + 0, z + 16, b, ms, 3);
		world.setBlock(x + 1, y + 1, z + 0, b, ms, 3);
		world.setBlock(x + 1, y + 1, z + 1, b, ms, 3);
		world.setBlock(x + 1, y + 1, z + 2, b, ms, 3);
		world.setBlock(x + 1, y + 1, z + 3, b, ms, 3);
		world.setBlock(x + 1, y + 1, z + 4, b, ms, 3);
		world.setBlock(x + 1, y + 1, z + 5, b, ms, 3);
		world.setBlock(x + 1, y + 1, z + 6, b, ms, 3);
		world.setBlock(x + 1, y + 1, z + 7, b, ms, 3);
		world.setBlock(x + 1, y + 1, z + 8, b, ms, 3);
		world.setBlock(x + 1, y + 1, z + 9, b, ms, 3);
		world.setBlock(x + 1, y + 1, z + 10, b, ms, 3);
		world.setBlock(x + 1, y + 1, z + 11, b, ms, 3);
		world.setBlock(x + 1, y + 1, z + 12, b, ms, 3);
		world.setBlock(x + 1, y + 1, z + 13, b, ms, 3);
		world.setBlock(x + 1, y + 1, z + 14, b, ms, 3);
		world.setBlock(x + 1, y + 1, z + 15, b, ms, 3);
		world.setBlock(x + 1, y + 1, z + 16, b, ms, 3);
		world.setBlock(x + 1, y + 2, z + 0, b, ms, 3);
		world.setBlock(x + 1, y + 2, z + 1, b, ms, 3);
		world.setBlock(x + 1, y + 2, z + 2, b, ms, 3);
		world.setBlock(x + 1, y + 2, z + 3, b, ms, 3);
		world.setBlock(x + 1, y + 2, z + 4, b, ms, 3);
		world.setBlock(x + 1, y + 2, z + 5, b, ms, 3);
		world.setBlock(x + 1, y + 2, z + 6, b, ms, 3);
		world.setBlock(x + 1, y + 2, z + 7, b, ms, 3);
		world.setBlock(x + 1, y + 2, z + 8, b, ms, 3);
		world.setBlock(x + 1, y + 2, z + 9, b, ms, 3);
		world.setBlock(x + 1, y + 2, z + 10, b, ms, 3);
		world.setBlock(x + 1, y + 2, z + 11, b, ms, 3);
		world.setBlock(x + 1, y + 2, z + 12, b, ms, 3);
		world.setBlock(x + 1, y + 2, z + 13, b, ms, 3);
		world.setBlock(x + 1, y + 2, z + 14, b, ms, 3);
		world.setBlock(x + 1, y + 2, z + 15, b, ms, 3);
		world.setBlock(x + 1, y + 2, z + 16, b, ms, 3);
		world.setBlock(x + 1, y + 3, z + 0, b, ms, 3);
		world.setBlock(x + 1, y + 3, z + 1, b, ms, 3);
		world.setBlock(x + 1, y + 3, z + 2, b, ms, 3);
		world.setBlock(x + 1, y + 3, z + 3, b, ms, 3);
		world.setBlock(x + 1, y + 3, z + 4, b, ms, 3);
		world.setBlock(x + 1, y + 3, z + 5, b, ms, 3);
		world.setBlock(x + 1, y + 3, z + 6, b, ms, 3);
		world.setBlock(x + 1, y + 3, z + 7, b, ms, 3);
		world.setBlock(x + 1, y + 3, z + 8, b, ms, 3);
		world.setBlock(x + 1, y + 3, z + 9, b, ms, 3);
		world.setBlock(x + 1, y + 3, z + 10, b, ms, 3);
		world.setBlock(x + 1, y + 3, z + 11, b, ms, 3);
		world.setBlock(x + 1, y + 3, z + 12, b, ms, 3);
		world.setBlock(x + 1, y + 3, z + 13, b, ms, 3);
		world.setBlock(x + 1, y + 3, z + 14, b, ms, 3);
		world.setBlock(x + 1, y + 3, z + 15, b, ms, 3);
		world.setBlock(x + 1, y + 3, z + 16, b, ms, 3);
		world.setBlock(x + 1, y + 4, z + 0, b, ms, 3);
		world.setBlock(x + 1, y + 4, z + 1, b, ms, 3);
		world.setBlock(x + 1, y + 4, z + 2, b, ms, 3);
		world.setBlock(x + 1, y + 4, z + 3, b, ms, 3);
		world.setBlock(x + 1, y + 4, z + 4, b, ms, 3);
		world.setBlock(x + 1, y + 4, z + 5, b, ms, 3);
		world.setBlock(x + 1, y + 4, z + 6, b, ms, 3);
		world.setBlock(x + 1, y + 4, z + 7, b, ms, 3);
		world.setBlock(x + 1, y + 4, z + 8, b, ms, 3);
		world.setBlock(x + 1, y + 4, z + 9, b, ms, 3);
		world.setBlock(x + 1, y + 4, z + 10, b, ms, 3);
		world.setBlock(x + 1, y + 4, z + 11, b, ms, 3);
		world.setBlock(x + 1, y + 4, z + 12, b, ms, 3);
		world.setBlock(x + 1, y + 4, z + 13, b, ms, 3);
		world.setBlock(x + 1, y + 4, z + 14, b, ms, 3);
		world.setBlock(x + 1, y + 4, z + 15, b, ms, 3);
		world.setBlock(x + 1, y + 4, z + 16, b, ms, 3);
		world.setBlock(x + 1, y + 5, z + 0, b, ms, 3);
		world.setBlock(x + 1, y + 5, z + 4, b, ms, 3);
		world.setBlock(x + 1, y + 5, z + 5, b, ms, 3);
		world.setBlock(x + 1, y + 5, z + 6, b, ms, 3);
		world.setBlock(x + 1, y + 5, z + 7, b, ms, 3);
		world.setBlock(x + 1, y + 5, z + 8, b, ms, 3);
		world.setBlock(x + 1, y + 5, z + 9, b, ms, 3);
		world.setBlock(x + 1, y + 5, z + 10, b, ms, 3);
		world.setBlock(x + 1, y + 5, z + 11, b, ms, 3);
		world.setBlock(x + 1, y + 5, z + 12, b, ms, 3);
		world.setBlock(x + 1, y + 5, z + 13, b, ms, 3);
		world.setBlock(x + 1, y + 5, z + 14, b, ms, 3);
		world.setBlock(x + 1, y + 5, z + 15, b, ms, 3);
		world.setBlock(x + 1, y + 5, z + 16, b, ms, 3);
		world.setBlock(x + 1, y + 6, z + 0, b, ms, 3);
		world.setBlock(x + 1, y + 6, z + 7, b, ms, 3);
		world.setBlock(x + 1, y + 6, z + 8, b, ms, 3);
		world.setBlock(x + 1, y + 6, z + 9, b, ms, 3);
		world.setBlock(x + 1, y + 6, z + 10, b, ms, 3);
		world.setBlock(x + 1, y + 6, z + 11, b, ms, 3);
		world.setBlock(x + 1, y + 6, z + 12, b, ms, 3);
		world.setBlock(x + 1, y + 6, z + 13, b, ms, 3);
		world.setBlock(x + 1, y + 6, z + 14, b, ms, 3);
		world.setBlock(x + 1, y + 6, z + 15, b, ms, 3);
		world.setBlock(x + 1, y + 6, z + 16, b, ms, 3);
		world.setBlock(x + 1, y + 7, z + 0, b, ms, 3);
		world.setBlock(x + 1, y + 7, z + 10, b, ms, 3);
		world.setBlock(x + 1, y + 7, z + 11, b, ms, 3);
		world.setBlock(x + 1, y + 7, z + 12, b, ms, 3);
		world.setBlock(x + 1, y + 7, z + 13, b, ms, 3);
		world.setBlock(x + 1, y + 7, z + 14, b, ms, 3);
		world.setBlock(x + 1, y + 7, z + 15, b, ms, 3);
		world.setBlock(x + 1, y + 7, z + 16, b, ms, 3);
		world.setBlock(x + 1, y + 8, z + 0, b, ms, 3);
		world.setBlock(x + 1, y + 8, z + 13, b, ms, 3);
		world.setBlock(x + 1, y + 8, z + 14, b, ms, 3);
		world.setBlock(x + 1, y + 8, z + 15, b, ms, 3);
		world.setBlock(x + 1, y + 8, z + 16, b, ms, 3);
		world.setBlock(x + 1, y + 9, z + 0, b, ms, 3);
		world.setBlock(x + 1, y + 9, z + 16, b, ms, 3);
		world.setBlock(x + 1, y + 10, z + 0, b, ms, 3);
		world.setBlock(x + 1, y + 10, z + 1, b, ms, 3);
		world.setBlock(x + 1, y + 10, z + 2, b, ms, 3);
		world.setBlock(x + 1, y + 10, z + 3, b, ms, 3);
		world.setBlock(x + 1, y + 10, z + 16, b, ms, 3);
		world.setBlock(x + 1, y + 11, z + 0, b, ms, 3);
		world.setBlock(x + 1, y + 11, z + 1, b, ms, 3);
		world.setBlock(x + 1, y + 11, z + 2, b, ms, 3);
		world.setBlock(x + 1, y + 11, z + 3, b, ms, 3);
		world.setBlock(x + 1, y + 11, z + 4, b, ms, 3);
		world.setBlock(x + 1, y + 11, z + 5, b, ms, 3);
		world.setBlock(x + 1, y + 11, z + 6, b, ms, 3);
		world.setBlock(x + 1, y + 11, z + 16, b, ms, 3);
		world.setBlock(x + 1, y + 12, z + 0, b, ms, 3);
		world.setBlock(x + 1, y + 12, z + 1, b, ms, 3);
		world.setBlock(x + 1, y + 12, z + 2, b, ms, 3);
		world.setBlock(x + 1, y + 12, z + 3, b, ms, 3);
		world.setBlock(x + 1, y + 12, z + 4, b, ms, 3);
		world.setBlock(x + 1, y + 12, z + 5, b, ms, 3);
		world.setBlock(x + 1, y + 12, z + 6, b, ms, 3);
		world.setBlock(x + 1, y + 12, z + 7, b, ms, 3);
		world.setBlock(x + 1, y + 12, z + 8, b, ms, 3);
		world.setBlock(x + 1, y + 12, z + 9, b, ms, 3);
		world.setBlock(x + 1, y + 12, z + 16, b, ms, 3);
		world.setBlock(x + 1, y + 13, z + 0, b, ms, 3);
		world.setBlock(x + 1, y + 13, z + 1, b, ms, 3);
		world.setBlock(x + 1, y + 13, z + 2, b, ms, 3);
		world.setBlock(x + 1, y + 13, z + 3, b, ms, 3);
		world.setBlock(x + 1, y + 13, z + 4, b, ms, 3);
		world.setBlock(x + 1, y + 13, z + 5, b, ms, 3);
		world.setBlock(x + 1, y + 13, z + 6, b, ms, 3);
		world.setBlock(x + 1, y + 13, z + 7, b, ms, 3);
		world.setBlock(x + 1, y + 13, z + 8, b, ms, 3);
		world.setBlock(x + 1, y + 13, z + 9, b, ms, 3);
		world.setBlock(x + 1, y + 13, z + 10, b, ms, 3);
		world.setBlock(x + 1, y + 13, z + 11, b, ms, 3);
		world.setBlock(x + 1, y + 13, z + 12, b, ms, 3);
		world.setBlock(x + 1, y + 13, z + 16, b, ms, 3);
		world.setBlock(x + 1, y + 14, z + 0, b, ms, 3);
		world.setBlock(x + 1, y + 14, z + 1, b, ms, 3);
		world.setBlock(x + 1, y + 14, z + 2, b, ms, 3);
		world.setBlock(x + 1, y + 14, z + 3, b, ms, 3);
		world.setBlock(x + 1, y + 14, z + 4, b, ms, 3);
		world.setBlock(x + 1, y + 14, z + 5, b, ms, 3);
		world.setBlock(x + 1, y + 14, z + 6, b, ms, 3);
		world.setBlock(x + 1, y + 14, z + 7, b, ms, 3);
		world.setBlock(x + 1, y + 14, z + 8, b, ms, 3);
		world.setBlock(x + 1, y + 14, z + 9, b, ms, 3);
		world.setBlock(x + 1, y + 14, z + 10, b, ms, 3);
		world.setBlock(x + 1, y + 14, z + 11, b, ms, 3);
		world.setBlock(x + 1, y + 14, z + 12, b, ms, 3);
		world.setBlock(x + 1, y + 14, z + 13, b, ms, 3);
		world.setBlock(x + 1, y + 14, z + 14, b, ms, 3);
		world.setBlock(x + 1, y + 14, z + 15, b, ms, 3);
		world.setBlock(x + 1, y + 14, z + 16, b, ms, 3);
		world.setBlock(x + 1, y + 15, z + 0, b, ms, 3);
		world.setBlock(x + 1, y + 15, z + 1, b, ms, 3);
		world.setBlock(x + 1, y + 15, z + 2, b, ms, 3);
		world.setBlock(x + 1, y + 15, z + 3, b, ms, 3);
		world.setBlock(x + 1, y + 15, z + 4, b, ms, 3);
		world.setBlock(x + 1, y + 15, z + 5, b, ms, 3);
		world.setBlock(x + 1, y + 15, z + 6, b, ms, 3);
		world.setBlock(x + 1, y + 15, z + 7, b, ms, 3);
		world.setBlock(x + 1, y + 15, z + 8, b, ms, 3);
		world.setBlock(x + 1, y + 15, z + 9, b, ms, 3);
		world.setBlock(x + 1, y + 15, z + 10, b, ms, 3);
		world.setBlock(x + 1, y + 15, z + 11, b, ms, 3);
		world.setBlock(x + 1, y + 15, z + 12, b, ms, 3);
		world.setBlock(x + 1, y + 15, z + 13, b, ms, 3);
		world.setBlock(x + 1, y + 15, z + 14, b, ms, 3);
		world.setBlock(x + 1, y + 15, z + 15, b, ms, 3);
		world.setBlock(x + 1, y + 15, z + 16, b, ms, 3);
		world.setBlock(x + 2, y + 0, z + 0, b, ms, 3);
		world.setBlock(x + 2, y + 0, z + 1, b, ms, 3);
		world.setBlock(x + 2, y + 0, z + 2, b, ms, 3);
		world.setBlock(x + 2, y + 0, z + 3, b, ms, 3);
		world.setBlock(x + 2, y + 0, z + 4, b, ms, 3);
		world.setBlock(x + 2, y + 0, z + 5, b, ms, 3);
		world.setBlock(x + 2, y + 0, z + 6, b, ms, 3);
		world.setBlock(x + 2, y + 0, z + 7, b, ms, 3);
		world.setBlock(x + 2, y + 0, z + 8, b, ms, 3);
		world.setBlock(x + 2, y + 0, z + 9, b, ms, 3);
		world.setBlock(x + 2, y + 0, z + 10, b, ms, 3);
		world.setBlock(x + 2, y + 0, z + 11, b, ms, 3);
		world.setBlock(x + 2, y + 0, z + 12, b, ms, 3);
		world.setBlock(x + 2, y + 0, z + 13, b, ms, 3);
		world.setBlock(x + 2, y + 0, z + 14, b, ms, 3);
		world.setBlock(x + 2, y + 0, z + 15, b, ms, 3);
		world.setBlock(x + 2, y + 0, z + 16, b, ms, 3);
		world.setBlock(x + 2, y + 1, z + 0, b, ms, 3);
		world.setBlock(x + 2, y + 1, z + 1, b, ms, 3);
		world.setBlock(x + 2, y + 1, z + 2, b, ms, 3);
		world.setBlock(x + 2, y + 1, z + 3, b, ms, 3);
		world.setBlock(x + 2, y + 1, z + 4, b, ms, 3);
		world.setBlock(x + 2, y + 1, z + 5, b, ms, 3);
		world.setBlock(x + 2, y + 1, z + 6, b, ms, 3);
		world.setBlock(x + 2, y + 1, z + 7, b, ms, 3);
		world.setBlock(x + 2, y + 1, z + 8, b, ms, 3);
		world.setBlock(x + 2, y + 1, z + 9, b, ms, 3);
		world.setBlock(x + 2, y + 1, z + 10, b, ms, 3);
		world.setBlock(x + 2, y + 1, z + 11, b, ms, 3);
		world.setBlock(x + 2, y + 1, z + 12, b, ms, 3);
		world.setBlock(x + 2, y + 1, z + 13, b, ms, 3);
		world.setBlock(x + 2, y + 1, z + 14, b, ms, 3);
		world.setBlock(x + 2, y + 1, z + 15, b, ms, 3);
		world.setBlock(x + 2, y + 1, z + 16, b, ms, 3);
		world.setBlock(x + 2, y + 2, z + 0, b, ms, 3);
		world.setBlock(x + 2, y + 2, z + 1, b, ms, 3);
		world.setBlock(x + 2, y + 2, z + 2, b, ms, 3);
		world.setBlock(x + 2, y + 2, z + 3, b, ms, 3);
		world.setBlock(x + 2, y + 2, z + 4, b, ms, 3);
		world.setBlock(x + 2, y + 2, z + 5, b, ms, 3);
		world.setBlock(x + 2, y + 2, z + 6, b, ms, 3);
		world.setBlock(x + 2, y + 2, z + 7, b, ms, 3);
		world.setBlock(x + 2, y + 2, z + 8, b, ms, 3);
		world.setBlock(x + 2, y + 2, z + 9, b, ms, 3);
		world.setBlock(x + 2, y + 2, z + 10, b, ms, 3);
		world.setBlock(x + 2, y + 2, z + 11, b, ms, 3);
		world.setBlock(x + 2, y + 2, z + 12, b, ms, 3);
		world.setBlock(x + 2, y + 2, z + 13, b, ms, 3);
		world.setBlock(x + 2, y + 2, z + 14, b, ms, 3);
		world.setBlock(x + 2, y + 2, z + 15, b, ms, 3);
		world.setBlock(x + 2, y + 2, z + 16, b, ms, 3);
		world.setBlock(x + 2, y + 3, z + 0, b, ms, 3);
		world.setBlock(x + 2, y + 3, z + 1, b, ms, 3);
		world.setBlock(x + 2, y + 3, z + 2, b, ms, 3);
		world.setBlock(x + 2, y + 3, z + 3, b, ms, 3);
		world.setBlock(x + 2, y + 3, z + 4, b, ms, 3);
		world.setBlock(x + 2, y + 3, z + 5, b, ms, 3);
		world.setBlock(x + 2, y + 3, z + 6, b, ms, 3);
		world.setBlock(x + 2, y + 3, z + 7, b, ms, 3);
		world.setBlock(x + 2, y + 3, z + 8, b, ms, 3);
		world.setBlock(x + 2, y + 3, z + 9, b, ms, 3);
		world.setBlock(x + 2, y + 3, z + 10, b, ms, 3);
		world.setBlock(x + 2, y + 3, z + 11, b, ms, 3);
		world.setBlock(x + 2, y + 3, z + 12, b, ms, 3);
		world.setBlock(x + 2, y + 3, z + 13, b, ms, 3);
		world.setBlock(x + 2, y + 3, z + 14, b, ms, 3);
		world.setBlock(x + 2, y + 3, z + 15, b, ms, 3);
		world.setBlock(x + 2, y + 3, z + 16, b, ms, 3);
		world.setBlock(x + 2, y + 4, z + 0, b, ms, 3);
		world.setBlock(x + 2, y + 4, z + 1, b, ms, 3);
		world.setBlock(x + 2, y + 4, z + 2, b, ms, 3);
		world.setBlock(x + 2, y + 4, z + 3, b, ms, 3);
		world.setBlock(x + 2, y + 4, z + 4, b, ms, 3);
		world.setBlock(x + 2, y + 4, z + 5, b, ms, 3);
		world.setBlock(x + 2, y + 4, z + 6, b, ms, 3);
		world.setBlock(x + 2, y + 4, z + 7, b, ms, 3);
		world.setBlock(x + 2, y + 4, z + 8, b, ms, 3);
		world.setBlock(x + 2, y + 4, z + 9, b, ms, 3);
		world.setBlock(x + 2, y + 4, z + 10, b, ms, 3);
		world.setBlock(x + 2, y + 4, z + 11, b, ms, 3);
		world.setBlock(x + 2, y + 4, z + 12, b, ms, 3);
		world.setBlock(x + 2, y + 4, z + 13, b, ms, 3);
		world.setBlock(x + 2, y + 4, z + 14, b, ms, 3);
		world.setBlock(x + 2, y + 4, z + 15, b, ms, 3);
		world.setBlock(x + 2, y + 4, z + 16, b, ms, 3);
		world.setBlock(x + 2, y + 5, z + 0, b, ms, 3);
		world.setBlock(x + 2, y + 5, z + 4, b, ms, 3);
		world.setBlock(x + 2, y + 5, z + 5, b, ms, 3);
		world.setBlock(x + 2, y + 5, z + 6, b, ms, 3);
		world.setBlock(x + 2, y + 5, z + 7, b, ms, 3);
		world.setBlock(x + 2, y + 5, z + 8, b, ms, 3);
		world.setBlock(x + 2, y + 5, z + 9, b, ms, 3);
		world.setBlock(x + 2, y + 5, z + 10, b, ms, 3);
		world.setBlock(x + 2, y + 5, z + 11, b, ms, 3);
		world.setBlock(x + 2, y + 5, z + 12, b, ms, 3);
		world.setBlock(x + 2, y + 5, z + 13, b, ms, 3);
		world.setBlock(x + 2, y + 5, z + 14, b, ms, 3);
		world.setBlock(x + 2, y + 5, z + 15, b, ms, 3);
		world.setBlock(x + 2, y + 5, z + 16, b, ms, 3);
		world.setBlock(x + 2, y + 6, z + 0, b, ml, 3);
		world.setBlock(x + 2, y + 6, z + 7, b, ms, 3);
		world.setBlock(x + 2, y + 6, z + 8, b, ms, 3);
		world.setBlock(x + 2, y + 6, z + 9, b, ms, 3);
		world.setBlock(x + 2, y + 6, z + 10, b, ms, 3);
		world.setBlock(x + 2, y + 6, z + 11, b, ms, 3);
		world.setBlock(x + 2, y + 6, z + 12, b, ms, 3);
		world.setBlock(x + 2, y + 6, z + 13, b, ms, 3);
		world.setBlock(x + 2, y + 6, z + 14, b, ms, 3);
		world.setBlock(x + 2, y + 6, z + 15, b, ms, 3);
		world.setBlock(x + 2, y + 6, z + 16, b, ms, 3);
		world.setBlock(x + 2, y + 7, z + 0, b, ms, 3);
		world.setBlock(x + 2, y + 7, z + 10, b, ms, 3);
		world.setBlock(x + 2, y + 7, z + 11, b, ms, 3);
		world.setBlock(x + 2, y + 7, z + 12, b, ms, 3);
		world.setBlock(x + 2, y + 7, z + 13, b, ms, 3);
		world.setBlock(x + 2, y + 7, z + 14, b, ms, 3);
		world.setBlock(x + 2, y + 7, z + 15, b, ms, 3);
		world.setBlock(x + 2, y + 7, z + 16, b, ms, 3);
		world.setBlock(x + 2, y + 8, z + 0, b, ms, 3);
		world.setBlock(x + 2, y + 8, z + 13, b, ms, 3);
		world.setBlock(x + 2, y + 8, z + 14, b, ms, 3);
		world.setBlock(x + 2, y + 8, z + 15, b, ms, 3);
		world.setBlock(x + 2, y + 8, z + 16, b, ms, 3);
		world.setBlock(x + 2, y + 9, z + 0, b, ms, 3);
		world.setBlock(x + 2, y + 9, z + 16, b, ms, 3);
		world.setBlock(x + 2, y + 10, z + 0, b, ms, 3);
		world.setBlock(x + 2, y + 10, z + 1, b, ms, 3);
		world.setBlock(x + 2, y + 10, z + 2, b, ms, 3);
		world.setBlock(x + 2, y + 10, z + 3, b, ms, 3);
		world.setBlock(x + 2, y + 10, z + 16, b, ml, 3);
		world.setBlock(x + 2, y + 11, z + 0, b, ms, 3);
		world.setBlock(x + 2, y + 11, z + 1, b, ms, 3);
		world.setBlock(x + 2, y + 11, z + 2, b, ms, 3);
		world.setBlock(x + 2, y + 11, z + 3, b, ms, 3);
		world.setBlock(x + 2, y + 11, z + 4, b, ms, 3);
		world.setBlock(x + 2, y + 11, z + 5, b, ms, 3);
		world.setBlock(x + 2, y + 11, z + 6, b, ms, 3);
		world.setBlock(x + 2, y + 11, z + 16, b, ms, 3);
		world.setBlock(x + 2, y + 12, z + 0, b, ms, 3);
		world.setBlock(x + 2, y + 12, z + 1, b, ms, 3);
		world.setBlock(x + 2, y + 12, z + 2, b, ms, 3);
		world.setBlock(x + 2, y + 12, z + 3, b, ms, 3);
		world.setBlock(x + 2, y + 12, z + 4, b, ms, 3);
		world.setBlock(x + 2, y + 12, z + 5, b, ms, 3);
		world.setBlock(x + 2, y + 12, z + 6, b, ms, 3);
		world.setBlock(x + 2, y + 12, z + 7, b, ms, 3);
		world.setBlock(x + 2, y + 12, z + 8, b, ms, 3);
		world.setBlock(x + 2, y + 12, z + 9, b, ms, 3);
		world.setBlock(x + 2, y + 12, z + 16, b, ms, 3);
		world.setBlock(x + 2, y + 13, z + 0, b, ms, 3);
		world.setBlock(x + 2, y + 13, z + 1, b, ms, 3);
		world.setBlock(x + 2, y + 13, z + 2, b, ms, 3);
		world.setBlock(x + 2, y + 13, z + 3, b, ms, 3);
		world.setBlock(x + 2, y + 13, z + 4, b, ms, 3);
		world.setBlock(x + 2, y + 13, z + 5, b, ms, 3);
		world.setBlock(x + 2, y + 13, z + 6, b, ms, 3);
		world.setBlock(x + 2, y + 13, z + 7, b, ms, 3);
		world.setBlock(x + 2, y + 13, z + 8, b, ms, 3);
		world.setBlock(x + 2, y + 13, z + 9, b, ms, 3);
		world.setBlock(x + 2, y + 13, z + 10, b, ms, 3);
		world.setBlock(x + 2, y + 13, z + 11, b, ms, 3);
		world.setBlock(x + 2, y + 13, z + 12, b, ms, 3);
		world.setBlock(x + 2, y + 13, z + 16, b, ms, 3);
		world.setBlock(x + 2, y + 14, z + 0, b, ms, 3);
		world.setBlock(x + 2, y + 14, z + 1, b, ms, 3);
		world.setBlock(x + 2, y + 14, z + 2, b, ms, 3);
		world.setBlock(x + 2, y + 14, z + 3, b, ms, 3);
		world.setBlock(x + 2, y + 14, z + 4, b, ms, 3);
		world.setBlock(x + 2, y + 14, z + 5, b, ms, 3);
		world.setBlock(x + 2, y + 14, z + 6, b, ms, 3);
		world.setBlock(x + 2, y + 14, z + 7, b, ms, 3);
		world.setBlock(x + 2, y + 14, z + 8, b, ms, 3);
		world.setBlock(x + 2, y + 14, z + 9, b, ms, 3);
		world.setBlock(x + 2, y + 14, z + 10, b, ms, 3);
		world.setBlock(x + 2, y + 14, z + 11, b, ms, 3);
		world.setBlock(x + 2, y + 14, z + 12, b, ms, 3);
		world.setBlock(x + 2, y + 14, z + 13, b, ms, 3);
		world.setBlock(x + 2, y + 14, z + 14, b, ms, 3);
		world.setBlock(x + 2, y + 14, z + 15, b, ms, 3);
		world.setBlock(x + 2, y + 14, z + 16, b, ms, 3);
		world.setBlock(x + 2, y + 15, z + 0, b, ms, 3);
		world.setBlock(x + 2, y + 15, z + 1, b, ms, 3);
		world.setBlock(x + 2, y + 15, z + 2, b, ms, 3);
		world.setBlock(x + 2, y + 15, z + 3, b, ms, 3);
		world.setBlock(x + 2, y + 15, z + 4, b, ms, 3);
		world.setBlock(x + 2, y + 15, z + 5, b, ms, 3);
		world.setBlock(x + 2, y + 15, z + 6, b, ms, 3);
		world.setBlock(x + 2, y + 15, z + 7, b, ms, 3);
		world.setBlock(x + 2, y + 15, z + 8, b, ms, 3);
		world.setBlock(x + 2, y + 15, z + 9, b, ms, 3);
		world.setBlock(x + 2, y + 15, z + 10, b, ms, 3);
		world.setBlock(x + 2, y + 15, z + 11, b, ms, 3);
		world.setBlock(x + 2, y + 15, z + 12, b, ms, 3);
		world.setBlock(x + 2, y + 15, z + 13, b, ms, 3);
		world.setBlock(x + 2, y + 15, z + 14, b, ms, 3);
		world.setBlock(x + 2, y + 15, z + 15, b, ms, 3);
		world.setBlock(x + 2, y + 15, z + 16, b, ms, 3);
		world.setBlock(x + 3, y + 0, z + 0, b, ms, 3);
		world.setBlock(x + 3, y + 0, z + 1, b, ms, 3);
		world.setBlock(x + 3, y + 0, z + 2, b, ms, 3);
		world.setBlock(x + 3, y + 0, z + 3, b, ms, 3);
		world.setBlock(x + 3, y + 0, z + 4, b, ms, 3);
		world.setBlock(x + 3, y + 0, z + 5, b, ms, 3);
		world.setBlock(x + 3, y + 0, z + 6, b, ms, 3);
		world.setBlock(x + 3, y + 0, z + 7, b, ms, 3);
		world.setBlock(x + 3, y + 0, z + 8, b, ms, 3);
		world.setBlock(x + 3, y + 0, z + 9, b, ms, 3);
		world.setBlock(x + 3, y + 0, z + 10, b, ms, 3);
		world.setBlock(x + 3, y + 0, z + 11, b, ms, 3);
		world.setBlock(x + 3, y + 0, z + 12, b, ms, 3);
		world.setBlock(x + 3, y + 0, z + 13, b, ms, 3);
		world.setBlock(x + 3, y + 0, z + 14, b, ms, 3);
		world.setBlock(x + 3, y + 0, z + 15, b, ms, 3);
		world.setBlock(x + 3, y + 0, z + 16, b, ms, 3);
		world.setBlock(x + 3, y + 1, z + 0, b, ms, 3);
		world.setBlock(x + 3, y + 1, z + 1, b, ms, 3);
		world.setBlock(x + 3, y + 1, z + 2, b, ms, 3);
		world.setBlock(x + 3, y + 1, z + 3, b, ms, 3);
		world.setBlock(x + 3, y + 1, z + 4, b, ms, 3);
		world.setBlock(x + 3, y + 1, z + 5, b, ms, 3);
		world.setBlock(x + 3, y + 1, z + 6, b, ms, 3);
		world.setBlock(x + 3, y + 1, z + 7, b, ms, 3);
		world.setBlock(x + 3, y + 1, z + 8, b, ms, 3);
		world.setBlock(x + 3, y + 1, z + 9, b, ms, 3);
		world.setBlock(x + 3, y + 1, z + 10, b, ms, 3);
		world.setBlock(x + 3, y + 1, z + 11, b, ms, 3);
		world.setBlock(x + 3, y + 1, z + 12, b, ms, 3);
		world.setBlock(x + 3, y + 1, z + 13, b, ms, 3);
		world.setBlock(x + 3, y + 1, z + 14, b, ms, 3);
		world.setBlock(x + 3, y + 1, z + 15, b, ms, 3);
		world.setBlock(x + 3, y + 1, z + 16, b, ms, 3);
		world.setBlock(x + 3, y + 2, z + 0, b, ms, 3);
		world.setBlock(x + 3, y + 2, z + 1, b, ms, 3);
		world.setBlock(x + 3, y + 2, z + 2, b, ms, 3);
		world.setBlock(x + 3, y + 2, z + 3, b, ms, 3);
		world.setBlock(x + 3, y + 2, z + 4, b, ms, 3);
		world.setBlock(x + 3, y + 2, z + 5, b, ms, 3);
		world.setBlock(x + 3, y + 2, z + 6, b, ms, 3);
		world.setBlock(x + 3, y + 2, z + 7, b, ms, 3);
		world.setBlock(x + 3, y + 2, z + 8, b, ms, 3);
		world.setBlock(x + 3, y + 2, z + 9, b, ms, 3);
		world.setBlock(x + 3, y + 2, z + 10, b, ms, 3);
		world.setBlock(x + 3, y + 2, z + 11, b, ms, 3);
		world.setBlock(x + 3, y + 2, z + 12, b, ms, 3);
		world.setBlock(x + 3, y + 2, z + 13, b, ms, 3);
		world.setBlock(x + 3, y + 2, z + 14, b, ms, 3);
		world.setBlock(x + 3, y + 2, z + 15, b, ms, 3);
		world.setBlock(x + 3, y + 2, z + 16, b, ms, 3);
		world.setBlock(x + 3, y + 3, z + 0, b, ms, 3);
		world.setBlock(x + 3, y + 3, z + 1, b, ms, 3);
		world.setBlock(x + 3, y + 3, z + 2, b, ms, 3);
		world.setBlock(x + 3, y + 3, z + 3, b, ms, 3);
		world.setBlock(x + 3, y + 3, z + 4, b, ms, 3);
		world.setBlock(x + 3, y + 3, z + 5, b, ms, 3);
		world.setBlock(x + 3, y + 3, z + 6, b, ms, 3);
		world.setBlock(x + 3, y + 3, z + 7, b, ms, 3);
		world.setBlock(x + 3, y + 3, z + 8, b, ms, 3);
		world.setBlock(x + 3, y + 3, z + 9, b, ms, 3);
		world.setBlock(x + 3, y + 3, z + 10, b, ms, 3);
		world.setBlock(x + 3, y + 3, z + 11, b, ms, 3);
		world.setBlock(x + 3, y + 3, z + 12, b, ms, 3);
		world.setBlock(x + 3, y + 3, z + 13, b, ms, 3);
		world.setBlock(x + 3, y + 3, z + 14, b, ms, 3);
		world.setBlock(x + 3, y + 3, z + 15, b, ms, 3);
		world.setBlock(x + 3, y + 3, z + 16, b, ms, 3);
		world.setBlock(x + 3, y + 4, z + 0, b, ms, 3);
		world.setBlock(x + 3, y + 4, z + 1, b, ms, 3);
		world.setBlock(x + 3, y + 4, z + 2, b, ms, 3);
		world.setBlock(x + 3, y + 4, z + 3, b, ms, 3);
		world.setBlock(x + 3, y + 4, z + 4, b, ms, 3);
		world.setBlock(x + 3, y + 4, z + 5, b, ms, 3);
		world.setBlock(x + 3, y + 4, z + 6, b, ms, 3);
		world.setBlock(x + 3, y + 4, z + 7, b, ms, 3);
		world.setBlock(x + 3, y + 4, z + 8, b, ms, 3);
		world.setBlock(x + 3, y + 4, z + 9, b, ms, 3);
		world.setBlock(x + 3, y + 4, z + 10, b, ms, 3);
		world.setBlock(x + 3, y + 4, z + 11, b, ms, 3);
		world.setBlock(x + 3, y + 4, z + 12, b, ms, 3);
		world.setBlock(x + 3, y + 4, z + 13, b, ms, 3);
		world.setBlock(x + 3, y + 4, z + 14, b, ms, 3);
		world.setBlock(x + 3, y + 4, z + 15, b, ms, 3);
		world.setBlock(x + 3, y + 4, z + 16, b, ms, 3);
		world.setBlock(x + 3, y + 5, z + 0, b, ms, 3);
		world.setBlock(x + 3, y + 5, z + 4, b, ms, 3);
		world.setBlock(x + 3, y + 5, z + 5, b, ms, 3);
		world.setBlock(x + 3, y + 5, z + 6, b, ms, 3);
		world.setBlock(x + 3, y + 5, z + 7, b, ms, 3);
		world.setBlock(x + 3, y + 5, z + 8, b, ms, 3);
		world.setBlock(x + 3, y + 5, z + 9, b, ms, 3);
		world.setBlock(x + 3, y + 5, z + 10, b, ms, 3);
		world.setBlock(x + 3, y + 5, z + 11, b, ms, 3);
		world.setBlock(x + 3, y + 5, z + 12, b, ms, 3);
		world.setBlock(x + 3, y + 5, z + 13, b, ms, 3);
		world.setBlock(x + 3, y + 5, z + 14, b, ms, 3);
		world.setBlock(x + 3, y + 5, z + 15, b, ms, 3);
		world.setBlock(x + 3, y + 5, z + 16, b, ms, 3);
		world.setBlock(x + 3, y + 6, z + 0, b, ms, 3);
		world.setBlock(x + 3, y + 6, z + 7, b, ms, 3);
		world.setBlock(x + 3, y + 6, z + 8, b, ms, 3);
		world.setBlock(x + 3, y + 6, z + 9, b, ms, 3);
		world.setBlock(x + 3, y + 6, z + 10, b, ms, 3);
		world.setBlock(x + 3, y + 6, z + 11, b, ms, 3);
		world.setBlock(x + 3, y + 6, z + 12, b, ms, 3);
		world.setBlock(x + 3, y + 6, z + 13, b, ms, 3);
		world.setBlock(x + 3, y + 6, z + 14, b, ms, 3);
		world.setBlock(x + 3, y + 6, z + 15, b, ms, 3);
		world.setBlock(x + 3, y + 6, z + 16, b, ms, 3);
		world.setBlock(x + 3, y + 7, z + 0, b, ms, 3);
		world.setBlock(x + 3, y + 7, z + 10, b, ms, 3);
		world.setBlock(x + 3, y + 7, z + 11, b, ms, 3);
		world.setBlock(x + 3, y + 7, z + 12, b, ms, 3);
		world.setBlock(x + 3, y + 7, z + 13, b, ms, 3);
		world.setBlock(x + 3, y + 7, z + 14, b, ms, 3);
		world.setBlock(x + 3, y + 7, z + 15, b, ms, 3);
		world.setBlock(x + 3, y + 7, z + 16, b, ms, 3);
		world.setBlock(x + 3, y + 8, z + 0, b, ms, 3);
		world.setBlock(x + 3, y + 8, z + 13, b, ms, 3);
		world.setBlock(x + 3, y + 8, z + 14, b, ms, 3);
		world.setBlock(x + 3, y + 8, z + 15, b, ms, 3);
		world.setBlock(x + 3, y + 8, z + 16, b, ms, 3);
		world.setBlock(x + 3, y + 9, z + 0, b, ms, 3);
		world.setBlock(x + 3, y + 9, z + 16, b, ms, 3);
		world.setBlock(x + 3, y + 10, z + 0, b, ms, 3);
		world.setBlock(x + 3, y + 10, z + 1, b, ms, 3);
		world.setBlock(x + 3, y + 10, z + 2, b, ms, 3);
		world.setBlock(x + 3, y + 10, z + 3, b, ms, 3);
		world.setBlock(x + 3, y + 10, z + 16, b, ms, 3);
		world.setBlock(x + 3, y + 11, z + 0, b, ms, 3);
		world.setBlock(x + 3, y + 11, z + 1, b, ms, 3);
		world.setBlock(x + 3, y + 11, z + 2, b, ms, 3);
		world.setBlock(x + 3, y + 11, z + 3, b, ms, 3);
		world.setBlock(x + 3, y + 11, z + 4, b, ms, 3);
		world.setBlock(x + 3, y + 11, z + 5, b, ms, 3);
		world.setBlock(x + 3, y + 11, z + 6, b, ms, 3);
		world.setBlock(x + 3, y + 11, z + 16, b, ms, 3);
		world.setBlock(x + 3, y + 12, z + 0, b, ms, 3);
		world.setBlock(x + 3, y + 12, z + 1, b, ms, 3);
		world.setBlock(x + 3, y + 12, z + 2, b, ms, 3);
		world.setBlock(x + 3, y + 12, z + 3, b, ms, 3);
		world.setBlock(x + 3, y + 12, z + 4, b, ms, 3);
		world.setBlock(x + 3, y + 12, z + 5, b, ms, 3);
		world.setBlock(x + 3, y + 12, z + 6, b, ms, 3);
		world.setBlock(x + 3, y + 12, z + 7, b, ms, 3);
		world.setBlock(x + 3, y + 12, z + 8, b, ms, 3);
		world.setBlock(x + 3, y + 12, z + 9, b, ms, 3);
		world.setBlock(x + 3, y + 12, z + 16, b, ms, 3);
		world.setBlock(x + 3, y + 13, z + 0, b, ms, 3);
		world.setBlock(x + 3, y + 13, z + 1, b, ms, 3);
		world.setBlock(x + 3, y + 13, z + 2, b, ms, 3);
		world.setBlock(x + 3, y + 13, z + 3, b, ms, 3);
		world.setBlock(x + 3, y + 13, z + 4, b, ms, 3);
		world.setBlock(x + 3, y + 13, z + 5, b, ms, 3);
		world.setBlock(x + 3, y + 13, z + 6, b, ms, 3);
		world.setBlock(x + 3, y + 13, z + 7, b, ms, 3);
		world.setBlock(x + 3, y + 13, z + 8, b, ms, 3);
		world.setBlock(x + 3, y + 13, z + 9, b, ms, 3);
		world.setBlock(x + 3, y + 13, z + 10, b, ms, 3);
		world.setBlock(x + 3, y + 13, z + 11, b, ms, 3);
		world.setBlock(x + 3, y + 13, z + 12, b, ms, 3);
		world.setBlock(x + 3, y + 13, z + 16, b, ms, 3);
		world.setBlock(x + 3, y + 14, z + 0, b, ms, 3);
		world.setBlock(x + 3, y + 14, z + 1, b, ms, 3);
		world.setBlock(x + 3, y + 14, z + 2, b, ms, 3);
		world.setBlock(x + 3, y + 14, z + 3, b, ms, 3);
		world.setBlock(x + 3, y + 14, z + 4, b, ms, 3);
		world.setBlock(x + 3, y + 14, z + 5, b, ms, 3);
		world.setBlock(x + 3, y + 14, z + 6, b, ms, 3);
		world.setBlock(x + 3, y + 14, z + 7, b, ms, 3);
		world.setBlock(x + 3, y + 14, z + 8, b, ms, 3);
		world.setBlock(x + 3, y + 14, z + 9, b, ms, 3);
		world.setBlock(x + 3, y + 14, z + 10, b, ms, 3);
		world.setBlock(x + 3, y + 14, z + 11, b, ms, 3);
		world.setBlock(x + 3, y + 14, z + 12, b, ms, 3);
		world.setBlock(x + 3, y + 14, z + 13, b, ms, 3);
		world.setBlock(x + 3, y + 14, z + 14, b, ms, 3);
		world.setBlock(x + 3, y + 14, z + 15, b, ms, 3);
		world.setBlock(x + 3, y + 14, z + 16, b, ms, 3);
		world.setBlock(x + 3, y + 15, z + 0, b, ms, 3);
		world.setBlock(x + 3, y + 15, z + 1, b, ms, 3);
		world.setBlock(x + 3, y + 15, z + 2, b, ms, 3);
		world.setBlock(x + 3, y + 15, z + 3, b, ms, 3);
		world.setBlock(x + 3, y + 15, z + 4, b, ms, 3);
		world.setBlock(x + 3, y + 15, z + 5, b, ms, 3);
		world.setBlock(x + 3, y + 15, z + 6, b, ms, 3);
		world.setBlock(x + 3, y + 15, z + 7, b, ms, 3);
		world.setBlock(x + 3, y + 15, z + 8, b, ms, 3);
		world.setBlock(x + 3, y + 15, z + 9, b, ms, 3);
		world.setBlock(x + 3, y + 15, z + 10, b, ms, 3);
		world.setBlock(x + 3, y + 15, z + 11, b, ms, 3);
		world.setBlock(x + 3, y + 15, z + 12, b, ms, 3);
		world.setBlock(x + 3, y + 15, z + 13, b, ms, 3);
		world.setBlock(x + 3, y + 15, z + 14, b, ms, 3);
		world.setBlock(x + 3, y + 15, z + 15, b, ms, 3);
		world.setBlock(x + 3, y + 15, z + 16, b, ms, 3);
		world.setBlock(x + 4, y + 0, z + 0, b, ms, 3);
		world.setBlock(x + 4, y + 0, z + 1, b, ms, 3);
		world.setBlock(x + 4, y + 0, z + 2, b, ms, 3);
		world.setBlock(x + 4, y + 0, z + 3, b, ms, 3);
		world.setBlock(x + 4, y + 0, z + 4, b, ms, 3);
		world.setBlock(x + 4, y + 0, z + 5, b, ms, 3);
		world.setBlock(x + 4, y + 0, z + 6, b, ms, 3);
		world.setBlock(x + 4, y + 0, z + 7, b, ms, 3);
		world.setBlock(x + 4, y + 0, z + 8, b, ms, 3);
		world.setBlock(x + 4, y + 0, z + 9, b, ms, 3);
		world.setBlock(x + 4, y + 0, z + 10, b, ms, 3);
		world.setBlock(x + 4, y + 0, z + 11, b, ms, 3);
		world.setBlock(x + 4, y + 0, z + 12, b, ms, 3);
		world.setBlock(x + 4, y + 0, z + 13, b, ms, 3);
		world.setBlock(x + 4, y + 0, z + 14, b, ms, 3);
		world.setBlock(x + 4, y + 0, z + 15, b, ms, 3);
		world.setBlock(x + 4, y + 0, z + 16, b, ms, 3);
		world.setBlock(x + 4, y + 1, z + 0, b, ms, 3);
		world.setBlock(x + 4, y + 1, z + 1, b, ms, 3);
		world.setBlock(x + 4, y + 1, z + 2, b, ms, 3);
		world.setBlock(x + 4, y + 1, z + 3, b, ms, 3);
		world.setBlock(x + 4, y + 1, z + 4, b, ms, 3);
		world.setBlock(x + 4, y + 1, z + 5, b, ms, 3);
		world.setBlock(x + 4, y + 1, z + 6, b, ms, 3);
		world.setBlock(x + 4, y + 1, z + 7, b, ms, 3);
		world.setBlock(x + 4, y + 1, z + 8, b, ms, 3);
		world.setBlock(x + 4, y + 1, z + 9, b, ms, 3);
		world.setBlock(x + 4, y + 1, z + 10, b, ms, 3);
		world.setBlock(x + 4, y + 1, z + 11, b, ms, 3);
		world.setBlock(x + 4, y + 1, z + 12, b, ms, 3);
		world.setBlock(x + 4, y + 1, z + 13, b, ms, 3);
		world.setBlock(x + 4, y + 1, z + 14, b, ms, 3);
		world.setBlock(x + 4, y + 1, z + 15, b, ms, 3);
		world.setBlock(x + 4, y + 1, z + 16, b, ms, 3);
		world.setBlock(x + 4, y + 2, z + 0, b, ms, 3);
		world.setBlock(x + 4, y + 2, z + 1, b, ms, 3);
		world.setBlock(x + 4, y + 2, z + 2, b, ms, 3);
		world.setBlock(x + 4, y + 2, z + 3, b, ms, 3);
		world.setBlock(x + 4, y + 2, z + 4, b, ms, 3);
		world.setBlock(x + 4, y + 2, z + 5, b, ms, 3);
		world.setBlock(x + 4, y + 2, z + 6, b, ms, 3);
		world.setBlock(x + 4, y + 2, z + 7, b, ms, 3);
		world.setBlock(x + 4, y + 2, z + 8, b, ms, 3);
		world.setBlock(x + 4, y + 2, z + 9, b, ms, 3);
		world.setBlock(x + 4, y + 2, z + 10, b, ms, 3);
		world.setBlock(x + 4, y + 2, z + 11, b, ms, 3);
		world.setBlock(x + 4, y + 2, z + 12, b, ms, 3);
		world.setBlock(x + 4, y + 2, z + 13, b, ms, 3);
		world.setBlock(x + 4, y + 2, z + 14, b, ms, 3);
		world.setBlock(x + 4, y + 2, z + 15, b, ms, 3);
		world.setBlock(x + 4, y + 2, z + 16, b, ms, 3);
		world.setBlock(x + 4, y + 3, z + 0, b, ms, 3);
		world.setBlock(x + 4, y + 3, z + 1, b, ms, 3);
		world.setBlock(x + 4, y + 3, z + 2, b, ms, 3);
		world.setBlock(x + 4, y + 3, z + 3, b, ms, 3);
		world.setBlock(x + 4, y + 3, z + 4, b, ms, 3);
		world.setBlock(x + 4, y + 3, z + 5, b, ms, 3);
		world.setBlock(x + 4, y + 3, z + 6, b, ms, 3);
		world.setBlock(x + 4, y + 3, z + 7, b, ms, 3);
		world.setBlock(x + 4, y + 3, z + 8, b, ml, 3);
		world.setBlock(x + 4, y + 3, z + 9, b, ms, 3);
		world.setBlock(x + 4, y + 3, z + 10, b, ms, 3);
		world.setBlock(x + 4, y + 3, z + 11, b, ms, 3);
		world.setBlock(x + 4, y + 3, z + 12, b, ms, 3);
		world.setBlock(x + 4, y + 3, z + 13, b, ms, 3);
		world.setBlock(x + 4, y + 3, z + 14, b, ms, 3);
		world.setBlock(x + 4, y + 3, z + 15, b, ms, 3);
		world.setBlock(x + 4, y + 3, z + 16, b, ms, 3);
		world.setBlock(x + 4, y + 4, z + 0, b, ms, 3);
		world.setBlock(x + 4, y + 4, z + 4, b, ms, 3);
		world.setBlock(x + 4, y + 4, z + 5, b, ms, 3);
		world.setBlock(x + 4, y + 4, z + 6, b, ms, 3);
		world.setBlock(x + 4, y + 4, z + 7, b, ms, 3);
		world.setBlock(x + 4, y + 4, z + 8, b, ms, 3);
		world.setBlock(x + 4, y + 4, z + 9, b, ms, 3);
		world.setBlock(x + 4, y + 4, z + 10, b, ms, 3);
		world.setBlock(x + 4, y + 4, z + 11, b, ms, 3);
		world.setBlock(x + 4, y + 4, z + 12, b, ms, 3);
		world.setBlock(x + 4, y + 4, z + 13, b, ms, 3);
		world.setBlock(x + 4, y + 4, z + 14, b, ms, 3);
		world.setBlock(x + 4, y + 4, z + 15, b, ms, 3);
		world.setBlock(x + 4, y + 4, z + 16, b, ms, 3);
		world.setBlock(x + 4, y + 5, z + 0, b, ms, 3);
		world.setBlock(x + 4, y + 5, z + 4, b, ms, 3);
		world.setBlock(x + 4, y + 5, z + 5, b, ms, 3);
		world.setBlock(x + 4, y + 5, z + 6, b, ms, 3);
		world.setBlock(x + 4, y + 5, z + 7, b, ms, 3);
		world.setBlock(x + 4, y + 5, z + 8, b, ms, 3);
		world.setBlock(x + 4, y + 5, z + 9, b, ms, 3);
		world.setBlock(x + 4, y + 5, z + 10, b, ms, 3);
		world.setBlock(x + 4, y + 5, z + 11, b, ms, 3);
		world.setBlock(x + 4, y + 5, z + 12, b, ms, 3);
		world.setBlock(x + 4, y + 5, z + 13, b, ms, 3);
		world.setBlock(x + 4, y + 5, z + 14, b, ms, 3);
		world.setBlock(x + 4, y + 5, z + 15, b, ms, 3);
		world.setBlock(x + 4, y + 5, z + 16, b, ms, 3);
		world.setBlock(x + 4, y + 6, z + 0, b, ms, 3);
		world.setBlock(x + 4, y + 6, z + 4, b, ms, 3);
		world.setBlock(x + 4, y + 6, z + 5, b, ms, 3);
		world.setBlock(x + 4, y + 6, z + 6, b, ms, 3);
		world.setBlock(x + 4, y + 6, z + 7, b, ms, 3);
		world.setBlock(x + 4, y + 6, z + 8, b, ms, 3);
		world.setBlock(x + 4, y + 6, z + 9, b, ms, 3);
		world.setBlock(x + 4, y + 6, z + 10, b, ms, 3);
		world.setBlock(x + 4, y + 6, z + 11, b, ms, 3);
		world.setBlock(x + 4, y + 6, z + 12, b, ms, 3);
		world.setBlock(x + 4, y + 6, z + 13, b, ms, 3);
		world.setBlock(x + 4, y + 6, z + 14, b, ms, 3);
		world.setBlock(x + 4, y + 6, z + 15, b, ms, 3);
		world.setBlock(x + 4, y + 6, z + 16, b, ms, 3);
		world.setBlock(x + 4, y + 7, z + 0, b, ms, 3);
		world.setBlock(x + 4, y + 7, z + 4, b, ms, 3);
		world.setBlock(x + 4, y + 7, z + 5, b, ms, 3);
		world.setBlock(x + 4, y + 7, z + 6, b, ms, 3);
		world.setBlock(x + 4, y + 7, z + 10, b, ms, 3);
		world.setBlock(x + 4, y + 7, z + 11, b, ms, 3);
		world.setBlock(x + 4, y + 7, z + 12, b, ms, 3);
		world.setBlock(x + 4, y + 7, z + 13, b, ms, 3);
		world.setBlock(x + 4, y + 7, z + 14, b, ms, 3);
		world.setBlock(x + 4, y + 7, z + 15, b, ms, 3);
		world.setBlock(x + 4, y + 7, z + 16, b, ms, 3);
		world.setBlock(x + 4, y + 8, z + 0, b, ms, 3);
		world.setBlock(x + 4, y + 8, z + 4, b, ms, 3);
		world.setBlock(x + 4, y + 8, z + 5, b, ms, 3);
		world.setBlock(x + 4, y + 8, z + 6, b, ms, 3);
		world.setBlock(x + 4, y + 8, z + 10, b, ms, 3);
		world.setBlock(x + 4, y + 8, z + 11, b, ms, 3);
		world.setBlock(x + 4, y + 8, z + 12, b, ms, 3);
		world.setBlock(x + 4, y + 8, z + 13, b, ms, 3);
		world.setBlock(x + 4, y + 8, z + 14, b, ms, 3);
		world.setBlock(x + 4, y + 8, z + 15, b, ms, 3);
		world.setBlock(x + 4, y + 8, z + 16, b, ms, 3);
		world.setBlock(x + 4, y + 9, z + 0, b, ms, 3);
		world.setBlock(x + 4, y + 9, z + 1, b, ms, 3);
		world.setBlock(x + 4, y + 9, z + 2, b, ms, 3);
		world.setBlock(x + 4, y + 9, z + 3, b, ms, 3);
		world.setBlock(x + 4, y + 9, z + 4, b, ms, 3);
		world.setBlock(x + 4, y + 9, z + 5, b, ms, 3);
		world.setBlock(x + 4, y + 9, z + 6, b, ms, 3);
		world.setBlock(x + 4, y + 9, z + 10, b, ms, 3);
		world.setBlock(x + 4, y + 9, z + 11, b, ms, 3);
		world.setBlock(x + 4, y + 9, z + 12, b, ms, 3);
		world.setBlock(x + 4, y + 9, z + 13, b, ms, 3);
		world.setBlock(x + 4, y + 9, z + 14, b, ms, 3);
		world.setBlock(x + 4, y + 9, z + 15, b, ms, 3);
		world.setBlock(x + 4, y + 9, z + 16, b, ms, 3);
		world.setBlock(x + 4, y + 10, z + 0, b, ms, 3);
		world.setBlock(x + 4, y + 10, z + 1, b, ms, 3);
		world.setBlock(x + 4, y + 10, z + 2, b, ms, 3);
		world.setBlock(x + 4, y + 10, z + 3, b, ms, 3);
		world.setBlock(x + 4, y + 10, z + 4, b, ms, 3);
		world.setBlock(x + 4, y + 10, z + 5, b, ms, 3);
		world.setBlock(x + 4, y + 10, z + 6, b, ms, 3);
		world.setBlock(x + 4, y + 10, z + 7, b, ms, 3);
		world.setBlock(x + 4, y + 10, z + 8, b, ms, 3);
		world.setBlock(x + 4, y + 10, z + 9, b, ms, 3);
		world.setBlock(x + 4, y + 10, z + 10, b, ms, 3);
		world.setBlock(x + 4, y + 10, z + 11, b, ms, 3);
		world.setBlock(x + 4, y + 10, z + 12, b, ms, 3);
		world.setBlock(x + 4, y + 10, z + 16, b, ms, 3);
		world.setBlock(x + 4, y + 11, z + 0, b, ms, 3);
		world.setBlock(x + 4, y + 11, z + 1, b, ms, 3);
		world.setBlock(x + 4, y + 11, z + 2, b, ms, 3);
		world.setBlock(x + 4, y + 11, z + 3, b, ms, 3);
		world.setBlock(x + 4, y + 11, z + 4, b, ms, 3);
		world.setBlock(x + 4, y + 11, z + 5, b, ms, 3);
		world.setBlock(x + 4, y + 11, z + 6, b, ms, 3);
		world.setBlock(x + 4, y + 11, z + 7, b, ms, 3);
		world.setBlock(x + 4, y + 11, z + 8, b, ms, 3);
		world.setBlock(x + 4, y + 11, z + 9, b, ms, 3);
		world.setBlock(x + 4, y + 11, z + 10, b, ms, 3);
		world.setBlock(x + 4, y + 11, z + 11, b, ms, 3);
		world.setBlock(x + 4, y + 11, z + 12, b, ms, 3);
		world.setBlock(x + 4, y + 11, z + 16, b, ms, 3);
		world.setBlock(x + 4, y + 12, z + 0, b, ms, 3);
		world.setBlock(x + 4, y + 12, z + 1, b, ms, 3);
		world.setBlock(x + 4, y + 12, z + 2, b, ms, 3);
		world.setBlock(x + 4, y + 12, z + 3, b, ms, 3);
		world.setBlock(x + 4, y + 12, z + 4, b, ms, 3);
		world.setBlock(x + 4, y + 12, z + 5, b, ms, 3);
		world.setBlock(x + 4, y + 12, z + 6, b, ms, 3);
		world.setBlock(x + 4, y + 12, z + 7, b, ms, 3);
		world.setBlock(x + 4, y + 12, z + 8, b, ms, 3);
		world.setBlock(x + 4, y + 12, z + 9, b, ms, 3);
		world.setBlock(x + 4, y + 12, z + 10, b, ms, 3);
		world.setBlock(x + 4, y + 12, z + 11, b, ms, 3);
		world.setBlock(x + 4, y + 12, z + 12, b, ms, 3);
		world.setBlock(x + 4, y + 12, z + 16, b, ms, 3);
		world.setBlock(x + 4, y + 13, z + 0, b, ms, 3);
		world.setBlock(x + 4, y + 13, z + 1, b, ms, 3);
		world.setBlock(x + 4, y + 13, z + 2, b, ms, 3);
		world.setBlock(x + 4, y + 13, z + 3, b, ms, 3);
		world.setBlock(x + 4, y + 13, z + 4, b, ms, 3);
		world.setBlock(x + 4, y + 13, z + 5, b, ms, 3);
		world.setBlock(x + 4, y + 13, z + 6, b, ms, 3);
		world.setBlock(x + 4, y + 13, z + 7, b, ms, 3);
		world.setBlock(x + 4, y + 13, z + 8, b, ml, 3);
		world.setBlock(x + 4, y + 13, z + 9, b, ms, 3);
		world.setBlock(x + 4, y + 13, z + 10, b, ms, 3);
		world.setBlock(x + 4, y + 13, z + 11, b, ms, 3);
		world.setBlock(x + 4, y + 13, z + 12, b, ms, 3);
		world.setBlock(x + 4, y + 13, z + 16, b, ms, 3);
		world.setBlock(x + 4, y + 14, z + 0, b, ms, 3);
		world.setBlock(x + 4, y + 14, z + 1, b, ms, 3);
		world.setBlock(x + 4, y + 14, z + 2, b, ms, 3);
		world.setBlock(x + 4, y + 14, z + 3, b, ms, 3);
		world.setBlock(x + 4, y + 14, z + 4, b, ms, 3);
		world.setBlock(x + 4, y + 14, z + 5, b, ms, 3);
		world.setBlock(x + 4, y + 14, z + 6, b, ms, 3);
		world.setBlock(x + 4, y + 14, z + 7, b, ms, 3);
		world.setBlock(x + 4, y + 14, z + 8, b, ms, 3);
		world.setBlock(x + 4, y + 14, z + 9, b, ms, 3);
		world.setBlock(x + 4, y + 14, z + 10, b, ms, 3);
		world.setBlock(x + 4, y + 14, z + 11, b, ms, 3);
		world.setBlock(x + 4, y + 14, z + 12, b, ms, 3);
		world.setBlock(x + 4, y + 14, z + 16, b, ms, 3);
		world.setBlock(x + 4, y + 15, z + 0, b, ms, 3);
		world.setBlock(x + 4, y + 15, z + 1, b, ms, 3);
		world.setBlock(x + 4, y + 15, z + 2, b, ms, 3);
		world.setBlock(x + 4, y + 15, z + 3, b, ms, 3);
		world.setBlock(x + 4, y + 15, z + 4, b, ms, 3);
		world.setBlock(x + 4, y + 15, z + 5, b, ms, 3);
		world.setBlock(x + 4, y + 15, z + 6, b, ms, 3);
		world.setBlock(x + 4, y + 15, z + 7, b, ms, 3);
		world.setBlock(x + 4, y + 15, z + 8, b, ms, 3);
		world.setBlock(x + 4, y + 15, z + 9, b, ms, 3);
		world.setBlock(x + 4, y + 15, z + 10, b, ms, 3);
		world.setBlock(x + 4, y + 15, z + 11, b, ms, 3);
		world.setBlock(x + 4, y + 15, z + 12, b, ms, 3);
		world.setBlock(x + 4, y + 15, z + 13, b, ms, 3);
		world.setBlock(x + 4, y + 15, z + 14, b, ms, 3);
		world.setBlock(x + 4, y + 15, z + 15, b, ms, 3);
		world.setBlock(x + 4, y + 15, z + 16, b, ms, 3);
		world.setBlock(x + 5, y + 0, z + 0, b, ms, 3);
		world.setBlock(x + 5, y + 0, z + 1, b, ms, 3);
		world.setBlock(x + 5, y + 0, z + 2, b, ms, 3);
		world.setBlock(x + 5, y + 0, z + 3, b, ms, 3);
		world.setBlock(x + 5, y + 0, z + 4, b, ms, 3);
		world.setBlock(x + 5, y + 0, z + 5, b, ms, 3);
		world.setBlock(x + 5, y + 0, z + 6, b, mc, 3);
		world.setBlock(x + 5, y + 0, z + 7, b, mc, 3);
		world.setBlock(x + 5, y + 0, z + 8, b, mc, 3);
		world.setBlock(x + 5, y + 0, z + 9, b, mc, 3);
		world.setBlock(x + 5, y + 0, z + 10, b, mc, 3);
		world.setBlock(x + 5, y + 0, z + 11, b, ms, 3);
		world.setBlock(x + 5, y + 0, z + 12, b, ms, 3);
		world.setBlock(x + 5, y + 0, z + 13, b, ms, 3);
		world.setBlock(x + 5, y + 0, z + 14, b, ms, 3);
		world.setBlock(x + 5, y + 0, z + 15, b, ms, 3);
		world.setBlock(x + 5, y + 0, z + 16, b, ms, 3);
		world.setBlock(x + 5, y + 1, z + 0, b, ms, 3);
		world.setBlock(x + 5, y + 1, z + 1, b, ms, 3);
		world.setBlock(x + 5, y + 1, z + 2, b, ms, 3);
		world.setBlock(x + 5, y + 1, z + 3, b, ms, 3);
		world.setBlock(x + 5, y + 1, z + 4, b, ms, 3);
		world.setBlock(x + 5, y + 1, z + 5, b, ms, 3);
		world.setBlock(x + 5, y + 1, z + 6, b, mc, 3);
		world.setBlock(x + 5, y + 1, z + 7, b, mc, 3);
		world.setBlock(x + 5, y + 1, z + 8, b, mc, 3);
		world.setBlock(x + 5, y + 1, z + 9, b, mc, 3);
		world.setBlock(x + 5, y + 1, z + 10, b, mc, 3);
		world.setBlock(x + 5, y + 1, z + 11, b, ms, 3);
		world.setBlock(x + 5, y + 1, z + 12, b, ms, 3);
		world.setBlock(x + 5, y + 1, z + 13, b, ms, 3);
		world.setBlock(x + 5, y + 1, z + 14, b, ms, 3);
		world.setBlock(x + 5, y + 1, z + 15, b, ms, 3);
		world.setBlock(x + 5, y + 1, z + 16, b, ms, 3);
		world.setBlock(x + 5, y + 2, z + 0, b, ms, 3);
		world.setBlock(x + 5, y + 2, z + 1, b, ms, 3);
		world.setBlock(x + 5, y + 2, z + 2, b, ms, 3);
		world.setBlock(x + 5, y + 2, z + 3, b, ms, 3);
		world.setBlock(x + 5, y + 2, z + 4, b, ms, 3);
		world.setBlock(x + 5, y + 2, z + 5, b, ms, 3);
		world.setBlock(x + 5, y + 2, z + 6, b, mc, 3);
		world.setBlock(x + 5, y + 2, z + 7, b, mc, 3);
		world.setBlock(x + 5, y + 2, z + 8, b, mc, 3);
		world.setBlock(x + 5, y + 2, z + 9, b, mc, 3);
		world.setBlock(x + 5, y + 2, z + 10, b, mc, 3);
		world.setBlock(x + 5, y + 2, z + 11, b, ms, 3);
		world.setBlock(x + 5, y + 2, z + 12, b, ms, 3);
		world.setBlock(x + 5, y + 2, z + 13, b, ms, 3);
		world.setBlock(x + 5, y + 2, z + 14, b, ms, 3);
		world.setBlock(x + 5, y + 2, z + 15, b, ms, 3);
		world.setBlock(x + 5, y + 2, z + 16, b, ms, 3);
		world.setBlock(x + 5, y + 3, z + 0, b, ms, 3);
		world.setBlock(x + 5, y + 3, z + 1, b, ms, 3);
		world.setBlock(x + 5, y + 3, z + 2, b, ms, 3);
		world.setBlock(x + 5, y + 3, z + 3, b, ms, 3);
		world.setBlock(x + 5, y + 3, z + 4, b, ms, 3);
		world.setBlock(x + 5, y + 3, z + 5, b, ms, 3);
		world.setBlock(x + 5, y + 3, z + 6, b, mc, 3);
		world.setBlock(x + 5, y + 3, z + 7, b, mc, 3);
		world.setBlock(x + 5, y + 3, z + 8, b, ml, 3);
		world.setBlock(x + 5, y + 3, z + 9, b, mc, 3);
		world.setBlock(x + 5, y + 3, z + 10, b, mc, 3);
		world.setBlock(x + 5, y + 3, z + 11, b, ms, 3);
		world.setBlock(x + 5, y + 3, z + 12, b, ms, 3);
		world.setBlock(x + 5, y + 3, z + 13, b, ms, 3);
		world.setBlock(x + 5, y + 3, z + 14, b, ms, 3);
		world.setBlock(x + 5, y + 3, z + 15, b, ms, 3);
		world.setBlock(x + 5, y + 3, z + 16, b, ms, 3);
		world.setBlock(x + 5, y + 4, z + 0, b, ms, 3);
		world.setBlock(x + 5, y + 4, z + 4, b, ms, 3);
		world.setBlock(x + 5, y + 4, z + 5, b, ms, 3);
		world.setBlock(x + 5, y + 4, z + 6, b, mc, 3);
		world.setBlock(x + 5, y + 4, z + 7, b, mc, 3);
		world.setBlock(x + 5, y + 4, z + 8, b, mc, 3);
		world.setBlock(x + 5, y + 4, z + 9, b, mc, 3);
		world.setBlock(x + 5, y + 4, z + 10, b, mc, 3);
		world.setBlock(x + 5, y + 4, z + 11, b, ms, 3);
		world.setBlock(x + 5, y + 4, z + 12, b, ms, 3);
		world.setBlock(x + 5, y + 4, z + 13, b, ms, 3);
		world.setBlock(x + 5, y + 4, z + 14, b, ms, 3);
		world.setBlock(x + 5, y + 4, z + 15, b, ms, 3);
		world.setBlock(x + 5, y + 4, z + 16, b, ms, 3);
		world.setBlock(x + 5, y + 5, z + 0, b, ms, 3);
		world.setBlock(x + 5, y + 5, z + 4, b, ms, 3);
		world.setBlock(x + 5, y + 5, z + 5, b, ms, 3);
		world.setBlock(x + 5, y + 5, z + 6, b, mc, 3);
		world.setBlock(x + 5, y + 5, z + 7, b, mc, 3);
		world.setBlock(x + 5, y + 5, z + 8, b, mc, 3);
		world.setBlock(x + 5, y + 5, z + 9, b, mc, 3);
		world.setBlock(x + 5, y + 5, z + 10, b, mc, 3);
		world.setBlock(x + 5, y + 5, z + 11, b, ms, 3);
		world.setBlock(x + 5, y + 5, z + 12, b, ms, 3);
		world.setBlock(x + 5, y + 5, z + 13, b, ms, 3);
		world.setBlock(x + 5, y + 5, z + 14, b, ms, 3);
		world.setBlock(x + 5, y + 5, z + 15, b, ms, 3);
		world.setBlock(x + 5, y + 5, z + 16, b, ms, 3);
		world.setBlock(x + 5, y + 6, z + 0, b, ms, 3);
		world.setBlock(x + 5, y + 6, z + 4, b, ms, 3);
		world.setBlock(x + 5, y + 6, z + 5, b, ms, 3);
		world.setBlock(x + 5, y + 6, z + 6, b, mc, 3);
		world.setBlock(x + 5, y + 6, z + 10, b, mc, 3);
		world.setBlock(x + 5, y + 6, z + 11, b, ms, 3);
		world.setBlock(x + 5, y + 6, z + 12, b, ms, 3);
		world.setBlock(x + 5, y + 6, z + 13, b, ms, 3);
		world.setBlock(x + 5, y + 6, z + 14, b, ms, 3);
		world.setBlock(x + 5, y + 6, z + 15, b, ms, 3);
		world.setBlock(x + 5, y + 6, z + 16, b, ms, 3);
		world.setBlock(x + 5, y + 7, z + 0, b, ms, 3);
		world.setBlock(x + 5, y + 7, z + 4, b, ms, 3);
		world.setBlock(x + 5, y + 7, z + 5, b, ms, 3);
		world.setBlock(x + 5, y + 7, z + 6, b, mc, 3);
		world.setBlock(x + 5, y + 7, z + 10, b, mc, 3);
		world.setBlock(x + 5, y + 7, z + 11, b, ms, 3);
		world.setBlock(x + 5, y + 7, z + 12, b, ms, 3);
		world.setBlock(x + 5, y + 7, z + 13, b, ms, 3);
		world.setBlock(x + 5, y + 7, z + 14, b, ms, 3);
		world.setBlock(x + 5, y + 7, z + 15, b, ms, 3);
		world.setBlock(x + 5, y + 7, z + 16, b, ms, 3);
		world.setBlock(x + 5, y + 8, z + 0, b, ms, 3);
		world.setBlock(x + 5, y + 8, z + 4, b, ms, 3);
		world.setBlock(x + 5, y + 8, z + 5, b, ms, 3);
		world.setBlock(x + 5, y + 8, z + 6, b, mc, 3);
		world.setBlock(x + 5, y + 8, z + 10, b, mc, 3);
		world.setBlock(x + 5, y + 8, z + 11, b, ms, 3);
		world.setBlock(x + 5, y + 8, z + 12, b, ms, 3);
		world.setBlock(x + 5, y + 8, z + 13, b, ms, 3);
		world.setBlock(x + 5, y + 8, z + 14, b, ms, 3);
		world.setBlock(x + 5, y + 8, z + 15, b, ms, 3);
		world.setBlock(x + 5, y + 8, z + 16, b, ms, 3);
		world.setBlock(x + 5, y + 9, z + 0, b, ms, 3);
		world.setBlock(x + 5, y + 9, z + 1, b, ms, 3);
		world.setBlock(x + 5, y + 9, z + 2, b, ms, 3);
		world.setBlock(x + 5, y + 9, z + 3, b, ms, 3);
		world.setBlock(x + 5, y + 9, z + 4, b, ms, 3);
		world.setBlock(x + 5, y + 9, z + 5, b, ms, 3);
		world.setBlock(x + 5, y + 9, z + 6, b, mc, 3);
		world.setBlock(x + 5, y + 9, z + 10, b, mc, 3);
		world.setBlock(x + 5, y + 9, z + 11, b, ms, 3);
		world.setBlock(x + 5, y + 9, z + 12, b, ms, 3);
		world.setBlock(x + 5, y + 9, z + 13, b, ms, 3);
		world.setBlock(x + 5, y + 9, z + 14, b, ms, 3);
		world.setBlock(x + 5, y + 9, z + 15, b, ms, 3);
		world.setBlock(x + 5, y + 9, z + 16, b, ms, 3);
		world.setBlock(x + 5, y + 10, z + 0, b, ms, 3);
		world.setBlock(x + 5, y + 10, z + 1, b, ms, 3);
		world.setBlock(x + 5, y + 10, z + 2, b, ms, 3);
		world.setBlock(x + 5, y + 10, z + 3, b, ms, 3);
		world.setBlock(x + 5, y + 10, z + 4, b, ms, 3);
		world.setBlock(x + 5, y + 10, z + 5, b, ms, 3);
		world.setBlock(x + 5, y + 10, z + 6, b, mc, 3);
		world.setBlock(x + 5, y + 10, z + 7, b, mc, 3);
		world.setBlock(x + 5, y + 10, z + 8, b, mc, 3);
		world.setBlock(x + 5, y + 10, z + 9, b, mc, 3);
		world.setBlock(x + 5, y + 10, z + 10, b, mc, 3);
		world.setBlock(x + 5, y + 10, z + 11, b, ms, 3);
		world.setBlock(x + 5, y + 10, z + 12, b, ms, 3);
		world.setBlock(x + 5, y + 10, z + 16, b, ms, 3);
		world.setBlock(x + 5, y + 11, z + 0, b, ms, 3);
		world.setBlock(x + 5, y + 11, z + 1, b, ms, 3);
		world.setBlock(x + 5, y + 11, z + 2, b, ms, 3);
		world.setBlock(x + 5, y + 11, z + 3, b, ms, 3);
		world.setBlock(x + 5, y + 11, z + 4, b, ms, 3);
		world.setBlock(x + 5, y + 11, z + 5, b, ms, 3);
		world.setBlock(x + 5, y + 11, z + 6, b, mc, 3);
		world.setBlock(x + 5, y + 11, z + 7, b, mc, 3);
		world.setBlock(x + 5, y + 11, z + 8, b, mc, 3);
		world.setBlock(x + 5, y + 11, z + 9, b, mc, 3);
		world.setBlock(x + 5, y + 11, z + 10, b, mc, 3);
		world.setBlock(x + 5, y + 11, z + 11, b, ms, 3);
		world.setBlock(x + 5, y + 11, z + 12, b, ms, 3);
		world.setBlock(x + 5, y + 11, z + 16, b, ms, 3);
		world.setBlock(x + 5, y + 12, z + 0, b, ms, 3);
		world.setBlock(x + 5, y + 12, z + 1, b, ms, 3);
		world.setBlock(x + 5, y + 12, z + 2, b, ms, 3);
		world.setBlock(x + 5, y + 12, z + 3, b, ms, 3);
		world.setBlock(x + 5, y + 12, z + 4, b, ms, 3);
		world.setBlock(x + 5, y + 12, z + 5, b, ms, 3);
		world.setBlock(x + 5, y + 12, z + 6, b, mc, 3);
		world.setBlock(x + 5, y + 12, z + 7, b, mc, 3);
		world.setBlock(x + 5, y + 12, z + 8, b, mc, 3);
		world.setBlock(x + 5, y + 12, z + 9, b, mc, 3);
		world.setBlock(x + 5, y + 12, z + 10, b, mc, 3);
		world.setBlock(x + 5, y + 12, z + 11, b, ms, 3);
		world.setBlock(x + 5, y + 12, z + 12, b, ms, 3);
		world.setBlock(x + 5, y + 12, z + 16, b, ms, 3);
		world.setBlock(x + 5, y + 13, z + 0, b, ms, 3);
		world.setBlock(x + 5, y + 13, z + 1, b, ms, 3);
		world.setBlock(x + 5, y + 13, z + 2, b, ms, 3);
		world.setBlock(x + 5, y + 13, z + 3, b, ms, 3);
		world.setBlock(x + 5, y + 13, z + 4, b, ms, 3);
		world.setBlock(x + 5, y + 13, z + 5, b, ms, 3);
		world.setBlock(x + 5, y + 13, z + 6, b, mc, 3);
		world.setBlock(x + 5, y + 13, z + 7, b, mc, 3);
		world.setBlock(x + 5, y + 13, z + 8, b, ml, 3);
		world.setBlock(x + 5, y + 13, z + 9, b, mc, 3);
		world.setBlock(x + 5, y + 13, z + 10, b, mc, 3);
		world.setBlock(x + 5, y + 13, z + 11, b, ms, 3);
		world.setBlock(x + 5, y + 13, z + 12, b, ms, 3);
		world.setBlock(x + 5, y + 13, z + 16, b, ms, 3);
		world.setBlock(x + 5, y + 14, z + 0, b, ms, 3);
		world.setBlock(x + 5, y + 14, z + 1, b, ms, 3);
		world.setBlock(x + 5, y + 14, z + 2, b, ms, 3);
		world.setBlock(x + 5, y + 14, z + 3, b, ms, 3);
		world.setBlock(x + 5, y + 14, z + 4, b, ms, 3);
		world.setBlock(x + 5, y + 14, z + 5, b, ms, 3);
		world.setBlock(x + 5, y + 14, z + 6, b, mc, 3);
		world.setBlock(x + 5, y + 14, z + 7, b, mc, 3);
		world.setBlock(x + 5, y + 14, z + 8, b, mc, 3);
		world.setBlock(x + 5, y + 14, z + 9, b, mc, 3);
		world.setBlock(x + 5, y + 14, z + 10, b, mc, 3);
		world.setBlock(x + 5, y + 14, z + 11, b, ms, 3);
		world.setBlock(x + 5, y + 14, z + 12, b, ms, 3);
		world.setBlock(x + 5, y + 14, z + 16, b, ms, 3);
		world.setBlock(x + 5, y + 15, z + 0, b, ms, 3);
		world.setBlock(x + 5, y + 15, z + 1, b, ms, 3);
		world.setBlock(x + 5, y + 15, z + 2, b, ms, 3);
		world.setBlock(x + 5, y + 15, z + 3, b, ms, 3);
		world.setBlock(x + 5, y + 15, z + 4, b, ms, 3);
		world.setBlock(x + 5, y + 15, z + 5, b, ms, 3);
		world.setBlock(x + 5, y + 15, z + 6, b, mc, 3);
		world.setBlock(x + 5, y + 15, z + 7, b, mc, 3);
		world.setBlock(x + 5, y + 15, z + 8, b, mc, 3);
		world.setBlock(x + 5, y + 15, z + 9, b, mc, 3);
		world.setBlock(x + 5, y + 15, z + 10, b, mc, 3);
		world.setBlock(x + 5, y + 15, z + 11, b, ms, 3);
		world.setBlock(x + 5, y + 15, z + 12, b, ms, 3);
		world.setBlock(x + 5, y + 15, z + 13, b, ms, 3);
		world.setBlock(x + 5, y + 15, z + 14, b, ms, 3);
		world.setBlock(x + 5, y + 15, z + 15, b, ms, 3);
		world.setBlock(x + 5, y + 15, z + 16, b, ms, 3);
		world.setBlock(x + 6, y + 0, z + 0, b, ms, 3);
		world.setBlock(x + 6, y + 0, z + 1, b, ms, 3);
		world.setBlock(x + 6, y + 0, z + 2, b, ms, 3);
		world.setBlock(x + 6, y + 0, z + 3, b, ms, 3);
		world.setBlock(x + 6, y + 0, z + 4, b, ms, 3);
		world.setBlock(x + 6, y + 0, z + 5, b, mc, 3);
		world.setBlock(x + 6, y + 0, z + 11, b, mc, 3);
		world.setBlock(x + 6, y + 0, z + 12, b, ms, 3);
		world.setBlock(x + 6, y + 0, z + 13, b, ms, 3);
		world.setBlock(x + 6, y + 0, z + 14, b, ms, 3);
		world.setBlock(x + 6, y + 0, z + 15, b, ms, 3);
		world.setBlock(x + 6, y + 0, z + 16, b, ms, 3);
		world.setBlock(x + 6, y + 1, z + 0, b, ms, 3);
		world.setBlock(x + 6, y + 1, z + 1, b, ms, 3);
		world.setBlock(x + 6, y + 1, z + 2, b, ms, 3);
		world.setBlock(x + 6, y + 1, z + 3, b, ms, 3);
		world.setBlock(x + 6, y + 1, z + 4, b, ms, 3);
		world.setBlock(x + 6, y + 1, z + 5, b, mc, 3);
		world.setBlock(x + 6, y + 1, z + 11, b, mc, 3);
		world.setBlock(x + 6, y + 1, z + 12, b, ms, 3);
		world.setBlock(x + 6, y + 1, z + 13, b, ms, 3);
		world.setBlock(x + 6, y + 1, z + 14, b, ms, 3);
		world.setBlock(x + 6, y + 1, z + 15, b, ms, 3);
		world.setBlock(x + 6, y + 1, z + 16, b, ms, 3);
		world.setBlock(x + 6, y + 2, z + 0, b, ms, 3);
		world.setBlock(x + 6, y + 2, z + 1, b, ms, 3);
		world.setBlock(x + 6, y + 2, z + 2, b, ms, 3);
		world.setBlock(x + 6, y + 2, z + 3, b, ms, 3);
		world.setBlock(x + 6, y + 2, z + 4, b, ms, 3);
		world.setBlock(x + 6, y + 2, z + 5, b, mc, 3);
		world.setBlock(x + 6, y + 2, z + 11, b, mc, 3);
		world.setBlock(x + 6, y + 2, z + 12, b, ms, 3);
		world.setBlock(x + 6, y + 2, z + 13, b, ms, 3);
		world.setBlock(x + 6, y + 2, z + 14, b, ms, 3);
		world.setBlock(x + 6, y + 2, z + 15, b, ms, 3);
		world.setBlock(x + 6, y + 2, z + 16, b, ms, 3);
		world.setBlock(x + 6, y + 3, z + 0, b, ms, 3);
		world.setBlock(x + 6, y + 3, z + 1, b, ms, 3);
		world.setBlock(x + 6, y + 3, z + 2, b, ms, 3);
		world.setBlock(x + 6, y + 3, z + 3, b, ms, 3);
		world.setBlock(x + 6, y + 3, z + 4, b, ms, 3);
		world.setBlock(x + 6, y + 3, z + 5, b, mc, 3);
		world.setBlock(x + 6, y + 3, z + 11, b, mc, 3);
		world.setBlock(x + 6, y + 3, z + 12, b, ms, 3);
		world.setBlock(x + 6, y + 3, z + 13, b, ms, 3);
		world.setBlock(x + 6, y + 3, z + 14, b, ms, 3);
		world.setBlock(x + 6, y + 3, z + 15, b, ms, 3);
		world.setBlock(x + 6, y + 3, z + 16, b, ms, 3);
		world.setBlock(x + 6, y + 4, z + 0, b, ms, 3);
		world.setBlock(x + 6, y + 4, z + 4, b, ms, 3);
		world.setBlock(x + 6, y + 4, z + 5, b, mc, 3);
		world.setBlock(x + 6, y + 4, z + 11, b, mc, 3);
		world.setBlock(x + 6, y + 4, z + 12, b, ms, 3);
		world.setBlock(x + 6, y + 4, z + 13, b, ms, 3);
		world.setBlock(x + 6, y + 4, z + 14, b, ms, 3);
		world.setBlock(x + 6, y + 4, z + 15, b, ms, 3);
		world.setBlock(x + 6, y + 4, z + 16, b, ms, 3);
		world.setBlock(x + 6, y + 5, z + 0, b, ms, 3);
		world.setBlock(x + 6, y + 5, z + 4, b, ms, 3);
		world.setBlock(x + 6, y + 5, z + 5, b, mc, 3);
		world.setBlock(x + 6, y + 5, z + 11, b, mc, 3);
		world.setBlock(x + 6, y + 5, z + 12, b, ms, 3);
		world.setBlock(x + 6, y + 5, z + 13, b, ms, 3);
		world.setBlock(x + 6, y + 5, z + 14, b, ms, 3);
		world.setBlock(x + 6, y + 5, z + 15, b, ms, 3);
		world.setBlock(x + 6, y + 5, z + 16, b, ms, 3);
		world.setBlock(x + 6, y + 6, z + 0, b, ms, 3);
		world.setBlock(x + 6, y + 6, z + 4, b, ms, 3);
		world.setBlock(x + 6, y + 6, z + 5, b, mc, 3);
		world.setBlock(x + 6, y + 6, z + 11, b, mc, 3);
		world.setBlock(x + 6, y + 6, z + 12, b, ms, 3);
		world.setBlock(x + 6, y + 6, z + 13, b, ms, 3);
		world.setBlock(x + 6, y + 6, z + 14, b, ms, 3);
		world.setBlock(x + 6, y + 6, z + 15, b, ms, 3);
		world.setBlock(x + 6, y + 6, z + 16, b, ms, 3);
		world.setBlock(x + 6, y + 7, z + 0, b, ms, 3);
		world.setBlock(x + 6, y + 7, z + 4, b, ms, 3);
		world.setBlock(x + 6, y + 7, z + 5, b, mc, 3);
		world.setBlock(x + 6, y + 7, z + 11, b, mc, 3);
		world.setBlock(x + 6, y + 7, z + 12, b, ms, 3);
		world.setBlock(x + 6, y + 7, z + 13, b, ms, 3);
		world.setBlock(x + 6, y + 7, z + 14, b, ms, 3);
		world.setBlock(x + 6, y + 7, z + 15, b, ms, 3);
		world.setBlock(x + 6, y + 7, z + 16, b, ms, 3);
		world.setBlock(x + 6, y + 8, z + 0, b, ms, 3);
		world.setBlock(x + 6, y + 8, z + 4, b, ms, 3);
		world.setBlock(x + 6, y + 8, z + 5, b, mc, 3);
		world.setBlock(x + 6, y + 8, z + 11, b, mc, 3);
		world.setBlock(x + 6, y + 8, z + 12, b, ms, 3);
		world.setBlock(x + 6, y + 8, z + 13, b, ms, 3);
		world.setBlock(x + 6, y + 8, z + 14, b, ms, 3);
		world.setBlock(x + 6, y + 8, z + 15, b, ms, 3);
		world.setBlock(x + 6, y + 8, z + 16, b, ms, 3);
		world.setBlock(x + 6, y + 9, z + 0, b, ms, 3);
		world.setBlock(x + 6, y + 9, z + 1, b, ms, 3);
		world.setBlock(x + 6, y + 9, z + 2, b, ms, 3);
		world.setBlock(x + 6, y + 9, z + 3, b, ms, 3);
		world.setBlock(x + 6, y + 9, z + 4, b, ms, 3);
		world.setBlock(x + 6, y + 9, z + 5, b, mc, 3);
		world.setBlock(x + 6, y + 9, z + 11, b, mc, 3);
		world.setBlock(x + 6, y + 9, z + 12, b, ms, 3);
		world.setBlock(x + 6, y + 9, z + 13, b, ms, 3);
		world.setBlock(x + 6, y + 9, z + 14, b, ms, 3);
		world.setBlock(x + 6, y + 9, z + 15, b, ms, 3);
		world.setBlock(x + 6, y + 9, z + 16, b, ms, 3);
		world.setBlock(x + 6, y + 10, z + 0, b, ms, 3);
		world.setBlock(x + 6, y + 10, z + 1, b, ms, 3);
		world.setBlock(x + 6, y + 10, z + 2, b, ms, 3);
		world.setBlock(x + 6, y + 10, z + 3, b, ms, 3);
		world.setBlock(x + 6, y + 10, z + 4, b, ms, 3);
		world.setBlock(x + 6, y + 10, z + 5, b, mc, 3);
		world.setBlock(x + 6, y + 10, z + 11, b, mc, 3);
		world.setBlock(x + 6, y + 10, z + 12, b, ms, 3);
		world.setBlock(x + 6, y + 10, z + 16, b, ms, 3);
		world.setBlock(x + 6, y + 11, z + 0, b, ms, 3);
		world.setBlock(x + 6, y + 11, z + 1, b, ms, 3);
		world.setBlock(x + 6, y + 11, z + 2, b, ms, 3);
		world.setBlock(x + 6, y + 11, z + 3, b, ms, 3);
		world.setBlock(x + 6, y + 11, z + 4, b, ms, 3);
		world.setBlock(x + 6, y + 11, z + 5, b, mc, 3);
		world.setBlock(x + 6, y + 11, z + 11, b, mc, 3);
		world.setBlock(x + 6, y + 11, z + 12, b, ms, 3);
		world.setBlock(x + 6, y + 11, z + 16, b, ms, 3);
		world.setBlock(x + 6, y + 12, z + 0, b, ms, 3);
		world.setBlock(x + 6, y + 12, z + 1, b, ms, 3);
		world.setBlock(x + 6, y + 12, z + 2, b, ms, 3);
		world.setBlock(x + 6, y + 12, z + 3, b, ms, 3);
		world.setBlock(x + 6, y + 12, z + 4, b, ms, 3);
		world.setBlock(x + 6, y + 12, z + 5, b, mc, 3);
		world.setBlock(x + 6, y + 12, z + 11, b, mc, 3);
		world.setBlock(x + 6, y + 12, z + 12, b, ms, 3);
		world.setBlock(x + 6, y + 12, z + 16, b, ms, 3);
		world.setBlock(x + 6, y + 13, z + 0, b, ms, 3);
		world.setBlock(x + 6, y + 13, z + 1, b, ms, 3);
		world.setBlock(x + 6, y + 13, z + 2, b, ms, 3);
		world.setBlock(x + 6, y + 13, z + 3, b, ms, 3);
		world.setBlock(x + 6, y + 13, z + 4, b, ms, 3);
		world.setBlock(x + 6, y + 13, z + 5, b, mc, 3);
		world.setBlock(x + 6, y + 13, z + 11, b, mc, 3);
		world.setBlock(x + 6, y + 13, z + 12, b, ms, 3);
		world.setBlock(x + 6, y + 13, z + 16, b, ms, 3);
		world.setBlock(x + 6, y + 14, z + 0, b, ms, 3);
		world.setBlock(x + 6, y + 14, z + 1, b, ms, 3);
		world.setBlock(x + 6, y + 14, z + 2, b, ms, 3);
		world.setBlock(x + 6, y + 14, z + 3, b, ms, 3);
		world.setBlock(x + 6, y + 14, z + 4, b, ms, 3);
		world.setBlock(x + 6, y + 14, z + 5, b, mc, 3);
		world.setBlock(x + 6, y + 14, z + 11, b, mc, 3);
		world.setBlock(x + 6, y + 14, z + 12, b, ms, 3);
		world.setBlock(x + 6, y + 14, z + 16, b, ms, 3);
		world.setBlock(x + 6, y + 15, z + 0, b, ms, 3);
		world.setBlock(x + 6, y + 15, z + 1, b, ms, 3);
		world.setBlock(x + 6, y + 15, z + 2, b, ms, 3);
		world.setBlock(x + 6, y + 15, z + 3, b, ms, 3);
		world.setBlock(x + 6, y + 15, z + 4, b, ms, 3);
		world.setBlock(x + 6, y + 15, z + 5, b, mc, 3);
		world.setBlock(x + 6, y + 15, z + 11, b, mc, 3);
		world.setBlock(x + 6, y + 15, z + 12, b, ms, 3);
		world.setBlock(x + 6, y + 15, z + 13, b, ms, 3);
		world.setBlock(x + 6, y + 15, z + 14, b, ms, 3);
		world.setBlock(x + 6, y + 15, z + 15, b, ms, 3);
		world.setBlock(x + 6, y + 15, z + 16, b, ms, 3);
		world.setBlock(x + 7, y + 0, z + 0, b, ms, 3);
		world.setBlock(x + 7, y + 0, z + 1, b, ms, 3);
		world.setBlock(x + 7, y + 0, z + 2, b, ms, 3);
		world.setBlock(x + 7, y + 0, z + 3, b, ms, 3);
		world.setBlock(x + 7, y + 0, z + 4, b, ms, 3);
		world.setBlock(x + 7, y + 0, z + 5, b, mc, 3);
		world.setBlock(x + 7, y + 0, z + 11, b, mc, 3);
		world.setBlock(x + 7, y + 0, z + 12, b, ms, 3);
		world.setBlock(x + 7, y + 0, z + 13, b, ms, 3);
		world.setBlock(x + 7, y + 0, z + 14, b, ms, 3);
		world.setBlock(x + 7, y + 0, z + 15, b, ms, 3);
		world.setBlock(x + 7, y + 0, z + 16, b, ms, 3);

		this.generate2(world, x, y, z);

	}

	public void generate2(World world, int x, int y, int z) {
		Block b = ChromaBlocks.STRUCTSHIELD.getBlockInstance();
		int mc = BlockType.CLOAK.metadata;
		int ms = BlockType.STONE.metadata;
		int ml = BlockType.LIGHT.metadata;

		world.setBlock(x + 7, y + 1, z + 0, b, ms, 3);
		world.setBlock(x + 7, y + 1, z + 1, b, ms, 3);
		world.setBlock(x + 7, y + 1, z + 2, b, ms, 3);
		world.setBlock(x + 7, y + 1, z + 3, b, ms, 3);
		world.setBlock(x + 7, y + 1, z + 4, b, ms, 3);
		world.setBlock(x + 7, y + 1, z + 5, b, mc, 3);
		world.setBlock(x + 7, y + 1, z + 11, b, mc, 3);
		world.setBlock(x + 7, y + 1, z + 12, b, ms, 3);
		world.setBlock(x + 7, y + 1, z + 13, b, ms, 3);
		world.setBlock(x + 7, y + 1, z + 14, b, ms, 3);
		world.setBlock(x + 7, y + 1, z + 15, b, ms, 3);
		world.setBlock(x + 7, y + 1, z + 16, b, ms, 3);
		world.setBlock(x + 7, y + 2, z + 0, b, ms, 3);
		world.setBlock(x + 7, y + 2, z + 1, b, ms, 3);
		world.setBlock(x + 7, y + 2, z + 2, b, ms, 3);
		world.setBlock(x + 7, y + 2, z + 3, b, ms, 3);
		world.setBlock(x + 7, y + 2, z + 4, b, ms, 3);
		world.setBlock(x + 7, y + 2, z + 11, b, mc, 3);
		world.setBlock(x + 7, y + 2, z + 12, b, ms, 3);
		world.setBlock(x + 7, y + 2, z + 13, b, ms, 3);
		world.setBlock(x + 7, y + 2, z + 14, b, ms, 3);
		world.setBlock(x + 7, y + 2, z + 15, b, ms, 3);
		world.setBlock(x + 7, y + 2, z + 16, b, ms, 3);
		world.setBlock(x + 7, y + 3, z + 0, b, ms, 3);
		world.setBlock(x + 7, y + 3, z + 11, b, mc, 3);
		world.setBlock(x + 7, y + 3, z + 12, b, ms, 3);
		world.setBlock(x + 7, y + 3, z + 13, b, ms, 3);
		world.setBlock(x + 7, y + 3, z + 14, b, ms, 3);
		world.setBlock(x + 7, y + 3, z + 15, b, ms, 3);
		world.setBlock(x + 7, y + 3, z + 16, b, ms, 3);
		world.setBlock(x + 7, y + 4, z + 0, b, ms, 3);
		world.setBlock(x + 7, y + 4, z + 11, b, mc, 3);
		world.setBlock(x + 7, y + 4, z + 12, b, ms, 3);
		world.setBlock(x + 7, y + 4, z + 13, b, ms, 3);
		world.setBlock(x + 7, y + 4, z + 14, b, ms, 3);
		world.setBlock(x + 7, y + 4, z + 15, b, ms, 3);
		world.setBlock(x + 7, y + 4, z + 16, b, ms, 3);
		world.setBlock(x + 7, y + 5, z + 0, b, ms, 3);
		world.setBlock(x + 7, y + 5, z + 11, b, mc, 3);
		world.setBlock(x + 7, y + 5, z + 12, b, ms, 3);
		world.setBlock(x + 7, y + 5, z + 13, b, ms, 3);
		world.setBlock(x + 7, y + 5, z + 14, b, ms, 3);
		world.setBlock(x + 7, y + 5, z + 15, b, ms, 3);
		world.setBlock(x + 7, y + 5, z + 16, b, ms, 3);
		world.setBlock(x + 7, y + 6, z + 0, b, ms, 3);
		world.setBlock(x + 7, y + 6, z + 4, b, ms, 3);
		world.setBlock(x + 7, y + 6, z + 5, b, mc, 3);
		world.setBlock(x + 7, y + 6, z + 11, b, mc, 3);
		world.setBlock(x + 7, y + 6, z + 12, b, ms, 3);
		world.setBlock(x + 7, y + 6, z + 13, b, ms, 3);
		world.setBlock(x + 7, y + 6, z + 14, b, ms, 3);
		world.setBlock(x + 7, y + 6, z + 15, b, ms, 3);
		world.setBlock(x + 7, y + 6, z + 16, b, ms, 3);
		world.setBlock(x + 7, y + 7, z + 0, b, ms, 3);
		world.setBlock(x + 7, y + 7, z + 4, b, ms, 3);
		world.setBlock(x + 7, y + 7, z + 5, b, mc, 3);
		world.setBlock(x + 7, y + 7, z + 11, b, mc, 3);
		world.setBlock(x + 7, y + 7, z + 12, b, ms, 3);
		world.setBlock(x + 7, y + 7, z + 13, b, ms, 3);
		world.setBlock(x + 7, y + 7, z + 14, b, ms, 3);
		world.setBlock(x + 7, y + 7, z + 15, b, ms, 3);
		world.setBlock(x + 7, y + 7, z + 16, b, ms, 3);
		world.setBlock(x + 7, y + 8, z + 0, b, ms, 3);
		world.setBlock(x + 7, y + 8, z + 1, b, ms, 3);
		world.setBlock(x + 7, y + 8, z + 2, b, ms, 3);
		world.setBlock(x + 7, y + 8, z + 3, b, ms, 3);
		world.setBlock(x + 7, y + 8, z + 4, b, ms, 3);
		world.setBlock(x + 7, y + 8, z + 5, b, mc, 3);
		world.setBlock(x + 7, y + 8, z + 11, b, mc, 3);
		world.setBlock(x + 7, y + 8, z + 12, b, ms, 3);
		world.setBlock(x + 7, y + 8, z + 13, b, ms, 3);
		world.setBlock(x + 7, y + 8, z + 14, b, ms, 3);
		world.setBlock(x + 7, y + 8, z + 15, b, ms, 3);
		world.setBlock(x + 7, y + 8, z + 16, b, ms, 3);
		world.setBlock(x + 7, y + 9, z + 0, b, ms, 3);
		world.setBlock(x + 7, y + 9, z + 1, b, ms, 3);
		world.setBlock(x + 7, y + 9, z + 2, b, ms, 3);
		world.setBlock(x + 7, y + 9, z + 3, b, ms, 3);
		world.setBlock(x + 7, y + 9, z + 4, b, ms, 3);
		world.setBlock(x + 7, y + 9, z + 5, b, mc, 3);
		world.setBlock(x + 7, y + 9, z + 11, b, mc, 3);
		world.setBlock(x + 7, y + 9, z + 12, b, ms, 3);
		world.setBlock(x + 7, y + 9, z + 13, b, ms, 3);
		world.setBlock(x + 7, y + 9, z + 14, b, ms, 3);
		world.setBlock(x + 7, y + 9, z + 15, b, ms, 3);
		world.setBlock(x + 7, y + 9, z + 16, b, ms, 3);
		world.setBlock(x + 7, y + 10, z + 0, b, ms, 3);
		world.setBlock(x + 7, y + 10, z + 1, b, ms, 3);
		world.setBlock(x + 7, y + 10, z + 2, b, ms, 3);
		world.setBlock(x + 7, y + 10, z + 3, b, ms, 3);
		world.setBlock(x + 7, y + 10, z + 4, b, ms, 3);
		world.setBlock(x + 7, y + 10, z + 5, b, mc, 3);
		world.setBlock(x + 7, y + 10, z + 12, b, ms, 3);
		world.setBlock(x + 7, y + 10, z + 13, b, ms, 3);
		world.setBlock(x + 7, y + 10, z + 14, b, ms, 3);
		world.setBlock(x + 7, y + 10, z + 15, b, ms, 3);
		world.setBlock(x + 7, y + 10, z + 16, b, ms, 3);
		world.setBlock(x + 7, y + 11, z + 0, b, ms, 3);
		world.setBlock(x + 7, y + 11, z + 1, b, ms, 3);
		world.setBlock(x + 7, y + 11, z + 2, b, ms, 3);
		world.setBlock(x + 7, y + 11, z + 3, b, ms, 3);
		world.setBlock(x + 7, y + 11, z + 4, b, ms, 3);
		world.setBlock(x + 7, y + 11, z + 5, b, mc, 3);
		world.setBlock(x + 7, y + 11, z + 16, b, ms, 3);
		world.setBlock(x + 7, y + 12, z + 0, b, ms, 3);
		world.setBlock(x + 7, y + 12, z + 1, b, ms, 3);
		world.setBlock(x + 7, y + 12, z + 2, b, ms, 3);
		world.setBlock(x + 7, y + 12, z + 3, b, ms, 3);
		world.setBlock(x + 7, y + 12, z + 4, b, ms, 3);
		world.setBlock(x + 7, y + 12, z + 5, b, mc, 3);
		world.setBlock(x + 7, y + 12, z + 16, b, ms, 3);
		world.setBlock(x + 7, y + 13, z + 0, b, ms, 3);
		world.setBlock(x + 7, y + 13, z + 1, b, ms, 3);
		world.setBlock(x + 7, y + 13, z + 2, b, ms, 3);
		world.setBlock(x + 7, y + 13, z + 3, b, ms, 3);
		world.setBlock(x + 7, y + 13, z + 4, b, ms, 3);
		world.setBlock(x + 7, y + 13, z + 5, b, mc, 3);
		world.setBlock(x + 7, y + 13, z + 16, b, ms, 3);
		world.setBlock(x + 7, y + 14, z + 0, b, ms, 3);
		world.setBlock(x + 7, y + 14, z + 1, b, ms, 3);
		world.setBlock(x + 7, y + 14, z + 2, b, ms, 3);
		world.setBlock(x + 7, y + 14, z + 3, b, ms, 3);
		world.setBlock(x + 7, y + 14, z + 4, b, ms, 3);
		world.setBlock(x + 7, y + 14, z + 5, b, mc, 3);
		world.setBlock(x + 7, y + 14, z + 11, b, mc, 3);
		world.setBlock(x + 7, y + 14, z + 12, b, ms, 3);
		world.setBlock(x + 7, y + 14, z + 16, b, ms, 3);
		world.setBlock(x + 7, y + 15, z + 0, b, ms, 3);
		world.setBlock(x + 7, y + 15, z + 1, b, ms, 3);
		world.setBlock(x + 7, y + 15, z + 2, b, ms, 3);
		world.setBlock(x + 7, y + 15, z + 3, b, ms, 3);
		world.setBlock(x + 7, y + 15, z + 4, b, ms, 3);
		world.setBlock(x + 7, y + 15, z + 5, b, mc, 3);
		world.setBlock(x + 7, y + 15, z + 11, b, mc, 3);
		world.setBlock(x + 7, y + 15, z + 12, b, ms, 3);
		world.setBlock(x + 7, y + 15, z + 16, b, ms, 3);
		world.setBlock(x + 8, y + 0, z + 0, b, ms, 3);
		world.setBlock(x + 8, y + 0, z + 1, b, ms, 3);
		world.setBlock(x + 8, y + 0, z + 2, b, ms, 3);
		world.setBlock(x + 8, y + 0, z + 3, b, ms, 3);
		world.setBlock(x + 8, y + 0, z + 4, b, ms, 3);
		world.setBlock(x + 8, y + 0, z + 5, b, mc, 3);
		world.setBlock(x + 8, y + 0, z + 11, b, mc, 3);
		world.setBlock(x + 8, y + 0, z + 12, b, ms, 3);
		world.setBlock(x + 8, y + 0, z + 13, b, ms, 3);
		world.setBlock(x + 8, y + 0, z + 14, b, ms, 3);
		world.setBlock(x + 8, y + 0, z + 15, b, ms, 3);
		world.setBlock(x + 8, y + 0, z + 16, b, ms, 3);
		world.setBlock(x + 8, y + 1, z + 0, b, ms, 3);
		world.setBlock(x + 8, y + 1, z + 1, b, ms, 3);
		world.setBlock(x + 8, y + 1, z + 2, b, ms, 3);
		world.setBlock(x + 8, y + 1, z + 3, b, ms, 3);
		world.setBlock(x + 8, y + 1, z + 4, b, ms, 3);
		world.setBlock(x + 8, y + 1, z + 5, b, mc, 3);
		world.setBlock(x + 8, y + 1, z + 11, b, ml, 3);
		world.setBlock(x + 8, y + 1, z + 12, b, ml, 3);
		world.setBlock(x + 8, y + 1, z + 13, b, ms, 3);
		world.setBlock(x + 8, y + 1, z + 14, b, ms, 3);
		world.setBlock(x + 8, y + 1, z + 15, b, ms, 3);
		world.setBlock(x + 8, y + 1, z + 16, b, ms, 3);
		world.setBlock(x + 8, y + 2, z + 0, b, ms, 3);
		world.setBlock(x + 8, y + 2, z + 1, b, ms, 3);
		world.setBlock(x + 8, y + 2, z + 2, b, ms, 3);
		world.setBlock(x + 8, y + 2, z + 3, b, ms, 3);
		world.setBlock(x + 8, y + 2, z + 4, b, ms, 3);
		world.setBlock(x + 8, y + 2, z + 11, b, mc, 3);
		world.setBlock(x + 8, y + 2, z + 12, b, ms, 3);
		world.setBlock(x + 8, y + 2, z + 13, b, ms, 3);
		world.setBlock(x + 8, y + 2, z + 14, b, ms, 3);
		world.setBlock(x + 8, y + 2, z + 15, b, ms, 3);
		world.setBlock(x + 8, y + 2, z + 16, b, ms, 3);
		world.setBlock(x + 8, y + 3, z + 0, b, ms, 3);
		world.setBlock(x + 8, y + 3, z + 11, b, mc, 3);
		world.setBlock(x + 8, y + 3, z + 12, b, ms, 3);
		world.setBlock(x + 8, y + 3, z + 13, b, ms, 3);
		world.setBlock(x + 8, y + 3, z + 14, b, ms, 3);
		world.setBlock(x + 8, y + 3, z + 15, b, ms, 3);
		world.setBlock(x + 8, y + 3, z + 16, b, ms, 3);
		world.setBlock(x + 8, y + 4, z + 0, b, ms, 3);
		world.setBlock(x + 8, y + 4, z + 11, b, mc, 3);
		world.setBlock(x + 8, y + 4, z + 12, b, ms, 3);
		world.setBlock(x + 8, y + 4, z + 13, b, ms, 3);
		world.setBlock(x + 8, y + 4, z + 14, b, ms, 3);
		world.setBlock(x + 8, y + 4, z + 15, b, ms, 3);
		world.setBlock(x + 8, y + 4, z + 16, b, ms, 3);
		world.setBlock(x + 8, y + 5, z + 0, b, ms, 3);
		world.setBlock(x + 8, y + 5, z + 11, b, mc, 3);
		world.setBlock(x + 8, y + 5, z + 12, b, ms, 3);
		world.setBlock(x + 8, y + 5, z + 13, b, ms, 3);
		world.setBlock(x + 8, y + 5, z + 14, b, ms, 3);
		world.setBlock(x + 8, y + 5, z + 15, b, ms, 3);
		world.setBlock(x + 8, y + 5, z + 16, b, ms, 3);
		world.setBlock(x + 8, y + 6, z + 0, b, ms, 3);
		world.setBlock(x + 8, y + 6, z + 4, b, ms, 3);
		world.setBlock(x + 8, y + 6, z + 5, b, mc, 3);
		world.setBlock(x + 8, y + 6, z + 11, b, mc, 3);
		world.setBlock(x + 8, y + 6, z + 12, b, ms, 3);
		world.setBlock(x + 8, y + 6, z + 13, b, ms, 3);
		world.setBlock(x + 8, y + 6, z + 14, b, ms, 3);
		world.setBlock(x + 8, y + 6, z + 15, b, ms, 3);
		world.setBlock(x + 8, y + 6, z + 16, b, ms, 3);
		world.setBlock(x + 8, y + 7, z + 0, b, ms, 3);
		world.setBlock(x + 8, y + 7, z + 4, b, ms, 3);
		world.setBlock(x + 8, y + 7, z + 5, b, mc, 3);
		world.setBlock(x + 8, y + 7, z + 11, b, ml, 3);
		world.setBlock(x + 8, y + 7, z + 12, b, ml, 3);
		world.setBlock(x + 8, y + 7, z + 13, b, ms, 3);
		world.setBlock(x + 8, y + 7, z + 14, b, ms, 3);
		world.setBlock(x + 8, y + 7, z + 15, b, ms, 3);
		world.setBlock(x + 8, y + 7, z + 16, b, ms, 3);
		world.setBlock(x + 8, y + 8, z + 0, b, ms, 3);
		world.setBlock(x + 8, y + 8, z + 1, b, ms, 3);
		world.setBlock(x + 8, y + 8, z + 2, b, ms, 3);
		world.setBlock(x + 8, y + 8, z + 3, b, ms, 3);
		world.setBlock(x + 8, y + 8, z + 4, b, ms, 3);
		world.setBlock(x + 8, y + 8, z + 5, b, mc, 3);
		world.setBlock(x + 8, y + 8, z + 11, b, mc, 3);
		world.setBlock(x + 8, y + 8, z + 12, b, ms, 3);
		world.setBlock(x + 8, y + 8, z + 13, b, ms, 3);
		world.setBlock(x + 8, y + 8, z + 14, b, ms, 3);
		world.setBlock(x + 8, y + 8, z + 15, b, ms, 3);
		world.setBlock(x + 8, y + 8, z + 16, b, ms, 3);
		world.setBlock(x + 8, y + 9, z + 0, b, ms, 3);
		world.setBlock(x + 8, y + 9, z + 1, b, ms, 3);
		world.setBlock(x + 8, y + 9, z + 2, b, ms, 3);
		world.setBlock(x + 8, y + 9, z + 3, b, ms, 3);
		world.setBlock(x + 8, y + 9, z + 4, b, ml, 3);
		world.setBlock(x + 8, y + 9, z + 5, b, ml, 3);
		world.setBlock(x + 8, y + 9, z + 11, b, mc, 3);
		world.setBlock(x + 8, y + 9, z + 12, b, ms, 3);
		world.setBlock(x + 8, y + 9, z + 13, b, ms, 3);
		world.setBlock(x + 8, y + 9, z + 14, b, ms, 3);
		world.setBlock(x + 8, y + 9, z + 15, b, ms, 3);
		world.setBlock(x + 8, y + 9, z + 16, b, ms, 3);
		world.setBlock(x + 8, y + 10, z + 0, b, ms, 3);
		world.setBlock(x + 8, y + 10, z + 1, b, ms, 3);
		world.setBlock(x + 8, y + 10, z + 2, b, ms, 3);
		world.setBlock(x + 8, y + 10, z + 3, b, ms, 3);
		world.setBlock(x + 8, y + 10, z + 4, b, ms, 3);
		world.setBlock(x + 8, y + 10, z + 5, b, mc, 3);
		world.setBlock(x + 8, y + 10, z + 12, b, ms, 3);
		world.setBlock(x + 8, y + 10, z + 13, b, ms, 3);
		world.setBlock(x + 8, y + 10, z + 14, b, ms, 3);
		world.setBlock(x + 8, y + 10, z + 15, b, ms, 3);
		world.setBlock(x + 8, y + 10, z + 16, b, ms, 3);
		world.setBlock(x + 8, y + 11, z + 0, b, ms, 3);
		world.setBlock(x + 8, y + 11, z + 1, b, ms, 3);
		world.setBlock(x + 8, y + 11, z + 2, b, ms, 3);
		world.setBlock(x + 8, y + 11, z + 3, b, ms, 3);
		world.setBlock(x + 8, y + 11, z + 4, b, ms, 3);
		world.setBlock(x + 8, y + 11, z + 5, b, mc, 3);
		world.setBlock(x + 8, y + 11, z + 16, b, ms, 3);
		world.setBlock(x + 8, y + 12, z + 0, b, ms, 3);
		world.setBlock(x + 8, y + 12, z + 1, b, ms, 3);
		world.setBlock(x + 8, y + 12, z + 2, b, ms, 3);
		world.setBlock(x + 8, y + 12, z + 3, b, ms, 3);
		world.setBlock(x + 8, y + 12, z + 4, b, ms, 3);
		world.setBlock(x + 8, y + 12, z + 5, b, mc, 3);
		world.setBlock(x + 8, y + 12, z + 16, b, ms, 3);
		world.setBlock(x + 8, y + 13, z + 0, b, ms, 3);
		world.setBlock(x + 8, y + 13, z + 1, b, ms, 3);
		world.setBlock(x + 8, y + 13, z + 2, b, ms, 3);
		world.setBlock(x + 8, y + 13, z + 3, b, ms, 3);
		world.setBlock(x + 8, y + 13, z + 4, b, ms, 3);
		world.setBlock(x + 8, y + 13, z + 5, b, mc, 3);
		world.setBlock(x + 8, y + 13, z + 16, b, ms, 3);
		world.setBlock(x + 8, y + 14, z + 0, b, ms, 3);
		world.setBlock(x + 8, y + 14, z + 1, b, ms, 3);
		world.setBlock(x + 8, y + 14, z + 2, b, ms, 3);
		world.setBlock(x + 8, y + 14, z + 3, b, ms, 3);
		world.setBlock(x + 8, y + 14, z + 4, b, ms, 3);
		world.setBlock(x + 8, y + 14, z + 5, b, mc, 3);
		world.setBlock(x + 8, y + 14, z + 11, b, mc, 3);
		world.setBlock(x + 8, y + 14, z + 12, b, ms, 3);
		world.setBlock(x + 8, y + 14, z + 16, b, ms, 3);
		world.setBlock(x + 8, y + 15, z + 0, b, ms, 3);
		world.setBlock(x + 8, y + 15, z + 1, b, ms, 3);
		world.setBlock(x + 8, y + 15, z + 2, b, ms, 3);
		world.setBlock(x + 8, y + 15, z + 3, b, ms, 3);
		world.setBlock(x + 8, y + 15, z + 4, b, ml, 3);
		world.setBlock(x + 8, y + 15, z + 5, b, ml, 3);
		world.setBlock(x + 8, y + 15, z + 11, b, mc, 3);
		world.setBlock(x + 8, y + 15, z + 12, b, ms, 3);
		world.setBlock(x + 8, y + 15, z + 16, b, ms, 3);
		world.setBlock(x + 9, y + 0, z + 0, b, ms, 3);
		world.setBlock(x + 9, y + 0, z + 1, b, ms, 3);
		world.setBlock(x + 9, y + 0, z + 2, b, ms, 3);
		world.setBlock(x + 9, y + 0, z + 3, b, ms, 3);
		world.setBlock(x + 9, y + 0, z + 4, b, ms, 3);
		world.setBlock(x + 9, y + 0, z + 5, b, mc, 3);
		world.setBlock(x + 9, y + 0, z + 11, b, mc, 3);
		world.setBlock(x + 9, y + 0, z + 12, b, ms, 3);
		world.setBlock(x + 9, y + 0, z + 13, b, ms, 3);
		world.setBlock(x + 9, y + 0, z + 14, b, ms, 3);
		world.setBlock(x + 9, y + 0, z + 15, b, ms, 3);
		world.setBlock(x + 9, y + 0, z + 16, b, ms, 3);
		world.setBlock(x + 9, y + 1, z + 0, b, ms, 3);
		world.setBlock(x + 9, y + 1, z + 1, b, ms, 3);
		world.setBlock(x + 9, y + 1, z + 2, b, ms, 3);
		world.setBlock(x + 9, y + 1, z + 3, b, ms, 3);
		world.setBlock(x + 9, y + 1, z + 4, b, ms, 3);
		world.setBlock(x + 9, y + 1, z + 5, b, mc, 3);
		world.setBlock(x + 9, y + 1, z + 11, b, mc, 3);
		world.setBlock(x + 9, y + 1, z + 12, b, ms, 3);
		world.setBlock(x + 9, y + 1, z + 13, b, ms, 3);
		world.setBlock(x + 9, y + 1, z + 14, b, ms, 3);
		world.setBlock(x + 9, y + 1, z + 15, b, ms, 3);
		world.setBlock(x + 9, y + 1, z + 16, b, ms, 3);
		world.setBlock(x + 9, y + 2, z + 0, b, ms, 3);
		world.setBlock(x + 9, y + 2, z + 1, b, ms, 3);
		world.setBlock(x + 9, y + 2, z + 2, b, ms, 3);
		world.setBlock(x + 9, y + 2, z + 3, b, ms, 3);
		world.setBlock(x + 9, y + 2, z + 4, b, ms, 3);
		world.setBlock(x + 9, y + 2, z + 11, b, mc, 3);
		world.setBlock(x + 9, y + 2, z + 12, b, ms, 3);
		world.setBlock(x + 9, y + 2, z + 13, b, ms, 3);
		world.setBlock(x + 9, y + 2, z + 14, b, ms, 3);
		world.setBlock(x + 9, y + 2, z + 15, b, ms, 3);
		world.setBlock(x + 9, y + 2, z + 16, b, ms, 3);
		world.setBlock(x + 9, y + 3, z + 0, b, ms, 3);
		world.setBlock(x + 9, y + 3, z + 11, b, mc, 3);
		world.setBlock(x + 9, y + 3, z + 12, b, ms, 3);
		world.setBlock(x + 9, y + 3, z + 13, b, ms, 3);
		world.setBlock(x + 9, y + 3, z + 14, b, ms, 3);
		world.setBlock(x + 9, y + 3, z + 15, b, ms, 3);
		world.setBlock(x + 9, y + 3, z + 16, b, ms, 3);
		world.setBlock(x + 9, y + 4, z + 0, b, ms, 3);
		world.setBlock(x + 9, y + 4, z + 11, b, mc, 3);
		world.setBlock(x + 9, y + 4, z + 12, b, ms, 3);
		world.setBlock(x + 9, y + 4, z + 13, b, ms, 3);
		world.setBlock(x + 9, y + 4, z + 14, b, ms, 3);
		world.setBlock(x + 9, y + 4, z + 15, b, ms, 3);
		world.setBlock(x + 9, y + 4, z + 16, b, ms, 3);
		world.setBlock(x + 9, y + 5, z + 0, b, ms, 3);
		world.setBlock(x + 9, y + 5, z + 11, b, mc, 3);
		world.setBlock(x + 9, y + 5, z + 12, b, ms, 3);
		world.setBlock(x + 9, y + 5, z + 13, b, ms, 3);
		world.setBlock(x + 9, y + 5, z + 14, b, ms, 3);
		world.setBlock(x + 9, y + 5, z + 15, b, ms, 3);
		world.setBlock(x + 9, y + 5, z + 16, b, ms, 3);
		world.setBlock(x + 9, y + 6, z + 0, b, ms, 3);
		world.setBlock(x + 9, y + 6, z + 4, b, ms, 3);
		world.setBlock(x + 9, y + 6, z + 5, b, mc, 3);
		world.setBlock(x + 9, y + 6, z + 11, b, mc, 3);
		world.setBlock(x + 9, y + 6, z + 12, b, ms, 3);
		world.setBlock(x + 9, y + 6, z + 13, b, ms, 3);
		world.setBlock(x + 9, y + 6, z + 14, b, ms, 3);
		world.setBlock(x + 9, y + 6, z + 15, b, ms, 3);
		world.setBlock(x + 9, y + 6, z + 16, b, ms, 3);
		world.setBlock(x + 9, y + 7, z + 0, b, ms, 3);
		world.setBlock(x + 9, y + 7, z + 4, b, ms, 3);
		world.setBlock(x + 9, y + 7, z + 5, b, mc, 3);
		world.setBlock(x + 9, y + 7, z + 11, b, mc, 3);
		world.setBlock(x + 9, y + 7, z + 12, b, ms, 3);
		world.setBlock(x + 9, y + 7, z + 13, b, ms, 3);
		world.setBlock(x + 9, y + 7, z + 14, b, ms, 3);
		world.setBlock(x + 9, y + 7, z + 15, b, ms, 3);
		world.setBlock(x + 9, y + 7, z + 16, b, ms, 3);
		world.setBlock(x + 9, y + 8, z + 0, b, ms, 3);
		world.setBlock(x + 9, y + 8, z + 1, b, ms, 3);
		world.setBlock(x + 9, y + 8, z + 2, b, ms, 3);
		world.setBlock(x + 9, y + 8, z + 3, b, ms, 3);
		world.setBlock(x + 9, y + 8, z + 4, b, ms, 3);
		world.setBlock(x + 9, y + 8, z + 5, b, mc, 3);
		world.setBlock(x + 9, y + 8, z + 11, b, mc, 3);
		world.setBlock(x + 9, y + 8, z + 12, b, ms, 3);
		world.setBlock(x + 9, y + 8, z + 13, b, ms, 3);
		world.setBlock(x + 9, y + 8, z + 14, b, ms, 3);
		world.setBlock(x + 9, y + 8, z + 15, b, ms, 3);
		world.setBlock(x + 9, y + 8, z + 16, b, ms, 3);
		world.setBlock(x + 9, y + 9, z + 0, b, ms, 3);
		world.setBlock(x + 9, y + 9, z + 1, b, ms, 3);
		world.setBlock(x + 9, y + 9, z + 2, b, ms, 3);
		world.setBlock(x + 9, y + 9, z + 3, b, ms, 3);
		world.setBlock(x + 9, y + 9, z + 4, b, ms, 3);
		world.setBlock(x + 9, y + 9, z + 5, b, mc, 3);
		world.setBlock(x + 9, y + 9, z + 11, b, mc, 3);
		world.setBlock(x + 9, y + 9, z + 12, b, ms, 3);
		world.setBlock(x + 9, y + 9, z + 13, b, ms, 3);
		world.setBlock(x + 9, y + 9, z + 14, b, ms, 3);
		world.setBlock(x + 9, y + 9, z + 15, b, ms, 3);
		world.setBlock(x + 9, y + 9, z + 16, b, ms, 3);
		world.setBlock(x + 9, y + 10, z + 0, b, ms, 3);
		world.setBlock(x + 9, y + 10, z + 1, b, ms, 3);
		world.setBlock(x + 9, y + 10, z + 2, b, ms, 3);
		world.setBlock(x + 9, y + 10, z + 3, b, ms, 3);
		world.setBlock(x + 9, y + 10, z + 4, b, ms, 3);
		world.setBlock(x + 9, y + 10, z + 5, b, mc, 3);
		world.setBlock(x + 9, y + 10, z + 12, b, ms, 3);
		world.setBlock(x + 9, y + 10, z + 13, b, ms, 3);
		world.setBlock(x + 9, y + 10, z + 14, b, ms, 3);
		world.setBlock(x + 9, y + 10, z + 15, b, ms, 3);
		world.setBlock(x + 9, y + 10, z + 16, b, ms, 3);
		world.setBlock(x + 9, y + 11, z + 0, b, ms, 3);
		world.setBlock(x + 9, y + 11, z + 1, b, ms, 3);
		world.setBlock(x + 9, y + 11, z + 2, b, ms, 3);
		world.setBlock(x + 9, y + 11, z + 3, b, ms, 3);
		world.setBlock(x + 9, y + 11, z + 4, b, ms, 3);
		world.setBlock(x + 9, y + 11, z + 5, b, mc, 3);
		world.setBlock(x + 9, y + 11, z + 16, b, ms, 3);
		world.setBlock(x + 9, y + 12, z + 0, b, ms, 3);
		world.setBlock(x + 9, y + 12, z + 1, b, ms, 3);
		world.setBlock(x + 9, y + 12, z + 2, b, ms, 3);
		world.setBlock(x + 9, y + 12, z + 3, b, ms, 3);
		world.setBlock(x + 9, y + 12, z + 4, b, ms, 3);
		world.setBlock(x + 9, y + 12, z + 5, b, mc, 3);
		world.setBlock(x + 9, y + 12, z + 16, b, ms, 3);
		world.setBlock(x + 9, y + 13, z + 0, b, ms, 3);
		world.setBlock(x + 9, y + 13, z + 1, b, ms, 3);
		world.setBlock(x + 9, y + 13, z + 2, b, ms, 3);
		world.setBlock(x + 9, y + 13, z + 3, b, ms, 3);
		world.setBlock(x + 9, y + 13, z + 4, b, ms, 3);
		world.setBlock(x + 9, y + 13, z + 5, b, mc, 3);
		world.setBlock(x + 9, y + 13, z + 16, b, ms, 3);
		world.setBlock(x + 9, y + 14, z + 0, b, ms, 3);
		world.setBlock(x + 9, y + 14, z + 1, b, ms, 3);
		world.setBlock(x + 9, y + 14, z + 2, b, ms, 3);
		world.setBlock(x + 9, y + 14, z + 3, b, ms, 3);
		world.setBlock(x + 9, y + 14, z + 4, b, ms, 3);
		world.setBlock(x + 9, y + 14, z + 5, b, mc, 3);
		world.setBlock(x + 9, y + 14, z + 11, b, mc, 3);
		world.setBlock(x + 9, y + 14, z + 12, b, ms, 3);
		world.setBlock(x + 9, y + 14, z + 16, b, ms, 3);
		world.setBlock(x + 9, y + 15, z + 0, b, ms, 3);
		world.setBlock(x + 9, y + 15, z + 1, b, ms, 3);
		world.setBlock(x + 9, y + 15, z + 2, b, ms, 3);
		world.setBlock(x + 9, y + 15, z + 3, b, ms, 3);
		world.setBlock(x + 9, y + 15, z + 4, b, ms, 3);
		world.setBlock(x + 9, y + 15, z + 5, b, mc, 3);
		world.setBlock(x + 9, y + 15, z + 11, b, mc, 3);
		world.setBlock(x + 9, y + 15, z + 12, b, ms, 3);
		world.setBlock(x + 9, y + 15, z + 16, b, ms, 3);
		world.setBlock(x + 10, y + 0, z + 0, b, ms, 3);
		world.setBlock(x + 10, y + 0, z + 1, b, ms, 3);
		world.setBlock(x + 10, y + 0, z + 2, b, ms, 3);
		world.setBlock(x + 10, y + 0, z + 3, b, ms, 3);
		world.setBlock(x + 10, y + 0, z + 4, b, ms, 3);
		world.setBlock(x + 10, y + 0, z + 5, b, mc, 3);
		world.setBlock(x + 10, y + 0, z + 11, b, mc, 3);
		world.setBlock(x + 10, y + 0, z + 12, b, ms, 3);
		world.setBlock(x + 10, y + 0, z + 13, b, ms, 3);
		world.setBlock(x + 10, y + 0, z + 14, b, ms, 3);
		world.setBlock(x + 10, y + 0, z + 15, b, ms, 3);
		world.setBlock(x + 10, y + 0, z + 16, b, ms, 3);
		world.setBlock(x + 10, y + 1, z + 0, b, ms, 3);
		world.setBlock(x + 10, y + 1, z + 1, b, ms, 3);
		world.setBlock(x + 10, y + 1, z + 2, b, ms, 3);
		world.setBlock(x + 10, y + 1, z + 3, b, ms, 3);
		world.setBlock(x + 10, y + 1, z + 4, b, ms, 3);
		world.setBlock(x + 10, y + 1, z + 5, b, mc, 3);
		world.setBlock(x + 10, y + 1, z + 11, b, mc, 3);
		world.setBlock(x + 10, y + 1, z + 12, b, ms, 3);
		world.setBlock(x + 10, y + 1, z + 13, b, ms, 3);
		world.setBlock(x + 10, y + 1, z + 14, b, ms, 3);
		world.setBlock(x + 10, y + 1, z + 15, b, ms, 3);
		world.setBlock(x + 10, y + 1, z + 16, b, ms, 3);
		world.setBlock(x + 10, y + 2, z + 0, b, ms, 3);
		world.setBlock(x + 10, y + 2, z + 4, b, ms, 3);
		world.setBlock(x + 10, y + 2, z + 5, b, mc, 3);
		world.setBlock(x + 10, y + 2, z + 11, b, mc, 3);
		world.setBlock(x + 10, y + 2, z + 12, b, ms, 3);
		world.setBlock(x + 10, y + 2, z + 13, b, ms, 3);
		world.setBlock(x + 10, y + 2, z + 14, b, ms, 3);
		world.setBlock(x + 10, y + 2, z + 15, b, ms, 3);
		world.setBlock(x + 10, y + 2, z + 16, b, ms, 3);
		world.setBlock(x + 10, y + 3, z + 0, b, ms, 3);
		world.setBlock(x + 10, y + 3, z + 4, b, ms, 3);
		world.setBlock(x + 10, y + 3, z + 5, b, mc, 3);
		world.setBlock(x + 10, y + 3, z + 11, b, mc, 3);
		world.setBlock(x + 10, y + 3, z + 12, b, ms, 3);
		world.setBlock(x + 10, y + 3, z + 13, b, ms, 3);
		world.setBlock(x + 10, y + 3, z + 14, b, ms, 3);
		world.setBlock(x + 10, y + 3, z + 15, b, ms, 3);
