/*******************************************************************************
 * @author Reika Kalseki
 * 
 * Copyright 2015
 * 
 * All rights reserved.
 * Distribution of the software in any form is only allowed with
 * explicit, prior permission from the owner.
 ******************************************************************************/
package Reika.ChromatiCraft.World.Dimension.Structure.Laser;

import net.minecraft.block.Block;
import net.minecraft.init.Blocks;
import net.minecraftforge.common.util.ForgeDirection;
import Reika.ChromatiCraft.Base.StructurePiece;
import Reika.ChromatiCraft.Block.Worldgen.BlockStructureShield.BlockType;
import Reika.ChromatiCraft.Registry.ChromaBlocks;
import Reika.ChromatiCraft.World.Dimension.Structure.LaserPuzzleGenerator;
import Reika.DragonAPI.Instantiable.Worldgen.ChunkSplicedGenerationCache;
import Reika.DragonAPI.Instantiable.Worldgen.OriginBlockCache;


public class LaserLoot extends StructurePiece {

	public LaserLoot(LaserPuzzleGenerator s) {
		super(s);
	}

	@Override
	public void generate(ChunkSplicedGenerationCache c, int x, int y, int z) {

		Block b = ChromaBlocks.STRUCTSHIELD.getBlockInstance();
		int ms = BlockType.STONE.metadata;
		int mg = BlockType.GLASS.metadata;
		int ml = BlockType.LIGHT.metadata;
		int mc = BlockType.CRACK.metadata;

		OriginBlockCache world = new OriginBlockCache(x, y, z, ForgeDirection.WEST);
		int i = x-13;
		int j = y+2;
		int k = z-3;

		parent.placeCore(i - 3+26, j + 2, k + 3);

		world.setBlock(i + 6, j + 1, k + 2, b, ms);
		world.setBlock(i + 6, j + 1, k + 3, b, ms);
		world.setBlock(i + 6, j + 1, k + 4, b, ms);
		world.setBlock(i + 6, j + 2, k + 2, b, ms);
		world.setBlock(i + 6, j + 2, k + 3, b, ms);
		world.setBlock(i + 6, j + 2, k + 4, b, ms);
		world.setBlock(i + 6, j + 0, k + 2, b, ms);
		world.setBlock(i + 6, j + 0, k + 3, b, ms);
		world.setBlock(i + 6, j + 0, k + 4, b, ms);

		parent.addBreakable(i + 6, j + 1, k + 2);
		parent.addBreakable(i + 6, j + 1, k + 3);
		parent.addBreakable(i + 6, j + 1, k + 4);
		parent.addBreakable(i + 6, j + 2, k + 2);
		parent.addBreakable(i + 6, j + 2, k + 3);
		parent.addBreakable(i + 6, j + 2, k + 4);
		parent.addBreakable(i + 6, j + 0, k + 2);
		parent.addBreakable(i + 6, j + 0, k + 3);
		parent.addBreakable(i + 6, j + 0, k + 4);

		world.setBlock(i + 0, j + 0, k + 0, b, ms);
		world.setBlock(i + 0, j + 0, k + 1, b, ms);
		world.setBlock(i + 0, j + 0, k + 2, b, ms);
		world.setBlock(i + 0, j + 0, k + 3, b, ms);
		world.setBlock(i + 0, j + 0, k + 4, b, ms);
		world.setBlock(i + 0, j + 0, k + 5, b, ms);
		world.setBlock(i + 0, j + 0, k + 6, b, ms);
		world.setBlock(i + 0, j + 1, k + 0, b, ms);
		world.setBlock(i + 0, j + 1, k + 1, b, ms);
		world.setBlock(i + 0, j + 1, k + 2, b, ms);
		world.setBlock(i + 0, j + 1, k + 3, b, ms);
		world.setBlock(i + 0, j + 1, k + 4, b, ms);
		world.setBlock(i + 0, j + 1, k + 5, b, ms);
		world.setBlock(i + 0, j + 1, k + 6, b, ms);
		world.setBlock(i + 0, j + 2, k + 0, b, ms);
		world.setBlock(i + 0, j + 2, k + 1, b, ms);
		world.setBlock(i + 0, j + 2, k + 2, b, ms);
		world.setBlock(i + 0, j + 2, k + 3, b, ms);
		world.setBlock(i + 0, j + 2, k + 4, b, ms);
		world.setBlock(i + 0, j + 2, k + 5, b, ms);
		world.setBlock(i + 0, j + 2, k + 6, b, ms);
		world.setBlock(i + 0, j + 3, k + 0, b, ms);
		world.setBlock(i + 0, j + 3, k + 1, b, ms);
		world.setBlock(i + 0, j + 3, k + 2, b, ms);
		world.setBlock(i + 0, j + 3, k + 3, b, ms);
		world.setBlock(i + 0, j + 3, k + 4, b, ms);
		world.setBlock(i + 0, j + 3, k + 5, b, ms);
		world.setBlock(i + 0, j + 3, k + 6, b, ms);
		world.setBlock(i + 0, j + 4, k + 0, b, ms);
		world.setBlock(i + 0, j + 4, k + 1, b, ms);
		world.setBlock(i + 0, j + 4, k + 2, b, ms);
		world.setBlock(i + 0, j + 4, k + 3, b, ms);
		world.setBlock(i + 0, j + 4, k + 4, b, ms);
		world.setBlock(i + 0, j + 4, k + 5, b, ms);
		world.setBlock(i + 0, j + 4, k + 6, b, ms);
		world.setBlock(i + 0, j + 5, k + 0, b, ms);
		world.setBlock(i + 0, j + 5, k + 1, b, ms);
		world.setBlock(i + 0, j + 5, k + 2, b, ms);
		world.setBlock(i + 0, j + 5, k + 3, b, ms);
		world.setBlock(i + 0, j + 5, k + 4, b, ms);
		world.setBlock(i + 0, j + 5, k + 5, b, ms);
		world.setBlock(i + 0, j + 5, k + 6, b, ms);
		world.setBlock(i + 0, j + 6, k + 0, b, ms);
		world.setBlock(i + 0, j + 6, k + 1, b, ms);
		world.setBlock(i + 0, j + 6, k + 2, b, ms);
		world.setBlock(i + 0, j + 6, k + 3, b, ms);
		world.setBlock(i + 0, j + 6, k + 4, b, ms);
		world.setBlock(i + 0, j + 6, k + 5, b, ms);
		world.setBlock(i + 0, j + 6, k + 6, b, ms);
		world.setBlock(i + 0, j + 7, k + 0, b, ms);
		world.setBlock(i + 0, j + 7, k + 1, b, ms);
		world.setBlock(i + 0, j + 7, k + 2, b, ms);
		world.setBlock(i + 0, j + 7, k + 3, b, ms);
		world.setBlock(i + 0, j + 7, k + 4, b, ms);
		world.setBlock(i + 0, j + 7, k + 5, b, ms);
		world.setBlock(i + 0, j + 7, k + 6, b, ms);
		world.setBlock(i + 0, j + 8, k + 0, b, ms);
		world.setBlock(i + 0, j + 8, k + 1, b, ms);
		world.setBlock(i + 0, j + 8, k + 2, b, ms);
		world.setBlock(i + 0, j + 8, k + 3, b, ms);
		world.setBlock(i + 0, j + 8, k + 4, b, ms);
		world.setBlock(i + 0, j + 8, k + 5, b, ms);
		world.setBlock(i + 0, j + 8, k + 6, b, ms);
		world.setBlock(i + 1, j + 0, k + 0, b, ms);
		world.setBlock(i + 1, j + 0, k + 1, b, ms);
		world.setBlock(i + 1, j + 0, k + 2, b, ms);
		world.setBlock(i + 1, j + 0, k + 3, b, ms);
		world.setBlock(i + 1, j + 0, k + 4, b, ms);
		world.setBlock(i + 1, j + 0, k + 5, b, ms);
		world.setBlock(i + 1, j + 0, k + 6, b, ms);
		world.setBlock(i + 1, j + 1, k + 0, b, ms);
		world.setBlock(i + 1, j + 1, k + 1, b, ms);
		world.setBlock(i + 1, j + 1, k + 5, b, ms);
		world.setBlock(i + 1, j + 1, k + 6, b, ms);
		world.setBlock(i + 1, j + 2, k + 0, b, ms);
		world.setBlock(i + 1, j + 2, k + 1, b, ms);
		world.setBlock(i + 1, j + 2, k + 5, b, ms);
		world.setBlock(i + 1, j + 2, k + 6, b, ms);
		world.setBlock(i + 1, j + 3, k + 0, b, ms);
		world.setBlock(i + 1, j + 3, k + 1, b, ms);
		world.setBlock(i + 1, j + 3, k + 5, b, ms);
		world.setBlock(i + 1, j + 3, k + 6, b, ms);
		world.setBlock(i + 1, j + 4, k + 0, b, ms);
		world.setBlock(i + 1, j + 4, k + 1, b, ms);
		world.setBlock(i + 1, j + 4, k + 2, b, mg);
		world.setBlock(i + 1, j + 4, k + 3, b, mg);
		world.setBlock(i + 1, j + 4, k + 4, b, mg);
		world.setBlock(i + 1, j + 4, k + 5, b, ms);
		world.setBlock(i + 1, j + 4, k + 6, b, ms);
		world.setBlock(i + 1, j + 5, k + 0, b, ms);
		world.setBlock(i + 1, j + 5, k + 6, b, ms);
		world.setBlock(i + 1, j + 6, k + 0, b, ms);
		world.setBlock(i + 1, j + 6, k + 6, b, ms);
		world.setBlock(i + 1, j + 7, k + 0, b, ms);
		world.setBlock(i + 1, j + 7, k + 1, b, ms);
		world.setBlock(i + 1, j + 7, k + 2, b, ms);
		world.setBlock(i + 1, j + 7, k + 3, b, ms);
		world.setBlock(i + 1, j + 7, k + 4, b, ms);
		world.setBlock(i + 1, j + 7, k + 5, b, ms);
		world.setBlock(i + 1, j + 7, k + 6, b, ms);
		world.setBlock(i + 1, j + 8, k + 0, b, ms);
		world.setBlock(i + 1, j + 8, k + 1, b, ms);
		world.setBlock(i + 1, j + 8, k + 2, b, ms);
		world.setBlock(i + 1, j + 8, k + 3, b, ms);
		world.setBlock(i + 1, j + 8, k + 4, b, ms);
		world.setBlock(i + 1, j + 8, k + 5, b, ms);
		world.setBlock(i + 1, j + 8, k + 6, b, ms);
		world.setBlock(i + 2, j + 0, k + 0, b, ms);
		world.setBlock(i + 2, j + 0, k + 1, b, ms);
		world.setBlock(i + 2, j + 0, k + 2, b, ms);
		world.setBlock(i + 2, j + 0, k + 3, b, ms);
		world.setBlock(i + 2, j + 0, k + 4, b, ms);
		world.setBlock(i + 2, j + 0, k + 5, b, ms);
		world.setBlock(i + 2, j + 0, k + 6, b, ms);
		world.setBlock(i + 2, j + 1, k + 0, b, ms);
		world.setBlock(i + 2, j + 1, k + 6, b, ms);
		world.setBlock(i + 2, j + 2, k + 0, b, ms);
		world.setBlock(i + 2, j + 2, k + 6, b, ms);
		world.setBlock(i + 2, j + 3, k + 0, b, ms);
		world.setBlock(i + 2, j + 3, k + 6, b, ms);
		world.setBlock(i + 2, j + 4, k + 0, b, ms);
		world.setBlock(i + 2, j + 4, k + 1, b, mg);
		world.setBlock(i + 2, j + 4, k + 2, b, ms);
		world.setBlock(i + 2, j + 4, k + 3, b, ms);
		world.setBlock(i + 2, j + 4, k + 4, b, ms);
		world.setBlock(i + 2, j + 4, k + 5, b, mg);
		world.setBlock(i + 2, j + 4, k + 6, b, ms);
		world.setBlock(i + 2, j + 5, k + 0, b, ms);
		world.setBlock(i + 2, j + 5, k + 6, b, ms);
		world.setBlock(i + 2, j + 6, k + 0, b, ml);
		world.setBlock(i + 2, j + 6, k + 6, b, ml);
		world.setBlock(i + 2, j + 7, k + 0, b, ms);
		world.setBlock(i + 2, j + 7, k + 6, b, ms);
		world.setBlock(i + 2, j + 8, k + 0, b, ms);
		world.setBlock(i + 2, j + 8, k + 1, b, ms);
		world.setBlock(i + 2, j + 8, k + 2, b, ms);
		world.setBlock(i + 2, j + 8, k + 3, b, ms);
		world.setBlock(i + 2, j + 8, k + 4, b, ms);
		world.setBlock(i + 2, j + 8, k + 5, b, ms);
		world.setBlock(i + 2, j + 8, k + 6, b, ms);
		world.setBlock(i + 3, j + 0, k + 0, b, ms);
		world.setBlock(i + 3, j + 0, k + 1, b, ms);
		world.setBlock(i + 3, j + 0, k + 2, b, ms);
		world.setBlock(i + 3, j + 0, k + 3, b, ms);
		world.setBlock(i + 3, j + 0, k + 4, b, ms);
		world.setBlock(i + 3, j + 0, k + 5, b, ms);
		world.setBlock(i + 3, j + 0, k + 6, b, ms);
		world.setBlock(i + 3, j + 1, k + 0, b, ms);
		world.setBlock(i + 3, j + 1, k + 6, b, ms);
		world.setBlock(i + 3, j + 2, k + 0, b, ms);

		world.setBlock(i + 3, j + 2, k + 6, b, ms);
		world.setBlock(i + 3, j + 3, k + 0, b, ms);
		world.setBlock(i + 3, j + 3, k + 6, b, ms);
		world.setBlock(i + 3, j + 4, k + 0, b, ms);
		world.setBlock(i + 3, j + 4, k + 1, b, mg);
		world.setBlock(i + 3, j + 4, k + 2, b, ms);
		world.setBlock(i + 3, j + 4, k + 3, b, mc);
		world.setBlock(i + 3, j + 4, k + 4, b, ms);
		world.setBlock(i + 3, j + 4, k + 5, b, mg);
		world.setBlock(i + 3, j + 4, k + 6, b, ms);
		world.setBlock(i + 3, j + 5, k + 0, b, ms);
		world.setBlock(i + 3, j + 5, k + 6, b, ms);
		world.setBlock(i + 3, j + 6, k + 0, b, ms);
		world.setBlock(i + 3, j + 6, k + 6, b, ms);
		world.setBlock(i + 3, j + 7, k + 0, b, ms);
		world.setBlock(i + 3, j + 7, k + 6, b, ms);
		world.setBlock(i + 3, j + 8, k + 0, b, ms);
		world.setBlock(i + 3, j + 8, k + 1, b, ms);
		world.setBlock(i + 3, j + 8, k + 2, b, ms);
		world.setBlock(i + 3, j + 8, k + 3, b, ms);
		world.setBlock(i + 3, j + 8, k + 4, b, ms);
		world.setBlock(i + 3, j + 8, k + 5, b, ms);
		world.setBlock(i + 3, j + 8, k + 6, b, ms);
		world.setBlock(i + 4, j + 0, k + 0, b, ms);
		world.setBlock(i + 4, j + 0, k + 1, b, ms);
		world.setBlock(i + 4, j + 0, k + 2, b, ms);
		world.setBlock(i + 4, j + 0, k + 3, b, ms);
		world.setBlock(i + 4, j + 0, k + 4, b, ms);
		world.setBlock(i + 4, j + 0, k + 5, b, ms);
		world.setBlock(i + 4, j + 0, k + 6, b, ms);
		world.setBlock(i + 4, j + 1, k + 0, b, ms);
		world.setBlock(i + 4, j + 1, k + 6, b, ms);
		world.setBlock(i + 4, j + 2, k + 0, b, ms);
		world.setBlock(i + 4, j + 2, k + 6, b, ms);
		world.setBlock(i + 4, j + 3, k + 0, b, ms);
		world.setBlock(i + 4, j + 3, k + 6, b, ms);
		world.setBlock(i + 4, j + 4, k + 0, b, ms);
		world.setBlock(i + 4, j + 4, k + 1, b, mg);
		world.setBlock(i + 4, j + 4, k + 2, b, ms);
		world.setBlock(i + 4, j + 4, k + 3, b, ms);
		world.setBlock(i + 4, j + 4, k + 4, b, ms);
		world.setBlock(i + 4, j + 4, k + 5, b, mg);
		world.setBlock(i + 4, j + 4, k + 6, b, ms);
		world.setBlock(i + 4, j + 5, k + 0, b, ms);
		world.setBlock(i + 4, j + 5, k + 6, b, ms);
		world.setBlock(i + 4, j + 6, k + 0, b, ms);
		world.setBlock(i + 4, j + 6, k + 6, b, ms);
		world.setBlock(i + 4, j + 7, k + 0, b, ms);
		world.setBlock(i + 4, j + 7, k + 6, b, ms);
		world.setBlock(i + 4, j + 8, k + 0, b, ms);
		world.setBlock(i + 4, j + 8, k + 1, b, ms);
		world.setBlock(i + 4, j + 8, k + 2, b, ms);
		world.setBlock(i + 4, j + 8, k + 3, b, ms);
		world.setBlock(i + 4, j + 8, k + 4, b, ms);
		world.setBlock(i + 4, j + 8, k + 5, b, ms);
		world.setBlock(i + 4, j + 8, k + 6, b, ms);
		world.setBlock(i + 5, j + 0, k + 0, b, ms);
		world.setBlock(i + 5, j + 0, k + 1, b, ms);
		world.setBlock(i + 5, j + 0, k + 2, b, ms);
		world.setBlock(i + 5, j + 0, k + 3, b, ms);
		world.setBlock(i + 5, j + 0, k + 4, b, ms);
		world.setBlock(i + 5, j + 0, k + 5, b, ms);
		world.setBlock(i + 5, j + 0, k + 6, b, ms);
		world.setBlock(i + 5, j + 1, k + 0, b, ms);
		world.setBlock(i + 5, j + 1, k + 1, b, ms);
		world.setBlock(i + 5, j + 1, k + 5, b, ms);
		world.setBlock(i + 5, j + 1, k + 6, b, ms);
		world.setBlock(i + 5, j + 2, k + 0, b, ms);
		world.setBlock(i + 5, j + 2, k + 1, b, ms);
		world.setBlock(i + 5, j + 2, k + 5, b, ms);
		world.setBlock(i + 5, j + 2, k + 6, b, ms);
		world.setBlock(i + 5, j + 3, k + 0, b, ms);
		world.setBlock(i + 5, j + 3, k + 1, b, ms);
		world.setBlock(i + 5, j + 3, k + 5, b, ms);
		world.setBlock(i + 5, j + 3, k + 6, b, ms);
		world.setBlock(i + 5, j + 4, k + 0, b, ms);
		world.setBlock(i + 5, j + 4, k + 1, b, ms);
		world.setBlock(i + 5, j + 4, k + 2, b, ms);
		world.setBlock(i + 5, j + 4, k + 3, b, ms);
		world.setBlock(i + 5, j + 4, k + 4, b, ms);
		world.setBlock(i + 5, j + 4, k + 5, b, ms);
		world.setBlock(i + 5, j + 4, k + 6, b, ms);
		world.setBlock(i + 5, j + 5, k + 0, b, ms);
		world.setBlock(i + 5, j + 5, k + 6, b, ms);
		world.setBlock(i + 5, j + 6, k + 0, b, ms);
		world.setBlock(i + 5, j + 6, k + 6, b, ms);
		world.setBlock(i + 5, j + 7, k + 0, b, ms);
		world.setBlock(i + 5, j + 7, k + 6, b, ms);
		world.setBlock(i + 5, j + 8, k + 0, b, ms);
		world.setBlock(i + 5, j + 8, k + 1, b, ms);
		world.setBlock(i + 5, j + 8, k + 2, b, ms);
		world.setBlock(i + 5, j + 8, k + 3, b, ms);
		world.setBlock(i + 5, j + 8, k + 4, b, ms);
		world.setBlock(i + 5, j + 8, k + 5, b, ms);
		world.setBlock(i + 5, j + 8, k + 6, b, ms);
		world.setBlock(i + 6, j + 0, k + 0, b, ms);
		world.setBlock(i + 6, j + 0, k + 1, b, ms);
		world.setBlock(i + 6, j + 0, k + 5, b, ms);
		world.setBlock(i + 6, j + 0, k + 6, b, ms);
		world.setBlock(i + 6, j + 1, k + 0, b, ms);
		world.setBlock(i + 6, j + 1, k + 1, b, ms);
		world.setBlock(i + 6, j + 1, k + 5, b, ms);
		world.setBlock(i + 6, j + 1, k + 6, b, ms);
		world.setBlock(i + 6, j + 2, k + 0, b, ms);
		world.setBlock(i + 6, j + 2, k + 1, b, ms);
		world.setBlock(i + 6, j + 2, k + 5, b, ms);
		world.setBlock(i + 6, j + 2, k + 6, b, ms);
		world.setBlock(i + 6, j + 3, k + 0, b, ms);
		world.setBlock(i + 6, j + 3, k + 1, b, ms);
		world.setBlock(i + 6, j + 3, k + 2, b, ms);
		world.setBlock(i + 6, j + 3, k + 3, b, ms);
		world.setBlock(i + 6, j + 3, k + 4, b, ms);
		world.setBlock(i + 6, j + 3, k + 5, b, ms);
		world.setBlock(i + 6, j + 3, k + 6, b, ms);
		world.setBlock(i + 6, j + 4, k + 0, b, ms);
		world.setBlock(i + 6, j + 4, k + 6, b, ms);
		world.setBlock(i + 6, j + 5, k + 0, b, ms);
		world.setBlock(i + 6, j + 5, k + 6, b, ms);
		world.setBlock(i + 6, j + 6, k + 0, b, ms);
		world.setBlock(i + 6, j + 6, k + 6, b, ms);
		world.setBlock(i + 6, j + 7, k + 0, b, ms);
		world.setBlock(i + 6, j + 7, k + 6, b, ms);
		world.setBlock(i + 6, j + 8, k + 0, b, ms);
		world.setBlock(i + 6, j + 8, k + 1, b, ms);
		world.setBlock(i + 6, j + 8, k + 2, b, ms);
		world.setBlock(i + 6, j + 8, k + 3, b, ms);
		world.setBlock(i + 6, j + 8, k + 4, b, ms);
		world.setBlock(i + 6, j + 8, k + 5, b, ms);
		world.setBlock(i + 6, j + 8, k + 6, b, ms);
		world.setBlock(i + 7, j + 0, k + 0, b, ms);
		world.setBlock(i + 7, j + 0, k + 1, b, ms);
		world.setBlock(i + 7, j + 0, k + 2, b, ms);
		world.setBlock(i + 7, j + 0, k + 3, b, ms);
		world.setBlock(i + 7, j + 0, k + 4, b, ms);
		world.setBlock(i + 7, j + 0, k + 5, b, ms);
		world.setBlock(i + 7, j + 0, k + 6, b, ms);
		world.setBlock(i + 7, j + 1, k + 0, b, ms);
		world.setBlock(i + 7, j + 1, k + 1, b, ms);
		world.setBlock(i + 7, j + 1, k + 2, b, ms);
		world.setBlock(i + 7, j + 1, k + 3, b, ms);
		world.setBlock(i + 7, j + 1, k + 4, b, ms);
		world.setBlock(i + 7, j + 1, k + 5, b, ms);
		world.setBlock(i + 7, j + 1, k + 6, b, ms);
		world.setBlock(i + 7, j + 2, k + 0, b, ms);
		world.setBlock(i + 7, j + 2, k + 1, b, ms);
		world.setBlock(i + 7, j + 2, k + 2, b, ms);
		world.setBlock(i + 7, j + 2, k + 3, b, ms);
		world.setBlock(i + 7, j + 2, k + 4, b, ms);
		world.setBlock(i + 7, j + 2, k + 5, b, ms);
		world.setBlock(i + 7, j + 2, k + 6, b, ms);
		world.setBlock(i + 7, j + 3, k + 0, b, ms);
		world.setBlock(i + 7, j + 3, k + 6, b, ms);
		world.setBlock(i + 7, j + 4, k + 0, b, ms);
		world.setBlock(i + 7, j + 4, k + 6, b, ms);
		world.setBlock(i + 7, j + 5, k + 0, b, ml);
		world.setBlock(i + 7, j + 5, k + 6, b, ml);
		world.setBlock(i + 7, j + 6, k + 0, b, ms);
		world.setBlock(i + 7, j + 6, k + 6, b, ms);
		world.setBlock(i + 7, j + 7, k + 0, b, ms);
		world.setBlock(i + 7, j + 7, k + 6, b, ms);
		world.setBlock(i + 7, j + 8, k + 0, b, ms);
		world.setBlock(i + 7, j + 8, k + 1, b, ms);
		world.setBlock(i + 7, j + 8, k + 2, b, ms);
		world.setBlock(i + 7, j + 8, k + 3, b, ms);
		world.setBlock(i + 7, j + 8, k + 4, b, ms);
		world.setBlock(i + 7, j + 8, k + 5, b, ms);
		world.setBlock(i + 7, j + 8, k + 6, b, ms);
		world.setBlock(i + 8, j + 0, k + 0, b, ms);
		world.setBlock(i + 8, j + 0, k + 1, b, ms);
		world.setBlock(i + 8, j + 0, k + 2, b, ms);
		world.setBlock(i + 8, j + 0, k + 3, b, ms);
		world.setBlock(i + 8, j + 0, k + 4, b, ms);
		world.setBlock(i + 8, j + 0, k + 5, b, ms);
		world.setBlock(i + 8, j + 0, k + 6, b, ms);
		world.setBlock(i + 8, j + 1, k + 0, b, ms);
		world.setBlock(i + 8, j + 1, k + 1, b, ms);
		world.setBlock(i + 8, j + 1, k + 2, b, ms);
		world.setBlock(i + 8, j + 1, k + 3, b, ms);
		world.setBlock(i + 8, j + 1, k + 4, b, ms);
		world.setBlock(i + 8, j + 1, k + 5, b, ms);
		world.setBlock(i + 8, j + 1, k + 6, b, ms);
		world.setBlock(i + 8, j + 2, k + 0, b, ms);
		world.setBlock(i + 8, j + 2, k + 6, b, ms);
		world.setBlock(i + 8, j + 3, k + 0, b, ms);
		world.setBlock(i + 8, j + 3, k + 6, b, ms);
		world.setBlock(i + 8, j + 4, k + 0, b, ms);
		world.setBlock(i + 8, j + 4, k + 6, b, ms);
		world.setBlock(i + 8, j + 5, k + 0, b, ms);
		world.setBlock(i + 8, j + 5, k + 6, b, ms);
		world.setBlock(i + 8, j + 6, k + 0, b, ms);
		world.setBlock(i + 8, j + 6, k + 6, b, ms);
		world.setBlock(i + 8, j + 7, k + 0, b, ms);
		world.setBlock(i + 8, j + 7, k + 6, b, ms);
		world.setBlock(i + 8, j + 8, k + 0, b, ms);
		world.setBlock(i + 8, j + 8, k + 1, b, ms);
		world.setBlock(i + 8, j + 8, k + 2, b, ms);
		world.setBlock(i + 8, j + 8, k + 3, b, ms);
		world.setBlock(i + 8, j + 8, k + 4, b, ms);
		world.setBlock(i + 8, j + 8, k + 5, b, ms);
		world.setBlock(i + 8, j + 8, k + 6, b, ms);
		world.setBlock(i + 9, j + 0, k + 0, b, ms);
		world.setBlock(i + 9, j + 0, k + 1, b, ms);
		world.setBlock(i + 9, j + 0, k + 2, b, ms);
		world.setBlock(i + 9, j + 0, k + 3, b, ms);
		world.setBlock(i + 9, j + 0, k + 4, b, ms);
		world.setBlock(i + 9, j + 0, k + 5, b, ms);
		world.setBlock(i + 9, j + 0, k + 6, b, ms);
		world.setBlock(i + 9, j + 1, k + 0, b, ms);
		world.setBlock(i + 9, j + 1, k + 6, b, ms);
		world.setBlock(i + 9, j + 2, k + 0, b, ms);
		world.setBlock(i + 9, j + 2, k + 6, b, ms);
		world.setBlock(i + 9, j + 3, k + 0, b, ms);
		world.setBlock(i + 9, j + 3, k + 6, b, ms);
		world.setBlock(i + 9, j + 4, k + 0, b, ms);
		world.setBlock(i + 9, j + 4, k + 6, b, ms);
		world.setBlock(i + 9, j + 5, k + 0, b, ms);
		world.setBlock(i + 9, j + 5, k + 6, b, ms);
		world.setBlock(i + 9, j + 6, k + 0, b, ms);
		world.setBlock(i + 9, j + 6, k + 6, b, ms);
		world.setBlock(i + 9, j + 7, k + 0, b, ms);
		world.setBlock(i + 9, j + 7, k + 1, b, ms);
		world.setBlock(i + 9, j + 7, k + 5, b, ms);
		world.setBlock(i + 9, j + 7, k + 6, b, ms);
		world.setBlock(i + 9, j + 8, k + 1, b, ms);
		world.setBlock(i + 9, j + 8, k + 2, b, ms);
		world.setBlock(i + 9, j + 8, k + 3, b, ms);
		world.setBlock(i + 9, j + 8, k + 4, b, ms);
		world.setBlock(i + 9, j + 8, k + 5, b, ms);
		world.setBlock(i + 10, j + 0, k + 0, b, ms);
		world.setBlock(i + 10, j + 0, k + 1, b, ms);
		world.setBlock(i + 10, j + 0, k + 2, b, ms);
		world.setBlock(i + 10, j + 0, k + 3, b, ms);
		world.setBlock(i + 10, j + 0, k + 4, b, ms);
		world.setBlock(i + 10, j + 0, k + 5, b, ms);
		world.setBlock(i + 10, j + 0, k + 6, b, ms);
		world.setBlock(i + 10, j + 1, k + 0, b, ms);
		world.setBlock(i + 10, j + 1, k + 6, b, ms);
		world.setBlock(i + 10, j + 2, k + 0, b, ml);
		world.setBlock(i + 10, j + 2, k + 6, b, ml);
		world.setBlock(i + 10, j + 3, k + 0, b, ms);
		world.setBlock(i + 10, j + 3, k + 6, b, ms);
		world.setBlock(i + 10, j + 4, k + 0, b, ms);
		world.setBlock(i + 10, j + 4, k + 6, b, ms);
		world.setBlock(i + 10, j + 5, k + 0, b, ms);
		world.setBlock(i + 10, j + 5, k + 6, b, ms);
		world.setBlock(i + 10, j + 6, k + 0, b, ms);
		world.setBlock(i + 10, j + 6, k + 1, b, ms);
		world.setBlock(i + 10, j + 6, k + 5, b, ms);
		world.setBlock(i + 10, j + 6, k + 6, b, ms);
		world.setBlock(i + 10, j + 7, k + 1, b, ms);
		world.setBlock(i + 10, j + 7, k + 2, b, ms);
		world.setBlock(i + 10, j + 7, k + 3, b, ms);
		world.setBlock(i + 10, j + 7, k + 4, b, ms);
		world.setBlock(i + 10, j + 7, k + 5, b, ms);
		world.setBlock(i + 11, j + 0, k + 0, b, ms);
		world.setBlock(i + 11, j + 0, k + 1, b, ms);
		world.setBlock(i + 11, j + 0, k + 2, b, ms);
		world.setBlock(i + 11, j + 0, k + 3, b, ms);
		world.setBlock(i + 11, j + 0, k + 4, b, ms);
		world.setBlock(i + 11, j + 0, k + 5, b, ms);
		world.setBlock(i + 11, j + 0, k + 6, b, ms);
		world.setBlock(i + 11, j + 1, k + 0, b, ms);
		world.setBlock(i + 11, j + 1, k + 6, b, ms);
		world.setBlock(i + 11, j + 2, k + 0, b, ms);
		world.setBlock(i + 11, j + 2, k + 6, b, ms);
		world.setBlock(i + 11, j + 3, k + 0, b, ms);
		world.setBlock(i + 11, j + 3, k + 6, b, ms);
		world.setBlock(i + 11, j + 4, k + 0, b, ms);
		world.setBlock(i + 11, j + 4, k + 6, b, ms);
		world.setBlock(i + 11, j + 5, k + 0, b, ms);
		world.setBlock(i + 11, j + 5, k + 1, b, ms);
		world.setBlock(i + 11, j + 5, k + 5, b, ms);
		world.setBlock(i + 11, j + 5, k + 6, b, ms);
		world.setBlock(i + 11, j + 6, k + 1, b, ms);
		world.setBlock(i + 11, j + 6, k + 2, b, ms);
		world.setBlock(i + 11, j + 6, k + 3, b, ms);
		world.setBlock(i + 11, j + 6, k + 4, b, ms);
		world.setBlock(i + 11, j + 6, k + 5, b, ms);
		world.setBlock(i + 12, j + 0, k + 0, b, ms);
		world.setBlock(i + 12, j + 0, k + 1, b, ms);
		world.setBlock(i + 12, j + 0, k + 2, b, ms);
		world.setBlock(i + 12, j + 0, k + 3, b, ms);
		world.setBlock(i + 12, j + 0, k + 4, b, ms);
		world.setBlock(i + 12, j + 0, k + 5, b, ms);
		world.setBlock(i + 12, j + 0, k + 6, b, ms);
		world.setBlock(i + 12, j + 1, k + 0, b, ms);
		world.setBlock(i + 12, j + 1, k + 6, b, ms);
		world.setBlock(i + 12, j + 2, k + 0, b, ms);
		world.setBlock(i + 12, j + 2, k + 6, b, ms);
		world.setBlock(i + 12, j + 3, k + 0, b, ms);
		world.setBlock(i + 12, j + 3, k + 6, b, ms);
		world.setBlock(i + 12, j + 4, k + 0, b, ms);
		world.setBlock(i + 12, j + 4, k + 1, b, ms);
		world.setBlock(i + 12, j + 4, k + 5, b, ms);
		world.setBlock(i + 12, j + 4, k + 6, b, ms);
		world.setBlock(i + 12, j + 5, k + 1, b, ms);
		world.setBlock(i + 12, j + 5, k + 2, b, ms);
		world.setBlock(i + 12, j + 5, k + 3, b, ms);
		world.setBlock(i + 12, j + 5, k + 4, b, ms);
		world.setBlock(i + 12, j + 5, k + 5, b, ms);
		world.setBlock(i + 13, j + 0, k + 0, b, ms);
		world.setBlock(i + 13, j + 0, k + 1, b, ms);
		world.setBlock(i + 13, j + 0, k + 2, b, ms);
		world.setBlock(i + 13, j + 0, k + 3, b, ms);
		world.setBlock(i + 13, j + 0, k + 4, b, ms);
		world.setBlock(i + 13, j + 0, k + 5, b, ms);
		world.setBlock(i + 13, j + 0, k + 6, b, ms);
		world.setBlock(i + 13, j + 1, k + 0, b, ms);
		world.setBlock(i + 13, j + 1, k + 6, b, ms);
		world.setBlock(i + 13, j + 2, k + 0, b, ms);
		world.setBlock(i + 13, j + 2, k + 6, b, ms);
		world.setBlock(i + 13, j + 3, k + 0, b, ms);
		world.setBlock(i + 13, j + 3, k + 6, b, ms);
		world.setBlock(i + 13, j + 4, k + 0, b, ms);
		world.setBlock(i + 13, j + 4, k + 1, b, ms);
		world.setBlock(i + 13, j + 4, k + 5, b, ms);
		world.setBlock(i + 13, j + 4, k + 6, b, ms);
		world.setBlock(i + 13, j + 5, k + 1, b, ms);
		world.setBlock(i + 13, j + 5, k + 2, b, ms);
		world.setBlock(i + 13, j + 5, k + 3, b, ms);
		world.setBlock(i + 13, j + 5, k + 4, b, ms);
		world.setBlock(i + 13, j + 5, k + 5, b, ms);

		this.generateAir(world, i, j, k);

		world.flipX();

		world.addToGenCache(c);
	}

	private void generateAir(OriginBlockCache world, int i, int j, int k) {
		world.setBlock(i + 1, j + 1, k + 2, Blocks.air);
		world.setBlock(i + 1, j + 1, k + 3, Blocks.air);
		world.setBlock(i + 1, j + 1, k + 4, Blocks.air);
		world.setBlock(i + 1, j + 2, k + 2, Blocks.air);
		world.setBlock(i + 1, j + 2, k + 3, Blocks.air);
		world.setBlock(i + 1, j + 2, k + 4, Blocks.air);
		world.setBlock(i + 1, j + 3, k + 2, Blocks.air);
		world.setBlock(i + 1, j + 3, k + 3, Blocks.air);
		world.setBlock(i + 1, j + 3, k + 4, Blocks.air);
		world.setBlock(i + 1, j + 5, k + 1, Blocks.air);
		world.setBlock(i + 1, j + 5, k + 2, Blocks.air);
		world.setBlock(i + 1, j + 5, k + 3, Blocks.air);
		world.setBlock(i + 1, j + 5, k + 4, Blocks.air);
		world.setBlock(i + 1, j + 5, k + 5, Blocks.air);
		world.setBlock(i + 1, j + 6, k + 1, Blocks.air);
		world.setBlock(i + 1, j + 6, k + 2, Blocks.air);
		world.setBlock(i + 1, j + 6, k + 3, Blocks.air);
		world.setBlock(i + 1, j + 6, k + 4, Blocks.air);
		world.setBlock(i + 1, j + 6, k + 5, Blocks.air);
		world.setBlock(i + 2, j + 1, k + 1, Blocks.air);
		world.setBlock(i + 2, j + 1, k + 2, Blocks.air);
		world.setBlock(i + 2, j + 1, k + 3, Blocks.air);
		world.setBlock(i + 2, j + 1, k + 4, Blocks.air);
		world.setBlock(i + 2, j + 1, k + 5, Blocks.air);
		world.setBlock(i + 2, j + 2, k + 1, Blocks.air);
		world.setBlock(i + 2, j + 2, k + 2, Blocks.air);
		world.setBlock(i + 2, j + 2, k + 3, Blocks.air);
		world.setBlock(i + 2, j + 2, k + 4, Blocks.air);
		world.setBlock(i + 2, j + 2, k + 5, Blocks.air);
		world.setBlock(i + 2, j + 3, k + 1, Blocks.air);
		world.setBlock(i + 2, j + 3, k + 2, Blocks.air);
		world.setBlock(i + 2, j + 3, k + 3, Blocks.air);
		world.setBlock(i + 2, j + 3, k + 4, Blocks.air);
		world.setBlock(i + 2, j + 3, k + 5, Blocks.air);
		world.setBlock(i + 2, j + 5, k + 1, Blocks.air);
		world.setBlock(i + 2, j + 5, k + 2, Blocks.air);
		world.setBlock(i + 2, j + 5, k + 3, Blocks.air);
		world.setBlock(i + 2, j + 5, k + 4, Blocks.air);
		world.setBlock(i + 2, j + 5, k + 5, Blocks.air);
		world.setBlock(i + 2, j + 6, k + 1, Blocks.air);
		world.setBlock(i + 2, j + 6, k + 2, Blocks.air);
		world.setBlock(i + 2, j + 6, k + 3, Blocks.air);
		world.setBlock(i + 2, j + 6, k + 4, Blocks.air);
		world.setBlock(i + 2, j + 6, k + 5, Blocks.air);
		world.setBlock(i + 2, j + 7, k + 1, Blocks.air);
		world.setBlock(i + 2, j + 7, k + 2, Blocks.air);
		world.setBlock(i + 2, j + 7, k + 3, Blocks.air);
		world.setBlock(i + 2, j + 7, k + 4, Blocks.air);
		world.setBlock(i + 2, j + 7, k + 5, Blocks.air);
		world.setBlock(i + 3, j + 1, k + 1, Blocks.air);
		world.setBlock(i + 3, j + 1, k + 2, Blocks.air);
		world.setBlock(i + 3, j + 1, k + 3, Blocks.air);
		world.setBlock(i + 3, j + 1, k + 4, Blocks.air);
		world.setBlock(i + 3, j + 1, k + 5, Blocks.air);
		world.setBlock(i + 3, j + 2, k + 1, Blocks.air);
		world.setBlock(i + 3, j + 2, k + 2, Blocks.air);
		world.setBlock(i + 3, j + 2, k + 4, Blocks.air);
		world.setBlock(i + 3, j + 2, k + 5, Blocks.air);
		world.setBlock(i + 3, j + 3, k + 1, Blocks.air);
		world.setBlock(i + 3, j + 3, k + 2, Blocks.air);
		world.setBlock(i + 3, j + 3, k + 3, Blocks.air);
		world.setBlock(i + 3, j + 3, k + 4, Blocks.air);
		world.setBlock(i + 3, j + 3, k + 5, Blocks.air);
		world.setBlock(i + 3, j + 5, k + 1, Blocks.air);
		world.setBlock(i + 3, j + 5, k + 2, Blocks.air);
		world.setBlock(i + 3, j + 5, k + 3, Blocks.air);
		world.setBlock(i + 3, j + 5, k + 4, Blocks.air);
		world.setBlock(i + 3, j + 5, k + 5, Blocks.air);
		world.setBlock(i + 3, j + 6, k + 1, Blocks.air);
		world.setBlock(i + 3, j + 6, k + 2, Blocks.air);
		world.setBlock(i + 3, j + 6, k + 3, Blocks.air);
		world.setBlock(i + 3, j + 6, k + 4, Blocks.air);
		world.setBlock(i + 3, j + 6, k + 5, Blocks.air);
		world.setBlock(i + 3, j + 7, k + 1, Blocks.air);
		world.setBlock(i + 3, j + 7, k + 2, Blocks.air);
		world.setBlock(i + 3, j + 7, k + 3, Blocks.air);
		world.setBlock(i + 3, j + 7, k + 4, Blocks.air);
		world.setBlock(i + 3, j + 7, k + 5, Blocks.air);
		world.setBlock(i + 4, j + 1, k + 1, Blocks.air);
		world.setBlock(i + 4, j + 1, k + 2, Blocks.air);
		world.setBlock(i + 4, j + 1, k + 3, Blocks.air);
		world.setBlock(i + 4, j + 1, k + 4, Blocks.air);
		world.setBlock(i + 4, j + 1, k + 5, Blocks.air);
		world.setBlock(i + 4, j + 2, k + 1, Blocks.air);
		world.setBlock(i + 4, j + 2, k + 2, Blocks.air);
		world.setBlock(i + 4, j + 2, k + 3, Blocks.air);
		world.setBlock(i + 4, j + 2, k + 4, Blocks.air);
		world.setBlock(i + 4, j + 2, k + 5, Blocks.air);
		world.setBlock(i + 4, j + 3, k + 1, Blocks.air);
		world.setBlock(i + 4, j + 3, k + 2, Blocks.air);
		world.setBlock(i + 4, j + 3, k + 3, Blocks.air);
		world.setBlock(i + 4, j + 3, k + 4, Blocks.air);
		world.setBlock(i + 4, j + 3, k + 5, Blocks.air);
		world.setBlock(i + 4, j + 5, k + 1, Blocks.air);
		world.setBlock(i + 4, j + 5, k + 2, Blocks.air);
		world.setBlock(i + 4, j + 5, k + 3, Blocks.air);
		world.setBlock(i + 4, j + 5, k + 4, Blocks.air);
		world.setBlock(i + 4, j + 5, k + 5, Blocks.air);
		world.setBlock(i + 4, j + 6, k + 1, Blocks.air);
		world.setBlock(i + 4, j + 6, k + 2, Blocks.air);
		world.setBlock(i + 4, j + 6, k + 3, Blocks.air);
		world.setBlock(i + 4, j + 6, k + 4, Blocks.air);
		world.setBlock(i + 4, j + 6, k + 5, Blocks.air);
		world.setBlock(i + 4, j + 7, k + 1, Blocks.air);
		world.setBlock(i + 4, j + 7, k + 2, Blocks.air);
		world.setBlock(i + 4, j + 7, k + 3, Blocks.air);
		world.setBlock(i + 4, j + 7, k + 4, Blocks.air);
		world.setBlock(i + 4, j + 7, k + 5, Blocks.air);
		world.setBlock(i + 5, j + 1, k + 2, Blocks.air);
		world.setBlock(i + 5, j + 1, k + 3, Blocks.air);
		world.setBlock(i + 5, j + 1, k + 4, Blocks.air);
		world.setBlock(i + 5, j + 2, k + 2, Blocks.air);
		world.setBlock(i + 5, j + 2, k + 3, Blocks.air);
		world.setBlock(i + 5, j + 2, k + 4, Blocks.air);
		world.setBlock(i + 5, j + 3, k + 2, Blocks.air);
		world.setBlock(i + 5, j + 3, k + 3, Blocks.air);
		world.setBlock(i + 5, j + 3, k + 4, Blocks.air);
		world.setBlock(i + 5, j + 5, k + 1, Blocks.air);
		world.setBlock(i + 5, j + 5, k + 2, Blocks.air);
		world.setBlock(i + 5, j + 5, k + 3, Blocks.air);
		world.setBlock(i + 5, j + 5, k + 4, Blocks.air);
		world.setBlock(i + 5, j + 5, k + 5, Blocks.air);
		world.setBlock(i + 5, j + 6, k + 1, Blocks.air);
		world.setBlock(i + 5, j + 6, k + 2, Blocks.air);
		world.setBlock(i + 5, j + 6, k + 3, Blocks.air);
		world.setBlock(i + 5, j + 6, k + 4, Blocks.air);
		world.setBlock(i + 5, j + 6, k + 5, Blocks.air);
		world.setBlock(i + 5, j + 7, k + 1, Blocks.air);
		world.setBlock(i + 5, j + 7, k + 2, Blocks.air);
		world.setBlock(i + 5, j + 7, k + 3, Blocks.air);
		world.setBlock(i + 5, j + 7, k + 4, Blocks.air);
		world.setBlock(i + 5, j + 7, k + 5, Blocks.air);
		world.setBlock(i + 6, j + 4, k + 1, Blocks.air);
		world.setBlock(i + 6, j + 4, k + 2, Blocks.air);
		world.setBlock(i + 6, j + 4, k + 3, Blocks.air);
		world.setBlock(i + 6, j + 4, k + 4, Blocks.air);
		world.setBlock(i + 6, j + 4, k + 5, Blocks.air);
		world.setBlock(i + 6, j + 5, k + 1, Blocks.air);
		world.setBlock(i + 6, j + 5, k + 2, Blocks.air);
		world.setBlock(i + 6, j + 5, k + 3, Blocks.air);
		world.setBlock(i + 6, j + 5, k + 4, Blocks.air);
		world.setBlock(i + 6, j + 5, k + 5, Blocks.air);
		world.setBlock(i + 6, j + 6, k + 1, Blocks.air);
		world.setBlock(i + 6, j + 6, k + 2, Blocks.air);
		world.setBlock(i + 6, j + 6, k + 3, Blocks.air);
		world.setBlock(i + 6, j + 6, k + 4, Blocks.air);
		world.setBlock(i + 6, j + 6, k + 5, Blocks.air);
		world.setBlock(i + 6, j + 7, k + 1, Blocks.air);
		world.setBlock(i + 6, j + 7, k + 2, Blocks.air);
		world.setBlock(i + 6, j + 7, k + 3, Blocks.air);
		world.setBlock(i + 6, j + 7, k + 4, Blocks.air);
		world.setBlock(i + 6, j + 7, k + 5, Blocks.air);
		world.setBlock(i + 7, j + 3, k + 1, Blocks.air);
		world.setBlock(i + 7, j + 3, k + 2, Blocks.air);
		world.setBlock(i + 7, j + 3, k + 3, Blocks.air);
		world.setBlock(i + 7, j + 3, k + 4, Blocks.air);
		world.setBlock(i + 7, j + 3, k + 5, Blocks.air);
		world.setBlock(i + 7, j + 4, k + 1, Blocks.air);
		world.setBlock(i + 7, j + 4, k + 2, Blocks.air);
		world.setBlock(i + 7, j + 4, k + 3, Blocks.air);
		world.setBlock(i + 7, j + 4, k + 4, Blocks.air);
		world.setBlock(i + 7, j + 4, k + 5, Blocks.air);
		world.setBlock(i + 7, j + 5, k + 1, Blocks.air);
		world.setBlock(i + 7, j + 5, k + 2, Blocks.air);
		world.setBlock(i + 7, j + 5, k + 3, Blocks.air);
		world.setBlock(i + 7, j + 5, k + 4, Blocks.air);
		world.setBlock(i + 7, j + 5, k + 5, Blocks.air);
		world.setBlock(i + 7, j + 6, k + 1, Blocks.air);
		world.setBlock(i + 7, j + 6, k + 2, Blocks.air);
		world.setBlock(i + 7, j + 6, k + 3, Blocks.air);
		world.setBlock(i + 7, j + 6, k + 4, Blocks.air);
		world.setBlock(i + 7, j + 6, k + 5, Blocks.air);
		world.setBlock(i + 7, j + 7, k + 1, Blocks.air);
		world.setBlock(i + 7, j + 7, k + 2, Blocks.air);
		world.setBlock(i + 7, j + 7, k + 3, Blocks.air);
		world.setBlock(i + 7, j + 7, k + 4, Blocks.air);
		world.setBlock(i + 7, j + 7, k + 5, Blocks.air);
		world.setBlock(i + 8, j + 2, k + 1, Blocks.air);
		world.setBlock(i + 8, j + 2, k + 2, Blocks.air);
		world.setBlock(i + 8, j + 2, k + 3, Blocks.air);
		world.setBlock(i + 8, j + 2, k + 4, Blocks.air);
		world.setBlock(i + 8, j + 2, k + 5, Blocks.air);
		world.setBlock(i + 8, j + 3, k + 1, Blocks.air);
		world.setBlock(i + 8, j + 3, k + 2, Blocks.air);
		world.setBlock(i + 8, j + 3, k + 3, Blocks.air);
		world.setBlock(i + 8, j + 3, k + 4, Blocks.air);
		world.setBlock(i + 8, j + 3, k + 5, Blocks.air);
		world.setBlock(i + 8, j + 4, k + 1, Blocks.air);
		world.setBlock(i + 8, j + 4, k + 2, Blocks.air);
		world.setBlock(i + 8, j + 4, k + 3, Blocks.air);
		world.setBlock(i + 8, j + 4, k + 4, Blocks.air);
		world.setBlock(i + 8, j + 4, k + 5, Blocks.air);
		world.setBlock(i + 8, j + 5, k + 1, Blocks.air);
		world.setBlock(i + 8, j + 5, k + 2, Blocks.air);
		world.setBlock(i + 8, j + 5, k + 3, Blocks.air);
		world.setBlock(i + 8, j + 5, k + 4, Blocks.air);
		world.setBlock(i + 8, j + 5, k + 5, Blocks.air);
		world.setBlock(i + 8, j + 6, k + 1, Blocks.air);
		world.setBlock(i + 8, j + 6, k + 2, Blocks.air);
		world.setBlock(i + 8, j + 6, k + 3, Blocks.air);
		world.setBlock(i + 8, j + 6, k + 4, Blocks.air);
		world.setBlock(i + 8, j + 6, k + 5, Blocks.air);
		world.setBlock(i + 8, j + 7, k + 1, Blocks.air);
		world.setBlock(i + 8, j + 7, k + 2, Blocks.air);
		world.setBlock(i + 8, j + 7, k + 3, Blocks.air);
		world.setBlock(i + 8, j + 7, k + 4, Blocks.air);
		world.setBlock(i + 8, j + 7, k + 5, Blocks.air);
		world.setBlock(i + 9, j + 1, k + 1, Blocks.air);
		world.setBlock(i + 9, j + 1, k + 2, Blocks.air);
		world.setBlock(i + 9, j + 1, k + 3, Blocks.air);
		world.setBlock(i + 9, j + 1, k + 4, Blocks.air);
		world.setBlock(i + 9, j + 1, k + 5, Blocks.air);
		world.setBlock(i + 9, j + 2, k + 1, Blocks.air);
		world.setBlock(i + 9, j + 2, k + 2, Blocks.air);
		world.setBlock(i + 9, j + 2, k + 3, Blocks.air);
		world.setBlock(i + 9, j + 2, k + 4, Blocks.air);
		world.setBlock(i + 9, j + 2, k + 5, Blocks.air);
		world.setBlock(i + 9, j + 3, k + 1, Blocks.air);
		world.setBlock(i + 9, j + 3, k + 2, Blocks.air);
		world.setBlock(i + 9, j + 3, k + 3, Blocks.air);
		world.setBlock(i + 9, j + 3, k + 4, Blocks.air);
		world.setBlock(i + 9, j + 3, k + 5, Blocks.air);
		world.setBlock(i + 9, j + 4, k + 1, Blocks.air);
		world.setBlock(i + 9, j + 4, k + 2, Blocks.air);
		world.setBlock(i + 9, j + 4, k + 3, Blocks.air);
		world.setBlock(i + 9, j + 4, k + 4, Blocks.air);
		world.setBlock(i + 9, j + 4, k + 5, Blocks.air);
		world.setBlock(i + 9, j + 5, k + 1, Blocks.air);
		world.setBlock(i + 9, j + 5, k + 2, Blocks.air);
		world.setBlock(i + 9, j + 5, k + 3, Blocks.air);
		world.setBlock(i + 9, j + 5, k + 4, Blocks.air);
		world.setBlock(i + 9, j + 5, k + 5, Blocks.air);
		world.setBlock(i + 9, j + 6, k + 1, Blocks.air);
		world.setBlock(i + 9, j + 6, k + 2, Blocks.air);
		world.setBlock(i + 9, j + 6, k + 3, Blocks.air);
		world.setBlock(i + 9, j + 6, k + 4, Blocks.air);
		world.setBlock(i + 9, j + 6, k + 5, Blocks.air);
		world.setBlock(i + 9, j + 7, k + 2, Blocks.air);
		world.setBlock(i + 9, j + 7, k + 3, Blocks.air);
		world.setBlock(i + 9, j + 7, k + 4, Blocks.air);
		world.setBlock(i + 10, j + 1, k + 1, Blocks.air);
		world.setBlock(i + 10, j + 1, k + 2, Blocks.air);
		world.setBlock(i + 10, j + 1, k + 3, Blocks.air);
		world.setBlock(i + 10, j + 1, k + 4, Blocks.air);
		world.setBlock(i + 10, j + 1, k + 5, Blocks.air);
		world.setBlock(i + 10, j + 2, k + 1, Blocks.air);
		world.setBlock(i + 10, j + 2, k + 2, Blocks.air);
		world.setBlock(i + 10, j + 2, k + 3, Blocks.air);
		world.setBlock(i + 10, j + 2, k + 4, Blocks.air);
		world.setBlock(i + 10, j + 2, k + 5, Blocks.air);
		world.setBlock(i + 10, j + 3, k + 1, Blocks.air);
		world.setBlock(i + 10, j + 3, k + 2, Blocks.air);
		world.setBlock(i + 10, j + 3, k + 3, Blocks.air);
		world.setBlock(i + 10, j + 3, k + 4, Blocks.air);
		world.setBlock(i + 10, j + 3, k + 5, Blocks.air);
		world.setBlock(i + 10, j + 4, k + 1, Blocks.air);
		world.setBlock(i + 10, j + 4, k + 2, Blocks.air);
		world.setBlock(i + 10, j + 4, k + 3, Blocks.air);
		world.setBlock(i + 10, j + 4, k + 4, Blocks.air);
		world.setBlock(i + 10, j + 4, k + 5, Blocks.air);
		world.setBlock(i + 10, j + 5, k + 1, Blocks.air);
		world.setBlock(i + 10, j + 5, k + 2, Blocks.air);
		world.setBlock(i + 10, j + 5, k + 3, Blocks.air);
		world.setBlock(i + 10, j + 5, k + 4, Blocks.air);
		world.setBlock(i + 10, j + 5, k + 5, Blocks.air);
		world.setBlock(i + 10, j + 6, k + 2, Blocks.air);
		world.setBlock(i + 10, j + 6, k + 3, Blocks.air);
		world.setBlock(i + 10, j + 6, k + 4, Blocks.air);
		world.setBlock(i + 11, j + 1, k + 1, Blocks.air);
		world.setBlock(i + 11, j + 1, k + 2, Blocks.air);
		world.setBlock(i + 11, j + 1, k + 3, Blocks.air);
		world.setBlock(i + 11, j + 1, k + 4, Blocks.air);
		world.setBlock(i + 11, j + 1, k + 5, Blocks.air);
		world.setBlock(i + 11, j + 2, k + 1, Blocks.air);
		world.setBlock(i + 11, j + 2, k + 2, Blocks.air);
		world.setBlock(i + 11, j + 2, k + 3, Blocks.air);
		world.setBlock(i + 11, j + 2, k + 4, Blocks.air);
		world.setBlock(i + 11, j + 2, k + 5, Blocks.air);
		world.setBlock(i + 11, j + 3, k + 1, Blocks.air);
		world.setBlock(i + 11, j + 3, k + 2, Blocks.air);
		world.setBlock(i + 11, j + 3, k + 3, Blocks.air);
		world.setBlock(i + 11, j + 3, k + 4, Blocks.air);
		world.setBlock(i + 11, j + 3, k + 5, Blocks.air);
		world.setBlock(i + 11, j + 4, k + 1, Blocks.air);
		world.setBlock(i + 11, j + 4, k + 2, Blocks.air);
		world.setBlock(i + 11, j + 4, k + 3, Blocks.air);
		world.setBlock(i + 11, j + 4, k + 4, Blocks.air);
		world.setBlock(i + 11, j + 4, k + 5, Blocks.air);
		world.setBlock(i + 11, j + 5, k + 2, Blocks.air);
		world.setBlock(i + 11, j + 5, k + 3, Blocks.air);
		world.setBlock(i + 11, j + 5, k + 4, Blocks.air);
		world.setBlock(i + 12, j + 1, k + 1, Blocks.air);
		world.setBlock(i + 12, j + 1, k + 2, Blocks.air);
		world.setBlock(i + 12, j + 1, k + 3, Blocks.air);
		world.setBlock(i + 12, j + 1, k + 4, Blocks.air);
		world.setBlock(i + 12, j + 1, k + 5, Blocks.air);
		world.setBlock(i + 12, j + 2, k + 1, Blocks.air);
		world.setBlock(i + 12, j + 2, k + 2, Blocks.air);
		world.setBlock(i + 12, j + 2, k + 3, Blocks.air);
		world.setBlock(i + 12, j + 2, k + 4, Blocks.air);
		world.setBlock(i + 12, j + 2, k + 5, Blocks.air);
		world.setBlock(i + 12, j + 3, k + 1, Blocks.air);
		world.setBlock(i + 12, j + 3, k + 2, Blocks.air);
		world.setBlock(i + 12, j + 3, k + 3, Blocks.air);
		world.setBlock(i + 12, j + 3, k + 4, Blocks.air);
		world.setBlock(i + 12, j + 3, k + 5, Blocks.air);
		world.setBlock(i + 12, j + 4, k + 2, Blocks.air);
		world.setBlock(i + 12, j + 4, k + 3, Blocks.air);
		world.setBlock(i + 12, j + 4, k + 4, Blocks.air);
		world.setBlock(i + 13, j + 1, k + 1, Blocks.air);
		world.setBlock(i + 13, j + 1, k + 2, Blocks.air);
		world.setBlock(i + 13, j + 1, k + 3, Blocks.air);
		world.setBlock(i + 13, j + 1, k + 4, Blocks.air);
		world.setBlock(i + 13, j + 1, k + 5, Blocks.air);
		world.setBlock(i + 13, j + 2, k + 1, Blocks.air);
		world.setBlock(i + 13, j + 2, k + 2, Blocks.air);
		world.setBlock(i + 13, j + 2, k + 3, Blocks.air);
		world.setBlock(i + 13, j + 2, k + 4, Blocks.air);
		world.setBlock(i + 13, j + 2, k + 5, Blocks.air);
		world.setBlock(i + 13, j + 3, k + 1, Blocks.air);
		world.setBlock(i + 13, j + 3, k + 2, Blocks.air);
		world.setBlock(i + 13, j + 3, k + 3, Blocks.air);
		world.setBlock(i + 13, j + 3, k + 4, Blocks.air);
		world.setBlock(i + 13, j + 3, k + 5, Blocks.air);
		world.setBlock(i + 13, j + 4, k + 2, Blocks.air);
		world.setBlock(i + 13, j + 4, k + 3, Blocks.air);
		world.setBlock(i + 13, j + 4, k + 4, Blocks.air);
	}

}
