/*******************************************************************************
 * @author Reika Kalseki
 *
 * Copyright 2017
 *
 * All rights reserved.
 * Distribution of the software in any form is only allowed with
 * explicit, prior permission from the owner.
 ******************************************************************************/
package Reika.ChromatiCraft.World.Dimension.Structure.RayBlend;


import net.minecraft.block.Block;
import net.minecraft.init.Blocks;
import net.minecraftforge.common.ChestGenHooks;
import net.minecraftforge.common.util.ForgeDirection;

import Reika.ChromatiCraft.Auxiliary.ChromaStacks;
import Reika.ChromatiCraft.Base.StructurePiece;
import Reika.ChromatiCraft.Block.Worldgen.BlockStructureShield.BlockType;
import Reika.ChromatiCraft.Registry.ChromaBlocks;
import Reika.ChromatiCraft.World.Dimension.Structure.RayBlendGenerator;
import Reika.DragonAPI.Instantiable.Worldgen.ChunkSplicedGenerationCache;

public class RayBlendLoot extends StructurePiece<RayBlendGenerator> {

	public RayBlendLoot(RayBlendGenerator s) {
		super(s);
	}

	@Override
	public void generate(ChunkSplicedGenerationCache world, int x, int y, int z) {
		Block b = ChromaBlocks.STRUCTSHIELD.getBlockInstance();

		Object[] items = {ChromaStacks.lumaDust, 50, ChromaStacks.multiShard, 90, ChromaStacks.lumenGem, 50, ChromaStacks.glowChunk, 10};
		parent.generateLootChest(x+2, y+7, z+5, ForgeDirection.SOUTH, ChestGenHooks.STRONGHOLD_CROSSING, 0, items);
		parent.generateLootChest(x+2, y+7, z+9, ForgeDirection.NORTH, ChestGenHooks.STRONGHOLD_CROSSING, 0, items);

		for (int i = 0; i < 3; i++) {
			for (int h = 0; h < 3; h++) {
				parent.addBreakable(x+1+i, y+1+h, z);
				parent.addBreakable(x+1+i, y+1+h, z+14);
			}
		}

		for (int i = -1; i <= 1; i++) {
			for (int j = -1; j <= 1; j++) {
				for (int k = -1; k <= 1; k++) {
					world.setBlock(x+6+i, y+2+j, z+7+k, Blocks.air);
				}
			}
		}
		world.setBlock(x+6, y+4, z+7, Blocks.air);

		this.placeCore(x+6, y+2, z+7);

		world.setBlock(x+0, y+0, z+0, b, BlockType.STONE.metadata);
		world.setBlock(x+0, y+0, z+1, b, BlockType.STONE.metadata);
		world.setBlock(x+0, y+0, z+2, b, BlockType.STONE.metadata);
		world.setBlock(x+0, y+0, z+3, b, BlockType.STONE.metadata);
		world.setBlock(x+0, y+0, z+4, b, BlockType.STONE.metadata);
		world.setBlock(x+0, y+0, z+5, b, BlockType.STONE.metadata);
		world.setBlock(x+0, y+0, z+6, b, BlockType.STONE.metadata);
		world.setBlock(x+0, y+0, z+7, b, BlockType.STONE.metadata);
		world.setBlock(x+0, y+0, z+8, b, BlockType.STONE.metadata);
		world.setBlock(x+0, y+0, z+9, b, BlockType.STONE.metadata);
		world.setBlock(x+0, y+0, z+10, b, BlockType.STONE.metadata);
		world.setBlock(x+0, y+0, z+11, b, BlockType.STONE.metadata);
		world.setBlock(x+0, y+0, z+12, b, BlockType.STONE.metadata);
		world.setBlock(x+0, y+0, z+13, b, BlockType.STONE.metadata);
		world.setBlock(x+0, y+0, z+14, b, BlockType.STONE.metadata);
		world.setBlock(x+0, y+1, z+0, b, BlockType.STONE.metadata);
		world.setBlock(x+0, y+1, z+1, b, BlockType.STONE.metadata);
		world.setBlock(x+0, y+1, z+2, b, BlockType.STONE.metadata);
		world.setBlock(x+0, y+1, z+3, b, BlockType.STONE.metadata);
		world.setBlock(x+0, y+1, z+4, b, BlockType.STONE.metadata);
		world.setBlock(x+0, y+1, z+10, b, BlockType.STONE.metadata);
		world.setBlock(x+0, y+1, z+11, b, BlockType.STONE.metadata);
		world.setBlock(x+0, y+1, z+12, b, BlockType.STONE.metadata);
		world.setBlock(x+0, y+1, z+13, b, BlockType.STONE.metadata);
		world.setBlock(x+0, y+1, z+14, b, BlockType.STONE.metadata);
		world.setBlock(x+0, y+2, z+0, b, BlockType.STONE.metadata);
		world.setBlock(x+0, y+2, z+1, b, BlockType.STONE.metadata);
		world.setBlock(x+0, y+2, z+2, b, BlockType.STONE.metadata);
		world.setBlock(x+0, y+2, z+3, b, BlockType.STONE.metadata);
		world.setBlock(x+0, y+2, z+4, b, BlockType.STONE.metadata);
		world.setBlock(x+0, y+2, z+10, b, BlockType.STONE.metadata);
		world.setBlock(x+0, y+2, z+11, b, BlockType.STONE.metadata);
		world.setBlock(x+0, y+2, z+12, b, BlockType.STONE.metadata);
		world.setBlock(x+0, y+2, z+13, b, BlockType.STONE.metadata);
		world.setBlock(x+0, y+2, z+14, b, BlockType.STONE.metadata);
		world.setBlock(x+0, y+3, z+0, b, BlockType.STONE.metadata);
		world.setBlock(x+0, y+3, z+1, b, BlockType.STONE.metadata);
		world.setBlock(x+0, y+3, z+2, b, BlockType.STONE.metadata);
		world.setBlock(x+0, y+3, z+3, b, BlockType.STONE.metadata);
		world.setBlock(x+0, y+3, z+4, b, BlockType.STONE.metadata);
		world.setBlock(x+0, y+3, z+10, b, BlockType.STONE.metadata);
		world.setBlock(x+0, y+3, z+11, b, BlockType.STONE.metadata);
		world.setBlock(x+0, y+3, z+12, b, BlockType.STONE.metadata);
		world.setBlock(x+0, y+3, z+13, b, BlockType.STONE.metadata);
		world.setBlock(x+0, y+3, z+14, b, BlockType.STONE.metadata);
		world.setBlock(x+0, y+4, z+0, b, BlockType.STONE.metadata);
		world.setBlock(x+0, y+4, z+1, b, BlockType.STONE.metadata);
		world.setBlock(x+0, y+4, z+2, b, BlockType.STONE.metadata);
		world.setBlock(x+0, y+4, z+3, b, BlockType.STONE.metadata);
		world.setBlock(x+0, y+4, z+4, b, BlockType.STONE.metadata);
		world.setBlock(x+0, y+4, z+5, b, BlockType.STONE.metadata);
		world.setBlock(x+0, y+4, z+6, b, BlockType.STONE.metadata);
		world.setBlock(x+0, y+4, z+7, b, BlockType.STONE.metadata);
		world.setBlock(x+0, y+4, z+8, b, BlockType.STONE.metadata);
		world.setBlock(x+0, y+4, z+9, b, BlockType.STONE.metadata);
		world.setBlock(x+0, y+4, z+10, b, BlockType.STONE.metadata);
		world.setBlock(x+0, y+4, z+11, b, BlockType.STONE.metadata);
		world.setBlock(x+0, y+4, z+12, b, BlockType.STONE.metadata);
		world.setBlock(x+0, y+4, z+13, b, BlockType.STONE.metadata);
		world.setBlock(x+0, y+4, z+14, b, BlockType.STONE.metadata);
		world.setBlock(x+0, y+5, z+4, b, BlockType.STONE.metadata);
		world.setBlock(x+0, y+5, z+5, b, BlockType.STONE.metadata);
		world.setBlock(x+0, y+5, z+6, b, BlockType.STONE.metadata);
		world.setBlock(x+0, y+5, z+7, b, BlockType.STONE.metadata);
		world.setBlock(x+0, y+5, z+8, b, BlockType.STONE.metadata);
		world.setBlock(x+0, y+5, z+9, b, BlockType.STONE.metadata);
		world.setBlock(x+0, y+5, z+10, b, BlockType.STONE.metadata);
		world.setBlock(x+0, y+6, z+4, b, BlockType.STONE.metadata);
		world.setBlock(x+0, y+6, z+5, b, BlockType.STONE.metadata);
		world.setBlock(x+0, y+6, z+6, b, BlockType.STONE.metadata);
		world.setBlock(x+0, y+6, z+7, b, BlockType.STONE.metadata);
		world.setBlock(x+0, y+6, z+8, b, BlockType.STONE.metadata);
		world.setBlock(x+0, y+6, z+9, b, BlockType.STONE.metadata);
		world.setBlock(x+0, y+6, z+10, b, BlockType.STONE.metadata);
		world.setBlock(x+0, y+7, z+4, b, BlockType.STONE.metadata);
		world.setBlock(x+0, y+7, z+5, b, BlockType.STONE.metadata);
		world.setBlock(x+0, y+7, z+6, b, BlockType.STONE.metadata);
		world.setBlock(x+0, y+7, z+7, b, BlockType.STONE.metadata);
		world.setBlock(x+0, y+7, z+8, b, BlockType.STONE.metadata);
		world.setBlock(x+0, y+7, z+9, b, BlockType.STONE.metadata);
		world.setBlock(x+0, y+7, z+10, b, BlockType.STONE.metadata);
		world.setBlock(x+0, y+8, z+4, b, BlockType.STONE.metadata);
		world.setBlock(x+0, y+8, z+5, b, BlockType.STONE.metadata);
		world.setBlock(x+0, y+8, z+6, b, BlockType.STONE.metadata);
		world.setBlock(x+0, y+8, z+7, b, BlockType.STONE.metadata);
		world.setBlock(x+0, y+8, z+8, b, BlockType.STONE.metadata);
		world.setBlock(x+0, y+8, z+9, b, BlockType.STONE.metadata);
		world.setBlock(x+0, y+8, z+10, b, BlockType.STONE.metadata);
		world.setBlock(x+0, y+9, z+4, b, BlockType.STONE.metadata);
		world.setBlock(x+0, y+9, z+5, b, BlockType.STONE.metadata);
		world.setBlock(x+0, y+9, z+6, b, BlockType.STONE.metadata);
		world.setBlock(x+0, y+9, z+7, b, BlockType.STONE.metadata);
		world.setBlock(x+0, y+9, z+8, b, BlockType.STONE.metadata);
		world.setBlock(x+0, y+9, z+9, b, BlockType.STONE.metadata);
		world.setBlock(x+0, y+9, z+10, b, BlockType.STONE.metadata);
		world.setBlock(x+1, y+0, z+0, b, BlockType.STONE.metadata);
		world.setBlock(x+1, y+0, z+1, b, BlockType.STONE.metadata);
		world.setBlock(x+1, y+0, z+2, b, BlockType.STONE.metadata);
		world.setBlock(x+1, y+0, z+3, b, BlockType.STONE.metadata);
		world.setBlock(x+1, y+0, z+4, b, BlockType.STONE.metadata);
		world.setBlock(x+1, y+0, z+5, b, BlockType.STONE.metadata);
		world.setBlock(x+1, y+0, z+6, b, BlockType.STONE.metadata);
		world.setBlock(x+1, y+0, z+7, b, BlockType.STONE.metadata);
		world.setBlock(x+1, y+0, z+8, b, BlockType.STONE.metadata);
		world.setBlock(x+1, y+0, z+9, b, BlockType.STONE.metadata);
		world.setBlock(x+1, y+0, z+10, b, BlockType.STONE.metadata);
		world.setBlock(x+1, y+0, z+11, b, BlockType.STONE.metadata);
		world.setBlock(x+1, y+0, z+12, b, BlockType.STONE.metadata);
		world.setBlock(x+1, y+0, z+13, b, BlockType.STONE.metadata);
		world.setBlock(x+1, y+0, z+14, b, BlockType.STONE.metadata);
		world.setBlock(x+1, y+1, z+0, b, BlockType.STONE.metadata);
		world.setBlock(x+1, y+1, z+14, b, BlockType.STONE.metadata);
		world.setBlock(x+1, y+2, z+0, b, BlockType.STONE.metadata);
		world.setBlock(x+1, y+2, z+14, b, BlockType.STONE.metadata);
		world.setBlock(x+1, y+3, z+0, b, BlockType.STONE.metadata);
		world.setBlock(x+1, y+3, z+14, b, BlockType.STONE.metadata);
		world.setBlock(x+1, y+4, z+0, b, BlockType.STONE.metadata);
		world.setBlock(x+1, y+4, z+1, b, BlockType.STONE.metadata);
		world.setBlock(x+1, y+4, z+2, b, BlockType.STONE.metadata);
		world.setBlock(x+1, y+4, z+3, b, BlockType.STONE.metadata);
		world.setBlock(x+1, y+4, z+4, b, BlockType.STONE.metadata);
		world.setBlock(x+1, y+4, z+5, b, BlockType.STONE.metadata);
		world.setBlock(x+1, y+4, z+6, b, BlockType.GLASS.metadata);
		world.setBlock(x+1, y+4, z+7, b, BlockType.GLASS.metadata);
		world.setBlock(x+1, y+4, z+8, b, BlockType.GLASS.metadata);
		world.setBlock(x+1, y+4, z+9, b, BlockType.STONE.metadata);
		world.setBlock(x+1, y+4, z+10, b, BlockType.STONE.metadata);
		world.setBlock(x+1, y+4, z+11, b, BlockType.STONE.metadata);
		world.setBlock(x+1, y+4, z+12, b, BlockType.STONE.metadata);
		world.setBlock(x+1, y+4, z+13, b, BlockType.STONE.metadata);
		world.setBlock(x+1, y+4, z+14, b, BlockType.STONE.metadata);
		world.setBlock(x+1, y+5, z+4, b, BlockType.STONE.metadata);
		world.setBlock(x+1, y+5, z+5, b, BlockType.STONE.metadata);
		world.setBlock(x+1, y+5, z+6, b, BlockType.CRACKS.metadata);
		world.setBlock(x+1, y+5, z+7, b, BlockType.CRACKS.metadata);
		world.setBlock(x+1, y+5, z+8, b, BlockType.CRACKS.metadata);
		world.setBlock(x+1, y+5, z+9, b, BlockType.STONE.metadata);
		world.setBlock(x+1, y+5, z+10, b, BlockType.STONE.metadata);
		world.setBlock(x+1, y+6, z+4, b, BlockType.STONE.metadata);
		world.setBlock(x+1, y+6, z+5, b, BlockType.STONE.metadata);
		world.setBlock(x+1, y+6, z+9, b, BlockType.STONE.metadata);
		world.setBlock(x+1, y+6, z+10, b, BlockType.STONE.metadata);
		world.setBlock(x+1, y+7, z+4, b, BlockType.STONE.metadata);
		world.setBlock(x+1, y+7, z+5, b, BlockType.STONE.metadata);
		world.setBlock(x+1, y+7, z+9, b, BlockType.STONE.metadata);
		world.setBlock(x+1, y+7, z+10, b, BlockType.STONE.metadata);
		world.setBlock(x+1, y+8, z+4, b, BlockType.STONE.metadata);
		world.setBlock(x+1, y+8, z+5, b, BlockType.STONE.metadata);
		world.setBlock(x+1, y+8, z+9, b, BlockType.STONE.metadata);
		world.setBlock(x+1, y+8, z+10, b, BlockType.STONE.metadata);
		world.setBlock(x+1, y+9, z+4, b, BlockType.STONE.metadata);
		world.setBlock(x+1, y+9, z+5, b, BlockType.STONE.metadata);
		world.setBlock(x+1, y+9, z+6, b, BlockType.STONE.metadata);
		world.setBlock(x+1, y+9, z+7, b, BlockType.STONE.metadata);
		world.setBlock(x+1, y+9, z+8, b, BlockType.STONE.metadata);
		world.setBlock(x+1, y+9, z+9, b, BlockType.STONE.metadata);
		world.setBlock(x+1, y+9, z+10, b, BlockType.STONE.metadata);
		world.setBlock(x+2, y+0, z+0, b, BlockType.STONE.metadata);
		world.setBlock(x+2, y+0, z+1, b, BlockType.STONE.metadata);
		world.setBlock(x+2, y+0, z+2, b, BlockType.STONE.metadata);
		world.setBlock(x+2, y+0, z+3, b, BlockType.STONE.metadata);
		world.setBlock(x+2, y+0, z+4, b, BlockType.STONE.metadata);
		world.setBlock(x+2, y+0, z+5, b, BlockType.STONE.metadata);
		world.setBlock(x+2, y+0, z+6, b, BlockType.STONE.metadata);
		world.setBlock(x+2, y+0, z+7, b, BlockType.LIGHT.metadata);
		world.setBlock(x+2, y+0, z+8, b, BlockType.STONE.metadata);
		world.setBlock(x+2, y+0, z+9, b, BlockType.STONE.metadata);
		world.setBlock(x+2, y+0, z+10, b, BlockType.STONE.metadata);
		world.setBlock(x+2, y+0, z+11, b, BlockType.STONE.metadata);
		world.setBlock(x+2, y+0, z+12, b, BlockType.STONE.metadata);
		world.setBlock(x+2, y+0, z+13, b, BlockType.STONE.metadata);
		world.setBlock(x+2, y+0, z+14, b, BlockType.STONE.metadata);
		world.setBlock(x+2, y+1, z+0, b, BlockType.STONE.metadata);
		world.setBlock(x+2, y+1, z+14, b, BlockType.STONE.metadata);
		world.setBlock(x+2, y+2, z+0, b, BlockType.STONE.metadata);
		world.setBlock(x+2, y+2, z+14, b, BlockType.STONE.metadata);
		world.setBlock(x+2, y+3, z+0, b, BlockType.STONE.metadata);
		world.setBlock(x+2, y+3, z+14, b, BlockType.STONE.metadata);
		world.setBlock(x+2, y+4, z+0, b, BlockType.STONE.metadata);
		world.setBlock(x+2, y+4, z+1, b, BlockType.STONE.metadata);
		world.setBlock(x+2, y+4, z+2, b, BlockType.LIGHT.metadata);
		world.setBlock(x+2, y+4, z+3, b, BlockType.STONE.metadata);
		world.setBlock(x+2, y+4, z+4, b, BlockType.STONE.metadata);
		world.setBlock(x+2, y+4, z+5, b, BlockType.STONE.metadata);
		world.setBlock(x+2, y+4, z+6, b, BlockType.GLASS.metadata);
		world.setBlock(x+2, y+4, z+7, b, BlockType.GLASS.metadata);
		world.setBlock(x+2, y+4, z+8, b, BlockType.GLASS.metadata);
		world.setBlock(x+2, y+4, z+9, b, BlockType.STONE.metadata);
		world.setBlock(x+2, y+4, z+10, b, BlockType.STONE.metadata);
		world.setBlock(x+2, y+4, z+11, b, BlockType.STONE.metadata);
		world.setBlock(x+2, y+4, z+12, b, BlockType.LIGHT.metadata);
		world.setBlock(x+2, y+4, z+13, b, BlockType.STONE.metadata);
		world.setBlock(x+2, y+4, z+14, b, BlockType.STONE.metadata);
		world.setBlock(x+2, y+5, z+4, b, BlockType.STONE.metadata);
		world.setBlock(x+2, y+5, z+5, b, BlockType.STONE.metadata);
		world.setBlock(x+2, y+5, z+6, b, BlockType.CRACKS.metadata);
		world.setBlock(x+2, y+5, z+7, b, BlockType.CRACKS.metadata);
		world.setBlock(x+2, y+5, z+8, b, BlockType.CRACKS.metadata);
		world.setBlock(x+2, y+5, z+9, b, BlockType.STONE.metadata);
		world.setBlock(x+2, y+5, z+10, b, BlockType.STONE.metadata);
		world.setBlock(x+2, y+6, z+4, b, BlockType.STONE.metadata);
		world.setBlock(x+2, y+6, z+5, b, BlockType.STONE.metadata);
		world.setBlock(x+2, y+6, z+9, b, BlockType.STONE.metadata);
		world.setBlock(x+2, y+6, z+10, b, BlockType.STONE.metadata);
		world.setBlock(x+2, y+7, z+4, b, BlockType.LIGHT.metadata);
		world.setBlock(x+2, y+7, z+10, b, BlockType.LIGHT.metadata);
		world.setBlock(x+2, y+8, z+4, b, BlockType.STONE.metadata);
		world.setBlock(x+2, y+8, z+5, b, BlockType.CRACK.metadata);
		world.setBlock(x+2, y+8, z+9, b, BlockType.CRACK.metadata);
		world.setBlock(x+2, y+8, z+10, b, BlockType.STONE.metadata);
		world.setBlock(x+2, y+9, z+4, b, BlockType.STONE.metadata);
		world.setBlock(x+2, y+9, z+5, b, BlockType.STONE.metadata);
		world.setBlock(x+2, y+9, z+6, b, BlockType.STONE.metadata);
		world.setBlock(x+2, y+9, z+7, b, BlockType.STONE.metadata);
		world.setBlock(x+2, y+9, z+8, b, BlockType.STONE.metadata);
		world.setBlock(x+2, y+9, z+9, b, BlockType.STONE.metadata);
		world.setBlock(x+2, y+9, z+10, b, BlockType.STONE.metadata);
		world.setBlock(x+3, y+0, z+0, b, BlockType.STONE.metadata);
		world.setBlock(x+3, y+0, z+1, b, BlockType.STONE.metadata);
		world.setBlock(x+3, y+0, z+2, b, BlockType.STONE.metadata);
		world.setBlock(x+3, y+0, z+3, b, BlockType.STONE.metadata);
		world.setBlock(x+3, y+0, z+4, b, BlockType.STONE.metadata);
		world.setBlock(x+3, y+0, z+5, b, BlockType.STONE.metadata);
		world.setBlock(x+3, y+0, z+6, b, BlockType.STONE.metadata);
		world.setBlock(x+3, y+0, z+7, b, BlockType.STONE.metadata);
		world.setBlock(x+3, y+0, z+8, b, BlockType.STONE.metadata);
		world.setBlock(x+3, y+0, z+9, b, BlockType.STONE.metadata);
		world.setBlock(x+3, y+0, z+10, b, BlockType.STONE.metadata);
		world.setBlock(x+3, y+0, z+11, b, BlockType.STONE.metadata);
		world.setBlock(x+3, y+0, z+12, b, BlockType.STONE.metadata);
		world.setBlock(x+3, y+0, z+13, b, BlockType.STONE.metadata);
		world.setBlock(x+3, y+0, z+14, b, BlockType.STONE.metadata);
		world.setBlock(x+3, y+1, z+0, b, BlockType.STONE.metadata);
		world.setBlock(x+3, y+1, z+14, b, BlockType.STONE.metadata);
		world.setBlock(x+3, y+2, z+0, b, BlockType.STONE.metadata);
		world.setBlock(x+3, y+2, z+14, b, BlockType.STONE.metadata);
		world.setBlock(x+3, y+3, z+0, b, BlockType.STONE.metadata);
		world.setBlock(x+3, y+3, z+14, b, BlockType.STONE.metadata);
		world.setBlock(x+3, y+4, z+0, b, BlockType.STONE.metadata);
		world.setBlock(x+3, y+4, z+1, b, BlockType.STONE.metadata);
		world.setBlock(x+3, y+4, z+2, b, BlockType.STONE.metadata);
		world.setBlock(x+3, y+4, z+3, b, BlockType.STONE.metadata);
		world.setBlock(x+3, y+4, z+4, b, BlockType.STONE.metadata);
		world.setBlock(x+3, y+4, z+5, b, BlockType.STONE.metadata);
		world.setBlock(x+3, y+4, z+6, b, BlockType.GLASS.metadata);
		world.setBlock(x+3, y+4, z+7, b, BlockType.GLASS.metadata);
		world.setBlock(x+3, y+4, z+8, b, BlockType.GLASS.metadata);
		world.setBlock(x+3, y+4, z+9, b, BlockType.STONE.metadata);
		world.setBlock(x+3, y+4, z+10, b, BlockType.STONE.metadata);
		world.setBlock(x+3, y+4, z+11, b, BlockType.STONE.metadata);
		world.setBlock(x+3, y+4, z+12, b, BlockType.STONE.metadata);
		world.setBlock(x+3, y+4, z+13, b, BlockType.STONE.metadata);
		world.setBlock(x+3, y+4, z+14, b, BlockType.STONE.metadata);
		world.setBlock(x+3, y+5, z+4, b, BlockType.STONE.metadata);
		world.setBlock(x+3, y+5, z+5, b, BlockType.STONE.metadata);
		world.setBlock(x+3, y+5, z+6, b, BlockType.CRACKS.metadata);
		world.setBlock(x+3, y+5, z+7, b, BlockType.CRACKS.metadata);
		world.setBlock(x+3, y+5, z+8, b, BlockType.CRACKS.metadata);
		world.setBlock(x+3, y+5, z+9, b, BlockType.STONE.metadata);
		world.setBlock(x+3, y+5, z+10, b, BlockType.STONE.metadata);
		world.setBlock(x+3, y+6, z+4, b, BlockType.STONE.metadata);
		world.setBlock(x+3, y+6, z+5, b, BlockType.STONE.metadata);
		world.setBlock(x+3, y+6, z+9, b, BlockType.STONE.metadata);
		world.setBlock(x+3, y+6, z+10, b, BlockType.STONE.metadata);
		world.setBlock(x+3, y+7, z+4, b, BlockType.STONE.metadata);
		world.setBlock(x+3, y+7, z+5, b, BlockType.STONE.metadata);
		world.setBlock(x+3, y+7, z+9, b, BlockType.STONE.metadata);
		world.setBlock(x+3, y+7, z+10, b, BlockType.STONE.metadata);
		world.setBlock(x+3, y+8, z+4, b, BlockType.STONE.metadata);
		world.setBlock(x+3, y+8, z+5, b, BlockType.STONE.metadata);
		world.setBlock(x+3, y+8, z+9, b, BlockType.STONE.metadata);
		world.setBlock(x+3, y+8, z+10, b, BlockType.STONE.metadata);
		world.setBlock(x+3, y+9, z+4, b, BlockType.STONE.metadata);
		world.setBlock(x+3, y+9, z+5, b, BlockType.STONE.metadata);
		world.setBlock(x+3, y+9, z+6, b, BlockType.STONE.metadata);
		world.setBlock(x+3, y+9, z+7, b, BlockType.STONE.metadata);
		world.setBlock(x+3, y+9, z+8, b, BlockType.STONE.metadata);
		world.setBlock(x+3, y+9, z+9, b, BlockType.STONE.metadata);
		world.setBlock(x+3, y+9, z+10, b, BlockType.STONE.metadata);
		world.setBlock(x+4, y+0, z+0, b, BlockType.STONE.metadata);
		world.setBlock(x+4, y+0, z+1, b, BlockType.STONE.metadata);
		world.setBlock(x+4, y+0, z+2, b, BlockType.STONE.metadata);
		world.setBlock(x+4, y+0, z+3, b, BlockType.STONE.metadata);
		world.setBlock(x+4, y+0, z+4, b, BlockType.STONE.metadata);
		world.setBlock(x+4, y+0, z+5, b, BlockType.STONE.metadata);
		world.setBlock(x+4, y+0, z+6, b, BlockType.CLOAK.metadata);
		world.setBlock(x+4, y+0, z+7, b, BlockType.CLOAK.metadata);
		world.setBlock(x+4, y+0, z+8, b, BlockType.CLOAK.metadata);
		world.setBlock(x+4, y+0, z+9, b, BlockType.STONE.metadata);
		world.setBlock(x+4, y+0, z+10, b, BlockType.STONE.metadata);
		world.setBlock(x+4, y+0, z+11, b, BlockType.STONE.metadata);
		world.setBlock(x+4, y+0, z+12, b, BlockType.STONE.metadata);
		world.setBlock(x+4, y+0, z+13, b, BlockType.STONE.metadata);
		world.setBlock(x+4, y+0, z+14, b, BlockType.STONE.metadata);
		world.setBlock(x+4, y+1, z+0, b, BlockType.STONE.metadata);
		world.setBlock(x+4, y+1, z+4, b, BlockType.STONE.metadata);
		world.setBlock(x+4, y+1, z+5, b, BlockType.STONE.metadata);
		world.setBlock(x+4, y+1, z+6, b, BlockType.GLASS.metadata);
		world.setBlock(x+4, y+1, z+7, b, BlockType.GLASS.metadata);
		world.setBlock(x+4, y+1, z+8, b, BlockType.GLASS.metadata);
		world.setBlock(x+4, y+1, z+9, b, BlockType.STONE.metadata);
		world.setBlock(x+4, y+1, z+10, b, BlockType.STONE.metadata);
		world.setBlock(x+4, y+1, z+14, b, BlockType.STONE.metadata);
		world.setBlock(x+4, y+2, z+0, b, BlockType.STONE.metadata);
		world.setBlock(x+4, y+2, z+4, b, BlockType.STONE.metadata);
		world.setBlock(x+4, y+2, z+5, b, BlockType.STONE.metadata);
		world.setBlock(x+4, y+2, z+6, b, BlockType.GLASS.metadata);
		world.setBlock(x+4, y+2, z+7, b, BlockType.GLASS.metadata);
		world.setBlock(x+4, y+2, z+8, b, BlockType.GLASS.metadata);
		world.setBlock(x+4, y+2, z+9, b, BlockType.STONE.metadata);
		world.setBlock(x+4, y+2, z+10, b, BlockType.STONE.metadata);
		world.setBlock(x+4, y+2, z+14, b, BlockType.STONE.metadata);
		world.setBlock(x+4, y+3, z+0, b, BlockType.STONE.metadata);
		world.setBlock(x+4, y+3, z+4, b, BlockType.STONE.metadata);
		world.setBlock(x+4, y+3, z+5, b, BlockType.STONE.metadata);
		world.setBlock(x+4, y+3, z+6, b, BlockType.GLASS.metadata);
		world.setBlock(x+4, y+3, z+7, b, BlockType.GLASS.metadata);
		world.setBlock(x+4, y+3, z+8, b, BlockType.GLASS.metadata);
		world.setBlock(x+4, y+3, z+9, b, BlockType.STONE.metadata);
		world.setBlock(x+4, y+3, z+10, b, BlockType.STONE.metadata);
		world.setBlock(x+4, y+3, z+14, b, BlockType.STONE.metadata);
		world.setBlock(x+4, y+4, z+0, b, BlockType.STONE.metadata);
		world.setBlock(x+4, y+4, z+4, b, BlockType.STONE.metadata);
		world.setBlock(x+4, y+4, z+5, b, BlockType.STONE.metadata);
		world.setBlock(x+4, y+4, z+6, b, BlockType.STONE.metadata);
		world.setBlock(x+4, y+4, z+7, b, BlockType.STONE.metadata);
		world.setBlock(x+4, y+4, z+8, b, BlockType.STONE.metadata);
		world.setBlock(x+4, y+4, z+9, b, BlockType.STONE.metadata);
		world.setBlock(x+4, y+4, z+10, b, BlockType.STONE.metadata);
		world.setBlock(x+4, y+4, z+11, b, BlockType.STONE.metadata);
		world.setBlock(x+4, y+4, z+12, b, BlockType.STONE.metadata);
		world.setBlock(x+4, y+4, z+13, b, BlockType.STONE.metadata);
		world.setBlock(x+4, y+4, z+14, b, BlockType.STONE.metadata);
		world.setBlock(x+4, y+5, z+0, b, BlockType.STONE.metadata);
		world.setBlock(x+4, y+5, z+1, b, BlockType.STONE.metadata);
		world.setBlock(x+4, y+5, z+2, b, BlockType.STONE.metadata);
		world.setBlock(x+4, y+5, z+3, b, BlockType.STONE.metadata);
		world.setBlock(x+4, y+5, z+4, b, BlockType.STONE.metadata);
		world.setBlock(x+4, y+5, z+5, b, BlockType.STONE.metadata);
		world.setBlock(x+4, y+5, z+6, b, BlockType.STONE.metadata);
		world.setBlock(x+4, y+5, z+7, b, BlockType.STONE.metadata);
		world.setBlock(x+4, y+5, z+8, b, BlockType.STONE.metadata);
		world.setBlock(x+4, y+5, z+9, b, BlockType.STONE.metadata);
		world.setBlock(x+4, y+5, z+10, b, BlockType.STONE.metadata);
		world.setBlock(x+4, y+5, z+11, b, BlockType.STONE.metadata);
		world.setBlock(x+4, y+5, z+12, b, BlockType.STONE.metadata);
		world.setBlock(x+4, y+5, z+13, b, BlockType.STONE.metadata);
		world.setBlock(x+4, y+5, z+14, b, BlockType.STONE.metadata);
		world.setBlock(x+4, y+6, z+0, b, BlockType.STONE.metadata);
		world.setBlock(x+4, y+6, z+1, b, BlockType.STONE.metadata);
		world.setBlock(x+4, y+6, z+2, b, BlockType.STONE.metadata);
		world.setBlock(x+4, y+6, z+3, b, BlockType.STONE.metadata);
		world.setBlock(x+4, y+6, z+4, b, BlockType.STONE.metadata);
		world.setBlock(x+4, y+6, z+5, b, BlockType.STONE.metadata);
		world.setBlock(x+4, y+6, z+6, b, BlockType.CRACKS.metadata);
		world.setBlock(x+4, y+6, z+7, b, BlockType.CRACKS.metadata);
		world.setBlock(x+4, y+6, z+8, b, BlockType.CRACKS.metadata);
		world.setBlock(x+4, y+6, z+9, b, BlockType.STONE.metadata);
		world.setBlock(x+4, y+6, z+10, b, BlockType.STONE.metadata);
		world.setBlock(x+4, y+6, z+11, b, BlockType.STONE.metadata);
		world.setBlock(x+4, y+6, z+12, b, BlockType.STONE.metadata);
		world.setBlock(x+4, y+6, z+13, b, BlockType.STONE.metadata);
		world.setBlock(x+4, y+6, z+14, b, BlockType.STONE.metadata);
		world.setBlock(x+4, y+7, z+0, b, BlockType.STONE.metadata);
		world.setBlock(x+4, y+7, z+1, b, BlockType.STONE.metadata);
		world.setBlock(x+4, y+7, z+2, b, BlockType.LIGHT.metadata);
		world.setBlock(x+4, y+7, z+3, b, BlockType.STONE.metadata);
		world.setBlock(x+4, y+7, z+4, b, BlockType.STONE.metadata);
		world.setBlock(x+4, y+7, z+5, b, BlockType.STONE.metadata);
		world.setBlock(x+4, y+7, z+6, b, BlockType.CRACKS.metadata);
		world.setBlock(x+4, y+7, z+7, b, BlockType.CRACKS.metadata);
		world.setBlock(x+4, y+7, z+8, b, BlockType.CRACKS.metadata);
		world.setBlock(x+4, y+7, z+9, b, BlockType.STONE.metadata);
		world.setBlock(x+4, y+7, z+10, b, BlockType.STONE.metadata);
		world.setBlock(x+4, y+7, z+11, b, BlockType.STONE.metadata);
		world.setBlock(x+4, y+7, z+12, b, BlockType.LIGHT.metadata);
		world.setBlock(x+4, y+7, z+13, b, BlockType.STONE.metadata);
		world.setBlock(x+4, y+7, z+14, b, BlockType.STONE.metadata);
		world.setBlock(x+4, y+8, z+0, b, BlockType.STONE.metadata);
		world.setBlock(x+4, y+8, z+1, b, BlockType.STONE.metadata);
		world.setBlock(x+4, y+8, z+2, b, BlockType.STONE.metadata);
		world.setBlock(x+4, y+8, z+3, b, BlockType.STONE.metadata);
		world.setBlock(x+4, y+8, z+4, b, BlockType.STONE.metadata);
		world.setBlock(x+4, y+8, z+5, b, BlockType.STONE.metadata);
		world.setBlock(x+4, y+8, z+6, b, BlockType.CRACKS.metadata);
		world.setBlock(x+4, y+8, z+7, b, BlockType.CRACKS.metadata);
		world.setBlock(x+4, y+8, z+8, b, BlockType.CRACKS.metadata);
		world.setBlock(x+4, y+8, z+9, b, BlockType.STONE.metadata);
		world.setBlock(x+4, y+8, z+10, b, BlockType.STONE.metadata);
		world.setBlock(x+4, y+8, z+11, b, BlockType.STONE.metadata);
		world.setBlock(x+4, y+8, z+12, b, BlockType.STONE.metadata);
		world.setBlock(x+4, y+8, z+13, b, BlockType.STONE.metadata);
		world.setBlock(x+4, y+8, z+14, b, BlockType.STONE.metadata);
		world.setBlock(x+4, y+9, z+0, b, BlockType.STONE.metadata);
		world.setBlock(x+4, y+9, z+1, b, BlockType.STONE.metadata);
		world.setBlock(x+4, y+9, z+2, b, BlockType.STONE.metadata);
		world.setBlock(x+4, y+9, z+3, b, BlockType.STONE.metadata);
		world.setBlock(x+4, y+9, z+4, b, BlockType.STONE.metadata);
		world.setBlock(x+4, y+9, z+5, b, BlockType.STONE.metadata);
		world.setBlock(x+4, y+9, z+6, b, BlockType.STONE.metadata);
		world.setBlock(x+4, y+9, z+7, b, BlockType.STONE.metadata);
		world.setBlock(x+4, y+9, z+8, b, BlockType.STONE.metadata);
		world.setBlock(x+4, y+9, z+9, b, BlockType.STONE.metadata);
		world.setBlock(x+4, y+9, z+10, b, BlockType.STONE.metadata);
		world.setBlock(x+4, y+9, z+11, b, BlockType.STONE.metadata);
		world.setBlock(x+4, y+9, z+12, b, BlockType.STONE.metadata);
		world.setBlock(x+4, y+9, z+13, b, BlockType.STONE.metadata);
		world.setBlock(x+4, y+9, z+14, b, BlockType.STONE.metadata);
		world.setBlock(x+5, y+0, z+0, b, BlockType.STONE.metadata);
		world.setBlock(x+5, y+0, z+1, b, BlockType.STONE.metadata);
		world.setBlock(x+5, y+0, z+2, b, BlockType.STONE.metadata);
		world.setBlock(x+5, y+0, z+3, b, BlockType.STONE.metadata);
		world.setBlock(x+5, y+0, z+4, b, BlockType.STONE.metadata);
		world.setBlock(x+5, y+0, z+5, b, BlockType.CLOAK.metadata);
		world.setBlock(x+5, y+0, z+6, b, BlockType.CLOAK.metadata);
		world.setBlock(x+5, y+0, z+7, b, BlockType.CLOAK.metadata);
		world.setBlock(x+5, y+0, z+8, b, BlockType.CLOAK.metadata);
		world.setBlock(x+5, y+0, z+9, b, BlockType.CLOAK.metadata);
		world.setBlock(x+5, y+0, z+10, b, BlockType.STONE.metadata);
		world.setBlock(x+5, y+0, z+11, b, BlockType.STONE.metadata);
		world.setBlock(x+5, y+0, z+12, b, BlockType.STONE.metadata);
		world.setBlock(x+5, y+0, z+13, b, BlockType.STONE.metadata);
		world.setBlock(x+5, y+0, z+14, b, BlockType.STONE.metadata);
		world.setBlock(x+5, y+1, z+0, b, BlockType.STONE.metadata);
		world.setBlock(x+5, y+1, z+1, b, BlockType.STONE.metadata);
		world.setBlock(x+5, y+1, z+2, b, BlockType.STONE.metadata);
		world.setBlock(x+5, y+1, z+3, b, BlockType.STONE.metadata);
		world.setBlock(x+5, y+1, z+4, b, BlockType.STONE.metadata);
		world.setBlock(x+5, y+1, z+5, b, BlockType.CLOAK.metadata);
		world.setBlock(x+5, y+1, z+9, b, BlockType.CLOAK.metadata);
		world.setBlock(x+5, y+1, z+10, b, BlockType.STONE.metadata);
		world.setBlock(x+5, y+1, z+11, b, BlockType.STONE.metadata);
		world.setBlock(x+5, y+1, z+12, b, BlockType.STONE.metadata);
		world.setBlock(x+5, y+1, z+13, b, BlockType.STONE.metadata);
		world.setBlock(x+5, y+1, z+14, b, BlockType.STONE.metadata);
		world.setBlock(x+5, y+2, z+0, b, BlockType.STONE.metadata);
		world.setBlock(x+5, y+2, z+4, b, BlockType.STONE.metadata);
		world.setBlock(x+5, y+2, z+5, b, BlockType.CLOAK.metadata);
		world.setBlock(x+5, y+2, z+9, b, BlockType.CLOAK.metadata);
		world.setBlock(x+5, y+2, z+10, b, BlockType.STONE.metadata);
		world.setBlock(x+5, y+2, z+14, b, BlockType.STONE.metadata);
		world.setBlock(x+5, y+3, z+0, b, BlockType.STONE.metadata);
		world.setBlock(x+5, y+3, z+4, b, BlockType.STONE.metadata);
		world.setBlock(x+5, y+3, z+5, b, BlockType.CLOAK.metadata);
		world.setBlock(x+5, y+3, z+9, b, BlockType.CLOAK.metadata);
		world.setBlock(x+5, y+3, z+10, b, BlockType.STONE.metadata);
		world.setBlock(x+5, y+3, z+14, b, BlockType.STONE.metadata);
		world.setBlock(x+5, y+4, z+0, b, BlockType.STONE.metadata);
		world.setBlock(x+5, y+4, z+4, b, BlockType.STONE.metadata);
		world.setBlock(x+5, y+4, z+5, b, BlockType.STONE.metadata);
		world.setBlock(x+5, y+4, z+6, b, BlockType.CLOAK.metadata);
		world.setBlock(x+5, y+4, z+7, b, BlockType.CLOAK.metadata);
		world.setBlock(x+5, y+4, z+8, b, BlockType.CLOAK.metadata);
		world.setBlock(x+5, y+4, z+9, b, BlockType.STONE.metadata);
		world.setBlock(x+5, y+4, z+10, b, BlockType.STONE.metadata);
		world.setBlock(x+5, y+4, z+14, b, BlockType.STONE.metadata);
		world.setBlock(x+5, y+5, z+0, b, BlockType.STONE.metadata);
		world.setBlock(x+5, y+5, z+4, b, BlockType.STONE.metadata);
		world.setBlock(x+5, y+5, z+5, b, BlockType.STONE.metadata);
		world.setBlock(x+5, y+5, z+6, b, BlockType.CRACKS.metadata);
		world.setBlock(x+5, y+5, z+7, b, BlockType.CRACKS.metadata);
		world.setBlock(x+5, y+5, z+8, b, BlockType.CRACKS.metadata);
		world.setBlock(x+5, y+5, z+9, b, BlockType.STONE.metadata);
		world.setBlock(x+5, y+5, z+10, b, BlockType.STONE.metadata);
		world.setBlock(x+5, y+5, z+14, b, BlockType.STONE.metadata);
		world.setBlock(x+5, y+6, z+0, b, BlockType.STONE.metadata);
		world.setBlock(x+5, y+6, z+4, b, BlockType.GLASS.metadata);
		world.setBlock(x+5, y+6, z+5, b, BlockType.GLASS.metadata);
		world.setBlock(x+5, y+6, z+9, b, BlockType.GLASS.metadata);
		world.setBlock(x+5, y+6, z+10, b, BlockType.GLASS.metadata);
		world.setBlock(x+5, y+6, z+14, b, BlockType.STONE.metadata);
		world.setBlock(x+5, y+7, z+0, b, BlockType.STONE.metadata);
		world.setBlock(x+5, y+7, z+4, b, BlockType.GLASS.metadata);
		world.setBlock(x+5, y+7, z+5, b, BlockType.GLASS.metadata);
		world.setBlock(x+5, y+7, z+9, b, BlockType.GLASS.metadata);
		world.setBlock(x+5, y+7, z+10, b, BlockType.GLASS.metadata);
		world.setBlock(x+5, y+7, z+14, b, BlockType.STONE.metadata);
		world.setBlock(x+5, y+8, z+0, b, BlockType.STONE.metadata);
		world.setBlock(x+5, y+8, z+4, b, BlockType.GLASS.metadata);
		world.setBlock(x+5, y+8, z+5, b, BlockType.GLASS.metadata);
		world.setBlock(x+5, y+8, z+9, b, BlockType.GLASS.metadata);
		world.setBlock(x+5, y+8, z+10, b, BlockType.GLASS.metadata);
		world.setBlock(x+5, y+8, z+14, b, BlockType.STONE.metadata);
		world.setBlock(x+5, y+9, z+0, b, BlockType.STONE.metadata);
		world.setBlock(x+5, y+9, z+1, b, BlockType.STONE.metadata);
		world.setBlock(x+5, y+9, z+2, b, BlockType.STONE.metadata);
		world.setBlock(x+5, y+9, z+3, b, BlockType.STONE.metadata);
		world.setBlock(x+5, y+9, z+4, b, BlockType.STONE.metadata);
		world.setBlock(x+5, y+9, z+5, b, BlockType.STONE.metadata);
		world.setBlock(x+5, y+9, z+6, b, BlockType.STONE.metadata);
		world.setBlock(x+5, y+9, z+7, b, BlockType.STONE.metadata);
		world.setBlock(x+5, y+9, z+8, b, BlockType.STONE.metadata);
		world.setBlock(x+5, y+9, z+9, b, BlockType.STONE.metadata);
		world.setBlock(x+5, y+9, z+10, b, BlockType.STONE.metadata);
		world.setBlock(x+5, y+9, z+11, b, BlockType.STONE.metadata);
		world.setBlock(x+5, y+9, z+12, b, BlockType.STONE.metadata);
		world.setBlock(x+5, y+9, z+13, b, BlockType.STONE.metadata);
		world.setBlock(x+5, y+9, z+14, b, BlockType.STONE.metadata);
		world.setBlock(x+6, y+0, z+0, b, BlockType.STONE.metadata);
		world.setBlock(x+6, y+0, z+1, b, BlockType.STONE.metadata);
		world.setBlock(x+6, y+0, z+2, b, BlockType.STONE.metadata);
		world.setBlock(x+6, y+0, z+3, b, BlockType.STONE.metadata);
		world.setBlock(x+6, y+0, z+4, b, BlockType.STONE.metadata);
		world.setBlock(x+6, y+0, z+5, b, BlockType.CLOAK.metadata);
		world.setBlock(x+6, y+0, z+6, b, BlockType.CLOAK.metadata);
		world.setBlock(x+6, y+0, z+7, b, BlockType.CLOAK.metadata);
		world.setBlock(x+6, y+0, z+8, b, BlockType.CLOAK.metadata);
		world.setBlock(x+6, y+0, z+9, b, BlockType.CLOAK.metadata);
		world.setBlock(x+6, y+0, z+10, b, BlockType.STONE.metadata);
		world.setBlock(x+6, y+0, z+11, b, BlockType.STONE.metadata);
		world.setBlock(x+6, y+0, z+12, b, BlockType.STONE.metadata);
		world.setBlock(x+6, y+0, z+13, b, BlockType.STONE.metadata);
		world.setBlock(x+6, y+0, z+14, b, BlockType.STONE.metadata);
		world.setBlock(x+6, y+1, z+0, b, BlockType.STONE.metadata);
		world.setBlock(x+6, y+1, z+4, b, BlockType.STONE.metadata);
		world.setBlock(x+6, y+1, z+5, b, BlockType.CLOAK.metadata);
		world.setBlock(x+6, y+1, z+9, b, BlockType.CLOAK.metadata);
		world.setBlock(x+6, y+1, z+10, b, BlockType.STONE.metadata);
		world.setBlock(x+6, y+1, z+14, b, BlockType.STONE.metadata);
		world.setBlock(x+6, y+2, z+0, b, BlockType.STONE.metadata);
		world.setBlock(x+6, y+2, z+1, b, BlockType.STONE.metadata);
		world.setBlock(x+6, y+2, z+2, b, BlockType.STONE.metadata);
		world.setBlock(x+6, y+2, z+3, b, BlockType.STONE.metadata);
		world.setBlock(x+6, y+2, z+4, b, BlockType.STONE.metadata);
		world.setBlock(x+6, y+2, z+5, b, BlockType.CLOAK.metadata);
		world.setBlock(x+6, y+2, z+9, b, BlockType.CLOAK.metadata);
		world.setBlock(x+6, y+2, z+10, b, BlockType.STONE.metadata);
		world.setBlock(x+6, y+2, z+11, b, BlockType.STONE.metadata);
		world.setBlock(x+6, y+2, z+12, b, BlockType.STONE.metadata);
		world.setBlock(x+6, y+2, z+13, b, BlockType.STONE.metadata);
		world.setBlock(x+6, y+2, z+14, b, BlockType.STONE.metadata);
		world.setBlock(x+6, y+3, z+0, b, BlockType.STONE.metadata);
		world.setBlock(x+6, y+3, z+4, b, BlockType.STONE.metadata);
		world.setBlock(x+6, y+3, z+5, b, BlockType.CLOAK.metadata);
		world.setBlock(x+6, y+3, z+9, b, BlockType.CLOAK.metadata);
		world.setBlock(x+6, y+3, z+10, b, BlockType.STONE.metadata);
		world.setBlock(x+6, y+3, z+14, b, BlockType.STONE.metadata);
		world.setBlock(x+6, y+4, z+0, b, BlockType.STONE.metadata);
		world.setBlock(x+6, y+4, z+4, b, BlockType.LIGHT.metadata);
		world.setBlock(x+6, y+4, z+5, b, BlockType.CLOAK.metadata);
		world.setBlock(x+6, y+4, z+6, b, BlockType.CLOAK.metadata);
		world.setBlock(x+6, y+4, z+8, b, BlockType.CLOAK.metadata);
		world.setBlock(x+6, y+4, z+9, b, BlockType.STONE.metadata);
		world.setBlock(x+6, y+4, z+10, b, BlockType.LIGHT.metadata);
		world.setBlock(x+6, y+4, z+14, b, BlockType.STONE.metadata);
		world.setBlock(x+6, y+5, z+0, b, BlockType.STONE.metadata);
		world.setBlock(x+6, y+5, z+4, b, BlockType.STONE.metadata);
		world.setBlock(x+6, y+5, z+5, b, BlockType.STONE.metadata);
		world.setBlock(x+6, y+5, z+6, b, BlockType.CRACKS.metadata);
		world.setBlock(x+6, y+5, z+7, b, BlockType.CRACKS.metadata);
		world.setBlock(x+6, y+5, z+8, b, BlockType.CRACKS.metadata);
		world.setBlock(x+6, y+5, z+9, b, BlockType.STONE.metadata);
		world.setBlock(x+6, y+5, z+10, b, BlockType.STONE.metadata);
		world.setBlock(x+6, y+5, z+14, b, BlockType.STONE.metadata);
		world.setBlock(x+6, y+6, z+0, b, BlockType.STONE.metadata);
		world.setBlock(x+6, y+6, z+4, b, BlockType.GLASS.metadata);
		world.setBlock(x+6, y+6, z+5, b, BlockType.GLASS.metadata);
		world.setBlock(x+6, y+6, z+9, b, BlockType.GLASS.metadata);
		world.setBlock(x+6, y+6, z+10, b, BlockType.GLASS.metadata);
		world.setBlock(x+6, y+6, z+14, b, BlockType.STONE.metadata);
		world.setBlock(x+6, y+7, z+0, b, BlockType.STONE.metadata);
		world.setBlock(x+6, y+7, z+4, b, BlockType.GLASS.metadata);
		world.setBlock(x+6, y+7, z+5, b, BlockType.GLASS.metadata);
		world.setBlock(x+6, y+7, z+9, b, BlockType.GLASS.metadata);
		world.setBlock(x+6, y+7, z+10, b, BlockType.GLASS.metadata);
		world.setBlock(x+6, y+7, z+14, b, BlockType.STONE.metadata);
		world.setBlock(x+6, y+8, z+0, b, BlockType.STONE.metadata);
		world.setBlock(x+6, y+8, z+4, b, BlockType.GLASS.metadata);
		world.setBlock(x+6, y+8, z+5, b, BlockType.GLASS.metadata);
		world.setBlock(x+6, y+8, z+9, b, BlockType.GLASS.metadata);
		world.setBlock(x+6, y+8, z+10, b, BlockType.GLASS.metadata);
		world.setBlock(x+6, y+8, z+14, b, BlockType.STONE.metadata);
		world.setBlock(x+6, y+9, z+0, b, BlockType.STONE.metadata);
		world.setBlock(x+6, y+9, z+1, b, BlockType.STONE.metadata);
		world.setBlock(x+6, y+9, z+2, b, BlockType.STONE.metadata);
		world.setBlock(x+6, y+9, z+3, b, BlockType.STONE.metadata);
		world.setBlock(x+6, y+9, z+4, b, BlockType.STONE.metadata);
		world.setBlock(x+6, y+9, z+5, b, BlockType.STONE.metadata);
		world.setBlock(x+6, y+9, z+6, b, BlockType.STONE.metadata);
		world.setBlock(x+6, y+9, z+7, b, BlockType.LIGHT.metadata);
		world.setBlock(x+6, y+9, z+8, b, BlockType.STONE.metadata);
		world.setBlock(x+6, y+9, z+9, b, BlockType.STONE.metadata);
		world.setBlock(x+6, y+9, z+10, b, BlockType.STONE.metadata);
		world.setBlock(x+6, y+9, z+11, b, BlockType.STONE.metadata);
		world.setBlock(x+6, y+9, z+12, b, BlockType.STONE.metadata);
		world.setBlock(x+6, y+9, z+13, b, BlockType.STONE.metadata);
		world.setBlock(x+6, y+9, z+14, b, BlockType.STONE.metadata);
		world.setBlock(x+7, y+0, z+0, b, BlockType.STONE.metadata);
		world.setBlock(x+7, y+0, z+1, b, BlockType.STONE.metadata);
		world.setBlock(x+7, y+0, z+2, b, BlockType.STONE.metadata);
		world.setBlock(x+7, y+0, z+3, b, BlockType.STONE.metadata);
		world.setBlock(x+7, y+0, z+4, b, BlockType.STONE.metadata);
		world.setBlock(x+7, y+0, z+5, b, BlockType.CLOAK.metadata);
		world.setBlock(x+7, y+0, z+6, b, BlockType.CLOAK.metadata);
		world.setBlock(x+7, y+0, z+7, b, BlockType.CLOAK.metadata);
		world.setBlock(x+7, y+0, z+8, b, BlockType.CLOAK.metadata);
		world.setBlock(x+7, y+0, z+9, b, BlockType.CLOAK.metadata);
		world.setBlock(x+7, y+0, z+10, b, BlockType.STONE.metadata);
		world.setBlock(x+7, y+0, z+11, b, BlockType.STONE.metadata);
		world.setBlock(x+7, y+0, z+12, b, BlockType.STONE.metadata);
		world.setBlock(x+7, y+0, z+13, b, BlockType.STONE.metadata);
		world.setBlock(x+7, y+0, z+14, b, BlockType.STONE.metadata);
		world.setBlock(x+7, y+1, z+0, b, BlockType.STONE.metadata);
		world.setBlock(x+7, y+1, z+4, b, BlockType.STONE.metadata);
		world.setBlock(x+7, y+1, z+5, b, BlockType.CLOAK.metadata);
		world.setBlock(x+7, y+1, z+9, b, BlockType.CLOAK.metadata);
		world.setBlock(x+7, y+1, z+10, b, BlockType.STONE.metadata);
		world.setBlock(x+7, y+1, z+14, b, BlockType.STONE.metadata);
		world.setBlock(x+7, y+2, z+0, b, BlockType.STONE.metadata);
		world.setBlock(x+7, y+2, z+4, b, BlockType.STONE.metadata);
		world.setBlock(x+7, y+2, z+5, b, BlockType.CLOAK.metadata);
		world.setBlock(x+7, y+2, z+9, b, BlockType.CLOAK.metadata);
		world.setBlock(x+7, y+2, z+10, b, BlockType.STONE.metadata);
		world.setBlock(x+7, y+2, z+14, b, BlockType.STONE.metadata);
		world.setBlock(x+7, y+3, z+0, b, BlockType.STONE.metadata);
		world.setBlock(x+7, y+3, z+1, b, BlockType.STONE.metadata);
		world.setBlock(x+7, y+3, z+2, b, BlockType.STONE.metadata);
		world.setBlock(x+7, y+3, z+3, b, BlockType.STONE.metadata);
		world.setBlock(x+7, y+3, z+4, b, BlockType.STONE.metadata);
		world.setBlock(x+7, y+3, z+5, b, BlockType.CLOAK.metadata);
		world.setBlock(x+7, y+3, z+9, b, BlockType.CLOAK.metadata);
		world.setBlock(x+7, y+3, z+10, b, BlockType.STONE.metadata);
		world.setBlock(x+7, y+3, z+11, b, BlockType.STONE.metadata);
		world.setBlock(x+7, y+3, z+12, b, BlockType.STONE.metadata);
		world.setBlock(x+7, y+3, z+13, b, BlockType.STONE.metadata);
		world.setBlock(x+7, y+3, z+14, b, BlockType.STONE.metadata);
		world.setBlock(x+7, y+4, z+0, b, BlockType.STONE.metadata);
		world.setBlock(x+7, y+4, z+4, b, BlockType.STONE.metadata);
		world.setBlock(x+7, y+4, z+5, b, BlockType.STONE.metadata);
		world.setBlock(x+7, y+4, z+6, b, BlockType.CLOAK.metadata);
		world.setBlock(x+7, y+4, z+7, b, BlockType.CLOAK.metadata);
		world.setBlock(x+7, y+4, z+8, b, BlockType.CLOAK.metadata);
		world.setBlock(x+7, y+4, z+9, b, BlockType.STONE.metadata);
		world.setBlock(x+7, y+4, z+10, b, BlockType.STONE.metadata);
		world.setBlock(x+7, y+4, z+14, b, BlockType.STONE.metadata);
		world.setBlock(x+7, y+5, z+0, b, BlockType.STONE.metadata);
		world.setBlock(x+7, y+5, z+4, b, BlockType.STONE.metadata);
		world.setBlock(x+7, y+5, z+5, b, BlockType.STONE.metadata);
		world.setBlock(x+7, y+5, z+6, b, BlockType.CRACKS.metadata);
		world.setBlock(x+7, y+5, z+7, b, BlockType.CRACKS.metadata);
		world.setBlock(x+7, y+5, z+8, b, BlockType.CRACKS.metadata);
		world.setBlock(x+7, y+5, z+9, b, BlockType.STONE.metadata);
		world.setBlock(x+7, y+5, z+10, b, BlockType.STONE.metadata);
		world.setBlock(x+7, y+5, z+14, b, BlockType.STONE.metadata);
		world.setBlock(x+7, y+6, z+0, b, BlockType.STONE.metadata);
		world.setBlock(x+7, y+6, z+4, b, BlockType.GLASS.metadata);
		world.setBlock(x+7, y+6, z+5, b, BlockType.GLASS.metadata);
		world.setBlock(x+7, y+6, z+9, b, BlockType.GLASS.metadata);
		world.setBlock(x+7, y+6, z+10, b, BlockType.GLASS.metadata);
		world.setBlock(x+7, y+6, z+14, b, BlockType.STONE.metadata);
		world.setBlock(x+7, y+7, z+0, b, BlockType.STONE.metadata);
		world.setBlock(x+7, y+7, z+4, b, BlockType.GLASS.metadata);
		world.setBlock(x+7, y+7, z+5, b, BlockType.GLASS.metadata);
		world.setBlock(x+7, y+7, z+9, b, BlockType.GLASS.metadata);
		world.setBlock(x+7, y+7, z+10, b, BlockType.GLASS.metadata);
		world.setBlock(x+7, y+7, z+14, b, BlockType.STONE.metadata);
		world.setBlock(x+7, y+8, z+0, b, BlockType.STONE.metadata);
		world.setBlock(x+7, y+8, z+4, b, BlockType.GLASS.metadata);
		world.setBlock(x+7, y+8, z+5, b, BlockType.GLASS.metadata);
		world.setBlock(x+7, y+8, z+9, b, BlockType.GLASS.metadata);
		world.setBlock(x+7, y+8, z+10, b, BlockType.GLASS.metadata);
		world.setBlock(x+7, y+8, z+14, b, BlockType.STONE.metadata);
		world.setBlock(x+7, y+9, z+0, b, BlockType.STONE.metadata);
		world.setBlock(x+7, y+9, z+1, b, BlockType.STONE.metadata);
		world.setBlock(x+7, y+9, z+2, b, BlockType.STONE.metadata);
		world.setBlock(x+7, y+9, z+3, b, BlockType.STONE.metadata);
		world.setBlock(x+7, y+9, z+4, b, BlockType.STONE.metadata);
		world.setBlock(x+7, y+9, z+5, b, BlockType.STONE.metadata);
		world.setBlock(x+7, y+9, z+6, b, BlockType.STONE.metadata);
		world.setBlock(x+7, y+9, z+7, b, BlockType.STONE.metadata);
		world.setBlock(x+7, y+9, z+8, b, BlockType.STONE.metadata);
		world.setBlock(x+7, y+9, z+9, b, BlockType.STONE.metadata);
		world.setBlock(x+7, y+9, z+10, b, BlockType.STONE.metadata);
		world.setBlock(x+7, y+9, z+11, b, BlockType.STONE.metadata);
		world.setBlock(x+7, y+9, z+12, b, BlockType.STONE.metadata);
		world.setBlock(x+7, y+9, z+13, b, BlockType.STONE.metadata);
		world.setBlock(x+7, y+9, z+14, b, BlockType.STONE.metadata);
		world.setBlock(x+8, y+0, z+0, b, BlockType.STONE.metadata);
		world.setBlock(x+8, y+0, z+1, b, BlockType.STONE.metadata);
		world.setBlock(x+8, y+0, z+2, b, BlockType.STONE.metadata);
		world.setBlock(x+8, y+0, z+3, b, BlockType.STONE.metadata);
		world.setBlock(x+8, y+0, z+4, b, BlockType.STONE.metadata);
		world.setBlock(x+8, y+0, z+5, b, BlockType.CLOAK.metadata);
		world.setBlock(x+8, y+0, z+6, b, BlockType.CLOAK.metadata);
		world.setBlock(x+8, y+0, z+7, b, BlockType.CLOAK.metadata);
		world.setBlock(x+8, y+0, z+8, b, BlockType.CLOAK.metadata);
		world.setBlock(x+8, y+0, z+9, b, BlockType.CLOAK.metadata);
		world.setBlock(x+8, y+0, z+10, b, BlockType.STONE.metadata);
		world.setBlock(x+8, y+0, z+11, b, BlockType.STONE.metadata);
		world.setBlock(x+8, y+0, z+12, b, BlockType.STONE.metadata);
		world.setBlock(x+8, y+0, z+13, b, BlockType.STONE.metadata);
		world.setBlock(x+8, y+0, z+14, b, BlockType.STONE.metadata);
		world.setBlock(x+8, y+1, z+0, b, BlockType.STONE.metadata);
		world.setBlock(x+8, y+1, z+4, b, BlockType.STONE.metadata);
		world.setBlock(x+8, y+1, z+5, b, BlockType.CLOAK.metadata);
		world.setBlock(x+8, y+1, z+6, b, BlockType.CLOAK.metadata);
		world.setBlock(x+8, y+1, z+7, b, BlockType.CLOAK.metadata);
		world.setBlock(x+8, y+1, z+8, b, BlockType.CLOAK.metadata);
		world.setBlock(x+8, y+1, z+9, b, BlockType.CLOAK.metadata);
		world.setBlock(x+8, y+1, z+10, b, BlockType.STONE.metadata);
		world.setBlock(x+8, y+1, z+14, b, BlockType.STONE.metadata);
		world.setBlock(x+8, y+2, z+0, b, BlockType.STONE.metadata);
		world.setBlock(x+8, y+2, z+4, b, BlockType.STONE.metadata);
		world.setBlock(x+8, y+2, z+5, b, BlockType.CLOAK.metadata);
		world.setBlock(x+8, y+2, z+6, b, BlockType.CLOAK.metadata);
		world.setBlock(x+8, y+2, z+7, b, BlockType.CLOAK.metadata);
		world.setBlock(x+8, y+2, z+8, b, BlockType.CLOAK.metadata);
		world.setBlock(x+8, y+2, z+9, b, BlockType.CLOAK.metadata);
		world.setBlock(x+8, y+2, z+10, b, BlockType.STONE.metadata);
		world.setBlock(x+8, y+2, z+14, b, BlockType.STONE.metadata);
		world.setBlock(x+8, y+3, z+0, b, BlockType.STONE.metadata);
		world.setBlock(x+8, y+3, z+4, b, BlockType.STONE.metadata);
		world.setBlock(x+8, y+3, z+5, b, BlockType.CLOAK.metadata);
		world.setBlock(x+8, y+3, z+6, b, BlockType.CLOAK.metadata);
		world.setBlock(x+8, y+3, z+7, b, BlockType.CLOAK.metadata);
		world.setBlock(x+8, y+3, z+8, b, BlockType.CLOAK.metadata);
		world.setBlock(x+8, y+3, z+9, b, BlockType.CLOAK.metadata);
		world.setBlock(x+8, y+3, z+10, b, BlockType.STONE.metadata);
		world.setBlock(x+8, y+3, z+14, b, BlockType.STONE.metadata);
		world.setBlock(x+8, y+4, z+0, b, BlockType.STONE.metadata);
		world.setBlock(x+8, y+4, z+1, b, BlockType.STONE.metadata);
		world.setBlock(x+8, y+4, z+2, b, BlockType.STONE.metadata);
		world.setBlock(x+8, y+4, z+3, b, BlockType.STONE.metadata);
		world.setBlock(x+8, y+4, z+4, b, BlockType.STONE.metadata);
		world.setBlock(x+8, y+4, z+5, b, BlockType.STONE.metadata);
		world.setBlock(x+8, y+4, z+6, b, BlockType.STONE.metadata);
		world.setBlock(x+8, y+4, z+7, b, BlockType.STONE.metadata);
		world.setBlock(x+8, y+4, z+8, b, BlockType.STONE.metadata);
		world.setBlock(x+8, y+4, z+9, b, BlockType.STONE.metadata);
		world.setBlock(x+8, y+4, z+10, b, BlockType.STONE.metadata);
		world.setBlock(x+8, y+4, z+11, b, BlockType.STONE.metadata);
		world.setBlock(x+8, y+4, z+12, b, BlockType.STONE.metadata);
		world.setBlock(x+8, y+4, z+13, b, BlockType.STONE.metadata);
		world.setBlock(x+8, y+4, z+14, b, BlockType.STONE.metadata);
		world.setBlock(x+8, y+5, z+0, b, BlockType.STONE.metadata);
		world.setBlock(x+8, y+5, z+4, b, BlockType.STONE.metadata);
		world.setBlock(x+8, y+5, z+5, b, BlockType.STONE.metadata);
		world.setBlock(x+8, y+5, z+6, b, BlockType.STONE.metadata);
		world.setBlock(x+8, y+5, z+7, b, BlockType.STONE.metadata);
		world.setBlock(x+8, y+5, z+8, b, BlockType.STONE.metadata);
		world.setBlock(x+8, y+5, z+9, b, BlockType.STONE.metadata);
		world.setBlock(x+8, y+5, z+10, b, BlockType.STONE.metadata);
		world.setBlock(x+8, y+5, z+14, b, BlockType.STONE.metadata);
		world.setBlock(x+8, y+6, z+0, b, BlockType.STONE.metadata);
		world.setBlock(x+8, y+6, z+4, b, BlockType.STONE.metadata);
		world.setBlock(x+8, y+6, z+5, b, BlockType.STONE.metadata);
		world.setBlock(x+8, y+6, z+9, b, BlockType.STONE.metadata);
		world.setBlock(x+8, y+6, z+10, b, BlockType.STONE.metadata);
		world.setBlock(x+8, y+6, z+14, b, BlockType.STONE.metadata);
		world.setBlock(x+8, y+7, z+0, b, BlockType.STONE.metadata);
		world.setBlock(x+8, y+7, z+4, b, BlockType.STONE.metadata);
		world.setBlock(x+8, y+7, z+5, b, BlockType.STONE.metadata);
		world.setBlock(x+8, y+7, z+9, b, BlockType.STONE.metadata);
		world.setBlock(x+8, y+7, z+10, b, BlockType.STONE.metadata);
		world.setBlock(x+8, y+7, z+14, b, BlockType.STONE.metadata);
		world.setBlock(x+8, y+8, z+0, b, BlockType.STONE.metadata);
		world.setBlock(x+8, y+8, z+4, b, BlockType.STONE.metadata);
		world.setBlock(x+8, y+8, z+5, b, BlockType.STONE.metadata);
		world.setBlock(x+8, y+8, z+9, b, BlockType.STONE.metadata);
		world.setBlock(x+8, y+8, z+10, b, BlockType.STONE.metadata);
		world.setBlock(x+8, y+8, z+14, b, BlockType.STONE.metadata);
		world.setBlock(x+8, y+9, z+0, b, BlockType.STONE.metadata);
		world.setBlock(x+8, y+9, z+1, b, BlockType.STONE.metadata);
		world.setBlock(x+8, y+9, z+2, b, BlockType.STONE.metadata);
		world.setBlock(x+8, y+9, z+3, b, BlockType.STONE.metadata);
		world.setBlock(x+8, y+9, z+4, b, BlockType.STONE.metadata);
		world.setBlock(x+8, y+9, z+5, b, BlockType.STONE.metadata);
		world.setBlock(x+8, y+9, z+6, b, BlockType.STONE.metadata);
		world.setBlock(x+8, y+9, z+7, b, BlockType.STONE.metadata);
		world.setBlock(x+8, y+9, z+8, b, BlockType.STONE.metadata);
		world.setBlock(x+8, y+9, z+9, b, BlockType.STONE.metadata);
		world.setBlock(x+8, y+9, z+10, b, BlockType.STONE.metadata);
		world.setBlock(x+8, y+9, z+11, b, BlockType.STONE.metadata);
		world.setBlock(x+8, y+9, z+12, b, BlockType.STONE.metadata);
		world.setBlock(x+8, y+9, z+13, b, BlockType.STONE.metadata);
		world.setBlock(x+8, y+9, z+14, b, BlockType.STONE.metadata);
		world.setBlock(x+9, y+5, z+0, b, BlockType.STONE.metadata);
		world.setBlock(x+9, y+5, z+1, b, BlockType.STONE.metadata);
		world.setBlock(x+9, y+5, z+2, b, BlockType.STONE.metadata);
		world.setBlock(x+9, y+5, z+3, b, BlockType.STONE.metadata);
		world.setBlock(x+9, y+5, z+4, b, BlockType.STONE.metadata);
		world.setBlock(x+9, y+5, z+5, b, BlockType.STONE.metadata);
		world.setBlock(x+9, y+5, z+6, b, BlockType.STONE.metadata);
		world.setBlock(x+9, y+5, z+7, b, BlockType.STONE.metadata);
		world.setBlock(x+9, y+5, z+8, b, BlockType.STONE.metadata);
		world.setBlock(x+9, y+5, z+9, b, BlockType.STONE.metadata);
		world.setBlock(x+9, y+5, z+10, b, BlockType.STONE.metadata);
		world.setBlock(x+9, y+5, z+11, b, BlockType.STONE.metadata);
		world.setBlock(x+9, y+5, z+12, b, BlockType.STONE.metadata);
		world.setBlock(x+9, y+5, z+13, b, BlockType.STONE.metadata);
		world.setBlock(x+9, y+5, z+14, b, BlockType.STONE.metadata);
		world.setBlock(x+9, y+6, z+0, b, BlockType.STONE.metadata);
		world.setBlock(x+9, y+6, z+14, b, BlockType.STONE.metadata);
		world.setBlock(x+9, y+7, z+0, b, BlockType.STONE.metadata);
		world.setBlock(x+9, y+7, z+14, b, BlockType.STONE.metadata);
		world.setBlock(x+9, y+8, z+0, b, BlockType.STONE.metadata);
		world.setBlock(x+9, y+8, z+14, b, BlockType.STONE.metadata);
		world.setBlock(x+9, y+9, z+0, b, BlockType.STONE.metadata);
		world.setBlock(x+9, y+9, z+1, b, BlockType.STONE.metadata);
		world.setBlock(x+9, y+9, z+2, b, BlockType.STONE.metadata);
		world.setBlock(x+9, y+9, z+3, b, BlockType.STONE.metadata);
		world.setBlock(x+9, y+9, z+4, b, BlockType.STONE.metadata);
		world.setBlock(x+9, y+9, z+5, b, BlockType.STONE.metadata);
		world.setBlock(x+9, y+9, z+6, b, BlockType.STONE.metadata);
		world.setBlock(x+9, y+9, z+7, b, BlockType.STONE.metadata);
		world.setBlock(x+9, y+9, z+8, b, BlockType.STONE.metadata);
		world.setBlock(x+9, y+9, z+9, b, BlockType.STONE.metadata);
		world.setBlock(x+9, y+9, z+10, b, BlockType.STONE.metadata);
		world.setBlock(x+9, y+9, z+11, b, BlockType.STONE.metadata);
		world.setBlock(x+9, y+9, z+12, b, BlockType.STONE.metadata);
		world.setBlock(x+9, y+9, z+13, b, BlockType.STONE.metadata);
		world.setBlock(x+9, y+9, z+14, b, BlockType.STONE.metadata);
		world.setBlock(x+10, y+5, z+0, b, BlockType.STONE.metadata);
		world.setBlock(x+10, y+5, z+1, b, BlockType.STONE.metadata);
		world.setBlock(x+10, y+5, z+2, b, BlockType.LIGHT.metadata);
		world.setBlock(x+10, y+5, z+3, b, BlockType.STONE.metadata);
		world.setBlock(x+10, y+5, z+4, b, BlockType.STONE.metadata);
		world.setBlock(x+10, y+5, z+5, b, BlockType.STONE.metadata);
		world.setBlock(x+10, y+5, z+6, b, BlockType.STONE.metadata);
		world.setBlock(x+10, y+5, z+7, b, BlockType.STONE.metadata);
		world.setBlock(x+10, y+5, z+8, b, BlockType.STONE.metadata);
		world.setBlock(x+10, y+5, z+9, b, BlockType.STONE.metadata);
		world.setBlock(x+10, y+5, z+10, b, BlockType.STONE.metadata);
		world.setBlock(x+10, y+5, z+11, b, BlockType.STONE.metadata);
		world.setBlock(x+10, y+5, z+12, b, BlockType.LIGHT.metadata);
		world.setBlock(x+10, y+5, z+13, b, BlockType.STONE.metadata);
		world.setBlock(x+10, y+5, z+14, b, BlockType.STONE.metadata);
		world.setBlock(x+10, y+6, z+0, b, BlockType.STONE.metadata);
		world.setBlock(x+10, y+6, z+14, b, BlockType.STONE.metadata);
		world.setBlock(x+10, y+7, z+0, b, BlockType.STONE.metadata);
		world.setBlock(x+10, y+7, z+14, b, BlockType.STONE.metadata);
		world.setBlock(x+10, y+8, z+0, b, BlockType.STONE.metadata);
		world.setBlock(x+10, y+8, z+14, b, BlockType.STONE.metadata);
		world.setBlock(x+10, y+9, z+0, b, BlockType.STONE.metadata);
		world.setBlock(x+10, y+9, z+1, b, BlockType.STONE.metadata);
		world.setBlock(x+10, y+9, z+2, b, BlockType.STONE.metadata);
		world.setBlock(x+10, y+9, z+3, b, BlockType.STONE.metadata);
		world.setBlock(x+10, y+9, z+4, b, BlockType.STONE.metadata);
		world.setBlock(x+10, y+9, z+5, b, BlockType.STONE.metadata);
		world.setBlock(x+10, y+9, z+6, b, BlockType.STONE.metadata);
		world.setBlock(x+10, y+9, z+7, b, BlockType.STONE.metadata);
		world.setBlock(x+10, y+9, z+8, b, BlockType.STONE.metadata);
		world.setBlock(x+10, y+9, z+9, b, BlockType.STONE.metadata);
		world.setBlock(x+10, y+9, z+10, b, BlockType.STONE.metadata);
		world.setBlock(x+10, y+9, z+11, b, BlockType.STONE.metadata);
		world.setBlock(x+10, y+9, z+12, b, BlockType.STONE.metadata);
		world.setBlock(x+10, y+9, z+13, b, BlockType.STONE.metadata);
		world.setBlock(x+10, y+9, z+14, b, BlockType.STONE.metadata);
		world.setBlock(x+11, y+5, z+0, b, BlockType.STONE.metadata);
		world.setBlock(x+11, y+5, z+1, b, BlockType.STONE.metadata);
		world.setBlock(x+11, y+5, z+2, b, BlockType.STONE.metadata);
		world.setBlock(x+11, y+5, z+3, b, BlockType.STONE.metadata);
		world.setBlock(x+11, y+5, z+4, b, BlockType.STONE.metadata);
		world.setBlock(x+11, y+5, z+5, b, BlockType.STONE.metadata);
		world.setBlock(x+11, y+5, z+6, b, BlockType.STONE.metadata);
		world.setBlock(x+11, y+5, z+7, b, BlockType.STONE.metadata);
		world.setBlock(x+11, y+5, z+8, b, BlockType.STONE.metadata);
		world.setBlock(x+11, y+5, z+9, b, BlockType.STONE.metadata);
		world.setBlock(x+11, y+5, z+10, b, BlockType.STONE.metadata);
		world.setBlock(x+11, y+5, z+11, b, BlockType.STONE.metadata);
		world.setBlock(x+11, y+5, z+12, b, BlockType.STONE.metadata);
		world.setBlock(x+11, y+5, z+13, b, BlockType.STONE.metadata);
		world.setBlock(x+11, y+5, z+14, b, BlockType.STONE.metadata);
		world.setBlock(x+11, y+6, z+0, b, BlockType.STONE.metadata);
		world.setBlock(x+11, y+6, z+14, b, BlockType.STONE.metadata);
		world.setBlock(x+11, y+7, z+0, b, BlockType.STONE.metadata);
		world.setBlock(x+11, y+7, z+14, b, BlockType.STONE.metadata);
		world.setBlock(x+11, y+8, z+0, b, BlockType.STONE.metadata);
		world.setBlock(x+11, y+8, z+14, b, BlockType.STONE.metadata);
		world.setBlock(x+11, y+9, z+0, b, BlockType.STONE.metadata);
		world.setBlock(x+11, y+9, z+1, b, BlockType.STONE.metadata);
		world.setBlock(x+11, y+9, z+2, b, BlockType.STONE.metadata);
		world.setBlock(x+11, y+9, z+3, b, BlockType.STONE.metadata);
		world.setBlock(x+11, y+9, z+4, b, BlockType.STONE.metadata);
		world.setBlock(x+11, y+9, z+5, b, BlockType.STONE.metadata);
		world.setBlock(x+11, y+9, z+6, b, BlockType.STONE.metadata);
		world.setBlock(x+11, y+9, z+7, b, BlockType.STONE.metadata);
		world.setBlock(x+11, y+9, z+8, b, BlockType.STONE.metadata);
		world.setBlock(x+11, y+9, z+9, b, BlockType.STONE.metadata);
		world.setBlock(x+11, y+9, z+10, b, BlockType.STONE.metadata);
		world.setBlock(x+11, y+9, z+11, b, BlockType.STONE.metadata);
		world.setBlock(x+11, y+9, z+12, b, BlockType.STONE.metadata);
		world.setBlock(x+11, y+9, z+13, b, BlockType.STONE.metadata);
		world.setBlock(x+11, y+9, z+14, b, BlockType.STONE.metadata);
		world.setBlock(x+12, y+5, z+0, b, BlockType.STONE.metadata);
		world.setBlock(x+12, y+5, z+1, b, BlockType.STONE.metadata);
		world.setBlock(x+12, y+5, z+2, b, BlockType.STONE.metadata);
		world.setBlock(x+12, y+5, z+3, b, BlockType.STONE.metadata);
		world.setBlock(x+12, y+5, z+4, b, BlockType.STONE.metadata);
		world.setBlock(x+12, y+5, z+5, b, BlockType.STONE.metadata);
		world.setBlock(x+12, y+5, z+6, b, BlockType.STONE.metadata);
		world.setBlock(x+12, y+5, z+7, b, BlockType.STONE.metadata);
		world.setBlock(x+12, y+5, z+8, b, BlockType.STONE.metadata);
		world.setBlock(x+12, y+5, z+9, b, BlockType.STONE.metadata);
		world.setBlock(x+12, y+5, z+10, b, BlockType.STONE.metadata);
		world.setBlock(x+12, y+5, z+11, b, BlockType.STONE.metadata);
		world.setBlock(x+12, y+5, z+12, b, BlockType.STONE.metadata);
		world.setBlock(x+12, y+5, z+13, b, BlockType.STONE.metadata);
		world.setBlock(x+12, y+5, z+14, b, BlockType.STONE.metadata);
		world.setBlock(x+12, y+6, z+0, b, BlockType.STONE.metadata);
		world.setBlock(x+12, y+6, z+1, b, BlockType.STONE.metadata);
		world.setBlock(x+12, y+6, z+2, b, BlockType.STONE.metadata);
		world.setBlock(x+12, y+6, z+3, b, BlockType.STONE.metadata);
		world.setBlock(x+12, y+6, z+4, b, BlockType.STONE.metadata);
		world.setBlock(x+12, y+6, z+5, b, BlockType.STONE.metadata);
		world.setBlock(x+12, y+6, z+6, b, BlockType.STONE.metadata);
		world.setBlock(x+12, y+6, z+7, b, BlockType.STONE.metadata);
		world.setBlock(x+12, y+6, z+8, b, BlockType.STONE.metadata);
		world.setBlock(x+12, y+6, z+9, b, BlockType.STONE.metadata);
		world.setBlock(x+12, y+6, z+10, b, BlockType.STONE.metadata);
		world.setBlock(x+12, y+6, z+11, b, BlockType.STONE.metadata);
		world.setBlock(x+12, y+6, z+12, b, BlockType.STONE.metadata);
		world.setBlock(x+12, y+6, z+13, b, BlockType.STONE.metadata);
		world.setBlock(x+12, y+6, z+14, b, BlockType.STONE.metadata);
		world.setBlock(x+12, y+7, z+0, b, BlockType.STONE.metadata);
		world.setBlock(x+12, y+7, z+1, b, BlockType.STONE.metadata);
		world.setBlock(x+12, y+7, z+2, b, BlockType.STONE.metadata);
		world.setBlock(x+12, y+7, z+3, b, BlockType.STONE.metadata);
		world.setBlock(x+12, y+7, z+4, b, BlockType.STONE.metadata);
		world.setBlock(x+12, y+7, z+5, b, BlockType.STONE.metadata);
		world.setBlock(x+12, y+7, z+6, b, BlockType.STONE.metadata);
		world.setBlock(x+12, y+7, z+7, b, BlockType.STONE.metadata);
		world.setBlock(x+12, y+7, z+8, b, BlockType.STONE.metadata);
		world.setBlock(x+12, y+7, z+9, b, BlockType.STONE.metadata);
		world.setBlock(x+12, y+7, z+10, b, BlockType.STONE.metadata);
		world.setBlock(x+12, y+7, z+11, b, BlockType.STONE.metadata);
		world.setBlock(x+12, y+7, z+12, b, BlockType.STONE.metadata);
		world.setBlock(x+12, y+7, z+13, b, BlockType.STONE.metadata);
		world.setBlock(x+12, y+7, z+14, b, BlockType.STONE.metadata);
		world.setBlock(x+12, y+8, z+0, b, BlockType.STONE.metadata);
		world.setBlock(x+12, y+8, z+1, b, BlockType.STONE.metadata);
		world.setBlock(x+12, y+8, z+2, b, BlockType.STONE.metadata);
		world.setBlock(x+12, y+8, z+3, b, BlockType.STONE.metadata);
		world.setBlock(x+12, y+8, z+4, b, BlockType.STONE.metadata);
		world.setBlock(x+12, y+8, z+5, b, BlockType.STONE.metadata);
		world.setBlock(x+12, y+8, z+6, b, BlockType.STONE.metadata);
		world.setBlock(x+12, y+8, z+7, b, BlockType.STONE.metadata);
		world.setBlock(x+12, y+8, z+8, b, BlockType.STONE.metadata);
		world.setBlock(x+12, y+8, z+9, b, BlockType.STONE.metadata);
		world.setBlock(x+12, y+8, z+10, b, BlockType.STONE.metadata);
		world.setBlock(x+12, y+8, z+11, b, BlockType.STONE.metadata);
		world.setBlock(x+12, y+8, z+12, b, BlockType.STONE.metadata);
		world.setBlock(x+12, y+8, z+13, b, BlockType.STONE.metadata);
		world.setBlock(x+12, y+8, z+14, b, BlockType.STONE.metadata);
		world.setBlock(x+12, y+9, z+0, b, BlockType.STONE.metadata);
		world.setBlock(x+12, y+9, z+1, b, BlockType.STONE.metadata);
		world.setBlock(x+12, y+9, z+2, b, BlockType.STONE.metadata);
		world.setBlock(x+12, y+9, z+3, b, BlockType.STONE.metadata);
		world.setBlock(x+12, y+9, z+4, b, BlockType.STONE.metadata);
		world.setBlock(x+12, y+9, z+5, b, BlockType.STONE.metadata);
		world.setBlock(x+12, y+9, z+6, b, BlockType.STONE.metadata);
		world.setBlock(x+12, y+9, z+7, b, BlockType.STONE.metadata);
		world.setBlock(x+12, y+9, z+8, b, BlockType.STONE.metadata);
		world.setBlock(x+12, y+9, z+9, b, BlockType.STONE.metadata);
		world.setBlock(x+12, y+9, z+10, b, BlockType.STONE.metadata);
		world.setBlock(x+12, y+9, z+11, b, BlockType.STONE.metadata);
		world.setBlock(x+12, y+9, z+12, b, BlockType.STONE.metadata);
		world.setBlock(x+12, y+9, z+13, b, BlockType.STONE.metadata);
		world.setBlock(x+12, y+9, z+14, b, BlockType.STONE.metadata);
		world.setBlock(x+0, y+1, z+5, Blocks.air);
		world.setBlock(x+0, y+1, z+6, Blocks.air);
		world.setBlock(x+0, y+1, z+7, Blocks.air);
		world.setBlock(x+0, y+1, z+8, Blocks.air);
		world.setBlock(x+0, y+1, z+9, Blocks.air);
		world.setBlock(x+0, y+2, z+5, Blocks.air);
		world.setBlock(x+0, y+2, z+6, Blocks.air);
		world.setBlock(x+0, y+2, z+7, Blocks.air);
		world.setBlock(x+0, y+2, z+8, Blocks.air);
		world.setBlock(x+0, y+2, z+9, Blocks.air);
		world.setBlock(x+0, y+3, z+5, Blocks.air);
		world.setBlock(x+0, y+3, z+6, Blocks.air);
		world.setBlock(x+0, y+3, z+7, Blocks.air);
		world.setBlock(x+0, y+3, z+8, Blocks.air);
		world.setBlock(x+0, y+3, z+9, Blocks.air);
		world.setBlock(x+1, y+1, z+1, Blocks.air);
		world.setBlock(x+1, y+1, z+2, Blocks.air);
		world.setBlock(x+1, y+1, z+3, Blocks.air);
		world.setBlock(x+1, y+1, z+4, Blocks.air);
		world.setBlock(x+1, y+1, z+5, Blocks.air);
		world.setBlock(x+1, y+1, z+6, Blocks.air);
		world.setBlock(x+1, y+1, z+7, Blocks.air);
		world.setBlock(x+1, y+1, z+8, Blocks.air);
		world.setBlock(x+1, y+1, z+9, Blocks.air);
		world.setBlock(x+1, y+1, z+10, Blocks.air);
		world.setBlock(x+1, y+1, z+11, Blocks.air);
		world.setBlock(x+1, y+1, z+12, Blocks.air);
		world.setBlock(x+1, y+1, z+13, Blocks.air);
		world.setBlock(x+1, y+2, z+1, Blocks.air);
		world.setBlock(x+1, y+2, z+2, Blocks.air);
		world.setBlock(x+1, y+2, z+3, Blocks.air);
		world.setBlock(x+1, y+2, z+4, Blocks.air);
		world.setBlock(x+1, y+2, z+5, Blocks.air);
		world.setBlock(x+1, y+2, z+6, Blocks.air);
		world.setBlock(x+1, y+2, z+7, Blocks.air);
		world.setBlock(x+1, y+2, z+8, Blocks.air);
		world.setBlock(x+1, y+2, z+9, Blocks.air);
		world.setBlock(x+1, y+2, z+10, Blocks.air);
		world.setBlock(x+1, y+2, z+11, Blocks.air);
		world.setBlock(x+1, y+2, z+12, Blocks.air);
		world.setBlock(x+1, y+2, z+13, Blocks.air);
		world.setBlock(x+1, y+3, z+1, Blocks.air);
		world.setBlock(x+1, y+3, z+2, Blocks.air);
		world.setBlock(x+1, y+3, z+3, Blocks.air);
		world.setBlock(x+1, y+3, z+4, Blocks.air);
		world.setBlock(x+1, y+3, z+5, Blocks.air);
		world.setBlock(x+1, y+3, z+6, Blocks.air);
		world.setBlock(x+1, y+3, z+7, Blocks.air);
		world.setBlock(x+1, y+3, z+8, Blocks.air);
		world.setBlock(x+1, y+3, z+9, Blocks.air);
		world.setBlock(x+1, y+3, z+10, Blocks.air);
		world.setBlock(x+1, y+3, z+11, Blocks.air);
		world.setBlock(x+1, y+3, z+12, Blocks.air);
		world.setBlock(x+1, y+3, z+13, Blocks.air);
		world.setBlock(x+1, y+6, z+6, Blocks.air);
		world.setBlock(x+1, y+6, z+7, Blocks.air);
		world.setBlock(x+1, y+6, z+8, Blocks.air);
		world.setBlock(x+1, y+7, z+6, Blocks.air);
		world.setBlock(x+1, y+7, z+7, Blocks.air);
		world.setBlock(x+1, y+7, z+8, Blocks.air);
		world.setBlock(x+1, y+8, z+6, Blocks.air);
		world.setBlock(x+1, y+8, z+7, Blocks.air);
		world.setBlock(x+1, y+8, z+8, Blocks.air);
		world.setBlock(x+2, y+1, z+1, Blocks.air);
		world.setBlock(x+2, y+1, z+2, Blocks.air);
		world.setBlock(x+2, y+1, z+3, Blocks.air);
		world.setBlock(x+2, y+1, z+4, Blocks.air);
		world.setBlock(x+2, y+1, z+5, Blocks.air);
		world.setBlock(x+2, y+1, z+6, Blocks.air);
		world.setBlock(x+2, y+1, z+7, Blocks.air);
		world.setBlock(x+2, y+1, z+8, Blocks.air);
		world.setBlock(x+2, y+1, z+9, Blocks.air);
		world.setBlock(x+2, y+1, z+10, Blocks.air);
		world.setBlock(x+2, y+1, z+11, Blocks.air);
		world.setBlock(x+2, y+1, z+12, Blocks.air);
		world.setBlock(x+2, y+1, z+13, Blocks.air);
		world.setBlock(x+2, y+2, z+1, Blocks.air);
		world.setBlock(x+2, y+2, z+2, Blocks.air);
		world.setBlock(x+2, y+2, z+3, Blocks.air);
		world.setBlock(x+2, y+2, z+4, Blocks.air);
		world.setBlock(x+2, y+2, z+5, Blocks.air);
		world.setBlock(x+2, y+2, z+6, Blocks.air);
		world.setBlock(x+2, y+2, z+7, Blocks.air);
		world.setBlock(x+2, y+2, z+8, Blocks.air);
		world.setBlock(x+2, y+2, z+9, Blocks.air);
		world.setBlock(x+2, y+2, z+10, Blocks.air);
		world.setBlock(x+2, y+2, z+11, Blocks.air);
		world.setBlock(x+2, y+2, z+12, Blocks.air);
		world.setBlock(x+2, y+2, z+13, Blocks.air);
		world.setBlock(x+2, y+3, z+1, Blocks.air);
		world.setBlock(x+2, y+3, z+2, Blocks.air);
		world.setBlock(x+2, y+3, z+3, Blocks.air);
		world.setBlock(x+2, y+3, z+4, Blocks.air);
		world.setBlock(x+2, y+3, z+5, Blocks.air);
		world.setBlock(x+2, y+3, z+6, Blocks.air);
		world.setBlock(x+2, y+3, z+7, Blocks.air);
		world.setBlock(x+2, y+3, z+8, Blocks.air);
		world.setBlock(x+2, y+3, z+9, Blocks.air);
		world.setBlock(x+2, y+3, z+10, Blocks.air);
		world.setBlock(x+2, y+3, z+11, Blocks.air);
		world.setBlock(x+2, y+3, z+12, Blocks.air);
		world.setBlock(x+2, y+3, z+13, Blocks.air);
		world.setBlock(x+2, y+6, z+6, Blocks.air);
		world.setBlock(x+2, y+6, z+7, Blocks.air);
		world.setBlock(x+2, y+6, z+8, Blocks.air);
		world.setBlock(x+2, y+7, z+6, Blocks.air);
		world.setBlock(x+2, y+7, z+7, Blocks.air);
		world.setBlock(x+2, y+7, z+8, Blocks.air);
		world.setBlock(x+2, y+8, z+6, Blocks.air);
		world.setBlock(x+2, y+8, z+7, Blocks.air);
		world.setBlock(x+2, y+8, z+8, Blocks.air);
		world.setBlock(x+3, y+1, z+1, Blocks.air);
		world.setBlock(x+3, y+1, z+2, Blocks.air);
		world.setBlock(x+3, y+1, z+3, Blocks.air);
		world.setBlock(x+3, y+1, z+4, Blocks.air);
		world.setBlock(x+3, y+1, z+5, Blocks.air);
		world.setBlock(x+3, y+1, z+6, Blocks.air);
		world.setBlock(x+3, y+1, z+7, Blocks.air);
		world.setBlock(x+3, y+1, z+8, Blocks.air);
		world.setBlock(x+3, y+1, z+9, Blocks.air);
		world.setBlock(x+3, y+1, z+10, Blocks.air);
		world.setBlock(x+3, y+1, z+11, Blocks.air);
		world.setBlock(x+3, y+1, z+12, Blocks.air);
		world.setBlock(x+3, y+1, z+13, Blocks.air);
		world.setBlock(x+3, y+2, z+1, Blocks.air);
		world.setBlock(x+3, y+2, z+2, Blocks.air);
		world.setBlock(x+3, y+2, z+3, Blocks.air);
		world.setBlock(x+3, y+2, z+4, Blocks.air);
		world.setBlock(x+3, y+2, z+5, Blocks.air);
		world.setBlock(x+3, y+2, z+6, Blocks.air);
		world.setBlock(x+3, y+2, z+7, Blocks.air);
		world.setBlock(x+3, y+2, z+8, Blocks.air);
		world.setBlock(x+3, y+2, z+9, Blocks.air);
		world.setBlock(x+3, y+2, z+10, Blocks.air);
		world.setBlock(x+3, y+2, z+11, Blocks.air);
		world.setBlock(x+3, y+2, z+12, Blocks.air);
		world.setBlock(x+3, y+2, z+13, Blocks.air);
		world.setBlock(x+3, y+3, z+1, Blocks.air);
		world.setBlock(x+3, y+3, z+2, Blocks.air);
		world.setBlock(x+3, y+3, z+3, Blocks.air);
		world.setBlock(x+3, y+3, z+4, Blocks.air);
		world.setBlock(x+3, y+3, z+5, Blocks.air);
		world.setBlock(x+3, y+3, z+6, Blocks.air);
		world.setBlock(x+3, y+3, z+7, Blocks.air);
		world.setBlock(x+3, y+3, z+8, Blocks.air);
		world.setBlock(x+3, y+3, z+9, Blocks.air);
		world.setBlock(x+3, y+3, z+10, Blocks.air);
		world.setBlock(x+3, y+3, z+11, Blocks.air);
		world.setBlock(x+3, y+3, z+12, Blocks.air);
		world.setBlock(x+3, y+3, z+13, Blocks.air);
		world.setBlock(x+3, y+6, z+6, Blocks.air);
		world.setBlock(x+3, y+6, z+7, Blocks.air);
		world.setBlock(x+3, y+6, z+8, Blocks.air);
		world.setBlock(x+3, y+7, z+6, Blocks.air);
		world.setBlock(x+3, y+7, z+7, Blocks.air);
		world.setBlock(x+3, y+7, z+8, Blocks.air);
		world.setBlock(x+3, y+8, z+6, Blocks.air);
		world.setBlock(x+3, y+8, z+7, Blocks.air);
		world.setBlock(x+3, y+8, z+8, Blocks.air);
		world.setBlock(x+4, y+1, z+1, Blocks.air);
		world.setBlock(x+4, y+1, z+2, Blocks.air);
		world.setBlock(x+4, y+1, z+3, Blocks.air);
		world.setBlock(x+4, y+1, z+11, Blocks.air);
		world.setBlock(x+4, y+1, z+12, Blocks.air);
		world.setBlock(x+4, y+1, z+13, Blocks.air);
		world.setBlock(x+4, y+2, z+1, Blocks.air);
		world.setBlock(x+4, y+2, z+2, Blocks.air);
		world.setBlock(x+4, y+2, z+3, Blocks.air);
		world.setBlock(x+4, y+2, z+11, Blocks.air);
		world.setBlock(x+4, y+2, z+12, Blocks.air);
		world.setBlock(x+4, y+2, z+13, Blocks.air);
		world.setBlock(x+4, y+3, z+1, Blocks.air);
		world.setBlock(x+4, y+3, z+2, Blocks.air);
		world.setBlock(x+4, y+3, z+3, Blocks.air);
		world.setBlock(x+4, y+3, z+11, Blocks.air);
		world.setBlock(x+4, y+3, z+12, Blocks.air);
		world.setBlock(x+4, y+3, z+13, Blocks.air);
		world.setBlock(x+4, y+4, z+1, Blocks.air);
		world.setBlock(x+4, y+4, z+2, Blocks.air);
		world.setBlock(x+4, y+4, z+3, Blocks.air);
		world.setBlock(x+5, y+1, z+6, Blocks.air);
		world.setBlock(x+5, y+1, z+7, Blocks.air);
		world.setBlock(x+5, y+1, z+8, Blocks.air);
		world.setBlock(x+5, y+2, z+1, Blocks.air);
		world.setBlock(x+5, y+2, z+2, Blocks.air);
		world.setBlock(x+5, y+2, z+3, Blocks.air);
		world.setBlock(x+5, y+2, z+6, Blocks.air);
		world.setBlock(x+5, y+2, z+7, Blocks.air);
		world.setBlock(x+5, y+2, z+8, Blocks.air);
		world.setBlock(x+5, y+2, z+11, Blocks.air);
		world.setBlock(x+5, y+2, z+12, Blocks.air);
		world.setBlock(x+5, y+2, z+13, Blocks.air);
		world.setBlock(x+5, y+3, z+1, Blocks.air);
		world.setBlock(x+5, y+3, z+2, Blocks.air);
		world.setBlock(x+5, y+3, z+3, Blocks.air);
		world.setBlock(x+5, y+3, z+6, Blocks.air);
		world.setBlock(x+5, y+3, z+7, Blocks.air);
		world.setBlock(x+5, y+3, z+8, Blocks.air);
		world.setBlock(x+5, y+3, z+11, Blocks.air);
		world.setBlock(x+5, y+3, z+12, Blocks.air);
		world.setBlock(x+5, y+3, z+13, Blocks.air);
		world.setBlock(x+5, y+4, z+1, Blocks.air);
		world.setBlock(x+5, y+4, z+2, Blocks.air);
		world.setBlock(x+5, y+4, z+3, Blocks.air);
		world.setBlock(x+5, y+4, z+11, Blocks.air);
		world.setBlock(x+5, y+4, z+12, Blocks.air);
		world.setBlock(x+5, y+4, z+13, Blocks.air);
		world.setBlock(x+5, y+5, z+1, Blocks.air);
		world.setBlock(x+5, y+5, z+2, Blocks.air);
		world.setBlock(x+5, y+5, z+3, Blocks.air);
		world.setBlock(x+5, y+5, z+11, Blocks.air);
		world.setBlock(x+5, y+5, z+12, Blocks.air);
		world.setBlock(x+5, y+5, z+13, Blocks.air);
		world.setBlock(x+5, y+6, z+1, Blocks.air);
		world.setBlock(x+5, y+6, z+2, Blocks.air);
		world.setBlock(x+5, y+6, z+3, Blocks.air);
		world.setBlock(x+5, y+6, z+6, Blocks.air);
		world.setBlock(x+5, y+6, z+7, Blocks.air);
		world.setBlock(x+5, y+6, z+8, Blocks.air);
		world.setBlock(x+5, y+6, z+11, Blocks.air);
		world.setBlock(x+5, y+6, z+12, Blocks.air);
		world.setBlock(x+5, y+6, z+13, Blocks.air);
		world.setBlock(x+5, y+7, z+1, Blocks.air);
		world.setBlock(x+5, y+7, z+2, Blocks.air);
		world.setBlock(x+5, y+7, z+3, Blocks.air);
		world.setBlock(x+5, y+7, z+6, Blocks.air);
		world.setBlock(x+5, y+7, z+7, Blocks.air);
		world.setBlock(x+5, y+7, z+8, Blocks.air);
		world.setBlock(x+5, y+7, z+11, Blocks.air);
		world.setBlock(x+5, y+7, z+12, Blocks.air);
		world.setBlock(x+5, y+7, z+13, Blocks.air);
		world.setBlock(x+5, y+8, z+1, Blocks.air);
		world.setBlock(x+5, y+8, z+2, Blocks.air);
		world.setBlock(x+5, y+8, z+3, Blocks.air);
		world.setBlock(x+5, y+8, z+6, Blocks.air);
		world.setBlock(x+5, y+8, z+7, Blocks.air);
		world.setBlock(x+5, y+8, z+8, Blocks.air);
		world.setBlock(x+5, y+8, z+11, Blocks.air);
		world.setBlock(x+5, y+8, z+12, Blocks.air);
		world.setBlock(x+5, y+8, z+13, Blocks.air);
		world.setBlock(x+6, y+1, z+6, Blocks.air);
		world.setBlock(x+6, y+1, z+7, Blocks.air);
		world.setBlock(x+6, y+1, z+8, Blocks.air);
		world.setBlock(x+6, y+2, z+6, Blocks.air);
		world.setBlock(x+6, y+2, z+8, Blocks.air);
		world.setBlock(x+6, y+3, z+1, Blocks.air);
		world.setBlock(x+6, y+3, z+2, Blocks.air);
		world.setBlock(x+6, y+3, z+3, Blocks.air);
		world.setBlock(x+6, y+3, z+6, Blocks.air);
		world.setBlock(x+6, y+3, z+7, Blocks.air);
		world.setBlock(x+6, y+3, z+8, Blocks.air);
		world.setBlock(x+6, y+3, z+11, Blocks.air);
		world.setBlock(x+6, y+3, z+12, Blocks.air);
		world.setBlock(x+6, y+3, z+13, Blocks.air);
		world.setBlock(x+6, y+4, z+1, Blocks.air);
		world.setBlock(x+6, y+4, z+2, Blocks.air);
		world.setBlock(x+6, y+4, z+3, Blocks.air);
		world.setBlock(x+6, y+4, z+7, Blocks.air);
		world.setBlock(x+6, y+4, z+11, Blocks.air);
		world.setBlock(x+6, y+4, z+12, Blocks.air);
		world.setBlock(x+6, y+4, z+13, Blocks.air);
		world.setBlock(x+6, y+5, z+1, Blocks.air);
		world.setBlock(x+6, y+5, z+2, Blocks.air);
		world.setBlock(x+6, y+5, z+3, Blocks.air);
		world.setBlock(x+6, y+5, z+11, Blocks.air);
		world.setBlock(x+6, y+5, z+12, Blocks.air);
		world.setBlock(x+6, y+5, z+13, Blocks.air);
		world.setBlock(x+6, y+6, z+1, Blocks.air);
		world.setBlock(x+6, y+6, z+2, Blocks.air);
		world.setBlock(x+6, y+6, z+3, Blocks.air);
		world.setBlock(x+6, y+6, z+6, Blocks.air);
		world.setBlock(x+6, y+6, z+7, Blocks.air);
		world.setBlock(x+6, y+6, z+8, Blocks.air);
		world.setBlock(x+6, y+6, z+11, Blocks.air);
		world.setBlock(x+6, y+6, z+12, Blocks.air);
		world.setBlock(x+6, y+6, z+13, Blocks.air);
		world.setBlock(x+6, y+7, z+1, Blocks.air);
		world.setBlock(x+6, y+7, z+2, Blocks.air);
		world.setBlock(x+6, y+7, z+3, Blocks.air);
		world.setBlock(x+6, y+7, z+6, Blocks.air);
		world.setBlock(x+6, y+7, z+7, Blocks.air);
		world.setBlock(x+6, y+7, z+8, Blocks.air);
		world.setBlock(x+6, y+7, z+11, Blocks.air);
		world.setBlock(x+6, y+7, z+12, Blocks.air);
		world.setBlock(x+6, y+7, z+13, Blocks.air);
		world.setBlock(x+6, y+8, z+1, Blocks.air);
		world.setBlock(x+6, y+8, z+2, Blocks.air);
		world.setBlock(x+6, y+8, z+3, Blocks.air);
		world.setBlock(x+6, y+8, z+6, Blocks.air);
		world.setBlock(x+6, y+8, z+7, Blocks.air);
		world.setBlock(x+6, y+8, z+8, Blocks.air);
		world.setBlock(x+6, y+8, z+11, Blocks.air);
		world.setBlock(x+6, y+8, z+12, Blocks.air);
		world.setBlock(x+6, y+8, z+13, Blocks.air);
		world.setBlock(x+7, y+1, z+6, Blocks.air);
		world.setBlock(x+7, y+1, z+7, Blocks.air);
		world.setBlock(x+7, y+1, z+8, Blocks.air);
		world.setBlock(x+7, y+2, z+6, Blocks.air);
		world.setBlock(x+7, y+2, z+7, Blocks.air);
		world.setBlock(x+7, y+2, z+8, Blocks.air);
		world.setBlock(x+7, y+3, z+6, Blocks.air);
		world.setBlock(x+7, y+3, z+7, Blocks.air);
		world.setBlock(x+7, y+3, z+8, Blocks.air);
		world.setBlock(x+7, y+4, z+1, Blocks.air);
		world.setBlock(x+7, y+4, z+2, Blocks.air);
		world.setBlock(x+7, y+4, z+3, Blocks.air);
		world.setBlock(x+7, y+4, z+11, Blocks.air);
		world.setBlock(x+7, y+4, z+12, Blocks.air);
		world.setBlock(x+7, y+4, z+13, Blocks.air);
		world.setBlock(x+7, y+5, z+1, Blocks.air);
		world.setBlock(x+7, y+5, z+2, Blocks.air);
		world.setBlock(x+7, y+5, z+3, Blocks.air);
		world.setBlock(x+7, y+5, z+11, Blocks.air);
		world.setBlock(x+7, y+5, z+12, Blocks.air);
		world.setBlock(x+7, y+5, z+13, Blocks.air);
		world.setBlock(x+7, y+6, z+1, Blocks.air);
		world.setBlock(x+7, y+6, z+2, Blocks.air);
		world.setBlock(x+7, y+6, z+3, Blocks.air);
		world.setBlock(x+7, y+6, z+6, Blocks.air);
		world.setBlock(x+7, y+6, z+7, Blocks.air);
		world.setBlock(x+7, y+6, z+8, Blocks.air);
		world.setBlock(x+7, y+6, z+11, Blocks.air);
		world.setBlock(x+7, y+6, z+12, Blocks.air);
		world.setBlock(x+7, y+6, z+13, Blocks.air);
		world.setBlock(x+7, y+7, z+1, Blocks.air);
		world.setBlock(x+7, y+7, z+2, Blocks.air);
		world.setBlock(x+7, y+7, z+3, Blocks.air);
		world.setBlock(x+7, y+7, z+6, Blocks.air);
		world.setBlock(x+7, y+7, z+7, Blocks.air);
		world.setBlock(x+7, y+7, z+8, Blocks.air);
		world.setBlock(x+7, y+7, z+11, Blocks.air);
		world.setBlock(x+7, y+7, z+12, Blocks.air);
		world.setBlock(x+7, y+7, z+13, Blocks.air);
		world.setBlock(x+7, y+8, z+1, Blocks.air);
		world.setBlock(x+7, y+8, z+2, Blocks.air);
		world.setBlock(x+7, y+8, z+3, Blocks.air);
		world.setBlock(x+7, y+8, z+6, Blocks.air);
		world.setBlock(x+7, y+8, z+7, Blocks.air);
		world.setBlock(x+7, y+8, z+8, Blocks.air);
		world.setBlock(x+7, y+8, z+11, Blocks.air);
		world.setBlock(x+7, y+8, z+12, Blocks.air);
		world.setBlock(x+7, y+8, z+13, Blocks.air);
		world.setBlock(x+8, y+5, z+1, Blocks.air);
		world.setBlock(x+8, y+5, z+2, Blocks.air);
		world.setBlock(x+8, y+5, z+3, Blocks.air);
		world.setBlock(x+8, y+5, z+11, Blocks.air);
		world.setBlock(x+8, y+5, z+12, Blocks.air);
		world.setBlock(x+8, y+5, z+13, Blocks.air);
		world.setBlock(x+8, y+6, z+1, Blocks.air);
		world.setBlock(x+8, y+6, z+2, Blocks.air);
		world.setBlock(x+8, y+6, z+3, Blocks.air);
		world.setBlock(x+8, y+6, z+6, Blocks.air);
		world.setBlock(x+8, y+6, z+7, Blocks.air);
		world.setBlock(x+8, y+6, z+8, Blocks.air);
		world.setBlock(x+8, y+6, z+11, Blocks.air);
		world.setBlock(x+8, y+6, z+12, Blocks.air);
		world.setBlock(x+8, y+6, z+13, Blocks.air);
		world.setBlock(x+8, y+7, z+1, Blocks.air);
		world.setBlock(x+8, y+7, z+2, Blocks.air);
		world.setBlock(x+8, y+7, z+3, Blocks.air);
		world.setBlock(x+8, y+7, z+6, Blocks.air);
		world.setBlock(x+8, y+7, z+7, Blocks.air);
		world.setBlock(x+8, y+7, z+8, Blocks.air);
		world.setBlock(x+8, y+7, z+11, Blocks.air);
		world.setBlock(x+8, y+7, z+12, Blocks.air);
		world.setBlock(x+8, y+7, z+13, Blocks.air);
		world.setBlock(x+8, y+8, z+1, Blocks.air);
		world.setBlock(x+8, y+8, z+2, Blocks.air);
		world.setBlock(x+8, y+8, z+3, Blocks.air);
		world.setBlock(x+8, y+8, z+6, Blocks.air);
		world.setBlock(x+8, y+8, z+7, Blocks.air);
		world.setBlock(x+8, y+8, z+8, Blocks.air);
		world.setBlock(x+8, y+8, z+11, Blocks.air);
		world.setBlock(x+8, y+8, z+12, Blocks.air);
		world.setBlock(x+8, y+8, z+13, Blocks.air);
		world.setBlock(x+9, y+6, z+1, Blocks.air);
		world.setBlock(x+9, y+6, z+2, Blocks.air);
		world.setBlock(x+9, y+6, z+3, Blocks.air);
		world.setBlock(x+9, y+6, z+4, Blocks.air);
		world.setBlock(x+9, y+6, z+5, Blocks.air);
		world.setBlock(x+9, y+6, z+6, Blocks.air);
		world.setBlock(x+9, y+6, z+7, Blocks.air);
		world.setBlock(x+9, y+6, z+8, Blocks.air);
		world.setBlock(x+9, y+6, z+9, Blocks.air);
		world.setBlock(x+9, y+6, z+10, Blocks.air);
		world.setBlock(x+9, y+6, z+11, Blocks.air);
		world.setBlock(x+9, y+6, z+12, Blocks.air);
		world.setBlock(x+9, y+6, z+13, Blocks.air);
		world.setBlock(x+9, y+7, z+1, Blocks.air);
		world.setBlock(x+9, y+7, z+2, Blocks.air);
		world.setBlock(x+9, y+7, z+3, Blocks.air);
		world.setBlock(x+9, y+7, z+4, Blocks.air);
		world.setBlock(x+9, y+7, z+5, Blocks.air);
		world.setBlock(x+9, y+7, z+6, Blocks.air);
		world.setBlock(x+9, y+7, z+7, Blocks.air);
		world.setBlock(x+9, y+7, z+8, Blocks.air);
		world.setBlock(x+9, y+7, z+9, Blocks.air);
		world.setBlock(x+9, y+7, z+10, Blocks.air);
		world.setBlock(x+9, y+7, z+11, Blocks.air);
		world.setBlock(x+9, y+7, z+12, Blocks.air);
		world.setBlock(x+9, y+7, z+13, Blocks.air);
		world.setBlock(x+9, y+8, z+1, Blocks.air);
		world.setBlock(x+9, y+8, z+2, Blocks.air);
		world.setBlock(x+9, y+8, z+3, Blocks.air);
		world.setBlock(x+9, y+8, z+4, Blocks.air);
		world.setBlock(x+9, y+8, z+5, Blocks.air);
		world.setBlock(x+9, y+8, z+6, Blocks.air);
		world.setBlock(x+9, y+8, z+7, Blocks.air);
		world.setBlock(x+9, y+8, z+8, Blocks.air);
		world.setBlock(x+9, y+8, z+9, Blocks.air);
		world.setBlock(x+9, y+8, z+10, Blocks.air);
		world.setBlock(x+9, y+8, z+11, Blocks.air);
		world.setBlock(x+9, y+8, z+12, Blocks.air);
		world.setBlock(x+9, y+8, z+13, Blocks.air);
		world.setBlock(x+10, y+6, z+1, Blocks.air);
		world.setBlock(x+10, y+6, z+2, Blocks.air);
		world.setBlock(x+10, y+6, z+3, Blocks.air);
		world.setBlock(x+10, y+6, z+4, Blocks.air);
		world.setBlock(x+10, y+6, z+5, Blocks.air);
		world.setBlock(x+10, y+6, z+6, Blocks.air);
		world.setBlock(x+10, y+6, z+7, Blocks.air);
		world.setBlock(x+10, y+6, z+8, Blocks.air);
		world.setBlock(x+10, y+6, z+9, Blocks.air);
		world.setBlock(x+10, y+6, z+10, Blocks.air);
		world.setBlock(x+10, y+6, z+11, Blocks.air);
		world.setBlock(x+10, y+6, z+12, Blocks.air);
		world.setBlock(x+10, y+6, z+13, Blocks.air);
		world.setBlock(x+10, y+7, z+1, Blocks.air);
		world.setBlock(x+10, y+7, z+2, Blocks.air);
		world.setBlock(x+10, y+7, z+3, Blocks.air);
		world.setBlock(x+10, y+7, z+4, Blocks.air);
		world.setBlock(x+10, y+7, z+5, Blocks.air);
		world.setBlock(x+10, y+7, z+6, Blocks.air);
		world.setBlock(x+10, y+7, z+7, Blocks.air);
		world.setBlock(x+10, y+7, z+8, Blocks.air);
		world.setBlock(x+10, y+7, z+9, Blocks.air);
		world.setBlock(x+10, y+7, z+10, Blocks.air);
		world.setBlock(x+10, y+7, z+11, Blocks.air);
		world.setBlock(x+10, y+7, z+12, Blocks.air);
		world.setBlock(x+10, y+7, z+13, Blocks.air);
		world.setBlock(x+10, y+8, z+1, Blocks.air);
		world.setBlock(x+10, y+8, z+2, Blocks.air);
		world.setBlock(x+10, y+8, z+3, Blocks.air);
		world.setBlock(x+10, y+8, z+4, Blocks.air);
		world.setBlock(x+10, y+8, z+5, Blocks.air);
		world.setBlock(x+10, y+8, z+6, Blocks.air);
		world.setBlock(x+10, y+8, z+7, Blocks.air);
		world.setBlock(x+10, y+8, z+8, Blocks.air);
		world.setBlock(x+10, y+8, z+9, Blocks.air);
		world.setBlock(x+10, y+8, z+10, Blocks.air);
		world.setBlock(x+10, y+8, z+11, Blocks.air);
		world.setBlock(x+10, y+8, z+12, Blocks.air);
		world.setBlock(x+10, y+8, z+13, Blocks.air);
		world.setBlock(x+11, y+6, z+1, Blocks.air);
		world.setBlock(x+11, y+6, z+2, Blocks.air);
		world.setBlock(x+11, y+6, z+3, Blocks.air);
		world.setBlock(x+11, y+6, z+4, Blocks.air);
		world.setBlock(x+11, y+6, z+5, Blocks.air);
		world.setBlock(x+11, y+6, z+6, Blocks.air);
		world.setBlock(x+11, y+6, z+7, Blocks.air);
		world.setBlock(x+11, y+6, z+8, Blocks.air);
		world.setBlock(x+11, y+6, z+9, Blocks.air);
		world.setBlock(x+11, y+6, z+10, Blocks.air);
		world.setBlock(x+11, y+6, z+11, Blocks.air);
		world.setBlock(x+11, y+6, z+12, Blocks.air);
		world.setBlock(x+11, y+6, z+13, Blocks.air);
		world.setBlock(x+11, y+7, z+1, Blocks.air);
		world.setBlock(x+11, y+7, z+2, Blocks.air);
		world.setBlock(x+11, y+7, z+3, Blocks.air);
		world.setBlock(x+11, y+7, z+4, Blocks.air);
		world.setBlock(x+11, y+7, z+5, Blocks.air);
		world.setBlock(x+11, y+7, z+6, Blocks.air);
		world.setBlock(x+11, y+7, z+7, Blocks.air);
		world.setBlock(x+11, y+7, z+8, Blocks.air);
		world.setBlock(x+11, y+7, z+9, Blocks.air);
		world.setBlock(x+11, y+7, z+10, Blocks.air);
		world.setBlock(x+11, y+7, z+11, Blocks.air);
		world.setBlock(x+11, y+7, z+12, Blocks.air);
		world.setBlock(x+11, y+7, z+13, Blocks.air);
		world.setBlock(x+11, y+8, z+1, Blocks.air);
		world.setBlock(x+11, y+8, z+2, Blocks.air);
		world.setBlock(x+11, y+8, z+3, Blocks.air);
		world.setBlock(x+11, y+8, z+4, Blocks.air);
		world.setBlock(x+11, y+8, z+5, Blocks.air);
		world.setBlock(x+11, y+8, z+6, Blocks.air);
		world.setBlock(x+11, y+8, z+7, Blocks.air);
		world.setBlock(x+11, y+8, z+8, Blocks.air);
		world.setBlock(x+11, y+8, z+9, Blocks.air);
		world.setBlock(x+11, y+8, z+10, Blocks.air);
		world.setBlock(x+11, y+8, z+11, Blocks.air);
		world.setBlock(x+11, y+8, z+12, Blocks.air);
		world.setBlock(x+11, y+8, z+13, Blocks.air);
	}

}
