/*******************************************************************************
 * @author Reika Kalseki
 *
 * Copyright 2017
 *
 * All rights reserved.
 * Distribution of the software in any form is only allowed with
 * explicit, prior permission from the owner.
 ******************************************************************************/
package Reika.ChromatiCraft.Auxiliary.Structure.Worldgen;

import net.minecraft.block.Block;
import net.minecraft.init.Blocks;
import net.minecraft.world.World;

import Reika.ChromatiCraft.Base.FragmentStructureBase;
import Reika.ChromatiCraft.Block.Worldgen.BlockStructureShield.BlockType;
import Reika.DragonAPI.Instantiable.Data.BlockStruct.FilledBlockArray;
import Reika.DragonAPI.Instantiable.Data.Immutable.Coordinate;


public class DesertStructure extends FragmentStructureBase {

	private static final int ms = BlockType.STONE.metadata;
	private static final int mc = BlockType.COBBLE.metadata;

	private static final int mcrack = ms;

	@Override
	public Coordinate getControllerRelativeLocation() {
		return new Coordinate(7, 3, 7);
	}

	@Override
	public FilledBlockArray getArray(World world, int x, int y, int z) {
		FilledBlockArray array = new FilledBlockArray(world);

		Block ch = getChestGen();

		array.setBlock(x+10, y+6, z+2, ch, 11);
		array.setBlock(x+10, y+6, z+12, ch, 10);
		array.setBlock(x+6, y+2, z+7, ch, 8);
		array.setBlock(x+2, y+6, z+4, ch, 9);
		array.setBlock(x+2, y+6, z+10, ch, 9);
		array.setBlock(x+4, y+6, z+2, ch, 11);
		array.setBlock(x+4, y+6, z+12, ch, 10);
		array.setBlock(x+7, y+2, z+6, ch, 10);
		array.setBlock(x+7, y+2, z+8, ch, 11);
		array.setBlock(x+8, y+2, z+7, ch, 9);
		array.setBlock(x+12, y+6, z+4, ch, 8);
		array.setBlock(x+12, y+6, z+10, ch, 8);

		array.setBlock(x+1, y+2, z+5, shield, ms);
		array.setBlock(x+1, y+2, z+6, shield, ms);
		array.setBlock(x+1, y+2, z+7, shield, ms);
		array.setBlock(x+1, y+2, z+8, shield, ms);
		array.setBlock(x+1, y+2, z+9, shield, ms);
		array.setBlock(x+1, y+3, z+5, shield, ms);
		array.setBlock(x+1, y+3, z+6, shield, ms);
		array.setBlock(x+1, y+3, z+7, shield, ms);
		array.setBlock(x+1, y+3, z+8, shield, ms);
		array.setBlock(x+1, y+3, z+9, shield, ms);
		array.setBlock(x+1, y+4, z+5, shield, ms);
		array.setBlock(x+1, y+4, z+6, shield, ms);
		array.setBlock(x+1, y+4, z+7, shield, ms);
		array.setBlock(x+1, y+4, z+8, shield, ms);
		array.setBlock(x+1, y+4, z+9, shield, ms);
		array.setBlock(x+1, y+6, z+1, shield, ms);
		array.setBlock(x+1, y+6, z+2, shield, ms);
		array.setBlock(x+1, y+6, z+3, shield, ms);
		array.setBlock(x+1, y+6, z+4, shield, ms);
		array.setBlock(x+1, y+6, z+5, shield, ms);
		array.setBlock(x+1, y+6, z+6, shield, ms);
		array.setBlock(x+1, y+6, z+7, shield, ms);
		array.setBlock(x+1, y+6, z+8, shield, ms);
		array.setBlock(x+1, y+6, z+9, shield, ms);
		array.setBlock(x+1, y+6, z+10, shield, ms);
		array.setBlock(x+1, y+6, z+11, shield, ms);
		array.setBlock(x+1, y+6, z+12, shield, ms);
		array.setBlock(x+1, y+6, z+13, shield, ms);
		array.setBlock(x+1, y+7, z+1, shield, ms);
		array.setBlock(x+1, y+7, z+2, shield, ms);
		array.setBlock(x+1, y+7, z+3, shield, ms);
		array.setBlock(x+1, y+7, z+4, shield, ms);
		array.setBlock(x+1, y+7, z+5, shield, ms);
		array.setBlock(x+1, y+7, z+6, shield, ms);
		array.setBlock(x+1, y+7, z+7, shield, ms);
		array.setBlock(x+1, y+7, z+8, shield, ms);
		array.setBlock(x+1, y+7, z+9, shield, ms);
		array.setBlock(x+1, y+7, z+10, shield, ms);
		array.setBlock(x+1, y+7, z+11, shield, ms);
		array.setBlock(x+1, y+7, z+12, shield, ms);
		array.setBlock(x+1, y+7, z+13, shield, ms);
		array.setBlock(x+1, y+8, z+1, shield, ms);
		array.setBlock(x+1, y+8, z+2, shield, ms);
		array.setBlock(x+1, y+8, z+3, shield, ms);
		array.setBlock(x+1, y+8, z+4, shield, ms);
		array.setBlock(x+1, y+8, z+5, shield, ms);
		array.setBlock(x+1, y+8, z+6, shield, ms);
		array.setBlock(x+1, y+8, z+7, shield, ms);
		array.setBlock(x+1, y+8, z+8, shield, ms);
		array.setBlock(x+1, y+8, z+9, shield, ms);
		array.setBlock(x+1, y+8, z+10, shield, ms);
		array.setBlock(x+1, y+8, z+11, shield, ms);
		array.setBlock(x+1, y+8, z+12, shield, ms);
		array.setBlock(x+1, y+8, z+13, shield, ms);
		array.setBlock(x+2, y+1, z+6, shield, ms);
		array.setBlock(x+2, y+1, z+7, shield, ms);
		array.setBlock(x+2, y+1, z+8, shield, ms);
		array.setBlock(x+2, y+2, z+5, shield, ms);
		array.setBlock(x+2, y+2, z+9, shield, ms);
		array.setBlock(x+2, y+3, z+5, shield, ms);
		array.setBlock(x+2, y+3, z+9, shield, ms);
		array.setBlock(x+2, y+4, z+5, shield, ms);
		array.setBlock(x+2, y+4, z+9, shield, ms);
		array.setBlock(x+2, y+5, z+2, shield, ms);
		array.setBlock(x+2, y+5, z+3, shield, ms);
		array.setBlock(x+2, y+5, z+4, shield, ms);
		array.setBlock(x+2, y+5, z+5, shield, ms);
		array.setBlock(x+2, y+5, z+9, shield, ms);
		array.setBlock(x+2, y+5, z+10, shield, ms);
		array.setBlock(x+2, y+5, z+11, shield, ms);
		array.setBlock(x+2, y+5, z+12, shield, ms);
		array.setBlock(x+2, y+6, z+1, shield, ms);
		array.setBlock(x+2, y+6, z+13, shield, ms);
		array.setBlock(x+2, y+7, z+1, shield, ms);
		array.setBlock(x+2, y+7, z+7, shield, ms);
		array.setBlock(x+2, y+7, z+13, shield, ms);
		array.setBlock(x+2, y+8, z+1, shield, ms);
		array.setBlock(x+2, y+8, z+7, shield, ms);
		array.setBlock(x+2, y+8, z+13, shield, ms);
		array.setBlock(x+2, y+9, z+2, shield, ms);
		array.setBlock(x+2, y+9, z+3, shield, ms);
		array.setBlock(x+2, y+9, z+4, shield, ms);
		array.setBlock(x+2, y+9, z+5, shield, ms);
		array.setBlock(x+2, y+9, z+6, shield, ms);
		array.setBlock(x+2, y+9, z+7, shield, ms);
		array.setBlock(x+2, y+9, z+8, shield, ms);
		array.setBlock(x+2, y+9, z+9, shield, ms);
		array.setBlock(x+2, y+9, z+10, shield, ms);
		array.setBlock(x+2, y+9, z+11, shield, ms);
		array.setBlock(x+2, y+9, z+12, shield, ms);
		array.setBlock(x+3, y+1, z+6, shield, ms);
		array.setBlock(x+3, y+1, z+7, shield, ms);
		array.setBlock(x+3, y+1, z+8, shield, ms);
		array.setBlock(x+3, y+2, z+4, shield, ms);
		array.setBlock(x+3, y+2, z+5, shield, ms);
		array.setBlock(x+3, y+2, z+9, shield, ms);
		array.setBlock(x+3, y+2, z+10, shield, ms);
		array.setBlock(x+3, y+3, z+4, shield, ms);
		array.setBlock(x+3, y+3, z+5, shield, ms);
		array.setBlock(x+3, y+3, z+9, shield, ms);
		array.setBlock(x+3, y+3, z+10, shield, ms);
		array.setBlock(x+3, y+4, z+4, shield, ms);
		array.setBlock(x+3, y+4, z+5, shield, ms);
		array.setBlock(x+3, y+4, z+9, shield, ms);
		array.setBlock(x+3, y+4, z+10, shield, ms);
		array.setBlock(x+3, y+5, z+2, shield, ms);
		array.setBlock(x+3, y+5, z+3, shield, ms);
		array.setBlock(x+3, y+5, z+4, shield, ms);
		array.setBlock(x+3, y+5, z+5, shield, ms);
		array.setBlock(x+3, y+5, z+9, shield, ms);
		array.setBlock(x+3, y+5, z+10, shield, ms);
		array.setBlock(x+3, y+5, z+11, shield, ms);
		array.setBlock(x+3, y+5, z+12, shield, ms);
		array.setBlock(x+3, y+6, z+1, shield, ms);
		array.setBlock(x+3, y+6, z+13, shield, ms);
		array.setBlock(x+3, y+7, z+1, shield, ms);
		array.setBlock(x+3, y+7, z+7, shield, ms);
		array.setBlock(x+3, y+7, z+13, shield, ms);
		array.setBlock(x+3, y+8, z+1, shield, ms);
		array.setBlock(x+3, y+8, z+7, shield, ms);
		array.setBlock(x+3, y+8, z+13, shield, ms);
		array.setBlock(x+3, y+9, z+2, shield, ms);
		array.setBlock(x+3, y+9, z+3, shield, ms);
		array.setBlock(x+3, y+9, z+4, shield, ms);
		array.setBlock(x+3, y+9, z+5, shield, ms);
		array.setBlock(x+3, y+9, z+6, shield, ms);
		array.setBlock(x+3, y+9, z+7, shield, ms);
		array.setBlock(x+3, y+9, z+8, shield, ms);
		array.setBlock(x+3, y+9, z+9, shield, ms);
		array.setBlock(x+3, y+9, z+10, shield, ms);
		array.setBlock(x+3, y+9, z+11, shield, ms);
		array.setBlock(x+3, y+9, z+12, shield, ms);
		array.setBlock(x+4, y+1, z+5, shield, ms);
		array.setBlock(x+4, y+1, z+6, shield, ms);
		array.setBlock(x+4, y+1, z+7, shield, ms);
		array.setBlock(x+4, y+1, z+8, shield, ms);
		array.setBlock(x+4, y+1, z+9, shield, ms);
		array.setBlock(x+4, y+2, z+3, shield, ms);
		array.setBlock(x+4, y+2, z+4, shield, ms);
		array.setBlock(x+4, y+2, z+10, shield, ms);
		array.setBlock(x+4, y+2, z+11, shield, ms);
		array.setBlock(x+4, y+3, z+3, shield, ms);
		array.setBlock(x+4, y+3, z+4, shield, ms);
		array.setBlock(x+4, y+3, z+10, shield, ms);
		array.setBlock(x+4, y+3, z+11, shield, ms);
		array.setBlock(x+4, y+4, z+3, shield, ms);
		array.setBlock(x+4, y+4, z+4, shield, ms);
		array.setBlock(x+4, y+4, z+10, shield, ms);
		array.setBlock(x+4, y+4, z+11, shield, ms);
		array.setBlock(x+4, y+5, z+2, shield, ms);
		array.setBlock(x+4, y+5, z+3, shield, ms);
		array.setBlock(x+4, y+5, z+4, Blocks.mob_spawner);
		array.setBlock(x+4, y+5, z+5, shield, mc);
		array.setBlock(x+4, y+5, z+6, shield, mc);
		array.setBlock(x+4, y+5, z+7, shield, mc);
		array.setBlock(x+4, y+5, z+8, shield, mc);
		array.setBlock(x+4, y+5, z+9, shield, mc);
		array.setBlock(x+4, y+5, z+10, Blocks.mob_spawner);
		array.setBlock(x+4, y+5, z+11, shield, ms);
		array.setBlock(x+4, y+5, z+12, shield, ms);
		array.setBlock(x+4, y+6, z+1, shield, ms);
		array.setBlock(x+4, y+6, z+4, shield, mc);
		array.setBlock(x+4, y+6, z+7, shield, mc);
		array.setBlock(x+4, y+6, z+10, shield, mc);
		array.setBlock(x+4, y+6, z+13, shield, ms);
		array.setBlock(x+4, y+7, z+1, shield, ms);
		array.setBlock(x+4, y+7, z+4, shield, mc);
		array.setBlock(x+4, y+7, z+7, shield, mc);
		array.setBlock(x+4, y+7, z+10, shield, mc);
		array.setBlock(x+4, y+7, z+13, shield, ms);
		array.setBlock(x+4, y+8, z+1, shield, ms);
		array.setBlock(x+4, y+8, z+4, shield, mc);
		array.setBlock(x+4, y+8, z+7, shield, mc);
		array.setBlock(x+4, y+8, z+10, shield, mc);
		array.setBlock(x+4, y+8, z+13, shield, ms);
		array.setBlock(x+4, y+9, z+2, shield, ms);
		array.setBlock(x+4, y+9, z+3, shield, ms);
		array.setBlock(x+4, y+9, z+4, shield, mc);
		array.setBlock(x+4, y+9, z+5, shield, mc);
		array.setBlock(x+4, y+9, z+6, shield, mc);
		array.setBlock(x+4, y+9, z+7, shield, mc);
		array.setBlock(x+4, y+9, z+8, shield, mc);
		array.setBlock(x+4, y+9, z+9, shield, mc);
		array.setBlock(x+4, y+9, z+10, shield, mc);
		array.setBlock(x+4, y+9, z+11, shield, ms);
		array.setBlock(x+4, y+9, z+12, shield, ms);
		array.setBlock(x+4, y+10, z+5, shield, mc);
		array.setBlock(x+4, y+10, z+6, shield, ms);
		array.setBlock(x+4, y+10, z+7, shield, mc);
		array.setBlock(x+4, y+10, z+8, shield, ms);
		array.setBlock(x+4, y+10, z+9, shield, mc);
		array.setBlock(x+5, y+1, z+4, shield, ms);
		array.setBlock(x+5, y+1, z+5, shield, ms);
		array.setBlock(x+5, y+1, z+6, shield, ms);
		array.setBlock(x+5, y+1, z+7, shield, ms);
		array.setBlock(x+5, y+1, z+8, shield, ms);
		array.setBlock(x+5, y+1, z+9, shield, ms);
		array.setBlock(x+5, y+1, z+10, shield, ms);
		array.setBlock(x+5, y+2, z+1, shield, ms);
		array.setBlock(x+5, y+2, z+2, shield, ms);
		array.setBlock(x+5, y+2, z+3, shield, ms);
		array.setBlock(x+5, y+2, z+5, shield, ms);
		array.setBlock(x+5, y+2, z+9, shield, ms);
		array.setBlock(x+5, y+2, z+11, shield, ms);
		array.setBlock(x+5, y+2, z+12, shield, ms);
		array.setBlock(x+5, y+2, z+13, shield, ms);
		array.setBlock(x+5, y+3, z+1, shield, ms);
		array.setBlock(x+5, y+3, z+2, shield, ms);
		array.setBlock(x+5, y+3, z+3, shield, ms);
		array.setBlock(x+5, y+3, z+5, shield, ms);
		array.setBlock(x+5, y+3, z+9, shield, ms);
		array.setBlock(x+5, y+3, z+11, shield, ms);
		array.setBlock(x+5, y+3, z+12, shield, ms);
		array.setBlock(x+5, y+3, z+13, shield, ms);
		array.setBlock(x+5, y+4, z+1, shield, ms);
		array.setBlock(x+5, y+4, z+2, shield, ms);
		array.setBlock(x+5, y+4, z+3, shield, ms);
		array.setBlock(x+5, y+4, z+5, shield, ms);
		array.setBlock(x+5, y+4, z+9, shield, ms);
		array.setBlock(x+5, y+4, z+11, shield, ms);
		array.setBlock(x+5, y+4, z+12, shield, ms);
		array.setBlock(x+5, y+4, z+13, shield, ms);
		array.setBlock(x+5, y+5, z+2, shield, ms);
		array.setBlock(x+5, y+5, z+3, shield, ms);
		array.setBlock(x+5, y+5, z+4, shield, mc);
		array.setBlock(x+5, y+5, z+6, shield, ms);
		array.setBlock(x+5, y+5, z+7, shield, ms);
		array.setBlock(x+5, y+5, z+8, shield, ms);
		array.setBlock(x+5, y+5, z+10, shield, mc);
		array.setBlock(x+5, y+5, z+11, shield, ms);
		array.setBlock(x+5, y+5, z+12, shield, ms);
		array.setBlock(x+5, y+6, z+1, shield, ms);
		array.setBlock(x+5, y+6, z+13, shield, ms);
		array.setBlock(x+5, y+7, z+1, shield, ms);
		array.setBlock(x+5, y+7, z+13, shield, ms);
		array.setBlock(x+5, y+8, z+1, shield, ms);
		array.setBlock(x+5, y+8, z+13, shield, ms);
		array.setBlock(x+5, y+9, z+2, shield, ms);
		array.setBlock(x+5, y+9, z+3, shield, ms);
		array.setBlock(x+5, y+9, z+4, shield, mc);
		array.setBlock(x+5, y+9, z+6, shield, ms);
		array.setBlock(x+5, y+9, z+8, shield, ms);
		array.setBlock(x+5, y+9, z+10, shield, mc);
		array.setBlock(x+5, y+9, z+11, shield, ms);
		array.setBlock(x+5, y+9, z+12, shield, ms);
		array.setBlock(x+5, y+10, z+4, shield, mc);
		array.setBlock(x+5, y+10, z+6, shield, ms);
		array.setBlock(x+5, y+10, z+7, shield, ms);
		array.setBlock(x+5, y+10, z+8, shield, ms);
		array.setBlock(x+5, y+10, z+10, shield, mc);
		array.setBlock(x+5, y+11, z+6, shield, mc);
		array.setBlock(x+5, y+11, z+8, shield, mc);
		array.setBlock(x+6, y+1, z+2, shield, ms);
		array.setBlock(x+6, y+1, z+3, shield, ms);
		array.setBlock(x+6, y+1, z+4, shield, ms);
		array.setBlock(x+6, y+1, z+5, shield, ms);
		array.setBlock(x+6, y+1, z+6, shield, ms);
		array.setBlock(x+6, y+1, z+7, shield, ms);
		array.setBlock(x+6, y+1, z+8, shield, ms);
		array.setBlock(x+6, y+1, z+9, shield, ms);
		array.setBlock(x+6, y+1, z+10, shield, ms);
		array.setBlock(x+6, y+1, z+11, shield, ms);
		array.setBlock(x+6, y+1, z+12, shield, ms);
		array.setBlock(x+6, y+2, z+1, shield, ms);
		array.setBlock(x+6, y+2, z+6, shield, ms);
		array.setBlock(x+6, y+2, z+8, shield, ms);
		array.setBlock(x+6, y+2, z+13, shield, ms);
		array.setBlock(x+6, y+3, z+1, shield, ms);
		array.setBlock(x+6, y+3, z+6, shield, ms);
		array.setBlock(x+6, y+3, z+8, shield, ms);
		array.setBlock(x+6, y+3, z+13, shield, ms);
		array.setBlock(x+6, y+4, z+1, shield, ms);
		array.setBlock(x+6, y+4, z+6, shield, ms);
		array.setBlock(x+6, y+4, z+8, shield, ms);
		array.setBlock(x+6, y+4, z+13, shield, ms);
		array.setBlock(x+6, y+5, z+4, shield, mc);
		array.setBlock(x+6, y+5, z+5, shield, ms);
		array.setBlock(x+6, y+5, z+6, shield, ms);
		array.setBlock(x+6, y+5, z+7, shield, ms);
		array.setBlock(x+6, y+5, z+8, shield, ms);
		array.setBlock(x+6, y+5, z+9, shield, ms);
		array.setBlock(x+6, y+5, z+10, shield, mc);
		array.setBlock(x+6, y+6, z+1, shield, ms);
		array.setBlock(x+6, y+6, z+13, shield, ms);
		array.setBlock(x+6, y+7, z+1, shield, ms);
		array.setBlock(x+6, y+7, z+13, shield, ms);
		array.setBlock(x+6, y+8, z+1, shield, ms);
		array.setBlock(x+6, y+8, z+13, shield, ms);
		array.setBlock(x+6, y+9, z+2, shield, ms);
		array.setBlock(x+6, y+9, z+3, shield, ms);
		array.setBlock(x+6, y+9, z+4, shield, mc);
		array.setBlock(x+6, y+9, z+5, shield, ms);
		array.setBlock(x+6, y+9, z+9, shield, ms);
		array.setBlock(x+6, y+9, z+10, shield, mc);
		array.setBlock(x+6, y+9, z+11, shield, ms);
		array.setBlock(x+6, y+9, z+12, shield, ms);
		array.setBlock(x+6, y+10, z+4, shield, ms);
		array.setBlock(x+6, y+10, z+5, shield, ms);
		array.setBlock(x+6, y+10, z+6, shield, ms);
		array.setBlock(x+6, y+10, z+7, shield, ms);
		array.setBlock(x+6, y+10, z+8, shield, ms);
		array.setBlock(x+6, y+10, z+9, shield, ms);
		array.setBlock(x+6, y+10, z+10, shield, ms);
		array.setBlock(x+6, y+11, z+5, shield, mc);
		array.setBlock(x+6, y+11, z+9, shield, mc);
		array.setBlock(x+7, y+1, z+2, shield, ms);
		array.setBlock(x+7, y+1, z+3, shield, ms);
		array.setBlock(x+7, y+1, z+4, shield, ms);
		array.setBlock(x+7, y+1, z+5, shield, ms);
		array.setBlock(x+7, y+1, z+6, shield, ms);
		array.setBlock(x+7, y+0, z+7, shield, ms);
		array.setBlock(x+7, y+1, z+7, Blocks.mob_spawner);
		array.setBlock(x+7, y+1, z+8, shield, ms);
		array.setBlock(x+7, y+1, z+9, shield, ms);
		array.setBlock(x+7, y+1, z+10, shield, ms);
		array.setBlock(x+7, y+1, z+11, shield, ms);
		array.setBlock(x+7, y+1, z+12, shield, ms);
		array.setBlock(x+7, y+2, z+1, shield, ms);
		array.setBlock(x+7, y+2, z+7, shield, ms);
		array.setBlock(x+7, y+2, z+13, shield, ms);
		array.setBlock(x+7, y+3, z+1, shield, ms);
		array.setBlock(x+7, y+3, z+13, shield, ms);
		array.setBlock(x+7, y+4, z+1, shield, ms);
		array.setBlock(x+7, y+4, z+7, shield, ms);
		array.setBlock(x+7, y+4, z+13, shield, ms);
		array.setBlock(x+7, y+5, z+4, shield, mc);
		array.setBlock(x+7, y+5, z+5, shield, ms);
		array.setBlock(x+7, y+5, z+6, shield, ms);
		array.setBlock(x+7, y+5, z+7, shield, ms);
		array.setBlock(x+7, y+5, z+8, shield, ms);
		array.setBlock(x+7, y+5, z+9, shield, ms);
		array.setBlock(x+7, y+5, z+10, shield, mc);
		array.setBlock(x+7, y+6, z+1, shield, ms);
		array.setBlock(x+7, y+6, z+4, shield, mc);
		array.setBlock(x+7, y+6, z+10, shield, mc);
		array.setBlock(x+7, y+6, z+13, shield, ms);
		array.setBlock(x+7, y+7, z+1, shield, ms);
		array.setBlock(x+7, y+7, z+2, shield, ms);
		array.setBlock(x+7, y+7, z+3, shield, ms);
		array.setBlock(x+7, y+7, z+4, shield, mc);
		array.setBlock(x+7, y+7, z+10, shield, mc);
		array.setBlock(x+7, y+7, z+11, shield, ms);
		array.setBlock(x+7, y+7, z+12, shield, ms);
		array.setBlock(x+7, y+7, z+13, shield, ms);
		array.setBlock(x+7, y+8, z+1, shield, ms);
		array.setBlock(x+7, y+8, z+2, shield, ms);
		array.setBlock(x+7, y+8, z+3, shield, ms);
		array.setBlock(x+7, y+8, z+4, shield, mc);
		array.setBlock(x+7, y+8, z+10, shield, mc);
		array.setBlock(x+7, y+8, z+11, shield, ms);
		array.setBlock(x+7, y+8, z+12, shield, ms);
		array.setBlock(x+7, y+8, z+13, shield, ms);
		array.setBlock(x+7, y+9, z+2, shield, ms);
		array.setBlock(x+7, y+9, z+3, shield, ms);
		array.setBlock(x+7, y+9, z+4, shield, mc);
		array.setBlock(x+7, y+9, z+10, shield, mc);
		array.setBlock(x+7, y+9, z+11, shield, ms);
		array.setBlock(x+7, y+9, z+12, shield, ms);
		array.setBlock(x+7, y+10, z+4, shield, mc);
		array.setBlock(x+7, y+10, z+5, shield, ms);
		array.setBlock(x+7, y+10, z+6, shield, ms);
		array.setBlock(x+7, y+10, z+7, shield, ms);
		array.setBlock(x+7, y+10, z+8, shield, ms);
		array.setBlock(x+7, y+10, z+9, shield, ms);
		array.setBlock(x+7, y+10, z+10, shield, mc);
		array.setBlock(x+8, y+1, z+2, shield, ms);
		array.setBlock(x+8, y+1, z+3, shield, ms);
		array.setBlock(x+8, y+1, z+4, shield, ms);
		array.setBlock(x+8, y+1, z+5, shield, ms);
		array.setBlock(x+8, y+1, z+6, shield, ms);
		array.setBlock(x+8, y+1, z+7, shield, ms);
		array.setBlock(x+8, y+1, z+8, shield, ms);
		array.setBlock(x+8, y+1, z+9, shield, ms);
		array.setBlock(x+8, y+1, z+10, shield, ms);
		array.setBlock(x+8, y+1, z+11, shield, ms);
		array.setBlock(x+8, y+1, z+12, shield, ms);
		array.setBlock(x+8, y+2, z+1, shield, ms);
		array.setBlock(x+8, y+2, z+6, shield, ms);
		array.setBlock(x+8, y+2, z+8, shield, ms);
		array.setBlock(x+8, y+2, z+13, shield, ms);
		array.setBlock(x+8, y+3, z+1, shield, ms);
		array.setBlock(x+8, y+3, z+6, shield, ms);
		array.setBlock(x+8, y+3, z+8, shield, ms);
		array.setBlock(x+8, y+3, z+13, shield, ms);
		array.setBlock(x+8, y+4, z+1, shield, ms);
		array.setBlock(x+8, y+4, z+6, shield, ms);
		array.setBlock(x+8, y+4, z+8, shield, ms);
		array.setBlock(x+8, y+4, z+13, shield, ms);
		array.setBlock(x+8, y+5, z+4, shield, mc);
		array.setBlock(x+8, y+5, z+5, shield, ms);
		array.setBlock(x+8, y+5, z+6, shield, ms);
		array.setBlock(x+8, y+5, z+7, shield, ms);
		array.setBlock(x+8, y+5, z+8, shield, ms);
		array.setBlock(x+8, y+5, z+9, shield, ms);
		array.setBlock(x+8, y+5, z+10, shield, mc);
		array.setBlock(x+8, y+6, z+1, shield, ms);
		array.setBlock(x+8, y+6, z+13, shield, ms);
		array.setBlock(x+8, y+7, z+1, shield, ms);
		array.setBlock(x+8, y+7, z+13, shield, ms);
		array.setBlock(x+8, y+8, z+1, shield, ms);
		array.setBlock(x+8, y+8, z+13, shield, ms);
		array.setBlock(x+8, y+9, z+2, shield, ms);
		array.setBlock(x+8, y+9, z+3, shield, ms);
		array.setBlock(x+8, y+9, z+4, shield, mc);
		array.setBlock(x+8, y+9, z+5, shield, ms);
		array.setBlock(x+8, y+9, z+9, shield, ms);
		array.setBlock(x+8, y+9, z+10, shield, mc);
		array.setBlock(x+8, y+9, z+11, shield, ms);
		array.setBlock(x+8, y+9, z+12, shield, ms);
		array.setBlock(x+8, y+10, z+4, shield, ms);
		array.setBlock(x+8, y+10, z+5, shield, ms);
		array.setBlock(x+8, y+10, z+6, shield, ms);
		array.setBlock(x+8, y+10, z+7, shield, ms);
		array.setBlock(x+8, y+10, z+8, shield, ms);
		array.setBlock(x+8, y+10, z+9, shield, ms);
		array.setBlock(x+8, y+10, z+10, shield, ms);
		array.setBlock(x+8, y+11, z+5, shield, mc);
		array.setBlock(x+8, y+11, z+9, shield, mc);
		array.setBlock(x+9, y+1, z+4, shield, ms);
		array.setBlock(x+9, y+1, z+5, shield, ms);
		array.setBlock(x+9, y+1, z+6, shield, ms);
		array.setBlock(x+9, y+1, z+7, shield, ms);
		array.setBlock(x+9, y+1, z+8, shield, ms);
		array.setBlock(x+9, y+1, z+9, shield, ms);
		array.setBlock(x+9, y+1, z+10, shield, ms);
		array.setBlock(x+9, y+2, z+1, shield, ms);
		array.setBlock(x+9, y+2, z+2, shield, ms);
		array.setBlock(x+9, y+2, z+3, shield, ms);
		array.setBlock(x+9, y+2, z+5, shield, ms);
		array.setBlock(x+9, y+2, z+9, shield, ms);
		array.setBlock(x+9, y+2, z+11, shield, ms);
		array.setBlock(x+9, y+2, z+12, shield, ms);
		array.setBlock(x+9, y+2, z+13, shield, ms);
		array.setBlock(x+9, y+3, z+1, shield, ms);
		array.setBlock(x+9, y+3, z+2, shield, ms);
		array.setBlock(x+9, y+3, z+3, shield, ms);
		array.setBlock(x+9, y+3, z+5, shield, ms);
		array.setBlock(x+9, y+3, z+9, shield, ms);
		array.setBlock(x+9, y+3, z+11, shield, ms);
		array.setBlock(x+9, y+3, z+12, shield, ms);
		array.setBlock(x+9, y+3, z+13, shield, ms);
		array.setBlock(x+9, y+4, z+1, shield, ms);
		array.setBlock(x+9, y+4, z+2, shield, ms);
		array.setBlock(x+9, y+4, z+3, shield, ms);
		array.setBlock(x+9, y+4, z+5, shield, ms);
		array.setBlock(x+9, y+4, z+9, shield, ms);
		array.setBlock(x+9, y+4, z+11, shield, ms);
		array.setBlock(x+9, y+4, z+12, shield, ms);
		array.setBlock(x+9, y+4, z+13, shield, ms);
		array.setBlock(x+9, y+5, z+2, shield, ms);
		array.setBlock(x+9, y+5, z+3, shield, ms);
		array.setBlock(x+9, y+5, z+4, shield, mc);
		array.setBlock(x+9, y+5, z+6, shield, ms);
		array.setBlock(x+9, y+5, z+7, shield, ms);
		array.setBlock(x+9, y+5, z+8, shield, ms);
		array.setBlock(x+9, y+5, z+10, shield, mc);
		array.setBlock(x+9, y+5, z+11, shield, ms);
		array.setBlock(x+9, y+5, z+12, shield, ms);
		array.setBlock(x+9, y+6, z+1, shield, ms);
		array.setBlock(x+9, y+6, z+13, shield, ms);
		array.setBlock(x+9, y+7, z+1, shield, ms);
		array.setBlock(x+9, y+7, z+13, shield, ms);
		array.setBlock(x+9, y+8, z+1, shield, ms);
		array.setBlock(x+9, y+8, z+13, shield, ms);
		array.setBlock(x+9, y+9, z+2, shield, ms);
		array.setBlock(x+9, y+9, z+3, shield, ms);
		array.setBlock(x+9, y+9, z+4, shield, mc);
		array.setBlock(x+9, y+9, z+6, shield, ms);
		array.setBlock(x+9, y+9, z+8, shield, ms);
		array.setBlock(x+9, y+9, z+10, shield, mc);
		array.setBlock(x+9, y+9, z+11, shield, ms);
		array.setBlock(x+9, y+9, z+12, shield, ms);
		array.setBlock(x+9, y+10, z+4, shield, mc);
		array.setBlock(x+9, y+10, z+6, shield, ms);
		array.setBlock(x+9, y+10, z+7, shield, ms);
		array.setBlock(x+9, y+10, z+8, shield, ms);
		array.setBlock(x+9, y+10, z+10, shield, mc);
		array.setBlock(x+9, y+11, z+6, shield, mc);
		array.setBlock(x+9, y+11, z+8, shield, mc);
		array.setBlock(x+10, y+1, z+5, shield, ms);
		array.setBlock(x+10, y+1, z+6, shield, ms);
		array.setBlock(x+10, y+1, z+7, shield, ms);
		array.setBlock(x+10, y+1, z+8, shield, ms);
		array.setBlock(x+10, y+1, z+9, shield, ms);
		array.setBlock(x+10, y+2, z+3, shield, ms);
		array.setBlock(x+10, y+2, z+4, shield, ms);
		array.setBlock(x+10, y+2, z+10, shield, ms);
		array.setBlock(x+10, y+2, z+11, shield, ms);
		array.setBlock(x+10, y+3, z+3, shield, ms);
		array.setBlock(x+10, y+3, z+4, shield, ms);
		array.setBlock(x+10, y+3, z+10, shield, ms);
		array.setBlock(x+10, y+3, z+11, shield, ms);
		array.setBlock(x+10, y+4, z+3, shield, ms);
		array.setBlock(x+10, y+4, z+4, shield, ms);
		array.setBlock(x+10, y+4, z+10, shield, ms);
		array.setBlock(x+10, y+4, z+11, shield, ms);
		array.setBlock(x+10, y+5, z+2, shield, ms);
		array.setBlock(x+10, y+5, z+3, shield, ms);
		array.setBlock(x+10, y+5, z+4, Blocks.mob_spawner);
		array.setBlock(x+10, y+5, z+5, shield, mc);
		array.setBlock(x+10, y+5, z+6, shield, mc);
		array.setBlock(x+10, y+5, z+7, shield, mc);
		array.setBlock(x+10, y+5, z+8, shield, mc);
		array.setBlock(x+10, y+5, z+9, shield, mc);
		array.setBlock(x+10, y+5, z+10, Blocks.mob_spawner);
		array.setBlock(x+10, y+5, z+11, shield, ms);
		array.setBlock(x+10, y+5, z+12, shield, ms);
		array.setBlock(x+10, y+6, z+1, shield, ms);
		array.setBlock(x+10, y+6, z+4, shield, mc);
		array.setBlock(x+10, y+6, z+7, shield, mc);
		array.setBlock(x+10, y+6, z+10, shield, mc);
		array.setBlock(x+10, y+6, z+13, shield, ms);
		array.setBlock(x+10, y+7, z+1, shield, ms);
		array.setBlock(x+10, y+7, z+4, shield, mc);
		array.setBlock(x+10, y+7, z+7, shield, mc);
		array.setBlock(x+10, y+7, z+10, shield, mc);
		array.setBlock(x+10, y+7, z+13, shield, ms);
		array.setBlock(x+10, y+8, z+1, shield, ms);
		array.setBlock(x+10, y+8, z+4, shield, mc);
		array.setBlock(x+10, y+8, z+7, shield, mc);
		array.setBlock(x+10, y+8, z+10, shield, mc);
		array.setBlock(x+10, y+8, z+13, shield, ms);
		array.setBlock(x+10, y+9, z+2, shield, ms);
		array.setBlock(x+10, y+9, z+3, shield, ms);
		array.setBlock(x+10, y+9, z+4, shield, mc);
		array.setBlock(x+10, y+9, z+5, shield, mc);
		array.setBlock(x+10, y+9, z+6, shield, mc);
		array.setBlock(x+10, y+9, z+7, shield, mc);
		array.setBlock(x+10, y+9, z+8, shield, mc);
		array.setBlock(x+10, y+9, z+9, shield, mc);
		array.setBlock(x+10, y+9, z+10, shield, mc);
		array.setBlock(x+10, y+9, z+11, shield, ms);
		array.setBlock(x+10, y+9, z+12, shield, ms);
		array.setBlock(x+10, y+10, z+5, shield, mc);
		array.setBlock(x+10, y+10, z+6, shield, ms);
		array.setBlock(x+10, y+10, z+7, shield, mc);
		array.setBlock(x+10, y+10, z+8, shield, ms);
		array.setBlock(x+10, y+10, z+9, shield, mc);
		array.setBlock(x+11, y+1, z+6, shield, ms);
		array.setBlock(x+11, y+1, z+7, shield, ms);
		array.setBlock(x+11, y+1, z+8, shield, ms);
		array.setBlock(x+11, y+2, z+4, shield, ms);
		array.setBlock(x+11, y+2, z+5, shield, ms);
		array.setBlock(x+11, y+2, z+9, shield, ms);
		array.setBlock(x+11, y+2, z+10, shield, ms);
		array.setBlock(x+11, y+3, z+4, shield, ms);
		array.setBlock(x+11, y+3, z+5, shield, ms);
		array.setBlock(x+11, y+3, z+9, shield, ms);
		array.setBlock(x+11, y+3, z+10, shield, ms);
		array.setBlock(x+11, y+4, z+4, shield, ms);
		array.setBlock(x+11, y+4, z+5, shield, ms);
		array.setBlock(x+11, y+4, z+9, shield, ms);
		array.setBlock(x+11, y+4, z+10, shield, ms);
		array.setBlock(x+11, y+5, z+2, shield, ms);
		array.setBlock(x+11, y+5, z+3, shield, ms);
		array.setBlock(x+11, y+5, z+4, shield, ms);
		array.setBlock(x+11, y+5, z+5, shield, ms);
		array.setBlock(x+11, y+5, z+9, shield, ms);
		array.setBlock(x+11, y+5, z+10, shield, ms);
		array.setBlock(x+11, y+5, z+11, shield, ms);
		array.setBlock(x+11, y+5, z+12, shield, ms);
		array.setBlock(x+11, y+8, z+1, shield, ms);
		array.setBlock(x+11, y+8, z+7, shield, ms);
		array.setBlock(x+11, y+8, z+13, shield, ms);
		array.setBlock(x+11, y+7, z+1, shield, ms);
		array.setBlock(x+11, y+7, z+7, shield, ms);
		array.setBlock(x+11, y+7, z+13, shield, ms);
		array.setBlock(x+11, y+6, z+1, shield, ms);
		array.setBlock(x+11, y+6, z+13, shield, ms);
		array.setBlock(x+11, y+9, z+2, shield, ms);
		array.setBlock(x+11, y+9, z+3, shield, ms);
		array.setBlock(x+11, y+9, z+4, shield, ms);
		array.setBlock(x+11, y+9, z+5, shield, ms);
		array.setBlock(x+11, y+9, z+6, shield, ms);
		array.setBlock(x+11, y+9, z+7, shield, ms);
		array.setBlock(x+11, y+9, z+8, shield, ms);
		array.setBlock(x+11, y+9, z+9, shield, ms);
		array.setBlock(x+11, y+9, z+10, shield, ms);
		array.setBlock(x+11, y+9, z+11, shield, ms);
		array.setBlock(x+11, y+9, z+12, shield, ms);
		array.setBlock(x+12, y+1, z+6, shield, ms);
		array.setBlock(x+12, y+1, z+7, shield, ms);
		array.setBlock(x+12, y+1, z+8, shield, ms);
		array.setBlock(x+12, y+2, z+5, shield, ms);
		array.setBlock(x+12, y+2, z+9, shield, ms);
		array.setBlock(x+12, y+3, z+5, shield, ms);
		array.setBlock(x+12, y+3, z+9, shield, ms);
		array.setBlock(x+12, y+4, z+5, shield, ms);
		array.setBlock(x+12, y+4, z+9, shield, ms);
		array.setBlock(x+12, y+5, z+2, shield, ms);
		array.setBlock(x+12, y+5, z+3, shield, ms);
		array.setBlock(x+12, y+5, z+4, shield, ms);
		array.setBlock(x+12, y+5, z+5, shield, ms);
		array.setBlock(x+12, y+5, z+6, shield, mcrack);
		array.setBlock(x+12, y+5, z+7, shield, mcrack);
		array.setBlock(x+12, y+5, z+8, shield, mcrack);
		array.setBlock(x+12, y+6, z+7, shield, mcrack);
		array.setBlock(x+11, y+5, z+6, shield, mcrack);
		array.setBlock(x+11, y+5, z+7, shield, mcrack);
		array.setBlock(x+11, y+5, z+8, shield, mcrack);
		array.setBlock(x+8, y+5, z+11, shield, mcrack);
		array.setBlock(x+8, y+5, z+12, shield, mcrack);
		array.setBlock(x+8, y+5, z+2, shield, mcrack);
		array.setBlock(x+8, y+5, z+3, shield, mcrack);
		array.setBlock(x+7, y+5, z+11, shield, mcrack);
		array.setBlock(x+7, y+5, z+12, shield, mcrack);
		array.setBlock(x+2, y+5, z+6, shield, mcrack);
		array.setBlock(x+2, y+5, z+7, shield, mcrack);
		array.setBlock(x+2, y+5, z+8, shield, mcrack);
		array.setBlock(x+2, y+6, z+7, shield, mcrack);
		array.setBlock(x+3, y+5, z+6, shield, mcrack);
		array.setBlock(x+3, y+5, z+7, shield, mcrack);
		array.setBlock(x+3, y+5, z+8, shield, mcrack);
		array.setBlock(x+3, y+6, z+7, shield, mcrack);
		array.setBlock(x+6, y+5, z+2, shield, mcrack);
		array.setBlock(x+6, y+5, z+3, shield, mcrack);
		array.setBlock(x+6, y+5, z+11, shield, mcrack);
		array.setBlock(x+6, y+5, z+12, shield, mcrack);
		array.setBlock(x+7, y+5, z+2, shield, mcrack);
		array.setBlock(x+7, y+5, z+3, shield, mcrack);
		array.setBlock(x+7, y+6, z+2, shield, mcrack);
		array.setBlock(x+7, y+6, z+3, shield, mcrack);
		array.setBlock(x+7, y+6, z+11, shield, mcrack);
		array.setBlock(x+7, y+6, z+12, shield, mcrack);
		array.setBlock(x+11, y+6, z+7, shield, mcrack);
		array.setBlock(x+12, y+5, z+9, shield, ms);
		array.setBlock(x+12, y+5, z+10, shield, ms);
		array.setBlock(x+12, y+5, z+11, shield, ms);
		array.setBlock(x+12, y+5, z+12, shield, ms);
		array.setBlock(x+12, y+6, z+1, shield, ms);
		array.setBlock(x+12, y+6, z+13, shield, ms);
		array.setBlock(x+12, y+7, z+1, shield, ms);
		array.setBlock(x+12, y+7, z+7, shield, ms);
		array.setBlock(x+12, y+7, z+13, shield, ms);
		array.setBlock(x+12, y+8, z+1, shield, ms);
		array.setBlock(x+12, y+8, z+7, shield, ms);
		array.setBlock(x+12, y+8, z+13, shield, ms);
		array.setBlock(x+12, y+9, z+2, shield, ms);
		array.setBlock(x+12, y+9, z+3, shield, ms);
		array.setBlock(x+12, y+9, z+4, shield, ms);
		array.setBlock(x+12, y+9, z+5, shield, ms);
		array.setBlock(x+12, y+9, z+6, shield, ms);
		array.setBlock(x+12, y+9, z+7, shield, ms);
		array.setBlock(x+12, y+9, z+8, shield, ms);
		array.setBlock(x+12, y+9, z+9, shield, ms);
		array.setBlock(x+12, y+9, z+10, shield, ms);
		array.setBlock(x+12, y+9, z+11, shield, ms);
		array.setBlock(x+12, y+9, z+12, shield, ms);
		array.setBlock(x+13, y+2, z+5, shield, ms);
		array.setBlock(x+13, y+2, z+6, shield, ms);
		array.setBlock(x+13, y+2, z+7, shield, ms);
		array.setBlock(x+13, y+2, z+8, shield, ms);
		array.setBlock(x+13, y+2, z+9, shield, ms);
		array.setBlock(x+13, y+3, z+5, shield, ms);
		array.setBlock(x+13, y+3, z+6, shield, ms);
		array.setBlock(x+13, y+3, z+7, shield, ms);
		array.setBlock(x+13, y+3, z+8, shield, ms);
		array.setBlock(x+13, y+3, z+9, shield, ms);
		array.setBlock(x+13, y+4, z+5, shield, ms);
		array.setBlock(x+13, y+4, z+6, shield, ms);
		array.setBlock(x+13, y+4, z+7, shield, ms);
		array.setBlock(x+13, y+4, z+8, shield, ms);
		array.setBlock(x+13, y+4, z+9, shield, ms);
		array.setBlock(x+13, y+6, z+1, shield, ms);
		array.setBlock(x+13, y+6, z+2, shield, ms);
		array.setBlock(x+13, y+6, z+3, shield, ms);
		array.setBlock(x+13, y+6, z+4, shield, ms);
		array.setBlock(x+13, y+6, z+5, shield, ms);
		array.setBlock(x+13, y+6, z+6, shield, ms);
		array.setBlock(x+13, y+6, z+7, shield, ms);
		array.setBlock(x+13, y+6, z+8, shield, ms);
		array.setBlock(x+13, y+6, z+9, shield, ms);
		array.setBlock(x+13, y+6, z+10, shield, ms);
		array.setBlock(x+13, y+6, z+11, shield, ms);
		array.setBlock(x+13, y+6, z+12, shield, ms);
		array.setBlock(x+13, y+6, z+13, shield, ms);
		array.setBlock(x+13, y+7, z+1, shield, ms);
		array.setBlock(x+13, y+7, z+2, shield, ms);
		array.setBlock(x+13, y+7, z+3, shield, ms);
		array.setBlock(x+13, y+7, z+4, shield, ms);
		array.setBlock(x+13, y+7, z+5, shield, ms);
		array.setBlock(x+13, y+7, z+6, shield, ms);
		array.setBlock(x+13, y+7, z+7, shield, ms);
		array.setBlock(x+13, y+7, z+8, shield, ms);
		array.setBlock(x+13, y+7, z+9, shield, ms);
		array.setBlock(x+13, y+7, z+10, shield, ms);
		array.setBlock(x+13, y+7, z+11, shield, ms);
		array.setBlock(x+13, y+7, z+12, shield, ms);
		array.setBlock(x+13, y+7, z+13, shield, ms);
		array.setBlock(x+13, y+8, z+1, shield, ms);
		array.setBlock(x+13, y+8, z+2, shield, ms);
		array.setBlock(x+13, y+8, z+3, shield, ms);
		array.setBlock(x+13, y+8, z+4, shield, ms);
		array.setBlock(x+13, y+8, z+5, shield, ms);
		array.setBlock(x+13, y+8, z+6, shield, ms);
		array.setBlock(x+13, y+8, z+7, shield, ms);
		array.setBlock(x+13, y+8, z+8, shield, ms);
		array.setBlock(x+13, y+8, z+9, shield, ms);
		array.setBlock(x+13, y+8, z+10, shield, ms);
		array.setBlock(x+13, y+8, z+11, shield, ms);
		array.setBlock(x+13, y+8, z+12, shield, ms);
		array.setBlock(x+13, y+8, z+13, shield, ms);

		for (int i = 5; i <= 9; i++) {
			for (int k = 5; k <= 9; k++) {
				array.setBlock(x+i, y+5, z+k, shield, BlockType.CLOAK.metadata);
			}
		}

		array.setBlock(x+5, y+5, z+5, Blocks.sandstone);
		array.setBlock(x+5, y+5, z+9, Blocks.sandstone);
		array.setBlock(x+9, y+5, z+5, Blocks.sandstone);
		array.setBlock(x+9, y+5, z+9, Blocks.sandstone);

		array.setBlock(x+2, y+2, z+6, Blocks.air);
		array.setBlock(x+2, y+2, z+7, Blocks.air);
		array.setBlock(x+2, y+2, z+8, Blocks.air);
		array.setBlock(x+2, y+3, z+6, Blocks.air);
		array.setBlock(x+2, y+3, z+7, Blocks.air);
		array.setBlock(x+2, y+3, z+8, Blocks.air);
		array.setBlock(x+2, y+4, z+6, Blocks.air);
		array.setBlock(x+2, y+4, z+7, Blocks.air);
		array.setBlock(x+2, y+4, z+8, Blocks.air);
		array.setBlock(x+2, y+6, z+2, Blocks.air);
		array.setBlock(x+2, y+6, z+3, Blocks.air);
		array.setBlock(x+2, y+6, z+5, Blocks.air);
		array.setBlock(x+2, y+6, z+6, Blocks.air);
		array.setBlock(x+2, y+6, z+8, Blocks.air);
		array.setBlock(x+2, y+6, z+9, Blocks.air);
		array.setBlock(x+2, y+6, z+11, Blocks.air);
		array.setBlock(x+2, y+6, z+12, Blocks.air);
		array.setBlock(x+2, y+7, z+2, Blocks.air);
		array.setBlock(x+2, y+7, z+3, Blocks.air);
		array.setBlock(x+2, y+7, z+4, Blocks.air);
		array.setBlock(x+2, y+7, z+5, Blocks.air);
		array.setBlock(x+2, y+7, z+6, Blocks.air);
		array.setBlock(x+2, y+7, z+8, Blocks.air);
		array.setBlock(x+2, y+7, z+9, Blocks.air);
		array.setBlock(x+2, y+7, z+10, Blocks.air);
		array.setBlock(x+2, y+7, z+11, Blocks.air);
		array.setBlock(x+2, y+7, z+12, Blocks.air);
		array.setBlock(x+2, y+8, z+2, Blocks.air);
		array.setBlock(x+2, y+8, z+3, Blocks.air);
		array.setBlock(x+2, y+8, z+4, Blocks.air);
		array.setBlock(x+2, y+8, z+5, Blocks.air);
		array.setBlock(x+2, y+8, z+6, Blocks.air);
		array.setBlock(x+2, y+8, z+8, Blocks.air);
		array.setBlock(x+2, y+8, z+9, Blocks.air);
		array.setBlock(x+2, y+8, z+10, Blocks.air);
		array.setBlock(x+2, y+8, z+11, Blocks.air);
		array.setBlock(x+2, y+8, z+12, Blocks.air);
		array.setBlock(x+3, y+2, z+6, Blocks.air);
		array.setBlock(x+3, y+2, z+7, Blocks.air);
		array.setBlock(x+3, y+2, z+8, Blocks.air);
		array.setBlock(x+3, y+3, z+6, Blocks.air);
		array.setBlock(x+3, y+3, z+7, Blocks.air);
		array.setBlock(x+3, y+3, z+8, Blocks.air);
		array.setBlock(x+3, y+4, z+6, Blocks.air);
		array.setBlock(x+3, y+4, z+7, Blocks.air);
		array.setBlock(x+3, y+4, z+8, Blocks.air);
		array.setBlock(x+3, y+6, z+2, Blocks.air);
		array.setBlock(x+3, y+6, z+3, Blocks.air);
		array.setBlock(x+3, y+6, z+4, Blocks.air);
		array.setBlock(x+3, y+6, z+5, Blocks.air);
		array.setBlock(x+3, y+6, z+6, Blocks.air);
		array.setBlock(x+3, y+6, z+8, Blocks.air);
		array.setBlock(x+3, y+6, z+9, Blocks.air);
		array.setBlock(x+3, y+6, z+10, Blocks.air);
		array.setBlock(x+3, y+6, z+11, Blocks.air);
		array.setBlock(x+3, y+6, z+12, Blocks.air);
		array.setBlock(x+3, y+7, z+2, Blocks.air);
		array.setBlock(x+3, y+7, z+3, Blocks.air);
		array.setBlock(x+3, y+7, z+4, Blocks.air);
		array.setBlock(x+3, y+7, z+5, Blocks.air);
		array.setBlock(x+3, y+7, z+6, Blocks.air);
		array.setBlock(x+3, y+7, z+8, Blocks.air);
		array.setBlock(x+3, y+7, z+9, Blocks.air);
		array.setBlock(x+3, y+7, z+10, Blocks.air);
		array.setBlock(x+3, y+7, z+11, Blocks.air);
		array.setBlock(x+3, y+7, z+12, Blocks.air);
		array.setBlock(x+3, y+8, z+2, Blocks.air);
		array.setBlock(x+3, y+8, z+3, Blocks.air);
		array.setBlock(x+3, y+8, z+4, Blocks.air);
		array.setBlock(x+3, y+8, z+5, Blocks.air);
		array.setBlock(x+3, y+8, z+6, Blocks.air);
		array.setBlock(x+3, y+8, z+8, Blocks.air);
		array.setBlock(x+3, y+8, z+9, Blocks.air);
		array.setBlock(x+3, y+8, z+10, Blocks.air);
		array.setBlock(x+3, y+8, z+11, Blocks.air);
		array.setBlock(x+3, y+8, z+12, Blocks.air);
		array.setBlock(x+4, y+2, z+5, Blocks.air);
		array.setBlock(x+4, y+2, z+6, Blocks.air);
		array.setBlock(x+4, y+2, z+7, Blocks.air);
		array.setBlock(x+4, y+2, z+8, Blocks.air);
		array.setBlock(x+4, y+2, z+9, Blocks.air);
		array.setBlock(x+4, y+3, z+5, Blocks.air);
		array.setBlock(x+4, y+3, z+6, Blocks.air);
		array.setBlock(x+4, y+3, z+7, Blocks.air);
		array.setBlock(x+4, y+3, z+8, Blocks.air);
		array.setBlock(x+4, y+3, z+9, Blocks.air);
		array.setBlock(x+4, y+4, z+5, Blocks.air);
		array.setBlock(x+4, y+4, z+6, Blocks.air);
		array.setBlock(x+4, y+4, z+7, Blocks.air);
		array.setBlock(x+4, y+4, z+8, Blocks.air);
		array.setBlock(x+4, y+4, z+9, Blocks.air);
		array.setBlock(x+4, y+6, z+3, Blocks.air);
		array.setBlock(x+4, y+6, z+5, Blocks.air);
		array.setBlock(x+4, y+6, z+6, Blocks.air);
		array.setBlock(x+4, y+6, z+8, Blocks.air);
		array.setBlock(x+4, y+6, z+9, Blocks.air);
		array.setBlock(x+4, y+6, z+11, Blocks.air);
		array.setBlock(x+4, y+7, z+2, Blocks.air);
		array.setBlock(x+4, y+7, z+3, Blocks.air);
		array.setBlock(x+4, y+7, z+5, Blocks.air);
		array.setBlock(x+4, y+7, z+6, Blocks.air);
		array.setBlock(x+4, y+7, z+8, Blocks.air);
		array.setBlock(x+4, y+7, z+9, Blocks.air);
		array.setBlock(x+4, y+7, z+11, Blocks.air);
		array.setBlock(x+4, y+7, z+12, Blocks.air);
		array.setBlock(x+4, y+8, z+2, Blocks.air);
		array.setBlock(x+4, y+8, z+3, Blocks.air);
		array.setBlock(x+4, y+8, z+5, Blocks.air);
		array.setBlock(x+4, y+8, z+6, Blocks.air);
		array.setBlock(x+4, y+8, z+8, Blocks.air);
		array.setBlock(x+4, y+8, z+9, Blocks.air);
		array.setBlock(x+4, y+8, z+11, Blocks.air);
		array.setBlock(x+4, y+8, z+12, Blocks.air);
		array.setBlock(x+5, y+2, z+4, Blocks.air);
		array.setBlock(x+5, y+2, z+6, Blocks.air);
		array.setBlock(x+5, y+2, z+7, Blocks.air);
		array.setBlock(x+5, y+2, z+8, Blocks.air);
		array.setBlock(x+5, y+2, z+10, Blocks.air);
		array.setBlock(x+5, y+3, z+4, Blocks.air);
		array.setBlock(x+5, y+3, z+6, Blocks.air);
		array.setBlock(x+5, y+3, z+7, Blocks.air);
		array.setBlock(x+5, y+3, z+8, Blocks.air);
		array.setBlock(x+5, y+3, z+10, Blocks.air);
		array.setBlock(x+5, y+4, z+4, Blocks.air);
		array.setBlock(x+5, y+4, z+6, Blocks.air);
		array.setBlock(x+5, y+4, z+7, Blocks.air);
		array.setBlock(x+5, y+4, z+8, Blocks.air);
		array.setBlock(x+5, y+4, z+10, Blocks.air);
		array.setBlock(x+5, y+6, z+2, Blocks.air);
		array.setBlock(x+5, y+6, z+3, Blocks.air);
		array.setBlock(x+5, y+6, z+4, Blocks.air);
		array.setBlock(x+5, y+6, z+5, Blocks.air);
		array.setBlock(x+5, y+6, z+6, Blocks.air);
		array.setBlock(x+5, y+6, z+7, Blocks.air);
		array.setBlock(x+5, y+6, z+8, Blocks.air);
		array.setBlock(x+5, y+6, z+9, Blocks.air);
		array.setBlock(x+5, y+6, z+10, Blocks.air);
		array.setBlock(x+5, y+6, z+11, Blocks.air);
		array.setBlock(x+5, y+6, z+12, Blocks.air);
		array.setBlock(x+5, y+7, z+2, Blocks.air);
		array.setBlock(x+5, y+7, z+3, Blocks.air);
		array.setBlock(x+5, y+7, z+4, Blocks.air);
		array.setBlock(x+5, y+7, z+5, Blocks.air);
		array.setBlock(x+5, y+7, z+6, Blocks.air);
		array.setBlock(x+5, y+7, z+7, Blocks.air);
		array.setBlock(x+5, y+7, z+8, Blocks.air);
		array.setBlock(x+5, y+7, z+9, Blocks.air);
		array.setBlock(x+5, y+7, z+10, Blocks.air);
		array.setBlock(x+5, y+7, z+11, Blocks.air);
		array.setBlock(x+5, y+7, z+12, Blocks.air);
		array.setBlock(x+5, y+8, z+2, Blocks.air);
		array.setBlock(x+5, y+8, z+3, Blocks.air);
		array.setBlock(x+5, y+8, z+4, Blocks.air);
		array.setBlock(x+5, y+8, z+5, Blocks.air);
		array.setBlock(x+5, y+8, z+6, Blocks.air);
		array.setBlock(x+5, y+8, z+7, Blocks.air);
		array.setBlock(x+5, y+8, z+8, Blocks.air);
		array.setBlock(x+5, y+8, z+9, Blocks.air);
		array.setBlock(x+5, y+8, z+10, Blocks.air);
		array.setBlock(x+5, y+8, z+11, Blocks.air);
		array.setBlock(x+5, y+8, z+12, Blocks.air);
		array.setBlock(x+5, y+9, z+5, Blocks.air);
		array.setBlock(x+5, y+9, z+7, Blocks.air);
		array.setBlock(x+5, y+9, z+9, Blocks.air);
		array.setBlock(x+5, y+10, z+5, Blocks.air);
		array.setBlock(x+5, y+10, z+9, Blocks.air);
		array.setBlock(x+5, y+11, z+5, Blocks.air);
		array.setBlock(x+5, y+11, z+9, Blocks.air);
		array.setBlock(x+6, y+2, z+2, Blocks.air);
		array.setBlock(x+6, y+2, z+3, Blocks.air);
		array.setBlock(x+6, y+2, z+4, Blocks.air);
		array.setBlock(x+6, y+2, z+5, Blocks.air);
		array.setBlock(x+6, y+2, z+9, Blocks.air);
		array.setBlock(x+6, y+2, z+10, Blocks.air);
		array.setBlock(x+6, y+2, z+11, Blocks.air);
		array.setBlock(x+6, y+2, z+12, Blocks.air);
		array.setBlock(x+6, y+3, z+2, Blocks.air);
		array.setBlock(x+6, y+3, z+3, Blocks.air);
		array.setBlock(x+6, y+3, z+4, Blocks.air);
		array.setBlock(x+6, y+3, z+5, Blocks.air);
		array.setBlock(x+6, y+3, z+7, Blocks.air);
		array.setBlock(x+6, y+3, z+9, Blocks.air);
		array.setBlock(x+6, y+3, z+10, Blocks.air);
		array.setBlock(x+6, y+3, z+11, Blocks.air);
		array.setBlock(x+6, y+3, z+12, Blocks.air);
		array.setBlock(x+6, y+4, z+2, Blocks.air);
		array.setBlock(x+6, y+4, z+3, Blocks.air);
		array.setBlock(x+6, y+4, z+4, Blocks.air);
		array.setBlock(x+6, y+4, z+5, Blocks.air);
		array.setBlock(x+6, y+4, z+7, Blocks.air);
		array.setBlock(x+6, y+4, z+9, Blocks.air);
		array.setBlock(x+6, y+4, z+10, Blocks.air);
		array.setBlock(x+6, y+4, z+11, Blocks.air);
		array.setBlock(x+6, y+4, z+12, Blocks.air);
		array.setBlock(x+6, y+6, z+2, Blocks.air);
		array.setBlock(x+6, y+6, z+3, Blocks.air);
		array.setBlock(x+6, y+6, z+4, Blocks.air);
		array.setBlock(x+6, y+6, z+5, Blocks.air);
		array.setBlock(x+6, y+6, z+6, Blocks.air);
		array.setBlock(x+6, y+6, z+7, Blocks.air);
		array.setBlock(x+6, y+6, z+8, Blocks.air);
		array.setBlock(x+6, y+6, z+9, Blocks.air);
		array.setBlock(x+6, y+6, z+10, Blocks.air);
		array.setBlock(x+6, y+6, z+11, Blocks.air);
		array.setBlock(x+6, y+6, z+12, Blocks.air);
		array.setBlock(x+6, y+7, z+2, Blocks.air);
		array.setBlock(x+6, y+7, z+3, Blocks.air);
		array.setBlock(x+6, y+7, z+4, Blocks.air);
		array.setBlock(x+6, y+7, z+5, Blocks.air);
		array.setBlock(x+6, y+7, z+6, Blocks.air);
		array.setBlock(x+6, y+7, z+7, Blocks.air);
		array.setBlock(x+6, y+7, z+8, Blocks.air);
		array.setBlock(x+6, y+7, z+9, Blocks.air);
		array.setBlock(x+6, y+7, z+10, Blocks.air);
		array.setBlock(x+6, y+7, z+11, Blocks.air);
		array.setBlock(x+6, y+7, z+12, Blocks.air);
		array.setBlock(x+6, y+8, z+2, Blocks.air);
		array.setBlock(x+6, y+8, z+3, Blocks.air);
		array.setBlock(x+6, y+8, z+4, Blocks.air);
		array.setBlock(x+6, y+8, z+5, Blocks.air);
		array.setBlock(x+6, y+8, z+6, Blocks.air);
		array.setBlock(x+6, y+8, z+7, Blocks.air);
		array.setBlock(x+6, y+8, z+8, Blocks.air);
		array.setBlock(x+6, y+8, z+9, Blocks.air);
		array.setBlock(x+6, y+8, z+10, Blocks.air);
		array.setBlock(x+6, y+8, z+11, Blocks.air);
		array.setBlock(x+6, y+8, z+12, Blocks.air);
		array.setBlock(x+6, y+9, z+6, Blocks.air);
		array.setBlock(x+6, y+9, z+7, Blocks.air);
		array.setBlock(x+6, y+9, z+8, Blocks.air);
		array.setBlock(x+7, y+2, z+2, Blocks.air);
		array.setBlock(x+7, y+2, z+3, Blocks.air);
		array.setBlock(x+7, y+2, z+4, Blocks.air);
		array.setBlock(x+7, y+2, z+5, Blocks.air);
		array.setBlock(x+7, y+2, z+9, Blocks.air);
		array.setBlock(x+7, y+2, z+10, Blocks.air);
		array.setBlock(x+7, y+2, z+11, Blocks.air);
		array.setBlock(x+7, y+2, z+12, Blocks.air);
		array.setBlock(x+7, y+3, z+2, Blocks.air);
		array.setBlock(x+7, y+3, z+3, Blocks.air);
		array.setBlock(x+7, y+3, z+4, Blocks.air);
		array.setBlock(x+7, y+3, z+5, Blocks.air);
		array.setBlock(x+7, y+3, z+6, Blocks.air);
		array.setBlock(x+7, y+3, z+8, Blocks.air);
		array.setBlock(x+7, y+3, z+9, Blocks.air);
		array.setBlock(x+7, y+3, z+10, Blocks.air);
		array.setBlock(x+7, y+3, z+11, Blocks.air);
		array.setBlock(x+7, y+3, z+12, Blocks.air);
		array.setBlock(x+7, y+4, z+2, Blocks.air);
		array.setBlock(x+7, y+4, z+3, Blocks.air);
		array.setBlock(x+7, y+4, z+4, Blocks.air);
		array.setBlock(x+7, y+4, z+5, Blocks.air);
		array.setBlock(x+7, y+4, z+6, Blocks.air);
		array.setBlock(x+7, y+4, z+8, Blocks.air);
		array.setBlock(x+7, y+4, z+9, Blocks.air);
		array.setBlock(x+7, y+4, z+10, Blocks.air);
		array.setBlock(x+7, y+4, z+11, Blocks.air);
		array.setBlock(x+7, y+4, z+12, Blocks.air);
		array.setBlock(x+7, y+6, z+5, Blocks.air);
		array.setBlock(x+7, y+6, z+6, Blocks.air);
		array.setBlock(x+7, y+6, z+7, Blocks.air);
		array.setBlock(x+7, y+6, z+8, Blocks.air);
		array.setBlock(x+7, y+6, z+9, Blocks.air);
		array.setBlock(x+7, y+7, z+5, Blocks.air);
		array.setBlock(x+7, y+7, z+6, Blocks.air);
		array.setBlock(x+7, y+7, z+7, Blocks.air);
		array.setBlock(x+7, y+7, z+8, Blocks.air);
		array.setBlock(x+7, y+7, z+9, Blocks.air);
		array.setBlock(x+7, y+8, z+5, Blocks.air);
		array.setBlock(x+7, y+8, z+6, Blocks.air);
		array.setBlock(x+7, y+8, z+7, Blocks.air);
		array.setBlock(x+7, y+8, z+8, Blocks.air);
		array.setBlock(x+7, y+8, z+9, Blocks.air);
		array.setBlock(x+7, y+9, z+5, Blocks.air);
		array.setBlock(x+7, y+9, z+6, Blocks.air);
		array.setBlock(x+7, y+9, z+7, Blocks.air);
		array.setBlock(x+7, y+9, z+8, Blocks.air);
		array.setBlock(x+7, y+9, z+9, Blocks.air);
		array.setBlock(x+8, y+2, z+2, Blocks.air);
		array.setBlock(x+8, y+2, z+3, Blocks.air);
		array.setBlock(x+8, y+2, z+4, Blocks.air);
		array.setBlock(x+8, y+2, z+5, Blocks.air);
		array.setBlock(x+8, y+2, z+9, Blocks.air);
		array.setBlock(x+8, y+2, z+10, Blocks.air);
		array.setBlock(x+8, y+2, z+11, Blocks.air);
		array.setBlock(x+8, y+2, z+12, Blocks.air);
		array.setBlock(x+8, y+3, z+2, Blocks.air);
		array.setBlock(x+8, y+3, z+3, Blocks.air);
		array.setBlock(x+8, y+3, z+4, Blocks.air);
		array.setBlock(x+8, y+3, z+5, Blocks.air);
		array.setBlock(x+8, y+3, z+7, Blocks.air);
		array.setBlock(x+8, y+3, z+9, Blocks.air);
		array.setBlock(x+8, y+3, z+10, Blocks.air);
		array.setBlock(x+8, y+3, z+11, Blocks.air);
		array.setBlock(x+8, y+3, z+12, Blocks.air);
		array.setBlock(x+8, y+4, z+2, Blocks.air);
		array.setBlock(x+8, y+4, z+3, Blocks.air);
		array.setBlock(x+8, y+4, z+4, Blocks.air);
		array.setBlock(x+8, y+4, z+5, Blocks.air);
		array.setBlock(x+8, y+4, z+7, Blocks.air);
		array.setBlock(x+8, y+4, z+9, Blocks.air);
		array.setBlock(x+8, y+4, z+10, Blocks.air);
		array.setBlock(x+8, y+4, z+11, Blocks.air);
		array.setBlock(x+8, y+4, z+12, Blocks.air);
		array.setBlock(x+8, y+6, z+2, Blocks.air);
		array.setBlock(x+8, y+6, z+3, Blocks.air);
		array.setBlock(x+8, y+6, z+4, Blocks.air);
		array.setBlock(x+8, y+6, z+5, Blocks.air);
		array.setBlock(x+8, y+6, z+6, Blocks.air);
		array.setBlock(x+8, y+6, z+7, Blocks.air);
		array.setBlock(x+8, y+6, z+8, Blocks.air);
		array.setBlock(x+8, y+6, z+9, Blocks.air);
		array.setBlock(x+8, y+6, z+10, Blocks.air);
		array.setBlock(x+8, y+6, z+11, Blocks.air);
		array.setBlock(x+8, y+6, z+12, Blocks.air);
		array.setBlock(x+8, y+7, z+2, Blocks.air);
		array.setBlock(x+8, y+7, z+3, Blocks.air);
		array.setBlock(x+8, y+7, z+4, Blocks.air);
		array.setBlock(x+8, y+7, z+5, Blocks.air);
		array.setBlock(x+8, y+7, z+6, Blocks.air);
		array.setBlock(x+8, y+7, z+7, Blocks.air);
		array.setBlock(x+8, y+7, z+8, Blocks.air);
		array.setBlock(x+8, y+7, z+9, Blocks.air);
		array.setBlock(x+8, y+7, z+10, Blocks.air);
		array.setBlock(x+8, y+7, z+11, Blocks.air);
		array.setBlock(x+8, y+7, z+12, Blocks.air);
		array.setBlock(x+8, y+8, z+2, Blocks.air);
		array.setBlock(x+8, y+8, z+3, Blocks.air);
		array.setBlock(x+8, y+8, z+4, Blocks.air);
		array.setBlock(x+8, y+8, z+5, Blocks.air);
		array.setBlock(x+8, y+8, z+6, Blocks.air);
		array.setBlock(x+8, y+8, z+7, Blocks.air);
		array.setBlock(x+8, y+8, z+8, Blocks.air);
		array.setBlock(x+8, y+8, z+9, Blocks.air);
		array.setBlock(x+8, y+8, z+10, Blocks.air);
		array.setBlock(x+8, y+8, z+11, Blocks.air);
		array.setBlock(x+8, y+8, z+12, Blocks.air);
		array.setBlock(x+8, y+9, z+6, Blocks.air);
		array.setBlock(x+8, y+9, z+7, Blocks.air);
		array.setBlock(x+8, y+9, z+8, Blocks.air);
		array.setBlock(x+9, y+2, z+4, Blocks.air);
		array.setBlock(x+9, y+2, z+6, Blocks.air);
		array.setBlock(x+9, y+2, z+7, Blocks.air);
		array.setBlock(x+9, y+2, z+8, Blocks.air);
		array.setBlock(x+9, y+2, z+10, Blocks.air);
		array.setBlock(x+9, y+3, z+4, Blocks.air);
		array.setBlock(x+9, y+3, z+6, Blocks.air);
		array.setBlock(x+9, y+3, z+7, Blocks.air);
		array.setBlock(x+9, y+3, z+8, Blocks.air);
		array.setBlock(x+9, y+3, z+10, Blocks.air);
		array.setBlock(x+9, y+4, z+4, Blocks.air);
		array.setBlock(x+9, y+4, z+6, Blocks.air);
		array.setBlock(x+9, y+4, z+7, Blocks.air);
		array.setBlock(x+9, y+4, z+8, Blocks.air);
		array.setBlock(x+9, y+4, z+10, Blocks.air);
		array.setBlock(x+9, y+6, z+2, Blocks.air);
		array.setBlock(x+9, y+6, z+3, Blocks.air);
		array.setBlock(x+9, y+6, z+4, Blocks.air);
		array.setBlock(x+9, y+6, z+5, Blocks.air);
		array.setBlock(x+9, y+6, z+6, Blocks.air);
		array.setBlock(x+9, y+6, z+7, Blocks.air);
		array.setBlock(x+9, y+6, z+8, Blocks.air);
		array.setBlock(x+9, y+6, z+9, Blocks.air);
		array.setBlock(x+9, y+6, z+10, Blocks.air);
		array.setBlock(x+9, y+6, z+11, Blocks.air);
		array.setBlock(x+9, y+6, z+12, Blocks.air);
		array.setBlock(x+9, y+7, z+2, Blocks.air);
		array.setBlock(x+9, y+7, z+3, Blocks.air);
		array.setBlock(x+9, y+7, z+4, Blocks.air);
		array.setBlock(x+9, y+7, z+5, Blocks.air);
		array.setBlock(x+9, y+7, z+6, Blocks.air);
		array.setBlock(x+9, y+7, z+7, Blocks.air);
		array.setBlock(x+9, y+7, z+8, Blocks.air);
		array.setBlock(x+9, y+7, z+9, Blocks.air);
		array.setBlock(x+9, y+7, z+10, Blocks.air);
		array.setBlock(x+9, y+7, z+11, Blocks.air);
		array.setBlock(x+9, y+7, z+12, Blocks.air);
		array.setBlock(x+9, y+8, z+2, Blocks.air);
		array.setBlock(x+9, y+8, z+3, Blocks.air);
		array.setBlock(x+9, y+8, z+4, Blocks.air);
		array.setBlock(x+9, y+8, z+5, Blocks.air);
		array.setBlock(x+9, y+8, z+6, Blocks.air);
		array.setBlock(x+9, y+8, z+7, Blocks.air);
		array.setBlock(x+9, y+8, z+8, Blocks.air);
		array.setBlock(x+9, y+8, z+9, Blocks.air);
		array.setBlock(x+9, y+8, z+10, Blocks.air);
		array.setBlock(x+9, y+8, z+11, Blocks.air);
		array.setBlock(x+9, y+8, z+12, Blocks.air);
		array.setBlock(x+9, y+9, z+5, Blocks.air);
		array.setBlock(x+9, y+9, z+7, Blocks.air);
		array.setBlock(x+9, y+9, z+9, Blocks.air);
		array.setBlock(x+9, y+10, z+5, Blocks.air);
		array.setBlock(x+9, y+10, z+9, Blocks.air);
		array.setBlock(x+9, y+11, z+5, Blocks.air);
		array.setBlock(x+9, y+11, z+9, Blocks.air);
		array.setBlock(x+10, y+2, z+5, Blocks.air);
		array.setBlock(x+10, y+2, z+6, Blocks.air);
		array.setBlock(x+10, y+2, z+7, Blocks.air);
		array.setBlock(x+10, y+2, z+8, Blocks.air);
		array.setBlock(x+10, y+2, z+9, Blocks.air);
		array.setBlock(x+10, y+3, z+5, Blocks.air);
		array.setBlock(x+10, y+3, z+6, Blocks.air);
		array.setBlock(x+10, y+3, z+7, Blocks.air);
		array.setBlock(x+10, y+3, z+8, Blocks.air);
		array.setBlock(x+10, y+3, z+9, Blocks.air);
		array.setBlock(x+10, y+4, z+5, Blocks.air);
		array.setBlock(x+10, y+4, z+6, Blocks.air);
		array.setBlock(x+10, y+4, z+7, Blocks.air);
		array.setBlock(x+10, y+4, z+8, Blocks.air);
		array.setBlock(x+10, y+4, z+9, Blocks.air);
		array.setBlock(x+10, y+6, z+3, Blocks.air);
		array.setBlock(x+10, y+6, z+5, Blocks.air);
		array.setBlock(x+10, y+6, z+6, Blocks.air);
		array.setBlock(x+10, y+6, z+8, Blocks.air);
		array.setBlock(x+10, y+6, z+9, Blocks.air);
		array.setBlock(x+10, y+6, z+11, Blocks.air);
		array.setBlock(x+10, y+7, z+2, Blocks.air);
		array.setBlock(x+10, y+7, z+3, Blocks.air);
		array.setBlock(x+10, y+7, z+5, Blocks.air);
		array.setBlock(x+10, y+7, z+6, Blocks.air);
		array.setBlock(x+10, y+7, z+8, Blocks.air);
		array.setBlock(x+10, y+7, z+9, Blocks.air);
		array.setBlock(x+10, y+7, z+11, Blocks.air);
		array.setBlock(x+10, y+7, z+12, Blocks.air);
		array.setBlock(x+10, y+8, z+2, Blocks.air);
		array.setBlock(x+10, y+8, z+3, Blocks.air);
		array.setBlock(x+10, y+8, z+5, Blocks.air);
		array.setBlock(x+10, y+8, z+6, Blocks.air);
		array.setBlock(x+10, y+8, z+8, Blocks.air);
		array.setBlock(x+10, y+8, z+9, Blocks.air);
		array.setBlock(x+10, y+8, z+11, Blocks.air);
		array.setBlock(x+10, y+8, z+12, Blocks.air);
		array.setBlock(x+11, y+2, z+6, Blocks.air);
		array.setBlock(x+11, y+2, z+7, Blocks.air);
		array.setBlock(x+11, y+2, z+8, Blocks.air);
		array.setBlock(x+11, y+3, z+6, Blocks.air);
		array.setBlock(x+11, y+3, z+7, Blocks.air);
		array.setBlock(x+11, y+3, z+8, Blocks.air);
		array.setBlock(x+11, y+4, z+6, Blocks.air);
		array.setBlock(x+11, y+4, z+7, Blocks.air);
		array.setBlock(x+11, y+4, z+8, Blocks.air);
		array.setBlock(x+11, y+6, z+2, Blocks.air);
		array.setBlock(x+11, y+6, z+3, Blocks.air);
		array.setBlock(x+11, y+6, z+4, Blocks.air);
		array.setBlock(x+11, y+6, z+5, Blocks.air);
		array.setBlock(x+11, y+6, z+6, Blocks.air);
		array.setBlock(x+11, y+6, z+8, Blocks.air);
		array.setBlock(x+11, y+6, z+9, Blocks.air);
		array.setBlock(x+11, y+6, z+10, Blocks.air);
		array.setBlock(x+11, y+6, z+11, Blocks.air);
		array.setBlock(x+11, y+6, z+12, Blocks.air);
		array.setBlock(x+11, y+7, z+2, Blocks.air);
		array.setBlock(x+11, y+7, z+3, Blocks.air);
		array.setBlock(x+11, y+7, z+4, Blocks.air);
		array.setBlock(x+11, y+7, z+5, Blocks.air);
		array.setBlock(x+11, y+7, z+6, Blocks.air);
		array.setBlock(x+11, y+7, z+8, Blocks.air);
		array.setBlock(x+11, y+7, z+9, Blocks.air);
		array.setBlock(x+11, y+7, z+10, Blocks.air);
		array.setBlock(x+11, y+7, z+11, Blocks.air);
		array.setBlock(x+11, y+7, z+12, Blocks.air);
		array.setBlock(x+11, y+8, z+2, Blocks.air);
		array.setBlock(x+11, y+8, z+3, Blocks.air);
		array.setBlock(x+11, y+8, z+4, Blocks.air);
		array.setBlock(x+11, y+8, z+5, Blocks.air);
		array.setBlock(x+11, y+8, z+6, Blocks.air);
		array.setBlock(x+11, y+8, z+8, Blocks.air);
		array.setBlock(x+11, y+8, z+9, Blocks.air);
		array.setBlock(x+11, y+8, z+10, Blocks.air);
		array.setBlock(x+11, y+8, z+11, Blocks.air);
		array.setBlock(x+11, y+8, z+12, Blocks.air);
		array.setBlock(x+12, y+2, z+6, Blocks.air);
		array.setBlock(x+12, y+2, z+7, Blocks.air);
		array.setBlock(x+12, y+2, z+8, Blocks.air);
		array.setBlock(x+12, y+3, z+6, Blocks.air);
		array.setBlock(x+12, y+3, z+7, Blocks.air);
		array.setBlock(x+12, y+3, z+8, Blocks.air);
		array.setBlock(x+12, y+4, z+6, Blocks.air);
		array.setBlock(x+12, y+4, z+7, Blocks.air);
		array.setBlock(x+12, y+4, z+8, Blocks.air);
		array.setBlock(x+12, y+6, z+2, Blocks.air);
		array.setBlock(x+12, y+6, z+3, Blocks.air);
		array.setBlock(x+12, y+6, z+5, Blocks.air);
		array.setBlock(x+12, y+6, z+6, Blocks.air);
		array.setBlock(x+12, y+6, z+8, Blocks.air);
		array.setBlock(x+12, y+6, z+9, Blocks.air);
		array.setBlock(x+12, y+6, z+11, Blocks.air);
		array.setBlock(x+12, y+6, z+12, Blocks.air);
		array.setBlock(x+12, y+7, z+2, Blocks.air);
		array.setBlock(x+12, y+7, z+3, Blocks.air);
		array.setBlock(x+12, y+7, z+4, Blocks.air);
		array.setBlock(x+12, y+7, z+5, Blocks.air);
		array.setBlock(x+12, y+7, z+6, Blocks.air);
		array.setBlock(x+12, y+7, z+8, Blocks.air);
		array.setBlock(x+12, y+7, z+9, Blocks.air);
		array.setBlock(x+12, y+7, z+10, Blocks.air);
		array.setBlock(x+12, y+7, z+11, Blocks.air);
		array.setBlock(x+12, y+7, z+12, Blocks.air);
		array.setBlock(x+12, y+8, z+2, Blocks.air);
		array.setBlock(x+12, y+8, z+3, Blocks.air);
		array.setBlock(x+12, y+8, z+4, Blocks.air);
		array.setBlock(x+12, y+8, z+5, Blocks.air);
		array.setBlock(x+12, y+8, z+6, Blocks.air);
		array.setBlock(x+12, y+8, z+8, Blocks.air);
		array.setBlock(x+12, y+8, z+9, Blocks.air);
		array.setBlock(x+12, y+8, z+10, Blocks.air);
		array.setBlock(x+12, y+8, z+11, Blocks.air);
		array.setBlock(x+12, y+8, z+12, Blocks.air);

		return array;
	}

	public static void getTerrain(FilledBlockArray array, int x, int y, int z) {
		array.setBlock(x+3, y+5, z+0, Blocks.sandstone);
		array.setBlock(x+3, y+5, z+1, Blocks.sandstone);
		array.setBlock(x+3, y+5, z+13, Blocks.sandstone);
		array.setBlock(x+3, y+5, z+14, Blocks.sandstone);
		array.setBlock(x+3, y+5, z+15, Blocks.sandstone);
		array.setBlock(x+3, y+6, z+0, Blocks.sand);
		array.setBlock(x+2, y+7, z+14, Blocks.sand);
		array.setBlock(x+2, y+7, z+15, Blocks.sand);
		array.setBlock(x+2, y+8, z+0, Blocks.sand);
		array.setBlock(x+2, y+8, z+14, Blocks.sand);
		array.setBlock(x+2, y+8, z+15, Blocks.sand);
		array.setBlock(x+2, y+9, z+0, Blocks.sand);
		array.setBlock(x+2, y+9, z+1, Blocks.sand);
		array.setBlock(x+2, y+9, z+13, Blocks.sand);
		array.setBlock(x+2, y+9, z+14, Blocks.sand);
		array.setBlock(x+2, y+9, z+15, Blocks.sand);
		array.setBlock(x+2, y+10, z+2, Blocks.sand);
		array.setBlock(x+2, y+10, z+3, Blocks.sand);
		array.setBlock(x+2, y+10, z+4, Blocks.sand);
		array.setBlock(x+2, y+10, z+5, Blocks.sand);
		array.setBlock(x+2, y+10, z+6, Blocks.sand);
		array.setBlock(x+2, y+10, z+7, Blocks.sand);
		array.setBlock(x+2, y+10, z+8, Blocks.sand);
		array.setBlock(x+2, y+10, z+9, Blocks.sand);
		array.setBlock(x+2, y+10, z+10, Blocks.sand);
		array.setBlock(x+2, y+10, z+11, Blocks.sand);
		array.setBlock(x+2, y+10, z+12, Blocks.sand);
		array.setBlock(x+3, y+6, z+14, Blocks.sand);
		array.setBlock(x+3, y+6, z+15, Blocks.sand);
		array.setBlock(x+3, y+7, z+0, Blocks.sand);
		array.setBlock(x+3, y+7, z+14, Blocks.sand);
		array.setBlock(x+3, y+7, z+15, Blocks.sand);
		array.setBlock(x+3, y+8, z+0, Blocks.sand);
		array.setBlock(x+3, y+8, z+14, Blocks.sand);
		array.setBlock(x+3, y+8, z+15, Blocks.sand);
		array.setBlock(x+3, y+9, z+0, Blocks.sand);
		array.setBlock(x+3, y+9, z+1, Blocks.sand);
		array.setBlock(x+13, y+8, z+14, Blocks.sand);
		array.setBlock(x+13, y+8, z+15, Blocks.sand);
		array.setBlock(x+13, y+9, z+0, Blocks.sand);
		array.setBlock(x+13, y+9, z+1, Blocks.sand);
		array.setBlock(x+13, y+9, z+2, Blocks.sand);
		array.setBlock(x+13, y+9, z+3, Blocks.sand);
		array.setBlock(x+13, y+9, z+4, Blocks.sand);
		array.setBlock(x+13, y+9, z+5, Blocks.sand);
		array.setBlock(x+13, y+9, z+6, Blocks.sand);
		array.setBlock(x+13, y+9, z+7, Blocks.sand);
		array.setBlock(x+13, y+9, z+8, Blocks.sand);
		array.setBlock(x+13, y+9, z+9, Blocks.sand);
		array.setBlock(x+13, y+9, z+10, Blocks.sand);
		array.setBlock(x+13, y+9, z+11, Blocks.sand);
		array.setBlock(x+13, y+9, z+12, Blocks.sand);
		array.setBlock(x+13, y+9, z+13, Blocks.sand);
		array.setBlock(x+13, y+9, z+14, Blocks.sand);
		array.setBlock(x+13, y+9, z+15, Blocks.sand);
		array.setBlock(x+13, y+10, z+4, Blocks.sand);
		array.setBlock(x+13, y+10, z+5, Blocks.sand);
		array.setBlock(x+13, y+10, z+6, Blocks.sand);
		array.setBlock(x+13, y+10, z+7, Blocks.sand);
		array.setBlock(x+13, y+10, z+8, Blocks.sand);
		array.setBlock(x+13, y+10, z+9, Blocks.sand);
		array.setBlock(x+13, y+10, z+10, Blocks.sand);
		array.setBlock(x+14, y+5, z+0, Blocks.sandstone);
		array.setBlock(x+14, y+5, z+1, Blocks.sandstone);
		array.setBlock(x+14, y+5, z+2, Blocks.sandstone);
		array.setBlock(x+14, y+5, z+3, Blocks.sandstone);
		array.setBlock(x+14, y+5, z+4, Blocks.sandstone);
		array.setBlock(x+14, y+5, z+5, Blocks.sandstone);
		array.setBlock(x+14, y+5, z+6, Blocks.sandstone);
		array.setBlock(x+14, y+5, z+7, Blocks.sandstone);
		array.setBlock(x+14, y+5, z+8, Blocks.sandstone);
		array.setBlock(x+14, y+5, z+9, Blocks.sandstone);
		array.setBlock(x+14, y+5, z+10, Blocks.sandstone);
		array.setBlock(x+14, y+5, z+11, Blocks.sandstone);
		array.setBlock(x+14, y+5, z+12, Blocks.sandstone);
		array.setBlock(x+14, y+5, z+13, Blocks.sandstone);
		array.setBlock(x+14, y+5, z+14, Blocks.sandstone);
		array.setBlock(x+14, y+5, z+15, Blocks.sandstone);
		array.setBlock(x+14, y+6, z+0, Blocks.sand);
		array.setBlock(x+14, y+6, z+1, Blocks.sand);
		array.setBlock(x+14, y+6, z+2, Blocks.sand);
		array.setBlock(x+14, y+6, z+3, Blocks.sand);
		array.setBlock(x+14, y+6, z+4, Blocks.sand);
		array.setBlock(x+14, y+6, z+5, Blocks.sand);
		array.setBlock(x+14, y+6, z+6, Blocks.sand);
		array.setBlock(x+14, y+6, z+7, Blocks.sand);
		array.setBlock(x+14, y+6, z+8, Blocks.sand);
		array.setBlock(x+14, y+6, z+9, Blocks.sand);
		array.setBlock(x+14, y+6, z+10, Blocks.sand);
		array.setBlock(x+14, y+6, z+11, Blocks.sand);
		array.setBlock(x+14, y+6, z+12, Blocks.sand);
		array.setBlock(x+14, y+6, z+13, Blocks.sand);
		array.setBlock(x+14, y+6, z+14, Blocks.sand);
		array.setBlock(x+14, y+6, z+15, Blocks.sand);
		array.setBlock(x+14, y+7, z+0, Blocks.sand);
		array.setBlock(x+14, y+7, z+1, Blocks.sand);
		array.setBlock(x+14, y+7, z+2, Blocks.sand);
		array.setBlock(x+14, y+7, z+3, Blocks.sand);
		array.setBlock(x+14, y+7, z+4, Blocks.sand);
		array.setBlock(x+14, y+7, z+5, Blocks.sand);
		array.setBlock(x+14, y+7, z+6, Blocks.sand);
		array.setBlock(x+14, y+7, z+7, Blocks.sand);
		array.setBlock(x+14, y+7, z+8, Blocks.sand);
		array.setBlock(x+14, y+7, z+9, Blocks.sand);
		array.setBlock(x+14, y+7, z+10, Blocks.sand);
		array.setBlock(x+14, y+7, z+11, Blocks.sand);
		array.setBlock(x+14, y+7, z+12, Blocks.sand);
		array.setBlock(x+14, y+7, z+13, Blocks.sand);
		array.setBlock(x+14, y+7, z+14, Blocks.sand);
		array.setBlock(x+14, y+7, z+15, Blocks.sand);
		array.setBlock(x+14, y+8, z+0, Blocks.sand);
		array.setBlock(x+14, y+8, z+1, Blocks.sand);
		array.setBlock(x+14, y+8, z+2, Blocks.sand);
		array.setBlock(x+14, y+8, z+3, Blocks.sand);
		array.setBlock(x+14, y+8, z+4, Blocks.sand);
		array.setBlock(x+14, y+8, z+5, Blocks.sand);
		array.setBlock(x+14, y+8, z+6, Blocks.sand);
		array.setBlock(x+14, y+8, z+7, Blocks.sand);
		array.setBlock(x+14, y+8, z+8, Blocks.sand);
		array.setBlock(x+14, y+8, z+9, Blocks.sand);
		array.setBlock(x+14, y+8, z+10, Blocks.sand);
		array.setBlock(x+14, y+8, z+11, Blocks.sand);
		array.setBlock(x+14, y+8, z+12, Blocks.sand);
		array.setBlock(x+14, y+8, z+13, Blocks.sand);
		array.setBlock(x+14, y+8, z+14, Blocks.sand);
		array.setBlock(x+14, y+8, z+15, Blocks.sand);
		array.setBlock(x+14, y+9, z+0, Blocks.sand);
		array.setBlock(x+14, y+9, z+1, Blocks.sand);
		array.setBlock(x+14, y+9, z+2, Blocks.sand);
		array.setBlock(x+14, y+9, z+3, Blocks.sand);
		array.setBlock(x+14, y+9, z+4, Blocks.sand);
		array.setBlock(x+14, y+9, z+5, Blocks.sand);
		array.setBlock(x+14, y+9, z+6, Blocks.sand);
		array.setBlock(x+14, y+9, z+7, Blocks.sand);
		array.setBlock(x+14, y+9, z+8, Blocks.sand);
		array.setBlock(x+14, y+9, z+9, Blocks.sand);
		array.setBlock(x+14, y+9, z+10, Blocks.sand);
		array.setBlock(x+14, y+9, z+11, Blocks.sand);
		array.setBlock(x+14, y+9, z+12, Blocks.sand);
		array.setBlock(x+14, y+9, z+13, Blocks.sand);
		array.setBlock(x+14, y+9, z+14, Blocks.sand);
		array.setBlock(x+14, y+9, z+15, Blocks.sand);
		array.setBlock(x+0, y+5, z+0, Blocks.sandstone);
		array.setBlock(x+0, y+5, z+1, Blocks.sandstone);
		array.setBlock(x+0, y+5, z+2, Blocks.sandstone);
		array.setBlock(x+0, y+5, z+3, Blocks.sandstone);
		array.setBlock(x+0, y+5, z+4, Blocks.sandstone);
		array.setBlock(x+0, y+5, z+5, Blocks.sandstone);
		array.setBlock(x+0, y+5, z+6, Blocks.sandstone);
		array.setBlock(x+0, y+5, z+7, Blocks.sandstone);
		array.setBlock(x+0, y+5, z+8, Blocks.sandstone);
		array.setBlock(x+0, y+5, z+9, Blocks.sandstone);
		array.setBlock(x+0, y+5, z+10, Blocks.sandstone);
		array.setBlock(x+0, y+5, z+11, Blocks.sandstone);
		array.setBlock(x+0, y+5, z+12, Blocks.sandstone);
		array.setBlock(x+0, y+5, z+13, Blocks.sandstone);
		array.setBlock(x+0, y+5, z+14, Blocks.sandstone);
		array.setBlock(x+0, y+5, z+15, Blocks.sandstone);
		array.setBlock(x+0, y+6, z+0, Blocks.sand);
		array.setBlock(x+0, y+6, z+1, Blocks.sand);
		array.setBlock(x+0, y+6, z+2, Blocks.sand);
		array.setBlock(x+0, y+6, z+3, Blocks.sand);
		array.setBlock(x+0, y+6, z+4, Blocks.sand);
		array.setBlock(x+0, y+6, z+5, Blocks.sand);
		array.setBlock(x+0, y+6, z+6, Blocks.sand);
		array.setBlock(x+0, y+6, z+7, Blocks.sand);
		array.setBlock(x+0, y+6, z+8, Blocks.sand);
		array.setBlock(x+0, y+6, z+9, Blocks.sand);
		array.setBlock(x+0, y+6, z+10, Blocks.sand);
		array.setBlock(x+0, y+6, z+11, Blocks.sand);
		array.setBlock(x+0, y+6, z+12, Blocks.sand);
		array.setBlock(x+0, y+6, z+13, Blocks.sand);
		array.setBlock(x+0, y+6, z+14, Blocks.sand);
		array.setBlock(x+0, y+6, z+15, Blocks.sand);
		array.setBlock(x+0, y+7, z+0, Blocks.sand);
		array.setBlock(x+0, y+7, z+1, Blocks.sand);
		array.setBlock(x+0, y+7, z+2, Blocks.sand);
		array.setBlock(x+0, y+7, z+3, Blocks.sand);
		array.setBlock(x+0, y+7, z+4, Blocks.sand);
		array.setBlock(x+0, y+7, z+5, Blocks.sand);
		array.setBlock(x+0, y+7, z+6, Blocks.sand);
		array.setBlock(x+0, y+7, z+7, Blocks.sand);
		array.setBlock(x+0, y+7, z+8, Blocks.sand);
		array.setBlock(x+0, y+7, z+9, Blocks.sand);
		array.setBlock(x+0, y+7, z+10, Blocks.sand);
		array.setBlock(x+0, y+7, z+11, Blocks.sand);
		array.setBlock(x+0, y+7, z+12, Blocks.sand);
		array.setBlock(x+0, y+7, z+13, Blocks.sand);
		array.setBlock(x+0, y+7, z+14, Blocks.sand);
		array.setBlock(x+0, y+7, z+15, Blocks.sand);
		array.setBlock(x+0, y+8, z+0, Blocks.sand);
		array.setBlock(x+0, y+8, z+1, Blocks.sand);
		array.setBlock(x+0, y+8, z+2, Blocks.sand);
		array.setBlock(x+0, y+8, z+3, Blocks.sand);
		array.setBlock(x+0, y+8, z+4, Blocks.sand);
		array.setBlock(x+0, y+8, z+5, Blocks.sand);
		array.setBlock(x+0, y+8, z+6, Blocks.sand);
		array.setBlock(x+0, y+8, z+7, Blocks.sand);
		array.setBlock(x+0, y+8, z+8, Blocks.sand);
		array.setBlock(x+0, y+8, z+9, Blocks.sand);
		array.setBlock(x+0, y+8, z+10, Blocks.sand);
		array.setBlock(x+0, y+8, z+11, Blocks.sand);
		array.setBlock(x+0, y+8, z+12, Blocks.sand);
		array.setBlock(x+0, y+8, z+13, Blocks.sand);
		array.setBlock(x+0, y+8, z+14, Blocks.sand);
		array.setBlock(x+0, y+8, z+15, Blocks.sand);
		array.setBlock(x+0, y+9, z+0, Blocks.sand);
		array.setBlock(x+0, y+9, z+1, Blocks.sand);
		array.setBlock(x+0, y+9, z+2, Blocks.sand);
		array.setBlock(x+0, y+9, z+3, Blocks.sand);
		array.setBlock(x+0, y+9, z+4, Blocks.sand);
		array.setBlock(x+0, y+9, z+5, Blocks.sand);
		array.setBlock(x+0, y+9, z+6, Blocks.sand);
		array.setBlock(x+0, y+9, z+7, Blocks.sand);
		array.setBlock(x+0, y+9, z+8, Blocks.sand);
		array.setBlock(x+0, y+9, z+9, Blocks.sand);
		array.setBlock(x+0, y+9, z+10, Blocks.sand);
		array.setBlock(x+0, y+9, z+11, Blocks.sand);
		array.setBlock(x+0, y+9, z+12, Blocks.sand);
		array.setBlock(x+0, y+9, z+13, Blocks.sand);
		array.setBlock(x+0, y+9, z+14, Blocks.sand);
		array.setBlock(x+0, y+9, z+15, Blocks.sand);
		array.setBlock(x+1, y+5, z+0, Blocks.sandstone);
		array.setBlock(x+1, y+5, z+1, Blocks.sandstone);
		array.setBlock(x+1, y+5, z+2, Blocks.sandstone);
		array.setBlock(x+1, y+5, z+3, Blocks.sandstone);
		array.setBlock(x+1, y+5, z+4, Blocks.sandstone);
		array.setBlock(x+1, y+5, z+5, Blocks.sandstone);
		array.setBlock(x+1, y+5, z+6, Blocks.sandstone);
		array.setBlock(x+1, y+5, z+7, Blocks.sandstone);
		array.setBlock(x+1, y+5, z+8, Blocks.sandstone);
		array.setBlock(x+1, y+5, z+9, Blocks.sandstone);
		array.setBlock(x+1, y+5, z+10, Blocks.sandstone);
		array.setBlock(x+1, y+5, z+11, Blocks.sandstone);
		array.setBlock(x+1, y+5, z+12, Blocks.sandstone);
		array.setBlock(x+1, y+5, z+13, Blocks.sandstone);
		array.setBlock(x+1, y+5, z+14, Blocks.sandstone);
		array.setBlock(x+1, y+5, z+15, Blocks.sandstone);
		array.setBlock(x+1, y+6, z+0, Blocks.sand);
		array.setBlock(x+1, y+6, z+14, Blocks.sand);
		array.setBlock(x+1, y+6, z+15, Blocks.sand);
		array.setBlock(x+1, y+7, z+0, Blocks.sand);
		array.setBlock(x+1, y+7, z+14, Blocks.sand);
		array.setBlock(x+1, y+7, z+15, Blocks.sand);
		array.setBlock(x+1, y+8, z+0, Blocks.sand);
		array.setBlock(x+1, y+8, z+14, Blocks.sand);
		array.setBlock(x+1, y+8, z+15, Blocks.sand);
		array.setBlock(x+1, y+9, z+0, Blocks.sand);
		array.setBlock(x+1, y+9, z+1, Blocks.sand);
		array.setBlock(x+1, y+9, z+2, Blocks.sand);
		array.setBlock(x+1, y+9, z+3, Blocks.sand);
		array.setBlock(x+1, y+9, z+4, Blocks.sand);
		array.setBlock(x+1, y+9, z+5, Blocks.sand);
		array.setBlock(x+1, y+9, z+6, Blocks.sand);
		array.setBlock(x+1, y+9, z+7, Blocks.sand);
		array.setBlock(x+1, y+9, z+8, Blocks.sand);
		array.setBlock(x+1, y+9, z+9, Blocks.sand);
		array.setBlock(x+1, y+9, z+10, Blocks.sand);
		array.setBlock(x+1, y+9, z+11, Blocks.sand);
		array.setBlock(x+1, y+9, z+12, Blocks.sand);
		array.setBlock(x+1, y+9, z+13, Blocks.sand);
		array.setBlock(x+1, y+9, z+14, Blocks.sand);
		array.setBlock(x+1, y+9, z+15, Blocks.sand);
		array.setBlock(x+1, y+10, z+4, Blocks.sand);
		array.setBlock(x+1, y+10, z+5, Blocks.sand);
		array.setBlock(x+1, y+10, z+6, Blocks.sand);
		array.setBlock(x+1, y+10, z+7, Blocks.sand);
		array.setBlock(x+1, y+10, z+8, Blocks.sand);
		array.setBlock(x+1, y+10, z+9, Blocks.sand);
		array.setBlock(x+1, y+10, z+10, Blocks.sand);
		array.setBlock(x+2, y+5, z+0, Blocks.sandstone);
		array.setBlock(x+2, y+5, z+1, Blocks.sandstone);
		array.setBlock(x+2, y+5, z+13, Blocks.sandstone);
		array.setBlock(x+2, y+5, z+14, Blocks.sandstone);
		array.setBlock(x+2, y+5, z+15, Blocks.sandstone);
		array.setBlock(x+2, y+6, z+0, Blocks.sand);
		array.setBlock(x+2, y+6, z+14, Blocks.sand);
		array.setBlock(x+2, y+6, z+15, Blocks.sand);
		array.setBlock(x+2, y+7, z+0, Blocks.sand);
		array.setBlock(x+3, y+9, z+13, Blocks.sand);
		array.setBlock(x+3, y+9, z+14, Blocks.sand);
		array.setBlock(x+3, y+9, z+15, Blocks.sand);
		array.setBlock(x+3, y+10, z+2, Blocks.sand);
		array.setBlock(x+3, y+10, z+3, Blocks.sand);
		array.setBlock(x+3, y+10, z+4, Blocks.sand);
		array.setBlock(x+3, y+10, z+5, Blocks.sand);
		array.setBlock(x+3, y+10, z+6, Blocks.sand);
		array.setBlock(x+3, y+10, z+7, Blocks.sand);
		array.setBlock(x+3, y+10, z+8, Blocks.sand);
		array.setBlock(x+3, y+10, z+9, Blocks.sand);
		array.setBlock(x+3, y+10, z+10, Blocks.sand);
		array.setBlock(x+3, y+10, z+11, Blocks.sand);
		array.setBlock(x+3, y+10, z+12, Blocks.sand);
		array.setBlock(x+3, y+11, z+4, Blocks.sand);
		array.setBlock(x+3, y+11, z+5, Blocks.sand);
		array.setBlock(x+3, y+11, z+6, Blocks.sand);
		array.setBlock(x+3, y+11, z+8, Blocks.sand);
		array.setBlock(x+3, y+11, z+9, Blocks.sand);
		array.setBlock(x+3, y+11, z+10, Blocks.sand);
		array.setBlock(x+4, y+5, z+0, Blocks.sandstone);
		array.setBlock(x+4, y+5, z+1, Blocks.sandstone);
		array.setBlock(x+4, y+5, z+13, Blocks.sandstone);
		array.setBlock(x+4, y+5, z+14, Blocks.sandstone);
		array.setBlock(x+4, y+5, z+15, Blocks.sandstone);
		array.setBlock(x+4, y+6, z+0, Blocks.sand);
		array.setBlock(x+4, y+6, z+14, Blocks.sand);
		array.setBlock(x+4, y+6, z+15, Blocks.sand);
		array.setBlock(x+4, y+7, z+0, Blocks.sand);
		array.setBlock(x+4, y+7, z+14, Blocks.sand);
		array.setBlock(x+4, y+7, z+15, Blocks.sand);
		array.setBlock(x+4, y+8, z+0, Blocks.sand);
		array.setBlock(x+4, y+8, z+14, Blocks.sand);
		array.setBlock(x+4, y+8, z+15, Blocks.sand);
		array.setBlock(x+4, y+9, z+0, Blocks.sand);
		array.setBlock(x+4, y+9, z+1, Blocks.sand);
		array.setBlock(x+4, y+9, z+13, Blocks.sand);
		array.setBlock(x+4, y+9, z+14, Blocks.sand);
		array.setBlock(x+4, y+9, z+15, Blocks.sand);
		array.setBlock(x+4, y+10, z+1, Blocks.sand);
		array.setBlock(x+4, y+10, z+2, Blocks.sand);
		array.setBlock(x+4, y+10, z+3, Blocks.sand);
		array.setBlock(x+4, y+10, z+4, Blocks.sand);
		array.setBlock(x+4, y+10, z+10, Blocks.sand);
		array.setBlock(x+4, y+10, z+11, Blocks.sand);
		array.setBlock(x+4, y+10, z+12, Blocks.sand);
		array.setBlock(x+4, y+10, z+13, Blocks.sand);
		array.setBlock(x+4, y+11, z+3, Blocks.sand);
		array.setBlock(x+4, y+11, z+4, Blocks.sand);
		array.setBlock(x+4, y+11, z+5, Blocks.sand);
		array.setBlock(x+4, y+11, z+6, Blocks.sand);
		array.setBlock(x+4, y+11, z+7, Blocks.sand);
		array.setBlock(x+4, y+11, z+8, Blocks.sand);
		array.setBlock(x+4, y+11, z+9, Blocks.sand);
		array.setBlock(x+4, y+11, z+10, Blocks.sand);
		array.setBlock(x+4, y+11, z+11, Blocks.sand);
		array.setBlock(x+5, y+5, z+0, Blocks.sandstone);
		array.setBlock(x+5, y+5, z+1, Blocks.sandstone);
		array.setBlock(x+5, y+5, z+13, Blocks.sandstone);
		array.setBlock(x+5, y+5, z+14, Blocks.sandstone);
		array.setBlock(x+5, y+5, z+15, Blocks.sandstone);
		array.setBlock(x+5, y+6, z+0, Blocks.sand);
		array.setBlock(x+5, y+6, z+14, Blocks.sand);
		array.setBlock(x+5, y+6, z+15, Blocks.sand);
		array.setBlock(x+5, y+7, z+0, Blocks.sand);
		array.setBlock(x+5, y+7, z+14, Blocks.sand);
		array.setBlock(x+5, y+7, z+15, Blocks.sand);
		array.setBlock(x+5, y+8, z+0, Blocks.sand);
		array.setBlock(x+5, y+8, z+14, Blocks.sand);
		array.setBlock(x+5, y+8, z+15, Blocks.sand);
		array.setBlock(x+5, y+9, z+0, Blocks.sand);
		array.setBlock(x+5, y+9, z+1, Blocks.sand);
		array.setBlock(x+5, y+9, z+13, Blocks.sand);
		array.setBlock(x+5, y+9, z+14, Blocks.sand);
		array.setBlock(x+5, y+9, z+15, Blocks.sand);
		array.setBlock(x+5, y+10, z+1, Blocks.sand);
		array.setBlock(x+5, y+10, z+2, Blocks.sand);
		array.setBlock(x+5, y+10, z+3, Blocks.sand);
		array.setBlock(x+5, y+10, z+11, Blocks.sand);
		array.setBlock(x+5, y+10, z+12, Blocks.sand);
		array.setBlock(x+5, y+10, z+13, Blocks.sand);
		array.setBlock(x+5, y+11, z+3, Blocks.sand);
		array.setBlock(x+5, y+11, z+4, Blocks.sand);
		array.setBlock(x+5, y+11, z+7, Blocks.sand);
		array.setBlock(x+5, y+11, z+10, Blocks.sand);
		array.setBlock(x+5, y+11, z+11, Blocks.sand);
		array.setBlock(x+5, y+12, z+6, Blocks.sand);
		array.setBlock(x+5, y+12, z+7, Blocks.sand);
		array.setBlock(x+5, y+12, z+8, Blocks.sand);
		array.setBlock(x+12, y+5, z+13, Blocks.sandstone);
		array.setBlock(x+12, y+5, z+14, Blocks.sandstone);
		array.setBlock(x+12, y+5, z+15, Blocks.sandstone);
		array.setBlock(x+12, y+6, z+0, Blocks.sand);
		array.setBlock(x+12, y+6, z+14, Blocks.sand);
		array.setBlock(x+12, y+6, z+15, Blocks.sand);
		array.setBlock(x+12, y+7, z+0, Blocks.sand);
		array.setBlock(x+12, y+7, z+14, Blocks.sand);
		array.setBlock(x+12, y+7, z+15, Blocks.sand);
		array.setBlock(x+12, y+8, z+0, Blocks.sand);
		array.setBlock(x+12, y+8, z+14, Blocks.sand);
		array.setBlock(x+12, y+8, z+15, Blocks.sand);
		array.setBlock(x+12, y+9, z+0, Blocks.sand);
		array.setBlock(x+12, y+9, z+1, Blocks.sand);
		array.setBlock(x+12, y+9, z+13, Blocks.sand);
		array.setBlock(x+12, y+9, z+14, Blocks.sand);
		array.setBlock(x+12, y+9, z+15, Blocks.sand);
		array.setBlock(x+12, y+10, z+2, Blocks.sand);
		array.setBlock(x+12, y+10, z+3, Blocks.sand);
		array.setBlock(x+12, y+10, z+4, Blocks.sand);
		array.setBlock(x+12, y+10, z+5, Blocks.sand);
		array.setBlock(x+12, y+10, z+6, Blocks.sand);
		array.setBlock(x+12, y+10, z+7, Blocks.sand);
		array.setBlock(x+12, y+10, z+8, Blocks.sand);
		array.setBlock(x+12, y+10, z+9, Blocks.sand);
		array.setBlock(x+12, y+10, z+10, Blocks.sand);
		array.setBlock(x+12, y+10, z+11, Blocks.sand);
		array.setBlock(x+12, y+10, z+12, Blocks.sand);
		array.setBlock(x+13, y+5, z+0, Blocks.sandstone);
		array.setBlock(x+13, y+5, z+1, Blocks.sandstone);
		array.setBlock(x+13, y+5, z+2, Blocks.sandstone);
		array.setBlock(x+13, y+5, z+3, Blocks.sandstone);
		array.setBlock(x+13, y+5, z+4, Blocks.sandstone);
		array.setBlock(x+13, y+5, z+5, Blocks.sandstone);
		array.setBlock(x+13, y+5, z+6, Blocks.sandstone);
		array.setBlock(x+13, y+5, z+7, Blocks.sandstone);
		array.setBlock(x+13, y+5, z+8, Blocks.sandstone);
		array.setBlock(x+13, y+5, z+9, Blocks.sandstone);
		array.setBlock(x+13, y+5, z+10, Blocks.sandstone);
		array.setBlock(x+13, y+5, z+11, Blocks.sandstone);
		array.setBlock(x+13, y+5, z+12, Blocks.sandstone);
		array.setBlock(x+13, y+5, z+13, Blocks.sandstone);
		array.setBlock(x+13, y+5, z+14, Blocks.sandstone);
		array.setBlock(x+13, y+5, z+15, Blocks.sandstone);
		array.setBlock(x+13, y+6, z+0, Blocks.sand);
		array.setBlock(x+13, y+6, z+14, Blocks.sand);
		array.setBlock(x+13, y+6, z+15, Blocks.sand);
		array.setBlock(x+13, y+7, z+0, Blocks.sand);
		array.setBlock(x+13, y+7, z+14, Blocks.sand);
		array.setBlock(x+13, y+7, z+15, Blocks.sand);
		array.setBlock(x+13, y+8, z+0, Blocks.sand);
		array.setBlock(x+6, y+5, z+0, Blocks.sandstone);
		array.setBlock(x+6, y+5, z+1, Blocks.sandstone);
		array.setBlock(x+6, y+5, z+13, Blocks.sandstone);
		array.setBlock(x+6, y+5, z+14, Blocks.sandstone);
		array.setBlock(x+6, y+5, z+15, Blocks.sandstone);
		array.setBlock(x+6, y+6, z+0, Blocks.sand);
		array.setBlock(x+6, y+6, z+14, Blocks.sand);
		array.setBlock(x+6, y+6, z+15, Blocks.sand);
		array.setBlock(x+6, y+7, z+0, Blocks.sand);
		array.setBlock(x+6, y+7, z+14, Blocks.sand);
		array.setBlock(x+6, y+7, z+15, Blocks.sand);
		array.setBlock(x+6, y+8, z+0, Blocks.sand);
		array.setBlock(x+6, y+8, z+14, Blocks.sand);
		array.setBlock(x+6, y+8, z+15, Blocks.sand);
		array.setBlock(x+6, y+9, z+0, Blocks.sand);
		array.setBlock(x+6, y+9, z+1, Blocks.sand);
		array.setBlock(x+6, y+9, z+13, Blocks.sand);
		array.setBlock(x+6, y+9, z+14, Blocks.sand);
		array.setBlock(x+6, y+9, z+15, Blocks.sand);
		array.setBlock(x+6, y+10, z+1, Blocks.sand);
		array.setBlock(x+6, y+10, z+2, Blocks.sand);
		array.setBlock(x+6, y+10, z+3, Blocks.sand);
		array.setBlock(x+6, y+10, z+11, Blocks.sand);
		array.setBlock(x+6, y+10, z+12, Blocks.sand);
		array.setBlock(x+6, y+10, z+13, Blocks.sand);
		array.setBlock(x+6, y+11, z+3, Blocks.sand);
		array.setBlock(x+6, y+11, z+4, Blocks.sand);
		array.setBlock(x+6, y+11, z+6, Blocks.sand);
		array.setBlock(x+6, y+11, z+7, Blocks.sand);
		array.setBlock(x+6, y+11, z+8, Blocks.sand);
		array.setBlock(x+6, y+11, z+10, Blocks.sand);
		array.setBlock(x+6, y+11, z+11, Blocks.sand);
		array.setBlock(x+6, y+12, z+5, Blocks.sand);
		array.setBlock(x+6, y+12, z+6, Blocks.sand);
		array.setBlock(x+6, y+12, z+7, Blocks.sand);
		array.setBlock(x+6, y+12, z+8, Blocks.sand);
		array.setBlock(x+6, y+12, z+9, Blocks.sand);
		array.setBlock(x+7, y+5, z+0, Blocks.sandstone);
		array.setBlock(x+7, y+5, z+1, Blocks.sandstone);
		array.setBlock(x+7, y+5, z+13, Blocks.sandstone);
		array.setBlock(x+7, y+5, z+14, Blocks.sandstone);
		array.setBlock(x+7, y+5, z+15, Blocks.sandstone);
		array.setBlock(x+7, y+6, z+0, Blocks.sand);
		array.setBlock(x+7, y+6, z+14, Blocks.sand);
		array.setBlock(x+7, y+6, z+15, Blocks.sand);
		array.setBlock(x+7, y+7, z+0, Blocks.sand);
		array.setBlock(x+7, y+7, z+14, Blocks.sand);
		array.setBlock(x+7, y+7, z+15, Blocks.sand);
		array.setBlock(x+7, y+8, z+0, Blocks.sand);
		array.setBlock(x+7, y+8, z+14, Blocks.sand);
		array.setBlock(x+7, y+8, z+15, Blocks.sand);
		array.setBlock(x+7, y+9, z+0, Blocks.sand);
		array.setBlock(x+7, y+9, z+1, Blocks.sand);
		array.setBlock(x+7, y+9, z+13, Blocks.sand);
		array.setBlock(x+7, y+9, z+14, Blocks.sand);
		array.setBlock(x+7, y+9, z+15, Blocks.sand);
		array.setBlock(x+7, y+10, z+1, Blocks.sand);
		array.setBlock(x+7, y+10, z+2, Blocks.sand);
		array.setBlock(x+7, y+10, z+3, Blocks.sand);
		array.setBlock(x+7, y+10, z+11, Blocks.sand);
		array.setBlock(x+7, y+10, z+12, Blocks.sand);
		array.setBlock(x+7, y+10, z+13, Blocks.sand);
		array.setBlock(x+7, y+11, z+4, Blocks.sand);
		array.setBlock(x+7, y+11, z+5, Blocks.sand);
		array.setBlock(x+7, y+11, z+6, Blocks.sand);
		array.setBlock(x+7, y+11, z+7, Blocks.sand);
		array.setBlock(x+7, y+11, z+8, Blocks.sand);
		array.setBlock(x+7, y+11, z+9, Blocks.sand);
		array.setBlock(x+7, y+11, z+10, Blocks.sand);
		array.setBlock(x+7, y+12, z+5, Blocks.sand);
		array.setBlock(x+7, y+12, z+6, Blocks.sand);
		array.setBlock(x+7, y+12, z+7, Blocks.sand);
		array.setBlock(x+7, y+12, z+8, Blocks.sand);
		array.setBlock(x+7, y+12, z+9, Blocks.sand);
		array.setBlock(x+8, y+5, z+0, Blocks.sandstone);
		array.setBlock(x+8, y+5, z+1, Blocks.sandstone);
		array.setBlock(x+8, y+5, z+13, Blocks.sandstone);
		array.setBlock(x+8, y+5, z+14, Blocks.sandstone);
		array.setBlock(x+8, y+5, z+15, Blocks.sandstone);
		array.setBlock(x+8, y+6, z+0, Blocks.sand);
		array.setBlock(x+8, y+6, z+14, Blocks.sand);
		array.setBlock(x+8, y+6, z+15, Blocks.sand);
		array.setBlock(x+8, y+7, z+0, Blocks.sand);
		array.setBlock(x+8, y+7, z+14, Blocks.sand);
		array.setBlock(x+8, y+7, z+15, Blocks.sand);
		array.setBlock(x+8, y+8, z+0, Blocks.sand);
		array.setBlock(x+8, y+8, z+14, Blocks.sand);
		array.setBlock(x+8, y+8, z+15, Blocks.sand);
		array.setBlock(x+8, y+9, z+0, Blocks.sand);
		array.setBlock(x+8, y+9, z+1, Blocks.sand);
		array.setBlock(x+8, y+9, z+13, Blocks.sand);
		array.setBlock(x+8, y+9, z+14, Blocks.sand);
		array.setBlock(x+8, y+9, z+15, Blocks.sand);
		array.setBlock(x+8, y+10, z+1, Blocks.sand);
		array.setBlock(x+8, y+10, z+2, Blocks.sand);
		array.setBlock(x+8, y+10, z+3, Blocks.sand);
		array.setBlock(x+8, y+10, z+11, Blocks.sand);
		array.setBlock(x+8, y+10, z+12, Blocks.sand);
		array.setBlock(x+8, y+10, z+13, Blocks.sand);
		array.setBlock(x+8, y+11, z+3, Blocks.sand);
		array.setBlock(x+8, y+11, z+4, Blocks.sand);
		array.setBlock(x+8, y+11, z+6, Blocks.sand);
		array.setBlock(x+8, y+11, z+7, Blocks.sand);
		array.setBlock(x+8, y+11, z+8, Blocks.sand);
		array.setBlock(x+8, y+11, z+10, Blocks.sand);
		array.setBlock(x+8, y+11, z+11, Blocks.sand);
		array.setBlock(x+8, y+12, z+5, Blocks.sand);
		array.setBlock(x+8, y+12, z+6, Blocks.sand);
		array.setBlock(x+8, y+12, z+7, Blocks.sand);
		array.setBlock(x+8, y+12, z+8, Blocks.sand);
		array.setBlock(x+8, y+12, z+9, Blocks.sand);
		array.setBlock(x+9, y+5, z+0, Blocks.sandstone);
		array.setBlock(x+9, y+5, z+1, Blocks.sandstone);
		array.setBlock(x+9, y+5, z+13, Blocks.sandstone);
		array.setBlock(x+9, y+5, z+14, Blocks.sandstone);
		array.setBlock(x+9, y+5, z+15, Blocks.sandstone);
		array.setBlock(x+9, y+6, z+0, Blocks.sand);
		array.setBlock(x+9, y+6, z+14, Blocks.sand);
		array.setBlock(x+9, y+6, z+15, Blocks.sand);
		array.setBlock(x+9, y+7, z+0, Blocks.sand);
		array.setBlock(x+9, y+7, z+14, Blocks.sand);
		array.setBlock(x+9, y+7, z+15, Blocks.sand);
		array.setBlock(x+9, y+8, z+0, Blocks.sand);
		array.setBlock(x+9, y+8, z+14, Blocks.sand);
		array.setBlock(x+9, y+8, z+15, Blocks.sand);
		array.setBlock(x+9, y+9, z+0, Blocks.sand);
		array.setBlock(x+9, y+9, z+1, Blocks.sand);
		array.setBlock(x+9, y+9, z+13, Blocks.sand);
		array.setBlock(x+9, y+9, z+14, Blocks.sand);
		array.setBlock(x+9, y+9, z+15, Blocks.sand);
		array.setBlock(x+9, y+10, z+1, Blocks.sand);
		array.setBlock(x+9, y+10, z+2, Blocks.sand);
		array.setBlock(x+9, y+10, z+3, Blocks.sand);
		array.setBlock(x+9, y+10, z+11, Blocks.sand);
		array.setBlock(x+9, y+10, z+12, Blocks.sand);
		array.setBlock(x+9, y+10, z+13, Blocks.sand);
		array.setBlock(x+9, y+11, z+3, Blocks.sand);
		array.setBlock(x+9, y+11, z+4, Blocks.sand);
		array.setBlock(x+9, y+11, z+7, Blocks.sand);
		array.setBlock(x+9, y+11, z+10, Blocks.sand);
		array.setBlock(x+9, y+11, z+11, Blocks.sand);
		array.setBlock(x+9, y+12, z+6, Blocks.sand);
		array.setBlock(x+9, y+12, z+7, Blocks.sand);
		array.setBlock(x+9, y+12, z+8, Blocks.sand);
		array.setBlock(x+10, y+5, z+0, Blocks.sandstone);
		array.setBlock(x+10, y+5, z+1, Blocks.sandstone);
		array.setBlock(x+10, y+5, z+13, Blocks.sandstone);
		array.setBlock(x+10, y+5, z+14, Blocks.sandstone);
		array.setBlock(x+10, y+5, z+15, Blocks.sandstone);
		array.setBlock(x+10, y+6, z+0, Blocks.sand);
		array.setBlock(x+10, y+6, z+14, Blocks.sand);
		array.setBlock(x+10, y+6, z+15, Blocks.sand);
		array.setBlock(x+10, y+7, z+0, Blocks.sand);
		array.setBlock(x+10, y+7, z+14, Blocks.sand);
		array.setBlock(x+10, y+7, z+15, Blocks.sand);
		array.setBlock(x+10, y+8, z+0, Blocks.sand);
		array.setBlock(x+10, y+8, z+14, Blocks.sand);
		array.setBlock(x+10, y+8, z+15, Blocks.sand);
		array.setBlock(x+10, y+9, z+0, Blocks.sand);
		array.setBlock(x+10, y+9, z+1, Blocks.sand);
		array.setBlock(x+10, y+9, z+13, Blocks.sand);
		array.setBlock(x+10, y+9, z+14, Blocks.sand);
		array.setBlock(x+10, y+9, z+15, Blocks.sand);
		array.setBlock(x+10, y+10, z+1, Blocks.sand);
		array.setBlock(x+10, y+10, z+2, Blocks.sand);
		array.setBlock(x+10, y+10, z+3, Blocks.sand);
		array.setBlock(x+10, y+10, z+4, Blocks.sand);
		array.setBlock(x+10, y+10, z+10, Blocks.sand);
		array.setBlock(x+10, y+10, z+11, Blocks.sand);
		array.setBlock(x+10, y+10, z+12, Blocks.sand);
		array.setBlock(x+10, y+10, z+13, Blocks.sand);
		array.setBlock(x+10, y+11, z+3, Blocks.sand);
		array.setBlock(x+10, y+11, z+4, Blocks.sand);
		array.setBlock(x+10, y+11, z+5, Blocks.sand);
		array.setBlock(x+10, y+11, z+6, Blocks.sand);
		array.setBlock(x+10, y+11, z+7, Blocks.sand);
		array.setBlock(x+10, y+11, z+8, Blocks.sand);
		array.setBlock(x+10, y+11, z+9, Blocks.sand);
		array.setBlock(x+10, y+11, z+10, Blocks.sand);
		array.setBlock(x+10, y+11, z+11, Blocks.sand);
		array.setBlock(x+11, y+5, z+0, Blocks.sandstone);
		array.setBlock(x+11, y+5, z+1, Blocks.sandstone);
		array.setBlock(x+11, y+5, z+13, Blocks.sandstone);
		array.setBlock(x+11, y+5, z+14, Blocks.sandstone);
		array.setBlock(x+11, y+5, z+15, Blocks.sandstone);
		array.setBlock(x+11, y+6, z+0, Blocks.sand);
		array.setBlock(x+11, y+6, z+14, Blocks.sand);
		array.setBlock(x+11, y+6, z+15, Blocks.sand);
		array.setBlock(x+11, y+7, z+0, Blocks.sand);
		array.setBlock(x+11, y+7, z+14, Blocks.sand);
		array.setBlock(x+11, y+7, z+15, Blocks.sand);
		array.setBlock(x+11, y+8, z+0, Blocks.sand);
		array.setBlock(x+11, y+8, z+14, Blocks.sand);
		array.setBlock(x+11, y+8, z+15, Blocks.sand);
		array.setBlock(x+11, y+9, z+0, Blocks.sand);
		array.setBlock(x+11, y+9, z+1, Blocks.sand);
		array.setBlock(x+11, y+9, z+13, Blocks.sand);
		array.setBlock(x+11, y+9, z+14, Blocks.sand);
		array.setBlock(x+11, y+9, z+15, Blocks.sand);
		array.setBlock(x+11, y+10, z+2, Blocks.sand);
		array.setBlock(x+11, y+10, z+3, Blocks.sand);
		array.setBlock(x+11, y+10, z+4, Blocks.sand);
		array.setBlock(x+11, y+10, z+5, Blocks.sand);
		array.setBlock(x+11, y+10, z+6, Blocks.sand);
		array.setBlock(x+11, y+10, z+7, Blocks.sand);
		array.setBlock(x+11, y+10, z+8, Blocks.sand);
		array.setBlock(x+11, y+10, z+9, Blocks.sand);
		array.setBlock(x+11, y+10, z+10, Blocks.sand);
		array.setBlock(x+11, y+10, z+11, Blocks.sand);
		array.setBlock(x+11, y+10, z+12, Blocks.sand);
		array.setBlock(x+11, y+11, z+4, Blocks.sand);
		array.setBlock(x+11, y+11, z+5, Blocks.sand);
		array.setBlock(x+11, y+11, z+6, Blocks.sand);
		array.setBlock(x+11, y+11, z+8, Blocks.sand);
		array.setBlock(x+11, y+11, z+9, Blocks.sand);
		array.setBlock(x+11, y+11, z+10, Blocks.sand);
		array.setBlock(x+12, y+5, z+0, Blocks.sandstone);
		array.setBlock(x+12, y+5, z+1, Blocks.sandstone);
	}

	@Override
	public int getStructureVersion() {
		return 1;
	}

}
