/*******************************************************************************
 * @author Reika Kalseki
 *
 * Copyright 2017
 *
 * All rights reserved.
 * Distribution of the software in any form is only allowed with
 * explicit, prior permission from the owner.
 ******************************************************************************/
package Reika.ChromatiCraft.Auxiliary.Structure.Worldgen;

import net.minecraft.block.Block;
import net.minecraft.init.Blocks;
import net.minecraft.world.World;

import Reika.ChromatiCraft.Base.FragmentStructureBase;
import Reika.DragonAPI.Instantiable.Data.BlockStruct.BlockArray;
import Reika.DragonAPI.Instantiable.Data.BlockStruct.FilledBlockArray;
import Reika.DragonAPI.Instantiable.Data.Immutable.Coordinate;

public class OceanStructure extends FragmentStructureBase {

	@Override
	public Coordinate getControllerRelativeLocation() {
		return new Coordinate(0, 0, 0);
	}

	@Override
	public FilledBlockArray getArray(World world, int x, int y, int z) {
		FilledBlockArray array = new FilledBlockArray(world);

		x -= 3;
		y -= 5;
		z -= 3;

		this.addChests(array, x, y, z);
		this.addPit(array, x, y, z, shield);
		this.addCloakTunnel(array, x, y, z, shield);
		this.addCovers(array, x, y, z, shield);

		array.setBlock(x+0, y+7, z+1, shield, 9);
		array.setBlock(x+0, y+7, z+2, shield, 9);
		array.setBlock(x+0, y+7, z+3, shield, 9);
		array.setBlock(x+0, y+7, z+4, shield, 9);
		array.setBlock(x+0, y+7, z+5, shield, 9);
		array.setBlock(x+0, y+7, z+14, shield, 9);
		array.setBlock(x+0, y+7, z+15, shield, 9);
		array.setBlock(x+0, y+7, z+16, shield, 9);
		array.setBlock(x+0, y+7, z+17, shield, 9);
		array.setBlock(x+0, y+7, z+18, shield, 9);
		array.setBlock(x+0, y+7, z+19, shield, 9);
		array.setBlock(x+0, y+7, z+20, shield, 9);
		array.setBlock(x+0, y+7, z+21, shield, 9);
		array.setBlock(x+0, y+7, z+22, shield, 9);
		array.setBlock(x+0, y+8, z+1, shield, 9);
		array.setBlock(x+0, y+8, z+2, shield, 9);
		array.setBlock(x+0, y+8, z+3, shield, 9);
		array.setBlock(x+0, y+8, z+4, shield, 9);
		array.setBlock(x+0, y+8, z+5, shield, 9);
		array.setBlock(x+0, y+8, z+14, shield, 9);
		array.setBlock(x+0, y+8, z+15, shield, 9);
		array.setBlock(x+0, y+8, z+16, shield, 9);
		array.setBlock(x+0, y+8, z+17, shield, 9);
		array.setBlock(x+0, y+8, z+18, shield, 9);
		array.setBlock(x+0, y+8, z+19, shield, 9);
		array.setBlock(x+0, y+8, z+20, shield, 9);
		array.setBlock(x+0, y+8, z+21, shield, 9);
		array.setBlock(x+0, y+8, z+22, shield, 9);
		array.setBlock(x+0, y+9, z+1, shield, 9);
		array.setBlock(x+0, y+9, z+2, shield, 13);
		array.setBlock(x+0, y+9, z+3, shield, 13);
		array.setBlock(x+0, y+9, z+4, shield, 13);
		array.setBlock(x+0, y+9, z+5, shield, 9);
		array.setBlock(x+0, y+9, z+14, shield, 9);
		array.setBlock(x+0, y+9, z+15, shield, 13);
		array.setBlock(x+0, y+9, z+16, shield, 13);
		array.setBlock(x+0, y+9, z+17, shield, 13);
		array.setBlock(x+0, y+9, z+18, shield, 13);
		array.setBlock(x+0, y+9, z+19, shield, 13);
		array.setBlock(x+0, y+9, z+20, shield, 13);
		array.setBlock(x+0, y+9, z+21, shield, 13);
		array.setBlock(x+0, y+9, z+22, shield, 9);
		array.setBlock(x+0, y+10, z+1, shield, 9);
		array.setBlock(x+0, y+10, z+2, shield, 13);
		array.setBlock(x+0, y+10, z+3, shield, 13);
		array.setBlock(x+0, y+10, z+4, shield, 13);
		array.setBlock(x+0, y+10, z+5, shield, 9);
		array.setBlock(x+0, y+10, z+14, shield, 9);
		array.setBlock(x+0, y+10, z+15, shield, 13);
		array.setBlock(x+0, y+10, z+16, shield, 13);
		array.setBlock(x+0, y+10, z+17, shield, 13);
		array.setBlock(x+0, y+10, z+18, shield, 13);
		array.setBlock(x+0, y+10, z+19, shield, 13);
		array.setBlock(x+0, y+10, z+20, shield, 13);
		array.setBlock(x+0, y+10, z+21, shield, 13);
		array.setBlock(x+0, y+10, z+22, shield, 9);
		array.setBlock(x+0, y+11, z+1, shield, 9);
		array.setBlock(x+0, y+11, z+2, shield, 9);
		array.setBlock(x+0, y+11, z+3, shield, 9);
		array.setBlock(x+0, y+11, z+4, shield, 9);
		array.setBlock(x+0, y+11, z+5, shield, 9);
		array.setBlock(x+0, y+11, z+14, shield, 9);
		array.setBlock(x+0, y+11, z+15, shield, 9);
		array.setBlock(x+0, y+11, z+16, shield, 9);
		array.setBlock(x+0, y+11, z+17, shield, 9);
		array.setBlock(x+0, y+11, z+18, shield, 9);
		array.setBlock(x+0, y+11, z+19, shield, 9);
		array.setBlock(x+0, y+11, z+20, shield, 9);
		array.setBlock(x+0, y+11, z+21, shield, 9);
		array.setBlock(x+0, y+11, z+22, shield, 9);
		array.setBlock(x+1, y+3, z+19, shield, 9);
		array.setBlock(x+1, y+3, z+20, shield, 9);
		array.setBlock(x+1, y+3, z+21, shield, 9);
		array.setBlock(x+1, y+3, z+22, shield, 9);
		array.setBlock(x+1, y+3, z+23, shield, 9);
		array.setBlock(x+1, y+3, z+24, shield, 9);
		array.setBlock(x+1, y+4, z+18, shield, 9);
		array.setBlock(x+1, y+4, z+19, shield, 9);
		array.setBlock(x+1, y+4, z+20, shield, 9);
		array.setBlock(x+1, y+4, z+21, shield, 9);
		array.setBlock(x+1, y+4, z+22, shield, 9);
		array.setBlock(x+1, y+4, z+23, shield, 9);
		array.setBlock(x+1, y+4, z+24, shield, 9);
		array.setBlock(x+1, y+5, z+17, shield, 9);
		array.setBlock(x+1, y+5, z+18, shield, 9);
		array.setBlock(x+1, y+5, z+19, shield, 9);
		array.setBlock(x+1, y+5, z+20, shield, 9);
		array.setBlock(x+1, y+5, z+21, shield, 9);
		array.setBlock(x+1, y+5, z+22, shield, 9);
		array.setBlock(x+1, y+5, z+23, shield, 9);
		array.setBlock(x+1, y+5, z+24, shield, 9);
		array.setBlock(x+1, y+6, z+16, shield, 9);
		array.setBlock(x+1, y+6, z+17, shield, 9);
		array.setBlock(x+1, y+6, z+18, shield, 9);
		array.setBlock(x+1, y+6, z+19, shield, 9);
		array.setBlock(x+1, y+6, z+20, shield, 9);
		array.setBlock(x+1, y+6, z+21, shield, 9);
		array.setBlock(x+1, y+6, z+22, shield, 9);
		array.setBlock(x+1, y+6, z+23, shield, 9);
		array.setBlock(x+1, y+6, z+24, shield, 9);
		array.setBlock(x+1, y+7, z+0, shield, 9);
		array.setBlock(x+1, y+7, z+1, shield, 9);
		array.setBlock(x+1, y+7, z+2, shield, 9);
		array.setBlock(x+1, y+7, z+3, shield, 9);
		array.setBlock(x+1, y+7, z+4, shield, 9);
		array.setBlock(x+1, y+7, z+5, shield, 9);
		array.setBlock(x+1, y+7, z+6, shield, 9);
		array.setBlock(x+1, y+7, z+7, shield, 9);
		array.setBlock(x+1, y+7, z+8, shield, 9);
		array.setBlock(x+1, y+7, z+9, shield, 9);
		array.setBlock(x+1, y+7, z+10, shield, 9);
		array.setBlock(x+1, y+7, z+11, shield, 9);
		array.setBlock(x+1, y+7, z+12, shield, 9);
		array.setBlock(x+1, y+7, z+13, shield, 9);
		array.setBlock(x+1, y+7, z+14, shield, 9);
		array.setBlock(x+1, y+7, z+15, shield, 9);
		array.setBlock(x+1, y+7, z+16, shield, 9);
		array.setBlock(x+1, y+7, z+17, shield, 9);
		array.setBlock(x+1, y+7, z+18, shield, 9);
		array.setBlock(x+1, y+7, z+19, shield, 9);
		array.setBlock(x+1, y+7, z+20, shield, 9);
		array.setBlock(x+1, y+7, z+21, shield, 9);
		array.setBlock(x+1, y+7, z+22, shield, 9);
		array.setBlock(x+1, y+7, z+23, shield, 9);
		array.setBlock(x+1, y+7, z+24, shield, 9);
		array.setBlock(x+1, y+7, z+25, shield, 9);
		array.setBlock(x+1, y+7, z+26, shield, 9);
		array.setBlock(x+1, y+7, z+27, shield, 9);
		array.setBlock(x+1, y+7, z+28, shield, 9);
		array.setBlock(x+1, y+7, z+29, shield, 9);
		array.setBlock(x+1, y+7, z+30, shield, 9);
		array.setBlock(x+1, y+8, z+0, shield, 9);
		array.setBlock(x+1, y+8, z+1, shield, 9);
		array.setBlock(x+1, y+8, z+5, shield, 9);
		array.setBlock(x+1, y+8, z+6, shield, 9);
		array.setBlock(x+1, y+8, z+7, shield, 9);
		array.setBlock(x+1, y+8, z+8, shield, 9);
		array.setBlock(x+1, y+8, z+9, shield, 9);
		array.setBlock(x+1, y+8, z+10, shield, 9);
		array.setBlock(x+1, y+8, z+11, shield, 9);
		array.setBlock(x+1, y+8, z+12, shield, 9);
		array.setBlock(x+1, y+8, z+13, shield, 9);
		array.setBlock(x+1, y+8, z+14, shield, 9);
		array.setBlock(x+1, y+8, z+22, shield, 9);
		array.setBlock(x+1, y+8, z+23, shield, 9);
		array.setBlock(x+1, y+8, z+24, shield, 9);
		array.setBlock(x+1, y+8, z+25, shield, 9);
		array.setBlock(x+1, y+8, z+26, shield, 9);
		array.setBlock(x+1, y+8, z+27, shield, 9);
		array.setBlock(x+1, y+8, z+28, shield, 9);
		array.setBlock(x+1, y+8, z+29, shield, 9);
		array.setBlock(x+1, y+8, z+30, shield, 9);
		array.setBlock(x+1, y+9, z+0, shield, 9);
		array.setBlock(x+1, y+9, z+1, shield, 9);
		array.setBlock(x+1, y+9, z+5, shield, 9);
		array.setBlock(x+1, y+9, z+6, shield, 13);
		array.setBlock(x+1, y+9, z+7, shield, 13);
		array.setBlock(x+1, y+9, z+8, shield, 13);
		array.setBlock(x+1, y+9, z+9, shield, 13);
		array.setBlock(x+1, y+9, z+10, shield, 13);
		array.setBlock(x+1, y+9, z+11, shield, 13);
		array.setBlock(x+1, y+9, z+12, shield, 13);
		array.setBlock(x+1, y+9, z+13, shield, 13);
		array.setBlock(x+1, y+9, z+14, shield, 9);
		array.setBlock(x+1, y+9, z+22, shield, 9);
		array.setBlock(x+1, y+9, z+23, shield, 13);
		array.setBlock(x+1, y+9, z+24, shield, 13);
		array.setBlock(x+1, y+9, z+25, shield, 13);
		array.setBlock(x+1, y+9, z+26, shield, 13);
		array.setBlock(x+1, y+9, z+27, shield, 13);
		array.setBlock(x+1, y+9, z+28, shield, 13);
		array.setBlock(x+1, y+9, z+29, shield, 13);
		array.setBlock(x+1, y+9, z+30, shield, 9);
		array.setBlock(x+1, y+10, z+0, shield, 9);
		array.setBlock(x+1, y+10, z+1, shield, 9);
		array.setBlock(x+1, y+10, z+5, shield, 9);
		array.setBlock(x+1, y+10, z+6, shield, 13);
		array.setBlock(x+1, y+10, z+7, shield, 13);
		array.setBlock(x+1, y+10, z+8, shield, 13);
		array.setBlock(x+1, y+10, z+9, shield, 13);
		array.setBlock(x+1, y+10, z+10, shield, 13);
		array.setBlock(x+1, y+10, z+11, shield, 13);
		array.setBlock(x+1, y+10, z+12, shield, 13);
		array.setBlock(x+1, y+10, z+13, shield, 13);
		array.setBlock(x+1, y+10, z+14, shield, 9);
		array.setBlock(x+1, y+10, z+22, shield, 9);
		array.setBlock(x+1, y+10, z+23, shield, 13);
		array.setBlock(x+1, y+10, z+24, shield, 13);
		array.setBlock(x+1, y+10, z+25, shield, 13);
		array.setBlock(x+1, y+10, z+26, shield, 13);
		array.setBlock(x+1, y+10, z+27, shield, 13);
		array.setBlock(x+1, y+10, z+28, shield, 13);
		array.setBlock(x+1, y+10, z+29, shield, 13);
		array.setBlock(x+1, y+10, z+30, shield, 9);
		array.setBlock(x+1, y+11, z+0, shield, 9);
		array.setBlock(x+1, y+11, z+1, shield, 9);
		array.setBlock(x+1, y+11, z+5, shield, 9);
		array.setBlock(x+1, y+11, z+6, shield, 9);
		array.setBlock(x+1, y+11, z+7, shield, 9);
		array.setBlock(x+1, y+11, z+8, shield, 9);
		array.setBlock(x+1, y+11, z+9, shield, 9);
		array.setBlock(x+1, y+11, z+10, shield, 9);
		array.setBlock(x+1, y+11, z+11, shield, 9);
		array.setBlock(x+1, y+11, z+12, shield, 9);
		array.setBlock(x+1, y+11, z+13, shield, 9);
		array.setBlock(x+1, y+11, z+14, shield, 9);
		array.setBlock(x+1, y+11, z+22, shield, 9);
		array.setBlock(x+1, y+11, z+23, shield, 9);
		array.setBlock(x+1, y+11, z+24, shield, 9);
		array.setBlock(x+1, y+11, z+25, shield, 9);
		array.setBlock(x+1, y+11, z+26, shield, 9);
		array.setBlock(x+1, y+11, z+27, shield, 9);
		array.setBlock(x+1, y+11, z+28, shield, 9);
		array.setBlock(x+1, y+11, z+29, shield, 9);
		array.setBlock(x+1, y+11, z+30, shield, 9);
		array.setBlock(x+1, y+12, z+1, shield, 9);
		array.setBlock(x+1, y+12, z+2, shield, 9);
		array.setBlock(x+1, y+12, z+3, shield, 9);
		array.setBlock(x+1, y+12, z+4, shield, 9);
		array.setBlock(x+1, y+12, z+5, shield, 9);
		array.setBlock(x+1, y+12, z+14, shield, 9);
		array.setBlock(x+1, y+12, z+15, shield, 9);
		array.setBlock(x+1, y+12, z+16, shield, 9);
		array.setBlock(x+1, y+12, z+17, shield, 9);
		array.setBlock(x+1, y+12, z+18, shield, 9);
		array.setBlock(x+1, y+12, z+19, shield, 9);
		array.setBlock(x+1, y+12, z+20, shield, 9);
		array.setBlock(x+1, y+12, z+21, shield, 9);
		array.setBlock(x+1, y+12, z+22, shield, 9);
		array.setBlock(x+2, y+2, z+20, shield, 9);
		array.setBlock(x+2, y+2, z+21, shield, 9);
		array.setBlock(x+2, y+2, z+22, shield, 9);
		array.setBlock(x+2, y+2, z+23, shield, 9);
		array.setBlock(x+2, y+2, z+24, shield, 9);
		array.setBlock(x+2, y+3, z+19, shield, 9);
		array.setBlock(x+2, y+3, z+25, shield, 9);
		array.setBlock(x+2, y+4, z+18, shield, 9);
		array.setBlock(x+2, y+4, z+25, shield, 9);
		array.setBlock(x+2, y+5, z+17, shield, 9);
		array.setBlock(x+2, y+5, z+25, shield, 9);
		array.setBlock(x+2, y+6, z+16, shield, 9);
		array.setBlock(x+2, y+6, z+22, shield, 9);
		array.setBlock(x+2, y+6, z+23, shield, 9);
		array.setBlock(x+2, y+6, z+24, shield, 9);
		array.setBlock(x+2, y+6, z+29, shield, 9);
		array.setBlock(x+2, y+7, z+0, shield, 9);
		array.setBlock(x+2, y+7, z+1, shield, 9);
		array.setBlock(x+2, y+7, z+2, shield, 9);
		array.setBlock(x+2, y+7, z+3, shield, 9);
		array.setBlock(x+2, y+7, z+4, shield, 9);
		array.setBlock(x+2, y+7, z+5, shield, 9);
		array.setBlock(x+2, y+7, z+6, shield, 9);
		array.setBlock(x+2, y+7, z+7, shield, 9);
		array.setBlock(x+2, y+7, z+8, shield, 9);
		array.setBlock(x+2, y+7, z+9, shield, 9);
		array.setBlock(x+2, y+7, z+10, shield, 9);
		array.setBlock(x+2, y+7, z+11, shield, 9);
		array.setBlock(x+2, y+7, z+12, shield, 9);
		array.setBlock(x+2, y+7, z+13, shield, 9);
		array.setBlock(x+2, y+7, z+14, shield, 9);
		array.setBlock(x+2, y+7, z+15, shield, 9);
		array.setBlock(x+2, y+7, z+21, shield, 9);
		array.setBlock(x+2, y+7, z+22, shield, 9);
		array.setBlock(x+2, y+7, z+23, shield, 9);
		array.setBlock(x+2, y+7, z+24, shield, 9);
		array.setBlock(x+2, y+7, z+25, shield, 9);
		array.setBlock(x+2, y+7, z+26, shield, 9);
		array.setBlock(x+2, y+7, z+27, shield, 9);
		array.setBlock(x+2, y+7, z+28, shield, 9);
		array.setBlock(x+2, y+7, z+30, shield, 9);
		array.setBlock(x+2, y+8, z+0, shield, 9);
		array.setBlock(x+2, y+9, z+0, shield, 13);
		array.setBlock(x+2, y+10, z+0, shield, 13);
		array.setBlock(x+2, y+11, z+0, shield, 9);
		array.setBlock(x+2, y+11, z+5, shield, 9);
		array.setBlock(x+2, y+11, z+6, shield, 13);
		array.setBlock(x+2, y+11, z+7, shield, 13);
		array.setBlock(x+2, y+11, z+8, shield, 13);
		array.setBlock(x+2, y+11, z+9, shield, 13);
		array.setBlock(x+2, y+11, z+10, shield, 13);
		array.setBlock(x+2, y+11, z+11, shield, 13);
		array.setBlock(x+2, y+11, z+12, shield, 13);
		array.setBlock(x+2, y+11, z+13, shield, 13);
		array.setBlock(x+2, y+11, z+14, shield, 9);
		array.setBlock(x+2, y+11, z+22, shield, 9);
		array.setBlock(x+2, y+11, z+23, shield, 13);
		array.setBlock(x+2, y+11, z+24, shield, 13);
		array.setBlock(x+2, y+11, z+25, shield, 13);
		array.setBlock(x+2, y+11, z+26, shield, 13);
		array.setBlock(x+2, y+11, z+27, shield, 13);
		array.setBlock(x+2, y+11, z+28, shield, 13);
		array.setBlock(x+2, y+11, z+29, shield, 13);
		array.setBlock(x+2, y+11, z+30, shield, 9);
		array.setBlock(x+2, y+12, z+1, shield, 9);
		array.setBlock(x+2, y+12, z+2, shield, 13);
		array.setBlock(x+2, y+12, z+3, shield, 13);
		array.setBlock(x+2, y+12, z+4, shield, 13);
		array.setBlock(x+2, y+12, z+5, shield, 9);
		array.setBlock(x+2, y+12, z+14, shield, 9);
		array.setBlock(x+2, y+12, z+15, shield, 13);
		array.setBlock(x+2, y+12, z+16, shield, 13);
		array.setBlock(x+2, y+12, z+17, shield, 13);
		array.setBlock(x+2, y+12, z+18, shield, 13);
		array.setBlock(x+2, y+12, z+19, shield, 13);
		array.setBlock(x+2, y+12, z+20, shield, 13);
		array.setBlock(x+2, y+12, z+21, shield, 13);
		array.setBlock(x+2, y+12, z+22, shield, 9);
		array.setBlock(x+3, y+2, z+20, shield, 9);
		array.setBlock(x+3, y+2, z+21, shield, 9);
		array.setBlock(x+3, y+2, z+22, shield, 9);
		array.setBlock(x+3, y+2, z+23, shield, 9);
		array.setBlock(x+3, y+2, z+24, shield, 9);
		array.setBlock(x+3, y+3, z+19, shield, 9);
		array.setBlock(x+3, y+3, z+25, shield, 9);
		array.setBlock(x+3, y+5, z+17, shield, 9);
		array.setBlock(x+3, y+5, z+25, shield, 9);
		array.setBlock(x+3, y+4, z+18, shield, 9);
		array.setBlock(x+3, y+4, z+25, shield, 9);
		array.setBlock(x+3, y+6, z+16, shield, 9);
		array.setBlock(x+3, y+6, z+22, shield, 9);
		array.setBlock(x+3, y+6, z+23, shield, 9);
		array.setBlock(x+3, y+6, z+24, shield, 9);
		array.setBlock(x+3, y+6, z+29, shield, 9);
		array.setBlock(x+3, y+7, z+0, shield, 9);
		array.setBlock(x+3, y+7, z+1, shield, 9);
		array.setBlock(x+3, y+7, z+2, shield, 9);
		array.setBlock(x+3, y+7, z+3, shield, 9);
		array.setBlock(x+3, y+7, z+4, shield, 9);
		array.setBlock(x+3, y+7, z+5, shield, 9);
		array.setBlock(x+3, y+7, z+6, shield, 9);
		array.setBlock(x+3, y+7, z+7, shield, 9);
		array.setBlock(x+3, y+7, z+8, shield, 9);
		array.setBlock(x+3, y+7, z+9, shield, 9);
		array.setBlock(x+3, y+7, z+10, shield, 9);
		array.setBlock(x+3, y+7, z+11, shield, 9);
		array.setBlock(x+3, y+7, z+12, shield, 9);
		array.setBlock(x+3, y+7, z+13, shield, 9);
		array.setBlock(x+3, y+7, z+14, shield, 9);
		array.setBlock(x+3, y+7, z+15, shield, 9);
		array.setBlock(x+3, y+7, z+21, shield, 9);
		array.setBlock(x+3, y+7, z+22, shield, 9);
		array.setBlock(x+3, y+7, z+23, shield, 9);
		array.setBlock(x+3, y+7, z+24, shield, 9);
		array.setBlock(x+3, y+7, z+25, shield, 9);
		array.setBlock(x+3, y+7, z+26, shield, 9);
		array.setBlock(x+3, y+7, z+27, shield, 9);
		array.setBlock(x+3, y+7, z+28, shield, 9);
		array.setBlock(x+3, y+7, z+30, shield, 9);
		array.setBlock(x+3, y+8, z+0, shield, 9);
		array.setBlock(x+3, y+9, z+0, shield, 13);
		array.setBlock(x+3, y+10, z+0, shield, 13);
		array.setBlock(x+3, y+11, z+0, shield, 9);
		array.setBlock(x+3, y+11, z+5, shield, 9);
		array.setBlock(x+3, y+11, z+6, shield, 13);
		array.setBlock(x+3, y+11, z+7, shield, 13);
		array.setBlock(x+3, y+11, z+8, shield, 13);
		array.setBlock(x+3, y+11, z+9, shield, 13);
		array.setBlock(x+3, y+11, z+10, shield, 13);
		array.setBlock(x+3, y+11, z+11, shield, 13);
		array.setBlock(x+3, y+11, z+12, shield, 13);
		array.setBlock(x+3, y+11, z+13, shield, 13);
		array.setBlock(x+3, y+11, z+14, shield, 9);
		array.setBlock(x+3, y+11, z+22, shield, 9);
		array.setBlock(x+3, y+11, z+23, shield, 13);
		array.setBlock(x+3, y+11, z+24, shield, 13);
		array.setBlock(x+3, y+11, z+25, shield, 13);
		array.setBlock(x+3, y+11, z+26, shield, 13);
		array.setBlock(x+3, y+11, z+27, shield, 13);
		array.setBlock(x+3, y+11, z+28, shield, 13);
		array.setBlock(x+3, y+11, z+29, shield, 13);
		array.setBlock(x+3, y+11, z+30, shield, 9);
		array.setBlock(x+3, y+12, z+1, shield, 9);
		array.setBlock(x+3, y+12, z+2, shield, 13);
		array.setBlock(x+3, y+12, z+3, shield, 13);
		array.setBlock(x+3, y+12, z+4, shield, 13);
		array.setBlock(x+3, y+12, z+5, shield, 9);
		array.setBlock(x+3, y+12, z+14, shield, 9);
		array.setBlock(x+3, y+12, z+15, shield, 13);
		array.setBlock(x+3, y+12, z+16, shield, 13);
		array.setBlock(x+3, y+12, z+17, shield, 13);
		array.setBlock(x+3, y+12, z+18, shield, 13);
		array.setBlock(x+3, y+12, z+19, shield, 13);
		array.setBlock(x+3, y+12, z+20, shield, 13);
		array.setBlock(x+3, y+12, z+21, shield, 13);
		array.setBlock(x+3, y+12, z+22, shield, 9);
		array.setBlock(x+4, y+2, z+20, shield, 9);
		array.setBlock(x+4, y+2, z+21, shield, 9);
		array.setBlock(x+4, y+2, z+22, shield, 9);
		array.setBlock(x+4, y+2, z+23, shield, 9);
		array.setBlock(x+4, y+2, z+24, shield, 9);
		array.setBlock(x+4, y+4, z+18, shield, 9);
		array.setBlock(x+4, y+4, z+25, shield, 9);
		array.setBlock(x+4, y+3, z+19, shield, 9);
		array.setBlock(x+4, y+3, z+25, shield, 9);
		array.setBlock(x+4, y+5, z+17, shield, 9);
		array.setBlock(x+4, y+5, z+25, shield, 9);
		array.setBlock(x+4, y+6, z+16, shield, 9);
		array.setBlock(x+4, y+6, z+22, shield, 9);
		array.setBlock(x+4, y+6, z+23, shield, 9);
		array.setBlock(x+4, y+6, z+24, shield, 9);
		array.setBlock(x+4, y+6, z+29, shield, 9);
		array.setBlock(x+4, y+7, z+0, shield, 9);
		array.setBlock(x+4, y+7, z+1, shield, 9);
		array.setBlock(x+4, y+7, z+2, shield, 9);
		array.setBlock(x+4, y+7, z+3, shield, 9);
		array.setBlock(x+4, y+7, z+4, shield, 9);
		array.setBlock(x+4, y+7, z+5, shield, 9);
		array.setBlock(x+4, y+7, z+6, shield, 9);
		array.setBlock(x+4, y+7, z+7, shield, 9);
		array.setBlock(x+4, y+7, z+8, shield, 9);
		array.setBlock(x+4, y+7, z+9, shield, 9);
		array.setBlock(x+4, y+7, z+10, shield, 9);
		array.setBlock(x+4, y+7, z+11, shield, 9);
		array.setBlock(x+4, y+7, z+12, shield, 9);
		array.setBlock(x+4, y+7, z+13, shield, 9);
		array.setBlock(x+4, y+7, z+14, shield, 9);
		array.setBlock(x+4, y+7, z+15, shield, 9);
		array.setBlock(x+4, y+7, z+21, shield, 9);
		array.setBlock(x+4, y+7, z+22, shield, 9);
		array.setBlock(x+4, y+7, z+23, shield, 9);
		array.setBlock(x+4, y+7, z+24, shield, 9);
		array.setBlock(x+4, y+7, z+25, shield, 9);
		array.setBlock(x+4, y+7, z+26, shield, 9);
		array.setBlock(x+4, y+7, z+27, shield, 9);
		array.setBlock(x+4, y+7, z+28, shield, 9);
		array.setBlock(x+4, y+7, z+30, shield, 9);
		array.setBlock(x+4, y+8, z+0, shield, 9);
		array.setBlock(x+4, y+9, z+0, shield, 13);
		array.setBlock(x+4, y+10, z+0, shield, 13);
		array.setBlock(x+4, y+11, z+0, shield, 9);
		array.setBlock(x+4, y+11, z+5, shield, 9);
		array.setBlock(x+4, y+11, z+6, shield, 13);
		array.setBlock(x+4, y+11, z+7, shield, 13);
		array.setBlock(x+4, y+11, z+8, shield, 13);
		array.setBlock(x+4, y+11, z+9, shield, 13);
		array.setBlock(x+4, y+11, z+10, shield, 13);
		array.setBlock(x+4, y+11, z+11, shield, 13);
		array.setBlock(x+4, y+11, z+12, shield, 13);
		array.setBlock(x+4, y+11, z+13, shield, 13);
		array.setBlock(x+4, y+11, z+14, shield, 9);
		array.setBlock(x+4, y+11, z+22, shield, 9);
		array.setBlock(x+4, y+11, z+23, shield, 13);
		array.setBlock(x+4, y+11, z+24, shield, 13);
		array.setBlock(x+4, y+11, z+25, shield, 13);
		array.setBlock(x+4, y+11, z+26, shield, 13);
		array.setBlock(x+4, y+11, z+27, shield, 13);
		array.setBlock(x+4, y+11, z+28, shield, 13);
		array.setBlock(x+4, y+11, z+29, shield, 13);
		array.setBlock(x+4, y+11, z+30, shield, 9);
		array.setBlock(x+4, y+12, z+1, shield, 9);
		array.setBlock(x+4, y+12, z+2, shield, 13);
		array.setBlock(x+4, y+12, z+3, shield, 13);
		array.setBlock(x+4, y+12, z+4, shield, 13);
		array.setBlock(x+4, y+12, z+5, shield, 9);
		array.setBlock(x+4, y+12, z+14, shield, 9);
		array.setBlock(x+4, y+12, z+15, shield, 13);
		array.setBlock(x+4, y+12, z+16, shield, 13);
		array.setBlock(x+4, y+12, z+17, shield, 13);
		array.setBlock(x+4, y+12, z+18, shield, 13);
		array.setBlock(x+4, y+12, z+19, shield, 13);
		array.setBlock(x+4, y+12, z+20, shield, 13);
		array.setBlock(x+4, y+12, z+21, shield, 13);
		array.setBlock(x+4, y+12, z+22, shield, 9);
		array.setBlock(x+5, y+4, z+18, shield, 9);
		array.setBlock(x+5, y+4, z+19, shield, 9);
		array.setBlock(x+5, y+4, z+20, shield, 9);
		array.setBlock(x+5, y+4, z+21, shield, 9);
		array.setBlock(x+5, y+4, z+25, shield, 9);
		array.setBlock(x+5, y+3, z+19, shield, 9);
		array.setBlock(x+5, y+3, z+20, shield, 9);
		array.setBlock(x+5, y+3, z+21, shield, 9);
		array.setBlock(x+5, y+3, z+25, shield, 9);
		array.setBlock(x+5, y+2, z+22, shield, 9);
		array.setBlock(x+5, y+2, z+23, shield, 9);
		array.setBlock(x+5, y+2, z+24, shield, 9);
		array.setBlock(x+5, y+5, z+17, shield, 9);
		array.setBlock(x+5, y+5, z+18, shield, 9);
		array.setBlock(x+5, y+5, z+19, shield, 9);
		array.setBlock(x+5, y+5, z+20, shield, 9);
		array.setBlock(x+5, y+5, z+21, shield, 9);
		array.setBlock(x+5, y+5, z+25, shield, 9);
		array.setBlock(x+5, y+6, z+16, shield, 9);
		array.setBlock(x+5, y+6, z+17, shield, 9);
		array.setBlock(x+5, y+6, z+18, shield, 9);
		array.setBlock(x+5, y+6, z+19, shield, 9);
		array.setBlock(x+5, y+6, z+20, shield, 9);
		array.setBlock(x+5, y+6, z+21, shield, 9);
		array.setBlock(x+5, y+6, z+22, shield, 9);
		array.setBlock(x+5, y+6, z+23, shield, 9);
		array.setBlock(x+5, y+6, z+24, shield, 9);
		array.setBlock(x+5, y+7, z+0, shield, 9);
		array.setBlock(x+5, y+7, z+1, shield, 9);
		array.setBlock(x+5, y+7, z+2, shield, 9);
		array.setBlock(x+5, y+7, z+3, shield, 9);
		array.setBlock(x+5, y+7, z+4, shield, 9);
		array.setBlock(x+5, y+7, z+5, shield, 9);
		array.setBlock(x+5, y+7, z+6, shield, 9);
		array.setBlock(x+5, y+7, z+7, shield, 9);
		array.setBlock(x+5, y+7, z+8, shield, 9);
		array.setBlock(x+5, y+7, z+9, shield, 9);
		array.setBlock(x+5, y+7, z+10, shield, 9);
		array.setBlock(x+5, y+7, z+11, shield, 9);
		array.setBlock(x+5, y+7, z+12, shield, 9);
		array.setBlock(x+5, y+7, z+13, shield, 9);
		array.setBlock(x+5, y+7, z+14, shield, 9);
		array.setBlock(x+5, y+7, z+15, shield, 9);
		array.setBlock(x+5, y+7, z+16, shield, 9);
		array.setBlock(x+5, y+7, z+17, shield, 9);
		array.setBlock(x+5, y+7, z+18, shield, 9);
		array.setBlock(x+5, y+7, z+19, shield, 9);
		array.setBlock(x+5, y+7, z+20, shield, 9);
		array.setBlock(x+5, y+7, z+21, shield, 9);
		array.setBlock(x+5, y+7, z+22, shield, 9);
		array.setBlock(x+5, y+7, z+23, shield, 9);
		array.setBlock(x+5, y+7, z+24, shield, 9);
		array.setBlock(x+5, y+7, z+25, shield, 9);
		array.setBlock(x+5, y+7, z+26, shield, 9);
		array.setBlock(x+5, y+7, z+27, shield, 9);
		array.setBlock(x+5, y+7, z+28, shield, 9);
		array.setBlock(x+5, y+7, z+29, shield, 9);
		array.setBlock(x+5, y+7, z+30, shield, 9);
		array.setBlock(x+5, y+8, z+0, shield, 9);
		array.setBlock(x+5, y+8, z+1, shield, 9);
		array.setBlock(x+5, y+8, z+5, shield, 9);
		array.setBlock(x+5, y+8, z+6, shield, 9);
		array.setBlock(x+5, y+8, z+7, shield, 9);
		array.setBlock(x+5, y+8, z+8, shield, 9);
		array.setBlock(x+5, y+8, z+9, shield, 9);
		array.setBlock(x+5, y+8, z+10, shield, 9);
		array.setBlock(x+5, y+8, z+11, shield, 9);
		array.setBlock(x+5, y+8, z+12, shield, 9);
		array.setBlock(x+5, y+8, z+13, shield, 9);
		array.setBlock(x+5, y+8, z+14, shield, 9);
		array.setBlock(x+5, y+8, z+22, shield, 9);
		array.setBlock(x+5, y+8, z+23, shield, 9);
		array.setBlock(x+5, y+8, z+24, shield, 9);
		array.setBlock(x+5, y+8, z+25, shield, 9);
		array.setBlock(x+5, y+8, z+26, shield, 9);
		array.setBlock(x+5, y+8, z+27, shield, 9);
		array.setBlock(x+5, y+8, z+28, shield, 9);
		array.setBlock(x+5, y+8, z+29, shield, 9);
		array.setBlock(x+5, y+8, z+30, shield, 9);
		array.setBlock(x+5, y+9, z+0, shield, 9);
		array.setBlock(x+5, y+9, z+1, shield, 9);
		array.setBlock(x+5, y+9, z+5, shield, 9);
		array.setBlock(x+5, y+9, z+6, shield, 13);
		array.setBlock(x+5, y+9, z+7, shield, 13);
		array.setBlock(x+5, y+9, z+8, shield, 13);
		array.setBlock(x+5, y+9, z+9, shield, 13);
		array.setBlock(x+5, y+9, z+10, shield, 13);
		array.setBlock(x+5, y+9, z+11, shield, 13);
		array.setBlock(x+5, y+9, z+12, shield, 13);
		array.setBlock(x+5, y+9, z+13, shield, 13);
		array.setBlock(x+5, y+9, z+14, shield, 9);
		array.setBlock(x+5, y+9, z+22, shield, 9);
		array.setBlock(x+5, y+9, z+23, shield, 13);
		array.setBlock(x+5, y+9, z+24, shield, 13);
		array.setBlock(x+5, y+9, z+25, shield, 13);
		array.setBlock(x+5, y+9, z+26, shield, 13);
		array.setBlock(x+5, y+9, z+27, shield, 13);
		array.setBlock(x+5, y+9, z+28, shield, 13);
		array.setBlock(x+5, y+9, z+29, shield, 13);
		array.setBlock(x+5, y+9, z+30, shield, 9);
		array.setBlock(x+5, y+10, z+0, shield, 9);
		array.setBlock(x+5, y+10, z+1, shield, 9);
		array.setBlock(x+5, y+10, z+5, shield, 9);
		array.setBlock(x+5, y+10, z+6, shield, 13);
		array.setBlock(x+5, y+10, z+7, shield, 13);
		array.setBlock(x+5, y+10, z+8, shield, 13);
		array.setBlock(x+5, y+10, z+9, shield, 13);
		array.setBlock(x+5, y+10, z+10, shield, 13);
		array.setBlock(x+5, y+10, z+11, shield, 13);
		array.setBlock(x+5, y+10, z+12, shield, 13);
		array.setBlock(x+5, y+10, z+13, shield, 13);
		array.setBlock(x+5, y+10, z+14, shield, 9);
		array.setBlock(x+5, y+10, z+22, shield, 9);
		array.setBlock(x+5, y+10, z+23, shield, 13);
		array.setBlock(x+5, y+10, z+24, shield, 13);
		array.setBlock(x+5, y+10, z+25, shield, 13);
		array.setBlock(x+5, y+10, z+26, shield, 13);
		array.setBlock(x+5, y+10, z+27, shield, 13);
		array.setBlock(x+5, y+10, z+28, shield, 13);
		array.setBlock(x+5, y+10, z+29, shield, 13);
		array.setBlock(x+5, y+10, z+30, shield, 9);
		array.setBlock(x+5, y+11, z+0, shield, 9);
		array.setBlock(x+5, y+11, z+1, shield, 9);
		array.setBlock(x+5, y+11, z+2, shield, 9);
		array.setBlock(x+5, y+11, z+3, shield, 9);
		array.setBlock(x+5, y+11, z+4, shield, 9);
		array.setBlock(x+5, y+11, z+5, shield, 9);
		array.setBlock(x+5, y+11, z+6, shield, 9);
		array.setBlock(x+5, y+11, z+7, shield, 9);
		array.setBlock(x+5, y+11, z+8, shield, 9);
		array.setBlock(x+5, y+11, z+9, shield, 9);
		array.setBlock(x+5, y+11, z+10, shield, 9);
		array.setBlock(x+5, y+11, z+11, shield, 9);
		array.setBlock(x+5, y+11, z+12, shield, 9);
		array.setBlock(x+5, y+11, z+13, shield, 9);
		array.setBlock(x+5, y+11, z+14, shield, 9);
		array.setBlock(x+5, y+11, z+22, shield, 9);
		array.setBlock(x+5, y+11, z+23, shield, 9);
		array.setBlock(x+5, y+11, z+24, shield, 9);
		array.setBlock(x+5, y+11, z+25, shield, 9);
		array.setBlock(x+5, y+11, z+26, shield, 9);
		array.setBlock(x+5, y+11, z+27, shield, 9);
		array.setBlock(x+5, y+11, z+28, shield, 9);
		array.setBlock(x+5, y+11, z+29, shield, 9);
		array.setBlock(x+5, y+11, z+30, shield, 9);
		array.setBlock(x+5, y+12, z+1, shield, 9);
		array.setBlock(x+5, y+12, z+2, shield, 9);
		array.setBlock(x+5, y+12, z+3, shield, 9);
		array.setBlock(x+5, y+12, z+4, shield, 9);
		array.setBlock(x+5, y+12, z+5, shield, 9);
		array.setBlock(x+5, y+12, z+14, shield, 9);
		array.setBlock(x+5, y+12, z+15, shield, 9);
		array.setBlock(x+5, y+12, z+16, shield, 9);
		array.setBlock(x+5, y+12, z+17, shield, 9);
		array.setBlock(x+5, y+12, z+18, shield, 9);
		array.setBlock(x+5, y+12, z+19, shield, 9);
		array.setBlock(x+5, y+12, z+20, shield, 9);
		array.setBlock(x+5, y+12, z+21, shield, 9);
		array.setBlock(x+5, y+12, z+22, shield, 9);
		array.setBlock(x+6, y+2, z+22, shield, 9);
		array.setBlock(x+6, y+2, z+23, shield, 9);
		array.setBlock(x+6, y+2, z+24, shield, 9);
		array.setBlock(x+6, y+3, z+9, shield, 9);
		array.setBlock(x+6, y+3, z+20, shield, 9);
		array.setBlock(x+6, y+3, z+21, shield, 9);
		array.setBlock(x+6, y+3, z+25, shield, 9);
		array.setBlock(x+6, y+4, z+9, shield, 9);
		array.setBlock(x+6, y+4, z+20, shield, 9);
		array.setBlock(x+6, y+4, z+21, shield, 9);
		array.setBlock(x+6, y+4, z+25, shield, 9);
		array.setBlock(x+6, y+5, z+9, shield, 9);
		array.setBlock(x+6, y+5, z+20, shield, 9);
		array.setBlock(x+6, y+5, z+21, shield, 9);
		array.setBlock(x+6, y+5, z+25, shield, 9);
		array.setBlock(x+6, y+6, z+22, shield, 9);
		array.setBlock(x+6, y+6, z+23, shield, 9);
		array.setBlock(x+6, y+6, z+24, shield, 9);
		array.setBlock(x+6, y+7, z+1, shield, 9);
		array.setBlock(x+6, y+7, z+2, shield, 9);
		array.setBlock(x+6, y+7, z+3, shield, 9);
		array.setBlock(x+6, y+7, z+4, shield, 9);
		array.setBlock(x+6, y+7, z+5, shield, 9);
		array.setBlock(x+6, y+7, z+14, shield, 9);
		array.setBlock(x+6, y+7, z+15, shield, 9);
		array.setBlock(x+6, y+7, z+16, shield, 9);
		array.setBlock(x+6, y+7, z+17, shield, 9);
		array.setBlock(x+6, y+7, z+18, shield, 9);
		array.setBlock(x+6, y+7, z+19, shield, 9);
		array.setBlock(x+6, y+7, z+20, shield, 9);
		array.setBlock(x+6, y+7, z+21, shield, 9);
		array.setBlock(x+6, y+7, z+22, shield, 9);
		array.setBlock(x+6, y+8, z+1, shield, 9);
		array.setBlock(x+6, y+8, z+5, shield, 9);
		array.setBlock(x+6, y+8, z+14, shield, 9);
		array.setBlock(x+6, y+8, z+15, shield, 9);
		array.setBlock(x+6, y+8, z+16, shield, 9);
		array.setBlock(x+6, y+8, z+17, shield, 9);
		array.setBlock(x+6, y+8, z+18, shield, 9);
		array.setBlock(x+6, y+8, z+19, shield, 9);
		array.setBlock(x+6, y+8, z+20, shield, 9);
		array.setBlock(x+6, y+8, z+21, shield, 9);
		array.setBlock(x+6, y+8, z+22, shield, 9);
		array.setBlock(x+6, y+9, z+1, shield, 13);
		array.setBlock(x+6, y+9, z+5, shield, 13);
		array.setBlock(x+6, y+9, z+14, shield, 9);
		array.setBlock(x+6, y+9, z+15, shield, 13);
		array.setBlock(x+6, y+9, z+16, shield, 13);
		array.setBlock(x+6, y+9, z+17, shield, 13);
		array.setBlock(x+6, y+9, z+18, shield, 13);
		array.setBlock(x+6, y+9, z+19, shield, 13);
		array.setBlock(x+6, y+9, z+20, shield, 13);
		array.setBlock(x+6, y+9, z+21, shield, 13);
		array.setBlock(x+6, y+9, z+22, shield, 9);
		array.setBlock(x+6, y+10, z+1, shield, 13);
		array.setBlock(x+6, y+10, z+5, shield, 13);
		array.setBlock(x+6, y+10, z+14, shield, 9);
		array.setBlock(x+6, y+10, z+15, shield, 13);
		array.setBlock(x+6, y+10, z+16, shield, 13);
		array.setBlock(x+6, y+10, z+17, shield, 13);
		array.setBlock(x+6, y+10, z+18, shield, 13);
		array.setBlock(x+6, y+10, z+19, shield, 13);
		array.setBlock(x+6, y+10, z+20, shield, 13);
		array.setBlock(x+6, y+10, z+21, shield, 13);
		array.setBlock(x+6, y+10, z+22, shield, 9);
		array.setBlock(x+6, y+11, z+1, shield, 9);
		array.setBlock(x+6, y+11, z+2, shield, 13);
		array.setBlock(x+6, y+11, z+3, shield, 13);
		array.setBlock(x+6, y+11, z+4, shield, 13);
		array.setBlock(x+6, y+11, z+5, shield, 9);
		array.setBlock(x+6, y+11, z+14, shield, 9);
		array.setBlock(x+6, y+11, z+15, shield, 9);
		array.setBlock(x+6, y+11, z+16, shield, 9);
		array.setBlock(x+6, y+11, z+17, shield, 9);
		array.setBlock(x+6, y+11, z+18, shield, 9);
		array.setBlock(x+6, y+11, z+19, shield, 9);
		array.setBlock(x+6, y+11, z+20, shield, 9);
		array.setBlock(x+6, y+11, z+21, shield, 9);
		array.setBlock(x+6, y+11, z+22, shield, 9);
		array.setBlock(x+7, y+2, z+9, shield, 9);
		array.setBlock(x+7, y+2, z+21, shield, 9);
		array.setBlock(x+7, y+2, z+22, shield, 9);
		array.setBlock(x+7, y+2, z+23, shield, 9);
		array.setBlock(x+7, y+2, z+24, shield, 9);
		array.setBlock(x+7, y+3, z+10, shield, 9);
		array.setBlock(x+7, y+3, z+11, shield, 9);
		array.setBlock(x+7, y+3, z+12, shield, 9);
		array.setBlock(x+7, y+3, z+13, shield, 9);
		array.setBlock(x+7, y+3, z+14, shield, 9);
		array.setBlock(x+7, y+3, z+15, shield, 9);
		array.setBlock(x+7, y+3, z+16, shield, 9);
		array.setBlock(x+7, y+3, z+17, shield, 9);
		array.setBlock(x+7, y+3, z+18, shield, 9);
		array.setBlock(x+7, y+3, z+19, shield, 9);
		array.setBlock(x+7, y+3, z+20, shield, 9);
		array.setBlock(x+7, y+3, z+25, shield, 9);
		array.setBlock(x+7, y+4, z+10, shield, 9);
		array.setBlock(x+7, y+4, z+11, shield, 9);
		array.setBlock(x+7, y+4, z+12, shield, 9);
		array.setBlock(x+7, y+4, z+13, shield, 9);
		array.setBlock(x+7, y+4, z+14, shield, 9);
		array.setBlock(x+7, y+4, z+15, shield, 9);
		array.setBlock(x+7, y+4, z+16, shield, 9);
		array.setBlock(x+7, y+4, z+17, shield, 9);
		array.setBlock(x+7, y+4, z+18, shield, 9);
		array.setBlock(x+7, y+4, z+19, shield, 9);
		array.setBlock(x+7, y+4, z+20, shield, 9);
		array.setBlock(x+7, y+4, z+25, shield, 9);
		array.setBlock(x+7, y+5, z+10, shield, 9);
		array.setBlock(x+7, y+5, z+11, shield, 9);
		array.setBlock(x+7, y+5, z+12, shield, 9);
		array.setBlock(x+7, y+5, z+13, shield, 9);
		array.setBlock(x+7, y+5, z+14, shield, 9);
		array.setBlock(x+7, y+5, z+15, shield, 9);
		array.setBlock(x+7, y+5, z+16, shield, 9);
		array.setBlock(x+7, y+5, z+17, shield, 9);
		array.setBlock(x+7, y+5, z+18, shield, 9);
		array.setBlock(x+7, y+5, z+19, shield, 9);
		array.setBlock(x+7, y+5, z+20, shield, 9);
		array.setBlock(x+7, y+5, z+25, shield, 9);
		array.setBlock(x+7, y+6, z+9, shield, 9);
		array.setBlock(x+7, y+6, z+21, shield, 9);
		array.setBlock(x+7, y+6, z+22, shield, 9);
		array.setBlock(x+7, y+6, z+23, shield, 9);
		array.setBlock(x+7, y+6, z+24, shield, 9);
		array.setBlock(x+7, y+7, z+1, shield, 9);
		array.setBlock(x+7, y+7, z+2, shield, 9);
		array.setBlock(x+7, y+7, z+3, shield, 9);
		array.setBlock(x+7, y+7, z+4, shield, 9);
		array.setBlock(x+7, y+7, z+5, shield, 9);
		array.setBlock(x+7, y+8, z+1, shield, 9);
		array.setBlock(x+7, y+8, z+5, shield, 9);
		array.setBlock(x+7, y+9, z+1, shield, 13);
		array.setBlock(x+7, y+9, z+5, shield, 13);
		array.setBlock(x+7, y+10, z+1, shield, 13);
		array.setBlock(x+7, y+10, z+5, shield, 13);
		array.setBlock(x+7, y+11, z+1, shield, 9);
		array.setBlock(x+7, y+11, z+2, shield, 13);
		array.setBlock(x+7, y+11, z+3, shield, 13);
		array.setBlock(x+7, y+11, z+4, shield, 13);
		array.setBlock(x+7, y+11, z+5, shield, 9);
		array.setBlock(x+8, y+2, z+8, shield, 9);
		array.setBlock(x+8, y+2, z+9, shield, 9);
		array.setBlock(x+8, y+2, z+10, shield, 9);
		array.setBlock(x+8, y+2, z+11, shield, 9);
		array.setBlock(x+8, y+2, z+12, shield, 9);
		array.setBlock(x+8, y+2, z+13, shield, 9);
		array.setBlock(x+8, y+2, z+14, shield, 9);
		array.setBlock(x+8, y+2, z+15, shield, 9);
		array.setBlock(x+8, y+2, z+16, shield, 9);
		array.setBlock(x+8, y+2, z+17, shield, 9);
		array.setBlock(x+8, y+2, z+18, shield, 9);
		array.setBlock(x+8, y+2, z+19, shield, 9);
		array.setBlock(x+8, y+2, z+20, shield, 9);
		array.setBlock(x+8, y+2, z+21, shield, 9);
		array.setBlock(x+8, y+2, z+22, shield, 9);
		array.setBlock(x+8, y+2, z+23, shield, 9);
		array.setBlock(x+8, y+2, z+24, shield, 9);
		array.setBlock(x+8, y+3, z+10, shield, 9);
		array.setBlock(x+8, y+3, z+17, shield, 9);
		array.setBlock(x+8, y+3, z+19, shield, 9);
		array.setBlock(x+8, y+3, z+20, shield, 9);
		array.setBlock(x+8, y+3, z+25, shield, 9);
		array.setBlock(x+8, y+4, z+10, shield, 9);
		array.setBlock(x+8, y+4, z+17, shield, 9);
		array.setBlock(x+8, y+4, z+18, shield, 9);
		array.setBlock(x+8, y+4, z+19, shield, 9);
		array.setBlock(x+8, y+4, z+25, shield, 9);
		array.setBlock(x+8, y+5, z+10, shield, 9);
		array.setBlock(x+8, y+5, z+17, shield, 9);
		array.setBlock(x+8, y+5, z+18, shield, 9);
		array.setBlock(x+8, y+5, z+25, shield, 9);
		array.setBlock(x+8, y+6, z+8, shield, 9);
		array.setBlock(x+8, y+6, z+9, shield, 9);
		array.setBlock(x+8, y+6, z+10, shield, 9);
		array.setBlock(x+8, y+6, z+11, shield, 9);
		array.setBlock(x+8, y+6, z+12, shield, 9);
		array.setBlock(x+8, y+6, z+13, shield, 9);
		array.setBlock(x+8, y+6, z+14, shield, 9);
		array.setBlock(x+8, y+6, z+15, shield, 9);
		array.setBlock(x+8, y+6, z+16, shield, 9);
		array.setBlock(x+8, y+6, z+17, shield, 9);
		array.setBlock(x+8, y+6, z+18, shield, 9);
		array.setBlock(x+8, y+6, z+19, shield, 9);
		array.setBlock(x+8, y+6, z+20, shield, 9);
		array.setBlock(x+8, y+6, z+21, shield, 9);
		array.setBlock(x+8, y+6, z+22, shield, 9);
		array.setBlock(x+8, y+6, z+23, shield, 9);
		array.setBlock(x+8, y+6, z+24, shield, 9);
		array.setBlock(x+8, y+7, z+1, shield, 9);
		array.setBlock(x+8, y+7, z+2, shield, 9);
		array.setBlock(x+8, y+7, z+3, shield, 9);
		array.setBlock(x+8, y+7, z+4, shield, 9);
		array.setBlock(x+8, y+7, z+5, shield, 9);
		array.setBlock(x+8, y+8, z+1, shield, 9);
		array.setBlock(x+8, y+8, z+5, shield, 9);
		array.setBlock(x+8, y+9, z+1, shield, 13);
		array.setBlock(x+8, y+9, z+5, shield, 13);
		array.setBlock(x+8, y+10, z+1, shield, 13);
		array.setBlock(x+8, y+10, z+5, shield, 13);
		array.setBlock(x+8, y+11, z+1, shield, 9);
		array.setBlock(x+8, y+11, z+2, shield, 13);
		array.setBlock(x+8, y+11, z+3, shield, 13);
		array.setBlock(x+8, y+11, z+4, shield, 13);
		array.setBlock(x+8, y+11, z+5, shield, 9);
		array.setBlock(x+9, y+2, z+7, shield, 9);
		array.setBlock(x+9, y+2, z+8, shield, 9);
		array.setBlock(x+9, y+2, z+9, shield, 9);
		array.setBlock(x+9, y+2, z+10, shield, 9);
		array.setBlock(x+9, y+2, z+11, shield, 9);
		array.setBlock(x+9, y+2, z+12, shield, 9);
		array.setBlock(x+9, y+2, z+13, shield, 9);
		array.setBlock(x+9, y+2, z+14, shield, 9);
		array.setBlock(x+9, y+2, z+15, shield, 9);
		array.setBlock(x+9, y+2, z+16, shield, 9);
		array.setBlock(x+9, y+2, z+17, shield, 9);
		array.setBlock(x+9, y+2, z+18, shield, 9);
		array.setBlock(x+9, y+2, z+19, shield, 9);
		array.setBlock(x+9, y+2, z+20, shield, 9);
		array.setBlock(x+9, y+2, z+21, shield, 9);
		array.setBlock(x+9, y+2, z+22, shield, 9);
		array.setBlock(x+9, y+2, z+23, shield, 9);
		array.setBlock(x+9, y+2, z+24, shield, 9);
		array.setBlock(x+9, y+3, z+6, shield, 9);
		array.setBlock(x+9, y+3, z+13, shield, 9);
		array.setBlock(x+9, y+3, z+17, shield, 9);
		array.setBlock(x+9, y+3, z+18, shield, 9);
		array.setBlock(x+9, y+3, z+19, shield, 9);
		array.setBlock(x+9, y+3, z+25, shield, 9);
		array.setBlock(x+9, y+4, z+6, shield, 9);
		array.setBlock(x+9, y+4, z+13, shield, 9);
		array.setBlock(x+9, y+4, z+17, shield, 9);
		array.setBlock(x+9, y+4, z+18, shield, 9);
		array.setBlock(x+9, y+4, z+25, shield, 9);
		array.setBlock(x+9, y+5, z+6, shield, 9);
		array.setBlock(x+9, y+5, z+13, shield, 9);
		array.setBlock(x+9, y+5, z+17, shield, 9);
		array.setBlock(x+9, y+5, z+25, shield, 9);
		array.setBlock(x+9, y+6, z+7, shield, 9);
		array.setBlock(x+9, y+6, z+8, shield, 9);
		array.setBlock(x+9, y+6, z+9, shield, 9);
		array.setBlock(x+9, y+6, z+10, shield, 9);
		array.setBlock(x+9, y+6, z+11, shield, 9);
		array.setBlock(x+9, y+6, z+12, shield, 9);
		array.setBlock(x+9, y+6, z+13, shield, 9);
		array.setBlock(x+9, y+6, z+14, shield, 9);
		array.setBlock(x+9, y+6, z+15, shield, 9);
		array.setBlock(x+9, y+6, z+16, shield, 9);
		array.setBlock(x+9, y+6, z+17, shield, 9);
		array.setBlock(x+9, y+6, z+18, shield, 9);
		array.setBlock(x+9, y+6, z+19, shield, 9);
		array.setBlock(x+9, y+6, z+20, shield, 9);
		array.setBlock(x+9, y+6, z+21, shield, 9);
		array.setBlock(x+9, y+6, z+22, shield, 9);
		array.setBlock(x+9, y+6, z+23, shield, 9);
		array.setBlock(x+9, y+6, z+24, shield, 9);
		array.setBlock(x+9, y+7, z+1, shield, 9);
		array.setBlock(x+9, y+7, z+2, shield, 9);
		array.setBlock(x+9, y+7, z+3, shield, 9);
		array.setBlock(x+9, y+7, z+4, shield, 9);
		array.setBlock(x+9, y+7, z+5, shield, 9);
		array.setBlock(x+9, y+8, z+1, shield, 9);
		array.setBlock(x+9, y+8, z+5, shield, 9);
		array.setBlock(x+9, y+9, z+1, shield, 13);
		array.setBlock(x+9, y+9, z+5, shield, 13);
		array.setBlock(x+9, y+10, z+1, shield, 13);
		array.setBlock(x+9, y+10, z+5, shield, 13);
		array.setBlock(x+9, y+11, z+1, shield, 9);
		array.setBlock(x+9, y+11, z+2, shield, 13);
		array.setBlock(x+9, y+11, z+3, shield, 13);
		array.setBlock(x+9, y+11, z+4, shield, 13);
		array.setBlock(x+9, y+11, z+5, shield, 9);
		array.setBlock(x+10, y+2, z+8, shield, 9);
		array.setBlock(x+10, y+2, z+9, shield, 9);
		array.setBlock(x+10, y+2, z+10, shield, 9);
		array.setBlock(x+10, y+2, z+11, shield, 9);
		array.setBlock(x+10, y+2, z+12, shield, 9);
		array.setBlock(x+10, y+2, z+13, shield, 9);
		array.setBlock(x+10, y+2, z+14, shield, 9);
		array.setBlock(x+10, y+2, z+15, shield, 9);
		array.setBlock(x+10, y+2, z+16, shield, 9);
		array.setBlock(x+10, y+2, z+17, shield, 9);
		array.setBlock(x+10, y+2, z+18, shield, 9);
		array.setBlock(x+10, y+2, z+19, shield, 9);
		array.setBlock(x+10, y+2, z+20, shield, 9);
		array.setBlock(x+10, y+2, z+21, shield, 9);
		array.setBlock(x+10, y+2, z+22, shield, 9);
		array.setBlock(x+10, y+2, z+23, shield, 9);
		array.setBlock(x+10, y+3, z+7, shield, 9);
		array.setBlock(x+10, y+3, z+8, shield, 9);
		array.setBlock(x+10, y+3, z+11, shield, 9);
		array.setBlock(x+10, y+3, z+13, shield, 9);
		array.setBlock(x+10, y+3, z+17, shield, 9);
		array.setBlock(x+10, y+3, z+18, shield, 9);
		array.setBlock(x+10, y+3, z+24, shield, 9);
		array.setBlock(x+10, y+4, z+7, shield, 9);
		array.setBlock(x+10, y+4, z+8, shield, 9);
		array.setBlock(x+10, y+4, z+11, shield, 9);
		array.setBlock(x+10, y+4, z+13, shield, 9);
		array.setBlock(x+10, y+4, z+17, shield, 9);
		array.setBlock(x+10, y+4, z+24, shield, 9);
		array.setBlock(x+10, y+5, z+7, shield, 9);
		array.setBlock(x+10, y+5, z+8, shield, 9);
		array.setBlock(x+10, y+5, z+11, shield, 9);
		array.setBlock(x+10, y+5, z+13, shield, 9);
		array.setBlock(x+10, y+5, z+17, shield, 9);
		array.setBlock(x+10, y+5, z+24, shield, 9);
		array.setBlock(x+10, y+6, z+8, shield, 9);
		array.setBlock(x+10, y+6, z+9, shield, 9);
		array.setBlock(x+10, y+6, z+10, shield, 9);
		array.setBlock(x+10, y+6, z+11, shield, 9);
		array.setBlock(x+10, y+6, z+12, shield, 9);
		array.setBlock(x+10, y+6, z+13, shield, 9);
		array.setBlock(x+10, y+6, z+14, shield, 9);
		array.setBlock(x+10, y+6, z+15, shield, 9);
		array.setBlock(x+10, y+6, z+16, shield, 9);
		array.setBlock(x+10, y+6, z+17, shield, 9);
		array.setBlock(x+10, y+6, z+18, shield, 9);
		array.setBlock(x+10, y+6, z+19, shield, 9);
		array.setBlock(x+10, y+6, z+20, shield, 9);
		array.setBlock(x+10, y+6, z+21, shield, 9);
		array.setBlock(x+10, y+6, z+22, shield, 9);
		array.setBlock(x+10, y+6, z+23, shield, 9);
		array.setBlock(x+10, y+7, z+1, shield, 9);
		array.setBlock(x+10, y+7, z+2, shield, 9);
		array.setBlock(x+10, y+7, z+3, shield, 9);
		array.setBlock(x+10, y+7, z+4, shield, 9);
		array.setBlock(x+10, y+7, z+5, shield, 9);
		array.setBlock(x+10, y+8, z+1, shield, 9);
		array.setBlock(x+10, y+8, z+5, shield, 9);
		array.setBlock(x+10, y+9, z+1, shield, 13);
		array.setBlock(x+10, y+9, z+5, shield, 13);
		array.setBlock(x+10, y+10, z+1, shield, 13);
		array.setBlock(x+10, y+10, z+5, shield, 13);
		array.setBlock(x+10, y+11, z+1, shield, 9);
		array.setBlock(x+10, y+11, z+2, shield, 13);
		array.setBlock(x+10, y+11, z+3, shield, 13);
		array.setBlock(x+10, y+11, z+4, shield, 13);
		array.setBlock(x+10, y+11, z+5, shield, 9);
		array.setBlock(x+11, y+2, z+8, shield, 9);
		array.setBlock(x+11, y+2, z+9, shield, 9);
		array.setBlock(x+11, y+2, z+10, shield, 9);
		array.setBlock(x+11, y+2, z+11, shield, 9);
		array.setBlock(x+11, y+2, z+12, shield, 9);
		array.setBlock(x+11, y+2, z+13, shield, 9);
		array.setBlock(x+11, y+2, z+14, shield, 9);
		array.setBlock(x+11, y+2, z+15, shield, 9);
		array.setBlock(x+11, y+2, z+16, shield, 9);
		array.setBlock(x+11, y+2, z+17, shield, 9);
		array.setBlock(x+11, y+2, z+18, shield, 9);
		array.setBlock(x+11, y+2, z+19, shield, 9);
		array.setBlock(x+11, y+2, z+20, shield, 9);
		array.setBlock(x+11, y+2, z+21, shield, 9);
		array.setBlock(x+11, y+2, z+22, shield, 9);
		array.setBlock(x+11, y+3, z+7, shield, 9);
		array.setBlock(x+11, y+3, z+10, shield, 9);
		array.setBlock(x+11, y+3, z+11, shield, 9);
		array.setBlock(x+11, y+3, z+13, shield, 9);
		array.setBlock(x+11, y+3, z+14, shield, 9);
		array.setBlock(x+11, y+3, z+15, shield, 9);
		array.setBlock(x+11, y+3, z+16, shield, 9);
		array.setBlock(x+11, y+3, z+17, shield, 9);
		array.setBlock(x+11, y+3, z+23, shield, 9);
		array.setBlock(x+11, y+4, z+7, shield, 9);
		array.setBlock(x+11, y+4, z+10, shield, 9);
		array.setBlock(x+11, y+4, z+11, shield, 9);
		array.setBlock(x+11, y+4, z+13, shield, 9);
		array.setBlock(x+11, y+4, z+14, shield, 9);
		array.setBlock(x+11, y+4, z+15, shield, 9);
		array.setBlock(x+11, y+4, z+16, shield, 9);
		array.setBlock(x+11, y+4, z+17, shield, 9);
		array.setBlock(x+11, y+4, z+23, shield, 9);
		array.setBlock(x+11, y+5, z+7, shield, 9);
		array.setBlock(x+11, y+5, z+10, shield, 9);
		array.setBlock(x+11, y+5, z+11, shield, 9);
		array.setBlock(x+11, y+5, z+13, shield, 9);
		array.setBlock(x+11, y+5, z+14, shield, 9);
		array.setBlock(x+11, y+5, z+15, shield, 9);
		array.setBlock(x+11, y+5, z+16, shield, 9);
		array.setBlock(x+11, y+5, z+17, shield, 9);
		array.setBlock(x+11, y+5, z+23, shield, 9);
		array.setBlock(x+11, y+6, z+8, shield, 9);
		array.setBlock(x+11, y+6, z+9, shield, 9);
		array.setBlock(x+11, y+6, z+10, shield, 9);
		array.setBlock(x+11, y+6, z+11, shield, 9);
		array.setBlock(x+11, y+6, z+12, shield, 9);
		array.setBlock(x+11, y+6, z+13, shield, 9);
		array.setBlock(x+11, y+6, z+14, shield, 9);
		array.setBlock(x+11, y+6, z+15, shield, 9);
		array.setBlock(x+11, y+6, z+16, shield, 9);
		array.setBlock(x+11, y+6, z+17, shield, 9);
		array.setBlock(x+11, y+6, z+18, shield, 9);
		array.setBlock(x+11, y+6, z+19, shield, 9);
		array.setBlock(x+11, y+6, z+20, shield, 9);
		array.setBlock(x+11, y+6, z+21, shield, 9);
		array.setBlock(x+11, y+6, z+22, shield, 9);
		array.setBlock(x+11, y+7, z+1, shield, 9);
		array.setBlock(x+11, y+7, z+2, shield, 9);
		array.setBlock(x+11, y+7, z+3, shield, 9);
		array.setBlock(x+11, y+7, z+4, shield, 9);
		array.setBlock(x+11, y+7, z+5, shield, 9);
		array.setBlock(x+11, y+8, z+1, shield, 9);
		array.setBlock(x+11, y+8, z+5, shield, 9);
		array.setBlock(x+11, y+9, z+1, shield, 13);
		array.setBlock(x+11, y+9, z+5, shield, 13);
		array.setBlock(x+11, y+10, z+1, shield, 13);
		array.setBlock(x+11, y+10, z+5, shield, 13);
		array.setBlock(x+11, y+11, z+1, shield, 9);
		array.setBlock(x+11, y+11, z+2, shield, 13);
		array.setBlock(x+11, y+11, z+3, shield, 13);
		array.setBlock(x+11, y+11, z+4, shield, 13);
		array.setBlock(x+11, y+11, z+5, shield, 9);
		array.setBlock(x+12, y+2, z+8, shield, 9);
		array.setBlock(x+12, y+2, z+9, shield, 9);
		array.setBlock(x+12, y+2, z+10, shield, 9);
		array.setBlock(x+12, y+2, z+11, shield, 9);
		array.setBlock(x+12, y+2, z+12, shield, 9);
		array.setBlock(x+12, y+2, z+13, shield, 9);
		array.setBlock(x+12, y+2, z+14, shield, 9);
		array.setBlock(x+12, y+2, z+15, shield, 9);
		array.setBlock(x+12, y+2, z+16, shield, 9);
		array.setBlock(x+12, y+2, z+17, shield, 9);
		array.setBlock(x+12, y+2, z+18, shield, 9);
		array.setBlock(x+12, y+2, z+19, shield, 9);
		array.setBlock(x+12, y+2, z+20, shield, 9);
		array.setBlock(x+12, y+2, z+21, shield, 9);
		array.setBlock(x+12, y+3, z+7, shield, 9);
		array.setBlock(x+12, y+3, z+15, shield, 9);
		array.setBlock(x+12, y+3, z+22, shield, 9);
		array.setBlock(x+12, y+4, z+7, shield, 9);
		array.setBlock(x+12, y+4, z+15, shield, 9);
		array.setBlock(x+12, y+4, z+22, shield, 9);
		array.setBlock(x+12, y+5, z+7, shield, 9);
		array.setBlock(x+12, y+5, z+15, shield, 9);
		array.setBlock(x+12, y+5, z+22, shield, 9);
		array.setBlock(x+12, y+6, z+8, shield, 9);
		array.setBlock(x+12, y+6, z+9, shield, 9);
		array.setBlock(x+12, y+6, z+10, shield, 9);
		array.setBlock(x+12, y+6, z+11, shield, 9);
		array.setBlock(x+12, y+6, z+12, shield, 9);
		array.setBlock(x+12, y+6, z+13, shield, 9);
		array.setBlock(x+12, y+6, z+14, shield, 9);
		array.setBlock(x+12, y+6, z+15, shield, 9);
		array.setBlock(x+12, y+6, z+16, shield, 9);
		array.setBlock(x+12, y+6, z+17, shield, 9);
		array.setBlock(x+12, y+6, z+18, shield, 9);
		array.setBlock(x+12, y+6, z+19, shield, 9);
		array.setBlock(x+12, y+6, z+20, shield, 9);
		array.setBlock(x+12, y+6, z+21, shield, 9);
		array.setBlock(x+12, y+7, z+1, shield, 9);
		array.setBlock(x+12, y+7, z+2, shield, 9);
		array.setBlock(x+12, y+7, z+3, shield, 9);
		array.setBlock(x+12, y+7, z+4, shield, 9);
		array.setBlock(x+12, y+7, z+5, shield, 9);
		array.setBlock(x+12, y+8, z+1, shield, 9);
		array.setBlock(x+12, y+8, z+5, shield, 9);
		array.setBlock(x+12, y+9, z+1, shield, 13);
		array.setBlock(x+12, y+9, z+5, shield, 13);
		array.setBlock(x+12, y+10, z+1, shield, 13);
		array.setBlock(x+12, y+10, z+5, shield, 13);
		array.setBlock(x+12, y+11, z+1, shield, 9);
		array.setBlock(x+12, y+11, z+2, shield, 13);
		array.setBlock(x+12, y+11, z+3, shield, 13);
		array.setBlock(x+12, y+11, z+4, shield, 13);
		array.setBlock(x+12, y+11, z+5, shield, 9);
		array.setBlock(x+13, y+2, z+8, shield, 9);
		array.setBlock(x+13, y+2, z+9, shield, 9);
		array.setBlock(x+13, y+2, z+10, shield, 9);
		array.setBlock(x+13, y+2, z+11, shield, 9);
		array.setBlock(x+13, y+2, z+12, shield, 9);
		array.setBlock(x+13, y+2, z+13, shield, 9);
		array.setBlock(x+13, y+2, z+14, shield, 9);
		array.setBlock(x+13, y+2, z+15, shield, 9);
		array.setBlock(x+13, y+2, z+16, shield, 9);
		array.setBlock(x+13, y+2, z+17, shield, 9);
		array.setBlock(x+13, y+2, z+18, shield, 9);
		array.setBlock(x+13, y+2, z+19, shield, 9);
		array.setBlock(x+13, y+2, z+20, shield, 9);
		array.setBlock(x+13, y+3, z+7, shield, 9);
		array.setBlock(x+13, y+3, z+9, shield, 9);
		array.setBlock(x+13, y+3, z+10, shield, 9);
		array.setBlock(x+13, y+3, z+11, shield, 9);
		array.setBlock(x+13, y+3, z+15, shield, 9);
		array.setBlock(x+13, y+3, z+21, shield, 9);
		array.setBlock(x+13, y+4, z+7, shield, 9);
		array.setBlock(x+13, y+4, z+9, shield, 9);
		array.setBlock(x+13, y+4, z+10, shield, 9);
		array.setBlock(x+13, y+4, z+11, shield, 9);
		array.setBlock(x+13, y+4, z+15, shield, 9);
		array.setBlock(x+13, y+4, z+21, shield, 9);
		array.setBlock(x+13, y+5, z+7, shield, 9);
		array.setBlock(x+13, y+5, z+9, shield, 9);
		array.setBlock(x+13, y+5, z+10, shield, 9);
		array.setBlock(x+13, y+5, z+11, shield, 9);
		array.setBlock(x+13, y+5, z+15, shield, 9);
		array.setBlock(x+13, y+5, z+21, shield, 9);
		array.setBlock(x+13, y+6, z+8, shield, 9);
		array.setBlock(x+13, y+6, z+9, shield, 9);
		array.setBlock(x+13, y+6, z+10, shield, 9);
		array.setBlock(x+13, y+6, z+11, shield, 9);
		array.setBlock(x+13, y+6, z+12, shield, 9);
		array.setBlock(x+13, y+6, z+13, shield, 9);
		array.setBlock(x+13, y+6, z+14, shield, 9);
		array.setBlock(x+13, y+6, z+15, shield, 9);
		array.setBlock(x+13, y+6, z+16, shield, 9);
		array.setBlock(x+13, y+6, z+17, shield, 9);
		array.setBlock(x+13, y+6, z+18, shield, 9);
		array.setBlock(x+13, y+6, z+19, shield, 9);
		array.setBlock(x+13, y+6, z+20, shield, 9);
		array.setBlock(x+13, y+7, z+1, shield, 9);
		array.setBlock(x+13, y+7, z+2, shield, 9);
		array.setBlock(x+13, y+7, z+3, shield, 9);
		array.setBlock(x+13, y+7, z+4, shield, 9);
		array.setBlock(x+13, y+7, z+5, shield, 9);
		array.setBlock(x+13, y+8, z+1, shield, 9);
		array.setBlock(x+13, y+8, z+5, shield, 9);
		array.setBlock(x+13, y+9, z+1, shield, 13);
		array.setBlock(x+13, y+9, z+5, shield, 13);
		array.setBlock(x+13, y+10, z+1, shield, 13);
		array.setBlock(x+13, y+10, z+5, shield, 13);
		array.setBlock(x+13, y+11, z+1, shield, 9);
		array.setBlock(x+13, y+11, z+2, shield, 13);
		array.setBlock(x+13, y+11, z+3, shield, 13);
		array.setBlock(x+13, y+11, z+4, shield, 13);
		array.setBlock(x+13, y+11, z+5, shield, 9);
		array.setBlock(x+14, y+2, z+8, shield, 9);
		array.setBlock(x+14, y+2, z+9, shield, 9);
		array.setBlock(x+14, y+2, z+10, shield, 9);
		array.setBlock(x+14, y+2, z+11, shield, 9);
		array.setBlock(x+14, y+2, z+12, shield, 9);
		array.setBlock(x+14, y+2, z+13, shield, 9);
		array.setBlock(x+14, y+2, z+14, shield, 9);
		array.setBlock(x+14, y+2, z+15, shield, 9);
		array.setBlock(x+14, y+2, z+16, shield, 9);
		array.setBlock(x+14, y+2, z+17, shield, 9);
		array.setBlock(x+14, y+2, z+18, shield, 9);
		array.setBlock(x+14, y+2, z+19, shield, 9);
		array.setBlock(x+14, y+3, z+7, shield, 9);
		array.setBlock(x+14, y+3, z+11, shield, 9);
		array.setBlock(x+14, y+3, z+20, shield, 9);
		array.setBlock(x+14, y+4, z+7, shield, 9);
		array.setBlock(x+14, y+4, z+11, shield, 9);
		array.setBlock(x+14, y+4, z+20, shield, 9);
		array.setBlock(x+14, y+5, z+7, shield, 9);
		array.setBlock(x+14, y+5, z+11, shield, 9);
		array.setBlock(x+14, y+5, z+20, shield, 9);
		array.setBlock(x+14, y+6, z+8, shield, 9);
		array.setBlock(x+14, y+6, z+9, shield, 9);
		array.setBlock(x+14, y+6, z+10, shield, 9);
		array.setBlock(x+14, y+6, z+11, shield, 9);
		array.setBlock(x+14, y+6, z+12, shield, 9);
		array.setBlock(x+14, y+6, z+13, shield, 9);
		array.setBlock(x+14, y+6, z+14, shield, 9);
		array.setBlock(x+14, y+6, z+15, shield, 9);
		array.setBlock(x+14, y+6, z+16, shield, 9);
		array.setBlock(x+14, y+6, z+17, shield, 9);
		array.setBlock(x+14, y+6, z+18, shield, 9);
		array.setBlock(x+14, y+6, z+19, shield, 9);
		array.setBlock(x+14, y+7, z+0, shield, 9);
		array.setBlock(x+14, y+7, z+1, shield, 9);
		array.setBlock(x+14, y+7, z+2, shield, 9);
		array.setBlock(x+14, y+7, z+3, shield, 9);
		array.setBlock(x+14, y+7, z+4, shield, 9);
		array.setBlock(x+14, y+7, z+5, shield, 9);
		array.setBlock(x+14, y+7, z+6, shield, 9);
		array.setBlock(x+14, y+8, z+0, shield, 9);
		array.setBlock(x+14, y+8, z+1, shield, 9);
		array.setBlock(x+14, y+8, z+5, shield, 9);
		array.setBlock(x+14, y+8, z+6, shield, 9);
		array.setBlock(x+14, y+9, z+0, shield, 9);
		array.setBlock(x+14, y+9, z+1, shield, 9);
		array.setBlock(x+14, y+9, z+5, shield, 9);
		array.setBlock(x+14, y+9, z+6, shield, 9);
		array.setBlock(x+14, y+10, z+0, shield, 9);
		array.setBlock(x+14, y+10, z+1, shield, 9);
		array.setBlock(x+14, y+10, z+5, shield, 9);
		array.setBlock(x+14, y+10, z+6, shield, 9);
		array.setBlock(x+14, y+11, z+0, shield, 9);
		array.setBlock(x+14, y+11, z+1, shield, 9);
		array.setBlock(x+14, y+11, z+2, shield, 9);
		array.setBlock(x+14, y+11, z+3, shield, 9);
		array.setBlock(x+14, y+11, z+4, shield, 9);
		array.setBlock(x+14, y+11, z+5, shield, 9);
		array.setBlock(x+14, y+11, z+6, shield, 9);
		array.setBlock(x+14, y+12, z+1, shield, 9);
		array.setBlock(x+14, y+12, z+2, shield, 9);
		array.setBlock(x+14, y+12, z+3, shield, 9);
		array.setBlock(x+14, y+12, z+4, shield, 9);
		array.setBlock(x+14, y+12, z+5, shield, 9);
		array.setBlock(x+15, y+2, z+8, shield, 9);
		array.setBlock(x+15, y+2, z+9, shield, 9);
		array.setBlock(x+15, y+2, z+10, shield, 9);
		array.setBlock(x+15, y+2, z+11, shield, 9);
		array.setBlock(x+15, y+2, z+12, shield, 9);
		array.setBlock(x+15, y+2, z+13, shield, 9);
		array.setBlock(x+15, y+2, z+14, shield, 9);
		array.setBlock(x+15, y+2, z+15, shield, 9);
		array.setBlock(x+15, y+2, z+16, shield, 9);
		array.setBlock(x+15, y+2, z+17, shield, 9);
		array.setBlock(x+15, y+2, z+18, shield, 9);
		array.setBlock(x+15, y+3, z+7, shield, 9);
		array.setBlock(x+15, y+3, z+11, shield, 9);
		array.setBlock(x+15, y+3, z+12, shield, 9);
		array.setBlock(x+15, y+3, z+13, shield, 9);
		array.setBlock(x+15, y+3, z+19, shield, 9);
		array.setBlock(x+15, y+4, z+7, shield, 9);
		array.setBlock(x+15, y+4, z+11, shield, 9);
		array.setBlock(x+15, y+4, z+12, shield, 9);
		array.setBlock(x+15, y+4, z+13, shield, 9);
		array.setBlock(x+15, y+4, z+19, shield, 9);
		array.setBlock(x+15, y+5, z+7, shield, 9);
		array.setBlock(x+15, y+5, z+11, shield, 9);
		array.setBlock(x+15, y+5, z+12, shield, 9);
		array.setBlock(x+15, y+5, z+13, shield, 9);
		array.setBlock(x+15, y+5, z+19, shield, 9);
		array.setBlock(x+15, y+6, z+8, shield, 9);
		array.setBlock(x+15, y+6, z+9, shield, 9);
		array.setBlock(x+15, y+6, z+10, shield, 9);
		array.setBlock(x+15, y+6, z+11, shield, 9);
		array.setBlock(x+15, y+6, z+12, shield, 9);
		array.setBlock(x+15, y+6, z+13, shield, 9);
		array.setBlock(x+15, y+6, z+14, shield, 9);
		array.setBlock(x+15, y+6, z+15, shield, 9);
		array.setBlock(x+15, y+6, z+16, shield, 9);
		array.setBlock(x+15, y+6, z+17, shield, 9);
		array.setBlock(x+15, y+6, z+18, shield, 9);
		array.setBlock(x+15, y+7, z+0, shield, 9);
		array.setBlock(x+15, y+7, z+1, shield, 9);
		array.setBlock(x+15, y+7, z+2, shield, 9);
		array.setBlock(x+15, y+7, z+3, shield, 9);
		array.setBlock(x+15, y+7, z+4, shield, 9);
		array.setBlock(x+15, y+7, z+5, shield, 9);
		array.setBlock(x+15, y+7, z+6, shield, 9);
		array.setBlock(x+15, y+8, z+0, shield, 9);
		array.setBlock(x+15, y+8, z+6, shield, 9);
		array.setBlock(x+15, y+9, z+0, shield, 13);
		array.setBlock(x+15, y+9, z+6, shield, 13);
		array.setBlock(x+15, y+10, z+0, shield, 13);
		array.setBlock(x+15, y+10, z+6, shield, 13);
		array.setBlock(x+15, y+11, z+0, shield, 9);
		array.setBlock(x+15, y+11, z+6, shield, 9);
		array.setBlock(x+15, y+12, z+1, shield, 9);
		array.setBlock(x+15, y+12, z+2, shield, 13);
		array.setBlock(x+15, y+12, z+3, shield, 13);
		array.setBlock(x+15, y+12, z+4, shield, 13);
		array.setBlock(x+15, y+12, z+5, shield, 9);
		array.setBlock(x+16, y+2, z+8, shield, 9);
		array.setBlock(x+16, y+2, z+9, shield, 9);
		array.setBlock(x+16, y+2, z+10, shield, 9);
		array.setBlock(x+16, y+2, z+11, shield, 9);
		array.setBlock(x+16, y+2, z+12, shield, 9);
		array.setBlock(x+16, y+2, z+13, shield, 9);
		array.setBlock(x+16, y+2, z+14, shield, 9);
		array.setBlock(x+16, y+2, z+15, shield, 9);
		array.setBlock(x+16, y+2, z+16, shield, 9);
		array.setBlock(x+16, y+2, z+17, shield, 9);
		array.setBlock(x+16, y+3, z+7, shield, 9);
		array.setBlock(x+16, y+3, z+11, shield, 9);
		array.setBlock(x+16, y+3, z+18, shield, 9);
		array.setBlock(x+16, y+4, z+7, shield, 9);
		array.setBlock(x+16, y+4, z+11, shield, 9);
		array.setBlock(x+16, y+4, z+18, shield, 9);
		array.setBlock(x+16, y+5, z+7, shield, 9);
		array.setBlock(x+16, y+5, z+11, shield, 9);
		array.setBlock(x+16, y+5, z+18, shield, 9);
		array.setBlock(x+16, y+6, z+1, shield, 9);
		array.setBlock(x+16, y+6, z+2, shield, 9);
		array.setBlock(x+16, y+6, z+3, shield, 9);
		array.setBlock(x+16, y+6, z+4, shield, 9);
		array.setBlock(x+16, y+6, z+5, shield, 9);
		array.setBlock(x+16, y+6, z+8, shield, 9);
		array.setBlock(x+16, y+6, z+9, shield, 9);
		array.setBlock(x+16, y+6, z+10, shield, 9);
		array.setBlock(x+16, y+6, z+11, shield, 9);
		array.setBlock(x+16, y+6, z+12, shield, 9);
		array.setBlock(x+16, y+6, z+13, shield, 9);
		array.setBlock(x+16, y+6, z+14, shield, 9);
		array.setBlock(x+16, y+6, z+15, shield, 9);
		array.setBlock(x+16, y+6, z+16, shield, 9);
		array.setBlock(x+16, y+6, z+17, shield, 9);
		array.setBlock(x+16, y+7, z+0, shield, 9);
		array.setBlock(x+16, y+7, z+1, shield, 9);
		array.setBlock(x+16, y+7, z+5, shield, 9);
		array.setBlock(x+16, y+7, z+6, shield, 9);
		array.setBlock(x+16, y+8, z+0, shield, 9);
		array.setBlock(x+16, y+8, z+6, shield, 9);
		array.setBlock(x+16, y+9, z+0, shield, 13);
		array.setBlock(x+16, y+9, z+6, shield, 13);
		array.setBlock(x+16, y+10, z+0, shield, 13);
		array.setBlock(x+16, y+10, z+6, shield, 13);
		array.setBlock(x+16, y+11, z+0, shield, 9);
		array.setBlock(x+16, y+11, z+6, shield, 9);
		array.setBlock(x+16, y+12, z+1, shield, 9);
		array.setBlock(x+16, y+12, z+2, shield, 13);
		array.setBlock(x+16, y+12, z+3, shield, 13);
		array.setBlock(x+16, y+12, z+4, shield, 13);
		array.setBlock(x+16, y+12, z+5, shield, 9);
		array.setBlock(x+17, y+2, z+8, shield, 9);
		array.setBlock(x+17, y+2, z+9, shield, 9);

		array.setBlock(x+17, y+2, z+10, shield, 9);
		array.setBlock(x+17, y+2, z+11, shield, 9);
		array.setBlock(x+17, y+2, z+12, shield, 9);
		array.setBlock(x+17, y+2, z+13, shield, 9);
		array.setBlock(x+17, y+2, z+14, shield, 9);
		array.setBlock(x+17, y+2, z+15, shield, 9);
		array.setBlock(x+17, y+2, z+16, shield, 9);
		array.setBlock(x+17, y+3, z+7, shield, 9);
		array.setBlock(x+17, y+3, z+8, shield, 9);
		array.setBlock(x+17, y+3, z+9, shield, 9);
		array.setBlock(x+17, y+3, z+10, shield, 9);
		array.setBlock(x+17, y+3, z+11, shield, 9);
		array.setBlock(x+17, y+3, z+17, shield, 9);
		array.setBlock(x+17, y+4, z+7, shield, 9);
		array.setBlock(x+17, y+4, z+8, shield, 9);
		array.setBlock(x+17, y+4, z+9, shield, 9);
		array.setBlock(x+17, y+4, z+10, shield, 9);
		array.setBlock(x+17, y+4, z+11, shield, 9);
		array.setBlock(x+17, y+4, z+17, shield, 9);
		array.setBlock(x+17, y+5, z+1, shield, 9);
		array.setBlock(x+17, y+5, z+2, shield, 9);
		array.setBlock(x+17, y+5, z+3, shield, 9);
		array.setBlock(x+17, y+5, z+4, shield, 9);
		array.setBlock(x+17, y+5, z+5, shield, 9);
		array.setBlock(x+17, y+5, z+7, shield, 9);
		array.setBlock(x+17, y+5, z+8, shield, 9);
		array.setBlock(x+17, y+5, z+9, shield, 9);
		array.setBlock(x+17, y+5, z+10, shield, 9);
		array.setBlock(x+17, y+5, z+11, shield, 9);
		array.setBlock(x+17, y+5, z+17, shield, 9);
		array.setBlock(x+17, y+6, z+1, shield, 9);
		array.setBlock(x+17, y+6, z+5, shield, 9);
		array.setBlock(x+17, y+6, z+8, shield, 9);
		array.setBlock(x+17, y+6, z+9, shield, 9);
		array.setBlock(x+17, y+6, z+10, shield, 9);
		array.setBlock(x+17, y+6, z+11, shield, 9);
		array.setBlock(x+17, y+6, z+12, shield, 9);
		array.setBlock(x+17, y+6, z+13, shield, 9);
		array.setBlock(x+17, y+6, z+14, shield, 9);
		array.setBlock(x+17, y+6, z+15, shield, 9);
		array.setBlock(x+17, y+6, z+16, shield, 9);
		array.setBlock(x+17, y+7, z+0, shield, 9);
		array.setBlock(x+17, y+7, z+1, shield, 9);
		array.setBlock(x+17, y+7, z+5, shield, 9);
		array.setBlock(x+17, y+7, z+6, shield, 9);
		array.setBlock(x+17, y+8, z+0, shield, 9);
		array.setBlock(x+17, y+8, z+6, shield, 9);
		array.setBlock(x+17, y+9, z+0, shield, 13);
		array.setBlock(x+17, y+9, z+6, shield, 13);
		array.setBlock(x+17, y+10, z+0, shield, 13);
		array.setBlock(x+17, y+10, z+6, shield, 13);
		array.setBlock(x+17, y+11, z+0, shield, 9);
		array.setBlock(x+17, y+11, z+6, shield, 9);
		array.setBlock(x+17, y+12, z+1, shield, 9);
		array.setBlock(x+17, y+12, z+2, shield, 13);
		array.setBlock(x+17, y+12, z+3, shield, 13);
		array.setBlock(x+17, y+12, z+4, shield, 13);
		array.setBlock(x+17, y+12, z+5, shield, 9);
		array.setBlock(x+18, y+2, z+8, shield, 9);
		array.setBlock(x+18, y+2, z+9, shield, 9);
		array.setBlock(x+18, y+2, z+10, shield, 9);
		array.setBlock(x+18, y+2, z+11, shield, 9);
		array.setBlock(x+18, y+2, z+12, shield, 9);
		array.setBlock(x+18, y+2, z+13, shield, 9);
		array.setBlock(x+18, y+2, z+14, shield, 9);
		array.setBlock(x+18, y+2, z+15, shield, 9);
		array.setBlock(x+18, y+3, z+7, shield, 9);
		array.setBlock(x+18, y+3, z+9, shield, 9);
		array.setBlock(x+18, y+3, z+10, shield, 9);
		array.setBlock(x+18, y+3, z+16, shield, 9);
		array.setBlock(x+18, y+4, z+1, shield, 9);
		array.setBlock(x+18, y+4, z+2, shield, 9);
		array.setBlock(x+18, y+4, z+3, shield, 9);
		array.setBlock(x+18, y+4, z+4, shield, 9);
		array.setBlock(x+18, y+4, z+5, shield, 9);
		array.setBlock(x+18, y+4, z+7, shield, 9);
		array.setBlock(x+18, y+4, z+8, shield, 9);
		array.setBlock(x+18, y+4, z+9, shield, 9);
		array.setBlock(x+18, y+4, z+16, shield, 9);
		array.setBlock(x+18, y+5, z+1, shield, 9);
		array.setBlock(x+18, y+5, z+5, shield, 9);
		array.setBlock(x+18, y+5, z+7, shield, 9);
		array.setBlock(x+18, y+5, z+8, shield, 9);
		array.setBlock(x+18, y+5, z+16, shield, 9);
		array.setBlock(x+18, y+6, z+1, shield, 9);
		array.setBlock(x+18, y+6, z+5, shield, 9);
		array.setBlock(x+18, y+6, z+8, shield, 9);
		array.setBlock(x+18, y+6, z+9, shield, 9);
		array.setBlock(x+18, y+6, z+10, shield, 9);
		array.setBlock(x+18, y+6, z+11, shield, 9);
		array.setBlock(x+18, y+6, z+12, shield, 9);
		array.setBlock(x+18, y+6, z+13, shield, 9);
		array.setBlock(x+18, y+6, z+14, shield, 9);
		array.setBlock(x+18, y+6, z+15, shield, 9);
		array.setBlock(x+18, y+7, z+0, shield, 9);
		array.setBlock(x+18, y+7, z+1, shield, 9);
		array.setBlock(x+18, y+7, z+5, shield, 9);
		array.setBlock(x+18, y+7, z+6, shield, 9);
		array.setBlock(x+18, y+8, z+0, shield, 9);
		array.setBlock(x+18, y+8, z+6, shield, 9);
		array.setBlock(x+18, y+9, z+0, shield, 13);
		array.setBlock(x+18, y+9, z+6, shield, 13);
		array.setBlock(x+18, y+10, z+0, shield, 13);
		array.setBlock(x+18, y+10, z+6, shield, 13);
		array.setBlock(x+18, y+11, z+0, shield, 9);
		array.setBlock(x+18, y+11, z+6, shield, 9);
		array.setBlock(x+18, y+12, z+1, shield, 9);
		array.setBlock(x+18, y+12, z+2, shield, 13);
		array.setBlock(x+18, y+12, z+3, shield, 13);
		array.setBlock(x+18, y+12, z+4, shield, 13);
		array.setBlock(x+18, y+12, z+5, shield, 9);
		array.setBlock(x+19, y+2, z+8, shield, 9);
		array.setBlock(x+19, y+2, z+9, shield, 9);
		array.setBlock(x+19, y+2, z+10, shield, 9);
		array.setBlock(x+19, y+2, z+11, shield, 9);
		array.setBlock(x+19, y+2, z+12, shield, 9);
		array.setBlock(x+19, y+2, z+13, shield, 9);
		array.setBlock(x+19, y+2, z+14, shield, 9);
		array.setBlock(x+19, y+3, z+1, shield, 9);
		array.setBlock(x+19, y+3, z+2, shield, 9);
		array.setBlock(x+19, y+3, z+3, shield, 9);
		array.setBlock(x+19, y+3, z+4, shield, 9);
		array.setBlock(x+19, y+3, z+5, shield, 9);
		array.setBlock(x+19, y+3, z+7, shield, 9);
		array.setBlock(x+19, y+3, z+8, shield, 9);
		array.setBlock(x+19, y+3, z+9, shield, 9);
		array.setBlock(x+19, y+3, z+15, shield, 9);
		array.setBlock(x+19, y+4, z+1, shield, 9);
		array.setBlock(x+19, y+4, z+5, shield, 9);
		array.setBlock(x+19, y+4, z+7, shield, 9);
		array.setBlock(x+19, y+4, z+8, shield, 9);
		array.setBlock(x+19, y+4, z+15, shield, 9);
		array.setBlock(x+19, y+5, z+1, shield, 9);
		array.setBlock(x+19, y+5, z+5, shield, 9);
		array.setBlock(x+19, y+5, z+7, shield, 9);
		array.setBlock(x+19, y+5, z+15, shield, 9);
		array.setBlock(x+19, y+6, z+1, shield, 9);
		array.setBlock(x+19, y+6, z+5, shield, 9);
		array.setBlock(x+19, y+6, z+8, shield, 9);
		array.setBlock(x+19, y+6, z+9, shield, 9);
		array.setBlock(x+19, y+6, z+10, shield, 9);
		array.setBlock(x+19, y+6, z+11, shield, 9);
		array.setBlock(x+19, y+6, z+12, shield, 9);
		array.setBlock(x+19, y+6, z+13, shield, 9);
		array.setBlock(x+19, y+6, z+14, shield, 9);
		array.setBlock(x+19, y+7, z+0, shield, 9);
		array.setBlock(x+19, y+7, z+1, shield, 9);
		array.setBlock(x+19, y+7, z+5, shield, 9);
		array.setBlock(x+19, y+7, z+6, shield, 9);
		array.setBlock(x+19, y+8, z+0, shield, 9);
		array.setBlock(x+19, y+8, z+6, shield, 9);
		array.setBlock(x+19, y+9, z+0, shield, 13);
		array.setBlock(x+19, y+9, z+6, shield, 13);
		array.setBlock(x+19, y+10, z+0, shield, 13);
		array.setBlock(x+19, y+10, z+6, shield, 13);
		array.setBlock(x+19, y+11, z+0, shield, 9);
		array.setBlock(x+19, y+11, z+6, shield, 9);
		array.setBlock(x+19, y+12, z+1, shield, 9);
		array.setBlock(x+19, y+12, z+2, shield, 13);
		array.setBlock(x+19, y+12, z+3, shield, 13);
		array.setBlock(x+19, y+12, z+4, shield, 13);
		array.setBlock(x+19, y+12, z+5, shield, 9);
		array.setBlock(x+20, y+2, z+2, shield, 9);
		array.setBlock(x+20, y+2, z+3, shield, 9);
		array.setBlock(x+20, y+2, z+4, shield, 9);
		array.setBlock(x+20, y+2, z+8, shield, 9);
		array.setBlock(x+20, y+2, z+9, shield, 9);
		array.setBlock(x+20, y+2, z+10, shield, 9);
		array.setBlock(x+20, y+2, z+11, shield, 9);
		array.setBlock(x+20, y+2, z+12, shield, 9);
		array.setBlock(x+20, y+2, z+13, shield, 9);
		array.setBlock(x+20, y+3, z+1, shield, 9);
		array.setBlock(x+20, y+3, z+5, shield, 9);
		array.setBlock(x+20, y+3, z+6, shield, 9);
		array.setBlock(x+20, y+3, z+7, shield, 9);
		array.setBlock(x+20, y+3, z+8, shield, 9);
		array.setBlock(x+20, y+3, z+14, shield, 9);
		array.setBlock(x+20, y+4, z+1, shield, 9);
		array.setBlock(x+20, y+4, z+5, shield, 9);
		array.setBlock(x+20, y+4, z+6, shield, 9);
		array.setBlock(x+20, y+4, z+7, shield, 9);
		array.setBlock(x+20, y+4, z+14, shield, 9);
		array.setBlock(x+20, y+5, z+1, shield, 9);
		array.setBlock(x+20, y+5, z+5, shield, 9);
		array.setBlock(x+20, y+5, z+6, shield, 9);
		array.setBlock(x+20, y+5, z+7, shield, 9);
		array.setBlock(x+20, y+5, z+14, shield, 9);
		array.setBlock(x+20, y+6, z+1, shield, 9);
		array.setBlock(x+20, y+6, z+5, shield, 9);
		array.setBlock(x+20, y+6, z+8, shield, 9);
		array.setBlock(x+20, y+6, z+9, shield, 9);
		array.setBlock(x+20, y+6, z+10, shield, 9);
		array.setBlock(x+20, y+6, z+11, shield, 9);
		array.setBlock(x+20, y+6, z+12, shield, 9);
		array.setBlock(x+20, y+6, z+13, shield, 9);
		array.setBlock(x+20, y+7, z+0, shield, 9);
		array.setBlock(x+20, y+7, z+1, shield, 9);
		array.setBlock(x+20, y+7, z+5, shield, 9);
		array.setBlock(x+20, y+7, z+6, shield, 9);
		array.setBlock(x+20, y+8, z+0, shield, 9);
		array.setBlock(x+20, y+8, z+6, shield, 9);
		array.setBlock(x+20, y+9, z+0, shield, 13);
		array.setBlock(x+20, y+9, z+6, shield, 13);
		array.setBlock(x+20, y+10, z+0, shield, 13);
		array.setBlock(x+20, y+10, z+6, shield, 13);
		array.setBlock(x+20, y+11, z+0, shield, 9);
		array.setBlock(x+20, y+11, z+6, shield, 9);
		array.setBlock(x+20, y+12, z+1, shield, 9);
		array.setBlock(x+20, y+12, z+2, shield, 13);
		array.setBlock(x+20, y+12, z+3, shield, 13);
		array.setBlock(x+20, y+12, z+4, shield, 13);
		array.setBlock(x+20, y+12, z+5, shield, 9);
		array.setBlock(x+21, y+2, z+2, shield, 9);
		array.setBlock(x+21, y+2, z+3, shield, 9);
		array.setBlock(x+21, y+2, z+4, shield, 9);
		array.setBlock(x+21, y+2, z+7, shield, 9);
		array.setBlock(x+21, y+2, z+8, shield, 9);
		array.setBlock(x+21, y+2, z+9, shield, 9);
		array.setBlock(x+21, y+2, z+10, shield, 9);
		array.setBlock(x+21, y+2, z+11, shield, 9);
		array.setBlock(x+21, y+2, z+12, shield, 9);
		array.setBlock(x+21, y+3, z+1, shield, 9);
		array.setBlock(x+21, y+3, z+5, shield, 9);
		array.setBlock(x+21, y+3, z+6, shield, 9);
		array.setBlock(x+21, y+3, z+13, shield, 9);
		array.setBlock(x+21, y+4, z+1, shield, 9);
		array.setBlock(x+21, y+4, z+5, shield, 9);
		array.setBlock(x+21, y+4, z+6, shield, 9);
		array.setBlock(x+21, y+4, z+13, shield, 9);
		array.setBlock(x+21, y+5, z+1, shield, 9);
		array.setBlock(x+21, y+5, z+5, shield, 9);
		array.setBlock(x+21, y+5, z+6, shield, 9);
		array.setBlock(x+21, y+5, z+13, shield, 9);
		array.setBlock(x+21, y+6, z+1, shield, 9);
		array.setBlock(x+21, y+6, z+5, shield, 9);
		array.setBlock(x+21, y+6, z+7, shield, 9);
		array.setBlock(x+21, y+6, z+8, shield, 9);
		array.setBlock(x+21, y+6, z+9, shield, 9);
		array.setBlock(x+21, y+6, z+10, shield, 9);
		array.setBlock(x+21, y+6, z+11, shield, 9);
		array.setBlock(x+21, y+6, z+12, shield, 9);
		array.setBlock(x+21, y+7, z+0, shield, 9);
		array.setBlock(x+21, y+7, z+1, shield, 9);
		array.setBlock(x+21, y+7, z+2, shield, 9);
		array.setBlock(x+21, y+7, z+3, shield, 9);
		array.setBlock(x+21, y+7, z+4, shield, 9);
		array.setBlock(x+21, y+7, z+5, shield, 9);
		array.setBlock(x+21, y+7, z+6, shield, 9);
		array.setBlock(x+21, y+8, z+0, shield, 9);
		array.setBlock(x+21, y+8, z+6, shield, 9);
		array.setBlock(x+21, y+9, z+0, shield, 13);
		array.setBlock(x+21, y+9, z+6, shield, 13);
		array.setBlock(x+21, y+10, z+0, shield, 13);
		array.setBlock(x+21, y+10, z+6, shield, 13);
		array.setBlock(x+21, y+11, z+0, shield, 9);
		array.setBlock(x+21, y+11, z+6, shield, 9);
		array.setBlock(x+21, y+12, z+1, shield, 9);
		array.setBlock(x+21, y+12, z+2, shield, 13);
		array.setBlock(x+21, y+12, z+3, shield, 13);
		array.setBlock(x+21, y+12, z+4, shield, 13);
		array.setBlock(x+21, y+12, z+5, shield, 9);
		array.setBlock(x+22, y+2, z+2, shield, 9);
		array.setBlock(x+22, y+2, z+3, shield, 9);
		array.setBlock(x+22, y+2, z+4, shield, 9);
		array.setBlock(x+22, y+2, z+5, shield, 9);
		array.setBlock(x+22, y+2, z+6, shield, 9);
		array.setBlock(x+22, y+2, z+7, shield, 9);
		array.setBlock(x+22, y+2, z+8, shield, 9);
		array.setBlock(x+22, y+2, z+9, shield, 9);
		array.setBlock(x+22, y+2, z+10, shield, 9);
		array.setBlock(x+22, y+2, z+11, shield, 9);
		array.setBlock(x+22, y+3, z+1, shield, 9);
		array.setBlock(x+22, y+3, z+12, shield, 9);
		array.setBlock(x+22, y+4, z+1, shield, 9);
		array.setBlock(x+22, y+4, z+12, shield, 9);
		array.setBlock(x+22, y+5, z+1, shield, 9);
		array.setBlock(x+22, y+5, z+12, shield, 9);
		array.setBlock(x+22, y+6, z+1, shield, 9);
		array.setBlock(x+22, y+6, z+2, shield, 9);
		array.setBlock(x+22, y+6, z+3, shield, 9);
		array.setBlock(x+22, y+6, z+4, shield, 9);
		array.setBlock(x+22, y+6, z+5, shield, 9);
		array.setBlock(x+22, y+6, z+6, shield, 9);
		array.setBlock(x+22, y+6, z+7, shield, 9);
		array.setBlock(x+22, y+6, z+8, shield, 9);
		array.setBlock(x+22, y+6, z+9, shield, 9);
		array.setBlock(x+22, y+6, z+10, shield, 9);
		array.setBlock(x+22, y+6, z+11, shield, 9);
		array.setBlock(x+22, y+7, z+0, shield, 9);
		array.setBlock(x+22, y+7, z+1, shield, 9);
		array.setBlock(x+22, y+7, z+2, shield, 9);
		array.setBlock(x+22, y+7, z+3, shield, 9);
		array.setBlock(x+22, y+7, z+4, shield, 9);
		array.setBlock(x+22, y+7, z+5, shield, 9);
		array.setBlock(x+22, y+7, z+6, shield, 9);
		array.setBlock(x+22, y+8, z+0, shield, 9);
		array.setBlock(x+22, y+8, z+1, shield, 9);
		array.setBlock(x+22, y+8, z+5, shield, 9);
		array.setBlock(x+22, y+8, z+6, shield, 9);
		array.setBlock(x+22, y+9, z+0, shield, 9);
		array.setBlock(x+22, y+9, z+1, shield, 9);
		array.setBlock(x+22, y+9, z+5, shield, 9);
		array.setBlock(x+22, y+9, z+6, shield, 9);
		array.setBlock(x+22, y+10, z+0, shield, 9);
		array.setBlock(x+22, y+10, z+1, shield, 9);
		array.setBlock(x+22, y+10, z+5, shield, 9);
		array.setBlock(x+22, y+10, z+6, shield, 9);
		array.setBlock(x+22, y+11, z+0, shield, 9);
		array.setBlock(x+22, y+11, z+1, shield, 9);
		array.setBlock(x+22, y+11, z+2, shield, 9);
		array.setBlock(x+22, y+11, z+3, shield, 9);
		array.setBlock(x+22, y+11, z+4, shield, 9);
		array.setBlock(x+22, y+11, z+5, shield, 9);
		array.setBlock(x+22, y+11, z+6, shield, 9);
		array.setBlock(x+22, y+12, z+1, shield, 9);
		array.setBlock(x+22, y+12, z+2, shield, 9);
		array.setBlock(x+22, y+12, z+3, shield, 9);
		array.setBlock(x+22, y+12, z+4, shield, 9);
		array.setBlock(x+22, y+12, z+5, shield, 9);
		array.setBlock(x+23, y+2, z+2, shield, 9);
		array.setBlock(x+23, y+2, z+3, shield, 9);
		array.setBlock(x+23, y+2, z+4, shield, 9);
		array.setBlock(x+23, y+2, z+5, shield, 9);
		array.setBlock(x+23, y+2, z+6, shield, 9);
		array.setBlock(x+23, y+2, z+7, shield, 9);
		array.setBlock(x+23, y+2, z+8, shield, 9);
		array.setBlock(x+23, y+2, z+9, shield, 9);
		array.setBlock(x+23, y+2, z+10, shield, 9);
		array.setBlock(x+23, y+3, z+1, shield, 9);
		array.setBlock(x+23, y+3, z+11, shield, 9);
		array.setBlock(x+23, y+4, z+1, shield, 9);
		array.setBlock(x+23, y+4, z+11, shield, 9);
		array.setBlock(x+23, y+5, z+1, shield, 9);
		array.setBlock(x+23, y+5, z+11, shield, 9);
		array.setBlock(x+23, y+6, z+1, shield, 9);
		array.setBlock(x+23, y+6, z+2, shield, 9);
		array.setBlock(x+23, y+6, z+3, shield, 9);
		array.setBlock(x+23, y+6, z+4, shield, 9);
		array.setBlock(x+23, y+6, z+5, shield, 9);
		array.setBlock(x+23, y+6, z+6, shield, 9);
		array.setBlock(x+23, y+6, z+7, shield, 9);
		array.setBlock(x+23, y+6, z+8, shield, 9);
		array.setBlock(x+23, y+6, z+9, shield, 9);
		array.setBlock(x+23, y+6, z+10, shield, 9);
		array.setBlock(x+23, y+7, z+1, shield, 9);
		array.setBlock(x+23, y+7, z+2, shield, 9);
		array.setBlock(x+23, y+7, z+3, shield, 9);
		array.setBlock(x+23, y+7, z+4, shield, 9);
		array.setBlock(x+23, y+7, z+5, shield, 9);
		array.setBlock(x+23, y+8, z+1, shield, 9);
		array.setBlock(x+23, y+8, z+5, shield, 9);
		array.setBlock(x+23, y+9, z+1, shield, 13);
		array.setBlock(x+23, y+9, z+5, shield, 13);
		array.setBlock(x+23, y+10, z+1, shield, 13);
		array.setBlock(x+23, y+10, z+5, shield, 13);
		array.setBlock(x+23, y+11, z+1, shield, 9);
		array.setBlock(x+23, y+11, z+2, shield, 13);
		array.setBlock(x+23, y+11, z+3, shield, 13);
		array.setBlock(x+23, y+11, z+4, shield, 13);
		array.setBlock(x+23, y+11, z+5, shield, 9);
		array.setBlock(x+24, y+2, z+2, shield, 9);
		array.setBlock(x+24, y+2, z+3, shield, 9);
		array.setBlock(x+24, y+2, z+4, shield, 9);
		array.setBlock(x+24, y+2, z+5, shield, 9);
		array.setBlock(x+24, y+2, z+6, shield, 9);
		array.setBlock(x+24, y+2, z+7, shield, 9);
		array.setBlock(x+24, y+2, z+8, shield, 9);
		array.setBlock(x+24, y+2, z+9, shield, 9);
		array.setBlock(x+24, y+3, z+1, shield, 9);
		array.setBlock(x+24, y+3, z+10, shield, 9);
		array.setBlock(x+24, y+4, z+1, shield, 9);
		array.setBlock(x+24, y+4, z+10, shield, 9);
		array.setBlock(x+24, y+5, z+1, shield, 9);
		array.setBlock(x+24, y+5, z+10, shield, 9);
		array.setBlock(x+24, y+6, z+1, shield, 9);
		array.setBlock(x+24, y+6, z+2, shield, 9);
		array.setBlock(x+24, y+6, z+3, shield, 9);
		array.setBlock(x+24, y+6, z+4, shield, 9);
		array.setBlock(x+24, y+6, z+5, shield, 9);
		array.setBlock(x+24, y+6, z+6, shield, 9);
		array.setBlock(x+24, y+6, z+7, shield, 9);
		array.setBlock(x+24, y+6, z+8, shield, 9);
		array.setBlock(x+24, y+6, z+9, shield, 9);
		array.setBlock(x+24, y+7, z+1, shield, 9);
		array.setBlock(x+24, y+7, z+2, shield, 9);
		array.setBlock(x+24, y+7, z+3, shield, 9);
		array.setBlock(x+24, y+7, z+4, shield, 9);
		array.setBlock(x+24, y+7, z+5, shield, 9);
		array.setBlock(x+24, y+8, z+1, shield, 9);
		array.setBlock(x+24, y+8, z+5, shield, 9);
		array.setBlock(x+24, y+9, z+1, shield, 13);
		array.setBlock(x+24, y+9, z+5, shield, 13);
		array.setBlock(x+24, y+10, z+1, shield, 13);
		array.setBlock(x+24, y+10, z+5, shield, 13);
		array.setBlock(x+24, y+11, z+1, shield, 9);
		array.setBlock(x+24, y+11, z+2, shield, 13);
		array.setBlock(x+24, y+11, z+3, shield, 13);
		array.setBlock(x+24, y+11, z+4, shield, 13);
		array.setBlock(x+24, y+11, z+5, shield, 9);
		array.setBlock(x+25, y+3, z+2, shield, 9);
		array.setBlock(x+25, y+3, z+3, shield, 9);
		array.setBlock(x+25, y+3, z+4, shield, 9);
		array.setBlock(x+25, y+3, z+5, shield, 9);
		array.setBlock(x+25, y+3, z+6, shield, 9);
		array.setBlock(x+25, y+3, z+7, shield, 9);
		array.setBlock(x+25, y+3, z+8, shield, 9);
		array.setBlock(x+25, y+3, z+9, shield, 9);
		array.setBlock(x+25, y+4, z+2, shield, 9);
		array.setBlock(x+25, y+4, z+3, shield, 9);
		array.setBlock(x+25, y+4, z+4, shield, 9);
		array.setBlock(x+25, y+4, z+5, shield, 9);
		array.setBlock(x+25, y+4, z+6, shield, 9);
		array.setBlock(x+25, y+4, z+7, shield, 9);
		array.setBlock(x+25, y+4, z+8, shield, 9);
		array.setBlock(x+25, y+4, z+9, shield, 9);
		array.setBlock(x+25, y+5, z+2, shield, 9);
		array.setBlock(x+25, y+5, z+3, shield, 9);
		array.setBlock(x+25, y+5, z+4, shield, 9);
		array.setBlock(x+25, y+5, z+5, shield, 9);
		array.setBlock(x+25, y+5, z+6, shield, 9);
		array.setBlock(x+25, y+5, z+7, shield, 9);
		array.setBlock(x+25, y+5, z+8, shield, 9);
		array.setBlock(x+25, y+5, z+9, shield, 9);
		array.setBlock(x+25, y+7, z+1, shield, 9);
		array.setBlock(x+25, y+7, z+2, shield, 9);
		array.setBlock(x+25, y+7, z+3, shield, 9);
		array.setBlock(x+25, y+7, z+4, shield, 9);
		array.setBlock(x+25, y+7, z+5, shield, 9);
		array.setBlock(x+25, y+8, z+1, shield, 9);
		array.setBlock(x+25, y+8, z+5, shield, 9);
		array.setBlock(x+25, y+9, z+1, shield, 13);
		array.setBlock(x+25, y+9, z+5, shield, 13);
		array.setBlock(x+25, y+10, z+1, shield, 13);
		array.setBlock(x+25, y+10, z+5, shield, 13);
		array.setBlock(x+25, y+11, z+1, shield, 9);
		array.setBlock(x+25, y+11, z+2, shield, 13);
		array.setBlock(x+25, y+11, z+3, shield, 13);
		array.setBlock(x+25, y+11, z+4, shield, 13);
		array.setBlock(x+25, y+11, z+5, shield, 9);
		array.setBlock(x+26, y+7, z+1, shield, 9);
		array.setBlock(x+26, y+7, z+2, shield, 9);
		array.setBlock(x+26, y+7, z+3, shield, 9);
		array.setBlock(x+26, y+7, z+4, shield, 9);
		array.setBlock(x+26, y+7, z+5, shield, 9);
		array.setBlock(x+26, y+8, z+1, shield, 9);
		array.setBlock(x+26, y+8, z+5, shield, 9);
		array.setBlock(x+26, y+9, z+1, shield, 13);
		array.setBlock(x+26, y+9, z+5, shield, 13);
		array.setBlock(x+26, y+10, z+1, shield, 13);
		array.setBlock(x+26, y+10, z+5, shield, 13);
		array.setBlock(x+26, y+11, z+1, shield, 9);
		array.setBlock(x+26, y+11, z+2, shield, 13);
		array.setBlock(x+26, y+11, z+3, shield, 13);
		array.setBlock(x+26, y+11, z+4, shield, 13);
		array.setBlock(x+26, y+11, z+5, shield, 9);
		array.setBlock(x+27, y+7, z+1, shield, 9);
		array.setBlock(x+27, y+7, z+2, shield, 9);
		array.setBlock(x+27, y+7, z+3, shield, 9);
		array.setBlock(x+27, y+7, z+4, shield, 9);
		array.setBlock(x+27, y+7, z+5, shield, 9);
		array.setBlock(x+27, y+8, z+1, shield, 9);
		array.setBlock(x+27, y+8, z+5, shield, 9);
		array.setBlock(x+27, y+9, z+1, shield, 13);
		array.setBlock(x+27, y+9, z+5, shield, 13);
		array.setBlock(x+27, y+10, z+1, shield, 13);
		array.setBlock(x+27, y+10, z+5, shield, 13);
		array.setBlock(x+27, y+11, z+1, shield, 9);
		array.setBlock(x+27, y+11, z+2, shield, 13);
		array.setBlock(x+27, y+11, z+3, shield, 13);
		array.setBlock(x+27, y+11, z+4, shield, 13);
		array.setBlock(x+27, y+11, z+5, shield, 9);
		array.setBlock(x+28, y+7, z+1, shield, 9);
		array.setBlock(x+28, y+7, z+2, shield, 9);
		array.setBlock(x+28, y+7, z+3, shield, 9);
		array.setBlock(x+28, y+7, z+4, shield, 9);
		array.setBlock(x+28, y+7, z+5, shield, 9);
		array.setBlock(x+28, y+8, z+1, shield, 9);
		array.setBlock(x+28, y+8, z+5, shield, 9);
		array.setBlock(x+28, y+9, z+1, shield, 13);
		array.setBlock(x+28, y+9, z+5, shield, 13);
		array.setBlock(x+28, y+10, z+1, shield, 13);
		array.setBlock(x+28, y+10, z+5, shield, 13);
		array.setBlock(x+28, y+11, z+1, shield, 9);
		array.setBlock(x+28, y+11, z+2, shield, 13);
		array.setBlock(x+28, y+11, z+3, shield, 13);
		array.setBlock(x+28, y+11, z+4, shield, 13);
		array.setBlock(x+28, y+11, z+5, shield, 9);
		array.setBlock(x+29, y+6, z+2, shield, 9);
		array.setBlock(x+29, y+6, z+3, shield, 9);
		array.setBlock(x+29, y+6, z+4, shield, 9);
		array.setBlock(x+29, y+7, z+1, shield, 9);
		array.setBlock(x+29, y+7, z+5, shield, 9);
		array.setBlock(x+29, y+8, z+1, shield, 9);
		array.setBlock(x+29, y+8, z+5, shield, 9);
		array.setBlock(x+29, y+9, z+1, shield, 13);
		array.setBlock(x+29, y+9, z+5, shield, 13);
		array.setBlock(x+29, y+10, z+1, shield, 13);
		array.setBlock(x+29, y+10, z+5, shield, 13);
		array.setBlock(x+29, y+11, z+1, shield, 9);
		array.setBlock(x+29, y+11, z+2, shield, 13);
		array.setBlock(x+29, y+11, z+3, shield, 13);
		array.setBlock(x+29, y+11, z+4, shield, 13);
		array.setBlock(x+29, y+11, z+5, shield, 9);
		array.setBlock(x+30, y+7, z+1, shield, 9);
		array.setBlock(x+30, y+7, z+2, shield, 9);
		array.setBlock(x+30, y+7, z+3, shield, 9);
		array.setBlock(x+30, y+7, z+4, shield, 9);
		array.setBlock(x+30, y+7, z+5, shield, 9);
		array.setBlock(x+30, y+8, z+1, shield, 9);
		array.setBlock(x+30, y+8, z+5, shield, 9);
		array.setBlock(x+30, y+9, z+1, shield, 9);
		array.setBlock(x+30, y+9, z+5, shield, 9);
		array.setBlock(x+30, y+10, z+1, shield, 9);
		array.setBlock(x+30, y+10, z+5, shield, 9);
		array.setBlock(x+30, y+11, z+1, shield, 9);
		array.setBlock(x+30, y+11, z+2, shield, 9);
		array.setBlock(x+30, y+11, z+3, shield, 9);
		array.setBlock(x+30, y+11, z+4, shield, 9);
		array.setBlock(x+30, y+11, z+5, shield, 9);

		array.setBlock(x+18, y+3, z+8, Blocks.mob_spawner);
		array.setBlock(x+8, y+3, z+18, Blocks.mob_spawner);
		this.cache(x+18, y+3, z+8, Blocks.mob_spawner);
		this.cache(x+8, y+3, z+18, Blocks.mob_spawner);

		array.setBlock(x+3, y+8, z+3, Blocks.torch, 5);

		this.addAir(array, x, y, z);

		this.addEndCaps(array, x, y, z, shield);

		return array;
	}

	private void addAir(FilledBlockArray array, int x, int y, int z) {
		array.setBlock(x+1, y+3, z+2, Blocks.air);
		array.setBlock(x+1, y+3, z+4, Blocks.air);
		array.setBlock(x+1, y+4, z+2, Blocks.air);
		array.setBlock(x+1, y+4, z+4, Blocks.air);
		array.setBlock(x+1, y+5, z+2, Blocks.air);
		array.setBlock(x+1, y+5, z+3, Blocks.air);
		array.setBlock(x+1, y+5, z+4, Blocks.air);
		array.setBlock(x+1, y+8, z+2, Blocks.air);
		array.setBlock(x+1, y+8, z+4, Blocks.air);
		array.setBlock(x+1, y+8, z+15, Blocks.air);
		array.setBlock(x+1, y+8, z+16, Blocks.air);
		array.setBlock(x+1, y+8, z+17, Blocks.air);
		array.setBlock(x+1, y+8, z+18, Blocks.air);
		array.setBlock(x+1, y+8, z+19, Blocks.air);
		array.setBlock(x+1, y+8, z+20, Blocks.air);
		array.setBlock(x+1, y+8, z+21, Blocks.air);
		array.setBlock(x+1, y+9, z+2, Blocks.air);
		array.setBlock(x+1, y+9, z+3, Blocks.air);
		array.setBlock(x+1, y+9, z+4, Blocks.air);
		array.setBlock(x+1, y+9, z+15, Blocks.air);
		array.setBlock(x+1, y+9, z+16, Blocks.air);
		array.setBlock(x+1, y+9, z+17, Blocks.air);
		array.setBlock(x+1, y+9, z+18, Blocks.air);
		array.setBlock(x+1, y+9, z+19, Blocks.air);
		array.setBlock(x+1, y+9, z+20, Blocks.air);
		array.setBlock(x+1, y+9, z+21, Blocks.air);
		array.setBlock(x+1, y+10, z+2, Blocks.air);
		array.setBlock(x+1, y+10, z+3, Blocks.air);
		array.setBlock(x+1, y+10, z+4, Blocks.air);
		array.setBlock(x+1, y+10, z+15, Blocks.air);
		array.setBlock(x+1, y+10, z+16, Blocks.air);
		array.setBlock(x+1, y+10, z+17, Blocks.air);
		array.setBlock(x+1, y+10, z+18, Blocks.air);
		array.setBlock(x+1, y+10, z+19, Blocks.air);
		array.setBlock(x+1, y+10, z+20, Blocks.air);
		array.setBlock(x+1, y+10, z+21, Blocks.air);
		array.setBlock(x+1, y+11, z+2, Blocks.air);
		array.setBlock(x+1, y+11, z+3, Blocks.air);
		array.setBlock(x+1, y+11, z+4, Blocks.air);
		array.setBlock(x+1, y+11, z+15, Blocks.air);
		array.setBlock(x+1, y+11, z+16, Blocks.air);
		array.setBlock(x+1, y+11, z+17, Blocks.air);
		array.setBlock(x+1, y+11, z+18, Blocks.air);
		array.setBlock(x+1, y+11, z+19, Blocks.air);
		array.setBlock(x+1, y+11, z+20, Blocks.air);
		array.setBlock(x+1, y+11, z+21, Blocks.air);
		array.setBlock(x+2, y+1, z+2, Blocks.air);
		array.setBlock(x+2, y+1, z+3, Blocks.air);
		array.setBlock(x+2, y+1, z+4, Blocks.air);
		array.setBlock(x+2, y+2, z+2, Blocks.air);
		array.setBlock(x+2, y+2, z+3, Blocks.air);
		array.setBlock(x+2, y+2, z+4, Blocks.air);
		array.setBlock(x+2, y+3, z+1, Blocks.air);
		array.setBlock(x+2, y+3, z+2, Blocks.air);
		array.setBlock(x+2, y+3, z+3, Blocks.air);
		array.setBlock(x+2, y+3, z+4, Blocks.air);
		array.setBlock(x+2, y+3, z+20, Blocks.air);
		array.setBlock(x+2, y+3, z+21, Blocks.air);
		array.setBlock(x+2, y+3, z+22, Blocks.air);
		array.setBlock(x+2, y+3, z+23, Blocks.air);
		array.setBlock(x+2, y+3, z+24, Blocks.air);
		array.setBlock(x+2, y+4, z+1, Blocks.air);
		array.setBlock(x+2, y+4, z+2, Blocks.air);
		array.setBlock(x+2, y+4, z+3, Blocks.air);
		array.setBlock(x+2, y+4, z+4, Blocks.air);
		array.setBlock(x+2, y+4, z+19, Blocks.air);
		array.setBlock(x+2, y+4, z+20, Blocks.air);
		array.setBlock(x+2, y+4, z+21, Blocks.air);
		array.setBlock(x+2, y+4, z+22, Blocks.air);
		array.setBlock(x+2, y+4, z+23, Blocks.air);
		array.setBlock(x+2, y+4, z+24, Blocks.air);
		array.setBlock(x+2, y+5, z+1, Blocks.air);
		array.setBlock(x+2, y+5, z+2, Blocks.air);
		array.setBlock(x+2, y+5, z+3, Blocks.air);
		array.setBlock(x+2, y+5, z+4, Blocks.air);
		array.setBlock(x+2, y+5, z+18, Blocks.air);
		array.setBlock(x+2, y+5, z+19, Blocks.air);
		array.setBlock(x+2, y+5, z+20, Blocks.air);
		array.setBlock(x+2, y+5, z+21, Blocks.air);
		array.setBlock(x+2, y+5, z+22, Blocks.air);
		array.setBlock(x+2, y+5, z+23, Blocks.air);
		array.setBlock(x+2, y+5, z+24, Blocks.air);
		array.setBlock(x+2, y+6, z+17, Blocks.air);
		array.setBlock(x+2, y+6, z+18, Blocks.air);
		array.setBlock(x+2, y+6, z+19, Blocks.air);
		array.setBlock(x+2, y+6, z+20, Blocks.air);
		array.setBlock(x+2, y+6, z+21, Blocks.air);
		array.setBlock(x+2, y+7, z+29, Blocks.air);
		array.setBlock(x+2, y+8, z+1, Blocks.air);
		array.setBlock(x+2, y+8, z+2, Blocks.air);
		array.setBlock(x+2, y+8, z+3, Blocks.air);
		array.setBlock(x+2, y+8, z+4, Blocks.air);
		array.setBlock(x+2, y+8, z+5, Blocks.air);
		array.setBlock(x+2, y+8, z+6, Blocks.air);
		array.setBlock(x+2, y+8, z+7, Blocks.air);
		array.setBlock(x+2, y+8, z+8, Blocks.air);
		array.setBlock(x+2, y+8, z+9, Blocks.air);
		array.setBlock(x+2, y+8, z+10, Blocks.air);
		array.setBlock(x+2, y+8, z+11, Blocks.air);
		array.setBlock(x+2, y+8, z+12, Blocks.air);
		array.setBlock(x+2, y+8, z+13, Blocks.air);
		array.setBlock(x+2, y+8, z+14, Blocks.air);
		array.setBlock(x+2, y+8, z+15, Blocks.air);
		array.setBlock(x+2, y+8, z+16, Blocks.air);
		array.setBlock(x+2, y+8, z+17, Blocks.air);
		array.setBlock(x+2, y+8, z+18, Blocks.air);
		array.setBlock(x+2, y+8, z+19, Blocks.air);
		array.setBlock(x+2, y+8, z+20, Blocks.air);
		array.setBlock(x+2, y+8, z+21, Blocks.air);
		array.setBlock(x+2, y+8, z+22, Blocks.air);
		array.setBlock(x+2, y+8, z+23, Blocks.air);
		array.setBlock(x+2, y+8, z+24, Blocks.air);
		array.setBlock(x+2, y+8, z+25, Blocks.air);
		array.setBlock(x+2, y+8, z+26, Blocks.air);
		array.setBlock(x+2, y+8, z+27, Blocks.air);
		array.setBlock(x+2, y+8, z+28, Blocks.air);
		array.setBlock(x+2, y+8, z+29, Blocks.air);
		array.setBlock(x+2, y+9, z+1, Blocks.air);
		array.setBlock(x+2, y+9, z+2, Blocks.air);
		array.setBlock(x+2, y+9, z+3, Blocks.air);
		array.setBlock(x+2, y+9, z+4, Blocks.air);
		array.setBlock(x+2, y+9, z+5, Blocks.air);
		array.setBlock(x+2, y+9, z+6, Blocks.air);
		array.setBlock(x+2, y+9, z+7, Blocks.air);
		array.setBlock(x+2, y+9, z+8, Blocks.air);
		array.setBlock(x+2, y+9, z+9, Blocks.air);
		array.setBlock(x+2, y+9, z+10, Blocks.air);
		array.setBlock(x+2, y+9, z+11, Blocks.air);
		array.setBlock(x+2, y+9, z+12, Blocks.air);
		array.setBlock(x+2, y+9, z+13, Blocks.air);
		array.setBlock(x+2, y+9, z+14, Blocks.air);
		array.setBlock(x+2, y+9, z+15, Blocks.air);
		array.setBlock(x+2, y+9, z+16, Blocks.air);
		array.setBlock(x+2, y+9, z+17, Blocks.air);
		array.setBlock(x+2, y+9, z+18, Blocks.air);
		array.setBlock(x+2, y+9, z+19, Blocks.air);
		array.setBlock(x+2, y+9, z+20, Blocks.air);
		array.setBlock(x+2, y+9, z+21, Blocks.air);
		array.setBlock(x+2, y+9, z+22, Blocks.air);
		array.setBlock(x+2, y+9, z+23, Blocks.air);
		array.setBlock(x+2, y+9, z+24, Blocks.air);
		array.setBlock(x+2, y+9, z+25, Blocks.air);
		array.setBlock(x+2, y+9, z+26, Blocks.air);
		array.setBlock(x+2, y+9, z+27, Blocks.air);
		array.setBlock(x+2, y+9, z+28, Blocks.air);
		array.setBlock(x+2, y+9, z+29, Blocks.air);
		array.setBlock(x+2, y+10, z+1, Blocks.air);
		array.setBlock(x+2, y+10, z+2, Blocks.air);
		array.setBlock(x+2, y+10, z+3, Blocks.air);
		array.setBlock(x+2, y+10, z+4, Blocks.air);
		array.setBlock(x+2, y+10, z+5, Blocks.air);
		array.setBlock(x+2, y+10, z+6, Blocks.air);
		array.setBlock(x+2, y+10, z+7, Blocks.air);
		array.setBlock(x+2, y+10, z+8, Blocks.air);
		array.setBlock(x+2, y+10, z+9, Blocks.air);
		array.setBlock(x+2, y+10, z+10, Blocks.air);
		array.setBlock(x+2, y+10, z+11, Blocks.air);
		array.setBlock(x+2, y+10, z+12, Blocks.air);
		array.setBlock(x+2, y+10, z+13, Blocks.air);
		array.setBlock(x+2, y+10, z+14, Blocks.air);
		array.setBlock(x+2, y+10, z+15, Blocks.air);
		array.setBlock(x+2, y+10, z+16, Blocks.air);
		array.setBlock(x+2, y+10, z+17, Blocks.air);
		array.setBlock(x+2, y+10, z+18, Blocks.air);
		array.setBlock(x+2, y+10, z+19, Blocks.air);
		array.setBlock(x+2, y+10, z+20, Blocks.air);
		array.setBlock(x+2, y+10, z+21, Blocks.air);
		array.setBlock(x+2, y+10, z+22, Blocks.air);
		array.setBlock(x+2, y+10, z+23, Blocks.air);
		array.setBlock(x+2, y+10, z+24, Blocks.air);
		array.setBlock(x+2, y+10, z+25, Blocks.air);
		array.setBlock(x+2, y+10, z+26, Blocks.air);
		array.setBlock(x+2, y+10, z+27, Blocks.air);
		array.setBlock(x+2, y+10, z+28, Blocks.air);
		array.setBlock(x+2, y+10, z+29, Blocks.air);
		array.setBlock(x+2, y+11, z+1, Blocks.air);
		array.setBlock(x+2, y+11, z+2, Blocks.air);
		array.setBlock(x+2, y+11, z+3, Blocks.air);
		array.setBlock(x+2, y+11, z+4, Blocks.air);
		array.setBlock(x+2, y+11, z+15, Blocks.air);
		array.setBlock(x+2, y+11, z+16, Blocks.air);
		array.setBlock(x+2, y+11, z+17, Blocks.air);
		array.setBlock(x+2, y+11, z+18, Blocks.air);
		array.setBlock(x+2, y+11, z+19, Blocks.air);
		array.setBlock(x+2, y+11, z+20, Blocks.air);
		array.setBlock(x+2, y+11, z+21, Blocks.air);
		array.setBlock(x+3, y+1, z+2, Blocks.air);
		array.setBlock(x+3, y+1, z+3, Blocks.air);
		array.setBlock(x+3, y+1, z+4, Blocks.air);
		array.setBlock(x+3, y+2, z+2, Blocks.air);
		array.setBlock(x+3, y+2, z+3, Blocks.air);
		array.setBlock(x+3, y+2, z+4, Blocks.air);
		array.setBlock(x+3, y+3, z+2, Blocks.air);
		array.setBlock(x+3, y+3, z+3, Blocks.air);
		array.setBlock(x+3, y+3, z+4, Blocks.air);
		array.setBlock(x+3, y+3, z+5, Blocks.air);
		array.setBlock(x+3, y+3, z+20, Blocks.air);
		array.setBlock(x+3, y+3, z+21, Blocks.air);
		array.setBlock(x+3, y+3, z+22, Blocks.air);
		array.setBlock(x+3, y+3, z+23, Blocks.air);
		array.setBlock(x+3, y+3, z+24, Blocks.air);
		array.setBlock(x+3, y+4, z+2, Blocks.air);
		array.setBlock(x+3, y+4, z+3, Blocks.air);
		array.setBlock(x+3, y+4, z+4, Blocks.air);
		array.setBlock(x+3, y+4, z+5, Blocks.air);
		array.setBlock(x+3, y+4, z+19, Blocks.air);
		array.setBlock(x+3, y+4, z+20, Blocks.air);
		array.setBlock(x+3, y+4, z+21, Blocks.air);
		array.setBlock(x+3, y+4, z+22, Blocks.air);
		array.setBlock(x+3, y+4, z+23, Blocks.air);
		array.setBlock(x+3, y+4, z+24, Blocks.air);
		array.setBlock(x+3, y+5, z+1, Blocks.air);
		array.setBlock(x+3, y+5, z+2, Blocks.air);
		array.setBlock(x+3, y+5, z+4, Blocks.air);
		array.setBlock(x+3, y+5, z+5, Blocks.air);
		array.setBlock(x+3, y+5, z+18, Blocks.air);
		array.setBlock(x+3, y+5, z+19, Blocks.air);
		array.setBlock(x+3, y+5, z+20, Blocks.air);
		array.setBlock(x+3, y+5, z+21, Blocks.air);
		array.setBlock(x+3, y+5, z+22, Blocks.air);
		array.setBlock(x+3, y+5, z+23, Blocks.air);
		array.setBlock(x+3, y+5, z+24, Blocks.air);
		array.setBlock(x+3, y+6, z+17, Blocks.air);
		array.setBlock(x+3, y+6, z+18, Blocks.air);
		array.setBlock(x+3, y+6, z+19, Blocks.air);
		array.setBlock(x+3, y+6, z+20, Blocks.air);
		array.setBlock(x+3, y+6, z+21, Blocks.air);
		array.setBlock(x+3, y+7, z+29, Blocks.air);
		array.setBlock(x+3, y+8, z+2, Blocks.air);
		array.setBlock(x+3, y+8, z+4, Blocks.air);
		array.setBlock(x+3, y+8, z+5, Blocks.air);
		array.setBlock(x+3, y+8, z+6, Blocks.air);
		array.setBlock(x+3, y+8, z+7, Blocks.air);
		array.setBlock(x+3, y+8, z+8, Blocks.air);
		array.setBlock(x+3, y+8, z+9, Blocks.air);
		array.setBlock(x+3, y+8, z+10, Blocks.air);
		array.setBlock(x+3, y+8, z+11, Blocks.air);
		array.setBlock(x+3, y+8, z+12, Blocks.air);
		array.setBlock(x+3, y+8, z+13, Blocks.air);
		array.setBlock(x+3, y+8, z+14, Blocks.air);
		array.setBlock(x+3, y+8, z+15, Blocks.air);
		array.setBlock(x+3, y+8, z+16, Blocks.air);
		array.setBlock(x+3, y+8, z+17, Blocks.air);
		array.setBlock(x+3, y+8, z+18, Blocks.air);
		array.setBlock(x+3, y+8, z+19, Blocks.air);
		array.setBlock(x+3, y+8, z+20, Blocks.air);
		array.setBlock(x+3, y+8, z+21, Blocks.air);
		array.setBlock(x+3, y+8, z+22, Blocks.air);
		array.setBlock(x+3, y+8, z+23, Blocks.air);
		array.setBlock(x+3, y+8, z+24, Blocks.air);
		array.setBlock(x+3, y+8, z+25, Blocks.air);
		array.setBlock(x+3, y+8, z+26, Blocks.air);
		array.setBlock(x+3, y+8, z+27, Blocks.air);
		array.setBlock(x+3, y+8, z+28, Blocks.air);
		array.setBlock(x+3, y+8, z+29, Blocks.air);
		array.setBlock(x+3, y+9, z+1, Blocks.air);
		array.setBlock(x+3, y+9, z+2, Blocks.air);
		array.setBlock(x+3, y+9, z+3, Blocks.air);
		array.setBlock(x+3, y+9, z+4, Blocks.air);
		array.setBlock(x+3, y+9, z+5, Blocks.air);
		array.setBlock(x+3, y+9, z+6, Blocks.air);
		array.setBlock(x+3, y+9, z+7, Blocks.air);
		array.setBlock(x+3, y+9, z+8, Blocks.air);
		array.setBlock(x+3, y+9, z+9, Blocks.air);
		array.setBlock(x+3, y+9, z+10, Blocks.air);
		array.setBlock(x+3, y+9, z+11, Blocks.air);
		array.setBlock(x+3, y+9, z+12, Blocks.air);
		array.setBlock(x+3, y+9, z+13, Blocks.air);
		array.setBlock(x+3, y+9, z+14, Blocks.air);
		array.setBlock(x+3, y+9, z+15, Blocks.air);
		array.setBlock(x+3, y+9, z+16, Blocks.air);
		array.setBlock(x+3, y+9, z+17, Blocks.air);
		array.setBlock(x+3, y+9, z+18, Blocks.air);
		array.setBlock(x+3, y+9, z+19, Blocks.air);
		array.setBlock(x+3, y+9, z+20, Blocks.air);
		array.setBlock(x+3, y+9, z+21, Blocks.air);
		array.setBlock(x+3, y+9, z+22, Blocks.air);
		array.setBlock(x+3, y+9, z+23, Blocks.air);
		array.setBlock(x+3, y+9, z+24, Blocks.air);
		array.setBlock(x+3, y+9, z+25, Blocks.air);
		array.setBlock(x+3, y+9, z+26, Blocks.air);
		array.setBlock(x+3, y+9, z+27, Blocks.air);
		array.setBlock(x+3, y+9, z+28, Blocks.air);
		array.setBlock(x+3, y+9, z+29, Blocks.air);
		array.setBlock(x+3, y+10, z+1, Blocks.air);
		array.setBlock(x+3, y+10, z+2, Blocks.air);
		array.setBlock(x+3, y+10, z+3, Blocks.air);
		array.setBlock(x+3, y+10, z+4, Blocks.air);
		array.setBlock(x+3, y+10, z+5, Blocks.air);
		array.setBlock(x+3, y+10, z+6, Blocks.air);
		array.setBlock(x+3, y+10, z+7, Blocks.air);
		array.setBlock(x+3, y+10, z+8, Blocks.air);
		array.setBlock(x+3, y+10, z+9, Blocks.air);
		array.setBlock(x+3, y+10, z+10, Blocks.air);
		array.setBlock(x+3, y+10, z+11, Blocks.air);
		array.setBlock(x+3, y+10, z+12, Blocks.air);
		array.setBlock(x+3, y+10, z+13, Blocks.air);
		array.setBlock(x+3, y+10, z+14, Blocks.air);
		array.setBlock(x+3, y+10, z+15, Blocks.air);
		array.setBlock(x+3, y+10, z+16, Blocks.air);
		array.setBlock(x+3, y+10, z+17, Blocks.air);
		array.setBlock(x+3, y+10, z+18, Blocks.air);
		array.setBlock(x+3, y+10, z+19, Blocks.air);
		array.setBlock(x+3, y+10, z+20, Blocks.air);
		array.setBlock(x+3, y+10, z+21, Blocks.air);
		array.setBlock(x+3, y+10, z+22, Blocks.air);
		array.setBlock(x+3, y+10, z+23, Blocks.air);
		array.setBlock(x+3, y+10, z+24, Blocks.air);
		array.setBlock(x+3, y+10, z+25, Blocks.air);
		array.setBlock(x+3, y+10, z+26, Blocks.air);
		array.setBlock(x+3, y+10, z+27, Blocks.air);
		array.setBlock(x+3, y+10, z+28, Blocks.air);
		array.setBlock(x+3, y+10, z+29, Blocks.air);
		array.setBlock(x+3, y+11, z+1, Blocks.air);
		array.setBlock(x+3, y+11, z+2, Blocks.air);
		array.setBlock(x+3, y+11, z+3, Blocks.air);
		array.setBlock(x+3, y+11, z+4, Blocks.air);
		array.setBlock(x+3, y+11, z+15, Blocks.air);
		array.setBlock(x+3, y+11, z+16, Blocks.air);
