/*******************************************************************************
 * @author Reika Kalseki
 *
 * Copyright 2017
 *
 * All rights reserved.
 * Distribution of the software in any form is only allowed with
 * explicit, prior permission from the owner.
 ******************************************************************************/
package Reika.ChromatiCraft.Auxiliary.Structure.Worldgen;

import java.util.ArrayList;
import java.util.Collection;
import java.util.Random;

import net.minecraft.block.Block;
import net.minecraft.init.Blocks;
import net.minecraft.world.World;
import net.minecraftforge.common.util.ForgeDirection;

import Reika.ChromatiCraft.Base.FragmentStructureBase;
import Reika.ChromatiCraft.Block.Dimension.Structure.ShiftMaze.BlockShiftLock.Passability;
import Reika.ChromatiCraft.Block.Worldgen.BlockStructureShield.BlockType;
import Reika.ChromatiCraft.Registry.ChromaBlocks;
import Reika.DragonAPI.ModList;
import Reika.DragonAPI.ASM.DependentMethodStripper.ModDependent;
import Reika.DragonAPI.Instantiable.Data.BlockStruct.FilledBlockArray;
import Reika.DragonAPI.Instantiable.Data.Immutable.BlockKey;
import Reika.DragonAPI.Instantiable.Data.Immutable.Coordinate;
import Reika.GeoStrata.Blocks.BlockLavaRock;
import Reika.GeoStrata.Registry.GeoBlocks;


public class SnowStructure extends FragmentStructureBase {

	private static final Block b2 = ChromaBlocks.TRAPFLOOR.getBlockInstance();
	private static final int ms = BlockType.STONE.metadata;
	private static final int mc = BlockType.COBBLE.metadata;
	private static final int mg = BlockType.GLASS.metadata;

	private static final int mcrack = ms;

	public static Collection<Coordinate> getCrackToCenter() {
		Collection<Coordinate> li = new ArrayList();
		li.add(new Coordinate(9, 5, 7));
		li.add(new Coordinate(9, 5, 8));
		li.add(new Coordinate(9, 5, 9));
		li.add(new Coordinate(9, 5, 10));
		li.add(new Coordinate(8, 5, 7));
		li.add(new Coordinate(8, 5, 8));
		li.add(new Coordinate(8, 5, 9));
		li.add(new Coordinate(8, 5, 10));
		//li.add(new Coordinate(8, 6, 10));
		li.add(new Coordinate(7, 5, 7));
		li.add(new Coordinate(7, 5, 8));
		li.add(new Coordinate(7, 5, 9));
		li.add(new Coordinate(7, 5, 10));
		//li.add(new Coordinate(7, 6, 10));
		//li.add(new Coordinate(7, 7, 10));
		//li.add(new Coordinate(7, 8, 10));
		//li.add(new Coordinate(8, 7, 10));
		//li.add(new Coordinate(8, 8, 10));
		//li.add(new Coordinate(9, 6, 10));
		//li.add(new Coordinate(9, 7, 10));
		//li.add(new Coordinate(9, 8, 10));
		return li;
	}

	public static Collection<Coordinate> getRoofCracks(Random rand) {
		Collection<Coordinate> li = new ArrayList();
		switch(rand.nextInt(8)) {
			case 0:
				li.add(new Coordinate(4, 10, 5));
				li.add(new Coordinate(4, 10, 6));
				li.add(new Coordinate(4, 11, 5));
				li.add(new Coordinate(4, 11, 6));
				break;
			case 1:
				li.add(new Coordinate(4, 10, 10));
				li.add(new Coordinate(4, 10, 11));
				li.add(new Coordinate(4, 11, 10));
				li.add(new Coordinate(4, 11, 11));
				break;
			case 2:
				li.add(new Coordinate(5, 10, 4));
				li.add(new Coordinate(5, 11, 4));
				li.add(new Coordinate(6, 10, 4));
				li.add(new Coordinate(6, 11, 4));
				break;
			case 3:
				li.add(new Coordinate(5, 10, 12));
				li.add(new Coordinate(5, 11, 12));
				li.add(new Coordinate(6, 10, 12));
				li.add(new Coordinate(6, 11, 12));
				break;
			case 4:
				li.add(new Coordinate(10, 10, 4));
				li.add(new Coordinate(10, 11, 4));
				li.add(new Coordinate(11, 10, 4));
				li.add(new Coordinate(11, 11, 4));
				break;
			case 5:
				li.add(new Coordinate(10, 10, 12));
				li.add(new Coordinate(10, 11, 12));
				li.add(new Coordinate(11, 10, 12));
				li.add(new Coordinate(11, 11, 12));
				break;
			case 6:
				li.add(new Coordinate(12, 10, 5));
				li.add(new Coordinate(12, 10, 6));
				li.add(new Coordinate(12, 11, 5));
				li.add(new Coordinate(12, 11, 6));
				break;
			case 7:
				li.add(new Coordinate(12, 10, 10));
				li.add(new Coordinate(12, 10, 11));
				li.add(new Coordinate(12, 11, 10));
				li.add(new Coordinate(12, 11, 11));
				break;
		}
		return li;
	}

	public static Collection<Coordinate> getCenterAccess(ForgeDirection dir) {
		Collection<Coordinate> li = new ArrayList();
		switch(dir) {
			case WEST:
				li.add(new Coordinate(6, 6, 7));
				li.add(new Coordinate(6, 6, 8));
				li.add(new Coordinate(6, 6, 9));
				li.add(new Coordinate(6, 7, 7));
				li.add(new Coordinate(6, 7, 8));
				li.add(new Coordinate(6, 7, 9));
				li.add(new Coordinate(6, 8, 7));
				li.add(new Coordinate(6, 8, 8));
				li.add(new Coordinate(6, 8, 9));
				break;
			case SOUTH:
				li.add(new Coordinate(7, 6, 10));
				li.add(new Coordinate(7, 7, 10));
				li.add(new Coordinate(7, 8, 10));
				li.add(new Coordinate(8, 6, 10));
				li.add(new Coordinate(8, 7, 10));
				li.add(new Coordinate(8, 8, 10));
				li.add(new Coordinate(9, 6, 10));
				li.add(new Coordinate(9, 7, 10));
				li.add(new Coordinate(9, 8, 10));
				break;
			case NORTH:
				li.add(new Coordinate(7, 6, 6));
				li.add(new Coordinate(7, 7, 6));
				li.add(new Coordinate(7, 8, 6));
				li.add(new Coordinate(8, 6, 6));
				li.add(new Coordinate(8, 7, 6));
				li.add(new Coordinate(8, 8, 6));
				li.add(new Coordinate(9, 6, 6));
				li.add(new Coordinate(9, 7, 6));
				li.add(new Coordinate(9, 8, 6));
				break;
			case EAST:
				li.add(new Coordinate(10, 6, 7));
				li.add(new Coordinate(10, 6, 8));
				li.add(new Coordinate(10, 6, 9));
				li.add(new Coordinate(10, 7, 7));
				li.add(new Coordinate(10, 7, 8));
				li.add(new Coordinate(10, 7, 9));
				li.add(new Coordinate(10, 8, 7));
				li.add(new Coordinate(10, 8, 8));
				li.add(new Coordinate(10, 8, 9));
				break;
			default:
				break;
		}
		return li;
	}

	@Override
	public Coordinate getControllerRelativeLocation() {
		return new Coordinate(8, 3, 6);
	}

	@Override
	public FilledBlockArray getArray(World world, int x, int y, int z) {
		FilledBlockArray array = new FilledBlockArray(world);

		//array.setBlock(x + 8, y + 3, z + 6, Blocks.blockDiamond);

		getBaseStructure(array, x, y, z);
		getAirSpaces(array, x, y, z);

		Block spw = ChromaBlocks.STRUCTSHIELD.getBlockInstance();//Blocks.mob_spawner;
		array.setBlock(x + 14, y + 4, z + 14, spw);
		array.setBlock(x + 3, y + 4, z + 14, spw);
		array.setBlock(x + 2, y + 4, z + 4, spw);

		for (Coordinate c : getCrackToCenter()) {
			array.setBlock(x + c.xCoord, y + c.yCoord, z + c.zCoord, shield, mcrack);
		}

		for (int i = 2; i < 6; i++) {
			ForgeDirection dir = ForgeDirection.VALID_DIRECTIONS[i];
			for (Coordinate c : getCenterAccess(dir)) {
				array.setBlock(x + c.xCoord, y + c.yCoord, z + c.zCoord, ChromaBlocks.SHIFTLOCK.getBlockInstance(), Passability.CLOSED_HIDDEN.ordinal());
			}
		}

		for (Coordinate c : getRoofCracks(rand)) {
			array.setBlock(x + c.xCoord, y + c.yCoord, z + c.zCoord, shield, ms);
		}

		array.setBlock(x + 5, y + 10, z + 4, shield, ms);
		array.setBlock(x + 5, y + 11, z + 4, shield, ms);
		array.setBlock(x + 6, y + 10, z + 4, shield, ms);
		array.setBlock(x + 6, y + 11, z + 4, shield, ms);

		//array.setBlock(x + 5, y + 10, z + 4, b, BlockType.CRACK.metadata);
		//array.setBlock(x + 5, y + 11, z + 4, b, BlockType.CRACK.metadata);
		//array.setBlock(x + 6, y + 10, z + 4, b, BlockType.CRACK.metadata);
		//array.setBlock(x + 6, y + 11, z + 4, b, BlockType.CRACK.metadata);

		array.setBlock(x + 5, y + 10, z + 12, shield, ms);
		array.setBlock(x + 5, y + 11, z + 12, shield, ms);
		array.setBlock(x + 6, y + 10, z + 12, shield, ms);
		array.setBlock(x + 6, y + 11, z + 12, shield, ms);

		return array;
	}

	private static void getBaseStructure(FilledBlockArray array, int x, int y, int z) {
		Block ch = getChestGen();

		array.setBlock(x + 0, y + 5, z + 6, shield, BlockType.MOSS.metadata);
		array.setBlock(x + 0, y + 5, z + 7, shield, BlockType.MOSS.metadata);
		array.setBlock(x + 0, y + 5, z + 8, shield, BlockType.MOSS.metadata);
		array.setBlock(x + 0, y + 5, z + 9, shield, BlockType.MOSS.metadata);
		array.setBlock(x + 0, y + 5, z + 10, shield, BlockType.MOSS.metadata);
		array.setBlock(x + 1, y + 4, z + 4, shield, ms);
		array.setBlock(x + 1, y + 4, z + 5, shield, ms);
		array.setBlock(x + 1, y + 4, z + 6, shield, ms);
		array.setBlock(x + 1, y + 4, z + 7, shield, ms);
		array.setBlock(x + 1, y + 4, z + 8, shield, ms);
		array.setBlock(x + 1, y + 5, z + 3, shield, ms);
		array.setBlock(x + 1, y + 5, z + 4, shield, ms);
		array.setBlock(x + 1, y + 5, z + 5, shield, ms);
		array.setBlock(x + 1, y + 5, z + 6, shield, ms);
		array.setBlock(x + 1, y + 5, z + 7, shield, ms);
		array.setBlock(x + 1, y + 5, z + 8, b2);
		array.setBlock(x + 1, y + 5, z + 9, shield, ms);
		array.setBlock(x + 1, y + 5, z + 10, shield, ms);
		array.setBlock(x + 1, y + 5, z + 11, shield, ms);
		array.setBlock(x + 1, y + 5, z + 12, shield, ms);
		array.setBlock(x + 1, y + 5, z + 13, shield, ms);
		array.setBlock(x + 1, y + 6, z + 3, shield, mc);
		array.setBlock(x + 1, y + 6, z + 4, shield, mg);
		array.setBlock(x + 1, y + 6, z + 5, shield, mg);
		array.setBlock(x + 1, y + 6, z + 6, shield, mg);
		array.setBlock(x + 1, y + 6, z + 7, shield, mc);
		array.setBlock(x + 1, y + 6, z + 9, shield, mc);
		array.setBlock(x + 1, y + 6, z + 10, shield, mg);
		array.setBlock(x + 1, y + 6, z + 11, shield, mg);
		array.setBlock(x + 1, y + 6, z + 12, shield, mg);
		array.setBlock(x + 1, y + 6, z + 13, shield, mc);
		array.setBlock(x + 1, y + 7, z + 3, shield, mc);
		array.setBlock(x + 1, y + 7, z + 4, shield, mg);
		array.setBlock(x + 1, y + 7, z + 5, shield, mg);
		array.setBlock(x + 1, y + 7, z + 6, shield, mg);
		array.setBlock(x + 1, y + 7, z + 7, shield, mc);
		array.setBlock(x + 1, y + 7, z + 9, shield, mc);
		array.setBlock(x + 1, y + 7, z + 10, shield, mg);
		array.setBlock(x + 1, y + 7, z + 11, shield, mg);
		array.setBlock(x + 1, y + 7, z + 12, shield, mg);
		array.setBlock(x + 1, y + 7, z + 13, shield, mc);
		array.setBlock(x + 1, y + 8, z + 3, shield, mc);
		array.setBlock(x + 1, y + 8, z + 4, shield, mg);
		array.setBlock(x + 1, y + 8, z + 5, shield, mg);
		array.setBlock(x + 1, y + 8, z + 6, shield, mg);
		array.setBlock(x + 1, y + 8, z + 7, shield, mc);
		array.setBlock(x + 1, y + 8, z + 8, shield, mc);
		array.setBlock(x + 1, y + 8, z + 9, shield, mc);
		array.setBlock(x + 1, y + 8, z + 10, shield, mg);
		array.setBlock(x + 1, y + 8, z + 11, shield, mg);
		array.setBlock(x + 1, y + 8, z + 12, shield, mg);
		array.setBlock(x + 1, y + 8, z + 13, shield, mc);
		array.setBlock(x + 1, y + 9, z + 3, shield, mc);
		array.setBlock(x + 1, y + 9, z + 4, shield, mc);
		array.setBlock(x + 1, y + 9, z + 5, shield, mc);
		array.setBlock(x + 1, y + 9, z + 6, shield, mc);
		array.setBlock(x + 1, y + 9, z + 7, shield, mc);
		array.setBlock(x + 1, y + 9, z + 8, shield, mc);
		array.setBlock(x + 1, y + 9, z + 9, shield, mc);
		array.setBlock(x + 1, y + 9, z + 10, shield, mc);
		array.setBlock(x + 1, y + 9, z + 11, shield, mc);
		array.setBlock(x + 1, y + 9, z + 12, shield, mc);
		array.setBlock(x + 1, y + 9, z + 13, shield, mc);
		array.setBlock(x + 1, y + 10, z + 3, shield, mc);
		array.setBlock(x + 1, y + 10, z + 5, shield, mc);
		array.setBlock(x + 1, y + 10, z + 11, shield, mc);
		array.setBlock(x + 1, y + 10, z + 13, shield, mc);
		array.setBlock(x + 2, y + 3, z + 4, shield, ms);
		array.setBlock(x + 2, y + 3, z + 5, shield, ms);
		array.setBlock(x + 2, y + 3, z + 6, shield, ms);
		array.setBlock(x + 2, y + 3, z + 7, shield, ms);
		array.setBlock(x + 2, y + 3, z + 8, shield, ms);
		array.setBlock(x + 2, y + 3, z + 9, shield, ms);
		array.setBlock(x + 2, y + 4, z + 3, shield, ms);
		array.setBlock(x + 2, y + 4, z + 5, shield, ms);
		array.setBlock(x + 2, y + 4, z + 6, shield, ms);
		array.setBlock(x + 2, y + 4, z + 7, shield, ms);
		array.setBlock(x + 2, y + 4, z + 8, shield, ms);
		array.setBlock(x + 2, y + 4, z + 9, shield, ms);
		array.setBlock(x + 2, y + 4, z + 10, shield, ms);
		array.setBlock(x + 2, y + 4, z + 11, shield, ms);
		array.setBlock(x + 2, y + 4, z + 12, shield, ms);
		array.setBlock(x + 2, y + 4, z + 13, shield, ms);
		array.setBlock(x + 2, y + 4, z + 14, shield, ms);
		array.setBlock(x + 2, y + 5, z + 2, shield, ms);
		array.setBlock(x + 2, y + 5, z + 3, b2);
		array.setBlock(x + 2, y + 5, z + 4, b2);
		array.setBlock(x + 2, y + 5, z + 5, b2);
		array.setBlock(x + 2, y + 5, z + 6, b2);
		array.setBlock(x + 2, y + 5, z + 7, b2);
		array.setBlock(x + 2, y + 5, z + 8, b2);
		array.setBlock(x + 2, y + 5, z + 9, shield, ms);
		array.setBlock(x + 2, y + 5, z + 10, b2);
		array.setBlock(x + 2, y + 5, z + 11, b2);
		array.setBlock(x + 2, y + 5, z + 12, b2);
		array.setBlock(x + 2, y + 5, z + 13, b2);
		array.setBlock(x + 2, y + 5, z + 14, shield, ms);
		array.setBlock(x + 2, y + 6, z + 2, shield, ms);
		array.setBlock(x + 2, y + 6, z + 9, shield, ms);
		array.setBlock(x + 2, y + 6, z + 14, shield, ms);
		array.setBlock(x + 2, y + 7, z + 2, shield, ms);
		array.setBlock(x + 2, y + 7, z + 9, shield, ms);
		array.setBlock(x + 2, y + 7, z + 14, shield, ms);
		array.setBlock(x + 2, y + 8, z + 2, shield, ms);
		array.setBlock(x + 2, y + 8, z + 9, shield, ms);
		array.setBlock(x + 2, y + 8, z + 14, shield, ms);
		array.setBlock(x + 2, y + 9, z + 2, shield, mc);
		array.setBlock(x + 2, y + 9, z + 3, shield, mc);
		array.setBlock(x + 2, y + 9, z + 4, shield, ms);
		array.setBlock(x + 2, y + 9, z + 5, shield, ms);
		array.setBlock(x + 2, y + 9, z + 6, shield, ms);
		array.setBlock(x + 2, y + 9, z + 7, shield, ms);
		array.setBlock(x + 2, y + 9, z + 8, shield, ms);
		array.setBlock(x + 2, y + 9, z + 9, shield, ms);
		array.setBlock(x + 2, y + 9, z + 10, shield, ms);
		array.setBlock(x + 2, y + 9, z + 11, shield, ms);
		array.setBlock(x + 2, y + 9, z + 12, shield, ms);
		array.setBlock(x + 2, y + 9, z + 13, shield, mc);
		array.setBlock(x + 2, y + 9, z + 14, shield, mc);
		array.setBlock(x + 2, y + 10, z + 5, shield, mc);
		array.setBlock(x + 2, y + 10, z + 6, shield, ms);
		array.setBlock(x + 2, y + 10, z + 7, shield, ms);
		array.setBlock(x + 2, y + 10, z + 8, shield, ms);
		array.setBlock(x + 2, y + 10, z + 9, shield, ms);
		array.setBlock(x + 2, y + 10, z + 10, shield, ms);
		array.setBlock(x + 2, y + 10, z + 11, shield, mc);
		array.setBlock(x + 3, y + 3, z + 4, shield, ms);
		array.setBlock(x + 3, y + 3, z + 5, shield, BlockType.CLOAK.metadata);
		array.setBlock(x + 3, y + 3, z + 6, shield, BlockType.CLOAK.metadata);
		array.setBlock(x + 3, y + 3, z + 7, shield, BlockType.CLOAK.metadata);
		array.setBlock(x + 3, y + 3, z + 8, shield, BlockType.CLOAK.metadata);
		array.setBlock(x + 3, y + 3, z + 9, shield, ms);
		array.setBlock(x + 3, y + 3, z + 10, shield, ms);
		array.setBlock(x + 3, y + 3, z + 11, shield, ms);
		array.setBlock(x + 3, y + 3, z + 12, shield, ms);
		array.setBlock(x + 3, y + 3, z + 13, shield, ms);
		array.setBlock(x + 3, y + 3, z + 14, shield, ms);
		array.setBlock(x + 3, y + 4, z + 2, shield, ms);
		array.setBlock(x + 3, y + 4, z + 3, shield, ms);
		array.setBlock(x + 3, y + 4, z + 4, shield, ms);
		array.setBlock(x + 3, y + 4, z + 9, shield, ms);
		array.setBlock(x + 3, y + 4, z + 10, shield, ms);
		array.setBlock(x + 3, y + 4, z + 11, shield, ms);
		array.setBlock(x + 3, y + 4, z + 12, shield, ms);
		array.setBlock(x + 3, y + 4, z + 13, shield, ms);
		array.setBlock(x + 3, y + 4, z + 15, shield, ms);
		array.setBlock(x + 3, y + 5, z + 1, shield, ms);
		array.setBlock(x + 3, y + 5, z + 2, b2);
		array.setBlock(x + 3, y + 5, z + 3, b2);
		array.setBlock(x + 3, y + 5, z + 4, b2);
		array.setBlock(x + 3, y + 5, z + 5, b2);
		array.setBlock(x + 3, y + 5, z + 6, b2);
		array.setBlock(x + 3, y + 5, z + 7, b2);
		array.setBlock(x + 3, y + 5, z + 8, b2);
		array.setBlock(x + 3, y + 5, z + 9, shield, ms);
		array.setBlock(x + 3, y + 5, z + 10, b2);
		array.setBlock(x + 3, y + 5, z + 11, b2);
		array.setBlock(x + 3, y + 5, z + 12, b2);
		array.setBlock(x + 3, y + 5, z + 13, b2);
		array.setBlock(x + 3, y + 5, z + 14, b2);
		array.setBlock(x + 3, y + 5, z + 15, shield, ms);
		array.setBlock(x + 3, y + 6, z + 1, shield, mc);
		array.setBlock(x + 3, y + 6, z + 9, shield, ms);
		array.setBlock(x + 3, y + 6, z + 15, shield, mc);
		array.setBlock(x + 3, y + 7, z + 1, shield, mc);
		array.setBlock(x + 3, y + 7, z + 9, shield, ms);
		array.setBlock(x + 3, y + 7, z + 15, shield, mc);
		array.setBlock(x + 3, y + 8, z + 1, shield, mc);
		array.setBlock(x + 3, y + 8, z + 9, shield, ms);
		array.setBlock(x + 3, y + 8, z + 15, shield, mc);
		array.setBlock(x + 3, y + 9, z + 1, shield, mc);
		array.setBlock(x + 3, y + 9, z + 2, shield, mc);
		array.setBlock(x + 3, y + 9, z + 3, shield, ms);
		array.setBlock(x + 3, y + 9, z + 4, shield, ms);
		array.setBlock(x + 3, y + 9, z + 5, shield, ms);
		array.setBlock(x + 3, y + 9, z + 6, shield, ms);
		array.setBlock(x + 3, y + 9, z + 7, shield, ms);
		array.setBlock(x + 3, y + 9, z + 8, shield, ms);
		array.setBlock(x + 3, y + 9, z + 9, shield, ms);
		array.setBlock(x + 3, y + 9, z + 10, shield, ms);
		array.setBlock(x + 3, y + 9, z + 11, shield, ms);
		array.setBlock(x + 3, y + 9, z + 12, shield, ms);
		array.setBlock(x + 3, y + 9, z + 13, shield, ms);
		array.setBlock(x + 3, y + 9, z + 14, shield, mc);
		array.setBlock(x + 3, y + 9, z + 15, shield, mc);
		array.setBlock(x + 3, y + 10, z + 1, shield, mc);
		array.setBlock(x + 3, y + 10, z + 5, shield, mc);
		array.setBlock(x + 3, y + 10, z + 6, shield, ms);
		array.setBlock(x + 3, y + 10, z + 7, shield, ms);
		array.setBlock(x + 3, y + 10, z + 8, shield, ms);
		array.setBlock(x + 3, y + 10, z + 9, shield, ms);
		array.setBlock(x + 3, y + 10, z + 10, shield, ms);
		array.setBlock(x + 3, y + 10, z + 11, shield, mc);
		array.setBlock(x + 3, y + 10, z + 15, shield, mc);
		array.setBlock(x + 3, y + 11, z + 5, shield, mc);
		array.setBlock(x + 3, y + 11, z + 6, shield, ms);
		array.setBlock(x + 3, y + 11, z + 7, shield, ms);
		array.setBlock(x + 3, y + 11, z + 8, shield, ms);
		array.setBlock(x + 3, y + 11, z + 9, shield, ms);
		array.setBlock(x + 3, y + 11, z + 10, shield, ms);
		array.setBlock(x + 3, y + 11, z + 11, shield, mc);
		array.setBlock(x + 3, y + 12, z + 5, shield, mc);
		array.setBlock(x + 3, y + 12, z + 6, shield, mc);
		array.setBlock(x + 3, y + 12, z + 7, shield, mc);
		array.setBlock(x + 3, y + 12, z + 8, shield, mc);
		array.setBlock(x + 3, y + 12, z + 9, shield, mc);
		array.setBlock(x + 3, y + 12, z + 10, shield, mc);
		array.setBlock(x + 3, y + 12, z + 11, shield, mc);
		array.setBlock(x + 3, y + 13, z + 5, shield, mc);
		array.setBlock(x + 3, y + 13, z + 11, shield, mc);
		array.setBlock(x + 4, y + 3, z + 4, shield, ms);
		array.setBlock(x + 4, y + 3, z + 5, shield, BlockType.CLOAK.metadata);
		array.setBlock(x + 4, y + 3, z + 6, shield, BlockType.CLOAK.metadata);
		array.setBlock(x + 4, y + 3, z + 7, shield, BlockType.CLOAK.metadata);
		array.setBlock(x + 4, y + 3, z + 8, shield, BlockType.CLOAK.metadata);
		array.setBlock(x + 4, y + 3, z + 9, shield, BlockType.CLOAK.metadata);
		array.setBlock(x + 4, y + 3, z + 10, shield, BlockType.CLOAK.metadata);
		array.setBlock(x + 4, y + 3, z + 11, shield, BlockType.CLOAK.metadata);
		array.setBlock(x + 4, y + 3, z + 12, shield, BlockType.CLOAK.metadata);
		array.setBlock(x + 4, y + 3, z + 13, shield, BlockType.CLOAK.metadata);
		array.setBlock(x + 4, y + 3, z + 14, shield, ms);
		array.setBlock(x + 4, y + 4, z + 2, shield, ms);
		array.setBlock(x + 4, y + 4, z + 3, shield, ms);
		array.setBlock(x + 4, y + 4, z + 4, shield, ms);
		array.setBlock(x + 4, y + 4, z + 14, shield, ms);
		array.setBlock(x + 4, y + 4, z + 15, shield, ms);
		array.setBlock(x + 4, y + 5, z + 1, shield, ms);
		array.setBlock(x + 4, y + 5, z + 2, b2);
		array.setBlock(x + 4, y + 5, z + 3, b2);
		array.setBlock(x + 4, y + 5, z + 4, b2);
		array.setBlock(x + 4, y + 5, z + 5, b2);
		array.setBlock(x + 4, y + 5, z + 6, b2);
		array.setBlock(x + 4, y + 5, z + 7, b2);
		array.setBlock(x + 4, y + 5, z + 8, b2);
		array.setBlock(x + 4, y + 5, z + 9, b2);
		array.setBlock(x + 4, y + 5, z + 10, shield, ms);
		array.setBlock(x + 4, y + 5, z + 11, b2);
		array.setBlock(x + 4, y + 5, z + 12, b2);
		array.setBlock(x + 4, y + 5, z + 13, b2);
		array.setBlock(x + 4, y + 5, z + 14, b2);
		array.setBlock(x + 4, y + 5, z + 15, shield, ms);
		array.setBlock(x + 4, y + 6, z + 1, shield, mg);
		array.setBlock(x + 4, y + 6, z + 10, shield, ms);
		array.setBlock(x + 4, y + 6, z + 15, shield, mg);
		array.setBlock(x + 4, y + 7, z + 1, shield, mg);
		array.setBlock(x + 4, y + 7, z + 10, shield, ms);
		array.setBlock(x + 4, y + 7, z + 15, shield, mg);
		array.setBlock(x + 4, y + 8, z + 1, shield, mg);
		array.setBlock(x + 4, y + 8, z + 10, shield, ms);
		array.setBlock(x + 4, y + 8, z + 15, shield, mg);
		array.setBlock(x + 4, y + 9, z + 1, shield, mc);
		array.setBlock(x + 4, y + 9, z + 2, shield, ms);
		array.setBlock(x + 4, y + 9, z + 3, shield, ms);
		array.setBlock(x + 4, y + 9, z + 4, shield, ms);
		array.setBlock(x + 4, y + 9, z + 5, shield, ms);
		array.setBlock(x + 4, y + 9, z + 6, shield, ms);
		array.setBlock(x + 4, y + 9, z + 7, shield, ms);
		array.setBlock(x + 4, y + 9, z + 8, shield, ms);
		array.setBlock(x + 4, y + 9, z + 9, shield, ms);
		array.setBlock(x + 4, y + 9, z + 10, shield, ms);
		array.setBlock(x + 4, y + 9, z + 11, shield, ms);
		array.setBlock(x + 4, y + 9, z + 12, shield, ms);
		array.setBlock(x + 4, y + 9, z + 13, shield, ms);
		array.setBlock(x + 4, y + 9, z + 14, shield, ms);
		array.setBlock(x + 4, y + 9, z + 15, shield, mc);
		array.setBlock(x + 4, y + 10, z + 5, shield, ms);
		array.setBlock(x + 4, y + 10, z + 6, shield, ms);
		array.setBlock(x + 4, y + 10, z + 7, shield, ms);
		array.setBlock(x + 4, y + 10, z + 8, ch, 1);
		array.setBlock(x + 4, y + 10, z + 9, shield, ms);
		array.setBlock(x + 4, y + 10, z + 10, shield, ms);
		array.setBlock(x + 4, y + 10, z + 11, shield, ms);
		array.setBlock(x + 4, y + 11, z + 5, shield, ms);
		array.setBlock(x + 4, y + 11, z + 6, shield, ms);
		array.setBlock(x + 4, y + 11, z + 7, shield, ms);
		array.setBlock(x + 4, y + 11, z + 8, shield, ms);
		array.setBlock(x + 4, y + 11, z + 9, shield, ms);
		array.setBlock(x + 4, y + 11, z + 10, shield, ms);
		array.setBlock(x + 4, y + 11, z + 11, shield, ms);
		array.setBlock(x + 4, y + 12, z + 5, shield, mc);
		array.setBlock(x + 4, y + 12, z + 6, shield, ms);
		array.setBlock(x + 4, y + 12, z + 7, shield, ms);
		array.setBlock(x + 4, y + 12, z + 8, shield, ms);
		array.setBlock(x + 4, y + 12, z + 9, shield, ms);
		array.setBlock(x + 4, y + 12, z + 10, shield, ms);
		array.setBlock(x + 4, y + 12, z + 11, shield, mc);
		array.setBlock(x + 5, y + 1, z + 5, shield, ms);
		array.setBlock(x + 5, y + 2, z + 4, shield, ms);
		array.setBlock(x + 5, y + 2, z + 5, shield, ms);
		array.setBlock(x + 5, y + 2, z + 6, shield, ms);
		array.setBlock(x + 5, y + 3, z + 4, shield, ms);
		array.setBlock(x + 5, y + 3, z + 5, shield, ms);
		array.setBlock(x + 5, y + 3, z + 6, shield, BlockType.CLOAK.metadata);
		array.setBlock(x + 5, y + 3, z + 7, shield, BlockType.CLOAK.metadata);
		array.setBlock(x + 5, y + 3, z + 8, shield, BlockType.CLOAK.metadata);
		array.setBlock(x + 5, y + 3, z + 9, shield, BlockType.CLOAK.metadata);
		array.setBlock(x + 5, y + 3, z + 10, shield, BlockType.CLOAK.metadata);
		array.setBlock(x + 5, y + 3, z + 11, shield, ms);
		array.setBlock(x + 5, y + 3, z + 12, shield, BlockType.CLOAK.metadata);
		array.setBlock(x + 5, y + 3, z + 13, shield, BlockType.CLOAK.metadata);
		array.setBlock(x + 5, y + 3, z + 14, shield, ms);
		array.setBlock(x + 5, y + 4, z + 2, shield, ms);
		array.setBlock(x + 5, y + 4, z + 3, shield, ms);
		array.setBlock(x + 5, y + 4, z + 4, shield, ms);
		array.setBlock(x + 5, y + 4, z + 5, shield, ms);
		array.setBlock(x + 5, y + 4, z + 11, shield, ms);
		array.setBlock(x + 5, y + 4, z + 14, shield, ms);
		array.setBlock(x + 5, y + 4, z + 15, shield, ms);
		array.setBlock(x + 5, y + 5, z + 1, shield, ms);
		array.setBlock(x + 5, y + 5, z + 2, b2);
		array.setBlock(x + 5, y + 5, z + 3, b2);
		array.setBlock(x + 5, y + 5, z + 4, b2);
		array.setBlock(x + 5, y + 5, z + 5, shield, ms);
		array.setBlock(x + 5, y + 5, z + 6, b2);
		array.setBlock(x + 5, y + 5, z + 7, b2);
		array.setBlock(x + 5, y + 5, z + 8, b2);
		array.setBlock(x + 5, y + 5, z + 9, b2);
		array.setBlock(x + 5, y + 5, z + 10, shield, ms);
		array.setBlock(x + 5, y + 5, z + 11, shield, ms);
		array.setBlock(x + 5, y + 5, z + 12, b2);
		array.setBlock(x + 5, y + 5, z + 13, b2);
		array.setBlock(x + 5, y + 5, z + 14, b2);
		array.setBlock(x + 5, y + 5, z + 15, shield, ms);
		array.setBlock(x + 5, y + 6, z + 1, shield, mg);
		array.setBlock(x + 5, y + 6, z + 5, shield, ms);
		array.setBlock(x + 5, y + 6, z + 10, shield, ms);
		array.setBlock(x + 5, y + 6, z + 11, shield, ms);
		array.setBlock(x + 5, y + 6, z + 15, shield, mg);
		array.setBlock(x + 5, y + 7, z + 1, shield, mg);
		array.setBlock(x + 5, y + 7, z + 5, shield, BlockType.LIGHT.metadata);
		array.setBlock(x + 5, y + 7, z + 10, ch, 2);
		array.setBlock(x + 5, y + 7, z + 11, shield, BlockType.LIGHT.metadata);
		array.setBlock(x + 5, y + 7, z + 15, shield, mg);
		array.setBlock(x + 5, y + 8, z + 1, shield, mg);
		array.setBlock(x + 5, y + 8, z + 5, shield, ms);
		array.setBlock(x + 5, y + 8, z + 10, shield, ms);
		array.setBlock(x + 5, y + 8, z + 11, shield, ms);
		array.setBlock(x + 5, y + 8, z + 15, shield, mg);
		array.setBlock(x + 5, y + 9, z + 1, shield, mc);
		array.setBlock(x + 5, y + 9, z + 2, shield, ms);
		array.setBlock(x + 5, y + 9, z + 3, shield, ms);
		array.setBlock(x + 5, y + 9, z + 4, shield, ms);
		array.setBlock(x + 5, y + 9, z + 5, shield, ms);
		array.setBlock(x + 5, y + 9, z + 6, shield, ms);
		array.setBlock(x + 5, y + 9, z + 7, shield, ms);
		array.setBlock(x + 5, y + 9, z + 8, shield, ms);
		array.setBlock(x + 5, y + 9, z + 9, shield, ms);
		array.setBlock(x + 5, y + 9, z + 10, shield, ms);
		array.setBlock(x + 5, y + 9, z + 11, shield, ms);
		array.setBlock(x + 5, y + 9, z + 12, shield, ms);
		array.setBlock(x + 5, y + 9, z + 13, shield, ms);
		array.setBlock(x + 5, y + 9, z + 14, shield, ms);
		array.setBlock(x + 5, y + 9, z + 15, shield, mc);
		array.setBlock(x + 5, y + 10, z + 1, shield, mc);
		array.setBlock(x + 5, y + 10, z + 2, shield, mc);
		array.setBlock(x + 5, y + 10, z + 3, shield, mc);
		array.setBlock(x + 5, y + 10, z + 5, shield, ms);
		array.setBlock(x + 5, y + 10, z + 11, shield, ms);
		array.setBlock(x + 5, y + 10, z + 13, shield, mc);
		array.setBlock(x + 5, y + 10, z + 14, shield, mc);
		array.setBlock(x + 5, y + 10, z + 15, shield, mc);
		array.setBlock(x + 5, y + 11, z + 3, shield, mc);
		array.setBlock(x + 5, y + 11, z + 5, shield, ms);
		array.setBlock(x + 5, y + 11, z + 11, shield, ms);
		array.setBlock(x + 5, y + 11, z + 13, shield, mc);
		array.setBlock(x + 5, y + 12, z + 3, shield, mc);
		array.setBlock(x + 5, y + 12, z + 4, shield, mc);
		array.setBlock(x + 5, y + 12, z + 5, shield, mc);
		array.setBlock(x + 5, y + 12, z + 6, shield, mc);
		array.setBlock(x + 5, y + 12, z + 7, shield, ms);
		array.setBlock(x + 5, y + 12, z + 8, shield, ms);
		array.setBlock(x + 5, y + 12, z + 9, shield, ms);
		array.setBlock(x + 5, y + 12, z + 10, shield, mc);
		array.setBlock(x + 5, y + 12, z + 11, shield, mc);
		array.setBlock(x + 5, y + 12, z + 12, shield, mc);
		array.setBlock(x + 5, y + 12, z + 13, shield, mc);
		array.setBlock(x + 5, y + 13, z + 3, shield, mc);
		array.setBlock(x + 5, y + 13, z + 13, shield, mc);
		array.setBlock(x + 6, y + 0, z + 5, shield, ms);
		array.setBlock(x + 6, y + 1, z + 4, shield, ms);
		array.setBlock(x + 6, y + 1, z + 5, shield, BlockType.LIGHT.metadata);
		array.setBlock(x + 6, y + 1, z + 6, shield, ms);
		array.setBlock(x + 6, y + 1, z + 7, shield, ms);
		array.setBlock(x + 6, y + 2, z + 4, shield, ms);
		array.setBlock(x + 6, y + 2, z + 5, ch, 1);
		array.setBlock(x + 6, y + 2, z + 6, shield, ms);
		array.setBlock(x + 6, y + 2, z + 7, shield, ms);
		array.setBlock(x + 6, y + 2, z + 8, shield, ms);
		array.setBlock(x + 6, y + 2, z + 9, shield, ms);
		array.setBlock(x + 6, y + 3, z + 4, shield, ms);
		array.setBlock(x + 6, y + 3, z + 5, shield, ms);
		array.setBlock(x + 6, y + 3, z + 6, shield, ms);
		array.setBlock(x + 6, y + 3, z + 7, shield, ms);
		array.setBlock(x + 6, y + 3, z + 8, shield, ms);
		array.setBlock(x + 6, y + 3, z + 9, shield, ms);
		array.setBlock(x + 6, y + 3, z + 10, shield, ms);
		array.setBlock(x + 6, y + 3, z + 11, shield, BlockType.CLOAK.metadata);
		array.setBlock(x + 6, y + 3, z + 12, shield, BlockType.CLOAK.metadata);
		array.setBlock(x + 6, y + 3, z + 13, shield, BlockType.CLOAK.metadata);
		array.setBlock(x + 6, y + 3, z + 14, shield, ms);
		array.setBlock(x + 6, y + 4, z + 2, shield, ms);
		array.setBlock(x + 6, y + 4, z + 3, shield, ms);
		array.setBlock(x + 6, y + 4, z + 4, shield, ms);
		array.setBlock(x + 6, y + 4, z + 5, shield, ms);
		array.setBlock(x + 6, y + 4, z + 6, shield, ms);
		array.setBlock(x + 6, y + 4, z + 7, shield, ms);
		array.setBlock(x + 6, y + 4, z + 8, shield, ms);
		array.setBlock(x + 6, y + 4, z + 9, shield, ms);
		array.setBlock(x + 6, y + 4, z + 10, shield, ms);
		array.setBlock(x + 6, y + 4, z + 14, shield, ms);
		array.setBlock(x + 6, y + 4, z + 15, shield, ms);
		array.setBlock(x + 6, y + 5, z + 0, shield, BlockType.MOSS.metadata);
		array.setBlock(x + 6, y + 5, z + 1, shield, ms);
		array.setBlock(x + 6, y + 5, z + 2, b2);
		array.setBlock(x + 6, y + 5, z + 3, b2);
		array.setBlock(x + 6, y + 5, z + 4, shield, ms);
		array.setBlock(x + 6, y + 5, z + 5, shield, ms);
		array.setBlock(x + 6, y + 5, z + 6, shield, ms);
		array.setBlock(x + 6, y + 5, z + 7, shield, ms);
		array.setBlock(x + 6, y + 5, z + 8, shield, ms);
		array.setBlock(x + 6, y + 5, z + 9, shield, ms);
		array.setBlock(x + 6, y + 5, z + 10, shield, ms);
		array.setBlock(x + 6, y + 5, z + 11, b2);
		array.setBlock(x + 6, y + 5, z + 12, b2);
		array.setBlock(x + 6, y + 5, z + 13, b2);
		array.setBlock(x + 6, y + 5, z + 14, b2);
		array.setBlock(x + 6, y + 5, z + 15, shield, ms);
		array.setBlock(x + 6, y + 5, z + 16, shield, BlockType.MOSS.metadata);
		array.setBlock(x + 6, y + 6, z + 1, shield, mg);
		array.setBlock(x + 6, y + 6, z + 4, shield, ms);
		array.setBlock(x + 6, y + 6, z + 5, shield, ms);
		array.setBlock(x + 6, y + 6, z + 6, shield, ms);
		array.setBlock(x + 6, y + 6, z + 7, shield, ms);
		array.setBlock(x + 6, y + 6, z + 8, shield, ms);
		array.setBlock(x + 6, y + 6, z + 9, shield, ms);
		array.setBlock(x + 6, y + 6, z + 10, shield, ms);
		array.setBlock(x + 6, y + 6, z + 15, shield, mg);
		array.setBlock(x + 6, y + 7, z + 1, shield, mg);
		array.setBlock(x + 6, y + 7, z + 4, shield, ms);
		array.setBlock(x + 6, y + 7, z + 5, ch, 1);
		array.setBlock(x + 6, y + 7, z + 6, shield, ms);
		array.setBlock(x + 6, y + 7, z + 7, shield, ms);
		array.setBlock(x + 6, y + 7, z + 8, shield, ms);
		array.setBlock(x + 6, y + 7, z + 9, shield, ms);
		array.setBlock(x + 6, y + 7, z + 10, shield, ms);
		array.setBlock(x + 6, y + 7, z + 15, shield, mg);
		array.setBlock(x + 6, y + 8, z + 1, shield, mg);
		array.setBlock(x + 6, y + 8, z + 4, shield, ms);
		array.setBlock(x + 6, y + 8, z + 5, shield, ms);
		array.setBlock(x + 6, y + 8, z + 6, shield, ms);
		array.setBlock(x + 6, y + 8, z + 7, shield, ms);
		array.setBlock(x + 6, y + 8, z + 8, shield, ms);
		array.setBlock(x + 6, y + 8, z + 9, shield, ms);
		array.setBlock(x + 6, y + 8, z + 10, shield, ms);
		array.setBlock(x + 6, y + 8, z + 15, shield, mg);
		array.setBlock(x + 6, y + 9, z + 1, shield, mc);
		array.setBlock(x + 6, y + 9, z + 2, shield, ms);
		array.setBlock(x + 6, y + 9, z + 3, shield, ms);
		array.setBlock(x + 6, y + 9, z + 4, shield, ms);
		array.setBlock(x + 6, y + 9, z + 5, shield, ms);
		array.setBlock(x + 6, y + 9, z + 6, shield, ms);
		array.setBlock(x + 6, y + 9, z + 7, shield, ms);
		array.setBlock(x + 6, y + 9, z + 8, shield, ms);
		array.setBlock(x + 6, y + 9, z + 9, shield, ms);
		array.setBlock(x + 6, y + 9, z + 10, shield, ms);
		array.setBlock(x + 6, y + 9, z + 11, shield, ms);
		array.setBlock(x + 6, y + 9, z + 12, shield, ms);
		array.setBlock(x + 6, y + 9, z + 13, shield, ms);
		array.setBlock(x + 6, y + 9, z + 14, shield, ms);
		array.setBlock(x + 6, y + 9, z + 15, shield, mc);
		array.setBlock(x + 6, y + 10, z + 2, shield, ms);
		array.setBlock(x + 6, y + 10, z + 3, shield, ms);
		array.setBlock(x + 6, y + 10, z + 13, shield, ms);
		array.setBlock(x + 6, y + 10, z + 14, shield, ms);
		array.setBlock(x + 6, y + 11, z + 3, shield, ms);
		array.setBlock(x + 6, y + 11, z + 13, shield, ms);
		array.setBlock(x + 6, y + 12, z + 3, shield, mc);
		array.setBlock(x + 6, y + 12, z + 4, shield, ms);
		array.setBlock(x + 6, y + 12, z + 5, shield, mc);
		array.setBlock(x + 6, y + 12, z + 6, shield, mc);
		array.setBlock(x + 6, y + 12, z + 7, shield, mc);
		array.setBlock(x + 6, y + 12, z + 8, shield, mc);
		array.setBlock(x + 6, y + 12, z + 9, shield, mc);
		array.setBlock(x + 6, y + 12, z + 10, shield, mc);
		array.setBlock(x + 6, y + 12, z + 11, shield, mc);
		array.setBlock(x + 6, y + 12, z + 12, shield, ms);
		array.setBlock(x + 6, y + 12, z + 13, shield, mc);
		array.setBlock(x + 6, y + 13, z + 6, shield, mc);
		array.setBlock(x + 6, y + 13, z + 7, shield, mc);
		array.setBlock(x + 6, y + 13, z + 8, shield, mc);
		array.setBlock(x + 6, y + 13, z + 9, shield, mc);
		array.setBlock(x + 6, y + 13, z + 10, shield, mc);
		array.setBlock(x + 6, y + 14, z + 6, shield, mc);
		array.setBlock(x + 6, y + 14, z + 10, shield, mc);
		array.setBlock(x + 7, y + 0, z + 5, shield, ms);
		array.setBlock(x + 7, y + 1, z + 4, shield, ms);
		array.setBlock(x + 7, y + 1, z + 5, shield, ms);
		array.setBlock(x + 7, y + 1, z + 6, shield, ms);
		array.setBlock(x + 7, y + 1, z + 7, shield, ms);
		array.setBlock(x + 7, y + 2, z + 3, shield, ms);
		array.setBlock(x + 7, y + 2, z + 4, shield, ms);
		array.setBlock(x + 7, y + 2, z + 8, shield, ms);
		array.setBlock(x + 7, y + 2, z + 9, shield, ms);
		array.setBlock(x + 7, y + 3, z + 3, shield, ms);
		array.setBlock(x + 7, y + 3, z + 4, shield, ms);
		array.setBlock(x + 7, y + 3, z + 9, shield, ms);
		array.setBlock(x + 7, y + 3, z + 10, shield, ms);
		array.setBlock(x + 7, y + 3, z + 11, shield, BlockType.CLOAK.metadata);
		array.setBlock(x + 7, y + 3, z + 12, shield, BlockType.CLOAK.metadata);
		array.setBlock(x + 7, y + 3, z + 13, shield, BlockType.CLOAK.metadata);
		array.setBlock(x + 7, y + 3, z + 14, shield, ms);
		array.setBlock(x + 7, y + 4, z + 2, shield, ms);
		array.setBlock(x + 7, y + 4, z + 3, shield, ms);
		array.setBlock(x + 7, y + 4, z + 4, shield, ms);
		array.setBlock(x + 7, y + 4, z + 5, shield, ms);
		array.setBlock(x + 7, y + 4, z + 10, shield, ms);
		array.setBlock(x + 7, y + 4, z + 14, shield, ms);
		array.setBlock(x + 7, y + 4, z + 15, shield, ms);
		array.setBlock(x + 7, y + 5, z + 0, shield, BlockType.MOSS.metadata);
		array.setBlock(x + 7, y + 5, z + 1, shield, ms);
		array.setBlock(x + 7, y + 5, z + 2, shield, ms);
		array.setBlock(x + 7, y + 5, z + 3, shield, ms);
		array.setBlock(x + 7, y + 5, z + 4, b2);
		array.setBlock(x + 7, y + 5, z + 5, b2);
		array.setBlock(x + 7, y + 5, z + 6, shield, ms);
		array.setBlock(x + 7, y + 5, z + 11, b2);
		array.setBlock(x + 7, y + 5, z + 12, b2);
		array.setBlock(x + 7, y + 5, z + 13, b2);
		array.setBlock(x + 7, y + 5, z + 14, b2);
		array.setBlock(x + 7, y + 5, z + 15, shield, ms);
		array.setBlock(x + 7, y + 5, z + 16, shield, BlockType.MOSS.metadata);
		array.setBlock(x + 7, y + 6, z + 1, shield, mc);
		array.setBlock(x + 7, y + 6, z + 2, shield, ms);
		array.setBlock(x + 7, y + 6, z + 3, shield, ms);
		array.setBlock(x + 7, y + 6, z + 6, shield, ms);
		array.setBlock(x + 7, y + 6, z + 15, shield, mc);
		array.setBlock(x + 7, y + 7, z + 1, shield, mc);
		array.setBlock(x + 7, y + 7, z + 2, shield, ms);
		array.setBlock(x + 7, y + 7, z + 3, shield, ms);
		array.setBlock(x + 7, y + 7, z + 6, shield, ms);
		array.setBlock(x + 7, y + 7, z + 15, shield, mc);
		array.setBlock(x + 7, y + 8, z + 1, shield, mc);
		array.setBlock(x + 7, y + 8, z + 2, shield, ms);
		array.setBlock(x + 7, y + 8, z + 3, shield, ms);
		array.setBlock(x + 7, y + 8, z + 6, shield, ms);
		array.setBlock(x + 7, y + 8, z + 15, shield, mc);
		array.setBlock(x + 7, y + 9, z + 1, shield, mc);
		array.setBlock(x + 7, y + 9, z + 2, shield, ms);
		array.setBlock(x + 7, y + 9, z + 3, shield, ms);
		array.setBlock(x + 7, y + 9, z + 4, shield, ms);
		array.setBlock(x + 7, y + 9, z + 5, shield, ms);
		array.setBlock(x + 7, y + 9, z + 6, shield, ms);
		array.setBlock(x + 7, y + 9, z + 7, shield, mg);
		array.setBlock(x + 7, y + 9, z + 8, shield, mg);
		array.setBlock(x + 7, y + 9, z + 9, shield, mg);
		array.setBlock(x + 7, y + 9, z + 10, shield, ms);
		array.setBlock(x + 7, y + 9, z + 11, shield, ms);
		array.setBlock(x + 7, y + 9, z + 12, shield, ms);
		array.setBlock(x + 7, y + 9, z + 13, shield, ms);
		array.setBlock(x + 7, y + 9, z + 14, shield, ms);
		array.setBlock(x + 7, y + 9, z + 15, shield, mc);
		array.setBlock(x + 7, y + 10, z + 2, shield, ms);
		array.setBlock(x + 7, y + 10, z + 3, shield, ms);
		array.setBlock(x + 7, y + 10, z + 4, shield, ms);
		array.setBlock(x + 7, y + 10, z + 7, shield, mg);
		array.setBlock(x + 7, y + 10, z + 8, shield, mg);
		array.setBlock(x + 7, y + 10, z + 9, shield, mg);
		array.setBlock(x + 7, y + 10, z + 12, shield, ms);
		array.setBlock(x + 7, y + 10, z + 13, shield, ms);
		array.setBlock(x + 7, y + 10, z + 14, shield, ms);
		array.setBlock(x + 7, y + 11, z + 3, shield, ms);
		array.setBlock(x + 7, y + 11, z + 4, shield, ms);
		array.setBlock(x + 7, y + 11, z + 7, shield, mg);
		array.setBlock(x + 7, y + 11, z + 8, shield, mg);
		array.setBlock(x + 7, y + 11, z + 9, shield, mg);
		array.setBlock(x + 7, y + 11, z + 12, shield, ms);
		array.setBlock(x + 7, y + 11, z + 13, shield, ms);
		array.setBlock(x + 7, y + 12, z + 3, shield, mc);
		array.setBlock(x + 7, y + 12, z + 4, shield, ms);
		array.setBlock(x + 7, y + 12, z + 5, shield, ms);
		array.setBlock(x + 7, y + 12, z + 6, shield, mc);
		array.setBlock(x + 7, y + 12, z + 7, shield, mg);
		array.setBlock(x + 7, y + 12, z + 8, shield, mg);
		array.setBlock(x + 7, y + 12, z + 9, shield, mg);
		array.setBlock(x + 7, y + 12, z + 10, shield, mc);
		array.setBlock(x + 7, y + 12, z + 11, shield, ms);
		array.setBlock(x + 7, y + 12, z + 12, shield, ms);
		array.setBlock(x + 7, y + 12, z + 13, shield, mc);
		array.setBlock(x + 7, y + 13, z + 6, shield, mc);
		array.setBlock(x + 7, y + 13, z + 10, shield, mc);
		array.setBlock(x + 8, y + 0, z + 4, shield, ms);
		array.setBlock(x + 8, y + 0, z + 5, shield, ms);
		array.setBlock(x + 8, y + 1, z + 3, shield, ms);
		array.setBlock(x + 8, y + 1, z + 4, shield, BlockType.LIGHT.metadata);
		array.setBlock(x + 8, y + 1, z + 5, shield, ms);
		array.setBlock(x + 8, y + 1, z + 6, shield, ms);
		array.setBlock(x + 8, y + 1, z + 7, shield, ms);
		array.setBlock(x + 8, y + 2, z + 3, shield, ms);
		array.setBlock(x + 8, y + 2, z + 4, ch, 3);
		array.setBlock(x + 8, y + 2, z + 8, shield, ms);
		array.setBlock(x + 8, y + 2, z + 9, shield, ms);
		array.setBlock(x + 8, y + 3, z + 3, shield, ms);
		array.setBlock(x + 8, y + 3, z + 4, shield, ms);

		array.setBlock(x + 8, y + 3, z + 9, shield, ms);
		array.setBlock(x + 8, y + 3, z + 10, shield, ms);
		array.setBlock(x + 8, y + 3, z + 11, shield, BlockType.CLOAK.metadata);
		array.setBlock(x + 8, y + 3, z + 12, shield, BlockType.CLOAK.metadata);
		array.setBlock(x + 8, y + 3, z + 13, shield, BlockType.CLOAK.metadata);
		array.setBlock(x + 8, y + 3, z + 14, shield, ms);
		array.setBlock(x + 8, y + 4, z + 1, shield, ms);
		array.setBlock(x + 8, y + 4, z + 2, shield, ms);
		array.setBlock(x + 8, y + 4, z + 3, shield, ms);
		array.setBlock(x + 8, y + 4, z + 4, shield, ms);
		array.setBlock(x + 8, y + 4, z + 5, shield, ms);
		array.setBlock(x + 8, y + 4, z + 10, shield, ms);
		array.setBlock(x + 8, y + 4, z + 14, shield, ms);
		array.setBlock(x + 8, y + 4, z + 15, shield, ms);
		array.setBlock(x + 8, y + 5, z + 0, shield, BlockType.MOSS.metadata);
		array.setBlock(x + 8, y + 5, z + 1, b2);
		array.setBlock(x + 8, y + 5, z + 2, b2);
		array.setBlock(x + 8, y + 5, z + 3, b2);
		array.setBlock(x + 8, y + 5, z + 4, b2);
		array.setBlock(x + 8, y + 5, z + 5, b2);
		array.setBlock(x + 8, y + 5, z + 6, shield, ms);
		array.setBlock(x + 8, y + 5, z + 11, b2);
		array.setBlock(x + 8, y + 5, z + 12, b2);
		array.setBlock(x + 8, y + 5, z + 13, b2);
		array.setBlock(x + 8, y + 5, z + 14, b2);
		array.setBlock(x + 8, y + 5, z + 15, b2);
		array.setBlock(x + 8, y + 5, z + 16, shield, BlockType.MOSS.metadata);
		array.setBlock(x + 8, y + 6, z + 6, shield, ms);
		array.setBlock(x + 8, y + 7, z + 6, shield, ms);
		array.setBlock(x + 8, y + 8, z + 1, shield, mc);
		array.setBlock(x + 8, y + 8, z + 6, shield, ms);
		array.setBlock(x + 8, y + 8, z + 15, shield, mc);
		array.setBlock(x + 8, y + 9, z + 1, shield, mc);
		array.setBlock(x + 8, y + 9, z + 2, shield, ms);
		array.setBlock(x + 8, y + 9, z + 3, shield, ms);
		array.setBlock(x + 8, y + 9, z + 4, shield, ms);
		array.setBlock(x + 8, y + 9, z + 5, shield, ms);
		array.setBlock(x + 8, y + 9, z + 6, shield, ms);
		array.setBlock(x + 8, y + 9, z + 7, shield, mg);
		array.setBlock(x + 8, y + 9, z + 8, shield, mg);
		array.setBlock(x + 8, y + 9, z + 9, shield, mg);
		array.setBlock(x + 8, y + 9, z + 10, shield, ms);
		array.setBlock(x + 8, y + 9, z + 11, shield, ms);
		array.setBlock(x + 8, y + 9, z + 12, shield, ms);
		array.setBlock(x + 8, y + 9, z + 13, shield, ms);
		array.setBlock(x + 8, y + 9, z + 14, shield, ms);
		array.setBlock(x + 8, y + 9, z + 15, shield, mc);
		array.setBlock(x + 8, y + 10, z + 2, shield, ms);
		array.setBlock(x + 8, y + 10, z + 3, shield, ms);
		array.setBlock(x + 8, y + 10, z + 4, ch, 3);
		array.setBlock(x + 8, y + 10, z + 7, shield, mg);
		array.setBlock(x + 8, y + 10, z + 8, shield, mg);
		array.setBlock(x + 8, y + 10, z + 9, shield, mg);
		array.setBlock(x + 8, y + 10, z + 12, ch, 2);
		array.setBlock(x + 8, y + 10, z + 13, shield, ms);
		array.setBlock(x + 8, y + 10, z + 14, shield, ms);
		array.setBlock(x + 8, y + 11, z + 3, shield, ms);
		array.setBlock(x + 8, y + 11, z + 4, shield, ms);
		array.setBlock(x + 8, y + 11, z + 7, shield, mg);
		array.setBlock(x + 8, y + 11, z + 8, shield, mg);
		array.setBlock(x + 8, y + 11, z + 9, shield, mg);
		array.setBlock(x + 8, y + 11, z + 12, shield, ms);
		array.setBlock(x + 8, y + 11, z + 13, shield, ms);
		array.setBlock(x + 8, y + 12, z + 3, shield, mc);
		array.setBlock(x + 8, y + 12, z + 4, shield, ms);
		array.setBlock(x + 8, y + 12, z + 5, shield, ms);
		array.setBlock(x + 8, y + 12, z + 6, shield, mc);
		array.setBlock(x + 8, y + 12, z + 7, shield, mg);
		array.setBlock(x + 8, y + 12, z + 8, shield, mg);
		array.setBlock(x + 8, y + 12, z + 9, shield, mg);
		array.setBlock(x + 8, y + 12, z + 10, shield, mc);
		array.setBlock(x + 8, y + 12, z + 11, shield, ms);
		array.setBlock(x + 8, y + 12, z + 12, shield, ms);
		array.setBlock(x + 8, y + 12, z + 13, shield, mc);
		array.setBlock(x + 8, y + 13, z + 6, shield, mc);
		array.setBlock(x + 8, y + 13, z + 10, shield, mc);
		array.setBlock(x + 9, y + 0, z + 5, shield, ms);
		array.setBlock(x + 9, y + 1, z + 4, shield, ms);
		array.setBlock(x + 9, y + 1, z + 5, shield, ms);
		array.setBlock(x + 9, y + 1, z + 6, shield, ms);
		array.setBlock(x + 9, y + 1, z + 7, shield, ms);
		array.setBlock(x + 9, y + 2, z + 3, shield, ms);
		array.setBlock(x + 9, y + 2, z + 4, shield, ms);
		array.setBlock(x + 9, y + 2, z + 8, shield, ms);
		array.setBlock(x + 9, y + 2, z + 9, shield, ms);
		array.setBlock(x + 9, y + 3, z + 3, shield, ms);
		array.setBlock(x + 9, y + 3, z + 4, shield, ms);
		array.setBlock(x + 9, y + 3, z + 9, shield, ms);
		array.setBlock(x + 9, y + 3, z + 10, shield, ms);
		array.setBlock(x + 9, y + 3, z + 11, shield, BlockType.CLOAK.metadata);
		array.setBlock(x + 9, y + 3, z + 12, shield, BlockType.CLOAK.metadata);
		array.setBlock(x + 9, y + 3, z + 13, shield, ms);
		array.setBlock(x + 9, y + 3, z + 14, shield, ms);
		array.setBlock(x + 9, y + 4, z + 2, shield, ms);
		array.setBlock(x + 9, y + 4, z + 3, shield, ms);
		array.setBlock(x + 9, y + 4, z + 4, shield, ms);
		array.setBlock(x + 9, y + 4, z + 5, shield, ms);
		array.setBlock(x + 9, y + 4, z + 10, shield, ms);
		array.setBlock(x + 9, y + 4, z + 13, shield, ms);
		array.setBlock(x + 9, y + 4, z + 14, shield, ms);
		array.setBlock(x + 9, y + 4, z + 15, shield, ms);
		array.setBlock(x + 9, y + 5, z + 0, shield, BlockType.MOSS.metadata);
		array.setBlock(x + 9, y + 5, z + 1, shield, ms);
		array.setBlock(x + 9, y + 5, z + 2, b2);
		array.setBlock(x + 9, y + 5, z + 3, b2);
		array.setBlock(x + 9, y + 5, z + 4, b2);
		array.setBlock(x + 9, y + 5, z + 5, b2);
		array.setBlock(x + 9, y + 5, z + 6, shield, ms);
		array.setBlock(x + 9, y + 5, z + 11, b2);
		array.setBlock(x + 9, y + 5, z + 12, b2);
		array.setBlock(x + 9, y + 5, z + 13, shield, ms);
		array.setBlock(x + 9, y + 5, z + 14, shield, ms);
		array.setBlock(x + 9, y + 5, z + 15, shield, ms);
		array.setBlock(x + 9, y + 5, z + 16, shield, BlockType.MOSS.metadata);
		array.setBlock(x + 9, y + 6, z + 1, shield, mc);
		array.setBlock(x + 9, y + 6, z + 6, shield, ms);
		array.setBlock(x + 9, y + 6, z + 13, shield, ms);
		array.setBlock(x + 9, y + 6, z + 14, shield, ms);
		array.setBlock(x + 9, y + 6, z + 15, shield, mc);
		array.setBlock(x + 9, y + 7, z + 1, shield, mc);
		array.setBlock(x + 9, y + 7, z + 6, shield, ms);
		array.setBlock(x + 9, y + 7, z + 13, shield, ms);
		array.setBlock(x + 9, y + 7, z + 14, shield, ms);
		array.setBlock(x + 9, y + 7, z + 15, shield, mc);
		array.setBlock(x + 9, y + 8, z + 1, shield, mc);
		array.setBlock(x + 9, y + 8, z + 6, shield, ms);
		array.setBlock(x + 9, y + 8, z + 13, shield, ms);
		array.setBlock(x + 9, y + 8, z + 14, shield, ms);
		array.setBlock(x + 9, y + 8, z + 15, shield, mc);
		array.setBlock(x + 9, y + 9, z + 1, shield, mc);
		array.setBlock(x + 9, y + 9, z + 2, shield, ms);
		array.setBlock(x + 9, y + 9, z + 3, shield, ms);
		array.setBlock(x + 9, y + 9, z + 4, shield, ms);
		array.setBlock(x + 9, y + 9, z + 5, shield, ms);
		array.setBlock(x + 9, y + 9, z + 6, shield, ms);
		array.setBlock(x + 9, y + 9, z + 7, shield, mg);
		array.setBlock(x + 9, y + 9, z + 8, shield, mg);
		array.setBlock(x + 9, y + 9, z + 9, shield, mg);
		array.setBlock(x + 9, y + 9, z + 10, shield, ms);
		array.setBlock(x + 9, y + 9, z + 11, shield, ms);
		array.setBlock(x + 9, y + 9, z + 12, shield, ms);
		array.setBlock(x + 9, y + 9, z + 13, shield, ms);
		array.setBlock(x + 9, y + 9, z + 14, shield, ms);
		array.setBlock(x + 9, y + 9, z + 15, shield, mc);
		array.setBlock(x + 9, y + 10, z + 2, shield, ms);
		array.setBlock(x + 9, y + 10, z + 3, shield, ms);
		array.setBlock(x + 9, y + 10, z + 4, shield, ms);
		array.setBlock(x + 9, y + 10, z + 7, shield, mg);
		array.setBlock(x + 9, y + 10, z + 8, shield, mg);
		array.setBlock(x + 9, y + 10, z + 9, shield, mg);
		array.setBlock(x + 9, y + 10, z + 12, shield, ms);
		array.setBlock(x + 9, y + 10, z + 13, shield, ms);
		array.setBlock(x + 9, y + 10, z + 14, shield, ms);
		array.setBlock(x + 9, y + 11, z + 3, shield, ms);
		array.setBlock(x + 9, y + 11, z + 4, shield, ms);
		array.setBlock(x + 9, y + 11, z + 7, shield, mg);
		array.setBlock(x + 9, y + 11, z + 8, shield, mg);
		array.setBlock(x + 9, y + 11, z + 9, shield, mg);
		array.setBlock(x + 9, y + 11, z + 12, shield, ms);
		array.setBlock(x + 9, y + 11, z + 13, shield, ms);
		array.setBlock(x + 9, y + 12, z + 3, shield, mc);
		array.setBlock(x + 9, y + 12, z + 4, shield, ms);
		array.setBlock(x + 9, y + 12, z + 5, shield, ms);
		array.setBlock(x + 9, y + 12, z + 6, shield, mc);
		array.setBlock(x + 9, y + 12, z + 7, shield, mg);
		array.setBlock(x + 9, y + 12, z + 8, shield, mg);
		array.setBlock(x + 9, y + 12, z + 9, shield, mg);
		array.setBlock(x + 9, y + 12, z + 10, shield, mc);
		array.setBlock(x + 9, y + 12, z + 11, shield, ms);
		array.setBlock(x + 9, y + 12, z + 12, shield, ms);
		array.setBlock(x + 9, y + 12, z + 13, shield, mc);
		array.setBlock(x + 9, y + 13, z + 6, shield, mc);
		array.setBlock(x + 9, y + 13, z + 10, shield, mc);
		array.setBlock(x + 10, y + 0, z + 5, shield, ms);
		array.setBlock(x + 10, y + 1, z + 4, shield, ms);
		array.setBlock(x + 10, y + 1, z + 5, shield, BlockType.LIGHT.metadata);
		array.setBlock(x + 10, y + 1, z + 6, shield, ms);
		array.setBlock(x + 10, y + 1, z + 7, shield, ms);
		array.setBlock(x + 10, y + 2, z + 4, shield, ms);
		array.setBlock(x + 10, y + 2, z + 5, ch);
		array.setBlock(x + 10, y + 2, z + 6, shield, ms);
		array.setBlock(x + 10, y + 2, z + 7, shield, ms);
		array.setBlock(x + 10, y + 2, z + 8, shield, ms);
		array.setBlock(x + 10, y + 2, z + 9, shield, ms);
		array.setBlock(x + 10, y + 3, z + 4, shield, ms);
		array.setBlock(x + 10, y + 3, z + 5, shield, ms);
		array.setBlock(x + 10, y + 3, z + 6, shield, ms);
		array.setBlock(x + 10, y + 3, z + 7, shield, ms);
		array.setBlock(x + 10, y + 3, z + 8, shield, ms);
		array.setBlock(x + 10, y + 3, z + 9, shield, ms);
		array.setBlock(x + 10, y + 3, z + 10, shield, ms);
		array.setBlock(x + 10, y + 3, z + 11, shield, BlockType.CLOAK.metadata);
		array.setBlock(x + 10, y + 3, z + 12, shield, BlockType.CLOAK.metadata);
		array.setBlock(x + 10, y + 3, z + 13, shield, BlockType.CLOAK.metadata);
		array.setBlock(x + 10, y + 3, z + 14, shield, ms);
		array.setBlock(x + 10, y + 4, z + 2, shield, ms);
		array.setBlock(x + 10, y + 4, z + 3, shield, ms);
		array.setBlock(x + 10, y + 4, z + 4, shield, ms);
		array.setBlock(x + 10, y + 4, z + 5, shield, ms);
		array.setBlock(x + 10, y + 4, z + 6, shield, ms);
		array.setBlock(x + 10, y + 4, z + 7, shield, ms);
		array.setBlock(x + 10, y + 4, z + 8, shield, ms);
		array.setBlock(x + 10, y + 4, z + 9, shield, ms);
		array.setBlock(x + 10, y + 4, z + 10, shield, ms);
		array.setBlock(x + 10, y + 4, z + 14, shield, ms);
		array.setBlock(x + 10, y + 4, z + 15, shield, ms);
		array.setBlock(x + 10, y + 5, z + 0, shield, BlockType.MOSS.metadata);
		array.setBlock(x + 10, y + 5, z + 1, shield, ms);
		array.setBlock(x + 10, y + 5, z + 2, b2);
		array.setBlock(x + 10, y + 5, z + 3, b2);
		array.setBlock(x + 10, y + 5, z + 4, b2);
		array.setBlock(x + 10, y + 5, z + 5, b2);
		array.setBlock(x + 10, y + 5, z + 6, shield, ms);
		array.setBlock(x + 10, y + 5, z + 7, shield, ms);
		array.setBlock(x + 10, y + 5, z + 8, shield, ms);
		array.setBlock(x + 10, y + 5, z + 9, shield, ms);
		array.setBlock(x + 10, y + 5, z + 10, shield, ms);
		array.setBlock(x + 10, y + 5, z + 11, shield, ms);
		array.setBlock(x + 10, y + 5, z + 12, shield, ms);
		array.setBlock(x + 10, y + 5, z + 13, b2);
		array.setBlock(x + 10, y + 5, z + 14, b2);
		array.setBlock(x + 10, y + 5, z + 15, shield, ms);
		array.setBlock(x + 10, y + 5, z + 16, shield, BlockType.MOSS.metadata);
		array.setBlock(x + 10, y + 6, z + 1, shield, mg);
		array.setBlock(x + 10, y + 6, z + 6, shield, ms);
		array.setBlock(x + 10, y + 6, z + 7, shield, ms);
		array.setBlock(x + 10, y + 6, z + 8, shield, ms);
		array.setBlock(x + 10, y + 6, z + 9, shield, ms);
		array.setBlock(x + 10, y + 6, z + 10, shield, ms);
		array.setBlock(x + 10, y + 6, z + 11, shield, ms);
		array.setBlock(x + 10, y + 6, z + 12, shield, ms);
		array.setBlock(x + 10, y + 6, z + 15, shield, mg);
		array.setBlock(x + 10, y + 7, z + 1, shield, mg);
		array.setBlock(x + 10, y + 7, z + 6, shield, ms);
		array.setBlock(x + 10, y + 7, z + 7, shield, ms);
		array.setBlock(x + 10, y + 7, z + 8, shield, ms);
		array.setBlock(x + 10, y + 7, z + 9, shield, ms);
		array.setBlock(x + 10, y + 7, z + 10, shield, ms);
		array.setBlock(x + 10, y + 7, z + 11, ch);
		array.setBlock(x + 10, y + 7, z + 12, shield, ms);
		array.setBlock(x + 10, y + 7, z + 15, shield, mg);
		array.setBlock(x + 10, y + 8, z + 1, shield, mg);
		array.setBlock(x + 10, y + 8, z + 6, shield, ms);
		array.setBlock(x + 10, y + 8, z + 7, shield, ms);
		array.setBlock(x + 10, y + 8, z + 8, shield, ms);
		array.setBlock(x + 10, y + 8, z + 9, shield, ms);
		array.setBlock(x + 10, y + 8, z + 10, shield, ms);
		array.setBlock(x + 10, y + 8, z + 11, shield, ms);
		array.setBlock(x + 10, y + 8, z + 12, shield, ms);
		array.setBlock(x + 10, y + 8, z + 15, shield, mg);
		array.setBlock(x + 10, y + 9, z + 1, shield, mc);
		array.setBlock(x + 10, y + 9, z + 2, shield, ms);
		array.setBlock(x + 10, y + 9, z + 3, shield, ms);
		array.setBlock(x + 10, y + 9, z + 4, shield, ms);
		array.setBlock(x + 10, y + 9, z + 5, shield, ms);
		array.setBlock(x + 10, y + 9, z + 6, shield, ms);
		array.setBlock(x + 10, y + 9, z + 7, shield, ms);
		array.setBlock(x + 10, y + 9, z + 8, shield, ms);
		array.setBlock(x + 10, y + 9, z + 9, shield, ms);
		array.setBlock(x + 10, y + 9, z + 10, shield, ms);
		array.setBlock(x + 10, y + 9, z + 11, shield, ms);
		array.setBlock(x + 10, y + 9, z + 12, shield, ms);
		array.setBlock(x + 10, y + 9, z + 13, shield, ms);
		array.setBlock(x + 10, y + 9, z + 14, shield, ms);
		array.setBlock(x + 10, y + 9, z + 15, shield, mc);
		array.setBlock(x + 10, y + 10, z + 2, shield, ms);
		array.setBlock(x + 10, y + 10, z + 3, shield, ms);
		array.setBlock(x + 10, y + 10, z + 4, shield, ms);
		array.setBlock(x + 10, y + 10, z + 12, shield, ms);
		array.setBlock(x + 10, y + 10, z + 13, shield, ms);
		array.setBlock(x + 10, y + 10, z + 14, shield, ms);
		array.setBlock(x + 10, y + 11, z + 3, shield, ms);
		array.setBlock(x + 10, y + 11, z + 4, shield, ms);
		array.setBlock(x + 10, y + 11, z + 12, shield, ms);
		array.setBlock(x + 10, y + 11, z + 13, shield, ms);
		array.setBlock(x + 10, y + 12, z + 3, shield, mc);
		array.setBlock(x + 10, y + 12, z + 4, shield, ms);
		array.setBlock(x + 10, y + 12, z + 5, shield, mc);
		array.setBlock(x + 10, y + 12, z + 6, shield, mc);
		array.setBlock(x + 10, y + 12, z + 7, shield, mc);
		array.setBlock(x + 10, y + 12, z + 8, shield, mc);
		array.setBlock(x + 10, y + 12, z + 9, shield, mc);
		array.setBlock(x + 10, y + 12, z + 10, shield, mc);
		array.setBlock(x + 10, y + 12, z + 11, shield, mc);
		array.setBlock(x + 10, y + 12, z + 12, shield, ms);
		array.setBlock(x + 10, y + 12, z + 13, shield, mc);
		array.setBlock(x + 10, y + 13, z + 6, shield, mc);
		array.setBlock(x + 10, y + 13, z + 7, shield, mc);
		array.setBlock(x + 10, y + 13, z + 8, shield, mc);
		array.setBlock(x + 10, y + 13, z + 9, shield, mc);
		array.setBlock(x + 10, y + 13, z + 10, shield, mc);
		array.setBlock(x + 10, y + 14, z + 6, shield, mc);
		array.setBlock(x + 10, y + 14, z + 10, shield, mc);
		array.setBlock(x + 11, y + 1, z + 5, shield, ms);
		array.setBlock(x + 11, y + 2, z + 4, shield, ms);
		array.setBlock(x + 11, y + 2, z + 5, shield, ms);
		array.setBlock(x + 11, y + 2, z + 6, shield, ms);
		array.setBlock(x + 11, y + 3, z + 4, shield, ms);
		array.setBlock(x + 11, y + 3, z + 5, shield, ms);
		array.setBlock(x + 11, y + 3, z + 6, shield, ms);
		array.setBlock(x + 11, y + 3, z + 7, shield, BlockType.CLOAK.metadata);
		array.setBlock(x + 11, y + 3, z + 8, shield, BlockType.CLOAK.metadata);
		array.setBlock(x + 11, y + 3, z + 9, shield, BlockType.CLOAK.metadata);
		array.setBlock(x + 11, y + 3, z + 10, shield, BlockType.CLOAK.metadata);
		array.setBlock(x + 11, y + 3, z + 11, shield, ms);
		array.setBlock(x + 11, y + 3, z + 12, shield, BlockType.CLOAK.metadata);
		array.setBlock(x + 11, y + 3, z + 13, shield, BlockType.CLOAK.metadata);
		array.setBlock(x + 11, y + 3, z + 14, shield, ms);
		array.setBlock(x + 11, y + 4, z + 2, shield, ms);
		array.setBlock(x + 11, y + 4, z + 3, shield, ms);
		array.setBlock(x + 11, y + 4, z + 4, shield, ms);
		array.setBlock(x + 11, y + 4, z + 5, shield, ms);
		array.setBlock(x + 11, y + 4, z + 6, shield, ms);
		array.setBlock(x + 11, y + 4, z + 11, shield, ms);
		array.setBlock(x + 11, y + 4, z + 14, shield, ms);
		array.setBlock(x + 11, y + 4, z + 15, shield, ms);
		array.setBlock(x + 11, y + 5, z + 1, shield, ms);
		array.setBlock(x + 11, y + 5, z + 2, b2);
		array.setBlock(x + 11, y + 5, z + 3, b2);
		array.setBlock(x + 11, y + 5, z + 4, b2);
		array.setBlock(x + 11, y + 5, z + 5, shield, ms);
		array.setBlock(x + 11, y + 5, z + 6, shield, ms);
		array.setBlock(x + 11, y + 5, z + 7, b2);
		array.setBlock(x + 11, y + 5, z + 8, b2);
		array.setBlock(x + 11, y + 5, z + 9, b2);
		array.setBlock(x + 11, y + 5, z + 10, b2);
		array.setBlock(x + 11, y + 5, z + 11, shield, ms);
		array.setBlock(x + 11, y + 5, z + 12, b2);
		array.setBlock(x + 11, y + 5, z + 13, b2);
		array.setBlock(x + 11, y + 5, z + 14, b2);
		array.setBlock(x + 11, y + 5, z + 15, shield, ms);
		array.setBlock(x + 11, y + 6, z + 1, shield, mg);
		array.setBlock(x + 11, y + 6, z + 5, shield, ms);
		array.setBlock(x + 11, y + 6, z + 6, shield, ms);
		array.setBlock(x + 11, y + 6, z + 11, shield, ms);
		array.setBlock(x + 11, y + 6, z + 15, shield, mg);
		array.setBlock(x + 11, y + 7, z + 1, shield, mg);
		array.setBlock(x + 11, y + 7, z + 5, shield, BlockType.LIGHT.metadata);
		array.setBlock(x + 11, y + 7, z + 6, ch, 3);
		array.setBlock(x + 11, y + 7, z + 11, shield, BlockType.LIGHT.metadata);
		array.setBlock(x + 11, y + 7, z + 15, shield, mg);
		array.setBlock(x + 11, y + 8, z + 1, shield, mg);
		array.setBlock(x + 11, y + 8, z + 5, shield, ms);
		array.setBlock(x + 11, y + 8, z + 6, shield, ms);
		array.setBlock(x + 11, y + 8, z + 11, shield, ms);
		array.setBlock(x + 11, y + 8, z + 15, shield, mg);
		array.setBlock(x + 11, y + 9, z + 1, shield, mc);
		array.setBlock(x + 11, y + 9, z + 2, shield, ms);
		array.setBlock(x + 11, y + 9, z + 3, shield, ms);
		array.setBlock(x + 11, y + 9, z + 4, shield, ms);
		array.setBlock(x + 11, y + 9, z + 5, shield, ms);
		array.setBlock(x + 11, y + 9, z + 6, shield, ms);
		array.setBlock(x + 11, y + 9, z + 7, shield, ms);
		array.setBlock(x + 11, y + 9, z + 8, shield, ms);
		array.setBlock(x + 11, y + 9, z + 9, shield, ms);
		array.setBlock(x + 11, y + 9, z + 10, shield, ms);
		array.setBlock(x + 11, y + 9, z + 11, shield, ms);
		array.setBlock(x + 11, y + 9, z + 12, shield, ms);
		array.setBlock(x + 11, y + 9, z + 13, shield, ms);
		array.setBlock(x + 11, y + 9, z + 14, shield, ms);
		array.setBlock(x + 11, y + 9, z + 15, shield, mc);
		array.setBlock(x + 11, y + 10, z + 1, shield, mc);
		array.setBlock(x + 11, y + 10, z + 2, shield, mc);
		array.setBlock(x + 11, y + 10, z + 3, shield, mc);
		array.setBlock(x + 11, y + 10, z + 4, shield, ms);
		array.setBlock(x + 11, y + 10, z + 5, shield, ms);
		array.setBlock(x + 11, y + 10, z + 11, shield, ms);
		array.setBlock(x + 11, y + 10, z + 12, shield, ms);
		array.setBlock(x + 11, y + 10, z + 13, shield, mc);
		array.setBlock(x + 11, y + 10, z + 14, shield, mc);
		array.setBlock(x + 11, y + 10, z + 15, shield, mc);
		array.setBlock(x + 11, y + 11, z + 3, shield, mc);
		array.setBlock(x + 11, y + 11, z + 4, shield, ms);
		array.setBlock(x + 11, y + 11, z + 5, shield, ms);
		array.setBlock(x + 11, y + 11, z + 11, shield, ms);
		array.setBlock(x + 11, y + 11, z + 12, shield, ms);
		array.setBlock(x + 11, y + 11, z + 13, shield, mc);
		array.setBlock(x + 11, y + 12, z + 3, shield, mc);
		array.setBlock(x + 11, y + 12, z + 4, shield, mc);
		array.setBlock(x + 11, y + 12, z + 5, shield, mc);
		array.setBlock(x + 11, y + 12, z + 6, shield, mc);
		array.setBlock(x + 11, y + 12, z + 7, shield, ms);
		array.setBlock(x + 11, y + 12, z + 8, shield, ms);
		array.setBlock(x + 11, y + 12, z + 9, shield, ms);
		array.setBlock(x + 11, y + 12, z + 10, shield, mc);
		array.setBlock(x + 11, y + 12, z + 11, shield, mc);
		array.setBlock(x + 11, y + 12, z + 12, shield, mc);
		array.setBlock(x + 11, y + 12, z + 13, shield, mc);
		array.setBlock(x + 11, y + 13, z + 3, shield, mc);
		array.setBlock(x + 11, y + 13, z + 13, shield, mc);
		array.setBlock(x + 12, y + 3, z + 6, shield, ms);
		array.setBlock(x + 12, y + 3, z + 7, shield, BlockType.CLOAK.metadata);
		array.setBlock(x + 12, y + 3, z + 8, shield, BlockType.CLOAK.metadata);
		array.setBlock(x + 12, y + 3, z + 9, shield, BlockType.CLOAK.metadata);
		array.setBlock(x + 12, y + 3, z + 10, shield, BlockType.CLOAK.metadata);
		array.setBlock(x + 12, y + 3, z + 11, shield, BlockType.CLOAK.metadata);
		array.setBlock(x + 12, y + 3, z + 12, shield, BlockType.CLOAK.metadata);
		array.setBlock(x + 12, y + 3, z + 13, shield, BlockType.CLOAK.metadata);
		array.setBlock(x + 12, y + 3, z + 14, shield, ms);
		array.setBlock(x + 12, y + 4, z + 2, shield, ms);
		array.setBlock(x + 12, y + 4, z + 3, shield, ms);
		array.setBlock(x + 12, y + 4, z + 4, shield, ms);
		array.setBlock(x + 12, y + 4, z + 5, shield, ms);
		array.setBlock(x + 12, y + 4, z + 6, shield, ms);
		array.setBlock(x + 12, y + 4, z + 14, shield, ms);
		array.setBlock(x + 12, y + 4, z + 15, shield, ms);
		array.setBlock(x + 12, y + 5, z + 1, shield, ms);
		array.setBlock(x + 12, y + 5, z + 2, b2);
		array.setBlock(x + 12, y + 5, z + 3, b2);
		array.setBlock(x + 12, y + 5, z + 4, b2);
		array.setBlock(x + 12, y + 5, z + 5, b2);
		array.setBlock(x + 12, y + 5, z + 6, shield, ms);
		array.setBlock(x + 12, y + 5, z + 7, b2);
		array.setBlock(x + 12, y + 5, z + 8, b2);
		array.setBlock(x + 12, y + 5, z + 9, b2);
		array.setBlock(x + 12, y + 5, z + 10, b2);
		array.setBlock(x + 12, y + 5, z + 11, b2);
		array.setBlock(x + 12, y + 5, z + 12, b2);
		array.setBlock(x + 12, y + 5, z + 13, b2);
		array.setBlock(x + 12, y + 5, z + 14, b2);
		array.setBlock(x + 12, y + 5, z + 15, shield, ms);
		array.setBlock(x + 12, y + 6, z + 1, shield, mg);
		array.setBlock(x + 12, y + 6, z + 6, shield, ms);
		array.setBlock(x + 12, y + 6, z + 15, shield, mg);
		array.setBlock(x + 12, y + 7, z + 1, shield, mg);
		array.setBlock(x + 12, y + 7, z + 6, shield, ms);
		array.setBlock(x + 12, y + 7, z + 15, shield, mg);
		array.setBlock(x + 12, y + 8, z + 1, shield, mg);
		array.setBlock(x + 12, y + 8, z + 6, shield, ms);
		array.setBlock(x + 12, y + 8, z + 15, shield, mg);
		array.setBlock(x + 12, y + 9, z + 1, shield, mc);
		array.setBlock(x + 12, y + 9, z + 2, shield, ms);
		array.setBlock(x + 12, y + 9, z + 3, shield, ms);
		array.setBlock(x + 12, y + 9, z + 4, shield, ms);
		array.setBlock(x + 12, y + 9, z + 5, shield, ms);
		array.setBlock(x + 12, y + 9, z + 6, shield, ms);
		array.setBlock(x + 12, y + 9, z + 7, shield, ms);
		array.setBlock(x + 12, y + 9, z + 8, shield, ms);
		array.setBlock(x + 12, y + 9, z + 9, shield, ms);
		array.setBlock(x + 12, y + 9, z + 10, shield, ms);
		array.setBlock(x + 12, y + 9, z + 11, shield, ms);
		array.setBlock(x + 12, y + 9, z + 12, shield, ms);
		array.setBlock(x + 12, y + 9, z + 13, shield, ms);
		array.setBlock(x + 12, y + 9, z + 14, shield, ms);
		array.setBlock(x + 12, y + 9, z + 15, shield, mc);
		array.setBlock(x + 12, y + 10, z + 5, shield, ms);
		array.setBlock(x + 12, y + 10, z + 6, shield, ms);
		array.setBlock(x + 12, y + 10, z + 7, shield, ms);
		array.setBlock(x + 12, y + 10, z + 8, ch);
		array.setBlock(x + 12, y + 10, z + 9, shield, ms);
		array.setBlock(x + 12, y + 10, z + 10, shield, ms);
		array.setBlock(x + 12, y + 10, z + 11, shield, ms);
		array.setBlock(x + 12, y + 11, z + 5, shield, ms);
		array.setBlock(x + 12, y + 11, z + 6, shield, ms);
		array.setBlock(x + 12, y + 11, z + 7, shield, ms);
		array.setBlock(x + 12, y + 11, z + 8, shield, ms);
		array.setBlock(x + 12, y + 11, z + 9, shield, ms);
		array.setBlock(x + 12, y + 11, z + 10, shield, ms);
		array.setBlock(x + 12, y + 11, z + 11, shield, ms);
		array.setBlock(x + 12, y + 12, z + 5, shield, mc);
		array.setBlock(x + 12, y + 12, z + 6, shield, ms);
		array.setBlock(x + 12, y + 12, z + 7, shield, ms);
		array.setBlock(x + 12, y + 12, z + 8, shield, ms);
		array.setBlock(x + 12, y + 12, z + 9, shield, ms);
		array.setBlock(x + 12, y + 12, z + 10, shield, ms);
		array.setBlock(x + 12, y + 12, z + 11, shield, mc);
		array.setBlock(x + 13, y + 3, z + 6, shield, ms);
		array.setBlock(x + 13, y + 3, z + 7, shield, ms);
		array.setBlock(x + 13, y + 3, z + 8, shield, BlockType.CLOAK.metadata);
		array.setBlock(x + 13, y + 3, z + 9, shield, BlockType.CLOAK.metadata);
		array.setBlock(x + 13, y + 3, z + 10, shield, BlockType.CLOAK.metadata);
		array.setBlock(x + 13, y + 3, z + 11, shield, BlockType.CLOAK.metadata);
		array.setBlock(x + 13, y + 3, z + 12, shield, BlockType.CLOAK.metadata);
		array.setBlock(x + 13, y + 3, z + 13, shield, BlockType.CLOAK.metadata);
		array.setBlock(x + 13, y + 3, z + 14, shield, ms);
		array.setBlock(x + 13, y + 4, z + 2, shield, ms);
		array.setBlock(x + 13, y + 4, z + 3, shield, ms);
		array.setBlock(x + 13, y + 4, z + 4, shield, ms);
		array.setBlock(x + 13, y + 4, z + 5, shield, ms);
		array.setBlock(x + 13, y + 4, z + 6, shield, ms);
		array.setBlock(x + 13, y + 4, z + 7, shield, ms);
		array.setBlock(x + 13, y + 4, z + 14, shield, ms);
		array.setBlock(x + 13, y + 4, z + 15, shield, ms);
		array.setBlock(x + 13, y + 5, z + 1, shield, ms);
		array.setBlock(x + 13, y + 5, z + 2, b2);
		array.setBlock(x + 13, y + 5, z + 3, b2);
		array.setBlock(x + 13, y + 5, z + 4, b2);
		array.setBlock(x + 13, y + 5, z + 5, b2);
		array.setBlock(x + 13, y + 5, z + 6, b2);
		array.setBlock(x + 13, y + 5, z + 7, shield, ms);
		array.setBlock(x + 13, y + 5, z + 8, b2);
		array.setBlock(x + 13, y + 5, z + 9, b2);
		array.setBlock(x + 13, y + 5, z + 10, b2);
		array.setBlock(x + 13, y + 5, z + 11, b2);
		array.setBlock(x + 13, y + 5, z + 12, b2);
		array.setBlock(x + 13, y + 5, z + 13, b2);
		array.setBlock(x + 13, y + 5, z + 14, b2);
		array.setBlock(x + 13, y + 5, z + 15, shield, ms);
		array.setBlock(x + 13, y + 6, z + 1, shield, mc);
		array.setBlock(x + 13, y + 6, z + 7, shield, ms);
		array.setBlock(x + 13, y + 6, z + 15, shield, mc);
		array.setBlock(x + 13, y + 7, z + 1, shield, mc);
		array.setBlock(x + 13, y + 7, z + 7, shield, ms);
		array.setBlock(x + 13, y + 7, z + 15, shield, mc);
		array.setBlock(x + 13, y + 8, z + 1, shield, mc);
		array.setBlock(x + 13, y + 8, z + 7, shield, ms);
		array.setBlock(x + 13, y + 8, z + 15, shield, mc);
		array.setBlock(x + 13, y + 9, z + 1, shield, mc);
		array.setBlock(x + 13, y + 9, z + 2, shield, mc);
		array.setBlock(x + 13, y + 9, z + 3, shield, ms);
		array.setBlock(x + 13, y + 9, z + 4, shield, ms);
		array.setBlock(x + 13, y + 9, z + 5, shield, ms);
		array.setBlock(x + 13, y + 9, z + 6, shield, ms);
		array.setBlock(x + 13, y + 9, z + 7, shield, ms);
		array.setBlock(x + 13, y + 9, z + 8, shield, ms);
		array.setBlock(x + 13, y + 9, z + 9, shield, ms);
		array.setBlock(x + 13, y + 9, z + 10, shield, ms);
		array.setBlock(x + 13, y + 9, z + 11, shield, ms);
		array.setBlock(x + 13, y + 9, z + 12, shield, ms);
		array.setBlock(x + 13, y + 9, z + 13, shield, ms);
		array.setBlock(x + 13, y + 9, z + 14, shield, mc);
		array.setBlock(x + 13, y + 9, z + 15, shield, mc);
		array.setBlock(x + 13, y + 10, z + 1, shield, mc);
		array.setBlock(x + 13, y + 10, z + 5, shield, mc);
		array.setBlock(x + 13, y + 10, z + 6, shield, ms);
		array.setBlock(x + 13, y + 10, z + 7, shield, ms);
		array.setBlock(x + 13, y + 10, z + 8, shield, ms);
		array.setBlock(x + 13, y + 10, z + 9, shield, ms);
		array.setBlock(x + 13, y + 10, z + 10, shield, ms);
		array.setBlock(x + 13, y + 10, z + 11, shield, mc);
		array.setBlock(x + 13, y + 10, z + 15, shield, mc);
		array.setBlock(x + 13, y + 11, z + 5, shield, mc);
		array.setBlock(x + 13, y + 11, z + 6, shield, ms);
		array.setBlock(x + 13, y + 11, z + 7, shield, ms);
		array.setBlock(x + 13, y + 11, z + 8, shield, ms);
		array.setBlock(x + 13, y + 11, z + 9, shield, ms);
		array.setBlock(x + 13, y + 11, z + 10, shield, ms);
		array.setBlock(x + 13, y + 11, z + 11, shield, mc);
		array.setBlock(x + 13, y + 12, z + 5, shield, mc);
		array.setBlock(x + 13, y + 12, z + 6, shield, mc);
		array.setBlock(x + 13, y + 12, z + 7, shield, mc);
		array.setBlock(x + 13, y + 12, z + 8, shield, mc);
		array.setBlock(x + 13, y + 12, z + 9, shield, mc);
		array.setBlock(x + 13, y + 12, z + 10, shield, mc);
		array.setBlock(x + 13, y + 12, z + 11, shield, mc);
		array.setBlock(x + 13, y + 13, z + 5, shield, mc);
		array.setBlock(x + 13, y + 13, z + 11, shield, mc);
		array.setBlock(x + 14, y + 3, z + 7, shield, ms);
		array.setBlock(x + 14, y + 3, z + 8, shield, ms);
		array.setBlock(x + 14, y + 3, z + 9, shield, ms);
		array.setBlock(x + 14, y + 3, z + 10, shield, ms);
		array.setBlock(x + 14, y + 3, z + 11, shield, ms);
		array.setBlock(x + 14, y + 3, z + 12, shield, ms);
		array.setBlock(x + 14, y + 3, z + 13, shield, ms);
		array.setBlock(x + 14, y + 3, z + 14, shield, ms);
		array.setBlock(x + 14, y + 4, z + 3, shield, ms);
		array.setBlock(x + 14, y + 4, z + 4, shield, ms);
		array.setBlock(x + 14, y + 4, z + 5, shield, ms);
		array.setBlock(x + 14, y + 4, z + 6, shield, ms);
		array.setBlock(x + 14, y + 4, z + 7, shield, ms);
		array.setBlock(x + 14, y + 4, z + 8, shield, ms);
		array.setBlock(x + 14, y + 4, z + 9, shield, ms);
		array.setBlock(x + 14, y + 4, z + 10, shield, ms);
		array.setBlock(x + 14, y + 4, z + 11, shield, ms);
		array.setBlock(x + 14, y + 4, z + 12, shield, ms);
		array.setBlock(x + 14, y + 4, z + 13, shield, ms);
		array.setBlock(x + 14, y + 4, z + 15, shield, ms);
		array.setBlock(x + 14, y + 5, z + 2, shield, ms);
		array.setBlock(x + 14, y + 5, z + 3, b2);
		array.setBlock(x + 14, y + 5, z + 4, b2);
		array.setBlock(x + 14, y + 5, z + 5, b2);
		array.setBlock(x + 14, y + 5, z + 6, b2);
		array.setBlock(x + 14, y + 5, z + 7, shield, ms);
		array.setBlock(x + 14, y + 5, z + 8, b2);
		array.setBlock(x + 14, y + 5, z + 9, b2);
		array.setBlock(x + 14, y + 5, z + 10, b2);
		array.setBlock(x + 14, y + 5, z + 11, b2);
		array.setBlock(x + 14, y + 5, z + 12, b2);
		array.setBlock(x + 14, y + 5, z + 13, b2);
		array.setBlock(x + 14, y + 5, z + 14, shield, ms);
		array.setBlock(x + 14, y + 6, z + 2, shield, ms);
		array.setBlock(x + 14, y + 6, z + 7, shield, ms);
		array.setBlock(x + 14, y + 6, z + 14, shield, ms);
		array.setBlock(x + 14, y + 7, z + 2, shield, ms);
		array.setBlock(x + 14, y + 7, z + 7, shield, ms);
		array.setBlock(x + 14, y + 7, z + 14, shield, ms);
		array.setBlock(x + 14, y + 8, z + 2, shield, ms);
		array.setBlock(x + 14, y + 8, z + 7, shield, ms);
		array.setBlock(x + 14, y + 8, z + 14, shield, ms);
		array.setBlock(x + 14, y + 9, z + 2, shield, mc);
		array.setBlock(x + 14, y + 9, z + 3, shield, mc);
		array.setBlock(x + 14, y + 9, z + 4, shield, ms);
		array.setBlock(x + 14, y + 9, z + 5, shield, ms);
		array.setBlock(x + 14, y + 9, z + 6, shield, ms);
		array.setBlock(x + 14, y + 9, z + 7, shield, ms);
		array.setBlock(x + 14, y + 9, z + 8, shield, ms);
		array.setBlock(x + 14, y + 9, z + 9, shield, ms);
		array.setBlock(x + 14, y + 9, z + 10, shield, ms);
		array.setBlock(x + 14, y + 9, z + 11, shield, ms);
		array.setBlock(x + 14, y + 9, z + 12, shield, ms);
		array.setBlock(x + 14, y + 9, z + 13, shield, mc);
		array.setBlock(x + 14, y + 9, z + 14, shield, mc);
		array.setBlock(x + 14, y + 10, z + 5, shield, mc);
		array.setBlock(x + 14, y + 10, z + 6, shield, ms);
		array.setBlock(x + 14, y + 10, z + 7, shield, ms);
		array.setBlock(x + 14, y + 10, z + 8, shield, ms);
		array.setBlock(x + 14, y + 10, z + 9, shield, ms);
		array.setBlock(x + 14, y + 10, z + 10, shield, ms);
		array.setBlock(x + 14, y + 10, z + 11, shield, mc);
		array.setBlock(x + 15, y + 4, z + 8, shield, ms);
		array.setBlock(x + 15, y + 4, z + 9, shield, ms);
		array.setBlock(x + 15, y + 4, z + 10, shield, ms);
		array.setBlock(x + 15, y + 4, z + 11, shield, ms);
		array.setBlock(x + 15, y + 4, z + 12, shield, ms);
		array.setBlock(x + 15, y + 4, z + 13, shield, ms);
		array.setBlock(x + 15, y + 4, z + 14, shield, ms);
		array.setBlock(x + 15, y + 5, z + 3, shield, ms);
		array.setBlock(x + 15, y + 5, z + 4, shield, ms);
		array.setBlock(x + 15, y + 5, z + 5, shield, ms);
		array.setBlock(x + 15, y + 5, z + 6, shield, ms);
		array.setBlock(x + 15, y + 5, z + 7, shield, ms);
		array.setBlock(x + 15, y + 5, z + 8, b2);
		array.setBlock(x + 15, y + 5, z + 9, shield, ms);
		array.setBlock(x + 15, y + 5, z + 10, shield, ms);
		array.setBlock(x + 15, y + 5, z + 11, shield, ms);
		array.setBlock(x + 15, y + 5, z + 12, shield, ms);
		array.setBlock(x + 15, y + 5, z + 13, shield, ms);
		array.setBlock(x + 15, y + 6, z + 3, shield, mc);
		array.setBlock(x + 15, y + 6, z + 4, shield, mg);
		array.setBlock(x + 15, y + 6, z + 5, shield, mg);
		array.setBlock(x + 15, y + 6, z + 6, shield, mg);
		array.setBlock(x + 15, y + 6, z + 7, shield, mc);
		array.setBlock(x + 15, y + 6, z + 9, shield, mc);
		array.setBlock(x + 15, y + 6, z + 10, shield, mg);
		array.setBlock(x + 15, y + 6, z + 11, shield, mg);
		array.setBlock(x + 15, y + 6, z + 12, shield, mg);
		array.setBlock(x + 15, y + 6, z + 13, shield, mc);
		array.setBlock(x + 15, y + 7, z + 3, shield, mc);
		array.setBlock(x + 15, y + 7, z + 4, shield, mg);
		array.setBlock(x + 15, y + 7, z + 5, shield, mg);
		array.setBlock(x + 15, y + 7, z + 6, shield, mg);
		array.setBlock(x + 15, y + 7, z + 7, shield, mc);
		array.setBlock(x + 15, y + 7, z + 9, shield, mc);
		array.setBlock(x + 15, y + 7, z + 10, shield, mg);
		array.setBlock(x + 15, y + 7, z + 11, shield, mg);
		array.setBlock(x + 15, y + 7, z + 12, shield, mg);
		array.setBlock(x + 15, y + 7, z + 13, shield, mc);
		array.setBlock(x + 15, y + 8, z + 3, shield, mc);
		array.setBlock(x + 15, y + 8, z + 4, shield, mg);
		array.setBlock(x + 15, y + 8, z + 5, shield, mg);
		array.setBlock(x + 15, y + 8, z + 6, shield, mg);
		array.setBlock(x + 15, y + 8, z + 7, shield, mc);
		array.setBlock(x + 15, y + 8, z + 8, shield, mc);
		array.setBlock(x + 15, y + 8, z + 9, shield, mc);
		array.setBlock(x + 15, y + 8, z + 10, shield, mg);
		array.setBlock(x + 15, y + 8, z + 11, shield, mg);
		array.setBlock(x + 15, y + 8, z + 12, shield, mg);
		array.setBlock(x + 15, y + 8, z + 13, shield, mc);
		array.setBlock(x + 15, y + 9, z + 3, shield, mc);
		array.setBlock(x + 15, y + 9, z + 4, shield, mc);
		array.setBlock(x + 15, y + 9, z + 5, shield, mc);
		array.setBlock(x + 15, y + 9, z + 6, shield, mc);
		array.setBlock(x + 15, y + 9, z + 7, shield, mc);
		array.setBlock(x + 15, y + 9, z + 8, shield, mc);
		array.setBlock(x + 15, y + 9, z + 9, shield, mc);
		array.setBlock(x + 15, y + 9, z + 10, shield, mc);
		array.setBlock(x + 15, y + 9, z + 11, shield, mc);
		array.setBlock(x + 15, y + 9, z + 12, shield, mc);
		array.setBlock(x + 15, y + 9, z + 13, shield, mc);
		array.setBlock(x + 15, y + 10, z + 3, shield, mc);
		array.setBlock(x + 15, y + 10, z + 5, shield, mc);
		array.setBlock(x + 15, y + 10, z + 11, shield, mc);
		array.setBlock(x + 15, y + 10, z + 13, shield, mc);
		array.setBlock(x + 16, y + 5, z + 6, shield, BlockType.MOSS.metadata);
		array.setBlock(x + 16, y + 5, z + 7, shield, BlockType.MOSS.metadata);
		array.setBlock(x + 16, y + 5, z + 8, shield, BlockType.MOSS.metadata);
		array.setBlock(x + 16, y + 5, z + 9, shield, BlockType.MOSS.metadata);
		array.setBlock(x + 16, y + 5, z + 10, shield, BlockType.MOSS.metadata);
	}

	private static void getAirSpaces(FilledBlockArray array, int x, int y, int z) {
		array.setBlock(x + 1, y + 6, z + 8, Blocks.air);
		array.setBlock(x + 1, y + 7, z + 8, Blocks.air);
		array.setBlock(x + 2, y + 6, z + 3, Blocks.air);
		array.setBlock(x + 2, y + 6, z + 4, Blocks.air);
		array.setBlock(x + 2, y + 6, z + 5, Blocks.air);
		array.setBlock(x + 2, y + 6, z + 6, Blocks.air);
		array.setBlock(x + 2, y + 6, z + 7, Blocks.air);
		array.setBlock(x + 2, y + 6, z + 8, Blocks.air);
		array.setBlock(x + 2, y + 6, z + 10, Blocks.air);
		array.setBlock(x + 2, y + 6, z + 11, Blocks.air);
		array.setBlock(x + 2, y + 6, z + 12, Blocks.air);
		array.setBlock(x + 2, y + 6, z + 13, Blocks.air);
		array.setBlock(x + 2, y + 7, z + 3, Blocks.air);
		array.setBlock(x + 2, y + 7, z + 4, Blocks.air);
		array.setBlock(x + 2, y + 7, z + 5, Blocks.air);
		array.setBlock(x + 2, y + 7, z + 6, Blocks.air);
		array.setBlock(x + 2, y + 7, z + 7, Blocks.air);
		array.setBlock(x + 2, y + 7, z + 8, Blocks.air);
		array.setBlock(x + 2, y + 7, z + 10, Blocks.air);
		array.setBlock(x + 2, y + 7, z + 11, Blocks.air);
		array.setBlock(x + 2, y + 7, z + 12, Blocks.air);
		array.setBlock(x + 2, y + 7, z + 13, Blocks.air);
		array.setBlock(x + 2, y + 8, z + 3, Blocks.air);
		array.setBlock(x + 2, y + 8, z + 4, Blocks.air);
		array.setBlock(x + 2, y + 8, z + 5, Blocks.air);
		array.setBlock(x + 2, y + 8, z + 6, Blocks.air);
		array.setBlock(x + 2, y + 8, z + 7, Blocks.air);
		array.setBlock(x + 2, y + 8, z + 8, Blocks.air);
		array.setBlock(x + 2, y + 8, z + 10, Blocks.air);
		array.setBlock(x + 2, y + 8, z + 11, Blocks.air);
		array.setBlock(x + 2, y + 8, z + 12, Blocks.air);
		array.setBlock(x + 2, y + 8, z + 13, Blocks.air);
		array.setBlock(x + 3, y + 4, z + 5, getLava());
		array.setBlock(x + 3, y + 4, z + 6, getLava());
		array.setBlock(x + 3, y + 4, z + 7, getLava());
		array.setBlock(x + 3, y + 4, z + 8, getLava());
		array.setBlock(x + 3, y + 6, z + 2, Blocks.air);
		array.setBlock(x + 3, y + 6, z + 3, Blocks.air);
		array.setBlock(x + 3, y + 6, z + 4, Blocks.air);
		array.setBlock(x + 3, y + 6, z + 5, Blocks.air);
		array.setBlock(x + 3, y + 6, z + 6, Blocks.air);
		array.setBlock(x + 3, y + 6, z + 7, Blocks.air);
		array.setBlock(x + 3, y + 6, z + 8, Blocks.air);
		array.setBlock(x + 3, y + 6, z + 10, Blocks.air);
		array.setBlock(x + 3, y + 6, z + 11, Blocks.air);
		array.setBlock(x + 3, y + 6, z + 12, Blocks.air);
		array.setBlock(x + 3, y + 6, z + 13, Blocks.air);
		array.setBlock(x + 3, y + 6, z + 14, Blocks.air);
		array.setBlock(x + 3, y + 7, z + 2, Blocks.air);
		array.setBlock(x + 3, y + 7, z + 3, Blocks.air);
		array.setBlock(x + 3, y + 7, z + 4, Blocks.air);
		array.setBlock(x + 3, y + 7, z + 5, Blocks.air);
		array.setBlock(x + 3, y + 7, z + 6, Blocks.air);
		array.setBlock(x + 3, y + 7, z + 7, Blocks.air);
		array.setBlock(x + 3, y + 7, z + 8, Blocks.air);
		array.setBlock(x + 3, y + 7, z + 10, Blocks.air);
		array.setBlock(x + 3, y + 7, z + 11, Blocks.air);
		array.setBlock(x + 3, y + 7, z + 12, Blocks.air);
		array.setBlock(x + 3, y + 7, z + 13, Blocks.air);
		array.setBlock(x + 3, y + 7, z + 14, Blocks.air);
		array.setBlock(x + 3, y + 8, z + 2, Blocks.air);
		array.setBlock(x + 3, y + 8, z + 3, Blocks.air);
		array.setBlock(x + 3, y + 8, z + 4, Blocks.air);
		array.setBlock(x + 3, y + 8, z + 5, Blocks.air);
		array.setBlock(x + 3, y + 8, z + 6, Blocks.air);
		array.setBlock(x + 3, y + 8, z + 7, Blocks.air);
		array.setBlock(x + 3, y + 8, z + 8, Blocks.air);
		array.setBlock(x + 3, y + 8, z + 10, Blocks.air);
		array.setBlock(x + 3, y + 8, z + 11, Blocks.air);
		array.setBlock(x + 3, y + 8, z + 12, Blocks.air);
		array.setBlock(x + 3, y + 8, z + 13, Blocks.air);
		array.setBlock(x + 3, y + 8, z + 14, Blocks.air);
		array.setBlock(x + 4, y + 4, z + 5, getLava());
		array.setBlock(x + 4, y + 4, z + 6, getLava());
		array.setBlock(x + 4, y + 4, z + 7, getLava());
		array.setBlock(x + 4, y + 4, z + 8, getLava());
		array.setBlock(x + 4, y + 4, z + 9, getLava());
		array.setBlock(x + 4, y + 4, z + 10, getLava());
		array.setBlock(x + 4, y + 4, z + 11, getLava());
		array.setBlock(x + 4, y + 4, z + 12, getLava());
		array.setBlock(x + 4, y + 4, z + 13, getLava());
		array.setBlock(x + 4, y + 6, z + 2, Blocks.air);
		array.setBlock(x + 4, y + 6, z + 3, Blocks.air);
		array.setBlock(x + 4, y + 6, z + 4, Blocks.air);
		array.setBlock(x + 4, y + 6, z + 5, Blocks.air);
		array.setBlock(x + 4, y + 6, z + 6, Blocks.air);
		array.setBlock(x + 4, y + 6, z + 7, Blocks.air);
		array.setBlock(x + 4, y + 6, z + 8, Blocks.air);
		array.setBlock(x + 4, y + 6, z + 9, Blocks.air);
		array.setBlock(x + 4, y + 6, z + 11, Blocks.air);
		array.setBlock(x + 4, y + 6, z + 12, Blocks.air);
		array.setBlock(x + 4, y + 6, z + 13, Blocks.air);
		array.setBlock(x + 4, y + 6, z + 14, Blocks.air);
		array.setBlock(x + 4, y + 7, z + 2, Blocks.air);
		array.setBlock(x + 4, y + 7, z + 3, Blocks.air);
		array.setBlock(x + 4, y + 7, z + 4, Blocks.air);
		array.setBlock(x + 4, y + 7, z + 5, Blocks.air);
		array.setBlock(x + 4, y + 7, z + 6, Blocks.air);
		array.setBlock(x + 4, y + 7, z + 7, Blocks.air);
		array.setBlock(x + 4, y + 7, z + 8, Blocks.air);
		array.setBlock(x + 4, y + 7, z + 9, Blocks.air);
		array.setBlock(x + 4, y + 7, z + 11, Blocks.air);
		array.setBlock(x + 4, y + 7, z + 12, Blocks.air);
		array.setBlock(x + 4, y + 7, z + 13, Blocks.air);
		array.setBlock(x + 4, y + 7, z + 14, Blocks.air);
		array.setBlock(x + 4, y + 8, z + 2, Blocks.air);
		array.setBlock(x + 4, y + 8, z + 3, Blocks.air);
		array.setBlock(x + 4, y + 8, z + 4, Blocks.air);
		array.setBlock(x + 4, y + 8, z + 5, Blocks.air);
		array.setBlock(x + 4, y + 8, z + 6, Blocks.air);
		array.setBlock(x + 4, y + 8, z + 7, Blocks.air);
		array.setBlock(x + 4, y + 8, z + 8, Blocks.air);
		array.setBlock(x + 4, y + 8, z + 9, Blocks.air);
		array.setBlock(x + 4, y + 8, z + 11, Blocks.air);
		array.setBlock(x + 4, y + 8, z + 12, Blocks.air);
		array.setBlock(x + 4, y + 8, z + 13, Blocks.air);
		array.setBlock(x + 4, y + 8, z + 14, Blocks.air);
		array.setBlock(x + 5, y + 4, z + 6, getLava());
		array.setBlock(x + 5, y + 4, z + 7, getLava());
		array.setBlock(x + 5, y + 4, z + 8, getLava());
		array.setBlock(x + 5, y + 4, z + 9, getLava());
		array.setBlock(x + 5, y + 4, z + 10, getLava());
		array.setBlock(x + 5, y + 4, z + 12, getLava());
		array.setBlock(x + 5, y + 4, z + 13, getLava());
		array.setBlock(x + 5, y + 6, z + 2, Blocks.air);
		array.setBlock(x + 5, y + 6, z + 3, Blocks.air);
		array.setBlock(x + 5, y + 6, z + 4, Blocks.air);
		array.setBlock(x + 5, y + 6, z + 6, Blocks.air);
		array.setBlock(x + 5, y + 6, z + 7, Blocks.air);
		array.setBlock(x + 5, y + 6, z + 8, Blocks.air);
		array.setBlock(x + 5, y + 6, z + 9, Blocks.air);
		array.setBlock(x + 5, y + 6, z + 12, Blocks.air);
		array.setBlock(x + 5, y + 6, z + 13, Blocks.air);
		array.setBlock(x + 5, y + 6, z + 14, Blocks.air);
		array.setBlock(x + 5, y + 7, z + 2, Blocks.air);
		array.setBlock(x + 5, y + 7, z + 3, Blocks.air);
		array.setBlock(x + 5, y + 7, z + 4, Blocks.air);
		array.setBlock(x + 5, y + 7, z + 6, Blocks.air);
		array.setBlock(x + 5, y + 7, z + 7, Blocks.air);
		array.setBlock(x + 5, y + 7, z + 8, Blocks.air);
		array.setBlock(x + 5, y + 7, z + 9, Blocks.air);
		array.setBlock(x + 5, y + 7, z + 12, Blocks.air);
		array.setBlock(x + 5, y + 7, z + 13, Blocks.air);
		array.setBlock(x + 5, y + 7, z + 14, Blocks.air);
		array.setBlock(x + 5, y + 8, z + 2, Blocks.air);
		array.setBlock(x + 5, y + 8, z + 3, Blocks.air);
		array.setBlock(x + 5, y + 8, z + 4, Blocks.air);
		array.setBlock(x + 5, y + 8, z + 6, Blocks.air);
		array.setBlock(x + 5, y + 8, z + 7, Blocks.air);
		array.setBlock(x + 5, y + 8, z + 8, Blocks.air);
		array.setBlock(x + 5, y + 8, z + 9, Blocks.air);
		array.setBlock(x + 5, y + 8, z + 12, Blocks.air);
		array.setBlock(x + 5, y + 8, z + 13, Blocks.air);
		array.setBlock(x + 5, y + 8, z + 14, Blocks.air);
		array.setBlock(x + 5, y + 10, z + 6, Blocks.air);
		array.setBlock(x + 5, y + 10, z + 7, Blocks.air);
		array.setBlock(x + 5, y + 10, z + 8, Blocks.air);
		array.setBlock(x + 5, y + 10, z + 9, Blocks.air);
		array.setBlock(x + 5, y + 10, z + 10, Blocks.air);
		array.setBlock(x + 5, y + 11, z + 6, Blocks.air);
		array.setBlock(x + 5, y + 11, z + 7, Blocks.air);
		array.setBlock(x + 5, y + 11, z + 8, Blocks.air);
		array.setBlock(x + 5, y + 11, z + 9, Blocks.air);
		array.setBlock(x + 5, y + 11, z + 10, Blocks.air);
		array.setBlock(x + 6, y + 4, z + 11, getLava());
		array.setBlock(x + 6, y + 4, z + 12, getLava());
		array.setBlock(x + 6, y + 4, z + 13, getLava());
		array.setBlock(x + 6, y + 6, z + 2, Blocks.air);
		array.setBlock(x + 6, y + 6, z + 3, Blocks.air);
		array.setBlock(x + 6, y + 6, z + 11, Blocks.air);
		array.setBlock(x + 6, y + 6, z + 12, Blocks.air);
		array.setBlock(x + 6, y + 6, z + 13, Blocks.air);
		array.setBlock(x + 6, y + 6, z + 14, Blocks.air);
		array.setBlock(x + 6, y + 7, z + 2, Blocks.air);
		array.setBlock(x + 6, y + 7, z + 3, Blocks.air);
		array.setBlock(x + 6, y + 7, z + 11, Blocks.air);
		array.setBlock(x + 6, y + 7, z + 12, Blocks.air);
		array.setBlock(x + 6, y + 7, z + 13, Blocks.air);
		array.setBlock(x + 6, y + 7, z + 14, Blocks.air);
		array.setBlock(x + 6, y + 8, z + 2, Blocks.air);
		array.setBlock(x + 6, y + 8, z + 3, Blocks.air);
		array.setBlock(x + 6, y + 8, z + 11, Blocks.air);
		array.setBlock(x + 6, y + 8, z + 12, Blocks.air);
		array.setBlock(x + 6, y + 8, z + 13, Blocks.air);
		array.setBlock(x + 6, y + 8, z + 14, Blocks.air);
		array.setBlock(x + 6, y + 10, z + 5, Blocks.air);
		array.setBlock(x + 6, y + 10, z + 6, Blocks.air);
		array.setBlock(x + 6, y + 10, z + 7, Blocks.air);
		array.setBlock(x + 6, y + 10, z + 8, Blocks.air);
		array.setBlock(x + 6, y + 10, z + 9, Blocks.air);
		array.setBlock(x + 6, y + 10, z + 10, Blocks.air);
		array.setBlock(x + 6, y + 10, z + 11, Blocks.air);
		array.setBlock(x + 6, y + 11, z + 5, Blocks.air);
		array.setBlock(x + 6, y + 11, z + 6, Blocks.air);
		array.setBlock(x + 6, y + 11, z + 7, Blocks.air);
		array.setBlock(x + 6, y + 11, z + 8, Blocks.air);
		array.setBlock(x + 6, y + 11, z + 9, Blocks.air);
		array.setBlock(x + 6, y + 11, z + 10, Blocks.air);
		array.setBlock(x + 6, y + 11, z + 11, Blocks.air);
		array.setBlock(x + 7, y + 2, z + 5, Blocks.air);
		array.setBlock(x + 7, y + 2, z + 6, Blocks.air);
		array.setBlock(x + 7, y + 2, z + 7, Blocks.air);
		array.setBlock(x + 7, y + 3, z + 5, Blocks.air);
		array.setBlock(x + 7, y + 3, z + 6, Blocks.air);
		array.setBlock(x + 7, y + 3, z + 7, Blocks.air);
		array.setBlock(x + 7, y + 3, z + 8, Blocks.air);
		array.setBlock(x + 7, y + 4, z + 6, Blocks.air);
		array.setBlock(x + 7, y + 4, z + 7, Blocks.air);
		array.setBlock(x + 7, y + 4, z + 8, Blocks.air);
		array.setBlock(x + 7, y + 4, z + 9, Blocks.air);
		array.setBlock(x + 7, y + 4, z + 11, getLava());
		array.setBlock(x + 7, y + 4, z + 12, getLava());
		array.setBlock(x + 7, y + 4, z + 13, getLava());
		array.setBlock(x + 7, y + 6, z + 4, Blocks.air);
		array.setBlock(x + 7, y + 6, z + 5, Blocks.air);
		array.setBlock(x + 7, y + 6, z + 7, Blocks.air);
		array.setBlock(x + 7, y + 6, z + 8, Blocks.air);
		array.setBlock(x + 7, y + 6, z + 9, Blocks.air);
		array.setBlock(x + 7, y + 6, z + 11, Blocks.air);
		array.setBlock(x + 7, y + 6, z + 12, Blocks.air);
		array.setBlock(x + 7, y + 6, z + 13, Blocks.air);
		array.setBlock(x + 7, y + 6, z + 14, Blocks.air);
		array.setBlock(x + 7, y + 7, z + 4, Blocks.air);
		array.setBlock(x + 7, y + 7, z + 5, Blocks.air);
		array.setBlock(x + 7, y + 7, z + 7, Blocks.air);
		array.setBlock(x + 7, y + 7, z + 8, Blocks.air);
		array.setBlock(x + 7, y + 7, z + 9, Blocks.air);
		array.setBlock(x + 7, y + 7, z + 11, Blocks.air);
		array.setBlock(x + 7, y + 7, z + 12, Blocks.air);
		array.setBlock(x + 7, y + 7, z + 13, Blocks.air);
		array.setBlock(x + 7, y + 7, z + 14, Blocks.air);
		array.setBlock(x + 7, y + 8, z + 4, Blocks.air);
		array.setBlock(x + 7, y + 8, z + 5, Blocks.air);
		array.setBlock(x + 7, y + 8, z + 7, Blocks.air);
		array.setBlock(x + 7, y + 8, z + 8, Blocks.air);
		array.setBlock(x + 7, y + 8, z + 9, Blocks.air);
		array.setBlock(x + 7, y + 8, z + 11, Blocks.air);
		array.setBlock(x + 7, y + 8, z + 12, Blocks.air);
		array.setBlock(x + 7, y + 8, z + 13, Blocks.air);
		array.setBlock(x + 7, y + 8, z + 14, Blocks.air);
		array.setBlock(x + 7, y + 10, z + 5, Blocks.air);
		array.setBlock(x + 7, y + 10, z + 6, Blocks.air);
		array.setBlock(x + 7, y + 10, z + 10, Blocks.air);
		array.setBlock(x + 7, y + 10, z + 11, Blocks.air);
		array.setBlock(x + 7, y + 11, z + 5, Blocks.air);
		array.setBlock(x + 7, y + 11, z + 6, Blocks.air);
		array.setBlock(x + 7, y + 11, z + 10, Blocks.air);
		array.setBlock(x + 7, y + 11, z + 11, Blocks.air);
		array.setBlock(x + 8, y + 2, z + 5, Blocks.air);
		array.setBlock(x + 8, y + 2, z + 6, Blocks.air);
		array.setBlock(x + 8, y + 2, z + 7, Blocks.air);
		array.setBlock(x + 8, y + 3, z + 5, Blocks.air);
		array.setBlock(x + 8, y + 3, z + 7, Blocks.air);
		array.setBlock(x + 8, y + 3, z + 8, Blocks.air);
		array.setBlock(x + 8, y + 4, z + 6, Blocks.air);
		array.setBlock(x + 8, y + 4, z + 7, Blocks.air);
		array.setBlock(x + 8, y + 4, z + 8, Blocks.air);
		array.setBlock(x + 8, y + 4, z + 9, Blocks.air);
		array.setBlock(x + 8, y + 4, z + 11, getLava());
		array.setBlock(x + 8, y + 4, z + 12, getLava());
		array.setBlock(x + 8, y + 4, z + 13, getLava());
		array.setBlock(x + 8, y + 6, z + 1, Blocks.air);
		array.setBlock(x + 8, y + 6, z + 2, Blocks.air);
		array.setBlock(x + 8, y + 6, z + 3, Blocks.air);
		array.setBlock(x + 8, y + 6, z + 4, Blocks.air);
		array.setBlock(x + 8, y + 6, z + 5, Blocks.air);
		array.setBlock(x + 8, y + 6, z + 7, Blocks.air);
		array.setBlock(x + 8, y + 6, z + 8, Blocks.air);
		array.setBlock(x + 8, y + 6, z + 9, Blocks.air);
		array.setBlock(x + 8, y + 6, z + 11, Blocks.air);
		array.setBlock(x + 8, y + 6, z + 12, Blocks.air);
		array.setBlock(x + 8, y + 6, z + 13, Blocks.air);
		array.setBlock(x + 8, y + 6, z + 14, Blocks.air);
		array.setBlock(x + 8, y + 6, z + 15, Blocks.air);
		array.setBlock(x + 8, y + 7, z + 1, Blocks.air);
		array.setBlock(x + 8, y + 7, z + 2, Blocks.air);
		array.setBlock(x + 8, y + 7, z + 3, Blocks.air);
		array.setBlock(x + 8, y + 7, z + 4, Blocks.air);
		array.setBlock(x + 8, y + 7, z + 5, Blocks.air);
		array.setBlock(x + 8, y + 7, z + 7, Blocks.air);
		array.setBlock(x + 8, y + 7, z + 8, Blocks.air);
		array.setBlock(x + 8, y + 7, z + 9, Blocks.air);
		array.setBlock(x + 8, y + 7, z + 11, Blocks.air);
		array.setBlock(x + 8, y + 7, z + 12, Blocks.air);
		array.setBlock(x + 8, y + 7, z + 13, Blocks.air);
		array.setBlock(x + 8, y + 7, z + 14, Blocks.air);
		array.setBlock(x + 8, y + 7, z + 15, Blocks.air);
		array.setBlock(x + 8, y + 8, z + 2, Blocks.air);
		array.setBlock(x + 8, y + 8, z + 3, Blocks.air);
		array.setBlock(x + 8, y + 8, z + 4, Blocks.air);
		array.setBlock(x + 8, y + 8, z + 5, Blocks.air);
		array.setBlock(x + 8, y + 8, z + 7, Blocks.air);
		array.setBlock(x + 8, y + 8, z + 8, Blocks.air);
		array.setBlock(x + 8, y + 8, z + 9, Blocks.air);
		array.setBlock(x + 8, y + 8, z + 11, Blocks.air);
		array.setBlock(x + 8, y + 8, z + 12, Blocks.air);
		array.setBlock(x + 8, y + 8, z + 13, Blocks.air);
		array.setBlock(x + 8, y + 8, z + 14, Blocks.air);
		array.setBlock(x + 8, y + 10, z + 5, Blocks.air);
		array.setBlock(x + 8, y + 10, z + 6, Blocks.air);
		array.setBlock(x + 8, y + 10, z + 10, Blocks.air);
		array.setBlock(x + 8, y + 10, z + 11, Blocks.air);
		array.setBlock(x + 8, y + 11, z + 5, Blocks.air);
		array.setBlock(x + 8, y + 11, z + 6, Blocks.air);
		array.setBlock(x + 8, y + 11, z + 10, Blocks.air);
		array.setBlock(x + 8, y + 11, z + 11, Blocks.air);
		array.setBlock(x + 9, y + 2, z + 5, Blocks.air);
		array.setBlock(x + 9, y + 2, z + 6, Blocks.air);
		array.setBlock(x + 9, y + 2, z + 7, Blocks.air);
		array.setBlock(x + 9, y + 3, z + 5, Blocks.air);
		array.setBlock(x + 9, y + 3, z + 6, Blocks.air);
		array.setBlock(x + 9, y + 3, z + 7, Blocks.air);
		array.setBlock(x + 9, y + 3, z + 8, Blocks.air);
		array.setBlock(x + 9, y + 4, z + 6, Blocks.air);
		array.setBlock(x + 9, y + 4, z + 7, Blocks.air);
		array.setBlock(x + 9, y + 4, z + 8, Blocks.air);
		array.setBlock(x + 9, y + 4, z + 9, Blocks.air);
		array.setBlock(x + 9, y + 4, z + 11, getLava());
		array.setBlock(x + 9, y + 4, z + 12, getLava());
		array.setBlock(x + 9, y + 6, z + 2, Blocks.air);
		array.setBlock(x + 9, y + 6, z + 3, Blocks.air);
		array.setBlock(x + 9, y + 6, z + 4, Blocks.air);
		array.setBlock(x + 9, y + 6, z + 5, Blocks.air);
		array.setBlock(x + 9, y + 6, z + 7, Blocks.air);
		array.setBlock(x + 9, y + 6, z + 8, Blocks.air);
		array.setBlock(x + 9, y + 6, z + 9, Blocks.air);
		array.setBlock(x + 9, y + 6, z + 11, Blocks.air);
		array.setBlock(x + 9, y + 6, z + 12, Blocks.air);
		array.setBlock(x + 9, y + 7, z + 2, Blocks.air);
		array.setBlock(x + 9, y + 7, z + 3, Blocks.air);
		array.setBlock(x + 9, y + 7, z + 4, Blocks.air);
		array.setBlock(x + 9, y + 7, z + 5, Blocks.air);
		array.setBlock(x + 9, y + 7, z + 7, Blocks.air);
		array.setBlock(x + 9, y + 7, z + 8, Blocks.air);
		array.setBlock(x + 9, y + 7, z + 9, Blocks.air);
		array.setBlock(x + 9, y + 7, z + 11, Blocks.air);
		array.setBlock(x + 9, y + 7, z + 12, Blocks.air);
		array.setBlock(x + 9, y + 8, z + 2, Blocks.air);
		array.setBlock(x + 9, y + 8, z + 3, Blocks.air);
		array.setBlock(x + 9, y + 8, z + 4, Blocks.air);
		array.setBlock(x + 9, y + 8, z + 5, Blocks.air);
		array.setBlock(x + 9, y + 8, z + 7, Blocks.air);
		array.setBlock(x + 9, y + 8, z + 8, Blocks.air);
		array.setBlock(x + 9, y + 8, z + 9, Blocks.air);
		array.setBlock(x + 9, y + 8, z + 11, Blocks.air);
		array.setBlock(x + 9, y + 8, z + 12, Blocks.air);
		array.setBlock(x + 9, y + 10, z + 5, Blocks.air);
		array.setBlock(x + 9, y + 10, z + 6, Blocks.air);
		array.setBlock(x + 9, y + 10, z + 10, Blocks.air);
		array.setBlock(x + 9, y + 10, z + 11, Blocks.air);
		array.setBlock(x + 9, y + 11, z + 5, Blocks.air);
		array.setBlock(x + 9, y + 11, z + 6, Blocks.air);
		array.setBlock(x + 9, y + 11, z + 10, Blocks.air);
		array.setBlock(x + 9, y + 11, z + 11, Blocks.air);
		array.setBlock(x + 10, y + 4, z + 11, getLava());
		array.setBlock(x + 10, y + 4, z + 12, getLava());
		array.setBlock(x + 10, y + 4, z + 13, getLava());
		array.setBlock(x + 10, y + 6, z + 2, Blocks.air);
		array.setBlock(x + 10, y + 6, z + 3, Blocks.air);
		array.setBlock(x + 10, y + 6, z + 4, Blocks.air);
		array.setBlock(x + 10, y + 6, z + 5, Blocks.air);
		array.setBlock(x + 10, y + 6, z + 13, Blocks.air);
		array.setBlock(x + 10, y + 6, z + 14, Blocks.air);
		array.setBlock(x + 10, y + 7, z + 2, Blocks.air);
		array.setBlock(x + 10, y + 7, z + 3, Blocks.air);
		array.setBlock(x + 10, y + 7, z + 4, Blocks.air);
		array.setBlock(x + 10, y + 7, z + 5, Blocks.air);
		array.setBlock(x + 10, y + 7, z + 13, Blocks.air);
		array.setBlock(x + 10, y + 7, z + 14, Blocks.air);
		array.setBlock(x + 10, y + 8, z + 2, Blocks.air);
		array.setBlock(x + 10, y + 8, z + 3, Blocks.air);
		array.setBlock(x + 10, y + 8, z + 4, Blocks.air);
		array.setBlock(x + 10, y + 8, z + 5, Blocks.air);
		array.setBlock(x + 10, y + 8, z + 13, Blocks.air);
		array.setBlock(x + 10, y + 8, z + 14, Blocks.air);
		array.setBlock(x + 10, y + 10, z + 5, Blocks.air);
		array.setBlock(x + 10, y + 10, z + 6, Blocks.air);
		array.setBlock(x + 10, y + 10, z + 7, Blocks.air);
		array.setBlock(x + 10, y + 10, z + 8, Blocks.air);
		array.setBlock(x + 10, y + 10, z + 9, Blocks.air);
		array.setBlock(x + 10, y + 10, z + 10, Blocks.air);
		array.setBlock(x + 10, y + 10, z + 11, Blocks.air);
		array.setBlock(x + 10, y + 11, z + 5, Blocks.air);
		array.setBlock(x + 10, y + 11, z + 6, Blocks.air);
		array.setBlock(x + 10, y + 11, z + 7, Blocks.air);
		array.setBlock(x + 10, y + 11, z + 8, Blocks.air);
		array.setBlock(x + 10, y + 11, z + 9, Blocks.air);
		array.setBlock(x + 10, y + 11, z + 10, Blocks.air);
		array.setBlock(x + 10, y + 11, z + 11, Blocks.air);
		array.setBlock(x + 11, y + 4, z + 7, getLava());
		array.setBlock(x + 11, y + 4, z + 8, getLava());
		array.setBlock(x + 11, y + 4, z + 9, getLava());
		array.setBlock(x + 11, y + 4, z + 10, getLava());
		array.setBlock(x + 11, y + 4, z + 12, getLava());
		array.setBlock(x + 11, y + 4, z + 13, getLava());
		array.setBlock(x + 11, y + 6, z + 2, Blocks.air);
		array.setBlock(x + 11, y + 6, z + 3, Blocks.air);
		array.setBlock(x + 11, y + 6, z + 4, Blocks.air);
		array.setBlock(x + 11, y + 6, z + 7, Blocks.air);
		array.setBlock(x + 11, y + 6, z + 8, Blocks.air);
		array.setBlock(x + 11, y + 6, z + 9, Blocks.air);
		array.setBlock(x + 11, y + 6, z + 10, Blocks.air);
		array.setBlock(x + 11, y + 6, z + 12, Blocks.air);
		array.setBlock(x + 11, y + 6, z + 13, Blocks.air);
		array.setBlock(x + 11, y + 6, z + 14, Blocks.air);
		array.setBlock(x + 11, y + 7, z + 2, Blocks.air);
		array.setBlock(x + 11, y + 7, z + 3, Blocks.air);
		array.setBlock(x + 11, y + 7, z + 4, Blocks.air);
		array.setBlock(x + 11, y + 7, z + 7, Blocks.air);
		array.setBlock(x + 11, y + 7, z + 8, Blocks.air);
		array.setBlock(x + 11, y + 7, z + 9, Blocks.air);
		array.setBlock(x + 11, y + 7, z + 10, Blocks.air);
		array.setBlock(x + 11, y + 7, z + 12, Blocks.air);
		array.setBlock(x + 11, y + 7, z + 13, Blocks.air);
		array.setBlock(x + 11, y + 7, z + 14, Blocks.air);
		array.setBlock(x + 11, y + 8, z + 2, Blocks.air);
		array.setBlock(x + 11, y + 8, z + 3, Blocks.air);
		array.setBlock(x + 11, y + 8, z + 4, Blocks.air);
		array.setBlock(x + 11, y + 8, z + 7, Blocks.air);
		array.setBlock(x + 11, y + 8, z + 8, Blocks.air);
		array.setBlock(x + 11, y + 8, z + 9, Blocks.air);
		array.setBlock(x + 11, y + 8, z + 10, Blocks.air);
		array.setBlock(x + 11, y + 8, z + 12, Blocks.air);
		array.setBlock(x + 11, y + 8, z + 13, Blocks.air);
		array.setBlock(x + 11, y + 8, z + 14, Blocks.air);
		array.setBlock(x + 11, y + 10, z + 6, Blocks.air);
		array.setBlock(x + 11, y + 10, z + 7, Blocks.air);
		array.setBlock(x + 11, y + 10, z + 8, Blocks.air);
		array.setBlock(x + 11, y + 10, z + 9, Blocks.air);
		array.setBlock(x + 11, y + 10, z + 10, Blocks.air);
		array.setBlock(x + 11, y + 11, z + 6, Blocks.air);
		array.setBlock(x + 11, y + 11, z + 7, Blocks.air);
		array.setBlock(x + 11, y + 11, z + 8, Blocks.air);
		array.setBlock(x + 11, y + 11, z + 9, Blocks.air);
		array.setBlock(x + 11, y + 11, z + 10, Blocks.air);
		array.setBlock(x + 12, y + 4, z + 7, getLava());
		array.setBlock(x + 12, y + 4, z + 8, getLava());
		array.setBlock(x + 12, y + 4, z + 9, getLava());
		array.setBlock(x + 12, y + 4, z + 10, getLava());
		array.setBlock(x + 12, y + 4, z + 11, getLava());
		array.setBlock(x + 12, y + 4, z + 12, getLava());
		array.setBlock(x + 12, y + 4, z + 13, getLava());
		array.setBlock(x + 12, y + 6, z + 2, Blocks.air);
		array.setBlock(x + 12, y + 6, z + 3, Blocks.air);
		array.setBlock(x + 12, y + 6, z + 4, Blocks.air);
		array.setBlock(x + 12, y + 6, z + 5, Blocks.air);
		array.setBlock(x + 12, y + 6, z + 7, Blocks.air);
		array.setBlock(x + 12, y + 6, z + 8, Blocks.air);
		array.setBlock(x + 12, y + 6, z + 9, Blocks.air);
		array.setBlock(x + 12, y + 6, z + 10, Blocks.air);
		array.setBlock(x + 12, y + 6, z + 11, Blocks.air);
		array.setBlock(x + 12, y + 6, z + 12, Blocks.air);
		array.setBlock(x + 12, y + 6, z + 13, Blocks.air);
		array.setBlock(x + 12, y + 6, z + 14, Blocks.air);
		array.setBlock(x + 12, y + 7, z + 2, Blocks.air);
		array.setBlock(x + 12, y + 7, z + 3, Blocks.air);
		array.setBlock(x + 12, y + 7, z + 4, Blocks.air);
		array.setBlock(x + 12, y + 7, z + 5, Blocks.air);
		array.setBlock(x + 12, y + 7, z + 7, Blocks.air);
		array.setBlock(x + 12, y + 7, z + 8, Blocks.air);
		array.setBlock(x + 12, y + 7, z + 9, Blocks.air);
		array.setBlock(x + 12, y + 7, z + 10, Blocks.air);
		array.setBlock(x + 12, y + 7, z + 11, Blocks.air);
		array.setBlock(x + 12, y + 7, z + 12, Blocks.air);
		array.setBlock(x + 12, y + 7, z + 13, Blocks.air);
		array.setBlock(x + 12, y + 7, z + 14, Blocks.air);
		array.setBlock(x + 12, y + 8, z + 2, Blocks.air);
		array.setBlock(x + 12, y + 8, z + 3, Blocks.air);
		array.setBlock(x + 12, y + 8, z + 4, Blocks.air);
		array.setBlock(x + 12, y + 8, z + 5, Blocks.air);
		array.setBlock(x + 12, y + 8, z + 7, Blocks.air);
		array.setBlock(x + 12, y + 8, z + 8, Blocks.air);
		array.setBlock(x + 12, y + 8, z + 9, Blocks.air);
		array.setBlock(x + 12, y + 8, z + 10, Blocks.air);
		array.setBlock(x + 12, y + 8, z + 11, Blocks.air);
		array.setBlock(x + 12, y + 8, z + 12, Blocks.air);
		array.setBlock(x + 12, y + 8, z + 13, Blocks.air);
		array.setBlock(x + 12, y + 8, z + 14, Blocks.air);
		array.setBlock(x + 13, y + 4, z + 8, getLava());
		array.setBlock(x + 13, y + 4, z + 9, getLava());
		array.setBlock(x + 13, y + 4, z + 10, getLava());
