package Reika.ChromatiCraft.World.Dimension.Structure.NonEuclid;

import java.util.Random;

import net.minecraft.block.Block;
import Reika.ChromatiCraft.Block.Worldgen.BlockStructureShield.BlockType;
import Reika.DragonAPI.Instantiable.Worldgen.ChunkSplicedGenerationCache;


public class NonEuclidLayer6 {

	public void generate(ChunkSplicedGenerationCache world, Random rand, int x, int y, int z, Block b, Block b2) {

		x -= 11;
		z -= 12;

		world.setBlock(x+60, y+0, z+19, b, BlockType.CLOAK.metadata);
		world.setBlock(x+60, y+0, z+20, b, BlockType.CLOAK.metadata);
		world.setBlock(x+60, y+0, z+21, b, BlockType.CLOAK.metadata);
		world.setBlock(x+60, y+0, z+22, b, BlockType.STONE.metadata);
		world.setBlock(x+60, y+0, z+26, b, BlockType.STONE.metadata);
		world.setBlock(x+60, y+0, z+27, b, BlockType.CLOAK.metadata);
		world.setBlock(x+60, y+0, z+28, b, BlockType.CLOAK.metadata);
		world.setBlock(x+60, y+0, z+29, b, BlockType.CLOAK.metadata);
		world.setBlock(x+60, y+0, z+30, b, BlockType.STONE.metadata);
		world.setBlock(x+60, y+1, z+12, b, BlockType.STONE.metadata);
		world.setBlock(x+60, y+1, z+22, b, BlockType.STONE.metadata);
		world.setBlock(x+60, y+1, z+26, b, BlockType.STONE.metadata);
		world.setBlock(x+60, y+1, z+30, b, BlockType.STONE.metadata);
		world.setBlock(x+60, y+2, z+12, b, BlockType.STONE.metadata);
		world.setBlock(x+60, y+2, z+22, b, BlockType.STONE.metadata);
		world.setBlock(x+60, y+2, z+26, b, BlockType.STONE.metadata);
		world.setBlock(x+60, y+2, z+30, b, BlockType.STONE.metadata);
		world.setBlock(x+60, y+3, z+12, b, BlockType.STONE.metadata);
		world.setBlock(x+60, y+3, z+22, b, BlockType.STONE.metadata);
		world.setBlock(x+60, y+3, z+26, b, BlockType.STONE.metadata);
		world.setBlock(x+60, y+3, z+30, b, BlockType.STONE.metadata);
		world.setBlock(x+60, y+4, z+12, b, BlockType.STONE.metadata);
		world.setBlock(x+60, y+4, z+13, b, BlockType.STONE.metadata);
		world.setBlock(x+60, y+4, z+14, b, BlockType.STONE.metadata);
		world.setBlock(x+60, y+4, z+15, b, BlockType.STONE.metadata);
		world.setBlock(x+60, y+4, z+16, b, BlockType.STONE.metadata);
		world.setBlock(x+60, y+4, z+17, b, BlockType.STONE.metadata);
		world.setBlock(x+60, y+4, z+18, b, BlockType.STONE.metadata);
		world.setBlock(x+60, y+4, z+19, b, BlockType.STONE.metadata);
		world.setBlock(x+60, y+4, z+20, b, BlockType.STONE.metadata);
		world.setBlock(x+60, y+4, z+21, b, BlockType.STONE.metadata);
		world.setBlock(x+60, y+4, z+22, b, BlockType.STONE.metadata);
		world.setBlock(x+60, y+4, z+26, b, BlockType.STONE.metadata);
		world.setBlock(x+60, y+4, z+27, b, BlockType.STONE.metadata);
		world.setBlock(x+60, y+4, z+28, b, BlockType.STONE.metadata);
		world.setBlock(x+60, y+4, z+29, b, BlockType.STONE.metadata);
		world.setBlock(x+60, y+4, z+30, b, BlockType.STONE.metadata);
		world.setBlock(x+61, y+0, z+12, b, BlockType.STONE.metadata);
		world.setBlock(x+61, y+0, z+13, b, BlockType.CLOAK.metadata);
		world.setBlock(x+61, y+0, z+14, b, BlockType.CLOAK.metadata);
		world.setBlock(x+61, y+0, z+15, b, BlockType.CLOAK.metadata);
		world.setBlock(x+61, y+0, z+16, b, BlockType.CLOAK.metadata);
		world.setBlock(x+61, y+0, z+17, b, BlockType.CLOAK.metadata);
		world.setBlock(x+61, y+0, z+18, b, BlockType.CLOAK.metadata);
		world.setBlock(x+61, y+0, z+19, b, BlockType.CLOAK.metadata);
		world.setBlock(x+61, y+0, z+20, b, BlockType.CLOAK.metadata);
		world.setBlock(x+61, y+0, z+21, b, BlockType.CLOAK.metadata);
		world.setBlock(x+61, y+0, z+22, b, BlockType.STONE.metadata);
		world.setBlock(x+61, y+0, z+26, b, BlockType.STONE.metadata);
		world.setBlock(x+61, y+0, z+27, b, BlockType.CLOAK.metadata);
		world.setBlock(x+61, y+0, z+28, b, BlockType.CLOAK.metadata);
		world.setBlock(x+61, y+0, z+29, b, BlockType.CLOAK.metadata);
		world.setBlock(x+61, y+0, z+30, b, BlockType.STONE.metadata);
		world.setBlock(x+61, y+1, z+12, b, BlockType.STONE.metadata);
		world.setBlock(x+61, y+1, z+22, b, BlockType.STONE.metadata);
		world.setBlock(x+61, y+1, z+26, b, BlockType.STONE.metadata);
		world.setBlock(x+61, y+1, z+30, b, BlockType.STONE.metadata);
		world.setBlock(x+61, y+2, z+12, b, BlockType.STONE.metadata);
		world.setBlock(x+61, y+2, z+22, b, BlockType.STONE.metadata);
		world.setBlock(x+61, y+2, z+26, b, BlockType.STONE.metadata);
		world.setBlock(x+61, y+2, z+30, b, BlockType.STONE.metadata);
		world.setBlock(x+61, y+3, z+12, b, BlockType.STONE.metadata);
		world.setBlock(x+61, y+3, z+22, b, BlockType.STONE.metadata);
		world.setBlock(x+61, y+3, z+26, b, BlockType.STONE.metadata);
		world.setBlock(x+61, y+3, z+30, b, BlockType.STONE.metadata);
		world.setBlock(x+61, y+4, z+12, b, BlockType.STONE.metadata);
		world.setBlock(x+61, y+4, z+13, b, BlockType.STONE.metadata);
		world.setBlock(x+61, y+4, z+14, b, BlockType.STONE.metadata);
		world.setBlock(x+61, y+4, z+15, b, BlockType.STONE.metadata);
		world.setBlock(x+61, y+4, z+16, b, BlockType.STONE.metadata);
		world.setBlock(x+61, y+4, z+17, b, BlockType.STONE.metadata);
		world.setBlock(x+61, y+4, z+18, b, BlockType.STONE.metadata);
		world.setBlock(x+61, y+4, z+19, b, BlockType.STONE.metadata);
		world.setBlock(x+61, y+4, z+20, b, BlockType.STONE.metadata);
		world.setBlock(x+61, y+4, z+21, b, BlockType.STONE.metadata);
		world.setBlock(x+61, y+4, z+22, b, BlockType.STONE.metadata);
		world.setBlock(x+61, y+4, z+26, b, BlockType.STONE.metadata);
		world.setBlock(x+61, y+4, z+27, b, BlockType.STONE.metadata);
		world.setBlock(x+61, y+4, z+28, b, BlockType.STONE.metadata);
		world.setBlock(x+61, y+4, z+29, b, BlockType.STONE.metadata);
		world.setBlock(x+61, y+4, z+30, b, BlockType.STONE.metadata);
		world.setBlock(x+62, y+0, z+12, b, BlockType.STONE.metadata);
		world.setBlock(x+62, y+0, z+13, b, BlockType.STONE.metadata);
		world.setBlock(x+62, y+0, z+14, b, BlockType.STONE.metadata);
		world.setBlock(x+62, y+0, z+15, b, BlockType.STONE.metadata);
		world.setBlock(x+62, y+0, z+16, b, BlockType.STONE.metadata);
		world.setBlock(x+62, y+0, z+17, b, BlockType.STONE.metadata);
		world.setBlock(x+62, y+0, z+18, b, BlockType.STONE.metadata);
		world.setBlock(x+62, y+0, z+19, b, BlockType.STONE.metadata);
		world.setBlock(x+62, y+0, z+20, b, BlockType.STONE.metadata);
		world.setBlock(x+62, y+0, z+21, b, BlockType.STONE.metadata);
		world.setBlock(x+62, y+0, z+22, b, BlockType.STONE.metadata);
		world.setBlock(x+62, y+0, z+25, b, BlockType.STONE.metadata);
		world.setBlock(x+62, y+0, z+26, b, BlockType.STONE.metadata);
		world.setBlock(x+62, y+0, z+27, b, BlockType.CLOAK.metadata);
		world.setBlock(x+62, y+0, z+28, b, BlockType.CLOAK.metadata);
		world.setBlock(x+62, y+0, z+29, b, BlockType.CLOAK.metadata);
		world.setBlock(x+62, y+0, z+30, b, BlockType.STONE.metadata);
		world.setBlock(x+62, y+0, z+31, b, BlockType.STONE.metadata);
		world.setBlock(x+62, y+1, z+12, b, BlockType.STONE.metadata);
		world.setBlock(x+62, y+1, z+13, b, BlockType.STONE.metadata);
		world.setBlock(x+62, y+1, z+14, b, BlockType.STONE.metadata);
		world.setBlock(x+62, y+1, z+15, b, BlockType.STONE.metadata);
		world.setBlock(x+62, y+1, z+16, b, BlockType.STONE.metadata);
		world.setBlock(x+62, y+1, z+17, b, BlockType.STONE.metadata);
		world.setBlock(x+62, y+1, z+18, b, BlockType.STONE.metadata);
		world.setBlock(x+62, y+1, z+19, b, BlockType.STONE.metadata);
		world.setBlock(x+62, y+1, z+20, b, BlockType.STONE.metadata);
		world.setBlock(x+62, y+1, z+21, b, BlockType.STONE.metadata);
		world.setBlock(x+62, y+1, z+22, b, BlockType.STONE.metadata);
		world.setBlock(x+62, y+1, z+25, b, BlockType.STONE.metadata);
		world.setBlock(x+62, y+1, z+26, b, BlockType.STONE.metadata);
		world.setBlock(x+62, y+1, z+30, b, BlockType.STONE.metadata);
		world.setBlock(x+62, y+1, z+31, b, BlockType.STONE.metadata);
		world.setBlock(x+62, y+2, z+12, b, BlockType.STONE.metadata);
		world.setBlock(x+62, y+2, z+13, b, BlockType.STONE.metadata);
		world.setBlock(x+62, y+2, z+14, b, BlockType.STONE.metadata);
		world.setBlock(x+62, y+2, z+15, b, BlockType.STONE.metadata);
		world.setBlock(x+62, y+2, z+16, b, BlockType.STONE.metadata);
		world.setBlock(x+62, y+2, z+17, b, BlockType.STONE.metadata);
		world.setBlock(x+62, y+2, z+18, b, BlockType.STONE.metadata);
		world.setBlock(x+62, y+2, z+19, b, BlockType.STONE.metadata);
		world.setBlock(x+62, y+2, z+20, b, BlockType.STONE.metadata);
		world.setBlock(x+62, y+2, z+21, b, BlockType.STONE.metadata);
		world.setBlock(x+62, y+2, z+22, b, BlockType.STONE.metadata);
		world.setBlock(x+62, y+2, z+25, b, BlockType.STONE.metadata);
		world.setBlock(x+62, y+2, z+26, b, BlockType.STONE.metadata);
		world.setBlock(x+62, y+2, z+30, b, BlockType.STONE.metadata);
		world.setBlock(x+62, y+2, z+31, b, BlockType.STONE.metadata);
		world.setBlock(x+62, y+3, z+12, b, BlockType.STONE.metadata);
		world.setBlock(x+62, y+3, z+13, b, BlockType.STONE.metadata);
		world.setBlock(x+62, y+3, z+14, b, BlockType.STONE.metadata);
		world.setBlock(x+62, y+3, z+15, b, BlockType.STONE.metadata);
		world.setBlock(x+62, y+3, z+16, b, BlockType.STONE.metadata);
		world.setBlock(x+62, y+3, z+17, b, BlockType.STONE.metadata);
		world.setBlock(x+62, y+3, z+18, b, BlockType.STONE.metadata);
		world.setBlock(x+62, y+3, z+19, b, BlockType.STONE.metadata);
		world.setBlock(x+62, y+3, z+20, b, BlockType.STONE.metadata);
		world.setBlock(x+62, y+3, z+21, b, BlockType.STONE.metadata);
		world.setBlock(x+62, y+3, z+22, b, BlockType.STONE.metadata);
		world.setBlock(x+62, y+3, z+25, b, BlockType.STONE.metadata);
		world.setBlock(x+62, y+3, z+26, b, BlockType.STONE.metadata);
		world.setBlock(x+62, y+3, z+30, b, BlockType.STONE.metadata);
		world.setBlock(x+62, y+3, z+31, b, BlockType.STONE.metadata);
		world.setBlock(x+62, y+4, z+12, b, BlockType.STONE.metadata);
		world.setBlock(x+62, y+4, z+13, b, BlockType.STONE.metadata);
		world.setBlock(x+62, y+4, z+14, b, BlockType.STONE.metadata);
		world.setBlock(x+62, y+4, z+15, b, BlockType.STONE.metadata);
		world.setBlock(x+62, y+4, z+16, b, BlockType.STONE.metadata);
		world.setBlock(x+62, y+4, z+17, b, BlockType.STONE.metadata);
		world.setBlock(x+62, y+4, z+18, b, BlockType.STONE.metadata);
		world.setBlock(x+62, y+4, z+19, b, BlockType.STONE.metadata);
		world.setBlock(x+62, y+4, z+20, b, BlockType.STONE.metadata);
		world.setBlock(x+62, y+4, z+21, b, BlockType.STONE.metadata);
		world.setBlock(x+62, y+4, z+22, b, BlockType.STONE.metadata);
		world.setBlock(x+62, y+4, z+25, b, BlockType.STONE.metadata);
		world.setBlock(x+62, y+4, z+26, b, BlockType.STONE.metadata);
		world.setBlock(x+62, y+4, z+27, b, BlockType.STONE.metadata);
		world.setBlock(x+62, y+4, z+28, b, BlockType.STONE.metadata);
		world.setBlock(x+62, y+4, z+29, b, BlockType.STONE.metadata);
		world.setBlock(x+62, y+4, z+30, b, BlockType.STONE.metadata);
		world.setBlock(x+62, y+4, z+31, b, BlockType.STONE.metadata);
		world.setBlock(x+63, y+0, z+25, b, BlockType.STONE.metadata);
		world.setBlock(x+63, y+0, z+26, b, BlockType.CLOAK.metadata);
		world.setBlock(x+63, y+0, z+27, b, BlockType.CLOAK.metadata);
		world.setBlock(x+63, y+0, z+28, b, BlockType.CLOAK.metadata);
		world.setBlock(x+63, y+0, z+29, b, BlockType.CLOAK.metadata);
		world.setBlock(x+63, y+0, z+30, b, BlockType.CLOAK.metadata);
		world.setBlock(x+63, y+0, z+31, b, BlockType.STONE.metadata);
		world.setBlock(x+63, y+4, z+25, b, BlockType.STONE.metadata);
		world.setBlock(x+63, y+4, z+26, b, BlockType.STONE.metadata);
		world.setBlock(x+63, y+4, z+27, b, BlockType.STONE.metadata);
		world.setBlock(x+63, y+4, z+28, b, BlockType.STONE.metadata);
		world.setBlock(x+63, y+4, z+29, b, BlockType.STONE.metadata);
		world.setBlock(x+63, y+4, z+30, b, BlockType.STONE.metadata);
		world.setBlock(x+63, y+4, z+31, b, BlockType.STONE.metadata);
		world.setBlock(x+64, y+0, z+25, b, BlockType.STONE.metadata);
		world.setBlock(x+64, y+0, z+26, b, BlockType.CLOAK.metadata);
		world.setBlock(x+64, y+0, z+27, b, BlockType.CLOAK.metadata);
		world.setBlock(x+64, y+0, z+28, b, BlockType.CLOAK.metadata);
		world.setBlock(x+64, y+0, z+29, b, BlockType.CLOAK.metadata);
		world.setBlock(x+64, y+0, z+30, b, BlockType.CLOAK.metadata);
		world.setBlock(x+64, y+0, z+31, b, BlockType.STONE.metadata);

		world.setBlock(x+64, y+4, z+25, b, BlockType.STONE.metadata);
		world.setBlock(x+64, y+4, z+26, b, BlockType.STONE.metadata);
		world.setBlock(x+64, y+4, z+27, b, BlockType.STONE.metadata);
		world.setBlock(x+64, y+4, z+28, b, BlockType.STONE.metadata);
		world.setBlock(x+64, y+4, z+29, b, BlockType.STONE.metadata);
		world.setBlock(x+64, y+4, z+30, b, BlockType.STONE.metadata);
		world.setBlock(x+64, y+4, z+31, b, BlockType.STONE.metadata);
		world.setBlock(x+65, y+0, z+25, b, BlockType.STONE.metadata);
		world.setBlock(x+65, y+0, z+26, b, BlockType.CLOAK.metadata);
		world.setBlock(x+65, y+0, z+27, b, BlockType.CLOAK.metadata);
		world.setBlock(x+65, y+0, z+28, b, BlockType.CLOAK.metadata);
		world.setBlock(x+65, y+0, z+29, b, BlockType.CLOAK.metadata);
		world.setBlock(x+65, y+0, z+30, b, BlockType.CLOAK.metadata);
		world.setBlock(x+65, y+0, z+31, b, BlockType.STONE.metadata);
		world.setBlock(x+65, y+4, z+25, b, BlockType.STONE.metadata);
		world.setBlock(x+65, y+4, z+26, b, BlockType.STONE.metadata);
		world.setBlock(x+65, y+4, z+27, b, BlockType.STONE.metadata);
		world.setBlock(x+65, y+4, z+28, b, BlockType.STONE.metadata);
		world.setBlock(x+65, y+4, z+29, b, BlockType.STONE.metadata);
		world.setBlock(x+65, y+4, z+30, b, BlockType.STONE.metadata);
		world.setBlock(x+65, y+4, z+31, b, BlockType.STONE.metadata);
		world.setBlock(x+66, y+0, z+25, b, BlockType.STONE.metadata);
		world.setBlock(x+66, y+0, z+26, b, BlockType.STONE.metadata);
		world.setBlock(x+66, y+0, z+27, b, BlockType.CLOAK.metadata);
		world.setBlock(x+66, y+0, z+28, b, BlockType.CLOAK.metadata);
		world.setBlock(x+66, y+0, z+29, b, BlockType.CLOAK.metadata);
		world.setBlock(x+66, y+0, z+30, b, BlockType.STONE.metadata);
		world.setBlock(x+66, y+0, z+31, b, BlockType.STONE.metadata);
		world.setBlock(x+66, y+1, z+25, b, BlockType.STONE.metadata);
		world.setBlock(x+66, y+1, z+26, b, BlockType.STONE.metadata);
		world.setBlock(x+66, y+1, z+30, b, BlockType.STONE.metadata);
		world.setBlock(x+66, y+1, z+31, b, BlockType.STONE.metadata);
		world.setBlock(x+66, y+2, z+25, b, BlockType.STONE.metadata);
		world.setBlock(x+66, y+2, z+26, b, BlockType.STONE.metadata);
		world.setBlock(x+66, y+2, z+30, b, BlockType.STONE.metadata);
		world.setBlock(x+66, y+2, z+31, b, BlockType.STONE.metadata);
		world.setBlock(x+66, y+3, z+25, b, BlockType.STONE.metadata);
		world.setBlock(x+66, y+3, z+26, b, BlockType.STONE.metadata);
		world.setBlock(x+66, y+3, z+30, b, BlockType.STONE.metadata);
		world.setBlock(x+66, y+3, z+31, b, BlockType.STONE.metadata);
		world.setBlock(x+66, y+4, z+25, b, BlockType.STONE.metadata);
		world.setBlock(x+66, y+4, z+26, b, BlockType.STONE.metadata);
		world.setBlock(x+66, y+4, z+27, b, BlockType.STONE.metadata);
		world.setBlock(x+66, y+4, z+28, b, BlockType.STONE.metadata);
		world.setBlock(x+66, y+4, z+29, b, BlockType.STONE.metadata);
		world.setBlock(x+66, y+4, z+30, b, BlockType.STONE.metadata);
		world.setBlock(x+66, y+4, z+31, b, BlockType.STONE.metadata);
		world.setBlock(x+67, y+0, z+26, b, BlockType.STONE.metadata);
		world.setBlock(x+67, y+0, z+27, b, BlockType.STONE.metadata);
		world.setBlock(x+67, y+0, z+28, b, BlockType.STONE.metadata);
		world.setBlock(x+67, y+0, z+29, b, BlockType.STONE.metadata);
		world.setBlock(x+67, y+0, z+30, b, BlockType.STONE.metadata);
		world.setBlock(x+67, y+1, z+26, b, BlockType.STONE.metadata);
		world.setBlock(x+67, y+1, z+30, b, BlockType.STONE.metadata);
		world.setBlock(x+67, y+2, z+26, b, BlockType.STONE.metadata);
		world.setBlock(x+67, y+2, z+30, b, BlockType.STONE.metadata);
		world.setBlock(x+67, y+3, z+26, b, BlockType.STONE.metadata);
		world.setBlock(x+67, y+3, z+30, b, BlockType.STONE.metadata);
		world.setBlock(x+67, y+4, z+26, b, BlockType.STONE.metadata);
		world.setBlock(x+67, y+4, z+27, b, BlockType.STONE.metadata);
		world.setBlock(x+67, y+4, z+28, b, BlockType.STONE.metadata);
		world.setBlock(x+67, y+4, z+29, b, BlockType.STONE.metadata);
		world.setBlock(x+67, y+4, z+30, b, BlockType.STONE.metadata);
	}

}
