package Reika.ChromatiCraft.World.Dimension.Structure.NonEuclid;

import java.util.Random;

import net.minecraft.block.Block;
import Reika.ChromatiCraft.Block.Worldgen.BlockStructureShield.BlockType;
import Reika.DragonAPI.Instantiable.Worldgen.ChunkSplicedGenerationCache;


public class NonEuclidLayer5 {

	public void generate(ChunkSplicedGenerationCache world, Random rand, int x, int y, int z, Block b, Block b2) {

		x -= 11;
		z -= 12;

		world.setBlock(x+49, y+0, z+16, b, BlockType.CLOAK.metadata);
		world.setBlock(x+49, y+0, z+17, b, BlockType.CLOAK.metadata);
		world.setBlock(x+49, y+0, z+18, b, BlockType.CLOAK.metadata);
		world.setBlock(x+49, y+0, z+19, b, BlockType.CLOAK.metadata);
		world.setBlock(x+49, y+0, z+20, b, BlockType.CLOAK.metadata);
		world.setBlock(x+49, y+0, z+21, b, BlockType.CLOAK.metadata);
		world.setBlock(x+49, y+0, z+22, b, BlockType.STONE.metadata);
		world.setBlock(x+49, y+0, z+24, b, BlockType.STONE.metadata);
		world.setBlock(x+49, y+0, z+25, b, BlockType.CLOAK.metadata);
		world.setBlock(x+49, y+0, z+26, b, BlockType.CLOAK.metadata);
		world.setBlock(x+49, y+0, z+27, b, BlockType.CLOAK.metadata);
		world.setBlock(x+49, y+0, z+28, b, BlockType.STONE.metadata);
		world.setBlock(x+49, y+0, z+34, b, BlockType.STONE.metadata);
		world.setBlock(x+49, y+0, z+35, b, BlockType.CLOAK.metadata);
		world.setBlock(x+49, y+0, z+36, b, BlockType.CLOAK.metadata);
		world.setBlock(x+49, y+0, z+37, b, BlockType.CLOAK.metadata);
		world.setBlock(x+49, y+0, z+38, b, BlockType.CLOAK.metadata);
		world.setBlock(x+49, y+0, z+39, b, BlockType.CLOAK.metadata);
		world.setBlock(x+49, y+0, z+40, b, BlockType.CLOAK.metadata);
		world.setBlock(x+49, y+0, z+41, b, BlockType.CLOAK.metadata);
		world.setBlock(x+49, y+0, z+42, b, BlockType.CLOAK.metadata);
		world.setBlock(x+49, y+0, z+43, b, BlockType.CLOAK.metadata);
		world.setBlock(x+49, y+0, z+44, b, BlockType.CLOAK.metadata);
		world.setBlock(x+49, y+0, z+45, b, BlockType.CLOAK.metadata);
		world.setBlock(x+49, y+0, z+46, b, BlockType.CLOAK.metadata);
		world.setBlock(x+49, y+0, z+47, b, BlockType.CLOAK.metadata);
		world.setBlock(x+49, y+0, z+48, b, BlockType.CLOAK.metadata);
		world.setBlock(x+49, y+0, z+49, b, BlockType.CLOAK.metadata);
		world.setBlock(x+49, y+0, z+50, b, BlockType.CLOAK.metadata);
		world.setBlock(x+49, y+0, z+51, b, BlockType.STONE.metadata);
		world.setBlock(x+49, y+0, z+52, b, BlockType.CLOAK.metadata);
		world.setBlock(x+49, y+0, z+53, b, BlockType.CLOAK.metadata);
		world.setBlock(x+49, y+0, z+54, b, BlockType.CLOAK.metadata);
		world.setBlock(x+49, y+0, z+55, b, BlockType.STONE.metadata);
		world.setBlock(x+49, y+0, z+56, b, BlockType.CLOAK.metadata);
		world.setBlock(x+49, y+0, z+57, b, BlockType.CLOAK.metadata);
		world.setBlock(x+49, y+0, z+58, b, BlockType.CLOAK.metadata);
		world.setBlock(x+49, y+0, z+59, b, BlockType.STONE.metadata);
		world.setBlock(x+49, y+0, z+60, b, BlockType.CLOAK.metadata);
		world.setBlock(x+49, y+0, z+61, b, BlockType.CLOAK.metadata);
		world.setBlock(x+49, y+0, z+62, b, BlockType.CLOAK.metadata);
		world.setBlock(x+49, y+0, z+63, b, BlockType.CLOAK.metadata);
		world.setBlock(x+49, y+0, z+64, b, BlockType.CLOAK.metadata);
		world.setBlock(x+49, y+0, z+65, b, BlockType.CLOAK.metadata);
		world.setBlock(x+49, y+0, z+66, b, BlockType.CLOAK.metadata);
		world.setBlock(x+49, y+0, z+67, b, BlockType.CLOAK.metadata);
		world.setBlock(x+49, y+0, z+68, b, BlockType.CLOAK.metadata);
		world.setBlock(x+49, y+0, z+69, b, BlockType.CLOAK.metadata);
		world.setBlock(x+49, y+0, z+70, b, BlockType.CLOAK.metadata);
		world.setBlock(x+49, y+0, z+71, b, BlockType.STONE.metadata);
		world.setBlock(x+49, y+1, z+12, b, BlockType.STONE.metadata);
		world.setBlock(x+49, y+1, z+22, b, BlockType.STONE.metadata);
		world.setBlock(x+49, y+1, z+24, b, BlockType.STONE.metadata);
		world.setBlock(x+49, y+1, z+28, b, BlockType.STONE.metadata);
		world.setBlock(x+49, y+1, z+34, b, BlockType.STONE.metadata);
		world.setBlock(x+49, y+1, z+51, b, BlockType.STONE.metadata);
		world.setBlock(x+49, y+1, z+55, b, BlockType.STONE.metadata);
		world.setBlock(x+49, y+1, z+59, b, BlockType.STONE.metadata);
		world.setBlock(x+49, y+1, z+71, b, BlockType.STONE.metadata);
		world.setBlock(x+49, y+2, z+12, b, BlockType.STONE.metadata);
		world.setBlock(x+49, y+2, z+22, b, BlockType.STONE.metadata);
		world.setBlock(x+49, y+2, z+24, b, BlockType.STONE.metadata);
		world.setBlock(x+49, y+2, z+28, b, BlockType.STONE.metadata);
		world.setBlock(x+49, y+2, z+34, b, BlockType.STONE.metadata);
		world.setBlock(x+49, y+2, z+51, b, BlockType.STONE.metadata);
		world.setBlock(x+49, y+2, z+55, b, BlockType.STONE.metadata);
		world.setBlock(x+49, y+2, z+59, b, BlockType.STONE.metadata);
		world.setBlock(x+49, y+2, z+71, b, BlockType.STONE.metadata);
		world.setBlock(x+49, y+3, z+12, b, BlockType.STONE.metadata);
		world.setBlock(x+49, y+3, z+22, b, BlockType.STONE.metadata);
		world.setBlock(x+49, y+3, z+24, b, BlockType.STONE.metadata);
		world.setBlock(x+49, y+3, z+28, b, BlockType.STONE.metadata);
		world.setBlock(x+49, y+3, z+34, b, BlockType.STONE.metadata);
		world.setBlock(x+49, y+3, z+51, b, BlockType.STONE.metadata);
		world.setBlock(x+49, y+3, z+55, b, BlockType.STONE.metadata);
		world.setBlock(x+49, y+3, z+59, b, BlockType.STONE.metadata);
		world.setBlock(x+49, y+3, z+71, b, BlockType.STONE.metadata);
		world.setBlock(x+49, y+4, z+12, b, BlockType.STONE.metadata);
		world.setBlock(x+49, y+4, z+13, b, BlockType.STONE.metadata);
		world.setBlock(x+49, y+4, z+14, b, BlockType.STONE.metadata);
		world.setBlock(x+49, y+4, z+15, b, BlockType.STONE.metadata);
		world.setBlock(x+49, y+4, z+16, b, BlockType.STONE.metadata);
		world.setBlock(x+49, y+4, z+17, b, BlockType.STONE.metadata);
		world.setBlock(x+49, y+4, z+18, b, BlockType.STONE.metadata);
		world.setBlock(x+49, y+4, z+19, b, BlockType.STONE.metadata);
		world.setBlock(x+49, y+4, z+20, b, BlockType.STONE.metadata);
		world.setBlock(x+49, y+4, z+21, b, BlockType.STONE.metadata);
		world.setBlock(x+49, y+4, z+22, b, BlockType.STONE.metadata);
		world.setBlock(x+49, y+4, z+24, b, BlockType.STONE.metadata);
		world.setBlock(x+49, y+4, z+25, b, BlockType.STONE.metadata);
		world.setBlock(x+49, y+4, z+26, b, BlockType.STONE.metadata);
		world.setBlock(x+49, y+4, z+27, b, BlockType.STONE.metadata);
		world.setBlock(x+49, y+4, z+28, b, BlockType.STONE.metadata);
		world.setBlock(x+49, y+4, z+34, b, BlockType.STONE.metadata);
		world.setBlock(x+49, y+4, z+35, b, BlockType.STONE.metadata);
		world.setBlock(x+49, y+4, z+36, b, BlockType.STONE.metadata);
		world.setBlock(x+49, y+4, z+37, b, BlockType.STONE.metadata);
		world.setBlock(x+49, y+4, z+38, b, BlockType.STONE.metadata);
		world.setBlock(x+49, y+4, z+39, b, BlockType.STONE.metadata);
		world.setBlock(x+49, y+4, z+40, b, BlockType.STONE.metadata);
		world.setBlock(x+49, y+4, z+41, b, BlockType.STONE.metadata);
		world.setBlock(x+49, y+4, z+42, b, BlockType.STONE.metadata);
		world.setBlock(x+49, y+4, z+43, b, BlockType.STONE.metadata);
		world.setBlock(x+49, y+4, z+44, b, BlockType.STONE.metadata);
		world.setBlock(x+49, y+4, z+45, b, BlockType.STONE.metadata);
		world.setBlock(x+49, y+4, z+46, b, BlockType.STONE.metadata);
		world.setBlock(x+49, y+4, z+47, b, BlockType.STONE.metadata);
		world.setBlock(x+49, y+4, z+48, b, BlockType.STONE.metadata);
		world.setBlock(x+49, y+4, z+49, b, BlockType.STONE.metadata);
		world.setBlock(x+49, y+4, z+50, b, BlockType.STONE.metadata);
		world.setBlock(x+49, y+4, z+51, b, BlockType.STONE.metadata);
		world.setBlock(x+49, y+4, z+52, b, BlockType.STONE.metadata);
		world.setBlock(x+49, y+4, z+53, b, BlockType.STONE.metadata);
		world.setBlock(x+49, y+4, z+54, b, BlockType.STONE.metadata);
		world.setBlock(x+49, y+4, z+55, b, BlockType.STONE.metadata);
		world.setBlock(x+49, y+4, z+56, b, BlockType.STONE.metadata);
		world.setBlock(x+49, y+4, z+57, b, BlockType.STONE.metadata);
		world.setBlock(x+49, y+4, z+58, b, BlockType.STONE.metadata);
		world.setBlock(x+49, y+4, z+59, b, BlockType.STONE.metadata);
		world.setBlock(x+49, y+4, z+60, b, BlockType.STONE.metadata);
		world.setBlock(x+49, y+4, z+61, b, BlockType.STONE.metadata);
		world.setBlock(x+49, y+4, z+62, b, BlockType.STONE.metadata);
		world.setBlock(x+49, y+4, z+63, b, BlockType.STONE.metadata);
		world.setBlock(x+49, y+4, z+64, b, BlockType.STONE.metadata);
		world.setBlock(x+49, y+4, z+65, b, BlockType.STONE.metadata);
		world.setBlock(x+49, y+4, z+66, b, BlockType.STONE.metadata);
		world.setBlock(x+49, y+4, z+67, b, BlockType.STONE.metadata);
		world.setBlock(x+49, y+4, z+68, b, BlockType.STONE.metadata);
		world.setBlock(x+49, y+4, z+69, b, BlockType.STONE.metadata);
		world.setBlock(x+49, y+4, z+70, b, BlockType.STONE.metadata);
		world.setBlock(x+49, y+4, z+71, b, BlockType.STONE.metadata);
		world.setBlock(x+50, y+0, z+12, b, BlockType.STONE.metadata);
		world.setBlock(x+50, y+0, z+13, b, BlockType.STONE.metadata);
		world.setBlock(x+50, y+0, z+14, b, BlockType.STONE.metadata);
		world.setBlock(x+50, y+0, z+15, b, BlockType.STONE.metadata);
		world.setBlock(x+50, y+0, z+16, b, BlockType.STONE.metadata);
		world.setBlock(x+50, y+0, z+17, b, BlockType.STONE.metadata);
		world.setBlock(x+50, y+0, z+18, b, BlockType.STONE.metadata);
		world.setBlock(x+50, y+0, z+19, b, BlockType.STONE.metadata);
		world.setBlock(x+50, y+0, z+20, b, BlockType.STONE.metadata);
		world.setBlock(x+50, y+0, z+21, b, BlockType.STONE.metadata);
		world.setBlock(x+50, y+0, z+22, b, BlockType.STONE.metadata);
		world.setBlock(x+50, y+0, z+24, b, BlockType.STONE.metadata);
		world.setBlock(x+50, y+0, z+25, b, BlockType.CLOAK.metadata);
		world.setBlock(x+50, y+0, z+26, b, BlockType.CLOAK.metadata);
		world.setBlock(x+50, y+0, z+27, b, BlockType.CLOAK.metadata);
		world.setBlock(x+50, y+0, z+28, b, BlockType.STONE.metadata);
		world.setBlock(x+50, y+0, z+29, b, BlockType.STONE.metadata);
		world.setBlock(x+50, y+0, z+30, b, BlockType.STONE.metadata);
		world.setBlock(x+50, y+0, z+31, b, BlockType.STONE.metadata);
		world.setBlock(x+50, y+0, z+32, b, BlockType.STONE.metadata);
		world.setBlock(x+50, y+0, z+33, b, BlockType.STONE.metadata);
		world.setBlock(x+50, y+0, z+34, b, BlockType.STONE.metadata);
		world.setBlock(x+50, y+0, z+35, b, BlockType.CLOAK.metadata);
		world.setBlock(x+50, y+0, z+36, b, BlockType.CLOAK.metadata);
		world.setBlock(x+50, y+0, z+37, b, BlockType.CLOAK.metadata);
		world.setBlock(x+50, y+0, z+38, b, BlockType.STONE.metadata);
		world.setBlock(x+50, y+0, z+39, b, BlockType.STONE.metadata);
		world.setBlock(x+50, y+0, z+40, b, BlockType.STONE.metadata);
		world.setBlock(x+50, y+0, z+41, b, BlockType.STONE.metadata);
		world.setBlock(x+50, y+0, z+42, b, BlockType.STONE.metadata);
		world.setBlock(x+50, y+0, z+43, b, BlockType.STONE.metadata);
		world.setBlock(x+50, y+0, z+44, b, BlockType.STONE.metadata);
		world.setBlock(x+50, y+0, z+45, b, BlockType.STONE.metadata);
		world.setBlock(x+50, y+0, z+46, b, BlockType.STONE.metadata);
		world.setBlock(x+50, y+0, z+47, b, BlockType.STONE.metadata);
		world.setBlock(x+50, y+0, z+48, b, BlockType.CLOAK.metadata);
		world.setBlock(x+50, y+0, z+49, b, BlockType.CLOAK.metadata);
		world.setBlock(x+50, y+0, z+50, b, BlockType.CLOAK.metadata);
		world.setBlock(x+50, y+0, z+51, b, BlockType.STONE.metadata);
		world.setBlock(x+50, y+0, z+52, b, BlockType.STONE.metadata);
		world.setBlock(x+50, y+0, z+53, b, BlockType.STONE.metadata);
		world.setBlock(x+50, y+0, z+54, b, BlockType.STONE.metadata);
		world.setBlock(x+50, y+0, z+55, b, BlockType.STONE.metadata);
		world.setBlock(x+50, y+0, z+56, b, BlockType.CLOAK.metadata);
		world.setBlock(x+50, y+0, z+57, b, BlockType.CLOAK.metadata);
		world.setBlock(x+50, y+0, z+58, b, BlockType.CLOAK.metadata);
		world.setBlock(x+50, y+0, z+59, b, BlockType.STONE.metadata);
		world.setBlock(x+50, y+0, z+60, b, BlockType.CLOAK.metadata);
		world.setBlock(x+50, y+0, z+61, b, BlockType.CLOAK.metadata);
		world.setBlock(x+50, y+0, z+62, b, BlockType.CLOAK.metadata);
		world.setBlock(x+50, y+0, z+63, b, BlockType.CLOAK.metadata);
		world.setBlock(x+50, y+0, z+64, b, BlockType.CLOAK.metadata);
		world.setBlock(x+50, y+0, z+65, b, BlockType.CLOAK.metadata);
		world.setBlock(x+50, y+0, z+66, b, BlockType.CLOAK.metadata);
		world.setBlock(x+50, y+0, z+67, b, BlockType.CLOAK.metadata);
		world.setBlock(x+50, y+0, z+68, b, BlockType.CLOAK.metadata);
		world.setBlock(x+50, y+0, z+69, b, BlockType.CLOAK.metadata);
		world.setBlock(x+50, y+0, z+70, b, BlockType.CLOAK.metadata);
		world.setBlock(x+50, y+0, z+71, b, BlockType.STONE.metadata);
		world.setBlock(x+50, y+1, z+12, b, BlockType.STONE.metadata);
		world.setBlock(x+50, y+1, z+13, b, BlockType.STONE.metadata);
		world.setBlock(x+50, y+1, z+14, b, BlockType.STONE.metadata);
		world.setBlock(x+50, y+1, z+15, b, BlockType.STONE.metadata);
		world.setBlock(x+50, y+1, z+16, b, BlockType.STONE.metadata);
		world.setBlock(x+50, y+1, z+17, b, BlockType.STONE.metadata);
		world.setBlock(x+50, y+1, z+18, b, BlockType.STONE.metadata);
		world.setBlock(x+50, y+1, z+19, b, BlockType.STONE.metadata);
		world.setBlock(x+50, y+1, z+20, b, BlockType.STONE.metadata);
		world.setBlock(x+50, y+1, z+21, b, BlockType.STONE.metadata);
		world.setBlock(x+50, y+1, z+22, b, BlockType.STONE.metadata);
		world.setBlock(x+50, y+1, z+24, b, BlockType.STONE.metadata);
		world.setBlock(x+50, y+1, z+28, b, BlockType.STONE.metadata);
		world.setBlock(x+50, y+1, z+29, b, BlockType.STONE.metadata);
		world.setBlock(x+50, y+1, z+30, b, BlockType.STONE.metadata);
		world.setBlock(x+50, y+1, z+31, b, BlockType.STONE.metadata);
		world.setBlock(x+50, y+1, z+32, b, BlockType.STONE.metadata);
		world.setBlock(x+50, y+1, z+33, b, BlockType.STONE.metadata);
		world.setBlock(x+50, y+1, z+34, b, BlockType.STONE.metadata);
		world.setBlock(x+50, y+1, z+38, b, BlockType.STONE.metadata);
		world.setBlock(x+50, y+1, z+39, b, BlockType.STONE.metadata);
		world.setBlock(x+50, y+1, z+40, b, BlockType.STONE.metadata);
		world.setBlock(x+50, y+1, z+41, b, BlockType.STONE.metadata);
		world.setBlock(x+50, y+1, z+42, b, BlockType.STONE.metadata);
		world.setBlock(x+50, y+1, z+43, b, BlockType.STONE.metadata);
		world.setBlock(x+50, y+1, z+44, b, BlockType.STONE.metadata);
		world.setBlock(x+50, y+1, z+45, b, BlockType.STONE.metadata);
		world.setBlock(x+50, y+1, z+46, b, BlockType.STONE.metadata);
		world.setBlock(x+50, y+1, z+47, b, BlockType.STONE.metadata);
		world.setBlock(x+50, y+1, z+51, b, BlockType.STONE.metadata);
		world.setBlock(x+50, y+1, z+52, b, BlockType.STONE.metadata);
		world.setBlock(x+50, y+1, z+53, b, BlockType.STONE.metadata);
		world.setBlock(x+50, y+1, z+54, b, BlockType.STONE.metadata);
		world.setBlock(x+50, y+1, z+55, b, BlockType.STONE.metadata);
		world.setBlock(x+50, y+1, z+59, b, BlockType.STONE.metadata);
		world.setBlock(x+50, y+1, z+71, b, BlockType.STONE.metadata);
		world.setBlock(x+50, y+2, z+12, b, BlockType.STONE.metadata);
		world.setBlock(x+50, y+2, z+13, b, BlockType.STONE.metadata);
		world.setBlock(x+50, y+2, z+14, b, BlockType.STONE.metadata);
		world.setBlock(x+50, y+2, z+15, b, BlockType.STONE.metadata);
		world.setBlock(x+50, y+2, z+16, b, BlockType.STONE.metadata);
		world.setBlock(x+50, y+2, z+17, b, BlockType.STONE.metadata);
		world.setBlock(x+50, y+2, z+18, b, BlockType.STONE.metadata);
		world.setBlock(x+50, y+2, z+19, b, BlockType.STONE.metadata);
		world.setBlock(x+50, y+2, z+20, b, BlockType.STONE.metadata);
		world.setBlock(x+50, y+2, z+21, b, BlockType.STONE.metadata);
		world.setBlock(x+50, y+2, z+22, b, BlockType.STONE.metadata);
		world.setBlock(x+50, y+2, z+24, b, BlockType.STONE.metadata);
		world.setBlock(x+50, y+2, z+28, b, BlockType.STONE.metadata);
		world.setBlock(x+50, y+2, z+29, b, BlockType.STONE.metadata);
		world.setBlock(x+50, y+2, z+30, b, BlockType.STONE.metadata);
		world.setBlock(x+50, y+2, z+31, b, BlockType.STONE.metadata);
		world.setBlock(x+50, y+2, z+32, b, BlockType.STONE.metadata);
		world.setBlock(x+50, y+2, z+33, b, BlockType.STONE.metadata);
		world.setBlock(x+50, y+2, z+34, b, BlockType.STONE.metadata);
		world.setBlock(x+50, y+2, z+38, b, BlockType.STONE.metadata);
		world.setBlock(x+50, y+2, z+39, b, BlockType.STONE.metadata);
		world.setBlock(x+50, y+2, z+40, b, BlockType.STONE.metadata);
		world.setBlock(x+50, y+2, z+41, b, BlockType.STONE.metadata);
		world.setBlock(x+50, y+2, z+42, b, BlockType.STONE.metadata);
		world.setBlock(x+50, y+2, z+43, b, BlockType.STONE.metadata);
		world.setBlock(x+50, y+2, z+44, b, BlockType.STONE.metadata);
		world.setBlock(x+50, y+2, z+45, b, BlockType.STONE.metadata);
		world.setBlock(x+50, y+2, z+46, b, BlockType.STONE.metadata);
		world.setBlock(x+50, y+2, z+47, b, BlockType.STONE.metadata);
		world.setBlock(x+50, y+2, z+51, b, BlockType.STONE.metadata);
		world.setBlock(x+50, y+2, z+52, b, BlockType.STONE.metadata);
		world.setBlock(x+50, y+2, z+53, b, BlockType.STONE.metadata);
		world.setBlock(x+50, y+2, z+54, b, BlockType.STONE.metadata);
		world.setBlock(x+50, y+2, z+55, b, BlockType.STONE.metadata);
		world.setBlock(x+50, y+2, z+59, b, BlockType.STONE.metadata);
		world.setBlock(x+50, y+2, z+71, b, BlockType.STONE.metadata);
		world.setBlock(x+50, y+3, z+12, b, BlockType.STONE.metadata);
		world.setBlock(x+50, y+3, z+13, b, BlockType.STONE.metadata);
		world.setBlock(x+50, y+3, z+14, b, BlockType.STONE.metadata);
		world.setBlock(x+50, y+3, z+15, b, BlockType.STONE.metadata);
		world.setBlock(x+50, y+3, z+16, b, BlockType.STONE.metadata);
		world.setBlock(x+50, y+3, z+17, b, BlockType.STONE.metadata);
		world.setBlock(x+50, y+3, z+18, b, BlockType.STONE.metadata);
		world.setBlock(x+50, y+3, z+19, b, BlockType.STONE.metadata);
		world.setBlock(x+50, y+3, z+20, b, BlockType.STONE.metadata);
		world.setBlock(x+50, y+3, z+21, b, BlockType.STONE.metadata);
		world.setBlock(x+50, y+3, z+22, b, BlockType.STONE.metadata);
		world.setBlock(x+50, y+3, z+24, b, BlockType.STONE.metadata);
		world.setBlock(x+50, y+3, z+28, b, BlockType.STONE.metadata);
		world.setBlock(x+50, y+3, z+29, b, BlockType.STONE.metadata);
		world.setBlock(x+50, y+3, z+30, b, BlockType.STONE.metadata);
		world.setBlock(x+50, y+3, z+31, b, BlockType.STONE.metadata);
		world.setBlock(x+50, y+3, z+32, b, BlockType.STONE.metadata);
		world.setBlock(x+50, y+3, z+33, b, BlockType.STONE.metadata);
		world.setBlock(x+50, y+3, z+34, b, BlockType.STONE.metadata);
		world.setBlock(x+50, y+3, z+38, b, BlockType.STONE.metadata);
		world.setBlock(x+50, y+3, z+39, b, BlockType.STONE.metadata);
		world.setBlock(x+50, y+3, z+40, b, BlockType.STONE.metadata);
		world.setBlock(x+50, y+3, z+41, b, BlockType.STONE.metadata);
		world.setBlock(x+50, y+3, z+42, b, BlockType.STONE.metadata);
		world.setBlock(x+50, y+3, z+43, b, BlockType.STONE.metadata);
		world.setBlock(x+50, y+3, z+44, b, BlockType.STONE.metadata);
		world.setBlock(x+50, y+3, z+45, b, BlockType.STONE.metadata);
		world.setBlock(x+50, y+3, z+46, b, BlockType.STONE.metadata);
		world.setBlock(x+50, y+3, z+47, b, BlockType.STONE.metadata);
		world.setBlock(x+50, y+3, z+51, b, BlockType.STONE.metadata);
		world.setBlock(x+50, y+3, z+52, b, BlockType.STONE.metadata);
		world.setBlock(x+50, y+3, z+53, b, BlockType.STONE.metadata);
		world.setBlock(x+50, y+3, z+54, b, BlockType.STONE.metadata);
		world.setBlock(x+50, y+3, z+55, b, BlockType.STONE.metadata);
		world.setBlock(x+50, y+3, z+59, b, BlockType.STONE.metadata);
		world.setBlock(x+50, y+3, z+71, b, BlockType.STONE.metadata);
		world.setBlock(x+50, y+4, z+12, b, BlockType.STONE.metadata);
		world.setBlock(x+50, y+4, z+13, b, BlockType.STONE.metadata);
		world.setBlock(x+50, y+4, z+14, b, BlockType.STONE.metadata);
		world.setBlock(x+50, y+4, z+15, b, BlockType.STONE.metadata);
		world.setBlock(x+50, y+4, z+16, b, BlockType.STONE.metadata);
		world.setBlock(x+50, y+4, z+17, b, BlockType.STONE.metadata);
		world.setBlock(x+50, y+4, z+18, b, BlockType.STONE.metadata);
		world.setBlock(x+50, y+4, z+19, b, BlockType.STONE.metadata);
		world.setBlock(x+50, y+4, z+20, b, BlockType.STONE.metadata);
		world.setBlock(x+50, y+4, z+21, b, BlockType.STONE.metadata);
		world.setBlock(x+50, y+4, z+22, b, BlockType.STONE.metadata);
		world.setBlock(x+50, y+4, z+24, b, BlockType.STONE.metadata);
		world.setBlock(x+50, y+4, z+25, b, BlockType.STONE.metadata);
		world.setBlock(x+50, y+4, z+26, b, BlockType.STONE.metadata);
		world.setBlock(x+50, y+4, z+27, b, BlockType.STONE.metadata);
		world.setBlock(x+50, y+4, z+28, b, BlockType.STONE.metadata);
		world.setBlock(x+50, y+4, z+29, b, BlockType.STONE.metadata);
		world.setBlock(x+50, y+4, z+30, b, BlockType.STONE.metadata);
		world.setBlock(x+50, y+4, z+31, b, BlockType.STONE.metadata);
		world.setBlock(x+50, y+4, z+32, b, BlockType.STONE.metadata);
		world.setBlock(x+50, y+4, z+33, b, BlockType.STONE.metadata);
		world.setBlock(x+50, y+4, z+34, b, BlockType.STONE.metadata);
		world.setBlock(x+50, y+4, z+35, b, BlockType.STONE.metadata);
		world.setBlock(x+50, y+4, z+36, b, BlockType.STONE.metadata);
		world.setBlock(x+50, y+4, z+37, b, BlockType.STONE.metadata);
		world.setBlock(x+50, y+4, z+38, b, BlockType.STONE.metadata);
		world.setBlock(x+50, y+4, z+39, b, BlockType.STONE.metadata);
		world.setBlock(x+50, y+4, z+40, b, BlockType.STONE.metadata);
		world.setBlock(x+50, y+4, z+41, b, BlockType.STONE.metadata);
		world.setBlock(x+50, y+4, z+42, b, BlockType.STONE.metadata);
		world.setBlock(x+50, y+4, z+43, b, BlockType.STONE.metadata);
		world.setBlock(x+50, y+4, z+44, b, BlockType.STONE.metadata);
		world.setBlock(x+50, y+4, z+45, b, BlockType.STONE.metadata);
		world.setBlock(x+50, y+4, z+46, b, BlockType.STONE.metadata);
		world.setBlock(x+50, y+4, z+47, b, BlockType.STONE.metadata);
		world.setBlock(x+50, y+4, z+48, b, BlockType.STONE.metadata);
		world.setBlock(x+50, y+4, z+49, b, BlockType.STONE.metadata);
		world.setBlock(x+50, y+4, z+50, b, BlockType.STONE.metadata);
		world.setBlock(x+50, y+4, z+51, b, BlockType.STONE.metadata);
		world.setBlock(x+50, y+4, z+52, b, BlockType.STONE.metadata);
		world.setBlock(x+50, y+4, z+53, b, BlockType.STONE.metadata);
		world.setBlock(x+50, y+4, z+54, b, BlockType.STONE.metadata);
		world.setBlock(x+50, y+4, z+55, b, BlockType.STONE.metadata);
		world.setBlock(x+50, y+4, z+56, b, BlockType.STONE.metadata);
		world.setBlock(x+50, y+4, z+57, b, BlockType.STONE.metadata);
		world.setBlock(x+50, y+4, z+58, b, BlockType.STONE.metadata);
		world.setBlock(x+50, y+4, z+59, b, BlockType.STONE.metadata);
		world.setBlock(x+50, y+4, z+60, b, BlockType.STONE.metadata);
		world.setBlock(x+50, y+4, z+61, b, BlockType.STONE.metadata);
		world.setBlock(x+50, y+4, z+62, b, BlockType.STONE.metadata);
		world.setBlock(x+50, y+4, z+63, b, BlockType.STONE.metadata);
		world.setBlock(x+50, y+4, z+64, b, BlockType.STONE.metadata);
		world.setBlock(x+50, y+4, z+65, b, BlockType.STONE.metadata);
		world.setBlock(x+50, y+4, z+66, b, BlockType.STONE.metadata);
		world.setBlock(x+50, y+4, z+67, b, BlockType.STONE.metadata);
		world.setBlock(x+50, y+4, z+68, b, BlockType.STONE.metadata);
		world.setBlock(x+50, y+4, z+69, b, BlockType.STONE.metadata);
		world.setBlock(x+50, y+4, z+70, b, BlockType.STONE.metadata);
		world.setBlock(x+50, y+4, z+71, b, BlockType.STONE.metadata);
		world.setBlock(x+51, y+0, z+12, b, BlockType.STONE.metadata);
		world.setBlock(x+51, y+0, z+13, b, BlockType.CLOAK.metadata);
		world.setBlock(x+51, y+0, z+14, b, BlockType.CLOAK.metadata);
		world.setBlock(x+51, y+0, z+15, b, BlockType.CLOAK.metadata);
		world.setBlock(x+51, y+0, z+16, b, BlockType.CLOAK.metadata);
		world.setBlock(x+51, y+0, z+17, b, BlockType.CLOAK.metadata);
		world.setBlock(x+51, y+0, z+18, b, BlockType.CLOAK.metadata);
		world.setBlock(x+51, y+0, z+19, b, BlockType.CLOAK.metadata);
		world.setBlock(x+51, y+0, z+20, b, BlockType.CLOAK.metadata);
		world.setBlock(x+51, y+0, z+21, b, BlockType.CLOAK.metadata);
		world.setBlock(x+51, y+0, z+22, b, BlockType.STONE.metadata);
		world.setBlock(x+51, y+0, z+24, b, BlockType.STONE.metadata);
		world.setBlock(x+51, y+0, z+25, b, BlockType.CLOAK.metadata);
		world.setBlock(x+51, y+0, z+26, b, BlockType.CLOAK.metadata);
		world.setBlock(x+51, y+0, z+27, b, BlockType.CLOAK.metadata);
		world.setBlock(x+51, y+0, z+28, b, BlockType.CLOAK.metadata);
		world.setBlock(x+51, y+0, z+29, b, BlockType.CLOAK.metadata);
		world.setBlock(x+51, y+0, z+30, b, BlockType.CLOAK.metadata);
		world.setBlock(x+51, y+0, z+31, b, BlockType.CLOAK.metadata);
		world.setBlock(x+51, y+0, z+32, b, BlockType.CLOAK.metadata);
		world.setBlock(x+51, y+0, z+33, b, BlockType.CLOAK.metadata);
		world.setBlock(x+51, y+0, z+34, b, BlockType.CLOAK.metadata);
		world.setBlock(x+51, y+0, z+35, b, BlockType.CLOAK.metadata);
		world.setBlock(x+51, y+0, z+36, b, BlockType.CLOAK.metadata);
		world.setBlock(x+51, y+0, z+37, b, BlockType.CLOAK.metadata);
		world.setBlock(x+51, y+0, z+38, b, BlockType.CLOAK.metadata);
		world.setBlock(x+51, y+0, z+39, b, BlockType.CLOAK.metadata);
		world.setBlock(x+51, y+0, z+40, b, BlockType.CLOAK.metadata);
		world.setBlock(x+51, y+0, z+41, b, BlockType.CLOAK.metadata);
		world.setBlock(x+51, y+0, z+42, b, BlockType.CLOAK.metadata);
		world.setBlock(x+51, y+0, z+43, b, BlockType.CLOAK.metadata);
		world.setBlock(x+51, y+0, z+44, b, BlockType.CLOAK.metadata);
		world.setBlock(x+51, y+0, z+45, b, BlockType.CLOAK.metadata);
		world.setBlock(x+51, y+0, z+46, b, BlockType.CLOAK.metadata);
		world.setBlock(x+51, y+0, z+47, b, BlockType.STONE.metadata);
		world.setBlock(x+51, y+0, z+48, b, BlockType.CLOAK.metadata);
		world.setBlock(x+51, y+0, z+49, b, BlockType.CLOAK.metadata);
		world.setBlock(x+51, y+0, z+50, b, BlockType.CLOAK.metadata);
		world.setBlock(x+51, y+0, z+51, b, BlockType.CLOAK.metadata);
		world.setBlock(x+51, y+0, z+52, b, BlockType.CLOAK.metadata);
		world.setBlock(x+51, y+0, z+53, b, BlockType.CLOAK.metadata);
		world.setBlock(x+51, y+0, z+54, b, BlockType.CLOAK.metadata);
		world.setBlock(x+51, y+0, z+55, b, BlockType.CLOAK.metadata);
		world.setBlock(x+51, y+0, z+56, b, BlockType.CLOAK.metadata);
		world.setBlock(x+51, y+0, z+57, b, BlockType.CLOAK.metadata);
		world.setBlock(x+51, y+0, z+58, b, BlockType.CLOAK.metadata);
		world.setBlock(x+51, y+0, z+59, b, BlockType.STONE.metadata);
		world.setBlock(x+51, y+0, z+60, b, BlockType.CLOAK.metadata);
		world.setBlock(x+51, y+0, z+61, b, BlockType.CLOAK.metadata);
		world.setBlock(x+51, y+0, z+62, b, BlockType.CLOAK.metadata);
		world.setBlock(x+51, y+0, z+63, b, BlockType.CLOAK.metadata);
		world.setBlock(x+51, y+0, z+64, b, BlockType.CLOAK.metadata);
		world.setBlock(x+51, y+0, z+65, b, BlockType.CLOAK.metadata);
		world.setBlock(x+51, y+0, z+66, b, BlockType.CLOAK.metadata);
		world.setBlock(x+51, y+0, z+67, b, BlockType.CLOAK.metadata);
		world.setBlock(x+51, y+0, z+68, b, BlockType.CLOAK.metadata);
		world.setBlock(x+51, y+0, z+69, b, BlockType.CLOAK.metadata);
		world.setBlock(x+51, y+0, z+70, b, BlockType.CLOAK.metadata);
		world.setBlock(x+51, y+0, z+71, b, BlockType.STONE.metadata);
		world.setBlock(x+51, y+1, z+12, b, BlockType.STONE.metadata);
		world.setBlock(x+51, y+1, z+22, b, BlockType.STONE.metadata);
		world.setBlock(x+51, y+1, z+24, b, BlockType.STONE.metadata);
		world.setBlock(x+51, y+1, z+47, b, BlockType.STONE.metadata);
		world.setBlock(x+51, y+1, z+59, b, BlockType.STONE.metadata);
		world.setBlock(x+51, y+1, z+71, b, BlockType.STONE.metadata);
		world.setBlock(x+51, y+2, z+12, b, BlockType.STONE.metadata);
		world.setBlock(x+51, y+2, z+22, b, BlockType.STONE.metadata);
		world.setBlock(x+51, y+2, z+24, b, BlockType.STONE.metadata);
		world.setBlock(x+51, y+2, z+47, b, BlockType.STONE.metadata);
		world.setBlock(x+51, y+2, z+59, b, BlockType.STONE.metadata);
		world.setBlock(x+51, y+2, z+71, b, BlockType.STONE.metadata);
		world.setBlock(x+51, y+3, z+12, b, BlockType.STONE.metadata);
		world.setBlock(x+51, y+3, z+22, b, BlockType.STONE.metadata);
		world.setBlock(x+51, y+3, z+24, b, BlockType.STONE.metadata);
		world.setBlock(x+51, y+3, z+47, b, BlockType.STONE.metadata);
		world.setBlock(x+51, y+3, z+59, b, BlockType.STONE.metadata);
		world.setBlock(x+51, y+3, z+71, b, BlockType.STONE.metadata);
		world.setBlock(x+51, y+4, z+12, b, BlockType.STONE.metadata);
		world.setBlock(x+51, y+4, z+13, b, BlockType.STONE.metadata);
		world.setBlock(x+51, y+4, z+14, b, BlockType.STONE.metadata);
		world.setBlock(x+51, y+4, z+15, b, BlockType.STONE.metadata);
		world.setBlock(x+51, y+4, z+16, b, BlockType.STONE.metadata);
		world.setBlock(x+51, y+4, z+17, b, BlockType.STONE.metadata);
		world.setBlock(x+51, y+4, z+18, b, BlockType.STONE.metadata);
		world.setBlock(x+51, y+4, z+19, b, BlockType.STONE.metadata);
		world.setBlock(x+51, y+4, z+20, b, BlockType.STONE.metadata);
		world.setBlock(x+51, y+4, z+21, b, BlockType.STONE.metadata);
		world.setBlock(x+51, y+4, z+22, b, BlockType.STONE.metadata);
		world.setBlock(x+51, y+4, z+24, b, BlockType.STONE.metadata);
		world.setBlock(x+51, y+4, z+25, b, BlockType.STONE.metadata);
		world.setBlock(x+51, y+4, z+26, b, BlockType.STONE.metadata);
		world.setBlock(x+51, y+4, z+27, b, BlockType.STONE.metadata);
		world.setBlock(x+51, y+4, z+28, b, BlockType.STONE.metadata);
		world.setBlock(x+51, y+4, z+29, b, BlockType.STONE.metadata);
		world.setBlock(x+51, y+4, z+30, b, BlockType.STONE.metadata);
		world.setBlock(x+51, y+4, z+31, b, BlockType.STONE.metadata);
		world.setBlock(x+51, y+4, z+32, b, BlockType.STONE.metadata);
		world.setBlock(x+51, y+4, z+33, b, BlockType.STONE.metadata);
		world.setBlock(x+51, y+4, z+34, b, BlockType.STONE.metadata);
		world.setBlock(x+51, y+4, z+35, b, BlockType.STONE.metadata);
		world.setBlock(x+51, y+4, z+36, b, BlockType.STONE.metadata);
		world.setBlock(x+51, y+4, z+37, b, BlockType.STONE.metadata);
		world.setBlock(x+51, y+4, z+38, b, BlockType.STONE.metadata);
		world.setBlock(x+51, y+4, z+39, b, BlockType.STONE.metadata);
		world.setBlock(x+51, y+4, z+40, b, BlockType.STONE.metadata);
		world.setBlock(x+51, y+4, z+41, b, BlockType.STONE.metadata);
		world.setBlock(x+51, y+4, z+42, b, BlockType.STONE.metadata);
		world.setBlock(x+51, y+4, z+43, b, BlockType.STONE.metadata);
		world.setBlock(x+51, y+4, z+44, b, BlockType.STONE.metadata);
		world.setBlock(x+51, y+4, z+45, b, BlockType.STONE.metadata);
		world.setBlock(x+51, y+4, z+46, b, BlockType.STONE.metadata);
		world.setBlock(x+51, y+4, z+47, b, BlockType.STONE.metadata);
		world.setBlock(x+51, y+4, z+48, b, BlockType.STONE.metadata);
		world.setBlock(x+51, y+4, z+49, b, BlockType.STONE.metadata);
		world.setBlock(x+51, y+4, z+50, b, BlockType.STONE.metadata);
		world.setBlock(x+51, y+4, z+51, b, BlockType.STONE.metadata);
		world.setBlock(x+51, y+4, z+52, b, BlockType.STONE.metadata);
		world.setBlock(x+51, y+4, z+53, b, BlockType.STONE.metadata);
		world.setBlock(x+51, y+4, z+54, b, BlockType.STONE.metadata);
		world.setBlock(x+51, y+4, z+55, b, BlockType.STONE.metadata);
		world.setBlock(x+51, y+4, z+56, b, BlockType.STONE.metadata);
		world.setBlock(x+51, y+4, z+57, b, BlockType.STONE.metadata);
		world.setBlock(x+51, y+4, z+58, b, BlockType.STONE.metadata);
		world.setBlock(x+51, y+4, z+59, b, BlockType.STONE.metadata);
		world.setBlock(x+51, y+4, z+60, b, BlockType.STONE.metadata);
		world.setBlock(x+51, y+4, z+61, b, BlockType.STONE.metadata);
		world.setBlock(x+51, y+4, z+62, b, BlockType.STONE.metadata);
		world.setBlock(x+51, y+4, z+63, b, BlockType.STONE.metadata);
		world.setBlock(x+51, y+4, z+64, b, BlockType.STONE.metadata);
		world.setBlock(x+51, y+4, z+65, b, BlockType.STONE.metadata);
		world.setBlock(x+51, y+4, z+66, b, BlockType.STONE.metadata);
		world.setBlock(x+51, y+4, z+67, b, BlockType.STONE.metadata);
		world.setBlock(x+51, y+4, z+68, b, BlockType.STONE.metadata);
		world.setBlock(x+51, y+4, z+69, b, BlockType.STONE.metadata);
		world.setBlock(x+51, y+4, z+70, b, BlockType.STONE.metadata);
		world.setBlock(x+51, y+4, z+71, b, BlockType.STONE.metadata);
		world.setBlock(x+52, y+0, z+12, b, BlockType.STONE.metadata);
		world.setBlock(x+52, y+0, z+13, b, BlockType.CLOAK.metadata);
		world.setBlock(x+52, y+0, z+14, b, BlockType.CLOAK.metadata);
		world.setBlock(x+52, y+0, z+15, b, BlockType.CLOAK.metadata);
		world.setBlock(x+52, y+0, z+16, b, BlockType.CLOAK.metadata);
		world.setBlock(x+52, y+0, z+17, b, BlockType.CLOAK.metadata);
		world.setBlock(x+52, y+0, z+18, b, BlockType.CLOAK.metadata);
		world.setBlock(x+52, y+0, z+19, b, BlockType.CLOAK.metadata);
		world.setBlock(x+52, y+0, z+20, b, BlockType.CLOAK.metadata);
		world.setBlock(x+52, y+0, z+21, b, BlockType.CLOAK.metadata);
		world.setBlock(x+52, y+0, z+22, b, BlockType.STONE.metadata);
		world.setBlock(x+52, y+0, z+24, b, BlockType.STONE.metadata);
		world.setBlock(x+52, y+0, z+25, b, BlockType.CLOAK.metadata);
		world.setBlock(x+52, y+0, z+26, b, BlockType.CLOAK.metadata);
		world.setBlock(x+52, y+0, z+27, b, BlockType.CLOAK.metadata);
		world.setBlock(x+52, y+0, z+28, b, BlockType.CLOAK.metadata);
		world.setBlock(x+52, y+0, z+29, b, BlockType.CLOAK.metadata);
		world.setBlock(x+52, y+0, z+30, b, BlockType.CLOAK.metadata);
		world.setBlock(x+52, y+0, z+31, b, BlockType.CLOAK.metadata);
		world.setBlock(x+52, y+0, z+32, b, BlockType.CLOAK.metadata);
		world.setBlock(x+52, y+0, z+33, b, BlockType.CLOAK.metadata);
		world.setBlock(x+52, y+0, z+34, b, BlockType.CLOAK.metadata);
		world.setBlock(x+52, y+0, z+35, b, BlockType.CLOAK.metadata);
		world.setBlock(x+52, y+0, z+36, b, BlockType.CLOAK.metadata);
		world.setBlock(x+52, y+0, z+37, b, BlockType.CLOAK.metadata);
		world.setBlock(x+52, y+0, z+38, b, BlockType.CLOAK.metadata);
		world.setBlock(x+52, y+0, z+39, b, BlockType.CLOAK.metadata);
		world.setBlock(x+52, y+0, z+40, b, BlockType.CLOAK.metadata);
		world.setBlock(x+52, y+0, z+41, b, BlockType.CLOAK.metadata);
		world.setBlock(x+52, y+0, z+42, b, BlockType.CLOAK.metadata);
		world.setBlock(x+52, y+0, z+43, b, BlockType.CLOAK.metadata);
		world.setBlock(x+52, y+0, z+44, b, BlockType.CLOAK.metadata);
		world.setBlock(x+52, y+0, z+45, b, BlockType.CLOAK.metadata);
		world.setBlock(x+52, y+0, z+46, b, BlockType.CLOAK.metadata);
		world.setBlock(x+52, y+0, z+47, b, BlockType.STONE.metadata);
		world.setBlock(x+52, y+0, z+48, b, BlockType.CLOAK.metadata);
		world.setBlock(x+52, y+0, z+49, b, BlockType.CLOAK.metadata);
		world.setBlock(x+52, y+0, z+50, b, BlockType.CLOAK.metadata);
		world.setBlock(x+52, y+0, z+51, b, BlockType.CLOAK.metadata);
		world.setBlock(x+52, y+0, z+52, b, BlockType.CLOAK.metadata);
		world.setBlock(x+52, y+0, z+53, b, BlockType.CLOAK.metadata);
		world.setBlock(x+52, y+0, z+54, b, BlockType.CLOAK.metadata);
		world.setBlock(x+52, y+0, z+55, b, BlockType.CLOAK.metadata);
		world.setBlock(x+52, y+0, z+56, b, BlockType.CLOAK.metadata);
		world.setBlock(x+52, y+0, z+57, b, BlockType.CLOAK.metadata);
		world.setBlock(x+52, y+0, z+58, b, BlockType.CLOAK.metadata);
		world.setBlock(x+52, y+0, z+59, b, BlockType.STONE.metadata);
		world.setBlock(x+52, y+0, z+60, b, BlockType.CLOAK.metadata);
		world.setBlock(x+52, y+0, z+61, b, BlockType.CLOAK.metadata);
		world.setBlock(x+52, y+0, z+62, b, BlockType.CLOAK.metadata);
		world.setBlock(x+52, y+0, z+63, b, BlockType.STONE.metadata);
		world.setBlock(x+52, y+0, z+64, b, BlockType.STONE.metadata);
		world.setBlock(x+52, y+0, z+65, b, BlockType.STONE.metadata);
		world.setBlock(x+52, y+0, z+66, b, BlockType.STONE.metadata);
		world.setBlock(x+52, y+0, z+67, b, BlockType.STONE.metadata);
		world.setBlock(x+52, y+0, z+68, b, BlockType.STONE.metadata);
		world.setBlock(x+52, y+0, z+69, b, BlockType.STONE.metadata);
		world.setBlock(x+52, y+0, z+70, b, BlockType.STONE.metadata);
		world.setBlock(x+52, y+0, z+71, b, BlockType.STONE.metadata);
		world.setBlock(x+52, y+1, z+12, b, BlockType.STONE.metadata);
		world.setBlock(x+52, y+1, z+22, b, BlockType.STONE.metadata);
		world.setBlock(x+52, y+1, z+24, b, BlockType.STONE.metadata);
		world.setBlock(x+52, y+1, z+47, b, BlockType.STONE.metadata);
		world.setBlock(x+52, y+1, z+59, b, BlockType.STONE.metadata);
		world.setBlock(x+52, y+1, z+63, b, BlockType.STONE.metadata);
		world.setBlock(x+52, y+1, z+64, b, BlockType.STONE.metadata);
		world.setBlock(x+52, y+1, z+65, b, BlockType.STONE.metadata);
		world.setBlock(x+52, y+1, z+66, b, BlockType.STONE.metadata);
		world.setBlock(x+52, y+1, z+67, b, BlockType.STONE.metadata);
		world.setBlock(x+52, y+1, z+68, b, BlockType.STONE.metadata);
		world.setBlock(x+52, y+1, z+69, b, BlockType.STONE.metadata);
		world.setBlock(x+52, y+1, z+70, b, BlockType.STONE.metadata);
		world.setBlock(x+52, y+1, z+71, b, BlockType.STONE.metadata);
		world.setBlock(x+52, y+2, z+12, b, BlockType.STONE.metadata);
		world.setBlock(x+52, y+2, z+22, b, BlockType.STONE.metadata);
		world.setBlock(x+52, y+2, z+24, b, BlockType.STONE.metadata);
		world.setBlock(x+52, y+2, z+47, b, BlockType.STONE.metadata);
		world.setBlock(x+52, y+2, z+59, b, BlockType.STONE.metadata);
		world.setBlock(x+52, y+2, z+63, b, BlockType.STONE.metadata);
		world.setBlock(x+52, y+2, z+64, b, BlockType.STONE.metadata);
		world.setBlock(x+52, y+2, z+65, b, BlockType.STONE.metadata);
		world.setBlock(x+52, y+2, z+66, b, BlockType.STONE.metadata);
		world.setBlock(x+52, y+2, z+67, b, BlockType.STONE.metadata);
		world.setBlock(x+52, y+2, z+68, b, BlockType.STONE.metadata);
		world.setBlock(x+52, y+2, z+69, b, BlockType.STONE.metadata);
		world.setBlock(x+52, y+2, z+70, b, BlockType.STONE.metadata);
		world.setBlock(x+52, y+2, z+71, b, BlockType.STONE.metadata);
		world.setBlock(x+52, y+3, z+12, b, BlockType.STONE.metadata);
		world.setBlock(x+52, y+3, z+22, b, BlockType.STONE.metadata);
		world.setBlock(x+52, y+3, z+24, b, BlockType.STONE.metadata);
		world.setBlock(x+52, y+3, z+47, b, BlockType.STONE.metadata);
		world.setBlock(x+52, y+3, z+59, b, BlockType.STONE.metadata);
		world.setBlock(x+52, y+3, z+63, b, BlockType.STONE.metadata);
		world.setBlock(x+52, y+3, z+64, b, BlockType.STONE.metadata);
		world.setBlock(x+52, y+3, z+65, b, BlockType.STONE.metadata);
		world.setBlock(x+52, y+3, z+66, b, BlockType.STONE.metadata);
		world.setBlock(x+52, y+3, z+67, b, BlockType.STONE.metadata);
		world.setBlock(x+52, y+3, z+68, b, BlockType.STONE.metadata);
		world.setBlock(x+52, y+3, z+69, b, BlockType.STONE.metadata);
		world.setBlock(x+52, y+3, z+70, b, BlockType.STONE.metadata);
		world.setBlock(x+52, y+3, z+71, b, BlockType.STONE.metadata);
		world.setBlock(x+52, y+4, z+12, b, BlockType.STONE.metadata);
		world.setBlock(x+52, y+4, z+13, b, BlockType.STONE.metadata);
		world.setBlock(x+52, y+4, z+14, b, BlockType.STONE.metadata);
		world.setBlock(x+52, y+4, z+15, b, BlockType.STONE.metadata);
		world.setBlock(x+52, y+4, z+16, b, BlockType.STONE.metadata);
		world.setBlock(x+52, y+4, z+17, b, BlockType.STONE.metadata);
		world.setBlock(x+52, y+4, z+18, b, BlockType.STONE.metadata);
		world.setBlock(x+52, y+4, z+19, b, BlockType.STONE.metadata);
		world.setBlock(x+52, y+4, z+20, b, BlockType.STONE.metadata);
		world.setBlock(x+52, y+4, z+21, b, BlockType.STONE.metadata);
		world.setBlock(x+52, y+4, z+22, b, BlockType.STONE.metadata);
		world.setBlock(x+52, y+4, z+24, b, BlockType.STONE.metadata);
		world.setBlock(x+52, y+4, z+25, b, BlockType.STONE.metadata);
		world.setBlock(x+52, y+4, z+26, b, BlockType.STONE.metadata);
		world.setBlock(x+52, y+4, z+27, b, BlockType.STONE.metadata);
		world.setBlock(x+52, y+4, z+28, b, BlockType.STONE.metadata);
		world.setBlock(x+52, y+4, z+29, b, BlockType.STONE.metadata);
		world.setBlock(x+52, y+4, z+30, b, BlockType.STONE.metadata);
		world.setBlock(x+52, y+4, z+31, b, BlockType.STONE.metadata);
		world.setBlock(x+52, y+4, z+32, b, BlockType.STONE.metadata);
		world.setBlock(x+52, y+4, z+33, b, BlockType.STONE.metadata);
		world.setBlock(x+52, y+4, z+34, b, BlockType.STONE.metadata);
		world.setBlock(x+52, y+4, z+35, b, BlockType.STONE.metadata);
		world.setBlock(x+52, y+4, z+36, b, BlockType.STONE.metadata);
		world.setBlock(x+52, y+4, z+37, b, BlockType.STONE.metadata);
		world.setBlock(x+52, y+4, z+38, b, BlockType.STONE.metadata);
		world.setBlock(x+52, y+4, z+39, b, BlockType.STONE.metadata);
		world.setBlock(x+52, y+4, z+40, b, BlockType.STONE.metadata);
		world.setBlock(x+52, y+4, z+41, b, BlockType.STONE.metadata);
		world.setBlock(x+52, y+4, z+42, b, BlockType.STONE.metadata);
		world.setBlock(x+52, y+4, z+43, b, BlockType.STONE.metadata);
		world.setBlock(x+52, y+4, z+44, b, BlockType.STONE.metadata);
		world.setBlock(x+52, y+4, z+45, b, BlockType.STONE.metadata);
		world.setBlock(x+52, y+4, z+46, b, BlockType.STONE.metadata);
		world.setBlock(x+52, y+4, z+47, b, BlockType.STONE.metadata);
		world.setBlock(x+52, y+4, z+48, b, BlockType.STONE.metadata);
		world.setBlock(x+52, y+4, z+49, b, BlockType.STONE.metadata);
		world.setBlock(x+52, y+4, z+50, b, BlockType.STONE.metadata);
		world.setBlock(x+52, y+4, z+51, b, BlockType.STONE.metadata);
		world.setBlock(x+52, y+4, z+52, b, BlockType.STONE.metadata);
		world.setBlock(x+52, y+4, z+53, b, BlockType.STONE.metadata);
		world.setBlock(x+52, y+4, z+54, b, BlockType.STONE.metadata);
		world.setBlock(x+52, y+4, z+55, b, BlockType.STONE.metadata);
		world.setBlock(x+52, y+4, z+56, b, BlockType.STONE.metadata);
		world.setBlock(x+52, y+4, z+57, b, BlockType.STONE.metadata);
		world.setBlock(x+52, y+4, z+58, b, BlockType.STONE.metadata);
		world.setBlock(x+52, y+4, z+59, b, BlockType.STONE.metadata);
		world.setBlock(x+52, y+4, z+60, b, BlockType.STONE.metadata);
		world.setBlock(x+52, y+4, z+61, b, BlockType.STONE.metadata);
		world.setBlock(x+52, y+4, z+62, b, BlockType.STONE.metadata);
		world.setBlock(x+52, y+4, z+63, b, BlockType.STONE.metadata);
		world.setBlock(x+52, y+4, z+64, b, BlockType.STONE.metadata);
		world.setBlock(x+52, y+4, z+65, b, BlockType.STONE.metadata);
		world.setBlock(x+52, y+4, z+66, b, BlockType.STONE.metadata);
		world.setBlock(x+52, y+4, z+67, b, BlockType.STONE.metadata);
		world.setBlock(x+52, y+4, z+68, b, BlockType.STONE.metadata);
		world.setBlock(x+52, y+4, z+69, b, BlockType.STONE.metadata);
		world.setBlock(x+52, y+4, z+70, b, BlockType.STONE.metadata);
		world.setBlock(x+52, y+4, z+71, b, BlockType.STONE.metadata);
		world.setBlock(x+53, y+0, z+12, b, BlockType.STONE.metadata);
		world.setBlock(x+53, y+0, z+13, b, BlockType.CLOAK.metadata);
		world.setBlock(x+53, y+0, z+14, b, BlockType.CLOAK.metadata);
		world.setBlock(x+53, y+0, z+15, b, BlockType.CLOAK.metadata);
		world.setBlock(x+53, y+0, z+16, b, BlockType.CLOAK.metadata);
		world.setBlock(x+53, y+0, z+17, b, BlockType.CLOAK.metadata);
		world.setBlock(x+53, y+0, z+18, b, BlockType.CLOAK.metadata);
		world.setBlock(x+53, y+0, z+19, b, BlockType.CLOAK.metadata);
		world.setBlock(x+53, y+0, z+20, b, BlockType.CLOAK.metadata);
		world.setBlock(x+53, y+0, z+21, b, BlockType.CLOAK.metadata);
		world.setBlock(x+53, y+0, z+22, b, BlockType.STONE.metadata);
		world.setBlock(x+53, y+0, z+24, b, BlockType.STONE.metadata);
		world.setBlock(x+53, y+0, z+25, b, BlockType.CLOAK.metadata);
		world.setBlock(x+53, y+0, z+26, b, BlockType.CLOAK.metadata);
		world.setBlock(x+53, y+0, z+27, b, BlockType.CLOAK.metadata);
		world.setBlock(x+53, y+0, z+28, b, BlockType.CLOAK.metadata);
		world.setBlock(x+53, y+0, z+29, b, BlockType.CLOAK.metadata);
		world.setBlock(x+53, y+0, z+30, b, BlockType.CLOAK.metadata);
		world.setBlock(x+53, y+0, z+31, b, BlockType.CLOAK.metadata);
		world.setBlock(x+53, y+0, z+32, b, BlockType.CLOAK.metadata);
		world.setBlock(x+53, y+0, z+33, b, BlockType.CLOAK.metadata);
		world.setBlock(x+53, y+0, z+34, b, BlockType.CLOAK.metadata);
		world.setBlock(x+53, y+0, z+35, b, BlockType.CLOAK.metadata);
		world.setBlock(x+53, y+0, z+36, b, BlockType.CLOAK.metadata);
		world.setBlock(x+53, y+0, z+37, b, BlockType.CLOAK.metadata);
		world.setBlock(x+53, y+0, z+38, b, BlockType.CLOAK.metadata);
		world.setBlock(x+53, y+0, z+39, b, BlockType.CLOAK.metadata);
		world.setBlock(x+53, y+0, z+40, b, BlockType.CLOAK.metadata);
		world.setBlock(x+53, y+0, z+41, b, BlockType.CLOAK.metadata);
		world.setBlock(x+53, y+0, z+42, b, BlockType.CLOAK.metadata);
		world.setBlock(x+53, y+0, z+43, b, BlockType.CLOAK.metadata);
		world.setBlock(x+53, y+0, z+44, b, BlockType.CLOAK.metadata);
		world.setBlock(x+53, y+0, z+45, b, BlockType.CLOAK.metadata);
		world.setBlock(x+53, y+0, z+46, b, BlockType.CLOAK.metadata);
		world.setBlock(x+53, y+0, z+47, b, BlockType.STONE.metadata);
		world.setBlock(x+53, y+0, z+48, b, BlockType.CLOAK.metadata);
		world.setBlock(x+53, y+0, z+49, b, BlockType.CLOAK.metadata);
		world.setBlock(x+53, y+0, z+50, b, BlockType.CLOAK.metadata);
		world.setBlock(x+53, y+0, z+51, b, BlockType.CLOAK.metadata);
		world.setBlock(x+53, y+0, z+52, b, BlockType.CLOAK.metadata);
		world.setBlock(x+53, y+0, z+53, b, BlockType.CLOAK.metadata);
		world.setBlock(x+53, y+0, z+54, b, BlockType.CLOAK.metadata);
		world.setBlock(x+53, y+0, z+55, b, BlockType.CLOAK.metadata);
		world.setBlock(x+53, y+0, z+56, b, BlockType.CLOAK.metadata);
		world.setBlock(x+53, y+0, z+57, b, BlockType.CLOAK.metadata);
		world.setBlock(x+53, y+0, z+58, b, BlockType.CLOAK.metadata);
		world.setBlock(x+53, y+0, z+59, b, BlockType.STONE.metadata);
		world.setBlock(x+53, y+0, z+60, b, BlockType.CLOAK.metadata);
		world.setBlock(x+53, y+0, z+61, b, BlockType.CLOAK.metadata);
		world.setBlock(x+53, y+0, z+62, b, BlockType.CLOAK.metadata);
		world.setBlock(x+53, y+0, z+63, b, BlockType.STONE.metadata);
		world.setBlock(x+53, y+1, z+12, b, BlockType.STONE.metadata);
		world.setBlock(x+53, y+1, z+22, b, BlockType.STONE.metadata);
		world.setBlock(x+53, y+1, z+24, b, BlockType.STONE.metadata);
		world.setBlock(x+53, y+1, z+47, b, BlockType.STONE.metadata);
		world.setBlock(x+53, y+1, z+59, b, BlockType.STONE.metadata);
		world.setBlock(x+53, y+1, z+63, b, BlockType.STONE.metadata);
		world.setBlock(x+53, y+2, z+12, b, BlockType.STONE.metadata);
		world.setBlock(x+53, y+2, z+22, b, BlockType.STONE.metadata);
		world.setBlock(x+53, y+2, z+24, b, BlockType.STONE.metadata);
		world.setBlock(x+53, y+2, z+47, b, BlockType.STONE.metadata);
		world.setBlock(x+53, y+2, z+59, b, BlockType.STONE.metadata);
		world.setBlock(x+53, y+2, z+63, b, BlockType.STONE.metadata);
		world.setBlock(x+53, y+3, z+12, b, BlockType.STONE.metadata);
		world.setBlock(x+53, y+3, z+22, b, BlockType.STONE.metadata);
		world.setBlock(x+53, y+3, z+24, b, BlockType.STONE.metadata);
		world.setBlock(x+53, y+3, z+47, b, BlockType.STONE.metadata);
		world.setBlock(x+53, y+3, z+59, b, BlockType.STONE.metadata);
		world.setBlock(x+53, y+3, z+63, b, BlockType.STONE.metadata);
		world.setBlock(x+53, y+4, z+12, b, BlockType.STONE.metadata);
		world.setBlock(x+53, y+4, z+13, b, BlockType.STONE.metadata);
		world.setBlock(x+53, y+4, z+14, b, BlockType.STONE.metadata);
		world.setBlock(x+53, y+4, z+15, b, BlockType.STONE.metadata);
		world.setBlock(x+53, y+4, z+16, b, BlockType.STONE.metadata);
		world.setBlock(x+53, y+4, z+17, b, BlockType.STONE.metadata);
		world.setBlock(x+53, y+4, z+18, b, BlockType.STONE.metadata);
		world.setBlock(x+53, y+4, z+19, b, BlockType.STONE.metadata);
		world.setBlock(x+53, y+4, z+20, b, BlockType.STONE.metadata);
		world.setBlock(x+53, y+4, z+21, b, BlockType.STONE.metadata);
		world.setBlock(x+53, y+4, z+22, b, BlockType.STONE.metadata);
		world.setBlock(x+53, y+4, z+24, b, BlockType.STONE.metadata);
		world.setBlock(x+53, y+4, z+25, b, BlockType.STONE.metadata);
		world.setBlock(x+53, y+4, z+26, b, BlockType.STONE.metadata);
		world.setBlock(x+53, y+4, z+27, b, BlockType.STONE.metadata);
		world.setBlock(x+53, y+4, z+28, b, BlockType.STONE.metadata);
		world.setBlock(x+53, y+4, z+29, b, BlockType.STONE.metadata);
		world.setBlock(x+53, y+4, z+30, b, BlockType.STONE.metadata);
		world.setBlock(x+53, y+4, z+31, b, BlockType.STONE.metadata);
		world.setBlock(x+53, y+4, z+32, b, BlockType.STONE.metadata);
		world.setBlock(x+53, y+4, z+33, b, BlockType.STONE.metadata);
		world.setBlock(x+53, y+4, z+34, b, BlockType.STONE.metadata);
		world.setBlock(x+53, y+4, z+35, b, BlockType.STONE.metadata);
		world.setBlock(x+53, y+4, z+36, b, BlockType.STONE.metadata);
		world.setBlock(x+53, y+4, z+37, b, BlockType.STONE.metadata);
		world.setBlock(x+53, y+4, z+38, b, BlockType.STONE.metadata);
		world.setBlock(x+53, y+4, z+39, b, BlockType.STONE.metadata);
		world.setBlock(x+53, y+4, z+40, b, BlockType.STONE.metadata);
		world.setBlock(x+53, y+4, z+41, b, BlockType.STONE.metadata);
		world.setBlock(x+53, y+4, z+42, b, BlockType.STONE.metadata);
		world.setBlock(x+53, y+4, z+43, b, BlockType.STONE.metadata);
		world.setBlock(x+53, y+4, z+44, b, BlockType.STONE.metadata);
		world.setBlock(x+53, y+4, z+45, b, BlockType.STONE.metadata);
		world.setBlock(x+53, y+4, z+46, b, BlockType.STONE.metadata);
		world.setBlock(x+53, y+4, z+47, b, BlockType.STONE.metadata);
		world.setBlock(x+53, y+4, z+48, b, BlockType.STONE.metadata);
		world.setBlock(x+53, y+4, z+49, b, BlockType.STONE.metadata);
		world.setBlock(x+53, y+4, z+50, b, BlockType.STONE.metadata);
		world.setBlock(x+53, y+4, z+51, b, BlockType.STONE.metadata);
		world.setBlock(x+53, y+4, z+52, b, BlockType.STONE.metadata);
		world.setBlock(x+53, y+4, z+53, b, BlockType.STONE.metadata);
		world.setBlock(x+53, y+4, z+54, b, BlockType.STONE.metadata);
		world.setBlock(x+53, y+4, z+55, b, BlockType.STONE.metadata);
		world.setBlock(x+53, y+4, z+56, b, BlockType.STONE.metadata);
		world.setBlock(x+53, y+4, z+57, b, BlockType.STONE.metadata);
		world.setBlock(x+53, y+4, z+58, b, BlockType.STONE.metadata);
		world.setBlock(x+53, y+4, z+59, b, BlockType.STONE.metadata);
		world.setBlock(x+53, y+4, z+60, b, BlockType.STONE.metadata);
		world.setBlock(x+53, y+4, z+61, b, BlockType.STONE.metadata);
		world.setBlock(x+53, y+4, z+62, b, BlockType.STONE.metadata);
		world.setBlock(x+53, y+4, z+63, b, BlockType.STONE.metadata);
		world.setBlock(x+54, y+0, z+12, b, BlockType.STONE.metadata);
		world.setBlock(x+54, y+0, z+13, b, BlockType.CLOAK.metadata);
		world.setBlock(x+54, y+0, z+14, b, BlockType.CLOAK.metadata);
		world.setBlock(x+54, y+0, z+15, b, BlockType.CLOAK.metadata);
		world.setBlock(x+54, y+0, z+16, b, BlockType.STONE.metadata);
		world.setBlock(x+54, y+0, z+17, b, BlockType.STONE.metadata);
		world.setBlock(x+54, y+0, z+18, b, BlockType.STONE.metadata);
		world.setBlock(x+54, y+0, z+19, b, BlockType.CLOAK.metadata);
		world.setBlock(x+54, y+0, z+20, b, BlockType.CLOAK.metadata);
		world.setBlock(x+54, y+0, z+21, b, BlockType.CLOAK.metadata);
		world.setBlock(x+54, y+0, z+22, b, BlockType.STONE.metadata);
		world.setBlock(x+54, y+0, z+23, b, BlockType.STONE.metadata);
		world.setBlock(x+54, y+0, z+24, b, BlockType.STONE.metadata);
		world.setBlock(x+54, y+0, z+25, b, BlockType.STONE.metadata);
		world.setBlock(x+54, y+0, z+26, b, BlockType.STONE.metadata);
		world.setBlock(x+54, y+0, z+27, b, BlockType.STONE.metadata);
		world.setBlock(x+54, y+0, z+28, b, BlockType.STONE.metadata);
		world.setBlock(x+54, y+0, z+29, b, BlockType.STONE.metadata);
		world.setBlock(x+54, y+0, z+30, b, BlockType.STONE.metadata);
		world.setBlock(x+54, y+0, z+31, b, BlockType.STONE.metadata);
		world.setBlock(x+54, y+0, z+32, b, BlockType.STONE.metadata);
		world.setBlock(x+54, y+0, z+33, b, BlockType.STONE.metadata);
		world.setBlock(x+54, y+0, z+34, b, BlockType.STONE.metadata);
		world.setBlock(x+54, y+0, z+35, b, BlockType.CLOAK.metadata);
		world.setBlock(x+54, y+0, z+36, b, BlockType.CLOAK.metadata);
		world.setBlock(x+54, y+0, z+37, b, BlockType.CLOAK.metadata);
		world.setBlock(x+54, y+0, z+38, b, BlockType.STONE.metadata);
		world.setBlock(x+54, y+0, z+39, b, BlockType.STONE.metadata);
		world.setBlock(x+54, y+0, z+40, b, BlockType.STONE.metadata);
		world.setBlock(x+54, y+0, z+41, b, BlockType.STONE.metadata);
		world.setBlock(x+54, y+0, z+42, b, BlockType.STONE.metadata);
		world.setBlock(x+54, y+0, z+43, b, BlockType.STONE.metadata);
		world.setBlock(x+54, y+0, z+44, b, BlockType.STONE.metadata);
		world.setBlock(x+54, y+0, z+45, b, BlockType.STONE.metadata);
		world.setBlock(x+54, y+0, z+46, b, BlockType.STONE.metadata);
		world.setBlock(x+54, y+0, z+47, b, BlockType.STONE.metadata);
		world.setBlock(x+54, y+0, z+48, b, BlockType.CLOAK.metadata);
		world.setBlock(x+54, y+0, z+49, b, BlockType.CLOAK.metadata);
		world.setBlock(x+54, y+0, z+50, b, BlockType.CLOAK.metadata);
		world.setBlock(x+54, y+0, z+51, b, BlockType.STONE.metadata);
		world.setBlock(x+54, y+0, z+52, b, BlockType.STONE.metadata);
		world.setBlock(x+54, y+0, z+53, b, BlockType.STONE.metadata);
		world.setBlock(x+54, y+0, z+54, b, BlockType.STONE.metadata);
		world.setBlock(x+54, y+0, z+55, b, BlockType.STONE.metadata);
		world.setBlock(x+54, y+0, z+56, b, BlockType.STONE.metadata);
		world.setBlock(x+54, y+0, z+57, b, BlockType.STONE.metadata);
		world.setBlock(x+54, y+0, z+58, b, BlockType.STONE.metadata);
		world.setBlock(x+54, y+0, z+59, b, BlockType.STONE.metadata);
		world.setBlock(x+54, y+0, z+60, b, BlockType.CLOAK.metadata);
		world.setBlock(x+54, y+0, z+61, b, BlockType.CLOAK.metadata);
		world.setBlock(x+54, y+0, z+62, b, BlockType.CLOAK.metadata);
		world.setBlock(x+54, y+0, z+63, b, BlockType.STONE.metadata);
		world.setBlock(x+54, y+1, z+12, b, BlockType.STONE.metadata);
		world.setBlock(x+54, y+1, z+16, b, BlockType.STONE.metadata);
		world.setBlock(x+54, y+1, z+17, b, BlockType.STONE.metadata);
		world.setBlock(x+54, y+1, z+18, b, BlockType.STONE.metadata);
		world.setBlock(x+54, y+1, z+22, b, BlockType.STONE.metadata);
		world.setBlock(x+54, y+1, z+23, b, BlockType.STONE.metadata);
		world.setBlock(x+54, y+1, z+24, b, BlockType.STONE.metadata);
		world.setBlock(x+54, y+1, z+25, b, BlockType.STONE.metadata);
		world.setBlock(x+54, y+1, z+26, b, BlockType.STONE.metadata);
		world.setBlock(x+54, y+1, z+27, b, BlockType.STONE.metadata);
		world.setBlock(x+54, y+1, z+28, b, BlockType.STONE.metadata);
		world.setBlock(x+54, y+1, z+29, b, BlockType.STONE.metadata);
		world.setBlock(x+54, y+1, z+30, b, BlockType.STONE.metadata);
		world.setBlock(x+54, y+1, z+31, b, BlockType.STONE.metadata);
		world.setBlock(x+54, y+1, z+32, b, BlockType.STONE.metadata);
		world.setBlock(x+54, y+1, z+33, b, BlockType.STONE.metadata);
		world.setBlock(x+54, y+1, z+34, b, BlockType.STONE.metadata);
		world.setBlock(x+54, y+1, z+38, b, BlockType.STONE.metadata);
		world.setBlock(x+54, y+1, z+39, b, BlockType.STONE.metadata);
		world.setBlock(x+54, y+1, z+40, b, BlockType.STONE.metadata);
		world.setBlock(x+54, y+1, z+41, b, BlockType.STONE.metadata);
		world.setBlock(x+54, y+1, z+42, b, BlockType.STONE.metadata);
		world.setBlock(x+54, y+1, z+43, b, BlockType.STONE.metadata);
		world.setBlock(x+54, y+1, z+44, b, BlockType.STONE.metadata);
		world.setBlock(x+54, y+1, z+45, b, BlockType.STONE.metadata);
		world.setBlock(x+54, y+1, z+46, b, BlockType.STONE.metadata);
		world.setBlock(x+54, y+1, z+47, b, BlockType.STONE.metadata);
		world.setBlock(x+54, y+1, z+51, b, BlockType.STONE.metadata);
		world.setBlock(x+54, y+1, z+52, b, BlockType.STONE.metadata);
		world.setBlock(x+54, y+1, z+53, b, BlockType.STONE.metadata);
		world.setBlock(x+54, y+1, z+54, b, BlockType.STONE.metadata);
		world.setBlock(x+54, y+1, z+55, b, BlockType.STONE.metadata);
		world.setBlock(x+54, y+1, z+56, b, BlockType.STONE.metadata);
		world.setBlock(x+54, y+1, z+57, b, BlockType.STONE.metadata);
		world.setBlock(x+54, y+1, z+58, b, BlockType.STONE.metadata);
		world.setBlock(x+54, y+1, z+59, b, BlockType.STONE.metadata);
		world.setBlock(x+54, y+1, z+63, b, BlockType.STONE.metadata);
		world.setBlock(x+54, y+2, z+12, b, BlockType.STONE.metadata);
		world.setBlock(x+54, y+2, z+16, b, BlockType.STONE.metadata);
		world.setBlock(x+54, y+2, z+17, b, BlockType.STONE.metadata);
		world.setBlock(x+54, y+2, z+18, b, BlockType.STONE.metadata);
		world.setBlock(x+54, y+2, z+22, b, BlockType.STONE.metadata);
		world.setBlock(x+54, y+2, z+23, b, BlockType.STONE.metadata);
		world.setBlock(x+54, y+2, z+24, b, BlockType.STONE.metadata);
		world.setBlock(x+54, y+2, z+25, b, BlockType.STONE.metadata);
		world.setBlock(x+54, y+2, z+26, b, BlockType.STONE.metadata);
		world.setBlock(x+54, y+2, z+27, b, BlockType.STONE.metadata);
		world.setBlock(x+54, y+2, z+28, b, BlockType.STONE.metadata);
		world.setBlock(x+54, y+2, z+29, b, BlockType.STONE.metadata);
		world.setBlock(x+54, y+2, z+30, b, BlockType.STONE.metadata);
		world.setBlock(x+54, y+2, z+31, b, BlockType.STONE.metadata);
		world.setBlock(x+54, y+2, z+32, b, BlockType.STONE.metadata);
		world.setBlock(x+54, y+2, z+33, b, BlockType.STONE.metadata);
		world.setBlock(x+54, y+2, z+34, b, BlockType.STONE.metadata);
		world.setBlock(x+54, y+2, z+38, b, BlockType.STONE.metadata);
		world.setBlock(x+54, y+2, z+39, b, BlockType.STONE.metadata);
		world.setBlock(x+54, y+2, z+40, b, BlockType.STONE.metadata);
		world.setBlock(x+54, y+2, z+41, b, BlockType.STONE.metadata);
		world.setBlock(x+54, y+2, z+42, b, BlockType.STONE.metadata);
		world.setBlock(x+54, y+2, z+43, b, BlockType.STONE.metadata);
		world.setBlock(x+54, y+2, z+44, b, BlockType.STONE.metadata);
		world.setBlock(x+54, y+2, z+45, b, BlockType.STONE.metadata);
		world.setBlock(x+54, y+2, z+46, b, BlockType.STONE.metadata);
		world.setBlock(x+54, y+2, z+47, b, BlockType.STONE.metadata);
		world.setBlock(x+54, y+2, z+51, b, BlockType.STONE.metadata);
		world.setBlock(x+54, y+2, z+52, b, BlockType.STONE.metadata);
		world.setBlock(x+54, y+2, z+53, b, BlockType.STONE.metadata);
		world.setBlock(x+54, y+2, z+54, b, BlockType.STONE.metadata);
		world.setBlock(x+54, y+2, z+55, b, BlockType.STONE.metadata);
		world.setBlock(x+54, y+2, z+56, b, BlockType.STONE.metadata);
		world.setBlock(x+54, y+2, z+57, b, BlockType.STONE.metadata);
		world.setBlock(x+54, y+2, z+58, b, BlockType.STONE.metadata);
		world.setBlock(x+54, y+2, z+59, b, BlockType.STONE.metadata);
		world.setBlock(x+54, y+2, z+63, b, BlockType.STONE.metadata);
		world.setBlock(x+54, y+3, z+12, b, BlockType.STONE.metadata);
		world.setBlock(x+54, y+3, z+16, b, BlockType.STONE.metadata);
		world.setBlock(x+54, y+3, z+17, b, BlockType.STONE.metadata);
		world.setBlock(x+54, y+3, z+18, b, BlockType.STONE.metadata);
		world.setBlock(x+54, y+3, z+22, b, BlockType.STONE.metadata);
		world.setBlock(x+54, y+3, z+23, b, BlockType.STONE.metadata);
		world.setBlock(x+54, y+3, z+24, b, BlockType.STONE.metadata);
		world.setBlock(x+54, y+3, z+25, b, BlockType.STONE.metadata);
		world.setBlock(x+54, y+3, z+26, b, BlockType.STONE.metadata);
		world.setBlock(x+54, y+3, z+27, b, BlockType.STONE.metadata);
		world.setBlock(x+54, y+3, z+28, b, BlockType.STONE.metadata);
		world.setBlock(x+54, y+3, z+29, b, BlockType.STONE.metadata);
		world.setBlock(x+54, y+3, z+30, b, BlockType.STONE.metadata);
		world.setBlock(x+54, y+3, z+31, b, BlockType.STONE.metadata);
		world.setBlock(x+54, y+3, z+32, b, BlockType.STONE.metadata);
		world.setBlock(x+54, y+3, z+33, b, BlockType.STONE.metadata);
		world.setBlock(x+54, y+3, z+34, b, BlockType.STONE.metadata);
		world.setBlock(x+54, y+3, z+38, b, BlockType.STONE.metadata);
		world.setBlock(x+54, y+3, z+39, b, BlockType.STONE.metadata);
		world.setBlock(x+54, y+3, z+40, b, BlockType.STONE.metadata);
		world.setBlock(x+54, y+3, z+41, b, BlockType.STONE.metadata);
		world.setBlock(x+54, y+3, z+42, b, BlockType.STONE.metadata);
		world.setBlock(x+54, y+3, z+43, b, BlockType.STONE.metadata);
		world.setBlock(x+54, y+3, z+44, b, BlockType.STONE.metadata);
		world.setBlock(x+54, y+3, z+45, b, BlockType.STONE.metadata);
		world.setBlock(x+54, y+3, z+46, b, BlockType.STONE.metadata);
		world.setBlock(x+54, y+3, z+47, b, BlockType.STONE.metadata);
		world.setBlock(x+54, y+3, z+51, b, BlockType.STONE.metadata);
		world.setBlock(x+54, y+3, z+52, b, BlockType.STONE.metadata);
		world.setBlock(x+54, y+3, z+53, b, BlockType.STONE.metadata);
		world.setBlock(x+54, y+3, z+54, b, BlockType.STONE.metadata);
		world.setBlock(x+54, y+3, z+55, b, BlockType.STONE.metadata);
		world.setBlock(x+54, y+3, z+56, b, BlockType.STONE.metadata);
		world.setBlock(x+54, y+3, z+57, b, BlockType.STONE.metadata);
		world.setBlock(x+54, y+3, z+58, b, BlockType.STONE.metadata);
		world.setBlock(x+54, y+3, z+59, b, BlockType.STONE.metadata);
		world.setBlock(x+54, y+3, z+63, b, BlockType.STONE.metadata);
		world.setBlock(x+54, y+4, z+12, b, BlockType.STONE.metadata);
		world.setBlock(x+54, y+4, z+13, b, BlockType.STONE.metadata);
		world.setBlock(x+54, y+4, z+14, b, BlockType.STONE.metadata);
		world.setBlock(x+54, y+4, z+15, b, BlockType.STONE.metadata);
		world.setBlock(x+54, y+4, z+16, b, BlockType.STONE.metadata);
		world.setBlock(x+54, y+4, z+17, b, BlockType.STONE.metadata);
		world.setBlock(x+54, y+4, z+18, b, BlockType.STONE.metadata);
		world.setBlock(x+54, y+4, z+19, b, BlockType.STONE.metadata);
		world.setBlock(x+54, y+4, z+20, b, BlockType.STONE.metadata);
		world.setBlock(x+54, y+4, z+21, b, BlockType.STONE.metadata);
		world.setBlock(x+54, y+4, z+22, b, BlockType.STONE.metadata);
		world.setBlock(x+54, y+4, z+23, b, BlockType.STONE.metadata);
		world.setBlock(x+54, y+4, z+24, b, BlockType.STONE.metadata);
		world.setBlock(x+54, y+4, z+25, b, BlockType.STONE.metadata);
		world.setBlock(x+54, y+4, z+26, b, BlockType.STONE.metadata);
		world.setBlock(x+54, y+4, z+27, b, BlockType.STONE.metadata);
		world.setBlock(x+54, y+4, z+28, b, BlockType.STONE.metadata);
		world.setBlock(x+54, y+4, z+29, b, BlockType.STONE.metadata);
		world.setBlock(x+54, y+4, z+30, b, BlockType.STONE.metadata);
		world.setBlock(x+54, y+4, z+31, b, BlockType.STONE.metadata);
		world.setBlock(x+54, y+4, z+32, b, BlockType.STONE.metadata);
		world.setBlock(x+54, y+4, z+33, b, BlockType.STONE.metadata);
		world.setBlock(x+54, y+4, z+34, b, BlockType.STONE.metadata);
		world.setBlock(x+54, y+4, z+35, b, BlockType.STONE.metadata);
		world.setBlock(x+54, y+4, z+36, b, BlockType.STONE.metadata);
		world.setBlock(x+54, y+4, z+37, b, BlockType.STONE.metadata);
		world.setBlock(x+54, y+4, z+38, b, BlockType.STONE.metadata);
		world.setBlock(x+54, y+4, z+39, b, BlockType.STONE.metadata);
		world.setBlock(x+54, y+4, z+40, b, BlockType.STONE.metadata);
		world.setBlock(x+54, y+4, z+41, b, BlockType.STONE.metadata);
		world.setBlock(x+54, y+4, z+42, b, BlockType.STONE.metadata);
		world.setBlock(x+54, y+4, z+43, b, BlockType.STONE.metadata);
		world.setBlock(x+54, y+4, z+44, b, BlockType.STONE.metadata);
		world.setBlock(x+54, y+4, z+45, b, BlockType.STONE.metadata);
		world.setBlock(x+54, y+4, z+46, b, BlockType.STONE.metadata);
		world.setBlock(x+54, y+4, z+47, b, BlockType.STONE.metadata);
		world.setBlock(x+54, y+4, z+48, b, BlockType.STONE.metadata);
		world.setBlock(x+54, y+4, z+49, b, BlockType.STONE.metadata);
		world.setBlock(x+54, y+4, z+50, b, BlockType.STONE.metadata);
		world.setBlock(x+54, y+4, z+51, b, BlockType.STONE.metadata);
		world.setBlock(x+54, y+4, z+52, b, BlockType.STONE.metadata);
		world.setBlock(x+54, y+4, z+53, b, BlockType.STONE.metadata);
		world.setBlock(x+54, y+4, z+54, b, BlockType.STONE.metadata);
		world.setBlock(x+54, y+4, z+55, b, BlockType.STONE.metadata);
		world.setBlock(x+54, y+4, z+56, b, BlockType.STONE.metadata);
		world.setBlock(x+54, y+4, z+57, b, BlockType.STONE.metadata);
		world.setBlock(x+54, y+4, z+58, b, BlockType.STONE.metadata);
		world.setBlock(x+54, y+4, z+59, b, BlockType.STONE.metadata);
		world.setBlock(x+54, y+4, z+60, b, BlockType.STONE.metadata);
		world.setBlock(x+54, y+4, z+61, b, BlockType.STONE.metadata);
		world.setBlock(x+54, y+4, z+62, b, BlockType.STONE.metadata);
		world.setBlock(x+54, y+4, z+63, b, BlockType.STONE.metadata);
		world.setBlock(x+55, y+0, z+12, b, BlockType.STONE.metadata);
		world.setBlock(x+55, y+0, z+13, b, BlockType.CLOAK.metadata);
		world.setBlock(x+55, y+0, z+14, b, BlockType.CLOAK.metadata);
		world.setBlock(x+55, y+0, z+15, b, BlockType.CLOAK.metadata);
		world.setBlock(x+55, y+0, z+16, b, BlockType.CLOAK.metadata);
		world.setBlock(x+55, y+0, z+17, b, BlockType.CLOAK.metadata);
		world.setBlock(x+55, y+0, z+18, b, BlockType.CLOAK.metadata);
		world.setBlock(x+55, y+0, z+19, b, BlockType.CLOAK.metadata);
		world.setBlock(x+55, y+0, z+20, b, BlockType.CLOAK.metadata);
		world.setBlock(x+55, y+0, z+21, b, BlockType.CLOAK.metadata);
		world.setBlock(x+55, y+0, z+22, b, BlockType.CLOAK.metadata);
		world.setBlock(x+55, y+0, z+23, b, BlockType.CLOAK.metadata);
		world.setBlock(x+55, y+0, z+24, b, BlockType.CLOAK.metadata);
		world.setBlock(x+55, y+0, z+25, b, BlockType.CLOAK.metadata);
		world.setBlock(x+55, y+0, z+26, b, BlockType.CLOAK.metadata);
		world.setBlock(x+55, y+0, z+27, b, BlockType.CLOAK.metadata);
		world.setBlock(x+55, y+0, z+28, b, BlockType.CLOAK.metadata);
		world.setBlock(x+55, y+0, z+29, b, BlockType.CLOAK.metadata);
		world.setBlock(x+55, y+0, z+30, b, BlockType.STONE.metadata);
		world.setBlock(x+55, y+0, z+34, b, BlockType.STONE.metadata);
		world.setBlock(x+55, y+0, z+35, b, BlockType.CLOAK.metadata);
		world.setBlock(x+55, y+0, z+36, b, BlockType.CLOAK.metadata);
		world.setBlock(x+55, y+0, z+37, b, BlockType.CLOAK.metadata);
		world.setBlock(x+55, y+0, z+38, b, BlockType.CLOAK.metadata);
		world.setBlock(x+55, y+0, z+39, b, BlockType.CLOAK.metadata);
		world.setBlock(x+55, y+0, z+40, b, BlockType.CLOAK.metadata);
		world.setBlock(x+55, y+0, z+41, b, BlockType.CLOAK.metadata);
		world.setBlock(x+55, y+0, z+42, b, BlockType.CLOAK.metadata);
		world.setBlock(x+55, y+0, z+43, b, BlockType.CLOAK.metadata);
		world.setBlock(x+55, y+0, z+44, b, BlockType.CLOAK.metadata);
		world.setBlock(x+55, y+0, z+45, b, BlockType.CLOAK.metadata);
		world.setBlock(x+55, y+0, z+46, b, BlockType.CLOAK.metadata);
		world.setBlock(x+55, y+0, z+47, b, BlockType.CLOAK.metadata);
		world.setBlock(x+55, y+0, z+48, b, BlockType.CLOAK.metadata);
		world.setBlock(x+55, y+0, z+49, b, BlockType.CLOAK.metadata);
		world.setBlock(x+55, y+0, z+50, b, BlockType.CLOAK.metadata);
		world.setBlock(x+55, y+0, z+51, b, BlockType.STONE.metadata);
		world.setBlock(x+55, y+0, z+59, b, BlockType.STONE.metadata);
		world.setBlock(x+55, y+0, z+60, b, BlockType.CLOAK.metadata);
		world.setBlock(x+55, y+0, z+61, b, BlockType.CLOAK.metadata);
		world.setBlock(x+55, y+0, z+62, b, BlockType.CLOAK.metadata);
		world.setBlock(x+55, y+0, z+63, b, BlockType.STONE.metadata);
		world.setBlock(x+55, y+1, z+12, b, BlockType.STONE.metadata);
		world.setBlock(x+55, y+1, z+30, b, BlockType.STONE.metadata);
		world.setBlock(x+55, y+1, z+34, b, BlockType.STONE.metadata);
		world.setBlock(x+55, y+1, z+51, b, BlockType.STONE.metadata);
		world.setBlock(x+55, y+1, z+59, b, BlockType.STONE.metadata);
		world.setBlock(x+55, y+1, z+63, b, BlockType.STONE.metadata);
		world.setBlock(x+55, y+2, z+12, b, BlockType.STONE.metadata);
		world.setBlock(x+55, y+2, z+30, b, BlockType.STONE.metadata);
		world.setBlock(x+55, y+2, z+34, b, BlockType.STONE.metadata);
		world.setBlock(x+55, y+2, z+51, b, BlockType.STONE.metadata);
		world.setBlock(x+55, y+2, z+59, b, BlockType.STONE.metadata);
		world.setBlock(x+55, y+2, z+63, b, BlockType.STONE.metadata);
		world.setBlock(x+55, y+3, z+12, b, BlockType.STONE.metadata);
		world.setBlock(x+55, y+3, z+30, b, BlockType.STONE.metadata);
		world.setBlock(x+55, y+3, z+34, b, BlockType.STONE.metadata);
		world.setBlock(x+55, y+3, z+51, b, BlockType.STONE.metadata);
		world.setBlock(x+55, y+3, z+59, b, BlockType.STONE.metadata);
		world.setBlock(x+55, y+3, z+63, b, BlockType.STONE.metadata);
		world.setBlock(x+55, y+4, z+12, b, BlockType.STONE.metadata);
		world.setBlock(x+55, y+4, z+13, b, BlockType.STONE.metadata);
		world.setBlock(x+55, y+4, z+14, b, BlockType.STONE.metadata);
		world.setBlock(x+55, y+4, z+15, b, BlockType.STONE.metadata);
		world.setBlock(x+55, y+4, z+16, b, BlockType.STONE.metadata);
		world.setBlock(x+55, y+4, z+17, b, BlockType.STONE.metadata);
		world.setBlock(x+55, y+4, z+18, b, BlockType.STONE.metadata);
		world.setBlock(x+55, y+4, z+19, b, BlockType.STONE.metadata);
		world.setBlock(x+55, y+4, z+20, b, BlockType.STONE.metadata);
		world.setBlock(x+55, y+4, z+21, b, BlockType.STONE.metadata);
		world.setBlock(x+55, y+4, z+22, b, BlockType.STONE.metadata);
		world.setBlock(x+55, y+4, z+23, b, BlockType.STONE.metadata);
		world.setBlock(x+55, y+4, z+24, b, BlockType.STONE.metadata);
		world.setBlock(x+55, y+4, z+25, b, BlockType.STONE.metadata);
		world.setBlock(x+55, y+4, z+26, b, BlockType.STONE.metadata);
		world.setBlock(x+55, y+4, z+27, b, BlockType.STONE.metadata);
		world.setBlock(x+55, y+4, z+28, b, BlockType.STONE.metadata);
		world.setBlock(x+55, y+4, z+29, b, BlockType.STONE.metadata);
		world.setBlock(x+55, y+4, z+30, b, BlockType.STONE.metadata);
		world.setBlock(x+55, y+4, z+34, b, BlockType.STONE.metadata);
		world.setBlock(x+55, y+4, z+35, b, BlockType.STONE.metadata);
		world.setBlock(x+55, y+4, z+36, b, BlockType.STONE.metadata);
		world.setBlock(x+55, y+4, z+37, b, BlockType.STONE.metadata);
		world.setBlock(x+55, y+4, z+38, b, BlockType.STONE.metadata);
		world.setBlock(x+55, y+4, z+39, b, BlockType.STONE.metadata);
		world.setBlock(x+55, y+4, z+40, b, BlockType.STONE.metadata);
		world.setBlock(x+55, y+4, z+41, b, BlockType.STONE.metadata);
		world.setBlock(x+55, y+4, z+42, b, BlockType.STONE.metadata);
		world.setBlock(x+55, y+4, z+43, b, BlockType.STONE.metadata);
		world.setBlock(x+55, y+4, z+44, b, BlockType.STONE.metadata);
		world.setBlock(x+55, y+4, z+45, b, BlockType.STONE.metadata);
		world.setBlock(x+55, y+4, z+46, b, BlockType.STONE.metadata);
		world.setBlock(x+55, y+4, z+47, b, BlockType.STONE.metadata);
		world.setBlock(x+55, y+4, z+48, b, BlockType.STONE.metadata);
		world.setBlock(x+55, y+4, z+49, b, BlockType.STONE.metadata);
		world.setBlock(x+55, y+4, z+50, b, BlockType.STONE.metadata);
		world.setBlock(x+55, y+4, z+51, b, BlockType.STONE.metadata);
		world.setBlock(x+55, y+4, z+59, b, BlockType.STONE.metadata);
		world.setBlock(x+55, y+4, z+60, b, BlockType.STONE.metadata);
		world.setBlock(x+55, y+4, z+61, b, BlockType.STONE.metadata);
		world.setBlock(x+55, y+4, z+62, b, BlockType.STONE.metadata);
		world.setBlock(x+55, y+4, z+63, b, BlockType.STONE.metadata);
		world.setBlock(x+56, y+0, z+12, b, BlockType.STONE.metadata);
		world.setBlock(x+56, y+0, z+13, b, BlockType.CLOAK.metadata);
		world.setBlock(x+56, y+0, z+14, b, BlockType.CLOAK.metadata);
		world.setBlock(x+56, y+0, z+15, b, BlockType.CLOAK.metadata);
		world.setBlock(x+56, y+0, z+16, b, BlockType.CLOAK.metadata);
		world.setBlock(x+56, y+0, z+17, b, BlockType.CLOAK.metadata);
		world.setBlock(x+56, y+0, z+18, b, BlockType.CLOAK.metadata);
		world.setBlock(x+56, y+0, z+19, b, BlockType.CLOAK.metadata);
		world.setBlock(x+56, y+0, z+20, b, BlockType.CLOAK.metadata);
		world.setBlock(x+56, y+0, z+21, b, BlockType.CLOAK.metadata);
		world.setBlock(x+56, y+0, z+22, b, BlockType.CLOAK.metadata);
		world.setBlock(x+56, y+0, z+23, b, BlockType.CLOAK.metadata);
		world.setBlock(x+56, y+0, z+24, b, BlockType.CLOAK.metadata);
		world.setBlock(x+56, y+0, z+25, b, BlockType.CLOAK.metadata);
		world.setBlock(x+56, y+0, z+26, b, BlockType.CLOAK.metadata);
		world.setBlock(x+56, y+0, z+27, b, BlockType.CLOAK.metadata);
		world.setBlock(x+56, y+0, z+28, b, BlockType.CLOAK.metadata);
		world.setBlock(x+56, y+0, z+29, b, BlockType.CLOAK.metadata);
		world.setBlock(x+56, y+0, z+30, b, BlockType.STONE.metadata);
		world.setBlock(x+56, y+0, z+34, b, BlockType.STONE.metadata);
		world.setBlock(x+56, y+0, z+35, b, BlockType.CLOAK.metadata);
		world.setBlock(x+56, y+0, z+36, b, BlockType.CLOAK.metadata);
		world.setBlock(x+56, y+0, z+37, b, BlockType.CLOAK.metadata);
		world.setBlock(x+56, y+0, z+38, b, BlockType.CLOAK.metadata);
		world.setBlock(x+56, y+0, z+39, b, BlockType.CLOAK.metadata);
		world.setBlock(x+56, y+0, z+40, b, BlockType.CLOAK.metadata);
		world.setBlock(x+56, y+0, z+41, b, BlockType.CLOAK.metadata);
		world.setBlock(x+56, y+0, z+42, b, BlockType.CLOAK.metadata);
		world.setBlock(x+56, y+0, z+43, b, BlockType.CLOAK.metadata);
		world.setBlock(x+56, y+0, z+44, b, BlockType.CLOAK.metadata);
		world.setBlock(x+56, y+0, z+45, b, BlockType.CLOAK.metadata);
		world.setBlock(x+56, y+0, z+46, b, BlockType.CLOAK.metadata);
		world.setBlock(x+56, y+0, z+47, b, BlockType.CLOAK.metadata);
		world.setBlock(x+56, y+0, z+48, b, BlockType.CLOAK.metadata);
		world.setBlock(x+56, y+0, z+49, b, BlockType.CLOAK.metadata);
		world.setBlock(x+56, y+0, z+50, b, BlockType.CLOAK.metadata);
		world.setBlock(x+56, y+0, z+51, b, BlockType.STONE.metadata);
		world.setBlock(x+56, y+0, z+59, b, BlockType.STONE.metadata);
		world.setBlock(x+56, y+0, z+60, b, BlockType.STONE.metadata);
		world.setBlock(x+56, y+0, z+61, b, BlockType.STONE.metadata);
		world.setBlock(x+56, y+0, z+62, b, BlockType.STONE.metadata);
		world.setBlock(x+56, y+0, z+63, b, BlockType.STONE.metadata);
		world.setBlock(x+56, y+1, z+12, b, BlockType.STONE.metadata);
		world.setBlock(x+56, y+1, z+30, b, BlockType.STONE.metadata);
		world.setBlock(x+56, y+1, z+34, b, BlockType.STONE.metadata);
		world.setBlock(x+56, y+1, z+51, b, BlockType.STONE.metadata);
		world.setBlock(x+56, y+1, z+59, b, BlockType.STONE.metadata);
		world.setBlock(x+56, y+1, z+60, b, BlockType.STONE.metadata);
		world.setBlock(x+56, y+1, z+61, b, BlockType.STONE.metadata);
		world.setBlock(x+56, y+1, z+62, b, BlockType.STONE.metadata);
		world.setBlock(x+56, y+1, z+63, b, BlockType.STONE.metadata);
		world.setBlock(x+56, y+2, z+12, b, BlockType.STONE.metadata);
		world.setBlock(x+56, y+2, z+30, b, BlockType.STONE.metadata);
		world.setBlock(x+56, y+2, z+34, b, BlockType.STONE.metadata);
		world.setBlock(x+56, y+2, z+51, b, BlockType.STONE.metadata);
		world.setBlock(x+56, y+2, z+59, b, BlockType.STONE.metadata);
		world.setBlock(x+56, y+2, z+60, b, BlockType.STONE.metadata);
		world.setBlock(x+56, y+2, z+61, b, BlockType.STONE.metadata);
		world.setBlock(x+56, y+2, z+62, b, BlockType.STONE.metadata);
		world.setBlock(x+56, y+2, z+63, b, BlockType.STONE.metadata);
		world.setBlock(x+56, y+3, z+12, b, BlockType.STONE.metadata);
		world.setBlock(x+56, y+3, z+30, b, BlockType.STONE.metadata);
		world.setBlock(x+56, y+3, z+34, b, BlockType.STONE.metadata);
		world.setBlock(x+56, y+3, z+51, b, BlockType.STONE.metadata);
		world.setBlock(x+56, y+3, z+59, b, BlockType.STONE.metadata);
		world.setBlock(x+56, y+3, z+60, b, BlockType.STONE.metadata);
		world.setBlock(x+56, y+3, z+61, b, BlockType.STONE.metadata);
		world.setBlock(x+56, y+3, z+62, b, BlockType.STONE.metadata);
		world.setBlock(x+56, y+3, z+63, b, BlockType.STONE.metadata);
		world.setBlock(x+56, y+4, z+12, b, BlockType.STONE.metadata);
		world.setBlock(x+56, y+4, z+13, b, BlockType.STONE.metadata);
		world.setBlock(x+56, y+4, z+14, b, BlockType.STONE.metadata);
		world.setBlock(x+56, y+4, z+15, b, BlockType.STONE.metadata);
		world.setBlock(x+56, y+4, z+16, b, BlockType.STONE.metadata);
		world.setBlock(x+56, y+4, z+17, b, BlockType.STONE.metadata);
		world.setBlock(x+56, y+4, z+18, b, BlockType.STONE.metadata);
		world.setBlock(x+56, y+4, z+19, b, BlockType.STONE.metadata);
		world.setBlock(x+56, y+4, z+20, b, BlockType.STONE.metadata);
		world.setBlock(x+56, y+4, z+21, b, BlockType.STONE.metadata);
		world.setBlock(x+56, y+4, z+22, b, BlockType.STONE.metadata);
		world.setBlock(x+56, y+4, z+23, b, BlockType.STONE.metadata);
		world.setBlock(x+56, y+4, z+24, b, BlockType.STONE.metadata);
		world.setBlock(x+56, y+4, z+25, b, BlockType.STONE.metadata);
		world.setBlock(x+56, y+4, z+26, b, BlockType.STONE.metadata);
		world.setBlock(x+56, y+4, z+27, b, BlockType.STONE.metadata);
		world.setBlock(x+56, y+4, z+28, b, BlockType.STONE.metadata);
		world.setBlock(x+56, y+4, z+29, b, BlockType.STONE.metadata);
		world.setBlock(x+56, y+4, z+30, b, BlockType.STONE.metadata);
		world.setBlock(x+56, y+4, z+34, b, BlockType.STONE.metadata);
		world.setBlock(x+56, y+4, z+35, b, BlockType.STONE.metadata);
		world.setBlock(x+56, y+4, z+36, b, BlockType.STONE.metadata);
		world.setBlock(x+56, y+4, z+37, b, BlockType.STONE.metadata);
		world.setBlock(x+56, y+4, z+38, b, BlockType.STONE.metadata);
		world.setBlock(x+56, y+4, z+39, b, BlockType.STONE.metadata);
		world.setBlock(x+56, y+4, z+40, b, BlockType.STONE.metadata);
		world.setBlock(x+56, y+4, z+41, b, BlockType.STONE.metadata);
		world.setBlock(x+56, y+4, z+42, b, BlockType.STONE.metadata);
		world.setBlock(x+56, y+4, z+43, b, BlockType.STONE.metadata);
		world.setBlock(x+56, y+4, z+44, b, BlockType.STONE.metadata);
		world.setBlock(x+56, y+4, z+45, b, BlockType.STONE.metadata);
		world.setBlock(x+56, y+4, z+46, b, BlockType.STONE.metadata);
		world.setBlock(x+56, y+4, z+47, b, BlockType.STONE.metadata);
		world.setBlock(x+56, y+4, z+48, b, BlockType.STONE.metadata);
		world.setBlock(x+56, y+4, z+49, b, BlockType.STONE.metadata);
		world.setBlock(x+56, y+4, z+50, b, BlockType.STONE.metadata);
		world.setBlock(x+56, y+4, z+51, b, BlockType.STONE.metadata);
		world.setBlock(x+56, y+4, z+59, b, BlockType.STONE.metadata);
		world.setBlock(x+56, y+4, z+60, b, BlockType.STONE.metadata);
		world.setBlock(x+56, y+4, z+61, b, BlockType.STONE.metadata);
		world.setBlock(x+56, y+4, z+62, b, BlockType.STONE.metadata);
		world.setBlock(x+56, y+4, z+63, b, BlockType.STONE.metadata);
		world.setBlock(x+57, y+0, z+12, b, BlockType.STONE.metadata);
		world.setBlock(x+57, y+0, z+13, b, BlockType.CLOAK.metadata);
		world.setBlock(x+57, y+0, z+14, b, BlockType.CLOAK.metadata);
		world.setBlock(x+57, y+0, z+15, b, BlockType.CLOAK.metadata);
		world.setBlock(x+57, y+0, z+16, b, BlockType.CLOAK.metadata);
		world.setBlock(x+57, y+0, z+17, b, BlockType.CLOAK.metadata);
		world.setBlock(x+57, y+0, z+18, b, BlockType.CLOAK.metadata);
		world.setBlock(x+57, y+0, z+19, b, BlockType.CLOAK.metadata);
		world.setBlock(x+57, y+0, z+20, b, BlockType.CLOAK.metadata);
		world.setBlock(x+57, y+0, z+21, b, BlockType.CLOAK.metadata);
		world.setBlock(x+57, y+0, z+22, b, BlockType.CLOAK.metadata);
		world.setBlock(x+57, y+0, z+23, b, BlockType.CLOAK.metadata);
		world.setBlock(x+57, y+0, z+24, b, BlockType.CLOAK.metadata);
		world.setBlock(x+57, y+0, z+25, b, BlockType.CLOAK.metadata);
		world.setBlock(x+57, y+0, z+26, b, BlockType.CLOAK.metadata);
		world.setBlock(x+57, y+0, z+27, b, BlockType.CLOAK.metadata);
		world.setBlock(x+57, y+0, z+28, b, BlockType.CLOAK.metadata);
		world.setBlock(x+57, y+0, z+29, b, BlockType.CLOAK.metadata);
		world.setBlock(x+57, y+0, z+30, b, BlockType.STONE.metadata);
		world.setBlock(x+57, y+0, z+34, b, BlockType.STONE.metadata);
		world.setBlock(x+57, y+0, z+35, b, BlockType.CLOAK.metadata);
		world.setBlock(x+57, y+0, z+36, b, BlockType.CLOAK.metadata);
		world.setBlock(x+57, y+0, z+37, b, BlockType.CLOAK.metadata);
		world.setBlock(x+57, y+0, z+38, b, BlockType.CLOAK.metadata);
		world.setBlock(x+57, y+0, z+39, b, BlockType.CLOAK.metadata);
		world.setBlock(x+57, y+0, z+40, b, BlockType.CLOAK.metadata);
		world.setBlock(x+57, y+0, z+41, b, BlockType.CLOAK.metadata);
		world.setBlock(x+57, y+0, z+42, b, BlockType.CLOAK.metadata);
		world.setBlock(x+57, y+0, z+43, b, BlockType.CLOAK.metadata);
		world.setBlock(x+57, y+0, z+44, b, BlockType.CLOAK.metadata);
		world.setBlock(x+57, y+0, z+45, b, BlockType.CLOAK.metadata);
		world.setBlock(x+57, y+0, z+46, b, BlockType.CLOAK.metadata);
		world.setBlock(x+57, y+0, z+47, b, BlockType.CLOAK.metadata);
		world.setBlock(x+57, y+0, z+48, b, BlockType.CLOAK.metadata);
		world.setBlock(x+57, y+0, z+49, b, BlockType.CLOAK.metadata);
		world.setBlock(x+57, y+0, z+50, b, BlockType.CLOAK.metadata);
		world.setBlock(x+57, y+0, z+51, b, BlockType.STONE.metadata);
		world.setBlock(x+57, y+1, z+12, b, BlockType.STONE.metadata);
		world.setBlock(x+57, y+1, z+30, b, BlockType.STONE.metadata);
		world.setBlock(x+57, y+1, z+34, b, BlockType.STONE.metadata);
		world.setBlock(x+57, y+1, z+51, b, BlockType.STONE.metadata);
		world.setBlock(x+57, y+2, z+12, b, BlockType.STONE.metadata);
		world.setBlock(x+57, y+2, z+30, b, BlockType.STONE.metadata);
		world.setBlock(x+57, y+2, z+34, b, BlockType.STONE.metadata);
		world.setBlock(x+57, y+2, z+51, b, BlockType.STONE.metadata);
		world.setBlock(x+57, y+3, z+12, b, BlockType.STONE.metadata);
		world.setBlock(x+57, y+3, z+30, b, BlockType.STONE.metadata);
		world.setBlock(x+57, y+3, z+34, b, BlockType.STONE.metadata);
		world.setBlock(x+57, y+3, z+51, b, BlockType.STONE.metadata);
		world.setBlock(x+57, y+4, z+12, b, BlockType.STONE.metadata);
		world.setBlock(x+57, y+4, z+13, b, BlockType.STONE.metadata);
		world.setBlock(x+57, y+4, z+14, b, BlockType.STONE.metadata);
		world.setBlock(x+57, y+4, z+15, b, BlockType.STONE.metadata);
		world.setBlock(x+57, y+4, z+16, b, BlockType.STONE.metadata);
		world.setBlock(x+57, y+4, z+17, b, BlockType.STONE.metadata);
		world.setBlock(x+57, y+4, z+18, b, BlockType.STONE.metadata);
		world.setBlock(x+57, y+4, z+19, b, BlockType.STONE.metadata);
		world.setBlock(x+57, y+4, z+20, b, BlockType.STONE.metadata);
		world.setBlock(x+57, y+4, z+21, b, BlockType.STONE.metadata);
		world.setBlock(x+57, y+4, z+22, b, BlockType.STONE.metadata);
		world.setBlock(x+57, y+4, z+23, b, BlockType.STONE.metadata);
		world.setBlock(x+57, y+4, z+24, b, BlockType.STONE.metadata);
		world.setBlock(x+57, y+4, z+25, b, BlockType.STONE.metadata);
		world.setBlock(x+57, y+4, z+26, b, BlockType.STONE.metadata);
		world.setBlock(x+57, y+4, z+27, b, BlockType.STONE.metadata);
		world.setBlock(x+57, y+4, z+28, b, BlockType.STONE.metadata);
		world.setBlock(x+57, y+4, z+29, b, BlockType.STONE.metadata);
		world.setBlock(x+57, y+4, z+30, b, BlockType.STONE.metadata);
		world.setBlock(x+57, y+4, z+34, b, BlockType.STONE.metadata);
		world.setBlock(x+57, y+4, z+35, b, BlockType.STONE.metadata);
		world.setBlock(x+57, y+4, z+36, b, BlockType.STONE.metadata);
		world.setBlock(x+57, y+4, z+37, b, BlockType.STONE.metadata);
		world.setBlock(x+57, y+4, z+38, b, BlockType.STONE.metadata);
		world.setBlock(x+57, y+4, z+39, b, BlockType.STONE.metadata);
		world.setBlock(x+57, y+4, z+40, b, BlockType.STONE.metadata);
		world.setBlock(x+57, y+4, z+41, b, BlockType.STONE.metadata);
		world.setBlock(x+57, y+4, z+42, b, BlockType.STONE.metadata);
		world.setBlock(x+57, y+4, z+43, b, BlockType.STONE.metadata);
		world.setBlock(x+57, y+4, z+44, b, BlockType.STONE.metadata);
		world.setBlock(x+57, y+4, z+45, b, BlockType.STONE.metadata);
		world.setBlock(x+57, y+4, z+46, b, BlockType.STONE.metadata);
		world.setBlock(x+57, y+4, z+47, b, BlockType.STONE.metadata);
		world.setBlock(x+57, y+4, z+48, b, BlockType.STONE.metadata);
		world.setBlock(x+57, y+4, z+49, b, BlockType.STONE.metadata);
		world.setBlock(x+57, y+4, z+50, b, BlockType.STONE.metadata);
		world.setBlock(x+57, y+4, z+51, b, BlockType.STONE.metadata);
		world.setBlock(x+58, y+0, z+12, b, BlockType.STONE.metadata);
		world.setBlock(x+58, y+0, z+13, b, BlockType.CLOAK.metadata);
		world.setBlock(x+58, y+0, z+14, b, BlockType.CLOAK.metadata);
		world.setBlock(x+58, y+0, z+15, b, BlockType.CLOAK.metadata);
		world.setBlock(x+58, y+0, z+16, b, BlockType.STONE.metadata);
		world.setBlock(x+58, y+0, z+17, b, BlockType.STONE.metadata);
		world.setBlock(x+58, y+0, z+18, b, BlockType.STONE.metadata);
		world.setBlock(x+58, y+0, z+19, b, BlockType.CLOAK.metadata);
		world.setBlock(x+58, y+0, z+20, b, BlockType.CLOAK.metadata);
		world.setBlock(x+58, y+0, z+21, b, BlockType.CLOAK.metadata);
		world.setBlock(x+58, y+0, z+22, b, BlockType.STONE.metadata);
		world.setBlock(x+58, y+0, z+23, b, BlockType.STONE.metadata);
		world.setBlock(x+58, y+0, z+24, b, BlockType.STONE.metadata);
		world.setBlock(x+58, y+0, z+25, b, BlockType.STONE.metadata);
		world.setBlock(x+58, y+0, z+26, b, BlockType.STONE.metadata);
		world.setBlock(x+58, y+0, z+27, b, BlockType.CLOAK.metadata);
		world.setBlock(x+58, y+0, z+28, b, BlockType.CLOAK.metadata);
		world.setBlock(x+58, y+0, z+29, b, BlockType.CLOAK.metadata);
		world.setBlock(x+58, y+0, z+30, b, BlockType.STONE.metadata);
		world.setBlock(x+58, y+0, z+34, b, BlockType.STONE.metadata);
		world.setBlock(x+58, y+0, z+35, b, BlockType.STONE.metadata);
		world.setBlock(x+58, y+0, z+36, b, BlockType.STONE.metadata);
		world.setBlock(x+58, y+0, z+37, b, BlockType.STONE.metadata);
		world.setBlock(x+58, y+0, z+38, b, BlockType.STONE.metadata);
		world.setBlock(x+58, y+0, z+39, b, BlockType.STONE.metadata);
		world.setBlock(x+58, y+0, z+40, b, BlockType.STONE.metadata);
		world.setBlock(x+58, y+0, z+41, b, BlockType.STONE.metadata);
		world.setBlock(x+58, y+0, z+42, b, BlockType.STONE.metadata);
		world.setBlock(x+58, y+0, z+43, b, BlockType.STONE.metadata);
		world.setBlock(x+58, y+0, z+44, b, BlockType.STONE.metadata);
		world.setBlock(x+58, y+0, z+45, b, BlockType.STONE.metadata);
		world.setBlock(x+58, y+0, z+46, b, BlockType.STONE.metadata);
		world.setBlock(x+58, y+0, z+47, b, BlockType.STONE.metadata);
		world.setBlock(x+58, y+0, z+48, b, BlockType.STONE.metadata);
		world.setBlock(x+58, y+0, z+49, b, BlockType.STONE.metadata);
		world.setBlock(x+58, y+0, z+50, b, BlockType.STONE.metadata);
		world.setBlock(x+58, y+0, z+51, b, BlockType.STONE.metadata);
		world.setBlock(x+58, y+1, z+12, b, BlockType.STONE.metadata);
		world.setBlock(x+58, y+1, z+16, b, BlockType.STONE.metadata);
		world.setBlock(x+58, y+1, z+17, b, BlockType.STONE.metadata);
		world.setBlock(x+58, y+1, z+18, b, BlockType.STONE.metadata);
		world.setBlock(x+58, y+1, z+22, b, BlockType.STONE.metadata);
		world.setBlock(x+58, y+1, z+23, b, BlockType.STONE.metadata);
		world.setBlock(x+58, y+1, z+24, b, BlockType.STONE.metadata);
		world.setBlock(x+58, y+1, z+25, b, BlockType.STONE.metadata);
		world.setBlock(x+58, y+1, z+26, b, BlockType.STONE.metadata);
		world.setBlock(x+58, y+1, z+30, b, BlockType.STONE.metadata);
		world.setBlock(x+58, y+1, z+34, b, BlockType.STONE.metadata);
		world.setBlock(x+58, y+1, z+35, b, BlockType.STONE.metadata);
		world.setBlock(x+58, y+1, z+36, b, BlockType.STONE.metadata);
		world.setBlock(x+58, y+1, z+37, b, BlockType.STONE.metadata);
		world.setBlock(x+58, y+1, z+38, b, BlockType.STONE.metadata);
		world.setBlock(x+58, y+1, z+39, b, BlockType.STONE.metadata);
		world.setBlock(x+58, y+1, z+40, b, BlockType.STONE.metadata);
		world.setBlock(x+58, y+1, z+41, b, BlockType.STONE.metadata);
		world.setBlock(x+58, y+1, z+42, b, BlockType.STONE.metadata);
		world.setBlock(x+58, y+1, z+43, b, BlockType.STONE.metadata);
		world.setBlock(x+58, y+1, z+44, b, BlockType.STONE.metadata);
		world.setBlock(x+58, y+1, z+45, b, BlockType.STONE.metadata);
		world.setBlock(x+58, y+1, z+46, b, BlockType.STONE.metadata);
		world.setBlock(x+58, y+1, z+47, b, BlockType.STONE.metadata);
		world.setBlock(x+58, y+1, z+48, b, BlockType.STONE.metadata);
		world.setBlock(x+58, y+1, z+49, b, BlockType.STONE.metadata);
		world.setBlock(x+58, y+1, z+50, b, BlockType.STONE.metadata);
		world.setBlock(x+58, y+1, z+51, b, BlockType.STONE.metadata);
		world.setBlock(x+58, y+2, z+12, b, BlockType.STONE.metadata);
		world.setBlock(x+58, y+2, z+16, b, BlockType.STONE.metadata);
		world.setBlock(x+58, y+2, z+17, b, BlockType.STONE.metadata);
		world.setBlock(x+58, y+2, z+18, b, BlockType.STONE.metadata);
		world.setBlock(x+58, y+2, z+22, b, BlockType.STONE.metadata);
		world.setBlock(x+58, y+2, z+23, b, BlockType.STONE.metadata);
		world.setBlock(x+58, y+2, z+24, b, BlockType.STONE.metadata);
		world.setBlock(x+58, y+2, z+25, b, BlockType.STONE.metadata);
		world.setBlock(x+58, y+2, z+26, b, BlockType.STONE.metadata);
		world.setBlock(x+58, y+2, z+30, b, BlockType.STONE.metadata);
		world.setBlock(x+58, y+2, z+34, b, BlockType.STONE.metadata);
		world.setBlock(x+58, y+2, z+35, b, BlockType.STONE.metadata);
		world.setBlock(x+58, y+2, z+36, b, BlockType.STONE.metadata);
		world.setBlock(x+58, y+2, z+37, b, BlockType.STONE.metadata);
		world.setBlock(x+58, y+2, z+38, b, BlockType.STONE.metadata);
		world.setBlock(x+58, y+2, z+39, b, BlockType.STONE.metadata);
		world.setBlock(x+58, y+2, z+40, b, BlockType.STONE.metadata);
		world.setBlock(x+58, y+2, z+41, b, BlockType.STONE.metadata);
		world.setBlock(x+58, y+2, z+42, b, BlockType.STONE.metadata);
		world.setBlock(x+58, y+2, z+43, b, BlockType.STONE.metadata);
		world.setBlock(x+58, y+2, z+44, b, BlockType.STONE.metadata);
		world.setBlock(x+58, y+2, z+45, b, BlockType.STONE.metadata);
		world.setBlock(x+58, y+2, z+46, b, BlockType.STONE.metadata);
		world.setBlock(x+58, y+2, z+47, b, BlockType.STONE.metadata);
		world.setBlock(x+58, y+2, z+48, b, BlockType.STONE.metadata);
		world.setBlock(x+58, y+2, z+49, b, BlockType.STONE.metadata);
		world.setBlock(x+58, y+2, z+50, b, BlockType.STONE.metadata);
		world.setBlock(x+58, y+2, z+51, b, BlockType.STONE.metadata);
		world.setBlock(x+58, y+3, z+12, b, BlockType.STONE.metadata);
		world.setBlock(x+58, y+3, z+16, b, BlockType.STONE.metadata);
		world.setBlock(x+58, y+3, z+17, b, BlockType.STONE.metadata);
		world.setBlock(x+58, y+3, z+18, b, BlockType.STONE.metadata);
		world.setBlock(x+58, y+3, z+22, b, BlockType.STONE.metadata);
		world.setBlock(x+58, y+3, z+23, b, BlockType.STONE.metadata);
		world.setBlock(x+58, y+3, z+24, b, BlockType.STONE.metadata);
		world.setBlock(x+58, y+3, z+25, b, BlockType.STONE.metadata);
		world.setBlock(x+58, y+3, z+26, b, BlockType.STONE.metadata);
		world.setBlock(x+58, y+3, z+30, b, BlockType.STONE.metadata);
		world.setBlock(x+58, y+3, z+34, b, BlockType.STONE.metadata);
		world.setBlock(x+58, y+3, z+35, b, BlockType.STONE.metadata);
		world.setBlock(x+58, y+3, z+36, b, BlockType.STONE.metadata);
		world.setBlock(x+58, y+3, z+37, b, BlockType.STONE.metadata);
		world.setBlock(x+58, y+3, z+38, b, BlockType.STONE.metadata);
		world.setBlock(x+58, y+3, z+39, b, BlockType.STONE.metadata);
		world.setBlock(x+58, y+3, z+40, b, BlockType.STONE.metadata);
		world.setBlock(x+58, y+3, z+41, b, BlockType.STONE.metadata);
		world.setBlock(x+58, y+3, z+42, b, BlockType.STONE.metadata);
		world.setBlock(x+58, y+3, z+43, b, BlockType.STONE.metadata);
		world.setBlock(x+58, y+3, z+44, b, BlockType.STONE.metadata);
		world.setBlock(x+58, y+3, z+45, b, BlockType.STONE.metadata);
		world.setBlock(x+58, y+3, z+46, b, BlockType.STONE.metadata);
		world.setBlock(x+58, y+3, z+47, b, BlockType.STONE.metadata);
		world.setBlock(x+58, y+3, z+48, b, BlockType.STONE.metadata);
		world.setBlock(x+58, y+3, z+49, b, BlockType.STONE.metadata);
		world.setBlock(x+58, y+3, z+50, b, BlockType.STONE.metadata);
		world.setBlock(x+58, y+3, z+51, b, BlockType.STONE.metadata);
		world.setBlock(x+58, y+4, z+12, b, BlockType.STONE.metadata);
		world.setBlock(x+58, y+4, z+13, b, BlockType.STONE.metadata);
		world.setBlock(x+58, y+4, z+14, b, BlockType.STONE.metadata);
		world.setBlock(x+58, y+4, z+15, b, BlockType.STONE.metadata);
		world.setBlock(x+58, y+4, z+16, b, BlockType.STONE.metadata);
		world.setBlock(x+58, y+4, z+17, b, BlockType.STONE.metadata);
		world.setBlock(x+58, y+4, z+18, b, BlockType.STONE.metadata);
		world.setBlock(x+58, y+4, z+19, b, BlockType.STONE.metadata);
		world.setBlock(x+58, y+4, z+20, b, BlockType.STONE.metadata);
		world.setBlock(x+58, y+4, z+21, b, BlockType.STONE.metadata);
		world.setBlock(x+58, y+4, z+22, b, BlockType.STONE.metadata);
		world.setBlock(x+58, y+4, z+23, b, BlockType.STONE.metadata);
		world.setBlock(x+58, y+4, z+24, b, BlockType.STONE.metadata);
		world.setBlock(x+58, y+4, z+25, b, BlockType.STONE.metadata);
		world.setBlock(x+58, y+4, z+26, b, BlockType.STONE.metadata);
		world.setBlock(x+58, y+4, z+27, b, BlockType.STONE.metadata);
		world.setBlock(x+58, y+4, z+28, b, BlockType.STONE.metadata);
		world.setBlock(x+58, y+4, z+29, b, BlockType.STONE.metadata);
		world.setBlock(x+58, y+4, z+30, b, BlockType.STONE.metadata);
		world.setBlock(x+58, y+4, z+34, b, BlockType.STONE.metadata);
		world.setBlock(x+58, y+4, z+35, b, BlockType.STONE.metadata);
		world.setBlock(x+58, y+4, z+36, b, BlockType.STONE.metadata);
		world.setBlock(x+58, y+4, z+37, b, BlockType.STONE.metadata);
		world.setBlock(x+58, y+4, z+38, b, BlockType.STONE.metadata);
		world.setBlock(x+58, y+4, z+39, b, BlockType.STONE.metadata);
		world.setBlock(x+58, y+4, z+40, b, BlockType.STONE.metadata);
		world.setBlock(x+58, y+4, z+41, b, BlockType.STONE.metadata);
		world.setBlock(x+58, y+4, z+42, b, BlockType.STONE.metadata);
		world.setBlock(x+58, y+4, z+43, b, BlockType.STONE.metadata);
		world.setBlock(x+58, y+4, z+44, b, BlockType.STONE.metadata);
		world.setBlock(x+58, y+4, z+45, b, BlockType.STONE.metadata);
		world.setBlock(x+58, y+4, z+46, b, BlockType.STONE.metadata);
		world.setBlock(x+58, y+4, z+47, b, BlockType.STONE.metadata);
		world.setBlock(x+58, y+4, z+48, b, BlockType.STONE.metadata);
		world.setBlock(x+58, y+4, z+49, b, BlockType.STONE.metadata);
		world.setBlock(x+58, y+4, z+50, b, BlockType.STONE.metadata);
		world.setBlock(x+58, y+4, z+51, b, BlockType.STONE.metadata);
		world.setBlock(x+59, y+0, z+12, b, BlockType.STONE.metadata);
		world.setBlock(x+59, y+0, z+13, b, BlockType.CLOAK.metadata);
		world.setBlock(x+59, y+0, z+14, b, BlockType.CLOAK.metadata);
		world.setBlock(x+59, y+0, z+15, b, BlockType.CLOAK.metadata);
		world.setBlock(x+59, y+0, z+16, b, BlockType.CLOAK.metadata);
		world.setBlock(x+59, y+0, z+17, b, BlockType.CLOAK.metadata);
		world.setBlock(x+59, y+0, z+18, b, BlockType.CLOAK.metadata);
		world.setBlock(x+59, y+0, z+19, b, BlockType.CLOAK.metadata);
		world.setBlock(x+59, y+0, z+20, b, BlockType.CLOAK.metadata);
		world.setBlock(x+59, y+0, z+21, b, BlockType.CLOAK.metadata);
		world.setBlock(x+59, y+0, z+22, b, BlockType.STONE.metadata);
		world.setBlock(x+59, y+0, z+26, b, BlockType.STONE.metadata);
		world.setBlock(x+59, y+0, z+27, b, BlockType.CLOAK.metadata);
		world.setBlock(x+59, y+0, z+28, b, BlockType.CLOAK.metadata);
		world.setBlock(x+59, y+0, z+29, b, BlockType.CLOAK.metadata);
		world.setBlock(x+59, y+0, z+30, b, BlockType.STONE.metadata);
		world.setBlock(x+59, y+1, z+12, b, BlockType.STONE.metadata);
		world.setBlock(x+59, y+1, z+22, b, BlockType.STONE.metadata);
		world.setBlock(x+59, y+1, z+26, b, BlockType.STONE.metadata);
		world.setBlock(x+59, y+1, z+30, b, BlockType.STONE.metadata);
		world.setBlock(x+59, y+2, z+12, b, BlockType.STONE.metadata);
		world.setBlock(x+59, y+2, z+22, b, BlockType.STONE.metadata);
		world.setBlock(x+59, y+2, z+26, b, BlockType.STONE.metadata);
		world.setBlock(x+59, y+2, z+30, b, BlockType.STONE.metadata);
		world.setBlock(x+59, y+3, z+12, b, BlockType.STONE.metadata);
		world.setBlock(x+59, y+3, z+22, b, BlockType.STONE.metadata);
		world.setBlock(x+59, y+3, z+26, b, BlockType.STONE.metadata);
		world.setBlock(x+59, y+3, z+30, b, BlockType.STONE.metadata);
		world.setBlock(x+59, y+4, z+12, b, BlockType.STONE.metadata);
		world.setBlock(x+59, y+4, z+13, b, BlockType.STONE.metadata);
		world.setBlock(x+59, y+4, z+14, b, BlockType.STONE.metadata);
		world.setBlock(x+59, y+4, z+15, b, BlockType.STONE.metadata);
		world.setBlock(x+59, y+4, z+16, b, BlockType.STONE.metadata);
		world.setBlock(x+59, y+4, z+17, b, BlockType.STONE.metadata);
		world.setBlock(x+59, y+4, z+18, b, BlockType.STONE.metadata);
		world.setBlock(x+59, y+4, z+19, b, BlockType.STONE.metadata);
		world.setBlock(x+59, y+4, z+20, b, BlockType.STONE.metadata);
		world.setBlock(x+59, y+4, z+21, b, BlockType.STONE.metadata);
		world.setBlock(x+59, y+4, z+22, b, BlockType.STONE.metadata);
		world.setBlock(x+59, y+4, z+26, b, BlockType.STONE.metadata);
		world.setBlock(x+59, y+4, z+27, b, BlockType.STONE.metadata);
		world.setBlock(x+59, y+4, z+28, b, BlockType.STONE.metadata);
		world.setBlock(x+59, y+4, z+29, b, BlockType.STONE.metadata);
		world.setBlock(x+59, y+4, z+30, b, BlockType.STONE.metadata);
		world.setBlock(x+60, y+0, z+12, b, BlockType.STONE.metadata);
		world.setBlock(x+60, y+0, z+13, b, BlockType.CLOAK.metadata);
		world.setBlock(x+60, y+0, z+14, b, BlockType.CLOAK.metadata);
		world.setBlock(x+60, y+0, z+15, b, BlockType.CLOAK.metadata);
		world.setBlock(x+60, y+0, z+16, b, BlockType.CLOAK.metadata);
		world.setBlock(x+60, y+0, z+17, b, BlockType.CLOAK.metadata);
		world.setBlock(x+60, y+0, z+18, b, BlockType.CLOAK.metadata);
	}

}
