package Reika.ChromatiCraft.Auxiliary.Structure;

import net.minecraft.init.Blocks;
import net.minecraft.world.World;

import Reika.ChromatiCraft.Base.ChromaStructureBase;
import Reika.ChromatiCraft.Block.BlockPylonStructure.StoneTypes;
import Reika.ChromatiCraft.Registry.ChromaTiles;
import Reika.DragonAPI.Instantiable.Data.BlockStruct.FilledBlockArray;


public class BroadcasterStructure extends ChromaStructureBase {

	@Override
	public FilledBlockArray getArray(World world, int x, int y, int z) {
		FilledBlockArray array = new FilledBlockArray(world);

		x -= 6;
		y -= 23;
		z -= 6;

		array.setBlock(x+0, y+3, z+5, b, 10);
		array.setBlock(x+0, y+3, z+6, b, 10);
		array.setBlock(x+0, y+3, z+7, b, 10);
		array.setBlock(x+1, y+3, z+5, b, 10);
		array.setBlock(x+1, y+3, z+6, b, 10);
		array.setBlock(x+1, y+3, z+7, b, 10);
		array.setBlock(x+2, y+3, z+4, b, 0);
		array.setBlock(x+2, y+3, z+5, b, 10);
		array.setBlock(x+2, y+3, z+6, b, 10);
		array.setBlock(x+2, y+3, z+7, b, 10);
		array.setBlock(x+2, y+3, z+8, b, 0);
		array.setBlock(x+3, y+2, z+5, b, 0);
		array.setBlock(x+3, y+2, z+6, b, 0);
		array.setBlock(x+3, y+2, z+7, b, 0);
		array.setBlock(x+3, y+3, z+3, b, 0);
		array.setBlock(x+3, y+3, z+4, b, 0);
		array.setBlock(x+3, y+3, z+5, b, 10);
		array.setBlock(x+3, y+3, z+6, b, 10);
		array.setBlock(x+3, y+3, z+7, b, 10);
		array.setBlock(x+3, y+3, z+8, b, 0);
		array.setBlock(x+3, y+3, z+9, b, 0);
		array.setBlock(x+3, y+4, z+4, b, 0);
		array.setBlock(x+3, y+4, z+8, b, 0);
		array.setBlock(x+3, y+5, z+4, b, 2);
		array.setBlock(x+3, y+5, z+8, b, 2);
		array.setBlock(x+3, y+6, z+4, b, 2);
		array.setBlock(x+3, y+6, z+8, b, 2);
		array.setBlock(x+3, y+7, z+4, b, 2);
		array.setBlock(x+3, y+7, z+8, b, 2);
		array.setBlock(x+3, y+8, z+4, b, 12);
		array.setBlock(x+3, y+8, z+5, b, 12);
		array.setBlock(x+3, y+8, z+6, b, 12);
		array.setBlock(x+3, y+8, z+7, b, 12);
		array.setBlock(x+3, y+8, z+8, b, 12);
		array.setBlock(x+3, y+9, z+4, b, 6);
		array.setBlock(x+3, y+9, z+5, b, 12);
		array.setBlock(x+3, y+9, z+6, b, 0);
		array.setBlock(x+3, y+9, z+7, b, 12);
		array.setBlock(x+3, y+9, z+8, b, 6);
		array.setBlock(x+3, y+10, z+5, b, 2);
		array.setBlock(x+3, y+10, z+6, b, 0);
		array.setBlock(x+3, y+10, z+7, b, 2);
		array.setBlock(x+3, y+11, z+5, b, 2);
		array.setBlock(x+3, y+11, z+6, b, 13);
		array.setBlock(x+3, y+11, z+7, b, 2);
		array.setBlock(x+3, y+12, z+5, b, 6);
		array.setBlock(x+3, y+12, z+6, b, 12);
		array.setBlock(x+3, y+12, z+7, b, 6);
		array.setBlock(x+3, y+13, z+6, b, 2);
		array.setBlock(x+3, y+14, z+6, b, 8);
		array.setBlock(x+4, y+1, z+5, b, 0);
		array.setBlock(x+4, y+1, z+6, b, 0);
		array.setBlock(x+4, y+1, z+7, b, 0);
		array.setBlock(x+4, y+2, z+4, b, 0);
		array.setBlock(x+4, y+2, z+5, b, 0);
		array.setBlock(x+4, y+2, z+6, b, 0);
		array.setBlock(x+4, y+2, z+7, b, 0);
		array.setBlock(x+4, y+2, z+8, b, 0);
		array.setBlock(x+4, y+3, z+2, b, 0);
		array.setBlock(x+4, y+3, z+3, b, 0);
		array.setBlock(x+4, y+3, z+4, b, 0);
		array.setBlock(x+4, y+3, z+5, b, 0);
		array.setBlock(x+4, y+3, z+6, b, 0);
		array.setBlock(x+4, y+3, z+7, b, 0);
		array.setBlock(x+4, y+3, z+8, b, 0);
		array.setBlock(x+4, y+3, z+9, b, 0);
		array.setBlock(x+4, y+3, z+10, b, 0);
		array.setBlock(x+4, y+4, z+3, b, 0);
		array.setBlock(x+4, y+4, z+4, b, 0);
		array.setBlock(x+4, y+4, z+5, b, 1);
		array.setBlock(x+4, y+4, z+6, b, 1);
		array.setBlock(x+4, y+4, z+7, b, 1);
		array.setBlock(x+4, y+4, z+8, b, 0);
		array.setBlock(x+4, y+4, z+9, b, 0);
		array.setBlock(x+4, y+5, z+3, b, 2);
		array.setBlock(x+4, y+5, z+4, b, 0);
		array.setBlock(x+4, y+5, z+8, b, 0);
		array.setBlock(x+4, y+5, z+9, b, 2);
		array.setBlock(x+4, y+6, z+3, b, 2);
		array.setBlock(x+4, y+6, z+4, b, 0);
		array.setBlock(x+4, y+6, z+8, b, 0);
		array.setBlock(x+4, y+6, z+9, b, 2);
		array.setBlock(x+4, y+7, z+3, b, 2);
		array.setBlock(x+4, y+7, z+4, b, 0);
		array.setBlock(x+4, y+7, z+5, b, 1);
		array.setBlock(x+4, y+7, z+6, b, 1);
		array.setBlock(x+4, y+7, z+7, b, 1);
		array.setBlock(x+4, y+7, z+8, b, 0);
		array.setBlock(x+4, y+7, z+9, b, 2);
		array.setBlock(x+4, y+8, z+3, b, 12);
		array.setBlock(x+4, y+8, z+4, b, 0);
		array.setBlock(x+4, y+8, z+5, b, 0);
		array.setBlock(x+4, y+8, z+6, b, 0);
		array.setBlock(x+4, y+8, z+7, b, 0);
		array.setBlock(x+4, y+8, z+8, b, 0);
		array.setBlock(x+4, y+8, z+9, b, 12);
		array.setBlock(x+4, y+9, z+3, b, 6);
		array.setBlock(x+4, y+9, z+4, b, 0);
		array.setBlock(x+4, y+9, z+5, b, 0);
		array.setBlock(x+4, y+9, z+6, b, 0);
		array.setBlock(x+4, y+9, z+7, b, 0);
		array.setBlock(x+4, y+9, z+8, b, 0);
		array.setBlock(x+4, y+9, z+9, b, 6);
		array.setBlock(x+4, y+10, z+4, b, 2);
		array.setBlock(x+4, y+10, z+5, b, 0);
		array.setBlock(x+4, y+10, z+6, b, 0);
		array.setBlock(x+4, y+10, z+7, b, 0);
		array.setBlock(x+4, y+10, z+8, b, 2);
		array.setBlock(x+4, y+11, z+4, b, 2);
		array.setBlock(x+4, y+11, z+5, b, 0);
		array.setBlock(x+4, y+11, z+6, b, 0);
		array.setBlock(x+4, y+11, z+7, b, 0);
		array.setBlock(x+4, y+11, z+8, b, 2);
		array.setBlock(x+4, y+12, z+4, b, 2);
		array.setBlock(x+4, y+12, z+5, b, 0);
		array.setBlock(x+4, y+12, z+6, b, 0);
		array.setBlock(x+4, y+12, z+7, b, 0);
		array.setBlock(x+4, y+12, z+8, b, 2);
		array.setBlock(x+4, y+13, z+4, b, 2);
		array.setBlock(x+4, y+13, z+5, b, 0);
		array.setBlock(x+4, y+13, z+6, b, 0);
		array.setBlock(x+4, y+13, z+7, b, 0);
		array.setBlock(x+4, y+13, z+8, b, 2);
		array.setBlock(x+4, y+14, z+4, b, 2);
		array.setBlock(x+4, y+14, z+5, b, 0);
		array.setBlock(x+4, y+14, z+6, b, 0);
		array.setBlock(x+4, y+14, z+7, b, 0);
		array.setBlock(x+4, y+14, z+8, b, 2);
		array.setBlock(x+4, y+15, z+4, b, 6);
		array.setBlock(x+4, y+15, z+5, b, 12);
		array.setBlock(x+4, y+15, z+6, b, 12);
		array.setBlock(x+4, y+15, z+7, b, 12);
		array.setBlock(x+4, y+15, z+8, b, 6);
		array.setBlock(x+4, y+16, z+5, b, 2);
		array.setBlock(x+4, y+16, z+6, b, 0);
		array.setBlock(x+4, y+16, z+7, b, 2);
		array.setBlock(x+4, y+17, z+5, b, 2);
		array.setBlock(x+4, y+17, z+6, b, 14);
		array.setBlock(x+4, y+17, z+7, b, 2);
		array.setBlock(x+4, y+18, z+5, b, 6);
		array.setBlock(x+4, y+18, z+6, b, 12);
		array.setBlock(x+4, y+18, z+7, b, 6);
		array.setBlock(x+4, y+19, z+6, b, 2);
		array.setBlock(x+4, y+20, z+6, b, 7);
		array.setBlock(x+5, y+0, z+5, b, 0);
		array.setBlock(x+5, y+0, z+6, b, 0);
		array.setBlock(x+5, y+0, z+7, b, 0);
		array.setBlock(x+5, y+1, z+4, b, 0);
		array.setBlock(x+5, y+1, z+5, b, 0);
		array.setBlock(x+5, y+1, z+6, b, 0);
		array.setBlock(x+5, y+1, z+7, b, 0);
		array.setBlock(x+5, y+1, z+8, b, 0);
		array.setBlock(x+5, y+2, z+3, b, 0);
		array.setBlock(x+5, y+2, z+4, b, 0);
		array.setBlock(x+5, y+2, z+5, b, 0);
		array.setBlock(x+5, y+2, z+6, b, 0);
		array.setBlock(x+5, y+2, z+7, b, 0);
		array.setBlock(x+5, y+2, z+8, b, 0);
		array.setBlock(x+5, y+2, z+9, b, 0);
		array.setBlock(x+5, y+3, z+0, b, 11);
		array.setBlock(x+5, y+3, z+1, b, 11);
		array.setBlock(x+5, y+3, z+2, b, 11);
		array.setBlock(x+5, y+3, z+3, b, 11);
		array.setBlock(x+5, y+3, z+4, b, 0);
		array.setBlock(x+5, y+3, z+5, b, 0);
		array.setBlock(x+5, y+3, z+6, b, 0);
		array.setBlock(x+5, y+3, z+7, b, 0);
		array.setBlock(x+5, y+3, z+8, b, 0);
		array.setBlock(x+5, y+3, z+9, b, 11);
		array.setBlock(x+5, y+3, z+10, b, 11);
		array.setBlock(x+5, y+3, z+11, b, 11);
		array.setBlock(x+5, y+3, z+12, b, 11);
		array.setBlock(x+5, y+4, z+4, b, 1);
		array.setBlock(x+5, y+4, z+5, b, 0);
		array.setBlock(x+5, y+4, z+6, b, 0);
		array.setBlock(x+5, y+4, z+7, b, 0);
		array.setBlock(x+5, y+4, z+8, b, 1);
		array.setBlock(x+5, y+5, z+5, b, 0);
		array.setBlock(x+5, y+5, z+6, b, 0);
		array.setBlock(x+5, y+5, z+7, b, 0);
		array.setBlock(x+5, y+6, z+5, b, 0);
		array.setBlock(x+5, y+6, z+7, b, 0);
		array.setBlock(x+5, y+7, z+4, b, 1);
		array.setBlock(x+5, y+7, z+5, b, 0);
		array.setBlock(x+5, y+7, z+6, b, 0);
		array.setBlock(x+5, y+7, z+7, b, 0);
		array.setBlock(x+5, y+7, z+8, b, 1);
		array.setBlock(x+5, y+8, z+3, b, 12);
		array.setBlock(x+5, y+8, z+4, b, 0);
		array.setBlock(x+5, y+8, z+5, b, 0);
		array.setBlock(x+5, y+8, z+6, b, 0);
		array.setBlock(x+5, y+8, z+7, b, 0);
		array.setBlock(x+5, y+8, z+8, b, 0);
		array.setBlock(x+5, y+8, z+9, b, 12);
		array.setBlock(x+5, y+9, z+3, b, 12);
		array.setBlock(x+5, y+9, z+4, b, 0);
		array.setBlock(x+5, y+9, z+5, b, 0);
		array.setBlock(x+5, y+9, z+6, b, 0);
		array.setBlock(x+5, y+9, z+7, b, 0);
		array.setBlock(x+5, y+9, z+8, b, 0);
		array.setBlock(x+5, y+9, z+9, b, 12);
		array.setBlock(x+5, y+10, z+3, b, 2);
		array.setBlock(x+5, y+10, z+4, b, 0);
		array.setBlock(x+5, y+10, z+5, b, 0);
		array.setBlock(x+5, y+10, z+6, b, 0);
		array.setBlock(x+5, y+10, z+7, b, 0);
		array.setBlock(x+5, y+10, z+8, b, 0);
		array.setBlock(x+5, y+10, z+9, b, 2);
		array.setBlock(x+5, y+11, z+3, b, 2);
		array.setBlock(x+5, y+11, z+4, b, 0);
		array.setBlock(x+5, y+11, z+5, b, 0);
		array.setBlock(x+5, y+11, z+6, b, 0);
		array.setBlock(x+5, y+11, z+7, b, 0);
		array.setBlock(x+5, y+11, z+8, b, 0);
		array.setBlock(x+5, y+11, z+9, b, 2);
		array.setBlock(x+5, y+12, z+3, b, 6);
		array.setBlock(x+5, y+12, z+4, b, 0);
		array.setBlock(x+5, y+12, z+5, b, 0);
		array.setBlock(x+5, y+12, z+6, b, 0);
		array.setBlock(x+5, y+12, z+7, b, 0);
		array.setBlock(x+5, y+12, z+8, b, 0);
		array.setBlock(x+5, y+12, z+9, b, 6);
		array.setBlock(x+5, y+13, z+4, b, 0);
		array.setBlock(x+5, y+13, z+5, b, 0);
		array.setBlock(x+5, y+13, z+6, b, 0);
		array.setBlock(x+5, y+13, z+7, b, 0);
		array.setBlock(x+5, y+13, z+8, b, 0);
		array.setBlock(x+5, y+14, z+4, b, 0);
		array.setBlock(x+5, y+14, z+5, b, 0);
		array.setBlock(x+5, y+14, z+6, b, 0);
		array.setBlock(x+5, y+14, z+7, b, 0);
		array.setBlock(x+5, y+14, z+8, b, 0);
		array.setBlock(x+5, y+15, z+4, b, 12);
		array.setBlock(x+5, y+15, z+5, b, 0);
		array.setBlock(x+5, y+15, z+6, b, 0);
		array.setBlock(x+5, y+15, z+7, b, 0);
		array.setBlock(x+5, y+15, z+8, b, 12);
		array.setBlock(x+5, y+16, z+4, b, 2);
		array.setBlock(x+5, y+16, z+5, b, 0);
		array.setBlock(x+5, y+16, z+6, b, 0);
		array.setBlock(x+5, y+16, z+7, b, 0);
		array.setBlock(x+5, y+16, z+8, b, 2);
		array.setBlock(x+5, y+17, z+4, b, 2);
		array.setBlock(x+5, y+17, z+5, b, 0);
		array.setBlock(x+5, y+17, z+6, b, 0);
		array.setBlock(x+5, y+17, z+7, b, 0);
		array.setBlock(x+5, y+17, z+8, b, 2);
		array.setBlock(x+5, y+18, z+4, b, 6);
		array.setBlock(x+5, y+18, z+5, b, 0);
		array.setBlock(x+5, y+18, z+6, b, 0);
		array.setBlock(x+5, y+18, z+7, b, 0);
		array.setBlock(x+5, y+18, z+8, b, 6);
		array.setBlock(x+5, y+19, z+5, b, 2);
		array.setBlock(x+5, y+19, z+6, b, 0);
		array.setBlock(x+5, y+19, z+7, b, 2);
		array.setBlock(x+5, y+20, z+5, b, 2);
		array.setBlock(x+5, y+20, z+6, b, 0);
		array.setBlock(x+5, y+20, z+7, b, 2);
		array.setBlock(x+5, y+21, z+5, b, 2);
		array.setBlock(x+5, y+21, z+6, b, 0);
		array.setBlock(x+5, y+21, z+7, b, 2);
		array.setBlock(x+5, y+22, z+5, b, 2);
		array.setBlock(x+5, y+22, z+6, b, 12);
		array.setBlock(x+5, y+22, z+7, b, 2);
		array.setBlock(x+5, y+23, z+5, b, 2);
		array.setBlock(x+5, y+23, z+7, b, 2);
		array.setBlock(x+5, y+24, z+5, b, 15);
		array.setBlock(x+5, y+24, z+6, b, 15);
		array.setBlock(x+5, y+24, z+7, b, 15);
		array.setBlock(x+5, y+25, z+6, b, 0);
		array.setBlock(x+6, y+0, z+5, b, 0);
		array.setBlock(x+6, y+0, z+7, b, 0);
		array.setBlock(x+6, y+1, z+4, b, 0);
		array.setBlock(x+6, y+1, z+5, b, 0);
		array.setBlock(x+6, y+1, z+7, b, 0);
		array.setBlock(x+6, y+1, z+8, b, 0);
		array.setBlock(x+6, y+2, z+3, b, 0);
		array.setBlock(x+6, y+2, z+4, b, 0);
		array.setBlock(x+6, y+2, z+5, b, 0);
		array.setBlock(x+6, y+2, z+7, b, 0);
		array.setBlock(x+6, y+2, z+8, b, 0);
		array.setBlock(x+6, y+2, z+9, b, 0);
		array.setBlock(x+6, y+3, z+0, b, 11);
		array.setBlock(x+6, y+3, z+1, b, 11);
		array.setBlock(x+6, y+3, z+2, b, 11);
		array.setBlock(x+6, y+3, z+3, b, 11);
		array.setBlock(x+6, y+3, z+4, b, 0);
		array.setBlock(x+6, y+3, z+5, b, 0);
		array.setBlock(x+6, y+3, z+7, b, 0);
		array.setBlock(x+6, y+3, z+8, b, 0);
		array.setBlock(x+6, y+3, z+9, b, 11);
		array.setBlock(x+6, y+3, z+10, b, 11);
		array.setBlock(x+6, y+3, z+11, b, 11);
		array.setBlock(x+6, y+3, z+12, b, 11);
		array.setBlock(x+6, y+4, z+4, b, 1);
		array.setBlock(x+6, y+4, z+5, b, 0);
		array.setBlock(x+6, y+4, z+7, b, 0);
		array.setBlock(x+6, y+4, z+8, b, 1);
		array.setBlock(x+6, y+5, z+5, b, 0);
		array.setBlock(x+6, y+5, z+7, b, 0);
		array.setBlock(x+6, y+7, z+4, b, 1);
		array.setBlock(x+6, y+7, z+5, b, 0);
		array.setBlock(x+6, y+7, z+7, b, 0);
		array.setBlock(x+6, y+7, z+8, b, 1);
		array.setBlock(x+6, y+8, z+3, b, 12);
		array.setBlock(x+6, y+8, z+4, b, 0);
		array.setBlock(x+6, y+8, z+5, b, 0);
		array.setBlock(x+6, y+8, z+7, b, 0);
		array.setBlock(x+6, y+8, z+8, b, 0);
		array.setBlock(x+6, y+8, z+9, b, 12);
		array.setBlock(x+6, y+9, z+3, b, 0);
		array.setBlock(x+6, y+9, z+4, b, 0);
		array.setBlock(x+6, y+9, z+5, b, 0);
		array.setBlock(x+6, y+9, z+7, b, 0);
		array.setBlock(x+6, y+9, z+8, b, 0);
		array.setBlock(x+6, y+9, z+9, b, 0);
		array.setBlock(x+6, y+10, z+3, b, 0);
		array.setBlock(x+6, y+10, z+4, b, 0);
		array.setBlock(x+6, y+10, z+5, b, 0);
		array.setBlock(x+6, y+10, z+7, b, 0);
		array.setBlock(x+6, y+10, z+8, b, 0);
		array.setBlock(x+6, y+10, z+9, b, 0);
		array.setBlock(x+6, y+11, z+3, b, 13);
		array.setBlock(x+6, y+11, z+4, b, 0);
		array.setBlock(x+6, y+11, z+5, b, 0);
		array.setBlock(x+6, y+11, z+7, b, 0);
		array.setBlock(x+6, y+11, z+8, b, 0);
		array.setBlock(x+6, y+11, z+9, b, 13);
		array.setBlock(x+6, y+12, z+3, b, 12);
		array.setBlock(x+6, y+12, z+4, b, 0);
		array.setBlock(x+6, y+12, z+5, b, 0);
		array.setBlock(x+6, y+12, z+7, b, 0);
		array.setBlock(x+6, y+12, z+8, b, 0);
		array.setBlock(x+6, y+12, z+9, b, 12);
		array.setBlock(x+6, y+13, z+3, b, 2);
		array.setBlock(x+6, y+13, z+4, b, 0);
		array.setBlock(x+6, y+13, z+5, b, 0);
		array.setBlock(x+6, y+13, z+7, b, 0);
		array.setBlock(x+6, y+13, z+8, b, 0);
		array.setBlock(x+6, y+13, z+9, b, 2);
		array.setBlock(x+6, y+14, z+3, b, 8);
		array.setBlock(x+6, y+14, z+4, b, 0);
		array.setBlock(x+6, y+14, z+5, b, 0);
		array.setBlock(x+6, y+14, z+7, b, 0);
		array.setBlock(x+6, y+14, z+8, b, 0);
		array.setBlock(x+6, y+14, z+9, b, 8);
		array.setBlock(x+6, y+15, z+4, b, 12);
		array.setBlock(x+6, y+15, z+5, b, 0);
		array.setBlock(x+6, y+15, z+7, b, 0);
		array.setBlock(x+6, y+15, z+8, b, 12);
		array.setBlock(x+6, y+16, z+4, b, 0);
		array.setBlock(x+6, y+16, z+5, b, 0);
		array.setBlock(x+6, y+16, z+7, b, 0);
		array.setBlock(x+6, y+16, z+8, b, 0);
		array.setBlock(x+6, y+17, z+4, b, 14);
		array.setBlock(x+6, y+17, z+5, b, 0);
		array.setBlock(x+6, y+17, z+7, b, 0);
		array.setBlock(x+6, y+17, z+8, b, 14);
		array.setBlock(x+6, y+18, z+4, b, 12);
		array.setBlock(x+6, y+18, z+5, b, 0);
		array.setBlock(x+6, y+18, z+7, b, 0);
		array.setBlock(x+6, y+18, z+8, b, 12);
		array.setBlock(x+6, y+19, z+4, b, 2);
		array.setBlock(x+6, y+19, z+5, b, 0);
		array.setBlock(x+6, y+19, z+7, b, 0);
		array.setBlock(x+6, y+19, z+8, b, 2);
		array.setBlock(x+6, y+20, z+4, b, 7);
		array.setBlock(x+6, y+20, z+5, b, 0);
		array.setBlock(x+6, y+20, z+7, b, 0);
		array.setBlock(x+6, y+20, z+8, b, 7);
		array.setBlock(x+6, y+21, z+5, b, 0);
		array.setBlock(x+6, y+21, z+7, b, 0);
		array.setBlock(x+6, y+22, z+5, b, 12);
		array.setBlock(x+6, y+22, z+7, b, 12);
		array.setBlock(x+6, y+24, z+5, b, 15);
		array.setBlock(x+6, y+24, z+7, b, 15);
		array.setBlock(x+6, y+25, z+5, b, 0);
		array.setBlock(x+6, y+25, z+7, b, 0);
		array.setBlock(x+7, y+0, z+5, b, 0);
		array.setBlock(x+7, y+0, z+6, b, 0);
		array.setBlock(x+7, y+0, z+7, b, 0);
		array.setBlock(x+7, y+1, z+4, b, 0);
		array.setBlock(x+7, y+1, z+5, b, 0);
		array.setBlock(x+7, y+1, z+6, b, 0);
		array.setBlock(x+7, y+1, z+7, b, 0);
		array.setBlock(x+7, y+1, z+8, b, 0);
		array.setBlock(x+7, y+2, z+3, b, 0);
		array.setBlock(x+7, y+2, z+4, b, 0);
		array.setBlock(x+7, y+2, z+5, b, 0);
		array.setBlock(x+7, y+2, z+6, b, 0);
		array.setBlock(x+7, y+2, z+7, b, 0);
		array.setBlock(x+7, y+2, z+8, b, 0);
		array.setBlock(x+7, y+2, z+9, b, 0);
		array.setBlock(x+7, y+3, z+0, b, 11);
		array.setBlock(x+7, y+3, z+1, b, 11);
		array.setBlock(x+7, y+3, z+2, b, 11);
		array.setBlock(x+7, y+3, z+3, b, 11);
		array.setBlock(x+7, y+3, z+4, b, 0);
		array.setBlock(x+7, y+3, z+5, b, 0);
		array.setBlock(x+7, y+3, z+6, b, 0);
		array.setBlock(x+7, y+3, z+7, b, 0);
		array.setBlock(x+7, y+3, z+8, b, 0);
		array.setBlock(x+7, y+3, z+9, b, 11);
		array.setBlock(x+7, y+3, z+10, b, 11);
		array.setBlock(x+7, y+3, z+11, b, 11);
		array.setBlock(x+7, y+3, z+12, b, 11);
		array.setBlock(x+7, y+4, z+4, b, 1);
		array.setBlock(x+7, y+4, z+5, b, 0);
		array.setBlock(x+7, y+4, z+6, b, 0);
		array.setBlock(x+7, y+4, z+7, b, 0);
		array.setBlock(x+7, y+4, z+8, b, 1);
		array.setBlock(x+7, y+5, z+5, b, 0);
		array.setBlock(x+7, y+5, z+6, b, 0);
		array.setBlock(x+7, y+5, z+7, b, 0);
		array.setBlock(x+7, y+6, z+5, b, 0);
		array.setBlock(x+7, y+6, z+7, b, 0);
		array.setBlock(x+7, y+7, z+4, b, 1);
		array.setBlock(x+7, y+7, z+5, b, 0);
		array.setBlock(x+7, y+7, z+6, b, 0);
		array.setBlock(x+7, y+7, z+7, b, 0);
		array.setBlock(x+7, y+7, z+8, b, 1);
		array.setBlock(x+7, y+8, z+3, b, 12);
		array.setBlock(x+7, y+8, z+4, b, 0);
		array.setBlock(x+7, y+8, z+5, b, 0);
		array.setBlock(x+7, y+8, z+6, b, 0);
		array.setBlock(x+7, y+8, z+7, b, 0);
		array.setBlock(x+7, y+8, z+8, b, 0);
		array.setBlock(x+7, y+8, z+9, b, 12);
		array.setBlock(x+7, y+9, z+3, b, 12);
		array.setBlock(x+7, y+9, z+4, b, 0);
		array.setBlock(x+7, y+9, z+5, b, 0);
		array.setBlock(x+7, y+9, z+6, b, 0);
		array.setBlock(x+7, y+9, z+7, b, 0);
		array.setBlock(x+7, y+9, z+8, b, 0);
		array.setBlock(x+7, y+9, z+9, b, 12);
		array.setBlock(x+7, y+10, z+3, b, 2);
		array.setBlock(x+7, y+10, z+4, b, 0);
		array.setBlock(x+7, y+10, z+5, b, 0);
		array.setBlock(x+7, y+10, z+6, b, 0);
		array.setBlock(x+7, y+10, z+7, b, 0);
		array.setBlock(x+7, y+10, z+8, b, 0);
		array.setBlock(x+7, y+10, z+9, b, 2);
		array.setBlock(x+7, y+11, z+3, b, 2);
		array.setBlock(x+7, y+11, z+4, b, 0);
		array.setBlock(x+7, y+11, z+5, b, 0);
		array.setBlock(x+7, y+11, z+6, b, 0);
		array.setBlock(x+7, y+11, z+7, b, 0);
		array.setBlock(x+7, y+11, z+8, b, 0);
		array.setBlock(x+7, y+11, z+9, b, 2);
		array.setBlock(x+7, y+12, z+3, b, 6);
		array.setBlock(x+7, y+12, z+4, b, 0);
		array.setBlock(x+7, y+12, z+5, b, 0);
		array.setBlock(x+7, y+12, z+6, b, 0);
		array.setBlock(x+7, y+12, z+7, b, 0);
		array.setBlock(x+7, y+12, z+8, b, 0);
		array.setBlock(x+7, y+12, z+9, b, 6);
		array.setBlock(x+7, y+13, z+4, b, 0);
		array.setBlock(x+7, y+13, z+5, b, 0);
		array.setBlock(x+7, y+13, z+6, b, 0);
		array.setBlock(x+7, y+13, z+7, b, 0);
		array.setBlock(x+7, y+13, z+8, b, 0);
		array.setBlock(x+7, y+14, z+4, b, 0);
		array.setBlock(x+7, y+14, z+5, b, 0);
		array.setBlock(x+7, y+14, z+6, b, 0);
		array.setBlock(x+7, y+14, z+7, b, 0);
		array.setBlock(x+7, y+14, z+8, b, 0);
		array.setBlock(x+7, y+15, z+4, b, 12);
		array.setBlock(x+7, y+15, z+5, b, 0);
		array.setBlock(x+7, y+15, z+6, b, 0);
		array.setBlock(x+7, y+15, z+7, b, 0);
		array.setBlock(x+7, y+15, z+8, b, 12);
		array.setBlock(x+7, y+16, z+4, b, 2);
		array.setBlock(x+7, y+16, z+5, b, 0);
		array.setBlock(x+7, y+16, z+6, b, 0);
		array.setBlock(x+7, y+16, z+7, b, 0);
		array.setBlock(x+7, y+16, z+8, b, 2);
		array.setBlock(x+7, y+17, z+4, b, 2);
		array.setBlock(x+7, y+17, z+5, b, 0);
		array.setBlock(x+7, y+17, z+6, b, 0);
		array.setBlock(x+7, y+17, z+7, b, 0);
		array.setBlock(x+7, y+17, z+8, b, 2);
		array.setBlock(x+7, y+18, z+4, b, 6);
		array.setBlock(x+7, y+18, z+5, b, 0);
		array.setBlock(x+7, y+18, z+6, b, 0);
		array.setBlock(x+7, y+18, z+7, b, 0);
		array.setBlock(x+7, y+18, z+8, b, 6);
		array.setBlock(x+7, y+19, z+5, b, 2);
		array.setBlock(x+7, y+19, z+6, b, 0);
		array.setBlock(x+7, y+19, z+7, b, 2);
		array.setBlock(x+7, y+20, z+5, b, 2);
		array.setBlock(x+7, y+20, z+6, b, 0);
		array.setBlock(x+7, y+20, z+7, b, 2);
		array.setBlock(x+7, y+21, z+5, b, 2);
		array.setBlock(x+7, y+21, z+6, b, 0);
		array.setBlock(x+7, y+21, z+7, b, 2);
		array.setBlock(x+7, y+22, z+5, b, 2);
		array.setBlock(x+7, y+22, z+6, b, 12);
		array.setBlock(x+7, y+22, z+7, b, 2);
		array.setBlock(x+7, y+23, z+5, b, 2);
		array.setBlock(x+7, y+23, z+7, b, 2);
		array.setBlock(x+7, y+24, z+5, b, 15);
		array.setBlock(x+7, y+24, z+6, b, 15);
		array.setBlock(x+7, y+24, z+7, b, 15);
		array.setBlock(x+7, y+25, z+6, b, 0);
		array.setBlock(x+8, y+1, z+5, b, 0);
		array.setBlock(x+8, y+1, z+6, b, 0);
		array.setBlock(x+8, y+1, z+7, b, 0);
		array.setBlock(x+8, y+2, z+4, b, 0);
		array.setBlock(x+8, y+2, z+5, b, 0);
		array.setBlock(x+8, y+2, z+6, b, 0);
		array.setBlock(x+8, y+2, z+7, b, 0);
		array.setBlock(x+8, y+2, z+8, b, 0);
		array.setBlock(x+8, y+3, z+2, b, 0);
		array.setBlock(x+8, y+3, z+3, b, 0);
		array.setBlock(x+8, y+3, z+4, b, 0);
		array.setBlock(x+8, y+3, z+5, b, 0);
		array.setBlock(x+8, y+3, z+6, b, 0);
		array.setBlock(x+8, y+3, z+7, b, 0);
		array.setBlock(x+8, y+3, z+8, b, 0);
		array.setBlock(x+8, y+3, z+9, b, 0);
		array.setBlock(x+8, y+3, z+10, b, 0);
		array.setBlock(x+8, y+4, z+3, b, 0);
		array.setBlock(x+8, y+4, z+4, b, 0);
		array.setBlock(x+8, y+4, z+5, b, 1);
		array.setBlock(x+8, y+4, z+6, b, 1);
		array.setBlock(x+8, y+4, z+7, b, 1);
		array.setBlock(x+8, y+4, z+8, b, 0);
		array.setBlock(x+8, y+4, z+9, b, 0);
		array.setBlock(x+8, y+5, z+3, b, 2);
		array.setBlock(x+8, y+5, z+4, b, 0);
		array.setBlock(x+8, y+5, z+8, b, 0);
		array.setBlock(x+8, y+5, z+9, b, 2);
		array.setBlock(x+8, y+6, z+3, b, 2);
		array.setBlock(x+8, y+6, z+4, b, 0);
		array.setBlock(x+8, y+6, z+8, b, 0);
		array.setBlock(x+8, y+6, z+9, b, 2);
		array.setBlock(x+8, y+7, z+3, b, 2);
		array.setBlock(x+8, y+7, z+4, b, 0);
		array.setBlock(x+8, y+7, z+5, b, 1);
		array.setBlock(x+8, y+7, z+6, b, 1);
		array.setBlock(x+8, y+7, z+7, b, 1);
		array.setBlock(x+8, y+7, z+8, b, 0);
		array.setBlock(x+8, y+7, z+9, b, 2);
		array.setBlock(x+8, y+8, z+3, b, 12);
		array.setBlock(x+8, y+8, z+4, b, 0);
		array.setBlock(x+8, y+8, z+5, b, 0);
		array.setBlock(x+8, y+8, z+6, b, 0);
		array.setBlock(x+8, y+8, z+7, b, 0);
		array.setBlock(x+8, y+8, z+8, b, 0);
		array.setBlock(x+8, y+8, z+9, b, 12);
		array.setBlock(x+8, y+9, z+3, b, 6);
		array.setBlock(x+8, y+9, z+4, b, 0);
		array.setBlock(x+8, y+9, z+5, b, 0);
		array.setBlock(x+8, y+9, z+6, b, 0);
		array.setBlock(x+8, y+9, z+7, b, 0);
		array.setBlock(x+8, y+9, z+8, b, 0);
		array.setBlock(x+8, y+9, z+9, b, 6);
		array.setBlock(x+8, y+10, z+4, b, 2);
		array.setBlock(x+8, y+10, z+5, b, 0);
		array.setBlock(x+8, y+10, z+6, b, 0);
		array.setBlock(x+8, y+10, z+7, b, 0);
		array.setBlock(x+8, y+10, z+8, b, 2);
		array.setBlock(x+8, y+11, z+4, b, 2);
		array.setBlock(x+8, y+11, z+5, b, 0);
		array.setBlock(x+8, y+11, z+6, b, 0);
		array.setBlock(x+8, y+11, z+7, b, 0);
		array.setBlock(x+8, y+11, z+8, b, 2);
		array.setBlock(x+8, y+12, z+4, b, 2);
		array.setBlock(x+8, y+12, z+5, b, 0);
		array.setBlock(x+8, y+12, z+6, b, 0);
		array.setBlock(x+8, y+12, z+7, b, 0);
		array.setBlock(x+8, y+12, z+8, b, 2);
		array.setBlock(x+8, y+13, z+4, b, 2);
		array.setBlock(x+8, y+13, z+5, b, 0);
		array.setBlock(x+8, y+13, z+6, b, 0);
		array.setBlock(x+8, y+13, z+7, b, 0);
		array.setBlock(x+8, y+13, z+8, b, 2);
		array.setBlock(x+8, y+14, z+4, b, 2);
		array.setBlock(x+8, y+14, z+5, b, 0);
		array.setBlock(x+8, y+14, z+6, b, 0);
		array.setBlock(x+8, y+14, z+7, b, 0);
		array.setBlock(x+8, y+14, z+8, b, 2);
		array.setBlock(x+8, y+15, z+4, b, 6);
		array.setBlock(x+8, y+15, z+5, b, 12);
		array.setBlock(x+8, y+15, z+6, b, 12);
		array.setBlock(x+8, y+15, z+7, b, 12);
		array.setBlock(x+8, y+15, z+8, b, 6);
		array.setBlock(x+8, y+16, z+5, b, 2);
		array.setBlock(x+8, y+16, z+6, b, 0);
		array.setBlock(x+8, y+16, z+7, b, 2);
		array.setBlock(x+8, y+17, z+5, b, 2);
		array.setBlock(x+8, y+17, z+6, b, 14);
		array.setBlock(x+8, y+17, z+7, b, 2);
		array.setBlock(x+8, y+18, z+5, b, 6);
		array.setBlock(x+8, y+18, z+6, b, 12);
		array.setBlock(x+8, y+18, z+7, b, 6);
		array.setBlock(x+8, y+19, z+6, b, 2);
		array.setBlock(x+8, y+20, z+6, b, 7);
		array.setBlock(x+9, y+2, z+5, b, 0);
		array.setBlock(x+9, y+2, z+6, b, 0);
		array.setBlock(x+9, y+2, z+7, b, 0);
		array.setBlock(x+9, y+3, z+3, b, 0);
		array.setBlock(x+9, y+3, z+4, b, 0);
		array.setBlock(x+9, y+3, z+5, b, 10);
		array.setBlock(x+9, y+3, z+6, b, 10);
		array.setBlock(x+9, y+3, z+7, b, 10);
		array.setBlock(x+9, y+3, z+8, b, 0);
		array.setBlock(x+9, y+3, z+9, b, 0);
		array.setBlock(x+9, y+4, z+4, b, 0);
		array.setBlock(x+9, y+4, z+8, b, 0);
		array.setBlock(x+9, y+5, z+4, b, 2);
		array.setBlock(x+9, y+5, z+8, b, 2);
		array.setBlock(x+9, y+6, z+4, b, 2);
		array.setBlock(x+9, y+6, z+8, b, 2);
		array.setBlock(x+9, y+7, z+4, b, 2);
		array.setBlock(x+9, y+7, z+8, b, 2);
		array.setBlock(x+9, y+8, z+4, b, 12);
		array.setBlock(x+9, y+8, z+5, b, 12);
		array.setBlock(x+9, y+8, z+6, b, 12);
		array.setBlock(x+9, y+8, z+7, b, 12);
		array.setBlock(x+9, y+8, z+8, b, 12);
		array.setBlock(x+9, y+9, z+4, b, 6);
		array.setBlock(x+9, y+9, z+5, b, 12);
		array.setBlock(x+9, y+9, z+6, b, 0);
		array.setBlock(x+9, y+9, z+7, b, 12);
		array.setBlock(x+9, y+9, z+8, b, 6);
		array.setBlock(x+9, y+10, z+5, b, 2);
		array.setBlock(x+9, y+10, z+6, b, 0);
		array.setBlock(x+9, y+10, z+7, b, 2);
		array.setBlock(x+9, y+11, z+5, b, 2);
		array.setBlock(x+9, y+11, z+6, b, 13);
		array.setBlock(x+9, y+11, z+7, b, 2);
		array.setBlock(x+9, y+12, z+5, b, 6);
		array.setBlock(x+9, y+12, z+6, b, 12);
		array.setBlock(x+9, y+12, z+7, b, 6);
		array.setBlock(x+9, y+13, z+6, b, 2);
		array.setBlock(x+9, y+14, z+6, b, 8);
		array.setBlock(x+10, y+3, z+4, b, 0);
		array.setBlock(x+10, y+3, z+5, b, 10);
		array.setBlock(x+10, y+3, z+6, b, 10);
		array.setBlock(x+10, y+3, z+7, b, 10);
		array.setBlock(x+10, y+3, z+8, b, 0);
		array.setBlock(x+11, y+3, z+5, b, 10);
		array.setBlock(x+11, y+3, z+6, b, 10);
		array.setBlock(x+11, y+3, z+7, b, 10);
		array.setBlock(x+12, y+3, z+5, b, 10);
		array.setBlock(x+12, y+3, z+6, b, 10);
		array.setBlock(x+12, y+3, z+7, b, 10);

		this.setTile(array, x+6, y+6, z+6, ChromaTiles.COMPOUND);
		this.setTile(array, x+6, y+23, z+6, ChromaTiles.BROADCAST);

		array.setBlock(x+6, y+0, z+6, b, 0);

		array.setBlock(x+6, y+1, z+6, b, 12);
		array.setBlock(x+6, y+2, z+6, b, 2);
		array.addBlock(x+6, y+2, z+6, b, StoneTypes.GLOWCOL.ordinal());
		array.setBlock(x+6, y+3, z+6, b, 13);
		array.setBlock(x+6, y+4, z+6, b, 2);
		array.addBlock(x+6, y+4, z+6, b, StoneTypes.GLOWCOL.ordinal());
		array.setBlock(x+6, y+5, z+6, b, 12);

		array.setBlock(x+6, y+24, z+6, b, 0);
		array.setBlock(x+6, y+25, z+6, b, 0);

		array.setBlock(x+6, y+20, z+6, Blocks.air);

		array.setBlock(x+3, y+4, z+5, Blocks.air);
		array.setBlock(x+3, y+4, z+6, Blocks.air);
		array.setBlock(x+3, y+4, z+7, Blocks.air);
		array.setBlock(x+3, y+5, z+5, Blocks.air);
		array.setBlock(x+3, y+5, z+6, Blocks.air);
		array.setBlock(x+3, y+5, z+7, Blocks.air);
		array.setBlock(x+3, y+6, z+5, Blocks.air);
		array.setBlock(x+3, y+6, z+6, Blocks.air);
		array.setBlock(x+3, y+6, z+7, Blocks.air);
		array.setBlock(x+3, y+7, z+5, Blocks.air);
		array.setBlock(x+3, y+7, z+6, Blocks.air);
		array.setBlock(x+3, y+7, z+7, Blocks.air);
		array.setBlock(x+4, y+5, z+5, Blocks.air);
		array.setBlock(x+4, y+5, z+6, Blocks.air);
		array.setBlock(x+4, y+5, z+7, Blocks.air);
		array.setBlock(x+4, y+6, z+5, Blocks.air);
		array.setBlock(x+4, y+6, z+6, Blocks.air);
		array.setBlock(x+4, y+6, z+7, Blocks.air);
		array.setBlock(x+5, y+4, z+3, Blocks.air);
		array.setBlock(x+5, y+4, z+9, Blocks.air);
		array.setBlock(x+5, y+5, z+3, Blocks.air);
		array.setBlock(x+5, y+5, z+4, Blocks.air);
		array.setBlock(x+5, y+5, z+8, Blocks.air);
		array.setBlock(x+5, y+5, z+9, Blocks.air);
		array.setBlock(x+5, y+6, z+3, Blocks.air);
		array.setBlock(x+5, y+6, z+4, Blocks.air);
		array.setBlock(x+5, y+6, z+6, Blocks.air);
		array.setBlock(x+5, y+6, z+8, Blocks.air);
		array.setBlock(x+5, y+6, z+9, Blocks.air);
		array.setBlock(x+5, y+7, z+3, Blocks.air);
		array.setBlock(x+5, y+7, z+9, Blocks.air);
		array.setBlock(x+5, y+23, z+6, Blocks.air);
		array.setBlock(x+6, y+4, z+3, Blocks.air);
		array.setBlock(x+6, y+4, z+9, Blocks.air);
		array.setBlock(x+6, y+5, z+3, Blocks.air);
		array.setBlock(x+6, y+5, z+4, Blocks.air);
		array.setBlock(x+6, y+5, z+8, Blocks.air);
		array.setBlock(x+6, y+5, z+9, Blocks.air);
		array.setBlock(x+6, y+6, z+3, Blocks.air);
		array.setBlock(x+6, y+6, z+4, Blocks.air);
		array.setBlock(x+6, y+6, z+5, Blocks.air);
		array.setBlock(x+6, y+6, z+7, Blocks.air);
		array.setBlock(x+6, y+6, z+8, Blocks.air);
		array.setBlock(x+6, y+6, z+9, Blocks.air);
		array.setBlock(x+6, y+7, z+3, Blocks.air);
		array.setBlock(x+6, y+7, z+9, Blocks.air);
		array.setBlock(x+6, y+23, z+5, Blocks.air);
		array.setBlock(x+6, y+23, z+7, Blocks.air);
		array.setBlock(x+7, y+4, z+3, Blocks.air);
		array.setBlock(x+7, y+4, z+9, Blocks.air);
		array.setBlock(x+7, y+5, z+3, Blocks.air);
		array.setBlock(x+7, y+5, z+4, Blocks.air);
		array.setBlock(x+7, y+5, z+8, Blocks.air);
		array.setBlock(x+7, y+5, z+9, Blocks.air);
		array.setBlock(x+7, y+6, z+3, Blocks.air);
		array.setBlock(x+7, y+6, z+4, Blocks.air);
		array.setBlock(x+7, y+6, z+6, Blocks.air);
		array.setBlock(x+7, y+6, z+8, Blocks.air);
		array.setBlock(x+7, y+6, z+9, Blocks.air);
		array.setBlock(x+7, y+7, z+3, Blocks.air);
		array.setBlock(x+7, y+7, z+9, Blocks.air);
		array.setBlock(x+7, y+23, z+6, Blocks.air);
		array.setBlock(x+8, y+5, z+5, Blocks.air);
		array.setBlock(x+8, y+5, z+6, Blocks.air);
		array.setBlock(x+8, y+5, z+7, Blocks.air);
		array.setBlock(x+8, y+6, z+5, Blocks.air);
		array.setBlock(x+8, y+6, z+6, Blocks.air);
		array.setBlock(x+8, y+6, z+7, Blocks.air);
		array.setBlock(x+9, y+4, z+5, Blocks.air);
		array.setBlock(x+9, y+4, z+6, Blocks.air);
		array.setBlock(x+9, y+4, z+7, Blocks.air);
		array.setBlock(x+9, y+5, z+5, Blocks.air);
		array.setBlock(x+9, y+5, z+6, Blocks.air);
		array.setBlock(x+9, y+5, z+7, Blocks.air);
		array.setBlock(x+9, y+6, z+5, Blocks.air);
		array.setBlock(x+9, y+6, z+6, Blocks.air);
		array.setBlock(x+9, y+6, z+7, Blocks.air);
		array.setBlock(x+9, y+7, z+5, Blocks.air);
		array.setBlock(x+9, y+7, z+6, Blocks.air);
		array.setBlock(x+9, y+7, z+7, Blocks.air);

		return array;
	}

}
