package Reika.ChromatiCraft.Auxiliary.Structure;

import net.minecraft.block.Block;
import net.minecraft.world.World;

import Reika.DragonAPI.Instantiable.Data.BlockStruct.BlockArray;

public class RainbowTreeBlueprint {

	public static void place(World world, int x, int y, int z, Block id, Block log, int meta, int meta2, int meta3) {
		world.setBlock(x, y+10, z+4, id, 0, 3);
		world.setBlock(x, y+10, z+5, id, 0, 3);
		world.setBlock(x, y+11, z+3, id, 0, 3);
		world.setBlock(x, y+11, z+4, id, 0, 3);
		world.setBlock(x, y+11, z+5, id, 0, 3);
		world.setBlock(x, y+11, z+6, id, 0, 3);
		world.setBlock(x, y+12, z+4, id, 0, 3);
		world.setBlock(x, y+12, z+5, id, 0, 3);
		world.setBlock(x, y+13, z+3, id, 0, 3);
		world.setBlock(x, y+13, z+4, id, 0, 3);
		world.setBlock(x, y+13, z+5, id, 0, 3);
		world.setBlock(x, y+13, z+6, id, 0, 3);
		world.setBlock(x, y+14, z+3, id, 0, 3);
		world.setBlock(x, y+14, z+4, id, 0, 3);
		world.setBlock(x, y+14, z+5, id, 0, 3);
		world.setBlock(x, y+14, z+6, id, 0, 3);
		world.setBlock(x, y+15, z+4, id, 0, 3);
		world.setBlock(x, y+15, z+5, id, 0, 3);
		world.setBlock(x, y+16, z+3, id, 0, 3);
		world.setBlock(x, y+16, z+4, id, 0, 3);
		world.setBlock(x, y+16, z+5, id, 0, 3);
		world.setBlock(x, y+16, z+6, id, 0, 3);
		world.setBlock(x, y+17, z+4, id, 0, 3);
		world.setBlock(x, y+17, z+5, id, 0, 3);

		world.setBlock(x+1, y+8, z+4, id, 0, 3);
		world.setBlock(x+1, y+8, z+5, id, 0, 3);
		world.setBlock(x+1, y+9, z+3, id, 0, 3);
		world.setBlock(x+1, y+9, z+4, id, 0, 3);
		world.setBlock(x+1, y+9, z+5, id, 0, 3);
		world.setBlock(x+1, y+9, z+6, id, 0, 3);
		world.setBlock(x+1, y+10, z+3, id, 0, 3);
		world.setBlock(x+1, y+10, z+4, id, 0, 3);
		world.setBlock(x+1, y+10, z+5, id, 0, 3);
		world.setBlock(x+1, y+10, z+6, id, 0, 3);
		world.setBlock(x+1, y+11, z+2, id, 0, 3);
		world.setBlock(x+1, y+11, z+3, id, 0, 3);
		world.setBlock(x+1, y+11, z+4, log, meta2, 3);
		world.setBlock(x+1, y+11, z+5, log, meta2, 3);
		world.setBlock(x+1, y+11, z+6, id, 0, 3);
		world.setBlock(x+1, y+11, z+7, id, 0, 3);
		world.setBlock(x+1, y+12, z+3, id, 0, 3);
		world.setBlock(x+1, y+12, z+4, id, 0, 3);
		world.setBlock(x+1, y+12, z+5, id, 0, 3);
		world.setBlock(x+1, y+12, z+6, id, 0, 3);
		world.setBlock(x+1, y+13, z+1, id, 0, 3);
		world.setBlock(x+1, y+13, z+2, id, 0, 3);
		world.setBlock(x+1, y+13, z+3, id, 0, 3);
		world.setBlock(x+1, y+13, z+4, id, 0, 3);
		world.setBlock(x+1, y+13, z+5, id, 0, 3);
		world.setBlock(x+1, y+13, z+6, id, 0, 3);
		world.setBlock(x+1, y+13, z+7, id, 0, 3);
		world.setBlock(x+1, y+13, z+8, id, 0, 3);
		world.setBlock(x+1, y+14, z+1, id, 0, 3);
		world.setBlock(x+1, y+14, z+2, id, 0, 3);
		world.setBlock(x+1, y+14, z+3, id, 0, 3);
		world.setBlock(x+1, y+14, z+4, id, 0, 3);
		world.setBlock(x+1, y+14, z+5, id, 0, 3);
		world.setBlock(x+1, y+14, z+6, id, 0, 3);
		world.setBlock(x+1, y+14, z+7, id, 0, 3);
		world.setBlock(x+1, y+14, z+8, id, 0, 3);
		world.setBlock(x+1, y+15, z+3, id, 0, 3);
		world.setBlock(x+1, y+15, z+4, id, 0, 3);
		world.setBlock(x+1, y+15, z+5, id, 0, 3);
		world.setBlock(x+1, y+15, z+6, id, 0, 3);
		world.setBlock(x+1, y+16, z+2, id, 0, 3);
		world.setBlock(x+1, y+16, z+3, id, 0, 3);
		world.setBlock(x+1, y+16, z+4, log, meta2, 3);
		world.setBlock(x+1, y+16, z+5, log, meta2, 3);
		world.setBlock(x+1, y+16, z+6, id, 0, 3);
		world.setBlock(x+1, y+16, z+7, id, 0, 3);
		world.setBlock(x+1, y+17, z+3, id, 0, 3);
		world.setBlock(x+1, y+17, z+4, id, 0, 3);
		world.setBlock(x+1, y+17, z+5, id, 0, 3);
		world.setBlock(x+1, y+17, z+6, id, 0, 3);
		world.setBlock(x+1, y+18, z+4, id, 0, 3);
		world.setBlock(x+1, y+18, z+5, id, 0, 3);
		world.setBlock(x+1, y+19, z+4, id, 0, 3);
		world.setBlock(x+1, y+19, z+5, id, 0, 3);
		world.setBlock(x+1, y+20, z+4, id, 0, 3);
		world.setBlock(x+1, y+20, z+5, id, 0, 3);

		world.setBlock(x+2, y+2, z+4, log, meta2, 3);
		world.setBlock(x+2, y+2, z+5, log, meta2, 3);
		world.setBlock(x+2, y+7, z+4, id, 0, 3);
		world.setBlock(x+2, y+7, z+5, id, 0, 3);
		world.setBlock(x+2, y+8, z+3, id, 0, 3);
		world.setBlock(x+2, y+8, z+4, id, 0, 3);
		world.setBlock(x+2, y+8, z+5, id, 0, 3);
		world.setBlock(x+2, y+8, z+6, id, 0, 3);
		world.setBlock(x+2, y+9, z+2, id, 0, 3);
		world.setBlock(x+2, y+9, z+3, id, 0, 3);
		world.setBlock(x+2, y+9, z+4, id, 0, 3);
		world.setBlock(x+2, y+9, z+5, id, 0, 3);
		world.setBlock(x+2, y+9, z+6, id, 0, 3);
		world.setBlock(x+2, y+9, z+7, id, 0, 3);
		world.setBlock(x+2, y+10, z+2, id, 0, 3);
		world.setBlock(x+2, y+10, z+3, id, 0, 3);
		world.setBlock(x+2, y+10, z+4, id, 0, 3);
		world.setBlock(x+2, y+10, z+5, id, 0, 3);
		world.setBlock(x+2, y+10, z+6, id, 0, 3);
		world.setBlock(x+2, y+10, z+7, id, 0, 3);
		world.setBlock(x+2, y+11, z+1, id, 0, 3);
		world.setBlock(x+2, y+11, z+2, id, 0, 3);
		world.setBlock(x+2, y+11, z+3, id, 0, 3);
		world.setBlock(x+2, y+11, z+4, log, meta2, 3);
		world.setBlock(x+2, y+11, z+5, log, meta2, 3);
		world.setBlock(x+2, y+11, z+6, id, 0, 3);
		world.setBlock(x+2, y+11, z+7, id, 0, 3);
		world.setBlock(x+2, y+11, z+8, id, 0, 3);
		world.setBlock(x+2, y+12, z+2, id, 0, 3);
		world.setBlock(x+2, y+12, z+3, id, 0, 3);
		world.setBlock(x+2, y+12, z+4, id, 0, 3);
		world.setBlock(x+2, y+12, z+5, id, 0, 3);
		world.setBlock(x+2, y+12, z+6, id, 0, 3);
		world.setBlock(x+2, y+12, z+7, id, 0, 3);
		world.setBlock(x+2, y+13, z+1, id, 0, 3);
		world.setBlock(x+2, y+13, z+2, id, 0, 3);
		world.setBlock(x+2, y+13, z+3, id, 0, 3);
		world.setBlock(x+2, y+13, z+4, id, 0, 3);
		world.setBlock(x+2, y+13, z+5, id, 0, 3);
		world.setBlock(x+2, y+13, z+6, id, 0, 3);
		world.setBlock(x+2, y+13, z+7, id, 0, 3);
		world.setBlock(x+2, y+13, z+8, id, 0, 3);
		world.setBlock(x+2, y+14, z+1, id, 0, 3);
		world.setBlock(x+2, y+14, z+2, id, 0, 3);
		world.setBlock(x+2, y+14, z+3, id, 0, 3);
		world.setBlock(x+2, y+14, z+4, id, 0, 3);
		world.setBlock(x+2, y+14, z+5, id, 0, 3);
		world.setBlock(x+2, y+14, z+6, id, 0, 3);
		world.setBlock(x+2, y+14, z+7, id, 0, 3);
		world.setBlock(x+2, y+14, z+8, id, 0, 3);
		world.setBlock(x+2, y+15, z+2, id, 0, 3);
		world.setBlock(x+2, y+15, z+3, id, 0, 3);
		world.setBlock(x+2, y+15, z+4, id, 0, 3);
		world.setBlock(x+2, y+15, z+5, id, 0, 3);
		world.setBlock(x+2, y+15, z+6, id, 0, 3);
		world.setBlock(x+2, y+15, z+7, id, 0, 3);
		world.setBlock(x+2, y+16, z+1, id, 0, 3);
		world.setBlock(x+2, y+16, z+2, id, 0, 3);
		world.setBlock(x+2, y+16, z+3, id, 0, 3);
		world.setBlock(x+2, y+16, z+4, log, meta2, 3);
		world.setBlock(x+2, y+16, z+5, log, meta2, 3);
		world.setBlock(x+2, y+16, z+6, id, 0, 3);
		world.setBlock(x+2, y+16, z+7, id, 0, 3);
		world.setBlock(x+2, y+16, z+8, id, 0, 3);
		world.setBlock(x+2, y+17, z+2, id, 0, 3);
		world.setBlock(x+2, y+17, z+3, id, 0, 3);
		world.setBlock(x+2, y+17, z+4, id, 0, 3);
		world.setBlock(x+2, y+17, z+5, id, 0, 3);
		world.setBlock(x+2, y+17, z+6, id, 0, 3);
		world.setBlock(x+2, y+17, z+7, id, 0, 3);
		world.setBlock(x+2, y+18, z+3, id, 0, 3);
		world.setBlock(x+2, y+18, z+4, id, 0, 3);
		world.setBlock(x+2, y+18, z+5, id, 0, 3);
		world.setBlock(x+2, y+18, z+6, id, 0, 3);
		world.setBlock(x+2, y+19, z+3, id, 0, 3);
		world.setBlock(x+2, y+19, z+4, id, 0, 3);
		world.setBlock(x+2, y+19, z+5, id, 0, 3);
		world.setBlock(x+2, y+19, z+6, id, 0, 3);
		world.setBlock(x+2, y+20, z+3, id, 0, 3);
		world.setBlock(x+2, y+20, z+4, id, 0, 3);
		world.setBlock(x+2, y+20, z+5, id, 0, 3);
		world.setBlock(x+2, y+20, z+6, id, 0, 3);
		world.setBlock(x+2, y+21, z+4, id, 0, 3);
		world.setBlock(x+2, y+21, z+5, id, 0, 3);
		world.setBlock(x+2, y+22, z+4, id, 0, 3);
		world.setBlock(x+2, y+22, z+5, id, 0, 3);
		world.setBlock(x+2, y+23, z+4, id, 0, 3);
		world.setBlock(x+2, y+23, z+5, id, 0, 3);
		world.setBlock(x+2, y+24, z+4, id, 0, 3);
		world.setBlock(x+2, y+24, z+5, id, 0, 3);

		world.setBlock(x+3, y+1, z+3, log, meta, 3);
		world.setBlock(x+3, y+1, z+4, log, meta, 3);
		world.setBlock(x+3, y+1, z+5, log, meta, 3);
		world.setBlock(x+3, y+1, z+6, log, meta, 3);

		world.setBlock(x+3, y+2, z+3, log, meta, 3);
		world.setBlock(x+3, y+2, z+4, log, meta, 3);
		world.setBlock(x+3, y+2, z+5, log, meta, 3);
		world.setBlock(x+3, y+2, z+6, log, meta, 3);
		world.setBlock(x+3, y+3, z+4, log, meta, 3);
		world.setBlock(x+3, y+3, z+5, log, meta, 3);
		world.setBlock(x+3, y+4, z+4, log, meta, 3);
		world.setBlock(x+3, y+4, z+5, log, meta, 3);
		world.setBlock(x+3, y+6, z+4, id, 0, 3);
		world.setBlock(x+3, y+6, z+5, id, 0, 3);
		world.setBlock(x+3, y+7, z+3, id, 0, 3);
		world.setBlock(x+3, y+7, z+4, id, 0, 3);
		world.setBlock(x+3, y+7, z+5, id, 0, 3);
		world.setBlock(x+3, y+7, z+6, id, 0, 3);
		world.setBlock(x+3, y+8, z+2, id, 0, 3);
		world.setBlock(x+3, y+8, z+3, id, 0, 3);
		world.setBlock(x+3, y+8, z+4, id, 0, 3);
		world.setBlock(x+3, y+8, z+5, id, 0, 3);
		world.setBlock(x+3, y+8, z+6, id, 0, 3);
		world.setBlock(x+3, y+8, z+7, id, 0, 3);
		world.setBlock(x+3, y+9, z+1, id, 0, 3);
		world.setBlock(x+3, y+9, z+2, id, 0, 3);
		world.setBlock(x+3, y+9, z+3, id, 0, 3);
		world.setBlock(x+3, y+9, z+4, id, 0, 3);
		world.setBlock(x+3, y+9, z+5, id, 0, 3);
		world.setBlock(x+3, y+9, z+6, id, 0, 3);
		world.setBlock(x+3, y+9, z+7, id, 0, 3);
		world.setBlock(x+3, y+9, z+8, id, 0, 3);
		world.setBlock(x+3, y+10, z+1, id, 0, 3);
		world.setBlock(x+3, y+10, z+2, id, 0, 3);
		world.setBlock(x+3, y+10, z+3, id, 0, 3);
		world.setBlock(x+3, y+10, z+4, id, 0, 3);
		world.setBlock(x+3, y+10, z+5, id, 0, 3);
		world.setBlock(x+3, y+10, z+6, id, 0, 3);
		world.setBlock(x+3, y+10, z+7, id, 0, 3);
		world.setBlock(x+3, y+10, z+8, id, 0, 3);
		world.setBlock(x+3, y+11, z, id, 0, 3);
		world.setBlock(x+3, y+11, z+1, id, 0, 3);
		world.setBlock(x+3, y+11, z+2, id, 0, 3);
		world.setBlock(x+3, y+11, z+3, id, 0, 3);
		world.setBlock(x+3, y+11, z+4, log, meta2, 3);
		world.setBlock(x+3, y+11, z+5, log, meta2, 3);
		world.setBlock(x+3, y+11, z+6, id, 0, 3);
		world.setBlock(x+3, y+11, z+7, id, 0, 3);
		world.setBlock(x+3, y+11, z+8, id, 0, 3);
		world.setBlock(x+3, y+11, z+9, id, 0, 3);
		world.setBlock(x+3, y+12, z+1, id, 0, 3);
		world.setBlock(x+3, y+12, z+2, id, 0, 3);
		world.setBlock(x+3, y+12, z+3, id, 0, 3);
		world.setBlock(x+3, y+12, z+4, id, 0, 3);
		world.setBlock(x+3, y+12, z+5, id, 0, 3);
		world.setBlock(x+3, y+12, z+6, id, 0, 3);
		world.setBlock(x+3, y+12, z+7, id, 0, 3);
		world.setBlock(x+3, y+12, z+8, id, 0, 3);
		world.setBlock(x+3, y+13, z, id, 0, 3);
		world.setBlock(x+3, y+13, z+1, id, 0, 3);
		world.setBlock(x+3, y+13, z+2, id, 0, 3);
		world.setBlock(x+3, y+13, z+3, id, 0, 3);
		world.setBlock(x+3, y+13, z+4, id, 0, 3);
		world.setBlock(x+3, y+13, z+5, id, 0, 3);
		world.setBlock(x+3, y+13, z+6, id, 0, 3);
		world.setBlock(x+3, y+13, z+7, id, 0, 3);
		world.setBlock(x+3, y+13, z+8, id, 0, 3);
		world.setBlock(x+3, y+13, z+9, id, 0, 3);
		world.setBlock(x+3, y+14, z, id, 0, 3);
		world.setBlock(x+3, y+14, z+1, id, 0, 3);
		world.setBlock(x+3, y+14, z+2, id, 0, 3);
		world.setBlock(x+3, y+14, z+3, id, 0, 3);
		world.setBlock(x+3, y+14, z+4, id, 0, 3);
		world.setBlock(x+3, y+14, z+5, id, 0, 3);
		world.setBlock(x+3, y+14, z+6, id, 0, 3);
		world.setBlock(x+3, y+14, z+7, id, 0, 3);
		world.setBlock(x+3, y+14, z+8, id, 0, 3);
		world.setBlock(x+3, y+14, z+9, id, 0, 3);
		world.setBlock(x+3, y+15, z+1, id, 0, 3);
		world.setBlock(x+3, y+15, z+2, id, 0, 3);
		world.setBlock(x+3, y+15, z+3, id, 0, 3);
		world.setBlock(x+3, y+15, z+4, id, 0, 3);
		world.setBlock(x+3, y+15, z+5, id, 0, 3);
		world.setBlock(x+3, y+15, z+6, id, 0, 3);
		world.setBlock(x+3, y+15, z+7, id, 0, 3);
		world.setBlock(x+3, y+15, z+8, id, 0, 3);
		world.setBlock(x+3, y+16, z, id, 0, 3);
		world.setBlock(x+3, y+16, z+1, id, 0, 3);
		world.setBlock(x+3, y+16, z+2, id, 0, 3);
		world.setBlock(x+3, y+16, z+3, id, 0, 3);
		world.setBlock(x+3, y+16, z+4, log, meta2, 3);
		world.setBlock(x+3, y+16, z+5, log, meta2, 3);
		world.setBlock(x+3, y+16, z+6, id, 0, 3);
		world.setBlock(x+3, y+16, z+7, id, 0, 3);
		world.setBlock(x+3, y+16, z+8, id, 0, 3);
		world.setBlock(x+3, y+16, z+9, id, 0, 3);
		world.setBlock(x+3, y+17, z+1, id, 0, 3);
		world.setBlock(x+3, y+17, z+2, id, 0, 3);
		world.setBlock(x+3, y+17, z+3, id, 0, 3);
		world.setBlock(x+3, y+17, z+4, id, 0, 3);
		world.setBlock(x+3, y+17, z+5, id, 0, 3);
		world.setBlock(x+3, y+17, z+6, id, 0, 3);
		world.setBlock(x+3, y+17, z+7, id, 0, 3);
		world.setBlock(x+3, y+17, z+8, id, 0, 3);
		world.setBlock(x+3, y+18, z+2, id, 0, 3);
		world.setBlock(x+3, y+18, z+3, id, 0, 3);
		world.setBlock(x+3, y+18, z+4, id, 0, 3);
		world.setBlock(x+3, y+18, z+5, id, 0, 3);
		world.setBlock(x+3, y+18, z+6, id, 0, 3);
		world.setBlock(x+3, y+18, z+7, id, 0, 3);
		world.setBlock(x+3, y+19, z+2, id, 0, 3);
		world.setBlock(x+3, y+19, z+3, id, 0, 3);
		world.setBlock(x+3, y+19, z+4, id, 0, 3);
		world.setBlock(x+3, y+19, z+5, id, 0, 3);
		world.setBlock(x+3, y+19, z+6, id, 0, 3);
		world.setBlock(x+3, y+19, z+7, id, 0, 3);
		world.setBlock(x+3, y+20, z+2, id, 0, 3);
		world.setBlock(x+3, y+20, z+3, id, 0, 3);
		world.setBlock(x+3, y+20, z+4, id, 0, 3);
		world.setBlock(x+3, y+20, z+5, id, 0, 3);
		world.setBlock(x+3, y+20, z+6, id, 0, 3);
		world.setBlock(x+3, y+20, z+7, id, 0, 3);
		world.setBlock(x+3, y+21, z+3, id, 0, 3);
		world.setBlock(x+3, y+21, z+4, id, 0, 3);
		world.setBlock(x+3, y+21, z+5, id, 0, 3);
		world.setBlock(x+3, y+21, z+6, id, 0, 3);
		world.setBlock(x+3, y+22, z+3, id, 0, 3);
		world.setBlock(x+3, y+22, z+4, id, 0, 3);
		world.setBlock(x+3, y+22, z+5, id, 0, 3);
		world.setBlock(x+3, y+22, z+6, id, 0, 3);
		world.setBlock(x+3, y+23, z+3, id, 0, 3);
		world.setBlock(x+3, y+23, z+4, id, 0, 3);
		world.setBlock(x+3, y+23, z+5, id, 0, 3);
		world.setBlock(x+3, y+23, z+6, id, 0, 3);
		world.setBlock(x+3, y+24, z+3, id, 0, 3);
		world.setBlock(x+3, y+24, z+4, id, 0, 3);
		world.setBlock(x+3, y+24, z+5, id, 0, 3);
		world.setBlock(x+3, y+24, z+6, id, 0, 3);
		world.setBlock(x+3, y+25, z+4, id, 0, 3);
		world.setBlock(x+3, y+25, z+5, id, 0, 3);
		world.setBlock(x+3, y+26, z+4, id, 0, 3);
		world.setBlock(x+3, y+26, z+5, id, 0, 3);
		world.setBlock(x+3, y+27, z+4, id, 0, 3);
		world.setBlock(x+3, y+27, z+5, id, 0, 3);

		world.setBlock(x+4, y - 1, z+4, log, meta, 3);
		world.setBlock(x+4, y - 1, z+5, log, meta, 3);

		world.setBlock(x+4, y, z+4, log, meta, 3);
		world.setBlock(x+4, y, z+5, log, meta, 3);

		world.setBlock(x+4, y+1, z+3, log, meta, 3);
		world.setBlock(x+4, y+1, z+4, log, meta, 3);
		world.setBlock(x+4, y+1, z+5, log, meta, 3);
		world.setBlock(x+4, y+1, z+6, log, meta, 3);

		world.setBlock(x+4, y+2, z+2, log, meta3, 3);
		world.setBlock(x+4, y+2, z+3, log, meta, 3);
		world.setBlock(x+4, y+2, z+4, log, meta, 3);
		world.setBlock(x+4, y+2, z+5, log, meta, 3);
		world.setBlock(x+4, y+2, z+6, log, meta, 3);
		world.setBlock(x+4, y+2, z+7, log, meta3, 3);
		world.setBlock(x+4, y+3, z+3, log, meta, 3);
		world.setBlock(x+4, y+3, z+4, log, meta, 3);
		world.setBlock(x+4, y+3, z+5, log, meta, 3);
		world.setBlock(x+4, y+3, z+6, log, meta, 3);
		world.setBlock(x+4, y+4, z+3, log, meta, 3);
		world.setBlock(x+4, y+4, z+4, log, meta, 3);
		world.setBlock(x+4, y+4, z+5, log, meta, 3);
		world.setBlock(x+4, y+4, z+6, log, meta, 3);
		world.setBlock(x+4, y+5, z+4, log, meta, 3);
		world.setBlock(x+4, y+5, z+5, log, meta, 3);
		world.setBlock(x+4, y+6, z+3, id, 0, 3);
		world.setBlock(x+4, y+6, z+4, log, meta, 3);
		world.setBlock(x+4, y+6, z+5, log, meta, 3);
		world.setBlock(x+4, y+6, z+6, id, 0, 3);
		world.setBlock(x+4, y+7, z+2, id, 0, 3);
		world.setBlock(x+4, y+7, z+3, id, 0, 3);
		world.setBlock(x+4, y+7, z+4, log, meta, 3);
		world.setBlock(x+4, y+7, z+5, log, meta, 3);
		world.setBlock(x+4, y+7, z+6, id, 0, 3);
		world.setBlock(x+4, y+7, z+7, id, 0, 3);
		world.setBlock(x+4, y+8, z+1, id, 0, 3);
		world.setBlock(x+4, y+8, z+2, id, 0, 3);
		world.setBlock(x+4, y+8, z+3, id, 0, 3);
		world.setBlock(x+4, y+8, z+4, log, meta, 3);
		world.setBlock(x+4, y+8, z+5, log, meta, 3);
		world.setBlock(x+4, y+8, z+6, id, 0, 3);
		world.setBlock(x+4, y+8, z+7, id, 0, 3);
		world.setBlock(x+4, y+8, z+8, id, 0, 3);
		world.setBlock(x+4, y+9, z+1, id, 0, 3);
		world.setBlock(x+4, y+9, z+2, id, 0, 3);
		world.setBlock(x+4, y+9, z+3, id, 0, 3);
		world.setBlock(x+4, y+9, z+4, log, meta, 3);
		world.setBlock(x+4, y+9, z+5, log, meta, 3);
		world.setBlock(x+4, y+9, z+6, id, 0, 3);
		world.setBlock(x+4, y+9, z+7, id, 0, 3);
		world.setBlock(x+4, y+9, z+8, id, 0, 3);
		world.setBlock(x+4, y+10, z, id, 0, 3);
		world.setBlock(x+4, y+10, z+1, id, 0, 3);
		world.setBlock(x+4, y+10, z+2, id, 0, 3);
		world.setBlock(x+4, y+10, z+3, id, 0, 3);
		world.setBlock(x+4, y+10, z+4, log, meta, 3);
		world.setBlock(x+4, y+10, z+5, log, meta, 3);
		world.setBlock(x+4, y+10, z+6, id, 0, 3);
		world.setBlock(x+4, y+10, z+7, id, 0, 3);
		world.setBlock(x+4, y+10, z+8, id, 0, 3);
		world.setBlock(x+4, y+10, z+9, id, 0, 3);
		world.setBlock(x+4, y+11, z, id, 0, 3);
		world.setBlock(x+4, y+11, z+1, log, meta3, 3);
		world.setBlock(x+4, y+11, z+2, log, meta3, 3);
		world.setBlock(x+4, y+11, z+3, log, meta3, 3);
		world.setBlock(x+4, y+11, z+4, log, meta, 3);
		world.setBlock(x+4, y+11, z+5, log, meta, 3);
		world.setBlock(x+4, y+11, z+6, log, meta3, 3);
		world.setBlock(x+4, y+11, z+7, log, meta3, 3);
		world.setBlock(x+4, y+11, z+8, log, meta3, 3);
		world.setBlock(x+4, y+11, z+9, id, 0, 3);
		world.setBlock(x+4, y+12, z, id, 0, 3);
		world.setBlock(x+4, y+12, z+1, id, 0, 3);
		world.setBlock(x+4, y+12, z+2, id, 0, 3);
		world.setBlock(x+4, y+12, z+3, id, 0, 3);
		world.setBlock(x+4, y+12, z+4, log, meta, 3);
		world.setBlock(x+4, y+12, z+5, log, meta, 3);
		world.setBlock(x+4, y+12, z+6, id, 0, 3);
		world.setBlock(x+4, y+12, z+7, id, 0, 3);
		world.setBlock(x+4, y+12, z+8, id, 0, 3);
		world.setBlock(x+4, y+12, z+9, id, 0, 3);
		world.setBlock(x+4, y+13, z, id, 0, 3);
		world.setBlock(x+4, y+13, z+1, id, 0, 3);
		world.setBlock(x+4, y+13, z+2, id, 0, 3);
		world.setBlock(x+4, y+13, z+3, id, 0, 3);
		world.setBlock(x+4, y+13, z+4, log, meta, 3);
		world.setBlock(x+4, y+13, z+5, log, meta, 3);
		world.setBlock(x+4, y+13, z+6, id, 0, 3);
		world.setBlock(x+4, y+13, z+7, id, 0, 3);
		world.setBlock(x+4, y+13, z+8, id, 0, 3);
		world.setBlock(x+4, y+13, z+9, id, 0, 3);
		world.setBlock(x+4, y+14, z, id, 0, 3);
		world.setBlock(x+4, y+14, z+1, id, 0, 3);
		world.setBlock(x+4, y+14, z+2, id, 0, 3);
		world.setBlock(x+4, y+14, z+3, id, 0, 3);
		world.setBlock(x+4, y+14, z+4, log, meta, 3);
		world.setBlock(x+4, y+14, z+5, log, meta, 3);
		world.setBlock(x+4, y+14, z+6, id, 0, 3);
		world.setBlock(x+4, y+14, z+7, id, 0, 3);
		world.setBlock(x+4, y+14, z+8, id, 0, 3);
		world.setBlock(x+4, y+14, z+9, id, 0, 3);
		world.setBlock(x+4, y+15, z, id, 0, 3);
		world.setBlock(x+4, y+15, z+1, id, 0, 3);
		world.setBlock(x+4, y+15, z+2, id, 0, 3);
		world.setBlock(x+4, y+15, z+3, id, 0, 3);
		world.setBlock(x+4, y+15, z+4, log, meta, 3);
		world.setBlock(x+4, y+15, z+5, log, meta, 3);
		world.setBlock(x+4, y+15, z+6, id, 0, 3);
		world.setBlock(x+4, y+15, z+7, id, 0, 3);
		world.setBlock(x+4, y+15, z+8, id, 0, 3);
		world.setBlock(x+4, y+15, z+9, id, 0, 3);
		world.setBlock(x+4, y+16, z, id, 0, 3);
		world.setBlock(x+4, y+16, z+1, log, meta3, 3);
		world.setBlock(x+4, y+16, z+2, log, meta3, 3);
		world.setBlock(x+4, y+16, z+3, log, meta3, 3);
		world.setBlock(x+4, y+16, z+4, log, meta, 3);
		world.setBlock(x+4, y+16, z+5, log, meta, 3);
		world.setBlock(x+4, y+16, z+6, log, meta3, 3);
		world.setBlock(x+4, y+16, z+7, log, meta3, 3);
		world.setBlock(x+4, y+16, z+8, log, meta3, 3);
		world.setBlock(x+4, y+16, z+9, id, 0, 3);
		world.setBlock(x+4, y+17, z, id, 0, 3);
		world.setBlock(x+4, y+17, z+1, id, 0, 3);
		world.setBlock(x+4, y+17, z+2, id, 0, 3);
		world.setBlock(x+4, y+17, z+3, id, 0, 3);
		world.setBlock(x+4, y+17, z+4, log, meta, 3);
		world.setBlock(x+4, y+17, z+5, log, meta, 3);
		world.setBlock(x+4, y+17, z+6, id, 0, 3);
		world.setBlock(x+4, y+17, z+7, id, 0, 3);
		world.setBlock(x+4, y+17, z+8, id, 0, 3);
		world.setBlock(x+4, y+17, z+9, id, 0, 3);
		world.setBlock(x+4, y+18, z+1, id, 0, 3);
		world.setBlock(x+4, y+18, z+2, id, 0, 3);
		world.setBlock(x+4, y+18, z+3, id, 0, 3);
		world.setBlock(x+4, y+18, z+4, log, meta, 3);
		world.setBlock(x+4, y+18, z+5, log, meta, 3);
		world.setBlock(x+4, y+18, z+6, id, 0, 3);
		world.setBlock(x+4, y+18, z+7, id, 0, 3);
		world.setBlock(x+4, y+18, z+8, id, 0, 3);
		world.setBlock(x+4, y+19, z+1, id, 0, 3);
		world.setBlock(x+4, y+19, z+2, id, 0, 3);
		world.setBlock(x+4, y+19, z+3, id, 0, 3);
		world.setBlock(x+4, y+19, z+4, log, meta, 3);
		world.setBlock(x+4, y+19, z+5, log, meta, 3);
		world.setBlock(x+4, y+19, z+6, id, 0, 3);
		world.setBlock(x+4, y+19, z+7, id, 0, 3);
		world.setBlock(x+4, y+19, z+8, id, 0, 3);
		world.setBlock(x+4, y+20, z+1, id, 0, 3);
		world.setBlock(x+4, y+20, z+2, id, 0, 3);
		world.setBlock(x+4, y+20, z+3, id, 0, 3);
		world.setBlock(x+4, y+20, z+4, log, meta, 3);
		world.setBlock(x+4, y+20, z+5, log, meta, 3);
		world.setBlock(x+4, y+20, z+6, id, 0, 3);
		world.setBlock(x+4, y+20, z+7, id, 0, 3);
		world.setBlock(x+4, y+20, z+8, id, 0, 3);
		world.setBlock(x+4, y+21, z+2, id, 0, 3);
		world.setBlock(x+4, y+21, z+3, id, 0, 3);
		world.setBlock(x+4, y+21, z+4, log, meta, 3);
		world.setBlock(x+4, y+21, z+5, log, meta, 3);
		world.setBlock(x+4, y+21, z+6, id, 0, 3);
		world.setBlock(x+4, y+21, z+7, id, 0, 3);
		world.setBlock(x+4, y+22, z+2, id, 0, 3);
		world.setBlock(x+4, y+22, z+3, id, 0, 3);
		world.setBlock(x+4, y+22, z+4, log, meta, 3);
		world.setBlock(x+4, y+22, z+5, log, meta, 3);
		world.setBlock(x+4, y+22, z+6, id, 0, 3);
		world.setBlock(x+4, y+22, z+7, id, 0, 3);
		world.setBlock(x+4, y+23, z+2, id, 0, 3);
		world.setBlock(x+4, y+23, z+3, id, 0, 3);
		world.setBlock(x+4, y+23, z+4, log, meta, 3);
		world.setBlock(x+4, y+23, z+5, log, meta, 3);
		world.setBlock(x+4, y+23, z+6, id, 0, 3);
		world.setBlock(x+4, y+23, z+7, id, 0, 3);
		world.setBlock(x+4, y+24, z+2, id, 0, 3);
		world.setBlock(x+4, y+24, z+3, id, 0, 3);
		world.setBlock(x+4, y+24, z+4, log, meta, 3);
		world.setBlock(x+4, y+24, z+5, log, meta, 3);
		world.setBlock(x+4, y+24, z+6, id, 0, 3);
		world.setBlock(x+4, y+24, z+7, id, 0, 3);
		world.setBlock(x+4, y+25, z+3, id, 0, 3);
		world.setBlock(x+4, y+25, z+4, log, meta, 3);
		world.setBlock(x+4, y+25, z+5, log, meta, 3);
		world.setBlock(x+4, y+25, z+6, id, 0, 3);
		world.setBlock(x+4, y+26, z+3, id, 0, 3);
		world.setBlock(x+4, y+26, z+4, log, meta, 3);
		world.setBlock(x+4, y+26, z+5, log, meta, 3);
		world.setBlock(x+4, y+26, z+6, id, 0, 3);
		world.setBlock(x+4, y+27, z+3, id, 0, 3);
		world.setBlock(x+4, y+27, z+4, id, 0, 3);
		world.setBlock(x+4, y+27, z+5, id, 0, 3);
		world.setBlock(x+4, y+27, z+6, id, 0, 3);
		world.setBlock(x+4, y+28, z+4, id, 0, 3);
		world.setBlock(x+4, y+28, z+5, id, 0, 3);
		world.setBlock(x+4, y+29, z+4, id, 0, 3);
		world.setBlock(x+4, y+29, z+5, id, 0, 3);
		world.setBlock(x+4, y+30, z+4, id, 2, 3);
		world.setBlock(x+4, y+30, z+5, id, 0, 3);

		world.setBlock(x+5, y - 1, z+4, log, meta, 3);
		world.setBlock(x+5, y - 1, z+5, log, meta, 3);

		world.setBlock(x+5, y, z+4, log, meta, 3);
		world.setBlock(x+5, y, z+5, log, meta, 3);

		world.setBlock(x+5, y+1, z+3, log, meta, 3);
		world.setBlock(x+5, y+1, z+4, log, meta, 3);
		world.setBlock(x+5, y+1, z+5, log, meta, 3);
		world.setBlock(x+5, y+1, z+6, log, meta, 3);

		world.setBlock(x+5, y+2, z+2, log, meta3, 3);
		world.setBlock(x+5, y+2, z+3, log, meta, 3);
		world.setBlock(x+5, y+2, z+4, log, meta, 3);
		world.setBlock(x+5, y+2, z+5, log, meta, 3);
		world.setBlock(x+5, y+2, z+6, log, meta, 3);
		world.setBlock(x+5, y+2, z+7, log, meta3, 3);
		world.setBlock(x+5, y+3, z+3, log, meta, 3);
		world.setBlock(x+5, y+3, z+4, log, meta, 3);
		world.setBlock(x+5, y+3, z+5, log, meta, 3);
		world.setBlock(x+5, y+3, z+6, log, meta, 3);
		world.setBlock(x+5, y+4, z+3, log, meta, 3);
		world.setBlock(x+5, y+4, z+4, log, meta, 3);
		world.setBlock(x+5, y+4, z+5, log, meta, 3);
		world.setBlock(x+5, y+4, z+6, log, meta, 3);
		world.setBlock(x+5, y+5, z+4, log, meta, 3);
		world.setBlock(x+5, y+5, z+5, log, meta, 3);
		world.setBlock(x+5, y+6, z+3, id, 0, 3);
		world.setBlock(x+5, y+6, z+4, log, meta, 3);
		world.setBlock(x+5, y+6, z+5, log, meta, 3);
		world.setBlock(x+5, y+6, z+6, id, 0, 3);
		world.setBlock(x+5, y+7, z+2, id, 0, 3);
		world.setBlock(x+5, y+7, z+3, id, 0, 3);
		world.setBlock(x+5, y+7, z+4, log, meta, 3);
		world.setBlock(x+5, y+7, z+5, log, meta, 3);
		world.setBlock(x+5, y+7, z+6, id, 0, 3);
		world.setBlock(x+5, y+7, z+7, id, 0, 3);
		world.setBlock(x+5, y+8, z+1, id, 0, 3);
		world.setBlock(x+5, y+8, z+2, id, 0, 3);
		world.setBlock(x+5, y+8, z+3, id, 0, 3);
		world.setBlock(x+5, y+8, z+4, log, meta, 3);
		world.setBlock(x+5, y+8, z+5, log, meta, 3);
		world.setBlock(x+5, y+8, z+6, id, 0, 3);
		world.setBlock(x+5, y+8, z+7, id, 0, 3);
		world.setBlock(x+5, y+8, z+8, id, 0, 3);
		world.setBlock(x+5, y+9, z+1, id, 0, 3);
		world.setBlock(x+5, y+9, z+2, id, 0, 3);
		world.setBlock(x+5, y+9, z+3, id, 0, 3);
		world.setBlock(x+5, y+9, z+4, log, meta, 3);
		world.setBlock(x+5, y+9, z+5, log, meta, 3);
		world.setBlock(x+5, y+9, z+6, id, 0, 3);
		world.setBlock(x+5, y+9, z+7, id, 0, 3);
		world.setBlock(x+5, y+9, z+8, id, 0, 3);
		world.setBlock(x+5, y+10, z, id, 0, 3);
		world.setBlock(x+5, y+10, z+1, id, 0, 3);
		world.setBlock(x+5, y+10, z+2, id, 0, 3);
		world.setBlock(x+5, y+10, z+3, id, 0, 3);
		world.setBlock(x+5, y+10, z+4, log, meta, 3);
		world.setBlock(x+5, y+10, z+5, log, meta, 3);
		world.setBlock(x+5, y+10, z+6, id, 0, 3);
		world.setBlock(x+5, y+10, z+7, id, 0, 3);
		world.setBlock(x+5, y+10, z+8, id, 0, 3);
		world.setBlock(x+5, y+10, z+9, id, 0, 3);
		world.setBlock(x+5, y+11, z, id, 0, 3);
		world.setBlock(x+5, y+11, z+1, log, meta3, 3);
		world.setBlock(x+5, y+11, z+2, log, meta3, 3);
		world.setBlock(x+5, y+11, z+3, log, meta3, 3);
		world.setBlock(x+5, y+11, z+4, log, meta, 3);
		world.setBlock(x+5, y+11, z+5, log, meta, 3);
		world.setBlock(x+5, y+11, z+6, log, meta3, 3);
		world.setBlock(x+5, y+11, z+7, log, meta3, 3);
		world.setBlock(x+5, y+11, z+8, log, meta3, 3);
		world.setBlock(x+5, y+11, z+9, id, 0, 3);
		world.setBlock(x+5, y+12, z, id, 0, 3);
		world.setBlock(x+5, y+12, z+1, id, 0, 3);
		world.setBlock(x+5, y+12, z+2, id, 0, 3);
		world.setBlock(x+5, y+12, z+3, id, 0, 3);
		world.setBlock(x+5, y+12, z+4, log, meta, 3);
		world.setBlock(x+5, y+12, z+5, log, meta, 3);
		world.setBlock(x+5, y+12, z+6, id, 0, 3);
		world.setBlock(x+5, y+12, z+7, id, 0, 3);
		world.setBlock(x+5, y+12, z+8, id, 0, 3);
		world.setBlock(x+5, y+12, z+9, id, 0, 3);
		world.setBlock(x+5, y+13, z, id, 0, 3);
		world.setBlock(x+5, y+13, z+1, id, 0, 3);
		world.setBlock(x+5, y+13, z+2, id, 0, 3);
		world.setBlock(x+5, y+13, z+3, id, 0, 3);
		world.setBlock(x+5, y+13, z+4, log, meta, 3);
		world.setBlock(x+5, y+13, z+5, log, meta, 3);
		world.setBlock(x+5, y+13, z+6, id, 0, 3);
		world.setBlock(x+5, y+13, z+7, id, 0, 3);
		world.setBlock(x+5, y+13, z+8, id, 0, 3);
		world.setBlock(x+5, y+13, z+9, id, 0, 3);
		world.setBlock(x+5, y+14, z, id, 0, 3);
		world.setBlock(x+5, y+14, z+1, id, 0, 3);
		world.setBlock(x+5, y+14, z+2, id, 0, 3);
		world.setBlock(x+5, y+14, z+3, id, 0, 3);
		world.setBlock(x+5, y+14, z+4, log, meta, 3);
		world.setBlock(x+5, y+14, z+5, log, meta, 3);
		world.setBlock(x+5, y+14, z+6, id, 0, 3);
		world.setBlock(x+5, y+14, z+7, id, 0, 3);
		world.setBlock(x+5, y+14, z+8, id, 0, 3);
		world.setBlock(x+5, y+14, z+9, id, 0, 3);
		world.setBlock(x+5, y+15, z, id, 0, 3);
		world.setBlock(x+5, y+15, z+1, id, 0, 3);
		world.setBlock(x+5, y+15, z+2, id, 0, 3);
		world.setBlock(x+5, y+15, z+3, id, 0, 3);
		world.setBlock(x+5, y+15, z+4, log, meta, 3);
		world.setBlock(x+5, y+15, z+5, log, meta, 3);
		world.setBlock(x+5, y+15, z+6, id, 0, 3);
		world.setBlock(x+5, y+15, z+7, id, 0, 3);
		world.setBlock(x+5, y+15, z+8, id, 0, 3);
		world.setBlock(x+5, y+15, z+9, id, 0, 3);
		world.setBlock(x+5, y+16, z, id, 0, 3);
		world.setBlock(x+5, y+16, z+1, log, meta3, 3);
		world.setBlock(x+5, y+16, z+2, log, meta3, 3);
		world.setBlock(x+5, y+16, z+3, log, meta3, 3);
		world.setBlock(x+5, y+16, z+4, log, meta, 3);
		world.setBlock(x+5, y+16, z+5, log, meta, 3);
		world.setBlock(x+5, y+16, z+6, log, meta3, 3);
		world.setBlock(x+5, y+16, z+7, log, meta3, 3);
		world.setBlock(x+5, y+16, z+8, log, meta3, 3);
		world.setBlock(x+5, y+16, z+9, id, 0, 3);
		world.setBlock(x+5, y+17, z, id, 0, 3);
		world.setBlock(x+5, y+17, z+1, id, 0, 3);
		world.setBlock(x+5, y+17, z+2, id, 0, 3);
		world.setBlock(x+5, y+17, z+3, id, 0, 3);
		world.setBlock(x+5, y+17, z+4, log, meta, 3);
		world.setBlock(x+5, y+17, z+5, log, meta, 3);
		world.setBlock(x+5, y+17, z+6, id, 0, 3);
		world.setBlock(x+5, y+17, z+7, id, 0, 3);
		world.setBlock(x+5, y+17, z+8, id, 0, 3);
		world.setBlock(x+5, y+17, z+9, id, 0, 3);
		world.setBlock(x+5, y+18, z+1, id, 0, 3);
		world.setBlock(x+5, y+18, z+2, id, 0, 3);
		world.setBlock(x+5, y+18, z+3, id, 0, 3);
		world.setBlock(x+5, y+18, z+4, log, meta, 3);
		world.setBlock(x+5, y+18, z+5, log, meta, 3);
		world.setBlock(x+5, y+18, z+6, id, 0, 3);
		world.setBlock(x+5, y+18, z+7, id, 0, 3);
		world.setBlock(x+5, y+18, z+8, id, 0, 3);
		world.setBlock(x+5, y+19, z+1, id, 0, 3);
		world.setBlock(x+5, y+19, z+2, id, 0, 3);
		world.setBlock(x+5, y+19, z+3, id, 0, 3);
		world.setBlock(x+5, y+19, z+4, log, meta, 3);
		world.setBlock(x+5, y+19, z+5, log, meta, 3);
		world.setBlock(x+5, y+19, z+6, id, 0, 3);
		world.setBlock(x+5, y+19, z+7, id, 0, 3);
		world.setBlock(x+5, y+19, z+8, id, 0, 3);
		world.setBlock(x+5, y+20, z+1, id, 0, 3);
		world.setBlock(x+5, y+20, z+2, id, 0, 3);
		world.setBlock(x+5, y+20, z+3, id, 0, 3);
		world.setBlock(x+5, y+20, z+4, log, meta, 3);
		world.setBlock(x+5, y+20, z+5, log, meta, 3);
		world.setBlock(x+5, y+20, z+6, id, 0, 3);
		world.setBlock(x+5, y+20, z+7, id, 0, 3);
		world.setBlock(x+5, y+20, z+8, id, 0, 3);
		world.setBlock(x+5, y+21, z+2, id, 0, 3);
		world.setBlock(x+5, y+21, z+3, id, 0, 3);
		world.setBlock(x+5, y+21, z+4, log, meta, 3);
		world.setBlock(x+5, y+21, z+5, log, meta, 3);
		world.setBlock(x+5, y+21, z+6, id, 0, 3);
		world.setBlock(x+5, y+21, z+7, id, 0, 3);
		world.setBlock(x+5, y+22, z+2, id, 0, 3);
		world.setBlock(x+5, y+22, z+3, id, 0, 3);
		world.setBlock(x+5, y+22, z+4, log, meta, 3);
		world.setBlock(x+5, y+22, z+5, log, meta, 3);
		world.setBlock(x+5, y+22, z+6, id, 0, 3);
		world.setBlock(x+5, y+22, z+7, id, 0, 3);
		world.setBlock(x+5, y+23, z+2, id, 0, 3);
		world.setBlock(x+5, y+23, z+3, id, 0, 3);
		world.setBlock(x+5, y+23, z+4, log, meta, 3);
		world.setBlock(x+5, y+23, z+5, log, meta, 3);
		world.setBlock(x+5, y+23, z+6, id, 0, 3);
		world.setBlock(x+5, y+23, z+7, id, 0, 3);
		world.setBlock(x+5, y+24, z+2, id, 0, 3);
		world.setBlock(x+5, y+24, z+3, id, 0, 3);
		world.setBlock(x+5, y+24, z+4, log, meta, 3);
		world.setBlock(x+5, y+24, z+5, log, meta, 3);
		world.setBlock(x+5, y+24, z+6, id, 0, 3);
		world.setBlock(x+5, y+24, z+7, id, 0, 3);
		world.setBlock(x+5, y+25, z+3, id, 0, 3);
		world.setBlock(x+5, y+25, z+4, log, meta, 3);
		world.setBlock(x+5, y+25, z+5, log, meta, 3);
		world.setBlock(x+5, y+25, z+6, id, 0, 3);
		world.setBlock(x+5, y+26, z+3, id, 0, 3);
		world.setBlock(x+5, y+26, z+4, log, meta, 3);
		world.setBlock(x+5, y+26, z+5, log, meta, 3);
		world.setBlock(x+5, y+26, z+6, id, 0, 3);
		world.setBlock(x+5, y+27, z+3, id, 0, 3);
		world.setBlock(x+5, y+27, z+4, id, 0, 3);
		world.setBlock(x+5, y+27, z+5, id, 0, 3);
		world.setBlock(x+5, y+27, z+6, id, 0, 3);
		world.setBlock(x+5, y+28, z+4, id, 0, 3);
		world.setBlock(x+5, y+28, z+5, id, 0, 3);
		world.setBlock(x+5, y+29, z+4, id, 0, 3);
		world.setBlock(x+5, y+29, z+5, id, 0, 3);
		world.setBlock(x+5, y+30, z+4, id, 0, 3);
		world.setBlock(x+5, y+30, z+5, id, 0, 3);

		world.setBlock(x+6, y+1, z+3, log, meta, 3);
		world.setBlock(x+6, y+1, z+4, log, meta, 3);
		world.setBlock(x+6, y+1, z+5, log, meta, 3);
		world.setBlock(x+6, y+1, z+6, log, meta, 3);

		world.setBlock(x+6, y+2, z+3, log, meta, 3);
		world.setBlock(x+6, y+2, z+4, log, meta, 3);
		world.setBlock(x+6, y+2, z+5, log, meta, 3);
		world.setBlock(x+6, y+2, z+6, log, meta, 3);
		world.setBlock(x+6, y+3, z+4, log, meta, 3);
		world.setBlock(x+6, y+3, z+5, log, meta, 3);
		world.setBlock(x+6, y+4, z+4, log, meta, 3);
		world.setBlock(x+6, y+4, z+5, log, meta, 3);
		world.setBlock(x+6, y+6, z+4, id, 0, 3);
		world.setBlock(x+6, y+6, z+5, id, 0, 3);
		world.setBlock(x+6, y+7, z+3, id, 0, 3);
		world.setBlock(x+6, y+7, z+4, id, 0, 3);
		world.setBlock(x+6, y+7, z+5, id, 0, 3);
		world.setBlock(x+6, y+7, z+6, id, 0, 3);
		world.setBlock(x+6, y+8, z+2, id, 0, 3);
		world.setBlock(x+6, y+8, z+3, id, 0, 3);
		world.setBlock(x+6, y+8, z+4, id, 0, 3);
		world.setBlock(x+6, y+8, z+5, id, 0, 3);
		world.setBlock(x+6, y+8, z+6, id, 0, 3);
		world.setBlock(x+6, y+8, z+7, id, 0, 3);
		world.setBlock(x+6, y+9, z+1, id, 0, 3);
		world.setBlock(x+6, y+9, z+2, id, 0, 3);
		world.setBlock(x+6, y+9, z+3, id, 0, 3);
		world.setBlock(x+6, y+9, z+4, id, 0, 3);
		world.setBlock(x+6, y+9, z+5, id, 0, 3);
		world.setBlock(x+6, y+9, z+6, id, 0, 3);
		world.setBlock(x+6, y+9, z+7, id, 0, 3);
		world.setBlock(x+6, y+9, z+8, id, 0, 3);
		world.setBlock(x+6, y+10, z+1, id, 0, 3);
		world.setBlock(x+6, y+10, z+2, id, 0, 3);
		world.setBlock(x+6, y+10, z+3, id, 0, 3);
		world.setBlock(x+6, y+10, z+4, id, 0, 3);
		world.setBlock(x+6, y+10, z+5, id, 0, 3);
		world.setBlock(x+6, y+10, z+6, id, 0, 3);
		world.setBlock(x+6, y+10, z+7, id, 0, 3);
		world.setBlock(x+6, y+10, z+8, id, 0, 3);
		world.setBlock(x+6, y+11, z, id, 0, 3);
		world.setBlock(x+6, y+11, z+1, id, 0, 3);
		world.setBlock(x+6, y+11, z+2, id, 0, 3);
		world.setBlock(x+6, y+11, z+3, id, 0, 3);
		world.setBlock(x+6, y+11, z+4, log, meta2, 3);
		world.setBlock(x+6, y+11, z+5, log, meta2, 3);
		world.setBlock(x+6, y+11, z+6, id, 0, 3);
		world.setBlock(x+6, y+11, z+7, id, 0, 3);
		world.setBlock(x+6, y+11, z+8, id, 0, 3);
		world.setBlock(x+6, y+11, z+9, id, 0, 3);
		world.setBlock(x+6, y+12, z+1, id, 0, 3);
		world.setBlock(x+6, y+12, z+2, id, 0, 3);
		world.setBlock(x+6, y+12, z+3, id, 0, 3);
		world.setBlock(x+6, y+12, z+4, id, 0, 3);
		world.setBlock(x+6, y+12, z+5, id, 0, 3);
		world.setBlock(x+6, y+12, z+6, id, 0, 3);
		world.setBlock(x+6, y+12, z+7, id, 0, 3);
		world.setBlock(x+6, y+12, z+8, id, 0, 3);
		world.setBlock(x+6, y+13, z, id, 0, 3);
		world.setBlock(x+6, y+13, z+1, id, 0, 3);
		world.setBlock(x+6, y+13, z+2, id, 0, 3);
		world.setBlock(x+6, y+13, z+3, id, 0, 3);
		world.setBlock(x+6, y+13, z+4, id, 0, 3);
		world.setBlock(x+6, y+13, z+5, id, 0, 3);
		world.setBlock(x+6, y+13, z+6, id, 0, 3);
		world.setBlock(x+6, y+13, z+7, id, 0, 3);
		world.setBlock(x+6, y+13, z+8, id, 0, 3);
		world.setBlock(x+6, y+13, z+9, id, 0, 3);
		world.setBlock(x+6, y+14, z, id, 0, 3);
		world.setBlock(x+6, y+14, z+1, id, 0, 3);
		world.setBlock(x+6, y+14, z+2, id, 0, 3);
		world.setBlock(x+6, y+14, z+3, id, 0, 3);
		world.setBlock(x+6, y+14, z+4, id, 0, 3);
		world.setBlock(x+6, y+14, z+5, id, 0, 3);
		world.setBlock(x+6, y+14, z+6, id, 0, 3);
		world.setBlock(x+6, y+14, z+7, id, 0, 3);
		world.setBlock(x+6, y+14, z+8, id, 0, 3);
		world.setBlock(x+6, y+14, z+9, id, 0, 3);
		world.setBlock(x+6, y+15, z+1, id, 0, 3);
		world.setBlock(x+6, y+15, z+2, id, 0, 3);
		world.setBlock(x+6, y+15, z+3, id, 0, 3);
		world.setBlock(x+6, y+15, z+4, id, 0, 3);
		world.setBlock(x+6, y+15, z+5, id, 0, 3);
		world.setBlock(x+6, y+15, z+6, id, 0, 3);
		world.setBlock(x+6, y+15, z+7, id, 0, 3);
		world.setBlock(x+6, y+15, z+8, id, 0, 3);
		world.setBlock(x+6, y+16, z, id, 0, 3);
		world.setBlock(x+6, y+16, z+1, id, 0, 3);
		world.setBlock(x+6, y+16, z+2, id, 0, 3);
		world.setBlock(x+6, y+16, z+3, id, 0, 3);
		world.setBlock(x+6, y+16, z+4, log, meta2, 3);
		world.setBlock(x+6, y+16, z+5, log, meta2, 3);
		world.setBlock(x+6, y+16, z+6, id, 0, 3);
		world.setBlock(x+6, y+16, z+7, id, 0, 3);
		world.setBlock(x+6, y+16, z+8, id, 0, 3);
		world.setBlock(x+6, y+16, z+9, id, 0, 3);
		world.setBlock(x+6, y+17, z+1, id, 0, 3);
		world.setBlock(x+6, y+17, z+2, id, 0, 3);
		world.setBlock(x+6, y+17, z+3, id, 0, 3);
		world.setBlock(x+6, y+17, z+4, id, 0, 3);
		world.setBlock(x+6, y+17, z+5, id, 0, 3);
		world.setBlock(x+6, y+17, z+6, id, 0, 3);
		world.setBlock(x+6, y+17, z+7, id, 0, 3);
		world.setBlock(x+6, y+17, z+8, id, 0, 3);
		world.setBlock(x+6, y+18, z+2, id, 0, 3);
		world.setBlock(x+6, y+18, z+3, id, 0, 3);
		world.setBlock(x+6, y+18, z+4, id, 0, 3);
		world.setBlock(x+6, y+18, z+5, id, 0, 3);
		world.setBlock(x+6, y+18, z+6, id, 0, 3);
		world.setBlock(x+6, y+18, z+7, id, 0, 3);
		world.setBlock(x+6, y+19, z+2, id, 0, 3);
		world.setBlock(x+6, y+19, z+3, id, 0, 3);
		world.setBlock(x+6, y+19, z+4, id, 0, 3);
		world.setBlock(x+6, y+19, z+5, id, 0, 3);
		world.setBlock(x+6, y+19, z+6, id, 0, 3);
		world.setBlock(x+6, y+19, z+7, id, 0, 3);
		world.setBlock(x+6, y+20, z+2, id, 0, 3);
		world.setBlock(x+6, y+20, z+3, id, 0, 3);
		world.setBlock(x+6, y+20, z+4, id, 0, 3);
		world.setBlock(x+6, y+20, z+5, id, 0, 3);
		world.setBlock(x+6, y+20, z+6, id, 0, 3);
		world.setBlock(x+6, y+20, z+7, id, 0, 3);
		world.setBlock(x+6, y+21, z+3, id, 0, 3);
		world.setBlock(x+6, y+21, z+4, id, 0, 3);
		world.setBlock(x+6, y+21, z+5, id, 0, 3);
		world.setBlock(x+6, y+21, z+6, id, 0, 3);
		world.setBlock(x+6, y+22, z+3, id, 0, 3);
		world.setBlock(x+6, y+22, z+4, id, 0, 3);
		world.setBlock(x+6, y+22, z+5, id, 0, 3);
		world.setBlock(x+6, y+22, z+6, id, 0, 3);
		world.setBlock(x+6, y+23, z+3, id, 0, 3);
		world.setBlock(x+6, y+23, z+4, id, 0, 3);
		world.setBlock(x+6, y+23, z+5, id, 0, 3);
		world.setBlock(x+6, y+23, z+6, id, 0, 3);
		world.setBlock(x+6, y+24, z+3, id, 0, 3);
		world.setBlock(x+6, y+24, z+4, id, 0, 3);
		world.setBlock(x+6, y+24, z+5, id, 0, 3);
		world.setBlock(x+6, y+24, z+6, id, 0, 3);
		world.setBlock(x+6, y+25, z+4, id, 0, 3);
		world.setBlock(x+6, y+25, z+5, id, 0, 3);
		world.setBlock(x+6, y+26, z+4, id, 0, 3);
		world.setBlock(x+6, y+26, z+5, id, 0, 3);
		world.setBlock(x+6, y+27, z+4, id, 0, 3);
		world.setBlock(x+6, y+27, z+5, id, 0, 3);

		world.setBlock(x+7, y+2, z+4, log, meta2, 3);
		world.setBlock(x+7, y+2, z+5, log, meta2, 3);
		world.setBlock(x+7, y+7, z+4, id, 0, 3);
		world.setBlock(x+7, y+7, z+5, id, 0, 3);
		world.setBlock(x+7, y+8, z+3, id, 0, 3);
		world.setBlock(x+7, y+8, z+4, id, 0, 3);
		world.setBlock(x+7, y+8, z+5, id, 0, 3);
		world.setBlock(x+7, y+8, z+6, id, 0, 3);
		world.setBlock(x+7, y+9, z+2, id, 0, 3);
		world.setBlock(x+7, y+9, z+3, id, 0, 3);
		world.setBlock(x+7, y+9, z+4, id, 0, 3);
		world.setBlock(x+7, y+9, z+5, id, 0, 3);
		world.setBlock(x+7, y+9, z+6, id, 0, 3);
		world.setBlock(x+7, y+9, z+7, id, 0, 3);
		world.setBlock(x+7, y+10, z+2, id, 0, 3);
		world.setBlock(x+7, y+10, z+3, id, 0, 3);
		world.setBlock(x+7, y+10, z+4, id, 0, 3);
		world.setBlock(x+7, y+10, z+5, id, 0, 3);
		world.setBlock(x+7, y+10, z+6, id, 0, 3);
		world.setBlock(x+7, y+10, z+7, id, 0, 3);
		world.setBlock(x+7, y+11, z+1, id, 0, 3);
		world.setBlock(x+7, y+11, z+2, id, 0, 3);
		world.setBlock(x+7, y+11, z+3, id, 0, 3);
		world.setBlock(x+7, y+11, z+4, log, meta2, 3);
		world.setBlock(x+7, y+11, z+5, log, meta2, 3);
		world.setBlock(x+7, y+11, z+6, id, 0, 3);
		world.setBlock(x+7, y+11, z+7, id, 0, 3);
		world.setBlock(x+7, y+11, z+8, id, 0, 3);
		world.setBlock(x+7, y+12, z+2, id, 0, 3);
		world.setBlock(x+7, y+12, z+3, id, 0, 3);
		world.setBlock(x+7, y+12, z+4, id, 0, 3);
		world.setBlock(x+7, y+12, z+5, id, 0, 3);
		world.setBlock(x+7, y+12, z+6, id, 0, 3);
		world.setBlock(x+7, y+12, z+7, id, 0, 3);
		world.setBlock(x+7, y+13, z+1, id, 0, 3);
		world.setBlock(x+7, y+13, z+2, id, 0, 3);
		world.setBlock(x+7, y+13, z+3, id, 0, 3);
		world.setBlock(x+7, y+13, z+4, id, 0, 3);
		world.setBlock(x+7, y+13, z+5, id, 0, 3);
		world.setBlock(x+7, y+13, z+6, id, 0, 3);
		world.setBlock(x+7, y+13, z+7, id, 0, 3);
		world.setBlock(x+7, y+13, z+8, id, 0, 3);
		world.setBlock(x+7, y+14, z+1, id, 0, 3);
		world.setBlock(x+7, y+14, z+2, id, 0, 3);
		world.setBlock(x+7, y+14, z+3, id, 0, 3);
		world.setBlock(x+7, y+14, z+4, id, 0, 3);
		world.setBlock(x+7, y+14, z+5, id, 0, 3);
		world.setBlock(x+7, y+14, z+6, id, 0, 3);
		world.setBlock(x+7, y+14, z+7, id, 0, 3);
		world.setBlock(x+7, y+14, z+8, id, 0, 3);
		world.setBlock(x+7, y+15, z+2, id, 0, 3);
		world.setBlock(x+7, y+15, z+3, id, 0, 3);
		world.setBlock(x+7, y+15, z+4, id, 0, 3);
		world.setBlock(x+7, y+15, z+5, id, 0, 3);
		world.setBlock(x+7, y+15, z+6, id, 0, 3);
		world.setBlock(x+7, y+15, z+7, id, 0, 3);
		world.setBlock(x+7, y+16, z+1, id, 0, 3);
		world.setBlock(x+7, y+16, z+2, id, 0, 3);
		world.setBlock(x+7, y+16, z+3, id, 0, 3);
		world.setBlock(x+7, y+16, z+4, log, meta2, 3);
		world.setBlock(x+7, y+16, z+5, log, meta2, 3);
		world.setBlock(x+7, y+16, z+6, id, 0, 3);
		world.setBlock(x+7, y+16, z+7, id, 0, 3);
		world.setBlock(x+7, y+16, z+8, id, 0, 3);
		world.setBlock(x+7, y+17, z+2, id, 0, 3);
		world.setBlock(x+7, y+17, z+3, id, 0, 3);
		world.setBlock(x+7, y+17, z+4, id, 0, 3);
		world.setBlock(x+7, y+17, z+5, id, 0, 3);
		world.setBlock(x+7, y+17, z+6, id, 0, 3);
		world.setBlock(x+7, y+17, z+7, id, 0, 3);
		world.setBlock(x+7, y+18, z+3, id, 0, 3);
		world.setBlock(x+7, y+18, z+4, id, 0, 3);
		world.setBlock(x+7, y+18, z+5, id, 0, 3);
		world.setBlock(x+7, y+18, z+6, id, 0, 3);
		world.setBlock(x+7, y+19, z+3, id, 0, 3);
		world.setBlock(x+7, y+19, z+4, id, 0, 3);
		world.setBlock(x+7, y+19, z+5, id, 0, 3);
		world.setBlock(x+7, y+19, z+6, id, 0, 3);
		world.setBlock(x+7, y+20, z+3, id, 0, 3);
		world.setBlock(x+7, y+20, z+4, id, 0, 3);
		world.setBlock(x+7, y+20, z+5, id, 0, 3);
		world.setBlock(x+7, y+20, z+6, id, 0, 3);
		world.setBlock(x+7, y+21, z+4, id, 0, 3);
		world.setBlock(x+7, y+21, z+5, id, 0, 3);
		world.setBlock(x+7, y+22, z+4, id, 0, 3);
		world.setBlock(x+7, y+22, z+5, id, 0, 3);
		world.setBlock(x+7, y+23, z+4, id, 0, 3);
		world.setBlock(x+7, y+23, z+5, id, 0, 3);
		world.setBlock(x+7, y+24, z+4, id, 0, 3);
		world.setBlock(x+7, y+24, z+5, id, 0, 3);

		world.setBlock(x+8, y+8, z+4, id, 0, 3);
		world.setBlock(x+8, y+8, z+5, id, 0, 3);
		world.setBlock(x+8, y+9, z+3, id, 0, 3);
		world.setBlock(x+8, y+9, z+4, id, 0, 3);
		world.setBlock(x+8, y+9, z+5, id, 0, 3);
		world.setBlock(x+8, y+9, z+6, id, 0, 3);
		world.setBlock(x+8, y+10, z+3, id, 0, 3);
		world.setBlock(x+8, y+10, z+4, id, 0, 3);
		world.setBlock(x+8, y+10, z+5, id, 0, 3);
		world.setBlock(x+8, y+10, z+6, id, 0, 3);
		world.setBlock(x+8, y+11, z+2, id, 0, 3);
		world.setBlock(x+8, y+11, z+3, id, 0, 3);
		world.setBlock(x+8, y+11, z+4, log, meta2, 3);
		world.setBlock(x+8, y+11, z+5, log, meta2, 3);
		world.setBlock(x+8, y+11, z+6, id, 0, 3);
		world.setBlock(x+8, y+11, z+7, id, 0, 3);
		world.setBlock(x+8, y+12, z+3, id, 0, 3);
		world.setBlock(x+8, y+12, z+4, id, 0, 3);
		world.setBlock(x+8, y+12, z+5, id, 0, 3);
		world.setBlock(x+8, y+12, z+6, id, 0, 3);
		world.setBlock(x+8, y+13, z+1, id, 0, 3);
		world.setBlock(x+8, y+13, z+2, id, 0, 3);
		world.setBlock(x+8, y+13, z+3, id, 0, 3);
		world.setBlock(x+8, y+13, z+4, id, 0, 3);
		world.setBlock(x+8, y+13, z+5, id, 0, 3);
		world.setBlock(x+8, y+13, z+6, id, 0, 3);
		world.setBlock(x+8, y+13, z+7, id, 0, 3);
		world.setBlock(x+8, y+13, z+8, id, 0, 3);
		world.setBlock(x+8, y+14, z+1, id, 0, 3);
		world.setBlock(x+8, y+14, z+2, id, 0, 3);
		world.setBlock(x+8, y+14, z+3, id, 0, 3);
		world.setBlock(x+8, y+14, z+4, id, 0, 3);
		world.setBlock(x+8, y+14, z+5, id, 0, 3);
		world.setBlock(x+8, y+14, z+6, id, 0, 3);
		world.setBlock(x+8, y+14, z+7, id, 0, 3);
		world.setBlock(x+8, y+14, z+8, id, 0, 3);
		world.setBlock(x+8, y+15, z+3, id, 0, 3);
		world.setBlock(x+8, y+15, z+4, id, 0, 3);
		world.setBlock(x+8, y+15, z+5, id, 0, 3);
		world.setBlock(x+8, y+15, z+6, id, 0, 3);
		world.setBlock(x+8, y+16, z+2, id, 0, 3);
		world.setBlock(x+8, y+16, z+3, id, 0, 3);
		world.setBlock(x+8, y+16, z+4, log, meta2, 3);
		world.setBlock(x+8, y+16, z+5, log, meta2, 3);
		world.setBlock(x+8, y+16, z+6, id, 0, 3);
		world.setBlock(x+8, y+16, z+7, id, 0, 3);
		world.setBlock(x+8, y+17, z+3, id, 0, 3);
		world.setBlock(x+8, y+17, z+4, id, 0, 3);
		world.setBlock(x+8, y+17, z+5, id, 0, 3);
		world.setBlock(x+8, y+17, z+6, id, 0, 3);
		world.setBlock(x+8, y+18, z+4, id, 0, 3);
		world.setBlock(x+8, y+18, z+5, id, 0, 3);
		world.setBlock(x+8, y+19, z+4, id, 0, 3);
		world.setBlock(x+8, y+19, z+5, id, 0, 3);
		world.setBlock(x+8, y+20, z+4, id, 0, 3);
		world.setBlock(x+8, y+20, z+5, id, 0, 3);

		world.setBlock(x+9, y+10, z+4, id, 0, 3);
		world.setBlock(x+9, y+10, z+5, id, 0, 3);
		world.setBlock(x+9, y+11, z+3, id, 0, 3);
		world.setBlock(x+9, y+11, z+4, id, 0, 3);
		world.setBlock(x+9, y+11, z+5, id, 0, 3);
		world.setBlock(x+9, y+11, z+6, id, 0, 3);
		world.setBlock(x+9, y+12, z+4, id, 0, 3);
		world.setBlock(x+9, y+12, z+5, id, 0, 3);
		world.setBlock(x+9, y+13, z+3, id, 0, 3);
		world.setBlock(x+9, y+13, z+4, id, 0, 3);
		world.setBlock(x+9, y+13, z+5, id, 0, 3);
		world.setBlock(x+9, y+13, z+6, id, 0, 3);
		world.setBlock(x+9, y+14, z+3, id, 0, 3);
		world.setBlock(x+9, y+14, z+4, id, 0, 3);
		world.setBlock(x+9, y+14, z+5, id, 0, 3);
		world.setBlock(x+9, y+14, z+6, id, 0, 3);
		world.setBlock(x+9, y+15, z+4, id, 0, 3);
		world.setBlock(x+9, y+15, z+5, id, 0, 3);
		world.setBlock(x+9, y+16, z+3, id, 0, 3);
		world.setBlock(x+9, y+16, z+4, id, 0, 3);
		world.setBlock(x+9, y+16, z+5, id, 0, 3);
		world.setBlock(x+9, y+16, z+6, id, 0, 3);
		world.setBlock(x+9, y+17, z+4, id, 0, 3);
		world.setBlock(x+9, y+17, z+5, id, 0, 3);
	}

	public static BlockArray getBlueprint(World world, int x, int y, int z) {
		BlockArray blocks = new BlockArray();

		blocks.addBlockCoordinate(x, y+10, z+4);
		blocks.addBlockCoordinate(x, y+10, z+5);
		blocks.addBlockCoordinate(x, y+11, z+3);
		blocks.addBlockCoordinate(x, y+11, z+4);
		blocks.addBlockCoordinate(x, y+11, z+5);
		blocks.addBlockCoordinate(x, y+11, z+6);
		blocks.addBlockCoordinate(x, y+12, z+4);
		blocks.addBlockCoordinate(x, y+12, z+5);
		blocks.addBlockCoordinate(x, y+13, z+3);
		blocks.addBlockCoordinate(x, y+13, z+4);
		blocks.addBlockCoordinate(x, y+13, z+5);
		blocks.addBlockCoordinate(x, y+13, z+6);
		blocks.addBlockCoordinate(x, y+14, z+3);
		blocks.addBlockCoordinate(x, y+14, z+4);
		blocks.addBlockCoordinate(x, y+14, z+5);
		blocks.addBlockCoordinate(x, y+14, z+6);
		blocks.addBlockCoordinate(x, y+15, z+4);
		blocks.addBlockCoordinate(x, y+15, z+5);
		blocks.addBlockCoordinate(x, y+16, z+3);
		blocks.addBlockCoordinate(x, y+16, z+4);
		blocks.addBlockCoordinate(x, y+16, z+5);
		blocks.addBlockCoordinate(x, y+16, z+6);
		blocks.addBlockCoordinate(x, y+17, z+4);
		blocks.addBlockCoordinate(x, y+17, z+5);

		blocks.addBlockCoordinate(x+1, y+8, z+4);
		blocks.addBlockCoordinate(x+1, y+8, z+5);
		blocks.addBlockCoordinate(x+1, y+9, z+3);
		blocks.addBlockCoordinate(x+1, y+9, z+4);
		blocks.addBlockCoordinate(x+1, y+9, z+5);
		blocks.addBlockCoordinate(x+1, y+9, z+6);
		blocks.addBlockCoordinate(x+1, y+10, z+3);
		blocks.addBlockCoordinate(x+1, y+10, z+4);
		blocks.addBlockCoordinate(x+1, y+10, z+5);
		blocks.addBlockCoordinate(x+1, y+10, z+6);
		blocks.addBlockCoordinate(x+1, y+11, z+2);
		blocks.addBlockCoordinate(x+1, y+11, z+3);
		blocks.addBlockCoordinate(x+1, y+11, z+4);
		blocks.addBlockCoordinate(x+1, y+11, z+5);
		blocks.addBlockCoordinate(x+1, y+11, z+6);
		blocks.addBlockCoordinate(x+1, y+11, z+7);
		blocks.addBlockCoordinate(x+1, y+12, z+3);
		blocks.addBlockCoordinate(x+1, y+12, z+4);
		blocks.addBlockCoordinate(x+1, y+12, z+5);
		blocks.addBlockCoordinate(x+1, y+12, z+6);
		blocks.addBlockCoordinate(x+1, y+13, z+1);
		blocks.addBlockCoordinate(x+1, y+13, z+2);
		blocks.addBlockCoordinate(x+1, y+13, z+3);
		blocks.addBlockCoordinate(x+1, y+13, z+4);
		blocks.addBlockCoordinate(x+1, y+13, z+5);
		blocks.addBlockCoordinate(x+1, y+13, z+6);
		blocks.addBlockCoordinate(x+1, y+13, z+7);
		blocks.addBlockCoordinate(x+1, y+13, z+8);
		blocks.addBlockCoordinate(x+1, y+14, z+1);
		blocks.addBlockCoordinate(x+1, y+14, z+2);
		blocks.addBlockCoordinate(x+1, y+14, z+3);
		blocks.addBlockCoordinate(x+1, y+14, z+4);
		blocks.addBlockCoordinate(x+1, y+14, z+5);
		blocks.addBlockCoordinate(x+1, y+14, z+6);
		blocks.addBlockCoordinate(x+1, y+14, z+7);
		blocks.addBlockCoordinate(x+1, y+14, z+8);
		blocks.addBlockCoordinate(x+1, y+15, z+3);
		blocks.addBlockCoordinate(x+1, y+15, z+4);
		blocks.addBlockCoordinate(x+1, y+15, z+5);
		blocks.addBlockCoordinate(x+1, y+15, z+6);
		blocks.addBlockCoordinate(x+1, y+16, z+2);
		blocks.addBlockCoordinate(x+1, y+16, z+3);
		blocks.addBlockCoordinate(x+1, y+16, z+4);
		blocks.addBlockCoordinate(x+1, y+16, z+5);
		blocks.addBlockCoordinate(x+1, y+16, z+6);
		blocks.addBlockCoordinate(x+1, y+16, z+7);
		blocks.addBlockCoordinate(x+1, y+17, z+3);
		blocks.addBlockCoordinate(x+1, y+17, z+4);
		blocks.addBlockCoordinate(x+1, y+17, z+5);
		blocks.addBlockCoordinate(x+1, y+17, z+6);
		blocks.addBlockCoordinate(x+1, y+18, z+4);
		blocks.addBlockCoordinate(x+1, y+18, z+5);
		blocks.addBlockCoordinate(x+1, y+19, z+4);
		blocks.addBlockCoordinate(x+1, y+19, z+5);
		blocks.addBlockCoordinate(x+1, y+20, z+4);
		blocks.addBlockCoordinate(x+1, y+20, z+5);

		blocks.addBlockCoordinate(x+2, y+2, z+4);
		blocks.addBlockCoordinate(x+2, y+2, z+5);
		blocks.addBlockCoordinate(x+2, y+7, z+4);
		blocks.addBlockCoordinate(x+2, y+7, z+5);
		blocks.addBlockCoordinate(x+2, y+8, z+3);
		blocks.addBlockCoordinate(x+2, y+8, z+4);
		blocks.addBlockCoordinate(x+2, y+8, z+5);
		blocks.addBlockCoordinate(x+2, y+8, z+6);
		blocks.addBlockCoordinate(x+2, y+9, z+2);
		blocks.addBlockCoordinate(x+2, y+9, z+3);
		blocks.addBlockCoordinate(x+2, y+9, z+4);
		blocks.addBlockCoordinate(x+2, y+9, z+5);
		blocks.addBlockCoordinate(x+2, y+9, z+6);
		blocks.addBlockCoordinate(x+2, y+9, z+7);
		blocks.addBlockCoordinate(x+2, y+10, z+2);
		blocks.addBlockCoordinate(x+2, y+10, z+3);
		blocks.addBlockCoordinate(x+2, y+10, z+4);
		blocks.addBlockCoordinate(x+2, y+10, z+5);
		blocks.addBlockCoordinate(x+2, y+10, z+6);
		blocks.addBlockCoordinate(x+2, y+10, z+7);
		blocks.addBlockCoordinate(x+2, y+11, z+1);
		blocks.addBlockCoordinate(x+2, y+11, z+2);
		blocks.addBlockCoordinate(x+2, y+11, z+3);
		blocks.addBlockCoordinate(x+2, y+11, z+4);
		blocks.addBlockCoordinate(x+2, y+11, z+5);
		blocks.addBlockCoordinate(x+2, y+11, z+6);
		blocks.addBlockCoordinate(x+2, y+11, z+7);
		blocks.addBlockCoordinate(x+2, y+11, z+8);
		blocks.addBlockCoordinate(x+2, y+12, z+2);
		blocks.addBlockCoordinate(x+2, y+12, z+3);
		blocks.addBlockCoordinate(x+2, y+12, z+4);
		blocks.addBlockCoordinate(x+2, y+12, z+5);
		blocks.addBlockCoordinate(x+2, y+12, z+6);
		blocks.addBlockCoordinate(x+2, y+12, z+7);
		blocks.addBlockCoordinate(x+2, y+13, z+1);
		blocks.addBlockCoordinate(x+2, y+13, z+2);
		blocks.addBlockCoordinate(x+2, y+13, z+3);
		blocks.addBlockCoordinate(x+2, y+13, z+4);
		blocks.addBlockCoordinate(x+2, y+13, z+5);
		blocks.addBlockCoordinate(x+2, y+13, z+6);
		blocks.addBlockCoordinate(x+2, y+13, z+7);
		blocks.addBlockCoordinate(x+2, y+13, z+8);
		blocks.addBlockCoordinate(x+2, y+14, z+1);
		blocks.addBlockCoordinate(x+2, y+14, z+2);
		blocks.addBlockCoordinate(x+2, y+14, z+3);
		blocks.addBlockCoordinate(x+2, y+14, z+4);
		blocks.addBlockCoordinate(x+2, y+14, z+5);
		blocks.addBlockCoordinate(x+2, y+14, z+6);
		blocks.addBlockCoordinate(x+2, y+14, z+7);
		blocks.addBlockCoordinate(x+2, y+14, z+8);
		blocks.addBlockCoordinate(x+2, y+15, z+2);
		blocks.addBlockCoordinate(x+2, y+15, z+3);
		blocks.addBlockCoordinate(x+2, y+15, z+4);
		blocks.addBlockCoordinate(x+2, y+15, z+5);
		blocks.addBlockCoordinate(x+2, y+15, z+6);
		blocks.addBlockCoordinate(x+2, y+15, z+7);
		blocks.addBlockCoordinate(x+2, y+16, z+1);
		blocks.addBlockCoordinate(x+2, y+16, z+2);
		blocks.addBlockCoordinate(x+2, y+16, z+3);
		blocks.addBlockCoordinate(x+2, y+16, z+4);
		blocks.addBlockCoordinate(x+2, y+16, z+5);
		blocks.addBlockCoordinate(x+2, y+16, z+6);
		blocks.addBlockCoordinate(x+2, y+16, z+7);
		blocks.addBlockCoordinate(x+2, y+16, z+8);
		blocks.addBlockCoordinate(x+2, y+17, z+2);
		blocks.addBlockCoordinate(x+2, y+17, z+3);
		blocks.addBlockCoordinate(x+2, y+17, z+4);
		blocks.addBlockCoordinate(x+2, y+17, z+5);
		blocks.addBlockCoordinate(x+2, y+17, z+6);
		blocks.addBlockCoordinate(x+2, y+17, z+7);
		blocks.addBlockCoordinate(x+2, y+18, z+3);
		blocks.addBlockCoordinate(x+2, y+18, z+4);
		blocks.addBlockCoordinate(x+2, y+18, z+5);
		blocks.addBlockCoordinate(x+2, y+18, z+6);
		blocks.addBlockCoordinate(x+2, y+19, z+3);
		blocks.addBlockCoordinate(x+2, y+19, z+4);
		blocks.addBlockCoordinate(x+2, y+19, z+5);
		blocks.addBlockCoordinate(x+2, y+19, z+6);
		blocks.addBlockCoordinate(x+2, y+20, z+3);
		blocks.addBlockCoordinate(x+2, y+20, z+4);
		blocks.addBlockCoordinate(x+2, y+20, z+5);
		blocks.addBlockCoordinate(x+2, y+20, z+6);
		blocks.addBlockCoordinate(x+2, y+21, z+4);
		blocks.addBlockCoordinate(x+2, y+21, z+5);
		blocks.addBlockCoordinate(x+2, y+22, z+4);
		blocks.addBlockCoordinate(x+2, y+22, z+5);
		blocks.addBlockCoordinate(x+2, y+23, z+4);
		blocks.addBlockCoordinate(x+2, y+23, z+5);
		blocks.addBlockCoordinate(x+2, y+24, z+4);
		blocks.addBlockCoordinate(x+2, y+24, z+5);

		blocks.addBlockCoordinate(x+3, y+2, z+3);
		blocks.addBlockCoordinate(x+3, y+2, z+4);
		blocks.addBlockCoordinate(x+3, y+2, z+5);
		blocks.addBlockCoordinate(x+3, y+2, z+6);
		blocks.addBlockCoordinate(x+3, y+3, z+4);
		blocks.addBlockCoordinate(x+3, y+3, z+5);
		blocks.addBlockCoordinate(x+3, y+4, z+4);
		blocks.addBlockCoordinate(x+3, y+4, z+5);
		blocks.addBlockCoordinate(x+3, y+6, z+4);
		blocks.addBlockCoordinate(x+3, y+6, z+5);
		blocks.addBlockCoordinate(x+3, y+7, z+3);
		blocks.addBlockCoordinate(x+3, y+7, z+4);
		blocks.addBlockCoordinate(x+3, y+7, z+5);
		blocks.addBlockCoordinate(x+3, y+7, z+6);
		blocks.addBlockCoordinate(x+3, y+8, z+2);
		blocks.addBlockCoordinate(x+3, y+8, z+3);
		blocks.addBlockCoordinate(x+3, y+8, z+4);
		blocks.addBlockCoordinate(x+3, y+8, z+5);
		blocks.addBlockCoordinate(x+3, y+8, z+6);
		blocks.addBlockCoordinate(x+3, y+8, z+7);
		blocks.addBlockCoordinate(x+3, y+9, z+1);
		blocks.addBlockCoordinate(x+3, y+9, z+2);
		blocks.addBlockCoordinate(x+3, y+9, z+3);
		blocks.addBlockCoordinate(x+3, y+9, z+4);
		blocks.addBlockCoordinate(x+3, y+9, z+5);
		blocks.addBlockCoordinate(x+3, y+9, z+6);
		blocks.addBlockCoordinate(x+3, y+9, z+7);
		blocks.addBlockCoordinate(x+3, y+9, z+8);
		blocks.addBlockCoordinate(x+3, y+10, z+1);
		blocks.addBlockCoordinate(x+3, y+10, z+2);
		blocks.addBlockCoordinate(x+3, y+10, z+3);
		blocks.addBlockCoordinate(x+3, y+10, z+4);
		blocks.addBlockCoordinate(x+3, y+10, z+5);
		blocks.addBlockCoordinate(x+3, y+10, z+6);
		blocks.addBlockCoordinate(x+3, y+10, z+7);
		blocks.addBlockCoordinate(x+3, y+10, z+8);
		blocks.addBlockCoordinate(x+3, y+11, z);
		blocks.addBlockCoordinate(x+3, y+11, z+1);
		blocks.addBlockCoordinate(x+3, y+11, z+2);
		blocks.addBlockCoordinate(x+3, y+11, z+3);
		blocks.addBlockCoordinate(x+3, y+11, z+4);
		blocks.addBlockCoordinate(x+3, y+11, z+5);
		blocks.addBlockCoordinate(x+3, y+11, z+6);
		blocks.addBlockCoordinate(x+3, y+11, z+7);
		blocks.addBlockCoordinate(x+3, y+11, z+8);
		blocks.addBlockCoordinate(x+3, y+11, z+9);
		blocks.addBlockCoordinate(x+3, y+12, z+1);
		blocks.addBlockCoordinate(x+3, y+12, z+2);
		blocks.addBlockCoordinate(x+3, y+12, z+3);
		blocks.addBlockCoordinate(x+3, y+12, z+4);
		blocks.addBlockCoordinate(x+3, y+12, z+5);
		blocks.addBlockCoordinate(x+3, y+12, z+6);
		blocks.addBlockCoordinate(x+3, y+12, z+7);
		blocks.addBlockCoordinate(x+3, y+12, z+8);
		blocks.addBlockCoordinate(x+3, y+13, z);
		blocks.addBlockCoordinate(x+3, y+13, z+1);
		blocks.addBlockCoordinate(x+3, y+13, z+2);
		blocks.addBlockCoordinate(x+3, y+13, z+3);
		blocks.addBlockCoordinate(x+3, y+13, z+4);
		blocks.addBlockCoordinate(x+3, y+13, z+5);
		blocks.addBlockCoordinate(x+3, y+13, z+6);
		blocks.addBlockCoordinate(x+3, y+13, z+7);
		blocks.addBlockCoordinate(x+3, y+13, z+8);
		blocks.addBlockCoordinate(x+3, y+13, z+9);
		blocks.addBlockCoordinate(x+3, y+14, z);
		blocks.addBlockCoordinate(x+3, y+14, z+1);
		blocks.addBlockCoordinate(x+3, y+14, z+2);
		blocks.addBlockCoordinate(x+3, y+14, z+3);
		blocks.addBlockCoordinate(x+3, y+14, z+4);
		blocks.addBlockCoordinate(x+3, y+14, z+5);
		blocks.addBlockCoordinate(x+3, y+14, z+6);
		blocks.addBlockCoordinate(x+3, y+14, z+7);
		blocks.addBlockCoordinate(x+3, y+14, z+8);
		blocks.addBlockCoordinate(x+3, y+14, z+9);
		blocks.addBlockCoordinate(x+3, y+15, z+1);
		blocks.addBlockCoordinate(x+3, y+15, z+2);
		blocks.addBlockCoordinate(x+3, y+15, z+3);
		blocks.addBlockCoordinate(x+3, y+15, z+4);
		blocks.addBlockCoordinate(x+3, y+15, z+5);
		blocks.addBlockCoordinate(x+3, y+15, z+6);
		blocks.addBlockCoordinate(x+3, y+15, z+7);
		blocks.addBlockCoordinate(x+3, y+15, z+8);
		blocks.addBlockCoordinate(x+3, y+16, z);
		blocks.addBlockCoordinate(x+3, y+16, z+1);
		blocks.addBlockCoordinate(x+3, y+16, z+2);
		blocks.addBlockCoordinate(x+3, y+16, z+3);
		blocks.addBlockCoordinate(x+3, y+16, z+4);
		blocks.addBlockCoordinate(x+3, y+16, z+5);
		blocks.addBlockCoordinate(x+3, y+16, z+6);
		blocks.addBlockCoordinate(x+3, y+16, z+7);
		blocks.addBlockCoordinate(x+3, y+16, z+8);
		blocks.addBlockCoordinate(x+3, y+16, z+9);
		blocks.addBlockCoordinate(x+3, y+17, z+1);
		blocks.addBlockCoordinate(x+3, y+17, z+2);
		blocks.addBlockCoordinate(x+3, y+17, z+3);
		blocks.addBlockCoordinate(x+3, y+17, z+4);
		blocks.addBlockCoordinate(x+3, y+17, z+5);
		blocks.addBlockCoordinate(x+3, y+17, z+6);
		blocks.addBlockCoordinate(x+3, y+17, z+7);
		blocks.addBlockCoordinate(x+3, y+17, z+8);
		blocks.addBlockCoordinate(x+3, y+18, z+2);
		blocks.addBlockCoordinate(x+3, y+18, z+3);
		blocks.addBlockCoordinate(x+3, y+18, z+4);
		blocks.addBlockCoordinate(x+3, y+18, z+5);
		blocks.addBlockCoordinate(x+3, y+18, z+6);
		blocks.addBlockCoordinate(x+3, y+18, z+7);
		blocks.addBlockCoordinate(x+3, y+19, z+2);
		blocks.addBlockCoordinate(x+3, y+19, z+3);
		blocks.addBlockCoordinate(x+3, y+19, z+4);
		blocks.addBlockCoordinate(x+3, y+19, z+5);
		blocks.addBlockCoordinate(x+3, y+19, z+6);
		blocks.addBlockCoordinate(x+3, y+19, z+7);
		blocks.addBlockCoordinate(x+3, y+20, z+2);
		blocks.addBlockCoordinate(x+3, y+20, z+3);
		blocks.addBlockCoordinate(x+3, y+20, z+4);
		blocks.addBlockCoordinate(x+3, y+20, z+5);
		blocks.addBlockCoordinate(x+3, y+20, z+6);
		blocks.addBlockCoordinate(x+3, y+20, z+7);
		blocks.addBlockCoordinate(x+3, y+21, z+3);
		blocks.addBlockCoordinate(x+3, y+21, z+4);
		blocks.addBlockCoordinate(x+3, y+21, z+5);
		blocks.addBlockCoordinate(x+3, y+21, z+6);
		blocks.addBlockCoordinate(x+3, y+22, z+3);
		blocks.addBlockCoordinate(x+3, y+22, z+4);
		blocks.addBlockCoordinate(x+3, y+22, z+5);
		blocks.addBlockCoordinate(x+3, y+22, z+6);
		blocks.addBlockCoordinate(x+3, y+23, z+3);
		blocks.addBlockCoordinate(x+3, y+23, z+4);
		blocks.addBlockCoordinate(x+3, y+23, z+5);
		blocks.addBlockCoordinate(x+3, y+23, z+6);
		blocks.addBlockCoordinate(x+3, y+24, z+3);
		blocks.addBlockCoordinate(x+3, y+24, z+4);
		blocks.addBlockCoordinate(x+3, y+24, z+5);
		blocks.addBlockCoordinate(x+3, y+24, z+6);
		blocks.addBlockCoordinate(x+3, y+25, z+4);
		blocks.addBlockCoordinate(x+3, y+25, z+5);
		blocks.addBlockCoordinate(x+3, y+26, z+4);
		blocks.addBlockCoordinate(x+3, y+26, z+5);
		blocks.addBlockCoordinate(x+3, y+27, z+4);
		blocks.addBlockCoordinate(x+3, y+27, z+5);

		blocks.addBlockCoordinate(x+4, y+2, z+2);
		blocks.addBlockCoordinate(x+4, y+2, z+3);
		blocks.addBlockCoordinate(x+4, y+2, z+4);
		blocks.addBlockCoordinate(x+4, y+2, z+5);
		blocks.addBlockCoordinate(x+4, y+2, z+6);
		blocks.addBlockCoordinate(x+4, y+2, z+7);
		blocks.addBlockCoordinate(x+4, y+3, z+3);
		blocks.addBlockCoordinate(x+4, y+3, z+4);
		blocks.addBlockCoordinate(x+4, y+3, z+5);
		blocks.addBlockCoordinate(x+4, y+3, z+6);
		blocks.addBlockCoordinate(x+4, y+4, z+3);
		blocks.addBlockCoordinate(x+4, y+4, z+4);
		blocks.addBlockCoordinate(x+4, y+4, z+5);
		blocks.addBlockCoordinate(x+4, y+4, z+6);
		blocks.addBlockCoordinate(x+4, y+5, z+4);
		blocks.addBlockCoordinate(x+4, y+5, z+5);
		blocks.addBlockCoordinate(x+4, y+6, z+3);
		blocks.addBlockCoordinate(x+4, y+6, z+4);
		blocks.addBlockCoordinate(x+4, y+6, z+5);
		blocks.addBlockCoordinate(x+4, y+6, z+6);
		blocks.addBlockCoordinate(x+4, y+7, z+2);
		blocks.addBlockCoordinate(x+4, y+7, z+3);
		blocks.addBlockCoordinate(x+4, y+7, z+4);
		blocks.addBlockCoordinate(x+4, y+7, z+5);
		blocks.addBlockCoordinate(x+4, y+7, z+6);
		blocks.addBlockCoordinate(x+4, y+7, z+7);
		blocks.addBlockCoordinate(x+4, y+8, z+1);
		blocks.addBlockCoordinate(x+4, y+8, z+2);
		blocks.addBlockCoordinate(x+4, y+8, z+3);
		blocks.addBlockCoordinate(x+4, y+8, z+4);
		blocks.addBlockCoordinate(x+4, y+8, z+5);
		blocks.addBlockCoordinate(x+4, y+8, z+6);
		blocks.addBlockCoordinate(x+4, y+8, z+7);
		blocks.addBlockCoordinate(x+4, y+8, z+8);
		blocks.addBlockCoordinate(x+4, y+9, z+1);
		blocks.addBlockCoordinate(x+4, y+9, z+2);
		blocks.addBlockCoordinate(x+4, y+9, z+3);
		blocks.addBlockCoordinate(x+4, y+9, z+4);
		blocks.addBlockCoordinate(x+4, y+9, z+5);
		blocks.addBlockCoordinate(x+4, y+9, z+6);
		blocks.addBlockCoordinate(x+4, y+9, z+7);
		blocks.addBlockCoordinate(x+4, y+9, z+8);
		blocks.addBlockCoordinate(x+4, y+10, z);
		blocks.addBlockCoordinate(x+4, y+10, z+1);
		blocks.addBlockCoordinate(x+4, y+10, z+2);
		blocks.addBlockCoordinate(x+4, y+10, z+3);
		blocks.addBlockCoordinate(x+4, y+10, z+4);
		blocks.addBlockCoordinate(x+4, y+10, z+5);
		blocks.addBlockCoordinate(x+4, y+10, z+6);
		blocks.addBlockCoordinate(x+4, y+10, z+7);
		blocks.addBlockCoordinate(x+4, y+10, z+8);
		blocks.addBlockCoordinate(x+4, y+10, z+9);
		blocks.addBlockCoordinate(x+4, y+11, z);
		blocks.addBlockCoordinate(x+4, y+11, z+1);
		blocks.addBlockCoordinate(x+4, y+11, z+2);
		blocks.addBlockCoordinate(x+4, y+11, z+3);
		blocks.addBlockCoordinate(x+4, y+11, z+4);
		blocks.addBlockCoordinate(x+4, y+11, z+5);
		blocks.addBlockCoordinate(x+4, y+11, z+6);
		blocks.addBlockCoordinate(x+4, y+11, z+7);
		blocks.addBlockCoordinate(x+4, y+11, z+8);
		blocks.addBlockCoordinate(x+4, y+11, z+9);
		blocks.addBlockCoordinate(x+4, y+12, z);
		blocks.addBlockCoordinate(x+4, y+12, z+1);
		blocks.addBlockCoordinate(x+4, y+12, z+2);
		blocks.addBlockCoordinate(x+4, y+12, z+3);
		blocks.addBlockCoordinate(x+4, y+12, z+4);
		blocks.addBlockCoordinate(x+4, y+12, z+5);
		blocks.addBlockCoordinate(x+4, y+12, z+6);
		blocks.addBlockCoordinate(x+4, y+12, z+7);
		blocks.addBlockCoordinate(x+4, y+12, z+8);
		blocks.addBlockCoordinate(x+4, y+12, z+9);
		blocks.addBlockCoordinate(x+4, y+13, z);
		blocks.addBlockCoordinate(x+4, y+13, z+1);
		blocks.addBlockCoordinate(x+4, y+13, z+2);
		blocks.addBlockCoordinate(x+4, y+13, z+3);
		blocks.addBlockCoordinate(x+4, y+13, z+4);
		blocks.addBlockCoordinate(x+4, y+13, z+5);
		blocks.addBlockCoordinate(x+4, y+13, z+6);
		blocks.addBlockCoordinate(x+4, y+13, z+7);
		blocks.addBlockCoordinate(x+4, y+13, z+8);
		blocks.addBlockCoordinate(x+4, y+13, z+9);
		blocks.addBlockCoordinate(x+4, y+14, z);
		blocks.addBlockCoordinate(x+4, y+14, z+1);
		blocks.addBlockCoordinate(x+4, y+14, z+2);
		blocks.addBlockCoordinate(x+4, y+14, z+3);
		blocks.addBlockCoordinate(x+4, y+14, z+4);
		blocks.addBlockCoordinate(x+4, y+14, z+5);
		blocks.addBlockCoordinate(x+4, y+14, z+6);
		blocks.addBlockCoordinate(x+4, y+14, z+7);
		blocks.addBlockCoordinate(x+4, y+14, z+8);
		blocks.addBlockCoordinate(x+4, y+14, z+9);
		blocks.addBlockCoordinate(x+4, y+15, z);
		blocks.addBlockCoordinate(x+4, y+15, z+1);
		blocks.addBlockCoordinate(x+4, y+15, z+2);
		blocks.addBlockCoordinate(x+4, y+15, z+3);
		blocks.addBlockCoordinate(x+4, y+15, z+4);
		blocks.addBlockCoordinate(x+4, y+15, z+5);
		blocks.addBlockCoordinate(x+4, y+15, z+6);
		blocks.addBlockCoordinate(x+4, y+15, z+7);
		blocks.addBlockCoordinate(x+4, y+15, z+8);
		blocks.addBlockCoordinate(x+4, y+15, z+9);
		blocks.addBlockCoordinate(x+4, y+16, z);
		blocks.addBlockCoordinate(x+4, y+16, z+1);
		blocks.addBlockCoordinate(x+4, y+16, z+2);
		blocks.addBlockCoordinate(x+4, y+16, z+3);
		blocks.addBlockCoordinate(x+4, y+16, z+4);
		blocks.addBlockCoordinate(x+4, y+16, z+5);
		blocks.addBlockCoordinate(x+4, y+16, z+6);
		blocks.addBlockCoordinate(x+4, y+16, z+7);
		blocks.addBlockCoordinate(x+4, y+16, z+8);
		blocks.addBlockCoordinate(x+4, y+16, z+9);
		blocks.addBlockCoordinate(x+4, y+17, z);
		blocks.addBlockCoordinate(x+4, y+17, z+1);
		blocks.addBlockCoordinate(x+4, y+17, z+2);
		blocks.addBlockCoordinate(x+4, y+17, z+3);
		blocks.addBlockCoordinate(x+4, y+17, z+4);
		blocks.addBlockCoordinate(x+4, y+17, z+5);
		blocks.addBlockCoordinate(x+4, y+17, z+6);
		blocks.addBlockCoordinate(x+4, y+17, z+7);
		blocks.addBlockCoordinate(x+4, y+17, z+8);
		blocks.addBlockCoordinate(x+4, y+17, z+9);
		blocks.addBlockCoordinate(x+4, y+18, z+1);
		blocks.addBlockCoordinate(x+4, y+18, z+2);
		blocks.addBlockCoordinate(x+4, y+18, z+3);
		blocks.addBlockCoordinate(x+4, y+18, z+4);
		blocks.addBlockCoordinate(x+4, y+18, z+5);
		blocks.addBlockCoordinate(x+4, y+18, z+6);
		blocks.addBlockCoordinate(x+4, y+18, z+7);
		blocks.addBlockCoordinate(x+4, y+18, z+8);
		blocks.addBlockCoordinate(x+4, y+19, z+1);
		blocks.addBlockCoordinate(x+4, y+19, z+2);
		blocks.addBlockCoordinate(x+4, y+19, z+3);
		blocks.addBlockCoordinate(x+4, y+19, z+4);
		blocks.addBlockCoordinate(x+4, y+19, z+5);
		blocks.addBlockCoordinate(x+4, y+19, z+6);
		blocks.addBlockCoordinate(x+4, y+19, z+7);
		blocks.addBlockCoordinate(x+4, y+19, z+8);
		blocks.addBlockCoordinate(x+4, y+20, z+1);
		blocks.addBlockCoordinate(x+4, y+20, z+2);
		blocks.addBlockCoordinate(x+4, y+20, z+3);
		blocks.addBlockCoordinate(x+4, y+20, z+4);
		blocks.addBlockCoordinate(x+4, y+20, z+5);
		blocks.addBlockCoordinate(x+4, y+20, z+6);
		blocks.addBlockCoordinate(x+4, y+20, z+7);
		blocks.addBlockCoordinate(x+4, y+20, z+8);
		blocks.addBlockCoordinate(x+4, y+21, z+2);
		blocks.addBlockCoordinate(x+4, y+21, z+3);
		blocks.addBlockCoordinate(x+4, y+21, z+4);
		blocks.addBlockCoordinate(x+4, y+21, z+5);
		blocks.addBlockCoordinate(x+4, y+21, z+6);
		blocks.addBlockCoordinate(x+4, y+21, z+7);
		blocks.addBlockCoordinate(x+4, y+22, z+2);
		blocks.addBlockCoordinate(x+4, y+22, z+3);
		blocks.addBlockCoordinate(x+4, y+22, z+4);
		blocks.addBlockCoordinate(x+4, y+22, z+5);
		blocks.addBlockCoordinate(x+4, y+22, z+6);
		blocks.addBlockCoordinate(x+4, y+22, z+7);
		blocks.addBlockCoordinate(x+4, y+23, z+2);
		blocks.addBlockCoordinate(x+4, y+23, z+3);
		blocks.addBlockCoordinate(x+4, y+23, z+4);
		blocks.addBlockCoordinate(x+4, y+23, z+5);
		blocks.addBlockCoordinate(x+4, y+23, z+6);
		blocks.addBlockCoordinate(x+4, y+23, z+7);
		blocks.addBlockCoordinate(x+4, y+24, z+2);
		blocks.addBlockCoordinate(x+4, y+24, z+3);
		blocks.addBlockCoordinate(x+4, y+24, z+4);
		blocks.addBlockCoordinate(x+4, y+24, z+5);
		blocks.addBlockCoordinate(x+4, y+24, z+6);
		blocks.addBlockCoordinate(x+4, y+24, z+7);
		blocks.addBlockCoordinate(x+4, y+25, z+3);
		blocks.addBlockCoordinate(x+4, y+25, z+4);
		blocks.addBlockCoordinate(x+4, y+25, z+5);
		blocks.addBlockCoordinate(x+4, y+25, z+6);
		blocks.addBlockCoordinate(x+4, y+26, z+3);
		blocks.addBlockCoordinate(x+4, y+26, z+4);
		blocks.addBlockCoordinate(x+4, y+26, z+5);
		blocks.addBlockCoordinate(x+4, y+26, z+6);
		blocks.addBlockCoordinate(x+4, y+27, z+3);
		blocks.addBlockCoordinate(x+4, y+27, z+4);
		blocks.addBlockCoordinate(x+4, y+27, z+5);
		blocks.addBlockCoordinate(x+4, y+27, z+6);
		blocks.addBlockCoordinate(x+4, y+28, z+4);
		blocks.addBlockCoordinate(x+4, y+28, z+5);
		blocks.addBlockCoordinate(x+4, y+29, z+4);
		blocks.addBlockCoordinate(x+4, y+29, z+5);
		blocks.addBlockCoordinate(x+4, y+30, z+4);
		blocks.addBlockCoordinate(x+4, y+30, z+5);

		blocks.addBlockCoordinate(x+5, y+2, z+2);
		blocks.addBlockCoordinate(x+5, y+2, z+3);
		blocks.addBlockCoordinate(x+5, y+2, z+4);
		blocks.addBlockCoordinate(x+5, y+2, z+5);
		blocks.addBlockCoordinate(x+5, y+2, z+6);
		blocks.addBlockCoordinate(x+5, y+2, z+7);
		blocks.addBlockCoordinate(x+5, y+3, z+3);
		blocks.addBlockCoordinate(x+5, y+3, z+4);
		blocks.addBlockCoordinate(x+5, y+3, z+5);
		blocks.addBlockCoordinate(x+5, y+3, z+6);
		blocks.addBlockCoordinate(x+5, y+4, z+3);
		blocks.addBlockCoordinate(x+5, y+4, z+4);
		blocks.addBlockCoordinate(x+5, y+4, z+5);
		blocks.addBlockCoordinate(x+5, y+4, z+6);
		blocks.addBlockCoordinate(x+5, y+5, z+4);
		blocks.addBlockCoordinate(x+5, y+5, z+5);
		blocks.addBlockCoordinate(x+5, y+6, z+3);
		blocks.addBlockCoordinate(x+5, y+6, z+4);
		blocks.addBlockCoordinate(x+5, y+6, z+5);
		blocks.addBlockCoordinate(x+5, y+6, z+6);
		blocks.addBlockCoordinate(x+5, y+7, z+2);
		blocks.addBlockCoordinate(x+5, y+7, z+3);
		blocks.addBlockCoordinate(x+5, y+7, z+4);
		blocks.addBlockCoordinate(x+5, y+7, z+5);
		blocks.addBlockCoordinate(x+5, y+7, z+6);
		blocks.addBlockCoordinate(x+5, y+7, z+7);
		blocks.addBlockCoordinate(x+5, y+8, z+1);
		blocks.addBlockCoordinate(x+5, y+8, z+2);
		blocks.addBlockCoordinate(x+5, y+8, z+3);
		blocks.addBlockCoordinate(x+5, y+8, z+4);
		blocks.addBlockCoordinate(x+5, y+8, z+5);
		blocks.addBlockCoordinate(x+5, y+8, z+6);
		blocks.addBlockCoordinate(x+5, y+8, z+7);
		blocks.addBlockCoordinate(x+5, y+8, z+8);
		blocks.addBlockCoordinate(x+5, y+9, z+1);
		blocks.addBlockCoordinate(x+5, y+9, z+2);
		blocks.addBlockCoordinate(x+5, y+9, z+3);
		blocks.addBlockCoordinate(x+5, y+9, z+4);
		blocks.addBlockCoordinate(x+5, y+9, z+5);
		blocks.addBlockCoordinate(x+5, y+9, z+6);
		blocks.addBlockCoordinate(x+5, y+9, z+7);
		blocks.addBlockCoordinate(x+5, y+9, z+8);
		blocks.addBlockCoordinate(x+5, y+10, z);
		blocks.addBlockCoordinate(x+5, y+10, z+1);
		blocks.addBlockCoordinate(x+5, y+10, z+2);
		blocks.addBlockCoordinate(x+5, y+10, z+3);
		blocks.addBlockCoordinate(x+5, y+10, z+4);
		blocks.addBlockCoordinate(x+5, y+10, z+5);
		blocks.addBlockCoordinate(x+5, y+10, z+6);
		blocks.addBlockCoordinate(x+5, y+10, z+7);
		blocks.addBlockCoordinate(x+5, y+10, z+8);
		blocks.addBlockCoordinate(x+5, y+10, z+9);
		blocks.addBlockCoordinate(x+5, y+11, z);
		blocks.addBlockCoordinate(x+5, y+11, z+1);
		blocks.addBlockCoordinate(x+5, y+11, z+2);
		blocks.addBlockCoordinate(x+5, y+11, z+3);
		blocks.addBlockCoordinate(x+5, y+11, z+4);
		blocks.addBlockCoordinate(x+5, y+11, z+5);
		blocks.addBlockCoordinate(x+5, y+11, z+6);
		blocks.addBlockCoordinate(x+5, y+11, z+7);
		blocks.addBlockCoordinate(x+5, y+11, z+8);
		blocks.addBlockCoordinate(x+5, y+11, z+9);
		blocks.addBlockCoordinate(x+5, y+12, z);
		blocks.addBlockCoordinate(x+5, y+12, z+1);
		blocks.addBlockCoordinate(x+5, y+12, z+2);
		blocks.addBlockCoordinate(x+5, y+12, z+3);
		blocks.addBlockCoordinate(x+5, y+12, z+4);
		blocks.addBlockCoordinate(x+5, y+12, z+5);
		blocks.addBlockCoordinate(x+5, y+12, z+6);
		blocks.addBlockCoordinate(x+5, y+12, z+7);
		blocks.addBlockCoordinate(x+5, y+12, z+8);
		blocks.addBlockCoordinate(x+5, y+12, z+9);
		blocks.addBlockCoordinate(x+5, y+13, z);
		blocks.addBlockCoordinate(x+5, y+13, z+1);
		blocks.addBlockCoordinate(x+5, y+13, z+2);
		blocks.addBlockCoordinate(x+5, y+13, z+3);
		blocks.addBlockCoordinate(x+5, y+13, z+4);
		blocks.addBlockCoordinate(x+5, y+13, z+5);
		blocks.addBlockCoordinate(x+5, y+13, z+6);
		blocks.addBlockCoordinate(x+5, y+13, z+7);
		blocks.addBlockCoordinate(x+5, y+13, z+8);
		blocks.addBlockCoordinate(x+5, y+13, z+9);
		blocks.addBlockCoordinate(x+5, y+14, z);
		blocks.addBlockCoordinate(x+5, y+14, z+1);
		blocks.addBlockCoordinate(x+5, y+14, z+2);
		blocks.addBlockCoordinate(x+5, y+14, z+3);
		blocks.addBlockCoordinate(x+5, y+14, z+4);
		blocks.addBlockCoordinate(x+5, y+14, z+5);
		blocks.addBlockCoordinate(x+5, y+14, z+6);
		blocks.addBlockCoordinate(x+5, y+14, z+7);
		blocks.addBlockCoordinate(x+5, y+14, z+8);
		blocks.addBlockCoordinate(x+5, y+14, z+9);
		blocks.addBlockCoordinate(x+5, y+15, z);
		blocks.addBlockCoordinate(x+5, y+15, z+1);
		blocks.addBlockCoordinate(x+5, y+15, z+2);
		blocks.addBlockCoordinate(x+5, y+15, z+3);
		blocks.addBlockCoordinate(x+5, y+15, z+4);
		blocks.addBlockCoordinate(x+5, y+15, z+5);
		blocks.addBlockCoordinate(x+5, y+15, z+6);
		blocks.addBlockCoordinate(x+5, y+15, z+7);
		blocks.addBlockCoordinate(x+5, y+15, z+8);
		blocks.addBlockCoordinate(x+5, y+15, z+9);
		blocks.addBlockCoordinate(x+5, y+16, z);
		blocks.addBlockCoordinate(x+5, y+16, z+1);
		blocks.addBlockCoordinate(x+5, y+16, z+2);
		blocks.addBlockCoordinate(x+5, y+16, z+3);
		blocks.addBlockCoordinate(x+5, y+16, z+4);
		blocks.addBlockCoordinate(x+5, y+16, z+5);
		blocks.addBlockCoordinate(x+5, y+16, z+6);
		blocks.addBlockCoordinate(x+5, y+16, z+7);
		blocks.addBlockCoordinate(x+5, y+16, z+8);
		blocks.addBlockCoordinate(x+5, y+16, z+9);
		blocks.addBlockCoordinate(x+5, y+17, z);
		blocks.addBlockCoordinate(x+5, y+17, z+1);
		blocks.addBlockCoordinate(x+5, y+17, z+2);
		blocks.addBlockCoordinate(x+5, y+17, z+3);
		blocks.addBlockCoordinate(x+5, y+17, z+4);
		blocks.addBlockCoordinate(x+5, y+17, z+5);
		blocks.addBlockCoordinate(x+5, y+17, z+6);
		blocks.addBlockCoordinate(x+5, y+17, z+7);
		blocks.addBlockCoordinate(x+5, y+17, z+8);
		blocks.addBlockCoordinate(x+5, y+17, z+9);
		blocks.addBlockCoordinate(x+5, y+18, z+1);
		blocks.addBlockCoordinate(x+5, y+18, z+2);
		blocks.addBlockCoordinate(x+5, y+18, z+3);
		blocks.addBlockCoordinate(x+5, y+18, z+4);
		blocks.addBlockCoordinate(x+5, y+18, z+5);
		blocks.addBlockCoordinate(x+5, y+18, z+6);
		blocks.addBlockCoordinate(x+5, y+18, z+7);
		blocks.addBlockCoordinate(x+5, y+18, z+8);
		blocks.addBlockCoordinate(x+5, y+19, z+1);
		blocks.addBlockCoordinate(x+5, y+19, z+2);
		blocks.addBlockCoordinate(x+5, y+19, z+3);
		blocks.addBlockCoordinate(x+5, y+19, z+4);
		blocks.addBlockCoordinate(x+5, y+19, z+5);
		blocks.addBlockCoordinate(x+5, y+19, z+6);
		blocks.addBlockCoordinate(x+5, y+19, z+7);
		blocks.addBlockCoordinate(x+5, y+19, z+8);
		blocks.addBlockCoordinate(x+5, y+20, z+1);
		blocks.addBlockCoordinate(x+5, y+20, z+2);
		blocks.addBlockCoordinate(x+5, y+20, z+3);
		blocks.addBlockCoordinate(x+5, y+20, z+4);
		blocks.addBlockCoordinate(x+5, y+20, z+5);
		blocks.addBlockCoordinate(x+5, y+20, z+6);
		blocks.addBlockCoordinate(x+5, y+20, z+7);
		blocks.addBlockCoordinate(x+5, y+20, z+8);
		blocks.addBlockCoordinate(x+5, y+21, z+2);
		blocks.addBlockCoordinate(x+5, y+21, z+3);
		blocks.addBlockCoordinate(x+5, y+21, z+4);
		blocks.addBlockCoordinate(x+5, y+21, z+5);
		blocks.addBlockCoordinate(x+5, y+21, z+6);
		blocks.addBlockCoordinate(x+5, y+21, z+7);
		blocks.addBlockCoordinate(x+5, y+22, z+2);
		blocks.addBlockCoordinate(x+5, y+22, z+3);
		blocks.addBlockCoordinate(x+5, y+22, z+4);
		blocks.addBlockCoordinate(x+5, y+22, z+5);
		blocks.addBlockCoordinate(x+5, y+22, z+6);
		blocks.addBlockCoordinate(x+5, y+22, z+7);
		blocks.addBlockCoordinate(x+5, y+23, z+2);
		blocks.addBlockCoordinate(x+5, y+23, z+3);
		blocks.addBlockCoordinate(x+5, y+23, z+4);
		blocks.addBlockCoordinate(x+5, y+23, z+5);
		blocks.addBlockCoordinate(x+5, y+23, z+6);
		blocks.addBlockCoordinate(x+5, y+23, z+7);
		blocks.addBlockCoordinate(x+5, y+24, z+2);
		blocks.addBlockCoordinate(x+5, y+24, z+3);
		blocks.addBlockCoordinate(x+5, y+24, z+4);
		blocks.addBlockCoordinate(x+5, y+24, z+5);
		blocks.addBlockCoordinate(x+5, y+24, z+6);
		blocks.addBlockCoordinate(x+5, y+24, z+7);
		blocks.addBlockCoordinate(x+5, y+25, z+3);
		blocks.addBlockCoordinate(x+5, y+25, z+4);
		blocks.addBlockCoordinate(x+5, y+25, z+5);
		blocks.addBlockCoordinate(x+5, y+25, z+6);
		blocks.addBlockCoordinate(x+5, y+26, z+3);
		blocks.addBlockCoordinate(x+5, y+26, z+4);
		blocks.addBlockCoordinate(x+5, y+26, z+5);
		blocks.addBlockCoordinate(x+5, y+26, z+6);
		blocks.addBlockCoordinate(x+5, y+27, z+3);
		blocks.addBlockCoordinate(x+5, y+27, z+4);
		blocks.addBlockCoordinate(x+5, y+27, z+5);
		blocks.addBlockCoordinate(x+5, y+27, z+6);
		blocks.addBlockCoordinate(x+5, y+28, z+4);
		blocks.addBlockCoordinate(x+5, y+28, z+5);
		blocks.addBlockCoordinate(x+5, y+29, z+4);
		blocks.addBlockCoordinate(x+5, y+29, z+5);
		blocks.addBlockCoordinate(x+5, y+30, z+4);
		blocks.addBlockCoordinate(x+5, y+30, z+5);

		blocks.addBlockCoordinate(x+6, y+2, z+3);
		blocks.addBlockCoordinate(x+6, y+2, z+4);
		blocks.addBlockCoordinate(x+6, y+2, z+5);
		blocks.addBlockCoordinate(x+6, y+2, z+6);
		blocks.addBlockCoordinate(x+6, y+3, z+4);
		blocks.addBlockCoordinate(x+6, y+3, z+5);
		blocks.addBlockCoordinate(x+6, y+4, z+4);
		blocks.addBlockCoordinate(x+6, y+4, z+5);
		blocks.addBlockCoordinate(x+6, y+6, z+4);
		blocks.addBlockCoordinate(x+6, y+6, z+5);
		blocks.addBlockCoordinate(x+6, y+7, z+3);
		blocks.addBlockCoordinate(x+6, y+7, z+4);
		blocks.addBlockCoordinate(x+6, y+7, z+5);
		blocks.addBlockCoordinate(x+6, y+7, z+6);
		blocks.addBlockCoordinate(x+6, y+8, z+2);
		blocks.addBlockCoordinate(x+6, y+8, z+3);
		blocks.addBlockCoordinate(x+6, y+8, z+4);
		blocks.addBlockCoordinate(x+6, y+8, z+5);
		blocks.addBlockCoordinate(x+6, y+8, z+6);
		blocks.addBlockCoordinate(x+6, y+8, z+7);
		blocks.addBlockCoordinate(x+6, y+9, z+1);
		blocks.addBlockCoordinate(x+6, y+9, z+2);
		blocks.addBlockCoordinate(x+6, y+9, z+3);
		blocks.addBlockCoordinate(x+6, y+9, z+4);
		blocks.addBlockCoordinate(x+6, y+9, z+5);
		blocks.addBlockCoordinate(x+6, y+9, z+6);
		blocks.addBlockCoordinate(x+6, y+9, z+7);
		blocks.addBlockCoordinate(x+6, y+9, z+8);
		blocks.addBlockCoordinate(x+6, y+10, z+1);
		blocks.addBlockCoordinate(x+6, y+10, z+2);
		blocks.addBlockCoordinate(x+6, y+10, z+3);
		blocks.addBlockCoordinate(x+6, y+10, z+4);
		blocks.addBlockCoordinate(x+6, y+10, z+5);
		blocks.addBlockCoordinate(x+6, y+10, z+6);
		blocks.addBlockCoordinate(x+6, y+10, z+7);
		blocks.addBlockCoordinate(x+6, y+10, z+8);
		blocks.addBlockCoordinate(x+6, y+11, z);
		blocks.addBlockCoordinate(x+6, y+11, z+1);
		blocks.addBlockCoordinate(x+6, y+11, z+2);
		blocks.addBlockCoordinate(x+6, y+11, z+3);
		blocks.addBlockCoordinate(x+6, y+11, z+4);
		blocks.addBlockCoordinate(x+6, y+11, z+5);
		blocks.addBlockCoordinate(x+6, y+11, z+6);
		blocks.addBlockCoordinate(x+6, y+11, z+7);
		blocks.addBlockCoordinate(x+6, y+11, z+8);
		blocks.addBlockCoordinate(x+6, y+11, z+9);
		blocks.addBlockCoordinate(x+6, y+12, z+1);
		blocks.addBlockCoordinate(x+6, y+12, z+2);
		blocks.addBlockCoordinate(x+6, y+12, z+3);
		blocks.addBlockCoordinate(x+6, y+12, z+4);
		blocks.addBlockCoordinate(x+6, y+12, z+5);
		blocks.addBlockCoordinate(x+6, y+12, z+6);
		blocks.addBlockCoordinate(x+6, y+12, z+7);
		blocks.addBlockCoordinate(x+6, y+12, z+8);
		blocks.addBlockCoordinate(x+6, y+13, z);
		blocks.addBlockCoordinate(x+6, y+13, z+1);
		blocks.addBlockCoordinate(x+6, y+13, z+2);
		blocks.addBlockCoordinate(x+6, y+13, z+3);
		blocks.addBlockCoordinate(x+6, y+13, z+4);
		blocks.addBlockCoordinate(x+6, y+13, z+5);
		blocks.addBlockCoordinate(x+6, y+13, z+6);
		blocks.addBlockCoordinate(x+6, y+13, z+7);
		blocks.addBlockCoordinate(x+6, y+13, z+8);
		blocks.addBlockCoordinate(x+6, y+13, z+9);
		blocks.addBlockCoordinate(x+6, y+14, z);
		blocks.addBlockCoordinate(x+6, y+14, z+1);
		blocks.addBlockCoordinate(x+6, y+14, z+2);
		blocks.addBlockCoordinate(x+6, y+14, z+3);
		blocks.addBlockCoordinate(x+6, y+14, z+4);
		blocks.addBlockCoordinate(x+6, y+14, z+5);
		blocks.addBlockCoordinate(x+6, y+14, z+6);
		blocks.addBlockCoordinate(x+6, y+14, z+7);
		blocks.addBlockCoordinate(x+6, y+14, z+8);
		blocks.addBlockCoordinate(x+6, y+14, z+9);
		blocks.addBlockCoordinate(x+6, y+15, z+1);
		blocks.addBlockCoordinate(x+6, y+15, z+2);
		blocks.addBlockCoordinate(x+6, y+15, z+3);
		blocks.addBlockCoordinate(x+6, y+15, z+4);
		blocks.addBlockCoordinate(x+6, y+15, z+5);
		blocks.addBlockCoordinate(x+6, y+15, z+6);
		blocks.addBlockCoordinate(x+6, y+15, z+7);
		blocks.addBlockCoordinate(x+6, y+15, z+8);
		blocks.addBlockCoordinate(x+6, y+16, z);
		blocks.addBlockCoordinate(x+6, y+16, z+1);
		blocks.addBlockCoordinate(x+6, y+16, z+2);
		blocks.addBlockCoordinate(x+6, y+16, z+3);
		blocks.addBlockCoordinate(x+6, y+16, z+4);
		blocks.addBlockCoordinate(x+6, y+16, z+5);
		blocks.addBlockCoordinate(x+6, y+16, z+6);
		blocks.addBlockCoordinate(x+6, y+16, z+7);
		blocks.addBlockCoordinate(x+6, y+16, z+8);
		blocks.addBlockCoordinate(x+6, y+16, z+9);
		blocks.addBlockCoordinate(x+6, y+17, z+1);
		blocks.addBlockCoordinate(x+6, y+17, z+2);
		blocks.addBlockCoordinate(x+6, y+17, z+3);
		blocks.addBlockCoordinate(x+6, y+17, z+4);
		blocks.addBlockCoordinate(x+6, y+17, z+5);
		blocks.addBlockCoordinate(x+6, y+17, z+6);
		blocks.addBlockCoordinate(x+6, y+17, z+7);
		blocks.addBlockCoordinate(x+6, y+17, z+8);
		blocks.addBlockCoordinate(x+6, y+18, z+2);
		blocks.addBlockCoordinate(x+6, y+18, z+3);
		blocks.addBlockCoordinate(x+6, y+18, z+4);
		blocks.addBlockCoordinate(x+6, y+18, z+5);
		blocks.addBlockCoordinate(x+6, y+18, z+6);
		blocks.addBlockCoordinate(x+6, y+18, z+7);
		blocks.addBlockCoordinate(x+6, y+19, z+2);
		blocks.addBlockCoordinate(x+6, y+19, z+3);
		blocks.addBlockCoordinate(x+6, y+19, z+4);
		blocks.addBlockCoordinate(x+6, y+19, z+5);
		blocks.addBlockCoordinate(x+6, y+19, z+6);
		blocks.addBlockCoordinate(x+6, y+19, z+7);
		blocks.addBlockCoordinate(x+6, y+20, z+2);
		blocks.addBlockCoordinate(x+6, y+20, z+3);
		blocks.addBlockCoordinate(x+6, y+20, z+4);
		blocks.addBlockCoordinate(x+6, y+20, z+5);
		blocks.addBlockCoordinate(x+6, y+20, z+6);
		blocks.addBlockCoordinate(x+6, y+20, z+7);
		blocks.addBlockCoordinate(x+6, y+21, z+3);
		blocks.addBlockCoordinate(x+6, y+21, z+4);
		blocks.addBlockCoordinate(x+6, y+21, z+5);
		blocks.addBlockCoordinate(x+6, y+21, z+6);
		blocks.addBlockCoordinate(x+6, y+22, z+3);
		blocks.addBlockCoordinate(x+6, y+22, z+4);
		blocks.addBlockCoordinate(x+6, y+22, z+5);
		blocks.addBlockCoordinate(x+6, y+22, z+6);
		blocks.addBlockCoordinate(x+6, y+23, z+3);
		blocks.addBlockCoordinate(x+6, y+23, z+4);
		blocks.addBlockCoordinate(x+6, y+23, z+5);
		blocks.addBlockCoordinate(x+6, y+23, z+6);
		blocks.addBlockCoordinate(x+6, y+24, z+3);
		blocks.addBlockCoordinate(x+6, y+24, z+4);
		blocks.addBlockCoordinate(x+6, y+24, z+5);
		blocks.addBlockCoordinate(x+6, y+24, z+6);
		blocks.addBlockCoordinate(x+6, y+25, z+4);
		blocks.addBlockCoordinate(x+6, y+25, z+5);
		blocks.addBlockCoordinate(x+6, y+26, z+4);
		blocks.addBlockCoordinate(x+6, y+26, z+5);
		blocks.addBlockCoordinate(x+6, y+27, z+4);
		blocks.addBlockCoordinate(x+6, y+27, z+5);

		blocks.addBlockCoordinate(x+7, y+2, z+4);
		blocks.addBlockCoordinate(x+7, y+2, z+5);
		blocks.addBlockCoordinate(x+7, y+7, z+4);
		blocks.addBlockCoordinate(x+7, y+7, z+5);
		blocks.addBlockCoordinate(x+7, y+8, z+3);
		blocks.addBlockCoordinate(x+7, y+8, z+4);
		blocks.addBlockCoordinate(x+7, y+8, z+5);
		blocks.addBlockCoordinate(x+7, y+8, z+6);
		blocks.addBlockCoordinate(x+7, y+9, z+2);
		blocks.addBlockCoordinate(x+7, y+9, z+3);
		blocks.addBlockCoordinate(x+7, y+9, z+4);
		blocks.addBlockCoordinate(x+7, y+9, z+5);
		blocks.addBlockCoordinate(x+7, y+9, z+6);
		blocks.addBlockCoordinate(x+7, y+9, z+7);
		blocks.addBlockCoordinate(x+7, y+10, z+2);
		blocks.addBlockCoordinate(x+7, y+10, z+3);
		blocks.addBlockCoordinate(x+7, y+10, z+4);
		blocks.addBlockCoordinate(x+7, y+10, z+5);
		blocks.addBlockCoordinate(x+7, y+10, z+6);
		blocks.addBlockCoordinate(x+7, y+10, z+7);
		blocks.addBlockCoordinate(x+7, y+11, z+1);
		blocks.addBlockCoordinate(x+7, y+11, z+2);
		blocks.addBlockCoordinate(x+7, y+11, z+3);
		blocks.addBlockCoordinate(x+7, y+11, z+4);
		blocks.addBlockCoordinate(x+7, y+11, z+5);
		blocks.addBlockCoordinate(x+7, y+11, z+6);
		blocks.addBlockCoordinate(x+7, y+11, z+7);
		blocks.addBlockCoordinate(x+7, y+11, z+8);
		blocks.addBlockCoordinate(x+7, y+12, z+2);
		blocks.addBlockCoordinate(x+7, y+12, z+3);
		blocks.addBlockCoordinate(x+7, y+12, z+4);
		blocks.addBlockCoordinate(x+7, y+12, z+5);
		blocks.addBlockCoordinate(x+7, y+12, z+6);
		blocks.addBlockCoordinate(x+7, y+12, z+7);
		blocks.addBlockCoordinate(x+7, y+13, z+1);
		blocks.addBlockCoordinate(x+7, y+13, z+2);
		blocks.addBlockCoordinate(x+7, y+13, z+3);
		blocks.addBlockCoordinate(x+7, y+13, z+4);
		blocks.addBlockCoordinate(x+7, y+13, z+5);
		blocks.addBlockCoordinate(x+7, y+13, z+6);
		blocks.addBlockCoordinate(x+7, y+13, z+7);
		blocks.addBlockCoordinate(x+7, y+13, z+8);
		blocks.addBlockCoordinate(x+7, y+14, z+1);
		blocks.addBlockCoordinate(x+7, y+14, z+2);
		blocks.addBlockCoordinate(x+7, y+14, z+3);
		blocks.addBlockCoordinate(x+7, y+14, z+4);
		blocks.addBlockCoordinate(x+7, y+14, z+5);
		blocks.addBlockCoordinate(x+7, y+14, z+6);
		blocks.addBlockCoordinate(x+7, y+14, z+7);
		blocks.addBlockCoordinate(x+7, y+14, z+8);
		blocks.addBlockCoordinate(x+7, y+15, z+2);
		blocks.addBlockCoordinate(x+7, y+15, z+3);
		blocks.addBlockCoordinate(x+7, y+15, z+4);
		blocks.addBlockCoordinate(x+7, y+15, z+5);
		blocks.addBlockCoordinate(x+7, y+15, z+6);
		blocks.addBlockCoordinate(x+7, y+15, z+7);
		blocks.addBlockCoordinate(x+7, y+16, z+1);
		blocks.addBlockCoordinate(x+7, y+16, z+2);
		blocks.addBlockCoordinate(x+7, y+16, z+3);
		blocks.addBlockCoordinate(x+7, y+16, z+4);
		blocks.addBlockCoordinate(x+7, y+16, z+5);
		blocks.addBlockCoordinate(x+7, y+16, z+6);
		blocks.addBlockCoordinate(x+7, y+16, z+7);
		blocks.addBlockCoordinate(x+7, y+16, z+8);
		blocks.addBlockCoordinate(x+7, y+17, z+2);
		blocks.addBlockCoordinate(x+7, y+17, z+3);
		blocks.addBlockCoordinate(x+7, y+17, z+4);
		blocks.addBlockCoordinate(x+7, y+17, z+5);
		blocks.addBlockCoordinate(x+7, y+17, z+6);
		blocks.addBlockCoordinate(x+7, y+17, z+7);
		blocks.addBlockCoordinate(x+7, y+18, z+3);
		blocks.addBlockCoordinate(x+7, y+18, z+4);
		blocks.addBlockCoordinate(x+7, y+18, z+5);
		blocks.addBlockCoordinate(x+7, y+18, z+6);
		blocks.addBlockCoordinate(x+7, y+19, z+3);
		blocks.addBlockCoordinate(x+7, y+19, z+4);
		blocks.addBlockCoordinate(x+7, y+19, z+5);
		blocks.addBlockCoordinate(x+7, y+19, z+6);
		blocks.addBlockCoordinate(x+7, y+20, z+3);
		blocks.addBlockCoordinate(x+7, y+20, z+4);
		blocks.addBlockCoordinate(x+7, y+20, z+5);
		blocks.addBlockCoordinate(x+7, y+20, z+6);
		blocks.addBlockCoordinate(x+7, y+21, z+4);
		blocks.addBlockCoordinate(x+7, y+21, z+5);
		blocks.addBlockCoordinate(x+7, y+22, z+4);
		blocks.addBlockCoordinate(x+7, y+22, z+5);
		blocks.addBlockCoordinate(x+7, y+23, z+4);
		blocks.addBlockCoordinate(x+7, y+23, z+5);
		blocks.addBlockCoordinate(x+7, y+24, z+4);
		blocks.addBlockCoordinate(x+7, y+24, z+5);

		blocks.addBlockCoordinate(x+8, y+8, z+4);
		blocks.addBlockCoordinate(x+8, y+8, z+5);
		blocks.addBlockCoordinate(x+8, y+9, z+3);
		blocks.addBlockCoordinate(x+8, y+9, z+4);
		blocks.addBlockCoordinate(x+8, y+9, z+5);
		blocks.addBlockCoordinate(x+8, y+9, z+6);
		blocks.addBlockCoordinate(x+8, y+10, z+3);
		blocks.addBlockCoordinate(x+8, y+10, z+4);
		blocks.addBlockCoordinate(x+8, y+10, z+5);
		blocks.addBlockCoordinate(x+8, y+10, z+6);
		blocks.addBlockCoordinate(x+8, y+11, z+2);
		blocks.addBlockCoordinate(x+8, y+11, z+3);
		blocks.addBlockCoordinate(x+8, y+11, z+4);
		blocks.addBlockCoordinate(x+8, y+11, z+5);
		blocks.addBlockCoordinate(x+8, y+11, z+6);
		blocks.addBlockCoordinate(x+8, y+11, z+7);
		blocks.addBlockCoordinate(x+8, y+12, z+3);
		blocks.addBlockCoordinate(x+8, y+12, z+4);
		blocks.addBlockCoordinate(x+8, y+12, z+5);
		blocks.addBlockCoordinate(x+8, y+12, z+6);
		blocks.addBlockCoordinate(x+8, y+13, z+1);
		blocks.addBlockCoordinate(x+8, y+13, z+2);
		blocks.addBlockCoordinate(x+8, y+13, z+3);
		blocks.addBlockCoordinate(x+8, y+13, z+4);
		blocks.addBlockCoordinate(x+8, y+13, z+5);
		blocks.addBlockCoordinate(x+8, y+13, z+6);
		blocks.addBlockCoordinate(x+8, y+13, z+7);
		blocks.addBlockCoordinate(x+8, y+13, z+8);
		blocks.addBlockCoordinate(x+8, y+14, z+1);
		blocks.addBlockCoordinate(x+8, y+14, z+2);
		blocks.addBlockCoordinate(x+8, y+14, z+3);
		blocks.addBlockCoordinate(x+8, y+14, z+4);
		blocks.addBlockCoordinate(x+8, y+14, z+5);
		blocks.addBlockCoordinate(x+8, y+14, z+6);
		blocks.addBlockCoordinate(x+8, y+14, z+7);
		blocks.addBlockCoordinate(x+8, y+14, z+8);
		blocks.addBlockCoordinate(x+8, y+15, z+3);
		blocks.addBlockCoordinate(x+8, y+15, z+4);
		blocks.addBlockCoordinate(x+8, y+15, z+5);
		blocks.addBlockCoordinate(x+8, y+15, z+6);
		blocks.addBlockCoordinate(x+8, y+16, z+2);
		blocks.addBlockCoordinate(x+8, y+16, z+3);
		blocks.addBlockCoordinate(x+8, y+16, z+4);
		blocks.addBlockCoordinate(x+8, y+16, z+5);
		blocks.addBlockCoordinate(x+8, y+16, z+6);
		blocks.addBlockCoordinate(x+8, y+16, z+7);
		blocks.addBlockCoordinate(x+8, y+17, z+3);
		blocks.addBlockCoordinate(x+8, y+17, z+4);
		blocks.addBlockCoordinate(x+8, y+17, z+5);
		blocks.addBlockCoordinate(x+8, y+17, z+6);
		blocks.addBlockCoordinate(x+8, y+18, z+4);
		blocks.addBlockCoordinate(x+8, y+18, z+5);
		blocks.addBlockCoordinate(x+8, y+19, z+4);
		blocks.addBlockCoordinate(x+8, y+19, z+5);
		blocks.addBlockCoordinate(x+8, y+20, z+4);
		blocks.addBlockCoordinate(x+8, y+20, z+5);

		blocks.addBlockCoordinate(x+9, y+10, z+4);
		blocks.addBlockCoordinate(x+9, y+10, z+5);
		blocks.addBlockCoordinate(x+9, y+11, z+3);
		blocks.addBlockCoordinate(x+9, y+11, z+4);
		blocks.addBlockCoordinate(x+9, y+11, z+5);
		blocks.addBlockCoordinate(x+9, y+11, z+6);
		blocks.addBlockCoordinate(x+9, y+12, z+4);
		blocks.addBlockCoordinate(x+9, y+12, z+5);
		blocks.addBlockCoordinate(x+9, y+13, z+3);
		blocks.addBlockCoordinate(x+9, y+13, z+4);
		blocks.addBlockCoordinate(x+9, y+13, z+5);
		blocks.addBlockCoordinate(x+9, y+13, z+6);
		blocks.addBlockCoordinate(x+9, y+14, z+3);
		blocks.addBlockCoordinate(x+9, y+14, z+4);
		blocks.addBlockCoordinate(x+9, y+14, z+5);
		blocks.addBlockCoordinate(x+9, y+14, z+6);
		blocks.addBlockCoordinate(x+9, y+15, z+4);
		blocks.addBlockCoordinate(x+9, y+15, z+5);
		blocks.addBlockCoordinate(x+9, y+16, z+3);
		blocks.addBlockCoordinate(x+9, y+16, z+4);
		blocks.addBlockCoordinate(x+9, y+16, z+5);
		blocks.addBlockCoordinate(x+9, y+16, z+6);
		blocks.addBlockCoordinate(x+9, y+17, z+4);
		blocks.addBlockCoordinate(x+9, y+17, z+5);

		return blocks;
	}

}
