/*******************************************************************************
 * @author Reika Kalseki
 * 
 * Copyright 2017
 * 
 * All rights reserved.
 * Distribution of the software in any form is only allowed with
 * explicit, prior permission from the owner.
 ******************************************************************************/
package Reika.ChromatiCraft.Auxiliary;

import java.util.ArrayList;
import java.util.Collection;

import net.minecraft.block.Block;
import net.minecraft.init.Blocks;
import net.minecraft.world.World;
import Reika.ChromatiCraft.Block.Worldgen.BlockStructureShield.BlockType;
import Reika.ChromatiCraft.Registry.ChromaBlocks;
import Reika.DragonAPI.Instantiable.Data.BlockStruct.FilledBlockArray;
import Reika.DragonAPI.Instantiable.Data.Immutable.Coordinate;


public class SnowStructure {

	private static final Block b = ChromaBlocks.STRUCTSHIELD.getBlockInstance();
	private static final Block b2 = ChromaBlocks.TRAPFLOOR.getBlockInstance();
	private static final int ms = BlockType.STONE.metadata;
	private static final int mc = BlockType.COBBLE.metadata;
	private static final int mg = BlockType.GLASS.metadata;

	private static final int mcrack = ms;

	private static final Block ch = ChromaBlocks.LOOTCHEST.getBlockInstance();

	public static Collection<Coordinate> getCrackToCenter() {
		Collection<Coordinate> li = new ArrayList();
		li.add(new Coordinate(9, 5, 7));
		li.add(new Coordinate(9, 5, 8));
		li.add(new Coordinate(9, 5, 9));
		li.add(new Coordinate(9, 5, 10));
		li.add(new Coordinate(8, 5, 7));
		li.add(new Coordinate(8, 5, 8));
		li.add(new Coordinate(8, 5, 9));
		li.add(new Coordinate(8, 5, 10));
		li.add(new Coordinate(8, 6, 10));
		li.add(new Coordinate(7, 5, 7));
		li.add(new Coordinate(7, 5, 8));
		li.add(new Coordinate(7, 5, 9));
		li.add(new Coordinate(7, 5, 10));
		li.add(new Coordinate(7, 6, 10));
		li.add(new Coordinate(7, 7, 10));
		li.add(new Coordinate(7, 8, 10));
		li.add(new Coordinate(8, 7, 10));
		li.add(new Coordinate(8, 8, 10));
		li.add(new Coordinate(9, 6, 10));
		li.add(new Coordinate(9, 7, 10));
		li.add(new Coordinate(9, 8, 10));
		return li;
	}

	public static FilledBlockArray getSnowStructure(World world, int x, int y, int z) {
		FilledBlockArray array = new FilledBlockArray(world);

		//array.setBlock(x + 8, y + 3, z + 6, Blocks.blockDiamond);

		for (Coordinate c : getCrackToCenter()) {
			array.setBlock(x + c.xCoord, y + c.yCoord, z + c.zCoord, b, mcrack);
		}

		array.setBlock(x + 0, y + 5, z + 6, b, BlockType.MOSS.metadata);
		array.setBlock(x + 0, y + 5, z + 7, b, BlockType.MOSS.metadata);
		array.setBlock(x + 0, y + 5, z + 8, b, BlockType.MOSS.metadata);
		array.setBlock(x + 0, y + 5, z + 9, b, BlockType.MOSS.metadata);
		array.setBlock(x + 0, y + 5, z + 10, b, BlockType.MOSS.metadata);
		array.setBlock(x + 1, y + 4, z + 4, b, ms);
		array.setBlock(x + 1, y + 4, z + 5, b, ms);
		array.setBlock(x + 1, y + 4, z + 6, b, ms);
		array.setBlock(x + 1, y + 4, z + 7, b, ms);
		array.setBlock(x + 1, y + 4, z + 8, b, ms);
		array.setBlock(x + 1, y + 5, z + 3, b, ms);
		array.setBlock(x + 1, y + 5, z + 4, b, ms);
		array.setBlock(x + 1, y + 5, z + 5, b, ms);
		array.setBlock(x + 1, y + 5, z + 6, b, ms);
		array.setBlock(x + 1, y + 5, z + 7, b, ms);
		array.setBlock(x + 1, y + 5, z + 8, b2);
		array.setBlock(x + 1, y + 5, z + 9, b, ms);
		array.setBlock(x + 1, y + 5, z + 10, b, ms);
		array.setBlock(x + 1, y + 5, z + 11, b, ms);
		array.setBlock(x + 1, y + 5, z + 12, b, ms);
		array.setBlock(x + 1, y + 5, z + 13, b, ms);
		array.setBlock(x + 1, y + 6, z + 3, b, mc);
		array.setBlock(x + 1, y + 6, z + 4, b, mg);
		array.setBlock(x + 1, y + 6, z + 5, b, mg);
		array.setBlock(x + 1, y + 6, z + 6, b, mg);
		array.setBlock(x + 1, y + 6, z + 7, b, mc);
		array.setBlock(x + 1, y + 6, z + 9, b, mc);
		array.setBlock(x + 1, y + 6, z + 10, b, mg);
		array.setBlock(x + 1, y + 6, z + 11, b, mg);
		array.setBlock(x + 1, y + 6, z + 12, b, mg);
		array.setBlock(x + 1, y + 6, z + 13, b, mc);
		array.setBlock(x + 1, y + 7, z + 3, b, mc);
		array.setBlock(x + 1, y + 7, z + 4, b, mg);
		array.setBlock(x + 1, y + 7, z + 5, b, mg);
		array.setBlock(x + 1, y + 7, z + 6, b, mg);
		array.setBlock(x + 1, y + 7, z + 7, b, mc);
		array.setBlock(x + 1, y + 7, z + 9, b, mc);
		array.setBlock(x + 1, y + 7, z + 10, b, mg);
		array.setBlock(x + 1, y + 7, z + 11, b, mg);
		array.setBlock(x + 1, y + 7, z + 12, b, mg);
		array.setBlock(x + 1, y + 7, z + 13, b, mc);
		array.setBlock(x + 1, y + 8, z + 3, b, mc);
		array.setBlock(x + 1, y + 8, z + 4, b, mg);
		array.setBlock(x + 1, y + 8, z + 5, b, mg);
		array.setBlock(x + 1, y + 8, z + 6, b, mg);
		array.setBlock(x + 1, y + 8, z + 7, b, mc);
		array.setBlock(x + 1, y + 8, z + 8, b, mc);
		array.setBlock(x + 1, y + 8, z + 9, b, mc);
		array.setBlock(x + 1, y + 8, z + 10, b, mg);
		array.setBlock(x + 1, y + 8, z + 11, b, mg);
		array.setBlock(x + 1, y + 8, z + 12, b, mg);
		array.setBlock(x + 1, y + 8, z + 13, b, mc);
		array.setBlock(x + 1, y + 9, z + 3, b, mc);
		array.setBlock(x + 1, y + 9, z + 4, b, mc);
		array.setBlock(x + 1, y + 9, z + 5, b, mc);
		array.setBlock(x + 1, y + 9, z + 6, b, mc);
		array.setBlock(x + 1, y + 9, z + 7, b, mc);
		array.setBlock(x + 1, y + 9, z + 8, b, mc);
		array.setBlock(x + 1, y + 9, z + 9, b, mc);
		array.setBlock(x + 1, y + 9, z + 10, b, mc);
		array.setBlock(x + 1, y + 9, z + 11, b, mc);
		array.setBlock(x + 1, y + 9, z + 12, b, mc);
		array.setBlock(x + 1, y + 9, z + 13, b, mc);
		array.setBlock(x + 1, y + 10, z + 3, b, mc);
		array.setBlock(x + 1, y + 10, z + 5, b, mc);
		array.setBlock(x + 1, y + 10, z + 11, b, mc);
		array.setBlock(x + 1, y + 10, z + 13, b, mc);
		array.setBlock(x + 2, y + 3, z + 4, b, ms);
		array.setBlock(x + 2, y + 3, z + 5, b, ms);
		array.setBlock(x + 2, y + 3, z + 6, b, ms);
		array.setBlock(x + 2, y + 3, z + 7, b, ms);
		array.setBlock(x + 2, y + 3, z + 8, b, ms);
		array.setBlock(x + 2, y + 3, z + 9, b, ms);
		array.setBlock(x + 2, y + 4, z + 3, b, ms);
		array.setBlock(x + 2, y + 4, z + 4, Blocks.mob_spawner);
		array.setBlock(x + 2, y + 4, z + 5, b, ms);
		array.setBlock(x + 2, y + 4, z + 6, b, ms);
		array.setBlock(x + 2, y + 4, z + 7, b, ms);
		array.setBlock(x + 2, y + 4, z + 8, b, ms);
		array.setBlock(x + 2, y + 4, z + 9, b, ms);
		array.setBlock(x + 2, y + 4, z + 10, b, ms);
		array.setBlock(x + 2, y + 4, z + 11, b, ms);
		array.setBlock(x + 2, y + 4, z + 12, b, ms);
		array.setBlock(x + 2, y + 4, z + 13, b, ms);
		array.setBlock(x + 2, y + 4, z + 14, b, ms);
		array.setBlock(x + 2, y + 5, z + 2, b, ms);
		array.setBlock(x + 2, y + 5, z + 3, b2);
		array.setBlock(x + 2, y + 5, z + 4, b2);
		array.setBlock(x + 2, y + 5, z + 5, b2);
		array.setBlock(x + 2, y + 5, z + 6, b2);
		array.setBlock(x + 2, y + 5, z + 7, b2);
		array.setBlock(x + 2, y + 5, z + 8, b2);
		array.setBlock(x + 2, y + 5, z + 9, b, ms);
		array.setBlock(x + 2, y + 5, z + 10, b2);
		array.setBlock(x + 2, y + 5, z + 11, b2);
		array.setBlock(x + 2, y + 5, z + 12, b2);
		array.setBlock(x + 2, y + 5, z + 13, b2);
		array.setBlock(x + 2, y + 5, z + 14, b, ms);
		array.setBlock(x + 2, y + 6, z + 2, b, ms);
		array.setBlock(x + 2, y + 6, z + 9, b, ms);
		array.setBlock(x + 2, y + 6, z + 14, b, ms);
		array.setBlock(x + 2, y + 7, z + 2, b, ms);
		array.setBlock(x + 2, y + 7, z + 9, b, ms);
		array.setBlock(x + 2, y + 7, z + 14, b, ms);
		array.setBlock(x + 2, y + 8, z + 2, b, ms);
		array.setBlock(x + 2, y + 8, z + 9, b, ms);
		array.setBlock(x + 2, y + 8, z + 14, b, ms);
		array.setBlock(x + 2, y + 9, z + 2, b, mc);
		array.setBlock(x + 2, y + 9, z + 3, b, mc);
		array.setBlock(x + 2, y + 9, z + 4, b, ms);
		array.setBlock(x + 2, y + 9, z + 5, b, ms);
		array.setBlock(x + 2, y + 9, z + 6, b, ms);
		array.setBlock(x + 2, y + 9, z + 7, b, ms);
		array.setBlock(x + 2, y + 9, z + 8, b, ms);
		array.setBlock(x + 2, y + 9, z + 9, b, ms);
		array.setBlock(x + 2, y + 9, z + 10, b, ms);
		array.setBlock(x + 2, y + 9, z + 11, b, ms);
		array.setBlock(x + 2, y + 9, z + 12, b, ms);
		array.setBlock(x + 2, y + 9, z + 13, b, mc);
		array.setBlock(x + 2, y + 9, z + 14, b, mc);
		array.setBlock(x + 2, y + 10, z + 5, b, mc);
		array.setBlock(x + 2, y + 10, z + 6, b, ms);
		array.setBlock(x + 2, y + 10, z + 7, b, ms);
		array.setBlock(x + 2, y + 10, z + 8, b, ms);
		array.setBlock(x + 2, y + 10, z + 9, b, ms);
		array.setBlock(x + 2, y + 10, z + 10, b, ms);
		array.setBlock(x + 2, y + 10, z + 11, b, mc);
		array.setBlock(x + 3, y + 3, z + 4, b, ms);
		array.setBlock(x + 3, y + 3, z + 5, b, BlockType.CLOAK.metadata);
		array.setBlock(x + 3, y + 3, z + 6, b, BlockType.CLOAK.metadata);
		array.setBlock(x + 3, y + 3, z + 7, b, BlockType.CLOAK.metadata);
		array.setBlock(x + 3, y + 3, z + 8, b, BlockType.CLOAK.metadata);
		array.setBlock(x + 3, y + 3, z + 9, b, ms);
		array.setBlock(x + 3, y + 3, z + 10, b, ms);
		array.setBlock(x + 3, y + 3, z + 11, b, ms);
		array.setBlock(x + 3, y + 3, z + 12, b, ms);
		array.setBlock(x + 3, y + 3, z + 13, b, ms);
		array.setBlock(x + 3, y + 3, z + 14, b, ms);
		array.setBlock(x + 3, y + 4, z + 2, b, ms);
		array.setBlock(x + 3, y + 4, z + 3, b, ms);
		array.setBlock(x + 3, y + 4, z + 4, b, ms);
		array.setBlock(x + 3, y + 4, z + 9, b, ms);
		array.setBlock(x + 3, y + 4, z + 10, b, ms);
		array.setBlock(x + 3, y + 4, z + 11, b, ms);
		array.setBlock(x + 3, y + 4, z + 12, b, ms);
		array.setBlock(x + 3, y + 4, z + 13, b, ms);
		array.setBlock(x + 3, y + 4, z + 14, Blocks.mob_spawner);
		array.setBlock(x + 3, y + 4, z + 15, b, ms);
		array.setBlock(x + 3, y + 5, z + 1, b, ms);
		array.setBlock(x + 3, y + 5, z + 2, b2);
		array.setBlock(x + 3, y + 5, z + 3, b2);
		array.setBlock(x + 3, y + 5, z + 4, b2);
		array.setBlock(x + 3, y + 5, z + 5, b2);
		array.setBlock(x + 3, y + 5, z + 6, b2);
		array.setBlock(x + 3, y + 5, z + 7, b2);
		array.setBlock(x + 3, y + 5, z + 8, b2);
		array.setBlock(x + 3, y + 5, z + 9, b, ms);
		array.setBlock(x + 3, y + 5, z + 10, b2);
		array.setBlock(x + 3, y + 5, z + 11, b2);
		array.setBlock(x + 3, y + 5, z + 12, b2);
		array.setBlock(x + 3, y + 5, z + 13, b2);
		array.setBlock(x + 3, y + 5, z + 14, b2);
		array.setBlock(x + 3, y + 5, z + 15, b, ms);
		array.setBlock(x + 3, y + 6, z + 1, b, mc);
		array.setBlock(x + 3, y + 6, z + 9, b, ms);
		array.setBlock(x + 3, y + 6, z + 15, b, mc);
		array.setBlock(x + 3, y + 7, z + 1, b, mc);
		array.setBlock(x + 3, y + 7, z + 9, b, ms);
		array.setBlock(x + 3, y + 7, z + 15, b, mc);
		array.setBlock(x + 3, y + 8, z + 1, b, mc);
		array.setBlock(x + 3, y + 8, z + 9, b, ms);
		array.setBlock(x + 3, y + 8, z + 15, b, mc);
		array.setBlock(x + 3, y + 9, z + 1, b, mc);
		array.setBlock(x + 3, y + 9, z + 2, b, mc);
		array.setBlock(x + 3, y + 9, z + 3, b, ms);
		array.setBlock(x + 3, y + 9, z + 4, b, ms);
		array.setBlock(x + 3, y + 9, z + 5, b, ms);
		array.setBlock(x + 3, y + 9, z + 6, b, ms);
		array.setBlock(x + 3, y + 9, z + 7, b, ms);
		array.setBlock(x + 3, y + 9, z + 8, b, ms);
		array.setBlock(x + 3, y + 9, z + 9, b, ms);
		array.setBlock(x + 3, y + 9, z + 10, b, ms);
		array.setBlock(x + 3, y + 9, z + 11, b, ms);
		array.setBlock(x + 3, y + 9, z + 12, b, ms);
		array.setBlock(x + 3, y + 9, z + 13, b, ms);
		array.setBlock(x + 3, y + 9, z + 14, b, mc);
		array.setBlock(x + 3, y + 9, z + 15, b, mc);
		array.setBlock(x + 3, y + 10, z + 1, b, mc);
		array.setBlock(x + 3, y + 10, z + 5, b, mc);
		array.setBlock(x + 3, y + 10, z + 6, b, ms);
		array.setBlock(x + 3, y + 10, z + 7, b, ms);
		array.setBlock(x + 3, y + 10, z + 8, b, ms);
		array.setBlock(x + 3, y + 10, z + 9, b, ms);
		array.setBlock(x + 3, y + 10, z + 10, b, ms);
		array.setBlock(x + 3, y + 10, z + 11, b, mc);
		array.setBlock(x + 3, y + 10, z + 15, b, mc);
		array.setBlock(x + 3, y + 11, z + 5, b, mc);
		array.setBlock(x + 3, y + 11, z + 6, b, ms);
		array.setBlock(x + 3, y + 11, z + 7, b, ms);
		array.setBlock(x + 3, y + 11, z + 8, b, ms);
		array.setBlock(x + 3, y + 11, z + 9, b, ms);
		array.setBlock(x + 3, y + 11, z + 10, b, ms);
		array.setBlock(x + 3, y + 11, z + 11, b, mc);
		array.setBlock(x + 3, y + 12, z + 5, b, mc);
		array.setBlock(x + 3, y + 12, z + 6, b, mc);
		array.setBlock(x + 3, y + 12, z + 7, b, mc);
		array.setBlock(x + 3, y + 12, z + 8, b, mc);
		array.setBlock(x + 3, y + 12, z + 9, b, mc);
		array.setBlock(x + 3, y + 12, z + 10, b, mc);
		array.setBlock(x + 3, y + 12, z + 11, b, mc);
		array.setBlock(x + 3, y + 13, z + 5, b, mc);
		array.setBlock(x + 3, y + 13, z + 11, b, mc);
		array.setBlock(x + 4, y + 3, z + 4, b, ms);
		array.setBlock(x + 4, y + 3, z + 5, b, BlockType.CLOAK.metadata);
		array.setBlock(x + 4, y + 3, z + 6, b, BlockType.CLOAK.metadata);
		array.setBlock(x + 4, y + 3, z + 7, b, BlockType.CLOAK.metadata);
		array.setBlock(x + 4, y + 3, z + 8, b, BlockType.CLOAK.metadata);
		array.setBlock(x + 4, y + 3, z + 9, b, BlockType.CLOAK.metadata);
		array.setBlock(x + 4, y + 3, z + 10, b, BlockType.CLOAK.metadata);
		array.setBlock(x + 4, y + 3, z + 11, b, BlockType.CLOAK.metadata);
		array.setBlock(x + 4, y + 3, z + 12, b, BlockType.CLOAK.metadata);
		array.setBlock(x + 4, y + 3, z + 13, b, BlockType.CLOAK.metadata);
		array.setBlock(x + 4, y + 3, z + 14, b, ms);
		array.setBlock(x + 4, y + 4, z + 2, b, ms);
		array.setBlock(x + 4, y + 4, z + 3, b, ms);
		array.setBlock(x + 4, y + 4, z + 4, b, ms);
		array.setBlock(x + 4, y + 4, z + 14, b, ms);
		array.setBlock(x + 4, y + 4, z + 15, b, ms);
		array.setBlock(x + 4, y + 5, z + 1, b, ms);
		array.setBlock(x + 4, y + 5, z + 2, b2);
		array.setBlock(x + 4, y + 5, z + 3, b2);
		array.setBlock(x + 4, y + 5, z + 4, b2);
		array.setBlock(x + 4, y + 5, z + 5, b2);
		array.setBlock(x + 4, y + 5, z + 6, b2);
		array.setBlock(x + 4, y + 5, z + 7, b2);
		array.setBlock(x + 4, y + 5, z + 8, b2);
		array.setBlock(x + 4, y + 5, z + 9, b2);
		array.setBlock(x + 4, y + 5, z + 10, b, ms);
		array.setBlock(x + 4, y + 5, z + 11, b2);
		array.setBlock(x + 4, y + 5, z + 12, b2);
		array.setBlock(x + 4, y + 5, z + 13, b2);
		array.setBlock(x + 4, y + 5, z + 14, b2);
		array.setBlock(x + 4, y + 5, z + 15, b, ms);
		array.setBlock(x + 4, y + 6, z + 1, b, mg);
		array.setBlock(x + 4, y + 6, z + 10, b, ms);
		array.setBlock(x + 4, y + 6, z + 15, b, mg);
		array.setBlock(x + 4, y + 7, z + 1, b, mg);
		array.setBlock(x + 4, y + 7, z + 10, b, ms);
		array.setBlock(x + 4, y + 7, z + 15, b, mg);
		array.setBlock(x + 4, y + 8, z + 1, b, mg);
		array.setBlock(x + 4, y + 8, z + 10, b, ms);
		array.setBlock(x + 4, y + 8, z + 15, b, mg);
		array.setBlock(x + 4, y + 9, z + 1, b, mc);
		array.setBlock(x + 4, y + 9, z + 2, b, ms);
		array.setBlock(x + 4, y + 9, z + 3, b, ms);
		array.setBlock(x + 4, y + 9, z + 4, b, ms);
		array.setBlock(x + 4, y + 9, z + 5, b, ms);
		array.setBlock(x + 4, y + 9, z + 6, b, ms);
		array.setBlock(x + 4, y + 9, z + 7, b, ms);
		array.setBlock(x + 4, y + 9, z + 8, b, ms);
		array.setBlock(x + 4, y + 9, z + 9, b, ms);
		array.setBlock(x + 4, y + 9, z + 10, b, ms);
		array.setBlock(x + 4, y + 9, z + 11, b, ms);
		array.setBlock(x + 4, y + 9, z + 12, b, ms);
		array.setBlock(x + 4, y + 9, z + 13, b, ms);
		array.setBlock(x + 4, y + 9, z + 14, b, ms);
		array.setBlock(x + 4, y + 9, z + 15, b, mc);
		array.setBlock(x + 4, y + 10, z + 5, b, ms);
		array.setBlock(x + 4, y + 10, z + 6, b, ms);
		array.setBlock(x + 4, y + 10, z + 7, b, ms);
		array.setBlock(x + 4, y + 10, z + 8, ch, 1);
		array.setBlock(x + 4, y + 10, z + 9, b, ms);
		array.setBlock(x + 4, y + 10, z + 10, b, ms);
		array.setBlock(x + 4, y + 10, z + 11, b, ms);
		array.setBlock(x + 4, y + 11, z + 5, b, ms);
		array.setBlock(x + 4, y + 11, z + 6, b, ms);
		array.setBlock(x + 4, y + 11, z + 7, b, ms);
		array.setBlock(x + 4, y + 11, z + 8, b, ms);
		array.setBlock(x + 4, y + 11, z + 9, b, ms);
		array.setBlock(x + 4, y + 11, z + 10, b, ms);
		array.setBlock(x + 4, y + 11, z + 11, b, ms);
		array.setBlock(x + 4, y + 12, z + 5, b, mc);
		array.setBlock(x + 4, y + 12, z + 6, b, ms);
		array.setBlock(x + 4, y + 12, z + 7, b, ms);
		array.setBlock(x + 4, y + 12, z + 8, b, ms);
		array.setBlock(x + 4, y + 12, z + 9, b, ms);
		array.setBlock(x + 4, y + 12, z + 10, b, ms);
		array.setBlock(x + 4, y + 12, z + 11, b, mc);
		array.setBlock(x + 5, y + 1, z + 5, b, ms);
		array.setBlock(x + 5, y + 2, z + 4, b, ms);
		array.setBlock(x + 5, y + 2, z + 5, b, ms);
		array.setBlock(x + 5, y + 2, z + 6, b, ms);
		array.setBlock(x + 5, y + 3, z + 4, b, ms);
		array.setBlock(x + 5, y + 3, z + 5, b, ms);
		array.setBlock(x + 5, y + 3, z + 6, b, BlockType.CLOAK.metadata);
		array.setBlock(x + 5, y + 3, z + 7, b, BlockType.CLOAK.metadata);
		array.setBlock(x + 5, y + 3, z + 8, b, BlockType.CLOAK.metadata);
		array.setBlock(x + 5, y + 3, z + 9, b, BlockType.CLOAK.metadata);
		array.setBlock(x + 5, y + 3, z + 10, b, BlockType.CLOAK.metadata);
		array.setBlock(x + 5, y + 3, z + 11, b, ms);
		array.setBlock(x + 5, y + 3, z + 12, b, BlockType.CLOAK.metadata);
		array.setBlock(x + 5, y + 3, z + 13, b, BlockType.CLOAK.metadata);
		array.setBlock(x + 5, y + 3, z + 14, b, ms);
		array.setBlock(x + 5, y + 4, z + 2, b, ms);
		array.setBlock(x + 5, y + 4, z + 3, b, ms);
		array.setBlock(x + 5, y + 4, z + 4, b, ms);
		array.setBlock(x + 5, y + 4, z + 5, b, ms);
		array.setBlock(x + 5, y + 4, z + 11, b, ms);
		array.setBlock(x + 5, y + 4, z + 14, b, ms);
		array.setBlock(x + 5, y + 4, z + 15, b, ms);
		array.setBlock(x + 5, y + 5, z + 1, b, ms);
		array.setBlock(x + 5, y + 5, z + 2, b2);
		array.setBlock(x + 5, y + 5, z + 3, b2);
		array.setBlock(x + 5, y + 5, z + 4, b2);
		array.setBlock(x + 5, y + 5, z + 5, b, ms);
		array.setBlock(x + 5, y + 5, z + 6, b2);
		array.setBlock(x + 5, y + 5, z + 7, b2);
		array.setBlock(x + 5, y + 5, z + 8, b2);
		array.setBlock(x + 5, y + 5, z + 9, b2);
		array.setBlock(x + 5, y + 5, z + 10, b, ms);
		array.setBlock(x + 5, y + 5, z + 11, b, ms);
		array.setBlock(x + 5, y + 5, z + 12, b2);
		array.setBlock(x + 5, y + 5, z + 13, b2);
		array.setBlock(x + 5, y + 5, z + 14, b2);
		array.setBlock(x + 5, y + 5, z + 15, b, ms);
		array.setBlock(x + 5, y + 6, z + 1, b, mg);
		array.setBlock(x + 5, y + 6, z + 5, b, ms);
		array.setBlock(x + 5, y + 6, z + 10, b, ms);
		array.setBlock(x + 5, y + 6, z + 11, b, ms);
		array.setBlock(x + 5, y + 6, z + 15, b, mg);
		array.setBlock(x + 5, y + 7, z + 1, b, mg);
		array.setBlock(x + 5, y + 7, z + 5, b, BlockType.LIGHT.metadata);
		array.setBlock(x + 5, y + 7, z + 10, ch, 2);
		array.setBlock(x + 5, y + 7, z + 11, b, BlockType.LIGHT.metadata);
		array.setBlock(x + 5, y + 7, z + 15, b, mg);
		array.setBlock(x + 5, y + 8, z + 1, b, mg);
		array.setBlock(x + 5, y + 8, z + 5, b, ms);
		array.setBlock(x + 5, y + 8, z + 10, b, ms);
		array.setBlock(x + 5, y + 8, z + 11, b, ms);
		array.setBlock(x + 5, y + 8, z + 15, b, mg);
		array.setBlock(x + 5, y + 9, z + 1, b, mc);
		array.setBlock(x + 5, y + 9, z + 2, b, ms);
		array.setBlock(x + 5, y + 9, z + 3, b, ms);
		array.setBlock(x + 5, y + 9, z + 4, b, ms);
		array.setBlock(x + 5, y + 9, z + 5, b, ms);
		array.setBlock(x + 5, y + 9, z + 6, b, ms);
		array.setBlock(x + 5, y + 9, z + 7, b, ms);
		array.setBlock(x + 5, y + 9, z + 8, b, ms);
		array.setBlock(x + 5, y + 9, z + 9, b, ms);
		array.setBlock(x + 5, y + 9, z + 10, b, ms);
		array.setBlock(x + 5, y + 9, z + 11, b, ms);
		array.setBlock(x + 5, y + 9, z + 12, b, ms);
		array.setBlock(x + 5, y + 9, z + 13, b, ms);
		array.setBlock(x + 5, y + 9, z + 14, b, ms);
		array.setBlock(x + 5, y + 9, z + 15, b, mc);
		array.setBlock(x + 5, y + 10, z + 1, b, mc);
		array.setBlock(x + 5, y + 10, z + 2, b, mc);
		array.setBlock(x + 5, y + 10, z + 3, b, mc);
		array.setBlock(x + 5, y + 10, z + 4, b, ms);
		array.setBlock(x + 5, y + 10, z + 5, b, ms);
		array.setBlock(x + 5, y + 10, z + 11, b, ms);
		array.setBlock(x + 5, y + 10, z + 12, b, 3);
		array.setBlock(x + 5, y + 10, z + 13, b, mc);
		array.setBlock(x + 5, y + 10, z + 14, b, mc);
		array.setBlock(x + 5, y + 10, z + 15, b, mc);
		array.setBlock(x + 5, y + 11, z + 3, b, mc);
		array.setBlock(x + 5, y + 11, z + 4, b, ms);
		array.setBlock(x + 5, y + 11, z + 5, b, ms);
		array.setBlock(x + 5, y + 11, z + 11, b, ms);
		array.setBlock(x + 5, y + 11, z + 12, b, 3);
		array.setBlock(x + 5, y + 11, z + 13, b, mc);
		array.setBlock(x + 5, y + 12, z + 3, b, mc);
		array.setBlock(x + 5, y + 12, z + 4, b, mc);
		array.setBlock(x + 5, y + 12, z + 5, b, mc);
		array.setBlock(x + 5, y + 12, z + 6, b, mc);
		array.setBlock(x + 5, y + 12, z + 7, b, ms);
		array.setBlock(x + 5, y + 12, z + 8, b, ms);
		array.setBlock(x + 5, y + 12, z + 9, b, ms);
		array.setBlock(x + 5, y + 12, z + 10, b, mc);
		array.setBlock(x + 5, y + 12, z + 11, b, mc);
		array.setBlock(x + 5, y + 12, z + 12, b, mc);
		array.setBlock(x + 5, y + 12, z + 13, b, mc);
		array.setBlock(x + 5, y + 13, z + 3, b, mc);
		array.setBlock(x + 5, y + 13, z + 13, b, mc);
		array.setBlock(x + 6, y + 0, z + 5, b, ms);
		array.setBlock(x + 6, y + 1, z + 4, b, ms);
		array.setBlock(x + 6, y + 1, z + 5, b, BlockType.LIGHT.metadata);
		array.setBlock(x + 6, y + 1, z + 6, b, ms);
		array.setBlock(x + 6, y + 1, z + 7, b, ms);
		array.setBlock(x + 6, y + 2, z + 4, b, ms);
		array.setBlock(x + 6, y + 2, z + 5, ch, 1);
		array.setBlock(x + 6, y + 2, z + 6, b, ms);
		array.setBlock(x + 6, y + 2, z + 7, b, ms);
		array.setBlock(x + 6, y + 2, z + 8, b, ms);
		array.setBlock(x + 6, y + 2, z + 9, b, ms);
		array.setBlock(x + 6, y + 3, z + 4, b, ms);
		array.setBlock(x + 6, y + 3, z + 5, b, ms);
		array.setBlock(x + 6, y + 3, z + 6, b, ms);
		array.setBlock(x + 6, y + 3, z + 7, b, ms);
		array.setBlock(x + 6, y + 3, z + 8, b, ms);
		array.setBlock(x + 6, y + 3, z + 9, b, ms);
		array.setBlock(x + 6, y + 3, z + 10, b, ms);
		array.setBlock(x + 6, y + 3, z + 11, b, BlockType.CLOAK.metadata);
		array.setBlock(x + 6, y + 3, z + 12, b, BlockType.CLOAK.metadata);
		array.setBlock(x + 6, y + 3, z + 13, b, BlockType.CLOAK.metadata);
		array.setBlock(x + 6, y + 3, z + 14, b, ms);
		array.setBlock(x + 6, y + 4, z + 2, b, ms);
		array.setBlock(x + 6, y + 4, z + 3, b, ms);
		array.setBlock(x + 6, y + 4, z + 4, b, ms);
		array.setBlock(x + 6, y + 4, z + 5, b, ms);
		array.setBlock(x + 6, y + 4, z + 6, b, ms);
		array.setBlock(x + 6, y + 4, z + 7, b, ms);
		array.setBlock(x + 6, y + 4, z + 8, b, ms);
		array.setBlock(x + 6, y + 4, z + 9, b, ms);
		array.setBlock(x + 6, y + 4, z + 10, b, ms);
		array.setBlock(x + 6, y + 4, z + 14, b, ms);
		array.setBlock(x + 6, y + 4, z + 15, b, ms);
		array.setBlock(x + 6, y + 5, z + 0, b, BlockType.MOSS.metadata);
		array.setBlock(x + 6, y + 5, z + 1, b, ms);
		array.setBlock(x + 6, y + 5, z + 2, b2);
		array.setBlock(x + 6, y + 5, z + 3, b2);
		array.setBlock(x + 6, y + 5, z + 4, b, ms);
		array.setBlock(x + 6, y + 5, z + 5, b, ms);
		array.setBlock(x + 6, y + 5, z + 6, b, ms);
		array.setBlock(x + 6, y + 5, z + 7, b, ms);
		array.setBlock(x + 6, y + 5, z + 8, b, ms);
		array.setBlock(x + 6, y + 5, z + 9, b, ms);
		array.setBlock(x + 6, y + 5, z + 10, b, ms);
		array.setBlock(x + 6, y + 5, z + 11, b2);
		array.setBlock(x + 6, y + 5, z + 12, b2);
		array.setBlock(x + 6, y + 5, z + 13, b2);
		array.setBlock(x + 6, y + 5, z + 14, b2);
		array.setBlock(x + 6, y + 5, z + 15, b, ms);
		array.setBlock(x + 6, y + 5, z + 16, b, BlockType.MOSS.metadata);
		array.setBlock(x + 6, y + 6, z + 1, b, mg);
		array.setBlock(x + 6, y + 6, z + 4, b, ms);
		array.setBlock(x + 6, y + 6, z + 5, b, ms);
		array.setBlock(x + 6, y + 6, z + 6, b, ms);
		array.setBlock(x + 6, y + 6, z + 7, b, ms);
		array.setBlock(x + 6, y + 6, z + 8, b, ms);
		array.setBlock(x + 6, y + 6, z + 9, b, ms);
		array.setBlock(x + 6, y + 6, z + 10, b, ms);
		array.setBlock(x + 6, y + 6, z + 15, b, mg);
		array.setBlock(x + 6, y + 7, z + 1, b, mg);
		array.setBlock(x + 6, y + 7, z + 4, b, ms);
		array.setBlock(x + 6, y + 7, z + 5, ch, 1);
		array.setBlock(x + 6, y + 7, z + 6, b, ms);
		array.setBlock(x + 6, y + 7, z + 7, b, ms);
		array.setBlock(x + 6, y + 7, z + 8, b, ms);
		array.setBlock(x + 6, y + 7, z + 9, b, ms);
		array.setBlock(x + 6, y + 7, z + 10, b, ms);
		array.setBlock(x + 6, y + 7, z + 15, b, mg);
		array.setBlock(x + 6, y + 8, z + 1, b, mg);
		array.setBlock(x + 6, y + 8, z + 4, b, ms);
		array.setBlock(x + 6, y + 8, z + 5, b, ms);
		array.setBlock(x + 6, y + 8, z + 6, b, ms);
		array.setBlock(x + 6, y + 8, z + 7, b, ms);
		array.setBlock(x + 6, y + 8, z + 8, b, ms);
		array.setBlock(x + 6, y + 8, z + 9, b, ms);
		array.setBlock(x + 6, y + 8, z + 10, b, ms);
		array.setBlock(x + 6, y + 8, z + 15, b, mg);
		array.setBlock(x + 6, y + 9, z + 1, b, mc);
		array.setBlock(x + 6, y + 9, z + 2, b, ms);
		array.setBlock(x + 6, y + 9, z + 3, b, ms);
		array.setBlock(x + 6, y + 9, z + 4, b, ms);
		array.setBlock(x + 6, y + 9, z + 5, b, ms);
		array.setBlock(x + 6, y + 9, z + 6, b, ms);
		array.setBlock(x + 6, y + 9, z + 7, b, ms);
		array.setBlock(x + 6, y + 9, z + 8, b, ms);
		array.setBlock(x + 6, y + 9, z + 9, b, ms);
		array.setBlock(x + 6, y + 9, z + 10, b, ms);
		array.setBlock(x + 6, y + 9, z + 11, b, ms);
		array.setBlock(x + 6, y + 9, z + 12, b, ms);
		array.setBlock(x + 6, y + 9, z + 13, b, ms);
		array.setBlock(x + 6, y + 9, z + 14, b, ms);
		array.setBlock(x + 6, y + 9, z + 15, b, mc);
		array.setBlock(x + 6, y + 10, z + 2, b, ms);
		array.setBlock(x + 6, y + 10, z + 3, b, ms);
		array.setBlock(x + 6, y + 10, z + 4, b, ms);
		array.setBlock(x + 6, y + 10, z + 12, b, 3);
		array.setBlock(x + 6, y + 10, z + 13, b, ms);
		array.setBlock(x + 6, y + 10, z + 14, b, ms);
		array.setBlock(x + 6, y + 11, z + 3, b, ms);
		array.setBlock(x + 6, y + 11, z + 4, b, ms);
		array.setBlock(x + 6, y + 11, z + 12, b, 3);
		array.setBlock(x + 6, y + 11, z + 13, b, ms);
		array.setBlock(x + 6, y + 12, z + 3, b, mc);
		array.setBlock(x + 6, y + 12, z + 4, b, ms);
		array.setBlock(x + 6, y + 12, z + 5, b, mc);
		array.setBlock(x + 6, y + 12, z + 6, b, mc);
		array.setBlock(x + 6, y + 12, z + 7, b, mc);
		array.setBlock(x + 6, y + 12, z + 8, b, mc);
		array.setBlock(x + 6, y + 12, z + 9, b, mc);
		array.setBlock(x + 6, y + 12, z + 10, b, mc);
		array.setBlock(x + 6, y + 12, z + 11, b, mc);
		array.setBlock(x + 6, y + 12, z + 12, b, ms);
		array.setBlock(x + 6, y + 12, z + 13, b, mc);
		array.setBlock(x + 6, y + 13, z + 6, b, mc);
		array.setBlock(x + 6, y + 13, z + 7, b, mc);
		array.setBlock(x + 6, y + 13, z + 8, b, mc);
		array.setBlock(x + 6, y + 13, z + 9, b, mc);
		array.setBlock(x + 6, y + 13, z + 10, b, mc);
		array.setBlock(x + 6, y + 14, z + 6, b, mc);
		array.setBlock(x + 6, y + 14, z + 10, b, mc);
		array.setBlock(x + 7, y + 0, z + 5, b, ms);
		array.setBlock(x + 7, y + 1, z + 4, b, ms);
		array.setBlock(x + 7, y + 1, z + 5, b, ms);
		array.setBlock(x + 7, y + 1, z + 6, b, ms);
		array.setBlock(x + 7, y + 1, z + 7, b, ms);
		array.setBlock(x + 7, y + 2, z + 3, b, ms);
		array.setBlock(x + 7, y + 2, z + 4, b, ms);
		array.setBlock(x + 7, y + 2, z + 8, b, ms);
		array.setBlock(x + 7, y + 2, z + 9, b, ms);
		array.setBlock(x + 7, y + 3, z + 3, b, ms);
		array.setBlock(x + 7, y + 3, z + 4, b, ms);
		array.setBlock(x + 7, y + 3, z + 9, b, ms);
		array.setBlock(x + 7, y + 3, z + 10, b, ms);
		array.setBlock(x + 7, y + 3, z + 11, b, BlockType.CLOAK.metadata);
		array.setBlock(x + 7, y + 3, z + 12, b, BlockType.CLOAK.metadata);
		array.setBlock(x + 7, y + 3, z + 13, b, BlockType.CLOAK.metadata);
		array.setBlock(x + 7, y + 3, z + 14, b, ms);
		array.setBlock(x + 7, y + 4, z + 2, b, ms);
		array.setBlock(x + 7, y + 4, z + 3, b, ms);
		array.setBlock(x + 7, y + 4, z + 4, b, ms);
		array.setBlock(x + 7, y + 4, z + 5, b, ms);
		array.setBlock(x + 7, y + 4, z + 10, b, ms);
		array.setBlock(x + 7, y + 4, z + 14, b, ms);
		array.setBlock(x + 7, y + 4, z + 15, b, ms);
		array.setBlock(x + 7, y + 5, z + 0, b, BlockType.MOSS.metadata);
		array.setBlock(x + 7, y + 5, z + 1, b, ms);
		array.setBlock(x + 7, y + 5, z + 2, b, ms);
		array.setBlock(x + 7, y + 5, z + 3, b, ms);
		array.setBlock(x + 7, y + 5, z + 4, b2);
		array.setBlock(x + 7, y + 5, z + 5, b2);
		array.setBlock(x + 7, y + 5, z + 6, b, ms);
		array.setBlock(x + 7, y + 5, z + 11, b2);
		array.setBlock(x + 7, y + 5, z + 12, b2);
		array.setBlock(x + 7, y + 5, z + 13, b2);
		array.setBlock(x + 7, y + 5, z + 14, b2);
		array.setBlock(x + 7, y + 5, z + 15, b, ms);
		array.setBlock(x + 7, y + 5, z + 16, b, BlockType.MOSS.metadata);
		array.setBlock(x + 7, y + 6, z + 1, b, mc);
		array.setBlock(x + 7, y + 6, z + 2, b, ms);
		array.setBlock(x + 7, y + 6, z + 3, b, ms);
		array.setBlock(x + 7, y + 6, z + 6, b, ms);
		array.setBlock(x + 7, y + 6, z + 15, b, mc);
		array.setBlock(x + 7, y + 7, z + 1, b, mc);
		array.setBlock(x + 7, y + 7, z + 2, b, ms);
		array.setBlock(x + 7, y + 7, z + 3, b, ms);
		array.setBlock(x + 7, y + 7, z + 6, b, ms);
		array.setBlock(x + 7, y + 7, z + 15, b, mc);
		array.setBlock(x + 7, y + 8, z + 1, b, mc);
		array.setBlock(x + 7, y + 8, z + 2, b, ms);
		array.setBlock(x + 7, y + 8, z + 3, b, ms);
		array.setBlock(x + 7, y + 8, z + 6, b, ms);
		array.setBlock(x + 7, y + 8, z + 15, b, mc);
		array.setBlock(x + 7, y + 9, z + 1, b, mc);
		array.setBlock(x + 7, y + 9, z + 2, b, ms);
		array.setBlock(x + 7, y + 9, z + 3, b, ms);
		array.setBlock(x + 7, y + 9, z + 4, b, ms);
		array.setBlock(x + 7, y + 9, z + 5, b, ms);
		array.setBlock(x + 7, y + 9, z + 6, b, ms);
		array.setBlock(x + 7, y + 9, z + 7, b, mg);
		array.setBlock(x + 7, y + 9, z + 8, b, mg);
		array.setBlock(x + 7, y + 9, z + 9, b, mg);
		array.setBlock(x + 7, y + 9, z + 10, b, ms);
		array.setBlock(x + 7, y + 9, z + 11, b, ms);
		array.setBlock(x + 7, y + 9, z + 12, b, ms);
		array.setBlock(x + 7, y + 9, z + 13, b, ms);
		array.setBlock(x + 7, y + 9, z + 14, b, ms);
		array.setBlock(x + 7, y + 9, z + 15, b, mc);
		array.setBlock(x + 7, y + 10, z + 2, b, ms);
		array.setBlock(x + 7, y + 10, z + 3, b, ms);
		array.setBlock(x + 7, y + 10, z + 4, b, ms);
		array.setBlock(x + 7, y + 10, z + 7, b, mg);
		array.setBlock(x + 7, y + 10, z + 8, b, mg);
		array.setBlock(x + 7, y + 10, z + 9, b, mg);
		array.setBlock(x + 7, y + 10, z + 12, b, ms);
		array.setBlock(x + 7, y + 10, z + 13, b, ms);
		array.setBlock(x + 7, y + 10, z + 14, b, ms);
		array.setBlock(x + 7, y + 11, z + 3, b, ms);
		array.setBlock(x + 7, y + 11, z + 4, b, ms);
		array.setBlock(x + 7, y + 11, z + 7, b, mg);
		array.setBlock(x + 7, y + 11, z + 8, b, mg);
		array.setBlock(x + 7, y + 11, z + 9, b, mg);
		array.setBlock(x + 7, y + 11, z + 12, b, ms);
		array.setBlock(x + 7, y + 11, z + 13, b, ms);
		array.setBlock(x + 7, y + 12, z + 3, b, mc);
		array.setBlock(x + 7, y + 12, z + 4, b, ms);
		array.setBlock(x + 7, y + 12, z + 5, b, ms);
		array.setBlock(x + 7, y + 12, z + 6, b, mc);
		array.setBlock(x + 7, y + 12, z + 7, b, mg);
		array.setBlock(x + 7, y + 12, z + 8, b, mg);
		array.setBlock(x + 7, y + 12, z + 9, b, mg);
		array.setBlock(x + 7, y + 12, z + 10, b, mc);
		array.setBlock(x + 7, y + 12, z + 11, b, ms);
		array.setBlock(x + 7, y + 12, z + 12, b, ms);
		array.setBlock(x + 7, y + 12, z + 13, b, mc);
		array.setBlock(x + 7, y + 13, z + 6, b, mc);
		array.setBlock(x + 7, y + 13, z + 10, b, mc);
		array.setBlock(x + 8, y + 0, z + 4, b, ms);
		array.setBlock(x + 8, y + 0, z + 5, b, ms);
		array.setBlock(x + 8, y + 1, z + 3, b, ms);
		array.setBlock(x + 8, y + 1, z + 4, b, BlockType.LIGHT.metadata);
		array.setBlock(x + 8, y + 1, z + 5, b, ms);
		array.setBlock(x + 8, y + 1, z + 6, b, ms);
		array.setBlock(x + 8, y + 1, z + 7, b, ms);
		array.setBlock(x + 8, y + 2, z + 3, b, ms);
		array.setBlock(x + 8, y + 2, z + 4, ch, 3);
		array.setBlock(x + 8, y + 2, z + 8, b, ms);
		array.setBlock(x + 8, y + 2, z + 9, b, ms);
		array.setBlock(x + 8, y + 3, z + 3, b, ms);
		array.setBlock(x + 8, y + 3, z + 4, b, ms);

		array.setBlock(x + 8, y + 3, z + 9, b, ms);
		array.setBlock(x + 8, y + 3, z + 10, b, ms);
		array.setBlock(x + 8, y + 3, z + 11, b, BlockType.CLOAK.metadata);
		array.setBlock(x + 8, y + 3, z + 12, b, BlockType.CLOAK.metadata);
		array.setBlock(x + 8, y + 3, z + 13, b, BlockType.CLOAK.metadata);
		array.setBlock(x + 8, y + 3, z + 14, b, ms);
		array.setBlock(x + 8, y + 4, z + 1, b, ms);
		array.setBlock(x + 8, y + 4, z + 2, b, ms);
		array.setBlock(x + 8, y + 4, z + 3, b, ms);
		array.setBlock(x + 8, y + 4, z + 4, b, ms);
		array.setBlock(x + 8, y + 4, z + 5, b, ms);
		array.setBlock(x + 8, y + 4, z + 10, b, ms);
		array.setBlock(x + 8, y + 4, z + 14, b, ms);
		array.setBlock(x + 8, y + 4, z + 15, b, ms);
		array.setBlock(x + 8, y + 5, z + 0, b, BlockType.MOSS.metadata);
		array.setBlock(x + 8, y + 5, z + 1, b2);
		array.setBlock(x + 8, y + 5, z + 2, b2);
		array.setBlock(x + 8, y + 5, z + 3, b2);
		array.setBlock(x + 8, y + 5, z + 4, b2);
		array.setBlock(x + 8, y + 5, z + 5, b2);
		array.setBlock(x + 8, y + 5, z + 6, b, ms);
		array.setBlock(x + 8, y + 5, z + 11, b2);
		array.setBlock(x + 8, y + 5, z + 12, b2);
		array.setBlock(x + 8, y + 5, z + 13, b2);
		array.setBlock(x + 8, y + 5, z + 14, b2);
		array.setBlock(x + 8, y + 5, z + 15, b2);
		array.setBlock(x + 8, y + 5, z + 16, b, BlockType.MOSS.metadata);
		array.setBlock(x + 8, y + 6, z + 6, b, ms);
		array.setBlock(x + 8, y + 7, z + 6, b, ms);
		array.setBlock(x + 8, y + 8, z + 1, b, mc);
		array.setBlock(x + 8, y + 8, z + 6, b, ms);
		array.setBlock(x + 8, y + 8, z + 15, b, mc);
		array.setBlock(x + 8, y + 9, z + 1, b, mc);
		array.setBlock(x + 8, y + 9, z + 2, b, ms);
		array.setBlock(x + 8, y + 9, z + 3, b, ms);
		array.setBlock(x + 8, y + 9, z + 4, b, ms);
		array.setBlock(x + 8, y + 9, z + 5, b, ms);
		array.setBlock(x + 8, y + 9, z + 6, b, ms);
		array.setBlock(x + 8, y + 9, z + 7, b, mg);
		array.setBlock(x + 8, y + 9, z + 8, b, mg);
		array.setBlock(x + 8, y + 9, z + 9, b, mg);
		array.setBlock(x + 8, y + 9, z + 10, b, ms);
		array.setBlock(x + 8, y + 9, z + 11, b, ms);
		array.setBlock(x + 8, y + 9, z + 12, b, ms);
		array.setBlock(x + 8, y + 9, z + 13, b, ms);
		array.setBlock(x + 8, y + 9, z + 14, b, ms);
		array.setBlock(x + 8, y + 9, z + 15, b, mc);
		array.setBlock(x + 8, y + 10, z + 2, b, ms);
		array.setBlock(x + 8, y + 10, z + 3, b, ms);
		array.setBlock(x + 8, y + 10, z + 4, ch, 3);
		array.setBlock(x + 8, y + 10, z + 7, b, mg);
		array.setBlock(x + 8, y + 10, z + 8, b, mg);
		array.setBlock(x + 8, y + 10, z + 9, b, mg);
		array.setBlock(x + 8, y + 10, z + 12, ch, 2);
		array.setBlock(x + 8, y + 10, z + 13, b, ms);
		array.setBlock(x + 8, y + 10, z + 14, b, ms);
		array.setBlock(x + 8, y + 11, z + 3, b, ms);
		array.setBlock(x + 8, y + 11, z + 4, b, ms);
		array.setBlock(x + 8, y + 11, z + 7, b, mg);
		array.setBlock(x + 8, y + 11, z + 8, b, mg);
		array.setBlock(x + 8, y + 11, z + 9, b, mg);
		array.setBlock(x + 8, y + 11, z + 12, b, ms);
		array.setBlock(x + 8, y + 11, z + 13, b, ms);
		array.setBlock(x + 8, y + 12, z + 3, b, mc);
		array.setBlock(x + 8, y + 12, z + 4, b, ms);
		array.setBlock(x + 8, y + 12, z + 5, b, ms);
		array.setBlock(x + 8, y + 12, z + 6, b, mc);
		array.setBlock(x + 8, y + 12, z + 7, b, mg);
		array.setBlock(x + 8, y + 12, z + 8, b, mg);
		array.setBlock(x + 8, y + 12, z + 9, b, mg);
		array.setBlock(x + 8, y + 12, z + 10, b, mc);
		array.setBlock(x + 8, y + 12, z + 11, b, ms);
		array.setBlock(x + 8, y + 12, z + 12, b, ms);
		array.setBlock(x + 8, y + 12, z + 13, b, mc);
		array.setBlock(x + 8, y + 13, z + 6, b, mc);
		array.setBlock(x + 8, y + 13, z + 10, b, mc);
		array.setBlock(x + 9, y + 0, z + 5, b, ms);
		array.setBlock(x + 9, y + 1, z + 4, b, ms);
		array.setBlock(x + 9, y + 1, z + 5, b, ms);
		array.setBlock(x + 9, y + 1, z + 6, b, ms);
		array.setBlock(x + 9, y + 1, z + 7, b, ms);
		array.setBlock(x + 9, y + 2, z + 3, b, ms);
		array.setBlock(x + 9, y + 2, z + 4, b, ms);
		array.setBlock(x + 9, y + 2, z + 8, b, ms);
		array.setBlock(x + 9, y + 2, z + 9, b, ms);
		array.setBlock(x + 9, y + 3, z + 3, b, ms);
		array.setBlock(x + 9, y + 3, z + 4, b, ms);
		array.setBlock(x + 9, y + 3, z + 9, b, ms);
		array.setBlock(x + 9, y + 3, z + 10, b, ms);
		array.setBlock(x + 9, y + 3, z + 11, b, BlockType.CLOAK.metadata);
		array.setBlock(x + 9, y + 3, z + 12, b, BlockType.CLOAK.metadata);
		array.setBlock(x + 9, y + 3, z + 13, b, ms);
		array.setBlock(x + 9, y + 3, z + 14, b, ms);
		array.setBlock(x + 9, y + 4, z + 2, b, ms);
		array.setBlock(x + 9, y + 4, z + 3, b, ms);
		array.setBlock(x + 9, y + 4, z + 4, b, ms);
		array.setBlock(x + 9, y + 4, z + 5, b, ms);
		array.setBlock(x + 9, y + 4, z + 10, b, ms);
		array.setBlock(x + 9, y + 4, z + 13, b, ms);
		array.setBlock(x + 9, y + 4, z + 14, b, ms);
		array.setBlock(x + 9, y + 4, z + 15, b, ms);
		array.setBlock(x + 9, y + 5, z + 0, b, BlockType.MOSS.metadata);
		array.setBlock(x + 9, y + 5, z + 1, b, ms);
		array.setBlock(x + 9, y + 5, z + 2, b2);
		array.setBlock(x + 9, y + 5, z + 3, b2);
		array.setBlock(x + 9, y + 5, z + 4, b2);
		array.setBlock(x + 9, y + 5, z + 5, b2);
		array.setBlock(x + 9, y + 5, z + 6, b, ms);
		array.setBlock(x + 9, y + 5, z + 11, b2);
		array.setBlock(x + 9, y + 5, z + 12, b2);
		array.setBlock(x + 9, y + 5, z + 13, b, ms);
		array.setBlock(x + 9, y + 5, z + 14, b, ms);
		array.setBlock(x + 9, y + 5, z + 15, b, ms);
		array.setBlock(x + 9, y + 5, z + 16, b, BlockType.MOSS.metadata);
		array.setBlock(x + 9, y + 6, z + 1, b, mc);
		array.setBlock(x + 9, y + 6, z + 6, b, ms);
		array.setBlock(x + 9, y + 6, z + 13, b, ms);
		array.setBlock(x + 9, y + 6, z + 14, b, ms);
		array.setBlock(x + 9, y + 6, z + 15, b, mc);
		array.setBlock(x + 9, y + 7, z + 1, b, mc);
		array.setBlock(x + 9, y + 7, z + 6, b, ms);
		array.setBlock(x + 9, y + 7, z + 13, b, ms);
		array.setBlock(x + 9, y + 7, z + 14, b, ms);
		array.setBlock(x + 9, y + 7, z + 15, b, mc);
		array.setBlock(x + 9, y + 8, z + 1, b, mc);
		array.setBlock(x + 9, y + 8, z + 6, b, ms);
		array.setBlock(x + 9, y + 8, z + 13, b, ms);
		array.setBlock(x + 9, y + 8, z + 14, b, ms);
		array.setBlock(x + 9, y + 8, z + 15, b, mc);
		array.setBlock(x + 9, y + 9, z + 1, b, mc);
		array.setBlock(x + 9, y + 9, z + 2, b, ms);
		array.setBlock(x + 9, y + 9, z + 3, b, ms);
		array.setBlock(x + 9, y + 9, z + 4, b, ms);
		array.setBlock(x + 9, y + 9, z + 5, b, ms);
		array.setBlock(x + 9, y + 9, z + 6, b, ms);
		array.setBlock(x + 9, y + 9, z + 7, b, mg);
		array.setBlock(x + 9, y + 9, z + 8, b, mg);
		array.setBlock(x + 9, y + 9, z + 9, b, mg);
		array.setBlock(x + 9, y + 9, z + 10, b, ms);
		array.setBlock(x + 9, y + 9, z + 11, b, ms);
		array.setBlock(x + 9, y + 9, z + 12, b, ms);
		array.setBlock(x + 9, y + 9, z + 13, b, ms);
		array.setBlock(x + 9, y + 9, z + 14, b, ms);
		array.setBlock(x + 9, y + 9, z + 15, b, mc);
		array.setBlock(x + 9, y + 10, z + 2, b, ms);
		array.setBlock(x + 9, y + 10, z + 3, b, ms);
		array.setBlock(x + 9, y + 10, z + 4, b, ms);
		array.setBlock(x + 9, y + 10, z + 7, b, mg);
		array.setBlock(x + 9, y + 10, z + 8, b, mg);
		array.setBlock(x + 9, y + 10, z + 9, b, mg);
		array.setBlock(x + 9, y + 10, z + 12, b, ms);
		array.setBlock(x + 9, y + 10, z + 13, b, ms);
		array.setBlock(x + 9, y + 10, z + 14, b, ms);
		array.setBlock(x + 9, y + 11, z + 3, b, ms);
		array.setBlock(x + 9, y + 11, z + 4, b, ms);
		array.setBlock(x + 9, y + 11, z + 7, b, mg);
		array.setBlock(x + 9, y + 11, z + 8, b, mg);
		array.setBlock(x + 9, y + 11, z + 9, b, mg);
		array.setBlock(x + 9, y + 11, z + 12, b, ms);
		array.setBlock(x + 9, y + 11, z + 13, b, ms);
		array.setBlock(x + 9, y + 12, z + 3, b, mc);
		array.setBlock(x + 9, y + 12, z + 4, b, ms);
		array.setBlock(x + 9, y + 12, z + 5, b, ms);
		array.setBlock(x + 9, y + 12, z + 6, b, mc);
		array.setBlock(x + 9, y + 12, z + 7, b, mg);
		array.setBlock(x + 9, y + 12, z + 8, b, mg);
		array.setBlock(x + 9, y + 12, z + 9, b, mg);
		array.setBlock(x + 9, y + 12, z + 10, b, mc);
		array.setBlock(x + 9, y + 12, z + 11, b, ms);
		array.setBlock(x + 9, y + 12, z + 12, b, ms);
		array.setBlock(x + 9, y + 12, z + 13, b, mc);
		array.setBlock(x + 9, y + 13, z + 6, b, mc);
		array.setBlock(x + 9, y + 13, z + 10, b, mc);
		array.setBlock(x + 10, y + 0, z + 5, b, ms);
		array.setBlock(x + 10, y + 1, z + 4, b, ms);
		array.setBlock(x + 10, y + 1, z + 5, b, BlockType.LIGHT.metadata);
		array.setBlock(x + 10, y + 1, z + 6, b, ms);
		array.setBlock(x + 10, y + 1, z + 7, b, ms);
		array.setBlock(x + 10, y + 2, z + 4, b, ms);
		array.setBlock(x + 10, y + 2, z + 5, ch);
		array.setBlock(x + 10, y + 2, z + 6, b, ms);
		array.setBlock(x + 10, y + 2, z + 7, b, ms);
		array.setBlock(x + 10, y + 2, z + 8, b, ms);
		array.setBlock(x + 10, y + 2, z + 9, b, ms);
		array.setBlock(x + 10, y + 3, z + 4, b, ms);
		array.setBlock(x + 10, y + 3, z + 5, b, ms);
		array.setBlock(x + 10, y + 3, z + 6, b, ms);
		array.setBlock(x + 10, y + 3, z + 7, b, ms);
		array.setBlock(x + 10, y + 3, z + 8, b, ms);
		array.setBlock(x + 10, y + 3, z + 9, b, ms);
		array.setBlock(x + 10, y + 3, z + 10, b, ms);
		array.setBlock(x + 10, y + 3, z + 11, b, BlockType.CLOAK.metadata);
		array.setBlock(x + 10, y + 3, z + 12, b, BlockType.CLOAK.metadata);
		array.setBlock(x + 10, y + 3, z + 13, b, BlockType.CLOAK.metadata);
		array.setBlock(x + 10, y + 3, z + 14, b, ms);
		array.setBlock(x + 10, y + 4, z + 2, b, ms);
		array.setBlock(x + 10, y + 4, z + 3, b, ms);
		array.setBlock(x + 10, y + 4, z + 4, b, ms);
		array.setBlock(x + 10, y + 4, z + 5, b, ms);
		array.setBlock(x + 10, y + 4, z + 6, b, ms);
		array.setBlock(x + 10, y + 4, z + 7, b, ms);
		array.setBlock(x + 10, y + 4, z + 8, b, ms);
		array.setBlock(x + 10, y + 4, z + 9, b, ms);
		array.setBlock(x + 10, y + 4, z + 10, b, ms);
		array.setBlock(x + 10, y + 4, z + 14, b, ms);
		array.setBlock(x + 10, y + 4, z + 15, b, ms);
		array.setBlock(x + 10, y + 5, z + 0, b, BlockType.MOSS.metadata);
		array.setBlock(x + 10, y + 5, z + 1, b, ms);
		array.setBlock(x + 10, y + 5, z + 2, b2);
		array.setBlock(x + 10, y + 5, z + 3, b2);
		array.setBlock(x + 10, y + 5, z + 4, b2);
		array.setBlock(x + 10, y + 5, z + 5, b2);
		array.setBlock(x + 10, y + 5, z + 6, b, ms);
		array.setBlock(x + 10, y + 5, z + 7, b, ms);
		array.setBlock(x + 10, y + 5, z + 8, b, ms);
		array.setBlock(x + 10, y + 5, z + 9, b, ms);
		array.setBlock(x + 10, y + 5, z + 10, b, ms);
		array.setBlock(x + 10, y + 5, z + 11, b, ms);
		array.setBlock(x + 10, y + 5, z + 12, b, ms);
		array.setBlock(x + 10, y + 5, z + 13, b2);
		array.setBlock(x + 10, y + 5, z + 14, b2);
		array.setBlock(x + 10, y + 5, z + 15, b, ms);
		array.setBlock(x + 10, y + 5, z + 16, b, BlockType.MOSS.metadata);
		array.setBlock(x + 10, y + 6, z + 1, b, mg);
		array.setBlock(x + 10, y + 6, z + 6, b, ms);
		array.setBlock(x + 10, y + 6, z + 7, b, ms);
		array.setBlock(x + 10, y + 6, z + 8, b, ms);
		array.setBlock(x + 10, y + 6, z + 9, b, ms);
		array.setBlock(x + 10, y + 6, z + 10, b, ms);
		array.setBlock(x + 10, y + 6, z + 11, b, ms);
		array.setBlock(x + 10, y + 6, z + 12, b, ms);
		array.setBlock(x + 10, y + 6, z + 15, b, mg);
		array.setBlock(x + 10, y + 7, z + 1, b, mg);
		array.setBlock(x + 10, y + 7, z + 6, b, ms);
		array.setBlock(x + 10, y + 7, z + 7, b, ms);
		array.setBlock(x + 10, y + 7, z + 8, b, ms);
		array.setBlock(x + 10, y + 7, z + 9, b, ms);
		array.setBlock(x + 10, y + 7, z + 10, b, ms);
		array.setBlock(x + 10, y + 7, z + 11, ch);
		array.setBlock(x + 10, y + 7, z + 12, b, ms);
		array.setBlock(x + 10, y + 7, z + 15, b, mg);
		array.setBlock(x + 10, y + 8, z + 1, b, mg);
		array.setBlock(x + 10, y + 8, z + 6, b, ms);
		array.setBlock(x + 10, y + 8, z + 7, b, ms);
		array.setBlock(x + 10, y + 8, z + 8, b, ms);
		array.setBlock(x + 10, y + 8, z + 9, b, ms);
		array.setBlock(x + 10, y + 8, z + 10, b, ms);
		array.setBlock(x + 10, y + 8, z + 11, b, ms);
		array.setBlock(x + 10, y + 8, z + 12, b, ms);
		array.setBlock(x + 10, y + 8, z + 15, b, mg);
		array.setBlock(x + 10, y + 9, z + 1, b, mc);
		array.setBlock(x + 10, y + 9, z + 2, b, ms);
		array.setBlock(x + 10, y + 9, z + 3, b, ms);
		array.setBlock(x + 10, y + 9, z + 4, b, ms);
		array.setBlock(x + 10, y + 9, z + 5, b, ms);
		array.setBlock(x + 10, y + 9, z + 6, b, ms);
		array.setBlock(x + 10, y + 9, z + 7, b, ms);
		array.setBlock(x + 10, y + 9, z + 8, b, ms);
		array.setBlock(x + 10, y + 9, z + 9, b, ms);
		array.setBlock(x + 10, y + 9, z + 10, b, ms);
		array.setBlock(x + 10, y + 9, z + 11, b, ms);
		array.setBlock(x + 10, y + 9, z + 12, b, ms);
		array.setBlock(x + 10, y + 9, z + 13, b, ms);
		array.setBlock(x + 10, y + 9, z + 14, b, ms);
		array.setBlock(x + 10, y + 9, z + 15, b, mc);
		array.setBlock(x + 10, y + 10, z + 2, b, ms);
		array.setBlock(x + 10, y + 10, z + 3, b, ms);
		array.setBlock(x + 10, y + 10, z + 4, b, ms);
		array.setBlock(x + 10, y + 10, z + 12, b, ms);
		array.setBlock(x + 10, y + 10, z + 13, b, ms);
		array.setBlock(x + 10, y + 10, z + 14, b, ms);
		array.setBlock(x + 10, y + 11, z + 3, b, ms);
		array.setBlock(x + 10, y + 11, z + 4, b, ms);
		array.setBlock(x + 10, y + 11, z + 12, b, ms);
		array.setBlock(x + 10, y + 11, z + 13, b, ms);
		array.setBlock(x + 10, y + 12, z + 3, b, mc);
		array.setBlock(x + 10, y + 12, z + 4, b, ms);
		array.setBlock(x + 10, y + 12, z + 5, b, mc);
		array.setBlock(x + 10, y + 12, z + 6, b, mc);
		array.setBlock(x + 10, y + 12, z + 7, b, mc);
		array.setBlock(x + 10, y + 12, z + 8, b, mc);
		array.setBlock(x + 10, y + 12, z + 9, b, mc);
		array.setBlock(x + 10, y + 12, z + 10, b, mc);
		array.setBlock(x + 10, y + 12, z + 11, b, mc);
		array.setBlock(x + 10, y + 12, z + 12, b, ms);
		array.setBlock(x + 10, y + 12, z + 13, b, mc);
		array.setBlock(x + 10, y + 13, z + 6, b, mc);
		array.setBlock(x + 10, y + 13, z + 7, b, mc);
		array.setBlock(x + 10, y + 13, z + 8, b, mc);
		array.setBlock(x + 10, y + 13, z + 9, b, mc);
		array.setBlock(x + 10, y + 13, z + 10, b, mc);
		array.setBlock(x + 10, y + 14, z + 6, b, mc);
		array.setBlock(x + 10, y + 14, z + 10, b, mc);
		array.setBlock(x + 11, y + 1, z + 5, b, ms);
		array.setBlock(x + 11, y + 2, z + 4, b, ms);
		array.setBlock(x + 11, y + 2, z + 5, b, ms);
		array.setBlock(x + 11, y + 2, z + 6, b, ms);
		array.setBlock(x + 11, y + 3, z + 4, b, ms);
		array.setBlock(x + 11, y + 3, z + 5, b, ms);
		array.setBlock(x + 11, y + 3, z + 6, b, ms);
		array.setBlock(x + 11, y + 3, z + 7, b, BlockType.CLOAK.metadata);
		array.setBlock(x + 11, y + 3, z + 8, b, BlockType.CLOAK.metadata);
		array.setBlock(x + 11, y + 3, z + 9, b, BlockType.CLOAK.metadata);
		array.setBlock(x + 11, y + 3, z + 10, b, BlockType.CLOAK.metadata);
		array.setBlock(x + 11, y + 3, z + 11, b, ms);
		array.setBlock(x + 11, y + 3, z + 12, b, BlockType.CLOAK.metadata);
		array.setBlock(x + 11, y + 3, z + 13, b, BlockType.CLOAK.metadata);
		array.setBlock(x + 11, y + 3, z + 14, b, ms);
		array.setBlock(x + 11, y + 4, z + 2, b, ms);
		array.setBlock(x + 11, y + 4, z + 3, b, ms);
		array.setBlock(x + 11, y + 4, z + 4, b, ms);
		array.setBlock(x + 11, y + 4, z + 5, b, ms);
		array.setBlock(x + 11, y + 4, z + 6, b, ms);
		array.setBlock(x + 11, y + 4, z + 11, b, ms);
		array.setBlock(x + 11, y + 4, z + 14, b, ms);
		array.setBlock(x + 11, y + 4, z + 15, b, ms);
		array.setBlock(x + 11, y + 5, z + 1, b, ms);
		array.setBlock(x + 11, y + 5, z + 2, b2);
		array.setBlock(x + 11, y + 5, z + 3, b2);
		array.setBlock(x + 11, y + 5, z + 4, b2);
		array.setBlock(x + 11, y + 5, z + 5, b, ms);
		array.setBlock(x + 11, y + 5, z + 6, b, ms);
		array.setBlock(x + 11, y + 5, z + 7, b2);
		array.setBlock(x + 11, y + 5, z + 8, b2);
		array.setBlock(x + 11, y + 5, z + 9, b2);
		array.setBlock(x + 11, y + 5, z + 10, b2);
		array.setBlock(x + 11, y + 5, z + 11, b, ms);
		array.setBlock(x + 11, y + 5, z + 12, b2);
		array.setBlock(x + 11, y + 5, z + 13, b2);
		array.setBlock(x + 11, y + 5, z + 14, b2);
		array.setBlock(x + 11, y + 5, z + 15, b, ms);
		array.setBlock(x + 11, y + 6, z + 1, b, mg);
		array.setBlock(x + 11, y + 6, z + 5, b, ms);
		array.setBlock(x + 11, y + 6, z + 6, b, ms);
		array.setBlock(x + 11, y + 6, z + 11, b, ms);
		array.setBlock(x + 11, y + 6, z + 15, b, mg);
		array.setBlock(x + 11, y + 7, z + 1, b, mg);
		array.setBlock(x + 11, y + 7, z + 5, b, BlockType.LIGHT.metadata);
		array.setBlock(x + 11, y + 7, z + 6, ch, 3);
		array.setBlock(x + 11, y + 7, z + 11, b, BlockType.LIGHT.metadata);
		array.setBlock(x + 11, y + 7, z + 15, b, mg);
		array.setBlock(x + 11, y + 8, z + 1, b, mg);
		array.setBlock(x + 11, y + 8, z + 5, b, ms);
		array.setBlock(x + 11, y + 8, z + 6, b, ms);
		array.setBlock(x + 11, y + 8, z + 11, b, ms);
		array.setBlock(x + 11, y + 8, z + 15, b, mg);
		array.setBlock(x + 11, y + 9, z + 1, b, mc);
		array.setBlock(x + 11, y + 9, z + 2, b, ms);
		array.setBlock(x + 11, y + 9, z + 3, b, ms);
		array.setBlock(x + 11, y + 9, z + 4, b, ms);
		array.setBlock(x + 11, y + 9, z + 5, b, ms);
		array.setBlock(x + 11, y + 9, z + 6, b, ms);
		array.setBlock(x + 11, y + 9, z + 7, b, ms);
		array.setBlock(x + 11, y + 9, z + 8, b, ms);
		array.setBlock(x + 11, y + 9, z + 9, b, ms);
		array.setBlock(x + 11, y + 9, z + 10, b, ms);
		array.setBlock(x + 11, y + 9, z + 11, b, ms);
		array.setBlock(x + 11, y + 9, z + 12, b, ms);
		array.setBlock(x + 11, y + 9, z + 13, b, ms);
		array.setBlock(x + 11, y + 9, z + 14, b, ms);
		array.setBlock(x + 11, y + 9, z + 15, b, mc);
		array.setBlock(x + 11, y + 10, z + 1, b, mc);
		array.setBlock(x + 11, y + 10, z + 2, b, mc);
		array.setBlock(x + 11, y + 10, z + 3, b, mc);
		array.setBlock(x + 11, y + 10, z + 4, b, ms);
		array.setBlock(x + 11, y + 10, z + 5, b, ms);
		array.setBlock(x + 11, y + 10, z + 11, b, ms);
		array.setBlock(x + 11, y + 10, z + 12, b, ms);
		array.setBlock(x + 11, y + 10, z + 13, b, mc);
		array.setBlock(x + 11, y + 10, z + 14, b, mc);
		array.setBlock(x + 11, y + 10, z + 15, b, mc);
		array.setBlock(x + 11, y + 11, z + 3, b, mc);
		array.setBlock(x + 11, y + 11, z + 4, b, ms);
		array.setBlock(x + 11, y + 11, z + 5, b, ms);
		array.setBlock(x + 11, y + 11, z + 11, b, ms);
		array.setBlock(x + 11, y + 11, z + 12, b, ms);
		array.setBlock(x + 11, y + 11, z + 13, b, mc);
		array.setBlock(x + 11, y + 12, z + 3, b, mc);
		array.setBlock(x + 11, y + 12, z + 4, b, mc);
		array.setBlock(x + 11, y + 12, z + 5, b, mc);
		array.setBlock(x + 11, y + 12, z + 6, b, mc);
		array.setBlock(x + 11, y + 12, z + 7, b, ms);
		array.setBlock(x + 11, y + 12, z + 8, b, ms);
		array.setBlock(x + 11, y + 12, z + 9, b, ms);
		array.setBlock(x + 11, y + 12, z + 10, b, mc);
		array.setBlock(x + 11, y + 12, z + 11, b, mc);
		array.setBlock(x + 11, y + 12, z + 12, b, mc);
		array.setBlock(x + 11, y + 12, z + 13, b, mc);
		array.setBlock(x + 11, y + 13, z + 3, b, mc);
		array.setBlock(x + 11, y + 13, z + 13, b, mc);
		array.setBlock(x + 12, y + 3, z + 6, b, ms);
		array.setBlock(x + 12, y + 3, z + 7, b, BlockType.CLOAK.metadata);
		array.setBlock(x + 12, y + 3, z + 8, b, BlockType.CLOAK.metadata);
		array.setBlock(x + 12, y + 3, z + 9, b, BlockType.CLOAK.metadata);
		array.setBlock(x + 12, y + 3, z + 10, b, BlockType.CLOAK.metadata);
		array.setBlock(x + 12, y + 3, z + 11, b, BlockType.CLOAK.metadata);
		array.setBlock(x + 12, y + 3, z + 12, b, BlockType.CLOAK.metadata);
		array.setBlock(x + 12, y + 3, z + 13, b, BlockType.CLOAK.metadata);
		array.setBlock(x + 12, y + 3, z + 14, b, ms);
		array.setBlock(x + 12, y + 4, z + 2, b, ms);
		array.setBlock(x + 12, y + 4, z + 3, b, ms);
		array.setBlock(x + 12, y + 4, z + 4, b, ms);
		array.setBlock(x + 12, y + 4, z + 5, b, ms);
		array.setBlock(x + 12, y + 4, z + 6, b, ms);
		array.setBlock(x + 12, y + 4, z + 14, b, ms);
		array.setBlock(x + 12, y + 4, z + 15, b, ms);
		array.setBlock(x + 12, y + 5, z + 1, b, ms);
		array.setBlock(x + 12, y + 5, z + 2, b2);
		array.setBlock(x + 12, y + 5, z + 3, b2);
		array.setBlock(x + 12, y + 5, z + 4, b2);
		array.setBlock(x + 12, y + 5, z + 5, b2);
		array.setBlock(x + 12, y + 5, z + 6, b, ms);
		array.setBlock(x + 12, y + 5, z + 7, b2);
		array.setBlock(x + 12, y + 5, z + 8, b2);
		array.setBlock(x + 12, y + 5, z + 9, b2);
		array.setBlock(x + 12, y + 5, z + 10, b2);
		array.setBlock(x + 12, y + 5, z + 11, b2);
		array.setBlock(x + 12, y + 5, z + 12, b2);
		array.setBlock(x + 12, y + 5, z + 13, b2);
		array.setBlock(x + 12, y + 5, z + 14, b2);
		array.setBlock(x + 12, y + 5, z + 15, b, ms);
		array.setBlock(x + 12, y + 6, z + 1, b, mg);
		array.setBlock(x + 12, y + 6, z + 6, b, ms);
		array.setBlock(x + 12, y + 6, z + 15, b, mg);
		array.setBlock(x + 12, y + 7, z + 1, b, mg);
		array.setBlock(x + 12, y + 7, z + 6, b, ms);
		array.setBlock(x + 12, y + 7, z + 15, b, mg);
		array.setBlock(x + 12, y + 8, z + 1, b, mg);
		array.setBlock(x + 12, y + 8, z + 6, b, ms);
		array.setBlock(x + 12, y + 8, z + 15, b, mg);
		array.setBlock(x + 12, y + 9, z + 1, b, mc);
		array.setBlock(x + 12, y + 9, z + 2, b, ms);
		array.setBlock(x + 12, y + 9, z + 3, b, ms);
		array.setBlock(x + 12, y + 9, z + 4, b, ms);
		array.setBlock(x + 12, y + 9, z + 5, b, ms);
		array.setBlock(x + 12, y + 9, z + 6, b, ms);
		array.setBlock(x + 12, y + 9, z + 7, b, ms);
		array.setBlock(x + 12, y + 9, z + 8, b, ms);
		array.setBlock(x + 12, y + 9, z + 9, b, ms);
		array.setBlock(x + 12, y + 9, z + 10, b, ms);
		array.setBlock(x + 12, y + 9, z + 11, b, ms);
		array.setBlock(x + 12, y + 9, z + 12, b, ms);
		array.setBlock(x + 12, y + 9, z + 13, b, ms);
		array.setBlock(x + 12, y + 9, z + 14, b, ms);
		array.setBlock(x + 12, y + 9, z + 15, b, mc);
		array.setBlock(x + 12, y + 10, z + 5, b, ms);
		array.setBlock(x + 12, y + 10, z + 6, b, ms);
		array.setBlock(x + 12, y + 10, z + 7, b, ms);
		array.setBlock(x + 12, y + 10, z + 8, ch);
		array.setBlock(x + 12, y + 10, z + 9, b, ms);
		array.setBlock(x + 12, y + 10, z + 10, b, ms);
		array.setBlock(x + 12, y + 10, z + 11, b, ms);
		array.setBlock(x + 12, y + 11, z + 5, b, ms);
		array.setBlock(x + 12, y + 11, z + 6, b, ms);
		array.setBlock(x + 12, y + 11, z + 7, b, ms);
		array.setBlock(x + 12, y + 11, z + 8, b, ms);
		array.setBlock(x + 12, y + 11, z + 9, b, ms);
		array.setBlock(x + 12, y + 11, z + 10, b, ms);
		array.setBlock(x + 12, y + 11, z + 11, b, ms);
		array.setBlock(x + 12, y + 12, z + 5, b, mc);
		array.setBlock(x + 12, y + 12, z + 6, b, ms);
		array.setBlock(x + 12, y + 12, z + 7, b, ms);
		array.setBlock(x + 12, y + 12, z + 8, b, ms);
		array.setBlock(x + 12, y + 12, z + 9, b, ms);
		array.setBlock(x + 12, y + 12, z + 10, b, ms);
		array.setBlock(x + 12, y + 12, z + 11, b, mc);
		array.setBlock(x + 13, y + 3, z + 6, b, ms);
		array.setBlock(x + 13, y + 3, z + 7, b, ms);
		array.setBlock(x + 13, y + 3, z + 8, b, BlockType.CLOAK.metadata);
		array.setBlock(x + 13, y + 3, z + 9, b, BlockType.CLOAK.metadata);
		array.setBlock(x + 13, y + 3, z + 10, b, BlockType.CLOAK.metadata);
		array.setBlock(x + 13, y + 3, z + 11, b, BlockType.CLOAK.metadata);
		array.setBlock(x + 13, y + 3, z + 12, b, BlockType.CLOAK.metadata);
		array.setBlock(x + 13, y + 3, z + 13, b, BlockType.CLOAK.metadata);
		array.setBlock(x + 13, y + 3, z + 14, b, ms);
		array.setBlock(x + 13, y + 4, z + 2, b, ms);
		array.setBlock(x + 13, y + 4, z + 3, b, ms);
		array.setBlock(x + 13, y + 4, z + 4, b, ms);
		array.setBlock(x + 13, y + 4, z + 5, b, ms);
		array.setBlock(x + 13, y + 4, z + 6, b, ms);
		array.setBlock(x + 13, y + 4, z + 7, b, ms);
		array.setBlock(x + 13, y + 4, z + 14, b, ms);
		array.setBlock(x + 13, y + 4, z + 15, b, ms);
		array.setBlock(x + 13, y + 5, z + 1, b, ms);
		array.setBlock(x + 13, y + 5, z + 2, b2);
		array.setBlock(x + 13, y + 5, z + 3, b2);
		array.setBlock(x + 13, y + 5, z + 4, b2);
		array.setBlock(x + 13, y + 5, z + 5, b2);
		array.setBlock(x + 13, y + 5, z + 6, b2);
		array.setBlock(x + 13, y + 5, z + 7, b, ms);
		array.setBlock(x + 13, y + 5, z + 8, b2);
		array.setBlock(x + 13, y + 5, z + 9, b2);
		array.setBlock(x + 13, y + 5, z + 10, b2);
		array.setBlock(x + 13, y + 5, z + 11, b2);
		array.setBlock(x + 13, y + 5, z + 12, b2);
		array.setBlock(x + 13, y + 5, z + 13, b2);
		array.setBlock(x + 13, y + 5, z + 14, b2);
		array.setBlock(x + 13, y + 5, z + 15, b, ms);
		array.setBlock(x + 13, y + 6, z + 1, b, mc);
		array.setBlock(x + 13, y + 6, z + 7, b, ms);
		array.setBlock(x + 13, y + 6, z + 15, b, mc);
		array.setBlock(x + 13, y + 7, z + 1, b, mc);
		array.setBlock(x + 13, y + 7, z + 7, b, ms);
		array.setBlock(x + 13, y + 7, z + 15, b, mc);
		array.setBlock(x + 13, y + 8, z + 1, b, mc);
		array.setBlock(x + 13, y + 8, z + 7, b, ms);
		array.setBlock(x + 13, y + 8, z + 15, b, mc);
		array.setBlock(x + 13, y + 9, z + 1, b, mc);
		array.setBlock(x + 13, y + 9, z + 2, b, mc);
		array.setBlock(x + 13, y + 9, z + 3, b, ms);
		array.setBlock(x + 13, y + 9, z + 4, b, ms);
		array.setBlock(x + 13, y + 9, z + 5, b, ms);
		array.setBlock(x + 13, y + 9, z + 6, b, ms);
		array.setBlock(x + 13, y + 9, z + 7, b, ms);
		array.setBlock(x + 13, y + 9, z + 8, b, ms);
		array.setBlock(x + 13, y + 9, z + 9, b, ms);
		array.setBlock(x + 13, y + 9, z + 10, b, ms);
		array.setBlock(x + 13, y + 9, z + 11, b, ms);
		array.setBlock(x + 13, y + 9, z + 12, b, ms);
		array.setBlock(x + 13, y + 9, z + 13, b, ms);
		array.setBlock(x + 13, y + 9, z + 14, b, mc);
		array.setBlock(x + 13, y + 9, z + 15, b, mc);
		array.setBlock(x + 13, y + 10, z + 1, b, mc);
		array.setBlock(x + 13, y + 10, z + 5, b, mc);
		array.setBlock(x + 13, y + 10, z + 6, b, ms);
		array.setBlock(x + 13, y + 10, z + 7, b, ms);
		array.setBlock(x + 13, y + 10, z + 8, b, ms);
		array.setBlock(x + 13, y + 10, z + 9, b, ms);
		array.setBlock(x + 13, y + 10, z + 10, b, ms);
		array.setBlock(x + 13, y + 10, z + 11, b, mc);
		array.setBlock(x + 13, y + 10, z + 15, b, mc);
		array.setBlock(x + 13, y + 11, z + 5, b, mc);
		array.setBlock(x + 13, y + 11, z + 6, b, ms);
		array.setBlock(x + 13, y + 11, z + 7, b, ms);
		array.setBlock(x + 13, y + 11, z + 8, b, ms);
		array.setBlock(x + 13, y + 11, z + 9, b, ms);
		array.setBlock(x + 13, y + 11, z + 10, b, ms);
		array.setBlock(x + 13, y + 11, z + 11, b, mc);
		array.setBlock(x + 13, y + 12, z + 5, b, mc);
		array.setBlock(x + 13, y + 12, z + 6, b, mc);
		array.setBlock(x + 13, y + 12, z + 7, b, mc);
		array.setBlock(x + 13, y + 12, z + 8, b, mc);
		array.setBlock(x + 13, y + 12, z + 9, b, mc);
		array.setBlock(x + 13, y + 12, z + 10, b, mc);
		array.setBlock(x + 13, y + 12, z + 11, b, mc);
		array.setBlock(x + 13, y + 13, z + 5, b, mc);
		array.setBlock(x + 13, y + 13, z + 11, b, mc);
		array.setBlock(x + 14, y + 3, z + 7, b, ms);
		array.setBlock(x + 14, y + 3, z + 8, b, ms);
		array.setBlock(x + 14, y + 3, z + 9, b, ms);
		array.setBlock(x + 14, y + 3, z + 10, b, ms);
		array.setBlock(x + 14, y + 3, z + 11, b, ms);
		array.setBlock(x + 14, y + 3, z + 12, b, ms);
		array.setBlock(x + 14, y + 3, z + 13, b, ms);
		array.setBlock(x + 14, y + 3, z + 14, b, ms);
		array.setBlock(x + 14, y + 4, z + 3, b, ms);
		array.setBlock(x + 14, y + 4, z + 4, b, ms);
		array.setBlock(x + 14, y + 4, z + 5, b, ms);
		array.setBlock(x + 14, y + 4, z + 6, b, ms);
		array.setBlock(x + 14, y + 4, z + 7, b, ms);
		array.setBlock(x + 14, y + 4, z + 8, b, ms);
		array.setBlock(x + 14, y + 4, z + 9, b, ms);
		array.setBlock(x + 14, y + 4, z + 10, b, ms);
		array.setBlock(x + 14, y + 4, z + 11, b, ms);
		array.setBlock(x + 14, y + 4, z + 12, b, ms);
		array.setBlock(x + 14, y + 4, z + 13, b, ms);
		array.setBlock(x + 14, y + 4, z + 14, Blocks.mob_spawner);
		array.setBlock(x + 14, y + 4, z + 15, b, ms);
		array.setBlock(x + 14, y + 5, z + 2, b, ms);
		array.setBlock(x + 14, y + 5, z + 3, b2);
		array.setBlock(x + 14, y + 5, z + 4, b2);
		array.setBlock(x + 14, y + 5, z + 5, b2);
		array.setBlock(x + 14, y + 5, z + 6, b2);
		array.setBlock(x + 14, y + 5, z + 7, b, ms);
		array.setBlock(x + 14, y + 5, z + 8, b2);
		array.setBlock(x + 14, y + 5, z + 9, b2);
		array.setBlock(x + 14, y + 5, z + 10, b2);
		array.setBlock(x + 14, y + 5, z + 11, b2);
		array.setBlock(x + 14, y + 5, z + 12, b2);
		array.setBlock(x + 14, y + 5, z + 13, b2);
		array.setBlock(x + 14, y + 5, z + 14, b, ms);
		array.setBlock(x + 14, y + 6, z + 2, b, ms);
		array.setBlock(x + 14, y + 6, z + 7, b, ms);
		array.setBlock(x + 14, y + 6, z + 14, b, ms);
		array.setBlock(x + 14, y + 7, z + 2, b, ms);
		array.setBlock(x + 14, y + 7, z + 7, b, ms);
		array.setBlock(x + 14, y + 7, z + 14, b, ms);
		array.setBlock(x + 14, y + 8, z + 2, b, ms);
		array.setBlock(x + 14, y + 8, z + 7, b, ms);
		array.setBlock(x + 14, y + 8, z + 14, b, ms);
		array.setBlock(x + 14, y + 9, z + 2, b, mc);
		array.setBlock(x + 14, y + 9, z + 3, b, mc);
		array.setBlock(x + 14, y + 9, z + 4, b, ms);
		array.setBlock(x + 14, y + 9, z + 5, b, ms);
		array.setBlock(x + 14, y + 9, z + 6, b, ms);
		array.setBlock(x + 14, y + 9, z + 7, b, ms);
		array.setBlock(x + 14, y + 9, z + 8, b, ms);
		array.setBlock(x + 14, y + 9, z + 9, b, ms);
		array.setBlock(x + 14, y + 9, z + 10, b, ms);
		array.setBlock(x + 14, y + 9, z + 11, b, ms);
		array.setBlock(x + 14, y + 9, z + 12, b, ms);
		array.setBlock(x + 14, y + 9, z + 13, b, mc);
		array.setBlock(x + 14, y + 9, z + 14, b, mc);
		array.setBlock(x + 14, y + 10, z + 5, b, mc);
		array.setBlock(x + 14, y + 10, z + 6, b, ms);
		array.setBlock(x + 14, y + 10, z + 7, b, ms);
		array.setBlock(x + 14, y + 10, z + 8, b, ms);
		array.setBlock(x + 14, y + 10, z + 9, b, ms);
		array.setBlock(x + 14, y + 10, z + 10, b, ms);
		array.setBlock(x + 14, y + 10, z + 11, b, mc);
		array.setBlock(x + 15, y + 4, z + 8, b, ms);
		array.setBlock(x + 15, y + 4, z + 9, b, ms);
		array.setBlock(x + 15, y + 4, z + 10, b, ms);
		array.setBlock(x + 15, y + 4, z + 11, b, ms);
		array.setBlock(x + 15, y + 4, z + 12, b, ms);
		array.setBlock(x + 15, y + 4, z + 13, b, ms);
		array.setBlock(x + 15, y + 4, z + 14, b, ms);
		array.setBlock(x + 15, y + 5, z + 3, b, ms);
		array.setBlock(x + 15, y + 5, z + 4, b, ms);
		array.setBlock(x + 15, y + 5, z + 5, b, ms);
		array.setBlock(x + 15, y + 5, z + 6, b, ms);
		array.setBlock(x + 15, y + 5, z + 7, b, ms);
		array.setBlock(x + 15, y + 5, z + 8, b2);
		array.setBlock(x + 15, y + 5, z + 9, b, ms);
		array.setBlock(x + 15, y + 5, z + 10, b, ms);
		array.setBlock(x + 15, y + 5, z + 11, b, ms);
		array.setBlock(x + 15, y + 5, z + 12, b, ms);
		array.setBlock(x + 15, y + 5, z + 13, b, ms);
		array.setBlock(x + 15, y + 6, z + 3, b, mc);
		array.setBlock(x + 15, y + 6, z + 4, b, mg);
		array.setBlock(x + 15, y + 6, z + 5, b, mg);
		array.setBlock(x + 15, y + 6, z + 6, b, mg);
		array.setBlock(x + 15, y + 6, z + 7, b, mc);
		array.setBlock(x + 15, y + 6, z + 9, b, mc);
		array.setBlock(x + 15, y + 6, z + 10, b, mg);
		array.setBlock(x + 15, y + 6, z + 11, b, mg);
		array.setBlock(x + 15, y + 6, z + 12, b, mg);
		array.setBlock(x + 15, y + 6, z + 13, b, mc);
		array.setBlock(x + 15, y + 7, z + 3, b, mc);
		array.setBlock(x + 15, y + 7, z + 4, b, mg);
		array.setBlock(x + 15, y + 7, z + 5, b, mg);
		array.setBlock(x + 15, y + 7, z + 6, b, mg);
		array.setBlock(x + 15, y + 7, z + 7, b, mc);
		array.setBlock(x + 15, y + 7, z + 9, b, mc);
		array.setBlock(x + 15, y + 7, z + 10, b, mg);
		array.setBlock(x + 15, y + 7, z + 11, b, mg);
		array.setBlock(x + 15, y + 7, z + 12, b, mg);
		array.setBlock(x + 15, y + 7, z + 13, b, mc);
		array.setBlock(x + 15, y + 8, z + 3, b, mc);
		array.setBlock(x + 15, y + 8, z + 4, b, mg);
		array.setBlock(x + 15, y + 8, z + 5, b, mg);
		array.setBlock(x + 15, y + 8, z + 6, b, mg);
		array.setBlock(x + 15, y + 8, z + 7, b, mc);
		array.setBlock(x + 15, y + 8, z + 8, b, mc);
		array.setBlock(x + 15, y + 8, z + 9, b, mc);
		array.setBlock(x + 15, y + 8, z + 10, b, mg);
		array.setBlock(x + 15, y + 8, z + 11, b, mg);
		array.setBlock(x + 15, y + 8, z + 12, b, mg);
		array.setBlock(x + 15, y + 8, z + 13, b, mc);
		array.setBlock(x + 15, y + 9, z + 3, b, mc);
		array.setBlock(x + 15, y + 9, z + 4, b, mc);
		array.setBlock(x + 15, y + 9, z + 5, b, mc);
		array.setBlock(x + 15, y + 9, z + 6, b, mc);
		array.setBlock(x + 15, y + 9, z + 7, b, mc);
		array.setBlock(x + 15, y + 9, z + 8, b, mc);
		array.setBlock(x + 15, y + 9, z + 9, b, mc);
		array.setBlock(x + 15, y + 9, z + 10, b, mc);
		array.setBlock(x + 15, y + 9, z + 11, b, mc);
		array.setBlock(x + 15, y + 9, z + 12, b, mc);
		array.setBlock(x + 15, y + 9, z + 13, b, mc);
		array.setBlock(x + 15, y + 10, z + 3, b, mc);
		array.setBlock(x + 15, y + 10, z + 5, b, mc);
		array.setBlock(x + 15, y + 10, z + 11, b, mc);
		array.setBlock(x + 15, y + 10, z + 13, b, mc);
		array.setBlock(x + 16, y + 5, z + 6, b, BlockType.MOSS.metadata);
		array.setBlock(x + 16, y + 5, z + 7, b, BlockType.MOSS.metadata);
		array.setBlock(x + 16, y + 5, z + 8, b, BlockType.MOSS.metadata);
		array.setBlock(x + 16, y + 5, z + 9, b, BlockType.MOSS.metadata);
		array.setBlock(x + 16, y + 5, z + 10, b, BlockType.MOSS.metadata);

		getAirSpaces(array, x, y, z);
		return array;
	}

	private static void getAirSpaces(FilledBlockArray array, int x, int y, int z) {
		array.setBlock(x + 1, y + 6, z + 8, Blocks.air);
		array.setBlock(x + 1, y + 7, z + 8, Blocks.air);
		array.setBlock(x + 2, y + 6, z + 3, Blocks.air);
		array.setBlock(x + 2, y + 6, z + 4, Blocks.air);
		array.setBlock(x + 2, y + 6, z + 5, Blocks.air);
		array.setBlock(x + 2, y + 6, z + 6, Blocks.air);
		array.setBlock(x + 2, y + 6, z + 7, Blocks.air);
		array.setBlock(x + 2, y + 6, z + 8, Blocks.air);
		array.setBlock(x + 2, y + 6, z + 10, Blocks.air);
		array.setBlock(x + 2, y + 6, z + 11, Blocks.air);
		array.setBlock(x + 2, y + 6, z + 12, Blocks.air);
		array.setBlock(x + 2, y + 6, z + 13, Blocks.air);
		array.setBlock(x + 2, y + 7, z + 3, Blocks.air);
		array.setBlock(x + 2, y + 7, z + 4, Blocks.air);
		array.setBlock(x + 2, y + 7, z + 5, Blocks.air);
		array.setBlock(x + 2, y + 7, z + 6, Blocks.air);
		array.setBlock(x + 2, y + 7, z + 7, Blocks.air);
		array.setBlock(x + 2, y + 7, z + 8, Blocks.air);
		array.setBlock(x + 2, y + 7, z + 10, Blocks.air);
		array.setBlock(x + 2, y + 7, z + 11, Blocks.air);
		array.setBlock(x + 2, y + 7, z + 12, Blocks.air);
		array.setBlock(x + 2, y + 7, z + 13, Blocks.air);
		array.setBlock(x + 2, y + 8, z + 3, Blocks.air);
		array.setBlock(x + 2, y + 8, z + 4, Blocks.air);
		array.setBlock(x + 2, y + 8, z + 5, Blocks.air);
		array.setBlock(x + 2, y + 8, z + 6, Blocks.air);
		array.setBlock(x + 2, y + 8, z + 7, Blocks.air);
		array.setBlock(x + 2, y + 8, z + 8, Blocks.air);
		array.setBlock(x + 2, y + 8, z + 10, Blocks.air);
		array.setBlock(x + 2, y + 8, z + 11, Blocks.air);
		array.setBlock(x + 2, y + 8, z + 12, Blocks.air);
		array.setBlock(x + 2, y + 8, z + 13, Blocks.air);
		array.setBlock(x + 3, y + 4, z + 5, Blocks.lava);
		array.setBlock(x + 3, y + 4, z + 6, Blocks.lava);
		array.setBlock(x + 3, y + 4, z + 7, Blocks.lava);
		array.setBlock(x + 3, y + 4, z + 8, Blocks.lava);
		array.setBlock(x + 3, y + 6, z + 2, Blocks.air);
		array.setBlock(x + 3, y + 6, z + 3, Blocks.air);
		array.setBlock(x + 3, y + 6, z + 4, Blocks.air);
		array.setBlock(x + 3, y + 6, z + 5, Blocks.air);
		array.setBlock(x + 3, y + 6, z + 6, Blocks.air);
		array.setBlock(x + 3, y + 6, z + 7, Blocks.air);
		array.setBlock(x + 3, y + 6, z + 8, Blocks.air);
		array.setBlock(x + 3, y + 6, z + 10, Blocks.air);
		array.setBlock(x + 3, y + 6, z + 11, Blocks.air);
		array.setBlock(x + 3, y + 6, z + 12, Blocks.air);
		array.setBlock(x + 3, y + 6, z + 13, Blocks.air);
		array.setBlock(x + 3, y + 6, z + 14, Blocks.air);
		array.setBlock(x + 3, y + 7, z + 2, Blocks.air);
		array.setBlock(x + 3, y + 7, z + 3, Blocks.air);
		array.setBlock(x + 3, y + 7, z + 4, Blocks.air);
		array.setBlock(x + 3, y + 7, z + 5, Blocks.air);
		array.setBlock(x + 3, y + 7, z + 6, Blocks.air);
		array.setBlock(x + 3, y + 7, z + 7, Blocks.air);
		array.setBlock(x + 3, y + 7, z + 8, Blocks.air);
		array.setBlock(x + 3, y + 7, z + 10, Blocks.air);
		array.setBlock(x + 3, y + 7, z + 11, Blocks.air);
		array.setBlock(x + 3, y + 7, z + 12, Blocks.air);
		array.setBlock(x + 3, y + 7, z + 13, Blocks.air);
		array.setBlock(x + 3, y + 7, z + 14, Blocks.air);
		array.setBlock(x + 3, y + 8, z + 2, Blocks.air);
		array.setBlock(x + 3, y + 8, z + 3, Blocks.air);
		array.setBlock(x + 3, y + 8, z + 4, Blocks.air);
		array.setBlock(x + 3, y + 8, z + 5, Blocks.air);
		array.setBlock(x + 3, y + 8, z + 6, Blocks.air);
		array.setBlock(x + 3, y + 8, z + 7, Blocks.air);
		array.setBlock(x + 3, y + 8, z + 8, Blocks.air);
		array.setBlock(x + 3, y + 8, z + 10, Blocks.air);
		array.setBlock(x + 3, y + 8, z + 11, Blocks.air);
		array.setBlock(x + 3, y + 8, z + 12, Blocks.air);
		array.setBlock(x + 3, y + 8, z + 13, Blocks.air);
		array.setBlock(x + 3, y + 8, z + 14, Blocks.air);
		array.setBlock(x + 4, y + 4, z + 5, Blocks.lava);
		array.setBlock(x + 4, y + 4, z + 6, Blocks.lava);
		array.setBlock(x + 4, y + 4, z + 7, Blocks.lava);
		array.setBlock(x + 4, y + 4, z + 8, Blocks.lava);
		array.setBlock(x + 4, y + 4, z + 9, Blocks.lava);
		array.setBlock(x + 4, y + 4, z + 10, Blocks.lava);
		array.setBlock(x + 4, y + 4, z + 11, Blocks.lava);
		array.setBlock(x + 4, y + 4, z + 12, Blocks.lava);
		array.setBlock(x + 4, y + 4, z + 13, Blocks.lava);
		array.setBlock(x + 4, y + 6, z + 2, Blocks.air);
		array.setBlock(x + 4, y + 6, z + 3, Blocks.air);
		array.setBlock(x + 4, y + 6, z + 4, Blocks.air);
		array.setBlock(x + 4, y + 6, z + 5, Blocks.air);
		array.setBlock(x + 4, y + 6, z + 6, Blocks.air);
		array.setBlock(x + 4, y + 6, z + 7, Blocks.air);
		array.setBlock(x + 4, y + 6, z + 8, Blocks.air);
		array.setBlock(x + 4, y + 6, z + 9, Blocks.air);
		array.setBlock(x + 4, y + 6, z + 11, Blocks.air);
		array.setBlock(x + 4, y + 6, z + 12, Blocks.air);
		array.setBlock(x + 4, y + 6, z + 13, Blocks.air);
		array.setBlock(x + 4, y + 6, z + 14, Blocks.air);
		array.setBlock(x + 4, y + 7, z + 2, Blocks.air);
		array.setBlock(x + 4, y + 7, z + 3, Blocks.air);
		array.setBlock(x + 4, y + 7, z + 4, Blocks.air);
		array.setBlock(x + 4, y + 7, z + 5, Blocks.air);
		array.setBlock(x + 4, y + 7, z + 6, Blocks.air);
		array.setBlock(x + 4, y + 7, z + 7, Blocks.air);
		array.setBlock(x + 4, y + 7, z + 8, Blocks.air);
		array.setBlock(x + 4, y + 7, z + 9, Blocks.air);
		array.setBlock(x + 4, y + 7, z + 11, Blocks.air);
		array.setBlock(x + 4, y + 7, z + 12, Blocks.air);
		array.setBlock(x + 4, y + 7, z + 13, Blocks.air);
		array.setBlock(x + 4, y + 7, z + 14, Blocks.air);
		array.setBlock(x + 4, y + 8, z + 2, Blocks.air);
		array.setBlock(x + 4, y + 8, z + 3, Blocks.air);
		array.setBlock(x + 4, y + 8, z + 4, Blocks.air);
		array.setBlock(x + 4, y + 8, z + 5, Blocks.air);
		array.setBlock(x + 4, y + 8, z + 6, Blocks.air);
		array.setBlock(x + 4, y + 8, z + 7, Blocks.air);
		array.setBlock(x + 4, y + 8, z + 8, Blocks.air);
		array.setBlock(x + 4, y + 8, z + 9, Blocks.air);
		array.setBlock(x + 4, y + 8, z + 11, Blocks.air);
		array.setBlock(x + 4, y + 8, z + 12, Blocks.air);
		array.setBlock(x + 4, y + 8, z + 13, Blocks.air);
		array.setBlock(x + 4, y + 8, z + 14, Blocks.air);
		array.setBlock(x + 5, y + 4, z + 6, Blocks.lava);
		array.setBlock(x + 5, y + 4, z + 7, Blocks.lava);
		array.setBlock(x + 5, y + 4, z + 8, Blocks.lava);
		array.setBlock(x + 5, y + 4, z + 9, Blocks.lava);
		array.setBlock(x + 5, y + 4, z + 10, Blocks.lava);
		array.setBlock(x + 5, y + 4, z + 12, Blocks.lava);
		array.setBlock(x + 5, y + 4, z + 13, Blocks.lava);
		array.setBlock(x + 5, y + 6, z + 2, Blocks.air);
		array.setBlock(x + 5, y + 6, z + 3, Blocks.air);
		array.setBlock(x + 5, y + 6, z + 4, Blocks.air);
		array.setBlock(x + 5, y + 6, z + 6, Blocks.air);
		array.setBlock(x + 5, y + 6, z + 7, Blocks.air);
		array.setBlock(x + 5, y + 6, z + 8, Blocks.air);
		array.setBlock(x + 5, y + 6, z + 9, Blocks.air);
		array.setBlock(x + 5, y + 6, z + 12, Blocks.air);
		array.setBlock(x + 5, y + 6, z + 13, Blocks.air);
		array.setBlock(x + 5, y + 6, z + 14, Blocks.air);
		array.setBlock(x + 5, y + 7, z + 2, Blocks.air);
		array.setBlock(x + 5, y + 7, z + 3, Blocks.air);
		array.setBlock(x + 5, y + 7, z + 4, Blocks.air);
		array.setBlock(x + 5, y + 7, z + 6, Blocks.air);
		array.setBlock(x + 5, y + 7, z + 7, Blocks.air);
		array.setBlock(x + 5, y + 7, z + 8, Blocks.air);
		array.setBlock(x + 5, y + 7, z + 9, Blocks.air);
		array.setBlock(x + 5, y + 7, z + 12, Blocks.air);
		array.setBlock(x + 5, y + 7, z + 13, Blocks.air);
		array.setBlock(x + 5, y + 7, z + 14, Blocks.air);
		array.setBlock(x + 5, y + 8, z + 2, Blocks.air);
		array.setBlock(x + 5, y + 8, z + 3, Blocks.air);
		array.setBlock(x + 5, y + 8, z + 4, Blocks.air);
		array.setBlock(x + 5, y + 8, z + 6, Blocks.air);
		array.setBlock(x + 5, y + 8, z + 7, Blocks.air);
		array.setBlock(x + 5, y + 8, z + 8, Blocks.air);
		array.setBlock(x + 5, y + 8, z + 9, Blocks.air);
		array.setBlock(x + 5, y + 8, z + 12, Blocks.air);
		array.setBlock(x + 5, y + 8, z + 13, Blocks.air);
		array.setBlock(x + 5, y + 8, z + 14, Blocks.air);
		array.setBlock(x + 5, y + 10, z + 6, Blocks.air);
		array.setBlock(x + 5, y + 10, z + 7, Blocks.air);
		array.setBlock(x + 5, y + 10, z + 8, Blocks.air);
		array.setBlock(x + 5, y + 10, z + 9, Blocks.air);
		array.setBlock(x + 5, y + 10, z + 10, Blocks.air);
		array.setBlock(x + 5, y + 11, z + 6, Blocks.air);
		array.setBlock(x + 5, y + 11, z + 7, Blocks.air);
		array.setBlock(x + 5, y + 11, z + 8, Blocks.air);
		array.setBlock(x + 5, y + 11, z + 9, Blocks.air);
		array.setBlock(x + 5, y + 11, z + 10, Blocks.air);
		array.setBlock(x + 6, y + 4, z + 11, Blocks.lava);
		array.setBlock(x + 6, y + 4, z + 12, Blocks.lava);
		array.setBlock(x + 6, y + 4, z + 13, Blocks.lava);
		array.setBlock(x + 6, y + 6, z + 2, Blocks.air);
		array.setBlock(x + 6, y + 6, z + 3, Blocks.air);
		array.setBlock(x + 6, y + 6, z + 11, Blocks.air);
		array.setBlock(x + 6, y + 6, z + 12, Blocks.air);
		array.setBlock(x + 6, y + 6, z + 13, Blocks.air);
		array.setBlock(x + 6, y + 6, z + 14, Blocks.air);
		array.setBlock(x + 6, y + 7, z + 2, Blocks.air);
		array.setBlock(x + 6, y + 7, z + 3, Blocks.air);
		array.setBlock(x + 6, y + 7, z + 11, Blocks.air);
		array.setBlock(x + 6, y + 7, z + 12, Blocks.air);
		array.setBlock(x + 6, y + 7, z + 13, Blocks.air);
		array.setBlock(x + 6, y + 7, z + 14, Blocks.air);
		array.setBlock(x + 6, y + 8, z + 2, Blocks.air);
		array.setBlock(x + 6, y + 8, z + 3, Blocks.air);
		array.setBlock(x + 6, y + 8, z + 11, Blocks.air);
		array.setBlock(x + 6, y + 8, z + 12, Blocks.air);
		array.setBlock(x + 6, y + 8, z + 13, Blocks.air);
		array.setBlock(x + 6, y + 8, z + 14, Blocks.air);
		array.setBlock(x + 6, y + 10, z + 5, Blocks.air);
		array.setBlock(x + 6, y + 10, z + 6, Blocks.air);
		array.setBlock(x + 6, y + 10, z + 7, Blocks.air);
		array.setBlock(x + 6, y + 10, z + 8, Blocks.air);
		array.setBlock(x + 6, y + 10, z + 9, Blocks.air);
		array.setBlock(x + 6, y + 10, z + 10, Blocks.air);
		array.setBlock(x + 6, y + 10, z + 11, Blocks.air);
		array.setBlock(x + 6, y + 11, z + 5, Blocks.air);
		array.setBlock(x + 6, y + 11, z + 6, Blocks.air);
		array.setBlock(x + 6, y + 11, z + 7, Blocks.air);
		array.setBlock(x + 6, y + 11, z + 8, Blocks.air);
		array.setBlock(x + 6, y + 11, z + 9, Blocks.air);
		array.setBlock(x + 6, y + 11, z + 10, Blocks.air);
		array.setBlock(x + 6, y + 11, z + 11, Blocks.air);
		array.setBlock(x + 7, y + 2, z + 5, Blocks.air);
		array.setBlock(x + 7, y + 2, z + 6, Blocks.air);
		array.setBlock(x + 7, y + 2, z + 7, Blocks.air);
		array.setBlock(x + 7, y + 3, z + 5, Blocks.air);
		array.setBlock(x + 7, y + 3, z + 6, Blocks.air);
		array.setBlock(x + 7, y + 3, z + 7, Blocks.air);
		array.setBlock(x + 7, y + 3, z + 8, Blocks.air);
		array.setBlock(x + 7, y + 4, z + 6, Blocks.air);
		array.setBlock(x + 7, y + 4, z + 7, Blocks.air);
		array.setBlock(x + 7, y + 4, z + 8, Blocks.air);
		array.setBlock(x + 7, y + 4, z + 9, Blocks.air);
		array.setBlock(x + 7, y + 4, z + 11, Blocks.lava);
		array.setBlock(x + 7, y + 4, z + 12, Blocks.lava);
		array.setBlock(x + 7, y + 4, z + 13, Blocks.lava);
		array.setBlock(x + 7, y + 6, z + 4, Blocks.air);
		array.setBlock(x + 7, y + 6, z + 5, Blocks.air);
		array.setBlock(x + 7, y + 6, z + 7, Blocks.air);
		array.setBlock(x + 7, y + 6, z + 8, Blocks.air);
		array.setBlock(x + 7, y + 6, z + 9, Blocks.air);
		array.setBlock(x + 7, y + 6, z + 11, Blocks.air);
		array.setBlock(x + 7, y + 6, z + 12, Blocks.air);
		array.setBlock(x + 7, y + 6, z + 13, Blocks.air);
		array.setBlock(x + 7, y + 6, z + 14, Blocks.air);
		array.setBlock(x + 7, y + 7, z + 4, Blocks.air);
		array.setBlock(x + 7, y + 7, z + 5, Blocks.air);
		array.setBlock(x + 7, y + 7, z + 7, Blocks.air);
		array.setBlock(x + 7, y + 7, z + 8, Blocks.air);
		array.setBlock(x + 7, y + 7, z + 9, Blocks.air);
		array.setBlock(x + 7, y + 7, z + 11, Blocks.air);
		array.setBlock(x + 7, y + 7, z + 12, Blocks.air);
		array.setBlock(x + 7, y + 7, z + 13, Blocks.air);
		array.setBlock(x + 7, y + 7, z + 14, Blocks.air);
		array.setBlock(x + 7, y + 8, z + 4, Blocks.air);
		array.setBlock(x + 7, y + 8, z + 5, Blocks.air);
		array.setBlock(x + 7, y + 8, z + 7, Blocks.air);
		array.setBlock(x + 7, y + 8, z + 8, Blocks.air);
		array.setBlock(x + 7, y + 8, z + 9, Blocks.air);
		array.setBlock(x + 7, y + 8, z + 11, Blocks.air);
		array.setBlock(x + 7, y + 8, z + 12, Blocks.air);
		array.setBlock(x + 7, y + 8, z + 13, Blocks.air);
		array.setBlock(x + 7, y + 8, z + 14, Blocks.air);
		array.setBlock(x + 7, y + 10, z + 5, Blocks.air);
		array.setBlock(x + 7, y + 10, z + 6, Blocks.air);
		array.setBlock(x + 7, y + 10, z + 10, Blocks.air);
		array.setBlock(x + 7, y + 10, z + 11, Blocks.air);
		array.setBlock(x + 7, y + 11, z + 5, Blocks.air);
		array.setBlock(x + 7, y + 11, z + 6, Blocks.air);
		array.setBlock(x + 7, y + 11, z + 10, Blocks.air);
		array.setBlock(x + 7, y + 11, z + 11, Blocks.air);
		array.setBlock(x + 8, y + 2, z + 5, Blocks.air);
		array.setBlock(x + 8, y + 2, z + 6, Blocks.air);
		array.setBlock(x + 8, y + 2, z + 7, Blocks.air);
		array.setBlock(x + 8, y + 3, z + 5, Blocks.air);
		array.setBlock(x + 8, y + 3, z + 7, Blocks.air);
		array.setBlock(x + 8, y + 3, z + 8, Blocks.air);
		array.setBlock(x + 8, y + 4, z + 6, Blocks.air);
		array.setBlock(x + 8, y + 4, z + 7, Blocks.air);
		array.setBlock(x + 8, y + 4, z + 8, Blocks.air);
		array.setBlock(x + 8, y + 4, z + 9, Blocks.air);
		array.setBlock(x + 8, y + 4, z + 11, Blocks.lava);
		array.setBlock(x + 8, y + 4, z + 12, Blocks.lava);
		array.setBlock(x + 8, y + 4, z + 13, Blocks.lava);
		array.setBlock(x + 8, y + 6, z + 1, Blocks.air);
		array.setBlock(x + 8, y + 6, z + 2, Blocks.air);
		array.setBlock(x + 8, y + 6, z + 3, Blocks.air);
		array.setBlock(x + 8, y + 6, z + 4, Blocks.air);
		array.setBlock(x + 8, y + 6, z + 5, Blocks.air);
		array.setBlock(x + 8, y + 6, z + 7, Blocks.air);
		array.setBlock(x + 8, y + 6, z + 8, Blocks.air);
		array.setBlock(x + 8, y + 6, z + 9, Blocks.air);
		array.setBlock(x + 8, y + 6, z + 11, Blocks.air);
		array.setBlock(x + 8, y + 6, z + 12, Blocks.air);
		array.setBlock(x + 8, y + 6, z + 13, Blocks.air);
		array.setBlock(x + 8, y + 6, z + 14, Blocks.air);
		array.setBlock(x + 8, y + 6, z + 15, Blocks.air);
		array.setBlock(x + 8, y + 7, z + 1, Blocks.air);
		array.setBlock(x + 8, y + 7, z + 2, Blocks.air);
		array.setBlock(x + 8, y + 7, z + 3, Blocks.air);
		array.setBlock(x + 8, y + 7, z + 4, Blocks.air);
		array.setBlock(x + 8, y + 7, z + 5, Blocks.air);
		array.setBlock(x + 8, y + 7, z + 7, Blocks.air);
		array.setBlock(x + 8, y + 7, z + 8, Blocks.air);
		array.setBlock(x + 8, y + 7, z + 9, Blocks.air);
		array.setBlock(x + 8, y + 7, z + 11, Blocks.air);
		array.setBlock(x + 8, y + 7, z + 12, Blocks.air);
		array.setBlock(x + 8, y + 7, z + 13, Blocks.air);
		array.setBlock(x + 8, y + 7, z + 14, Blocks.air);
		array.setBlock(x + 8, y + 7, z + 15, Blocks.air);
		array.setBlock(x + 8, y + 8, z + 2, Blocks.air);
		array.setBlock(x + 8, y + 8, z + 3, Blocks.air);
		array.setBlock(x + 8, y + 8, z + 4, Blocks.air);
		array.setBlock(x + 8, y + 8, z + 5, Blocks.air);
		array.setBlock(x + 8, y + 8, z + 7, Blocks.air);
		array.setBlock(x + 8, y + 8, z + 8, Blocks.air);
		array.setBlock(x + 8, y + 8, z + 9, Blocks.air);
		array.setBlock(x + 8, y + 8, z + 11, Blocks.air);
		array.setBlock(x + 8, y + 8, z + 12, Blocks.air);
		array.setBlock(x + 8, y + 8, z + 13, Blocks.air);
		array.setBlock(x + 8, y + 8, z + 14, Blocks.air);
		array.setBlock(x + 8, y + 10, z + 5, Blocks.air);
		array.setBlock(x + 8, y + 10, z + 6, Blocks.air);
		array.setBlock(x + 8, y + 10, z + 10, Blocks.air);
		array.setBlock(x + 8, y + 10, z + 11, Blocks.air);
		array.setBlock(x + 8, y + 11, z + 5, Blocks.air);
		array.setBlock(x + 8, y + 11, z + 6, Blocks.air);
		array.setBlock(x + 8, y + 11, z + 10, Blocks.air);
		array.setBlock(x + 8, y + 11, z + 11, Blocks.air);
		array.setBlock(x + 9, y + 2, z + 5, Blocks.air);
		array.setBlock(x + 9, y + 2, z + 6, Blocks.air);
		array.setBlock(x + 9, y + 2, z + 7, Blocks.air);
		array.setBlock(x + 9, y + 3, z + 5, Blocks.air);
		array.setBlock(x + 9, y + 3, z + 6, Blocks.air);
		array.setBlock(x + 9, y + 3, z + 7, Blocks.air);
		array.setBlock(x + 9, y + 3, z + 8, Blocks.air);
		array.setBlock(x + 9, y + 4, z + 6, Blocks.air);
		array.setBlock(x + 9, y + 4, z + 7, Blocks.air);
		array.setBlock(x + 9, y + 4, z + 8, Blocks.air);
		array.setBlock(x + 9, y + 4, z + 9, Blocks.air);
		array.setBlock(x + 9, y + 4, z + 11, Blocks.lava);
		array.setBlock(x + 9, y + 4, z + 12, Blocks.lava);
		array.setBlock(x + 9, y + 6, z + 2, Blocks.air);
		array.setBlock(x + 9, y + 6, z + 3, Blocks.air);
		array.setBlock(x + 9, y + 6, z + 4, Blocks.air);
		array.setBlock(x + 9, y + 6, z + 5, Blocks.air);
		array.setBlock(x + 9, y + 6, z + 7, Blocks.air);
		array.setBlock(x + 9, y + 6, z + 8, Blocks.air);
		array.setBlock(x + 9, y + 6, z + 9, Blocks.air);
		array.setBlock(x + 9, y + 6, z + 11, Blocks.air);
		array.setBlock(x + 9, y + 6, z + 12, Blocks.air);
		array.setBlock(x + 9, y + 7, z + 2, Blocks.air);
		array.setBlock(x + 9, y + 7, z + 3, Blocks.air);
		array.setBlock(x + 9, y + 7, z + 4, Blocks.air);
		array.setBlock(x + 9, y + 7, z + 5, Blocks.air);
		array.setBlock(x + 9, y + 7, z + 7, Blocks.air);
		array.setBlock(x + 9, y + 7, z + 8, Blocks.air);
		array.setBlock(x + 9, y + 7, z + 9, Blocks.air);
		array.setBlock(x + 9, y + 7, z + 11, Blocks.air);
		array.setBlock(x + 9, y + 7, z + 12, Blocks.air);
		array.setBlock(x + 9, y + 8, z + 2, Blocks.air);
		array.setBlock(x + 9, y + 8, z + 3, Blocks.air);
		array.setBlock(x + 9, y + 8, z + 4, Blocks.air);
		array.setBlock(x + 9, y + 8, z + 5, Blocks.air);
		array.setBlock(x + 9, y + 8, z + 7, Blocks.air);
		array.setBlock(x + 9, y + 8, z + 8, Blocks.air);
		array.setBlock(x + 9, y + 8, z + 9, Blocks.air);
		array.setBlock(x + 9, y + 8, z + 11, Blocks.air);
		array.setBlock(x + 9, y + 8, z + 12, Blocks.air);
		array.setBlock(x + 9, y + 10, z + 5, Blocks.air);
		array.setBlock(x + 9, y + 10, z + 6, Blocks.air);
		array.setBlock(x + 9, y + 10, z + 10, Blocks.air);
		array.setBlock(x + 9, y + 10, z + 11, Blocks.air);
		array.setBlock(x + 9, y + 11, z + 5, Blocks.air);
		array.setBlock(x + 9, y + 11, z + 6, Blocks.air);
		array.setBlock(x + 9, y + 11, z + 10, Blocks.air);
		array.setBlock(x + 9, y + 11, z + 11, Blocks.air);
		array.setBlock(x + 10, y + 4, z + 11, Blocks.lava);
		array.setBlock(x + 10, y + 4, z + 12, Blocks.lava);
		array.setBlock(x + 10, y + 4, z + 13, Blocks.lava);
		array.setBlock(x + 10, y + 6, z + 2, Blocks.air);
		array.setBlock(x + 10, y + 6, z + 3, Blocks.air);
		array.setBlock(x + 10, y + 6, z + 4, Blocks.air);
		array.setBlock(x + 10, y + 6, z + 5, Blocks.air);
		array.setBlock(x + 10, y + 6, z + 13, Blocks.air);
		array.setBlock(x + 10, y + 6, z + 14, Blocks.air);
		array.setBlock(x + 10, y + 7, z + 2, Blocks.air);
		array.setBlock(x + 10, y + 7, z + 3, Blocks.air);
		array.setBlock(x + 10, y + 7, z + 4, Blocks.air);
		array.setBlock(x + 10, y + 7, z + 5, Blocks.air);
		array.setBlock(x + 10, y + 7, z + 13, Blocks.air);
		array.setBlock(x + 10, y + 7, z + 14, Blocks.air);
		array.setBlock(x + 10, y + 8, z + 2, Blocks.air);
		array.setBlock(x + 10, y + 8, z + 3, Blocks.air);
		array.setBlock(x + 10, y + 8, z + 4, Blocks.air);
		array.setBlock(x + 10, y + 8, z + 5, Blocks.air);
		array.setBlock(x + 10, y + 8, z + 13, Blocks.air);
		array.setBlock(x + 10, y + 8, z + 14, Blocks.air);
		array.setBlock(x + 10, y + 10, z + 5, Blocks.air);
		array.setBlock(x + 10, y + 10, z + 6, Blocks.air);
		array.setBlock(x + 10, y + 10, z + 7, Blocks.air);
		array.setBlock(x + 10, y + 10, z + 8, Blocks.air);
		array.setBlock(x + 10, y + 10, z + 9, Blocks.air);
		array.setBlock(x + 10, y + 10, z + 10, Blocks.air);
		array.setBlock(x + 10, y + 10, z + 11, Blocks.air);
		array.setBlock(x + 10, y + 11, z + 5, Blocks.air);
		array.setBlock(x + 10, y + 11, z + 6, Blocks.air);
		array.setBlock(x + 10, y + 11, z + 7, Blocks.air);
		array.setBlock(x + 10, y + 11, z + 8, Blocks.air);
		array.setBlock(x + 10, y + 11, z + 9, Blocks.air);
		array.setBlock(x + 10, y + 11, z + 10, Blocks.air);
		array.setBlock(x + 10, y + 11, z + 11, Blocks.air);
		array.setBlock(x + 11, y + 4, z + 7, Blocks.lava);
		array.setBlock(x + 11, y + 4, z + 8, Blocks.lava);
		array.setBlock(x + 11, y + 4, z + 9, Blocks.lava);
		array.setBlock(x + 11, y + 4, z + 10, Blocks.lava);
		array.setBlock(x + 11, y + 4, z + 12, Blocks.lava);
		array.setBlock(x + 11, y + 4, z + 13, Blocks.lava);
		array.setBlock(x + 11, y + 6, z + 2, Blocks.air);
		array.setBlock(x + 11, y + 6, z + 3, Blocks.air);
		array.setBlock(x + 11, y + 6, z + 4, Blocks.air);
		array.setBlock(x + 11, y + 6, z + 7, Blocks.air);
		array.setBlock(x + 11, y + 6, z + 8, Blocks.air);
		array.setBlock(x + 11, y + 6, z + 9, Blocks.air);
		array.setBlock(x + 11, y + 6, z + 10, Blocks.air);
		array.setBlock(x + 11, y + 6, z + 12, Blocks.air);
		array.setBlock(x + 11, y + 6, z + 13, Blocks.air);
		array.setBlock(x + 11, y + 6, z + 14, Blocks.air);
		array.setBlock(x + 11, y + 7, z + 2, Blocks.air);
		array.setBlock(x + 11, y + 7, z + 3, Blocks.air);
		array.setBlock(x + 11, y + 7, z + 4, Blocks.air);
		array.setBlock(x + 11, y + 7, z + 7, Blocks.air);
		array.setBlock(x + 11, y + 7, z + 8, Blocks.air);
		array.setBlock(x + 11, y + 7, z + 9, Blocks.air);
		array.setBlock(x + 11, y + 7, z + 10, Blocks.air);
		array.setBlock(x + 11, y + 7, z + 12, Blocks.air);
		array.setBlock(x + 11, y + 7, z + 13, Blocks.air);
		array.setBlock(x + 11, y + 7, z + 14, Blocks.air);
		array.setBlock(x + 11, y + 8, z + 2, Blocks.air);
		array.setBlock(x + 11, y + 8, z + 3, Blocks.air);
		array.setBlock(x + 11, y + 8, z + 4, Blocks.air);
		array.setBlock(x + 11, y + 8, z + 7, Blocks.air);
		array.setBlock(x + 11, y + 8, z + 8, Blocks.air);
		array.setBlock(x + 11, y + 8, z + 9, Blocks.air);
		array.setBlock(x + 11, y + 8, z + 10, Blocks.air);
		array.setBlock(x + 11, y + 8, z + 12, Blocks.air);
		array.setBlock(x + 11, y + 8, z + 13, Blocks.air);
		array.setBlock(x + 11, y + 8, z + 14, Blocks.air);
		array.setBlock(x + 11, y + 10, z + 6, Blocks.air);
		array.setBlock(x + 11, y + 10, z + 7, Blocks.air);
		array.setBlock(x + 11, y + 10, z + 8, Blocks.air);
		array.setBlock(x + 11, y + 10, z + 9, Blocks.air);
		array.setBlock(x + 11, y + 10, z + 10, Blocks.air);
		array.setBlock(x + 11, y + 11, z + 6, Blocks.air);
		array.setBlock(x + 11, y + 11, z + 7, Blocks.air);
		array.setBlock(x + 11, y + 11, z + 8, Blocks.air);
		array.setBlock(x + 11, y + 11, z + 9, Blocks.air);
		array.setBlock(x + 11, y + 11, z + 10, Blocks.air);
		array.setBlock(x + 12, y + 4, z + 7, Blocks.lava);
		array.setBlock(x + 12, y + 4, z + 8, Blocks.lava);
		array.setBlock(x + 12, y + 4, z + 9, Blocks.lava);
		array.setBlock(x + 12, y + 4, z + 10, Blocks.lava);
		array.setBlock(x + 12, y + 4, z + 11, Blocks.lava);
		array.setBlock(x + 12, y + 4, z + 12, Blocks.lava);
		array.setBlock(x + 12, y + 4, z + 13, Blocks.lava);
		array.setBlock(x + 12, y + 6, z + 2, Blocks.air);
		array.setBlock(x + 12, y + 6, z + 3, Blocks.air);
		array.setBlock(x + 12, y + 6, z + 4, Blocks.air);
		array.setBlock(x + 12, y + 6, z + 5, Blocks.air);
		array.setBlock(x + 12, y + 6, z + 7, Blocks.air);
		array.setBlock(x + 12, y + 6, z + 8, Blocks.air);
		array.setBlock(x + 12, y + 6, z + 9, Blocks.air);
		array.setBlock(x + 12, y + 6, z + 10, Blocks.air);
		array.setBlock(x + 12, y + 6, z + 11, Blocks.air);
		array.setBlock(x + 12, y + 6, z + 12, Blocks.air);
		array.setBlock(x + 12, y + 6, z + 13, Blocks.air);
		array.setBlock(x + 12, y + 6, z + 14, Blocks.air);
		array.setBlock(x + 12, y + 7, z + 2, Blocks.air);
		array.setBlock(x + 12, y + 7, z + 3, Blocks.air);
		array.setBlock(x + 12, y + 7, z + 4, Blocks.air);
		array.setBlock(x + 12, y + 7, z + 5, Blocks.air);
		array.setBlock(x + 12, y + 7, z + 7, Blocks.air);
		array.setBlock(x + 12, y + 7, z + 8, Blocks.air);
		array.setBlock(x + 12, y + 7, z + 9, Blocks.air);
		array.setBlock(x + 12, y + 7, z + 10, Blocks.air);
		array.setBlock(x + 12, y + 7, z + 11, Blocks.air);
		array.setBlock(x + 12, y + 7, z + 12, Blocks.air);
		array.setBlock(x + 12, y + 7, z + 13, Blocks.air);
		array.setBlock(x + 12, y + 7, z + 14, Blocks.air);
		array.setBlock(x + 12, y + 8, z + 2, Blocks.air);
		array.setBlock(x + 12, y + 8, z + 3, Blocks.air);
		array.setBlock(x + 12, y + 8, z + 4, Blocks.air);
		array.setBlock(x + 12, y + 8, z + 5, Blocks.air);
		array.setBlock(x + 12, y + 8, z + 7, Blocks.air);
		array.setBlock(x + 12, y + 8, z + 8, Blocks.air);
		array.setBlock(x + 12, y + 8, z + 9, Blocks.air);
		array.setBlock(x + 12, y + 8, z + 10, Blocks.air);
		array.setBlock(x + 12, y + 8, z + 11, Blocks.air);
		array.setBlock(x + 12, y + 8, z + 12, Blocks.air);
		array.setBlock(x + 12, y + 8, z + 13, Blocks.air);
		array.setBlock(x + 12, y + 8, z + 14, Blocks.air);
		array.setBlock(x + 13, y + 4, z + 8, Blocks.lava);
		array.setBlock(x + 13, y + 4, z + 9, Blocks.lava);
		array.setBlock(x + 13, y + 4, z + 10, Blocks.lava);
		array.setBlock(x + 13, y + 4, z + 11, Blocks.lava);
		array.setBlock(x + 13, y + 4, z + 12, Blocks.lava);
		array.setBlock(x + 13, y + 4, z + 13, Blocks.lava);
		array.setBlock(x + 13, y + 6, z + 2, Blocks.air);
		array.setBlock(x + 13, y + 6, z + 3, Blocks.air);
		array.setBlock(x + 13, y + 6, z + 4, Blocks.air);
		array.setBlock(x + 13, y + 6, z + 5, Blocks.air);
		array.setBlock(x + 13, y + 6, z + 6, Blocks.air);
		array.setBlock(x + 13, y + 6, z + 8, Blocks.air);
		array.setBlock(x + 13, y + 6, z + 9, Blocks.air);
		array.setBlock(x + 13, y + 6, z + 10, Blocks.air);
		array.setBlock(x + 13, y + 6, z + 11, Blocks.air);
		array.setBlock(x + 13, y + 6, z + 12, Blocks.air);
		array.setBlock(x + 13, y + 6, z + 13, Blocks.air);
		array.setBlock(x + 13, y + 6, z + 14, Blocks.air);
		array.setBlock(x + 13, y + 7, z + 2, Blocks.air);
		array.setBlock(x + 13, y + 7, z + 3, Blocks.air);
		array.setBlock(x + 13, y + 7, z + 4, Blocks.air);
		array.setBlock(x + 13, y + 7, z + 5, Blocks.air);
		array.setBlock(x + 13, y + 7, z + 6, Blocks.air);
		array.setBlock(x + 13, y + 7, z + 8, Blocks.air);
		array.setBlock(x + 13, y + 7, z + 9, Blocks.air);
		array.setBlock(x + 13, y + 7, z + 10, Blocks.air);
		array.setBlock(x + 13, y + 7, z + 11, Blocks.air);
		array.setBlock(x + 13, y + 7, z + 12, Blocks.air);
		array.setBlock(x + 13, y + 7, z + 13, Blocks.air);
		array.setBlock(x + 13, y + 7, z + 14, Blocks.air);
		array.setBlock(x + 13, y + 8, z + 2, Blocks.air);
		array.setBlock(x + 13, y + 8, z + 3, Blocks.air);
		array.setBlock(x + 13, y + 8, z + 4, Blocks.air);
		array.setBlock(x + 13, y + 8, z + 5, Blocks.air);
		array.setBlock(x + 13, y + 8, z + 6, Blocks.air);
		array.setBlock(x + 13, y + 8, z + 8, Blocks.air);
		array.setBlock(x + 13, y + 8, z + 9, Blocks.air);
		array.setBlock(x + 13, y + 8, z + 10, Blocks.air);
		array.setBlock(x + 13, y + 8, z + 11, Blocks.air);
		array.setBlock(x + 13, y + 8, z + 12, Blocks.air);
		array.setBlock(x + 13, y + 8, z + 13, Blocks.air);
		array.setBlock(x + 13, y + 8, z + 14, Blocks.air);
		array.setBlock(x + 14, y + 6, z + 3, Blocks.air);
		array.setBlock(x + 14, y + 6, z + 4, Blocks.air);
		array.setBlock(x + 14, y + 6, z + 5, Blocks.air);
		array.setBlock(x + 14, y + 6, z + 6, Blocks.air);
		array.setBlock(x + 14, y + 6, z + 8, Blocks.air);
		array.setBlock(x + 14, y + 6, z + 9, Blocks.air);
		array.setBlock(x + 14, y + 6, z + 10, Blocks.air);
		array.setBlock(x + 14, y + 6, z + 11, Blocks.air);
		array.setBlock(x + 14, y + 6, z + 12, Blocks.air);
		array.setBlock(x + 14, y + 6, z + 13, Blocks.air);
		array.setBlock(x + 14, y + 7, z + 3, Blocks.air);
		array.setBlock(x + 14, y + 7, z + 4, Blocks.air);
		array.setBlock(x + 14, y + 7, z + 5, Blocks.air);
		array.setBlock(x + 14, y + 7, z + 6, Blocks.air);
		array.setBlock(x + 14, y + 7, z + 8, Blocks.air);
		array.setBlock(x + 14, y + 7, z + 9, Blocks.air);
		array.setBlock(x + 14, y + 7, z + 10, Blocks.air);
		array.setBlock(x + 14, y + 7, z + 11, Blocks.air);
		array.setBlock(x + 14, y + 7, z + 12, Blocks.air);
		array.setBlock(x + 14, y + 7, z + 13, Blocks.air);
		array.setBlock(x + 14, y + 8, z + 3, Blocks.air);
		array.setBlock(x + 14, y + 8, z + 4, Blocks.air);
		array.setBlock(x + 14, y + 8, z + 5, Blocks.air);
		array.setBlock(x + 14, y + 8, z + 6, Blocks.air);
		array.setBlock(x + 14, y + 8, z + 8, Blocks.air);
		array.setBlock(x + 14, y + 8, z + 9, Blocks.air);
		array.setBlock(x + 14, y + 8, z + 10, Blocks.air);
		array.setBlock(x + 14, y + 8, z + 11, Blocks.air);
		array.setBlock(x + 14, y + 8, z + 12, Blocks.air);
		array.setBlock(x + 14, y + 8, z + 13, Blocks.air);
		array.setBlock(x + 15, y + 6, z + 8, Blocks.air);
		array.setBlock(x + 15, y + 7, z + 8, Blocks.air);
	}
}
