/*******************************************************************************
 * @author Reika Kalseki
 *
 * Copyright 2017
 *
 * All rights reserved.
 * Distribution of the software in any form is only allowed with
 * explicit, prior permission from the owner.
 ******************************************************************************/
package Reika.ChromatiCraft.World.Nether;

import java.util.Random;

import net.minecraft.block.Block;
import net.minecraft.init.Blocks;
import net.minecraft.world.World;
import net.minecraftforge.common.ChestGenHooks;
import net.minecraftforge.common.util.ForgeDirection;

import Reika.ChromatiCraft.Auxiliary.ChromaAux;
import Reika.ChromatiCraft.Block.Worldgen.BlockLootChest;
import Reika.ChromatiCraft.Block.Worldgen.BlockLootChest.TileEntityLootChest;
import Reika.ChromatiCraft.Block.Worldgen.BlockStructureShield.BlockType;
import Reika.ChromatiCraft.Magic.Progression.ProgressStage;
import Reika.ChromatiCraft.Registry.ChromaBlocks;


public class NetherTemple {

	private static Block b = ChromaBlocks.STRUCTSHIELD.getBlockInstance();
	private static int ms = BlockType.STONE.metadata;
	private static Block ch = ChromaBlocks.LOOTCHEST.getBlockInstance();
	private static int mc = BlockLootChest.getMeta(ForgeDirection.NORTH);

	static void generateAt(World world, int i, int j, int k, Random rand) {
		//door
		world.setBlock(i + 13, j + 2, k + 9, Blocks.sticky_piston, 11, 2);
		world.setBlock(i + 13, j + 2, k + 10, Blocks.piston_head, 11, 2);
		world.setBlock(i + 12, j + 2, k + 9, Blocks.sticky_piston, 11, 2);
		world.setBlock(i + 12, j + 2, k + 10, Blocks.piston_head, 11, 2);

		world.setBlock(i + 13, j + 2, k + 11, b, ms%8, 3);
		world.setBlock(i + 12, j + 2, k + 11, b, ms%8, 3);

		world.setBlock(i + 0, j + 0, k + 0, Blocks.bedrock);
		world.setBlock(i + 0, j + 0, k + 1, Blocks.bedrock);
		world.setBlock(i + 0, j + 0, k + 2, Blocks.bedrock);
		world.setBlock(i + 0, j + 0, k + 3, Blocks.bedrock);
		world.setBlock(i + 0, j + 0, k + 4, Blocks.bedrock);
		world.setBlock(i + 0, j + 0, k + 5, Blocks.bedrock);
		world.setBlock(i + 0, j + 0, k + 6, Blocks.bedrock);
		world.setBlock(i + 0, j + 0, k + 7, Blocks.bedrock);
		world.setBlock(i + 0, j + 0, k + 8, Blocks.bedrock);
		world.setBlock(i + 0, j + 0, k + 9, Blocks.bedrock);
		world.setBlock(i + 0, j + 0, k + 10, Blocks.bedrock);
		world.setBlock(i + 0, j + 0, k + 11, Blocks.bedrock);
		world.setBlock(i + 0, j + 0, k + 12, Blocks.bedrock);
		world.setBlock(i + 0, j + 0, k + 13, Blocks.bedrock);
		world.setBlock(i + 0, j + 0, k + 14, Blocks.bedrock);
		world.setBlock(i + 0, j + 0, k + 15, Blocks.bedrock);
		world.setBlock(i + 0, j + 0, k + 16, Blocks.bedrock);
		world.setBlock(i + 0, j + 0, k + 17, Blocks.bedrock);
		world.setBlock(i + 0, j + 0, k + 18, Blocks.bedrock);
		world.setBlock(i + 0, j + 0, k + 19, Blocks.bedrock);
		world.setBlock(i + 0, j + 0, k + 20, Blocks.bedrock);
		world.setBlock(i + 0, j + 0, k + 21, Blocks.bedrock);
		world.setBlock(i + 0, j + 0, k + 22, Blocks.bedrock);
		world.setBlock(i + 0, j + 0, k + 23, Blocks.bedrock);
		world.setBlock(i + 0, j + 0, k + 24, Blocks.bedrock);
		world.setBlock(i + 0, j + 0, k + 25, Blocks.bedrock);
		world.setBlock(i + 0, j + 1, k + 0, Blocks.air);
		world.setBlock(i + 0, j + 1, k + 1, Blocks.bedrock);
		world.setBlock(i + 0, j + 1, k + 2, Blocks.bedrock);
		world.setBlock(i + 0, j + 1, k + 3, Blocks.bedrock);
		world.setBlock(i + 0, j + 1, k + 4, Blocks.bedrock);
		world.setBlock(i + 0, j + 1, k + 5, Blocks.bedrock);
		world.setBlock(i + 0, j + 1, k + 6, Blocks.bedrock);
		world.setBlock(i + 0, j + 1, k + 7, Blocks.bedrock);
		world.setBlock(i + 0, j + 1, k + 8, Blocks.bedrock);
		world.setBlock(i + 0, j + 1, k + 9, Blocks.bedrock);
		world.setBlock(i + 0, j + 1, k + 10, Blocks.bedrock);
		world.setBlock(i + 0, j + 1, k + 11, Blocks.bedrock);
		world.setBlock(i + 0, j + 1, k + 12, Blocks.bedrock);
		world.setBlock(i + 0, j + 1, k + 13, Blocks.bedrock);
		world.setBlock(i + 0, j + 1, k + 14, Blocks.bedrock);
		world.setBlock(i + 0, j + 1, k + 15, Blocks.bedrock);
		world.setBlock(i + 0, j + 1, k + 16, Blocks.bedrock);
		world.setBlock(i + 0, j + 1, k + 17, Blocks.bedrock);
		world.setBlock(i + 0, j + 1, k + 18, Blocks.bedrock);
		world.setBlock(i + 0, j + 1, k + 19, Blocks.bedrock);
		world.setBlock(i + 0, j + 1, k + 20, Blocks.bedrock);
		world.setBlock(i + 0, j + 1, k + 21, Blocks.bedrock);
		world.setBlock(i + 0, j + 1, k + 22, Blocks.bedrock);
		world.setBlock(i + 0, j + 1, k + 23, Blocks.bedrock);
		world.setBlock(i + 0, j + 1, k + 24, Blocks.bedrock);
		world.setBlock(i + 0, j + 1, k + 25, Blocks.air);
		world.setBlock(i + 0, j + 2, k + 0, Blocks.air);
		world.setBlock(i + 0, j + 2, k + 1, Blocks.air);
		world.setBlock(i + 0, j + 2, k + 2, Blocks.bedrock);
		world.setBlock(i + 0, j + 2, k + 3, Blocks.bedrock);
		world.setBlock(i + 0, j + 2, k + 4, Blocks.bedrock);
		world.setBlock(i + 0, j + 2, k + 5, Blocks.bedrock);
		world.setBlock(i + 0, j + 2, k + 6, Blocks.bedrock);
		world.setBlock(i + 0, j + 2, k + 7, Blocks.bedrock);
		world.setBlock(i + 0, j + 2, k + 8, Blocks.bedrock);
		world.setBlock(i + 0, j + 2, k + 9, Blocks.bedrock);
		world.setBlock(i + 0, j + 2, k + 10, Blocks.bedrock);
		world.setBlock(i + 0, j + 2, k + 11, Blocks.bedrock);
		world.setBlock(i + 0, j + 2, k + 12, Blocks.bedrock);
		world.setBlock(i + 0, j + 2, k + 13, Blocks.bedrock);
		world.setBlock(i + 0, j + 2, k + 14, Blocks.bedrock);
		world.setBlock(i + 0, j + 2, k + 15, Blocks.bedrock);
		world.setBlock(i + 0, j + 2, k + 16, Blocks.bedrock);
		world.setBlock(i + 0, j + 2, k + 17, Blocks.bedrock);
		world.setBlock(i + 0, j + 2, k + 18, Blocks.bedrock);
		world.setBlock(i + 0, j + 2, k + 19, Blocks.bedrock);
		world.setBlock(i + 0, j + 2, k + 20, Blocks.bedrock);
		world.setBlock(i + 0, j + 2, k + 21, Blocks.bedrock);
		world.setBlock(i + 0, j + 2, k + 22, Blocks.bedrock);
		world.setBlock(i + 0, j + 2, k + 23, Blocks.bedrock);
		world.setBlock(i + 0, j + 2, k + 24, Blocks.air);
		world.setBlock(i + 0, j + 2, k + 25, Blocks.air);
		world.setBlock(i + 0, j + 3, k + 0, Blocks.air);
		world.setBlock(i + 0, j + 3, k + 1, Blocks.air);
		world.setBlock(i + 0, j + 3, k + 2, Blocks.air);
		world.setBlock(i + 0, j + 3, k + 3, Blocks.nether_brick);
		world.setBlock(i + 0, j + 3, k + 4, Blocks.nether_brick);
		world.setBlock(i + 0, j + 3, k + 5, Blocks.nether_brick);
		world.setBlock(i + 0, j + 3, k + 6, Blocks.nether_brick);
		world.setBlock(i + 0, j + 3, k + 7, Blocks.nether_brick);
		world.setBlock(i + 0, j + 3, k + 8, Blocks.nether_brick);
		world.setBlock(i + 0, j + 3, k + 9, Blocks.nether_brick);
		world.setBlock(i + 0, j + 3, k + 10, Blocks.nether_brick);
		world.setBlock(i + 0, j + 3, k + 11, Blocks.nether_brick);
		world.setBlock(i + 0, j + 3, k + 12, Blocks.nether_brick);
		world.setBlock(i + 0, j + 3, k + 13, Blocks.nether_brick);
		world.setBlock(i + 0, j + 3, k + 14, Blocks.nether_brick);
		world.setBlock(i + 0, j + 3, k + 15, Blocks.nether_brick);
		world.setBlock(i + 0, j + 3, k + 16, Blocks.nether_brick);
		world.setBlock(i + 0, j + 3, k + 17, Blocks.nether_brick);
		world.setBlock(i + 0, j + 3, k + 18, Blocks.nether_brick);
		world.setBlock(i + 0, j + 3, k + 19, Blocks.nether_brick);
		world.setBlock(i + 0, j + 3, k + 20, Blocks.nether_brick);
		world.setBlock(i + 0, j + 3, k + 21, Blocks.nether_brick);
		world.setBlock(i + 0, j + 3, k + 22, Blocks.nether_brick);
		world.setBlock(i + 0, j + 3, k + 23, Blocks.air);
		world.setBlock(i + 0, j + 3, k + 24, Blocks.air);
		world.setBlock(i + 0, j + 3, k + 25, Blocks.air);
		world.setBlock(i + 0, j + 4, k + 0, Blocks.air);
		world.setBlock(i + 0, j + 4, k + 1, Blocks.air);
		world.setBlock(i + 0, j + 4, k + 2, Blocks.air);
		world.setBlock(i + 0, j + 4, k + 3, Blocks.nether_brick);
		world.setBlock(i + 0, j + 4, k + 4, Blocks.nether_brick);
		world.setBlock(i + 0, j + 4, k + 5, Blocks.nether_brick);
		world.setBlock(i + 0, j + 4, k + 6, Blocks.nether_brick);
		world.setBlock(i + 0, j + 4, k + 7, Blocks.nether_brick);
		world.setBlock(i + 0, j + 4, k + 8, Blocks.nether_brick);
		world.setBlock(i + 0, j + 4, k + 9, Blocks.nether_brick);
		world.setBlock(i + 0, j + 4, k + 10, Blocks.nether_brick);
		world.setBlock(i + 0, j + 4, k + 11, Blocks.nether_brick);
		world.setBlock(i + 0, j + 4, k + 12, Blocks.nether_brick);
		world.setBlock(i + 0, j + 4, k + 13, Blocks.nether_brick);
		world.setBlock(i + 0, j + 4, k + 14, Blocks.nether_brick);
		world.setBlock(i + 0, j + 4, k + 15, Blocks.nether_brick);
		world.setBlock(i + 0, j + 4, k + 16, Blocks.nether_brick);
		world.setBlock(i + 0, j + 4, k + 17, Blocks.nether_brick);
		world.setBlock(i + 0, j + 4, k + 18, Blocks.nether_brick);
		world.setBlock(i + 0, j + 4, k + 19, Blocks.nether_brick);
		world.setBlock(i + 0, j + 4, k + 20, Blocks.nether_brick);
		world.setBlock(i + 0, j + 4, k + 21, Blocks.nether_brick);
		world.setBlock(i + 0, j + 4, k + 22, Blocks.nether_brick);
		world.setBlock(i + 0, j + 4, k + 23, Blocks.air);
		world.setBlock(i + 0, j + 4, k + 24, Blocks.air);
		world.setBlock(i + 0, j + 4, k + 25, Blocks.air);
		world.setBlock(i + 0, j + 5, k + 0, Blocks.air);
		world.setBlock(i + 0, j + 5, k + 1, Blocks.air);
		world.setBlock(i + 0, j + 5, k + 2, Blocks.air);
		world.setBlock(i + 0, j + 5, k + 3, Blocks.nether_brick);
		world.setBlock(i + 0, j + 5, k + 4, Blocks.nether_brick);
		world.setBlock(i + 0, j + 5, k + 5, Blocks.nether_brick);
		world.setBlock(i + 0, j + 5, k + 6, Blocks.nether_brick);
		world.setBlock(i + 0, j + 5, k + 7, Blocks.nether_brick);
		world.setBlock(i + 0, j + 5, k + 8, Blocks.nether_brick);
		world.setBlock(i + 0, j + 5, k + 9, Blocks.nether_brick);
		world.setBlock(i + 0, j + 5, k + 10, Blocks.nether_brick);
		world.setBlock(i + 0, j + 5, k + 11, Blocks.nether_brick);
		world.setBlock(i + 0, j + 5, k + 12, Blocks.nether_brick);
		world.setBlock(i + 0, j + 5, k + 13, Blocks.nether_brick);
		world.setBlock(i + 0, j + 5, k + 14, Blocks.nether_brick);
		world.setBlock(i + 0, j + 5, k + 15, Blocks.nether_brick);
		world.setBlock(i + 0, j + 5, k + 16, Blocks.nether_brick);
		world.setBlock(i + 0, j + 5, k + 17, Blocks.nether_brick);
		world.setBlock(i + 0, j + 5, k + 18, Blocks.nether_brick);
		world.setBlock(i + 0, j + 5, k + 19, Blocks.nether_brick);
		world.setBlock(i + 0, j + 5, k + 20, Blocks.nether_brick);
		world.setBlock(i + 0, j + 5, k + 21, Blocks.nether_brick);
		world.setBlock(i + 0, j + 5, k + 22, Blocks.nether_brick);
		world.setBlock(i + 0, j + 5, k + 23, Blocks.air);
		world.setBlock(i + 0, j + 5, k + 24, Blocks.air);
		world.setBlock(i + 0, j + 5, k + 25, Blocks.air);
		world.setBlock(i + 0, j + 6, k + 0, Blocks.air);
		world.setBlock(i + 0, j + 6, k + 1, Blocks.air);
		world.setBlock(i + 0, j + 6, k + 2, Blocks.air);
		world.setBlock(i + 0, j + 6, k + 3, Blocks.nether_brick);
		world.setBlock(i + 0, j + 6, k + 4, Blocks.nether_brick);
		world.setBlock(i + 0, j + 6, k + 5, Blocks.nether_brick);
		world.setBlock(i + 0, j + 6, k + 6, Blocks.nether_brick);
		world.setBlock(i + 0, j + 6, k + 7, Blocks.nether_brick);
		world.setBlock(i + 0, j + 6, k + 8, Blocks.nether_brick);
		world.setBlock(i + 0, j + 6, k + 9, Blocks.nether_brick);
		world.setBlock(i + 0, j + 6, k + 10, Blocks.nether_brick);
		world.setBlock(i + 0, j + 6, k + 11, Blocks.nether_brick);
		world.setBlock(i + 0, j + 6, k + 12, Blocks.nether_brick);
		world.setBlock(i + 0, j + 6, k + 13, Blocks.nether_brick);
		world.setBlock(i + 0, j + 6, k + 14, Blocks.nether_brick);
		world.setBlock(i + 0, j + 6, k + 15, Blocks.nether_brick);
		world.setBlock(i + 0, j + 6, k + 16, Blocks.nether_brick);
		world.setBlock(i + 0, j + 6, k + 17, Blocks.nether_brick);
		world.setBlock(i + 0, j + 6, k + 18, Blocks.nether_brick);
		world.setBlock(i + 0, j + 6, k + 19, Blocks.nether_brick);
		world.setBlock(i + 0, j + 6, k + 20, Blocks.nether_brick);
		world.setBlock(i + 0, j + 6, k + 21, Blocks.nether_brick);
		world.setBlock(i + 0, j + 6, k + 22, Blocks.nether_brick);
		world.setBlock(i + 0, j + 6, k + 23, Blocks.air);
		world.setBlock(i + 0, j + 6, k + 24, Blocks.air);
		world.setBlock(i + 0, j + 6, k + 25, Blocks.air);
		world.setBlock(i + 0, j + 7, k + 0, Blocks.air);
		world.setBlock(i + 0, j + 7, k + 1, Blocks.air);
		world.setBlock(i + 0, j + 7, k + 2, Blocks.air);
		world.setBlock(i + 0, j + 7, k + 3, Blocks.nether_brick);
		world.setBlock(i + 0, j + 7, k + 4, Blocks.nether_brick);
		world.setBlock(i + 0, j + 7, k + 5, Blocks.nether_brick);
		world.setBlock(i + 0, j + 7, k + 6, Blocks.nether_brick);
		world.setBlock(i + 0, j + 7, k + 7, Blocks.nether_brick);
		world.setBlock(i + 0, j + 7, k + 8, Blocks.nether_brick);
		world.setBlock(i + 0, j + 7, k + 9, Blocks.nether_brick);
		world.setBlock(i + 0, j + 7, k + 10, Blocks.nether_brick);
		world.setBlock(i + 0, j + 7, k + 11, Blocks.nether_brick);
		world.setBlock(i + 0, j + 7, k + 12, Blocks.nether_brick);
		world.setBlock(i + 0, j + 7, k + 13, Blocks.nether_brick);
		world.setBlock(i + 0, j + 7, k + 14, Blocks.nether_brick);
		world.setBlock(i + 0, j + 7, k + 15, Blocks.nether_brick);
		world.setBlock(i + 0, j + 7, k + 16, Blocks.nether_brick);
		world.setBlock(i + 0, j + 7, k + 17, Blocks.nether_brick);
		world.setBlock(i + 0, j + 7, k + 18, Blocks.nether_brick);
		world.setBlock(i + 0, j + 7, k + 19, Blocks.nether_brick);
		world.setBlock(i + 0, j + 7, k + 20, Blocks.nether_brick);
		world.setBlock(i + 0, j + 7, k + 21, Blocks.nether_brick);
		world.setBlock(i + 0, j + 7, k + 22, Blocks.nether_brick);
		world.setBlock(i + 0, j + 7, k + 23, Blocks.air);
		world.setBlock(i + 0, j + 7, k + 24, Blocks.air);
		world.setBlock(i + 0, j + 7, k + 25, Blocks.air);
		world.setBlock(i + 0, j + 8, k + 0, Blocks.air);
		world.setBlock(i + 0, j + 8, k + 1, Blocks.air);
		world.setBlock(i + 0, j + 8, k + 2, Blocks.air);
		world.setBlock(i + 0, j + 8, k + 3, Blocks.nether_brick);
		world.setBlock(i + 0, j + 8, k + 4, Blocks.nether_brick);
		world.setBlock(i + 0, j + 8, k + 5, Blocks.nether_brick);
		world.setBlock(i + 0, j + 8, k + 6, Blocks.air);
		world.setBlock(i + 0, j + 8, k + 7, Blocks.air);
		world.setBlock(i + 0, j + 8, k + 8, Blocks.air);
		world.setBlock(i + 0, j + 8, k + 9, Blocks.air);
		world.setBlock(i + 0, j + 8, k + 10, Blocks.air);
		world.setBlock(i + 0, j + 8, k + 11, Blocks.air);
		world.setBlock(i + 0, j + 8, k + 12, Blocks.air);
		world.setBlock(i + 0, j + 8, k + 13, Blocks.air);
		world.setBlock(i + 0, j + 8, k + 14, Blocks.air);
		world.setBlock(i + 0, j + 8, k + 15, Blocks.air);
		world.setBlock(i + 0, j + 8, k + 16, Blocks.air);
		world.setBlock(i + 0, j + 8, k + 17, Blocks.air);
		world.setBlock(i + 0, j + 8, k + 18, Blocks.air);
		world.setBlock(i + 0, j + 8, k + 19, Blocks.air);
		world.setBlock(i + 0, j + 8, k + 20, Blocks.air);
		world.setBlock(i + 0, j + 8, k + 21, Blocks.air);
		world.setBlock(i + 0, j + 8, k + 22, Blocks.air);
		world.setBlock(i + 0, j + 8, k + 23, Blocks.air);
		world.setBlock(i + 0, j + 8, k + 24, Blocks.air);
		world.setBlock(i + 0, j + 8, k + 25, Blocks.air);
		world.setBlock(i + 0, j + 9, k + 0, Blocks.air);
		world.setBlock(i + 0, j + 9, k + 1, Blocks.air);
		world.setBlock(i + 0, j + 9, k + 2, Blocks.air);
		world.setBlock(i + 0, j + 9, k + 3, Blocks.air);
		world.setBlock(i + 0, j + 9, k + 4, Blocks.air);
		world.setBlock(i + 0, j + 9, k + 5, Blocks.air);
		world.setBlock(i + 0, j + 9, k + 6, Blocks.air);
		world.setBlock(i + 0, j + 9, k + 7, Blocks.air);
		world.setBlock(i + 0, j + 9, k + 8, Blocks.air);
		world.setBlock(i + 0, j + 9, k + 9, Blocks.air);
		world.setBlock(i + 0, j + 9, k + 10, Blocks.air);
		world.setBlock(i + 0, j + 9, k + 11, Blocks.air);
		world.setBlock(i + 0, j + 9, k + 12, Blocks.air);
		world.setBlock(i + 0, j + 9, k + 13, Blocks.air);
		world.setBlock(i + 0, j + 9, k + 14, Blocks.air);
		world.setBlock(i + 0, j + 9, k + 15, Blocks.air);
		world.setBlock(i + 0, j + 9, k + 16, Blocks.air);
		world.setBlock(i + 0, j + 9, k + 17, Blocks.air);
		world.setBlock(i + 0, j + 9, k + 18, Blocks.air);
		world.setBlock(i + 0, j + 9, k + 19, Blocks.air);
		world.setBlock(i + 0, j + 9, k + 20, Blocks.air);
		world.setBlock(i + 0, j + 9, k + 21, Blocks.air);
		world.setBlock(i + 0, j + 9, k + 22, Blocks.air);
		world.setBlock(i + 0, j + 9, k + 23, Blocks.air);
		world.setBlock(i + 0, j + 9, k + 24, Blocks.air);
		world.setBlock(i + 0, j + 9, k + 25, Blocks.air);
		world.setBlock(i + 0, j + 10, k + 0, Blocks.air);
		world.setBlock(i + 0, j + 10, k + 1, Blocks.air);
		world.setBlock(i + 0, j + 10, k + 2, Blocks.air);
		world.setBlock(i + 0, j + 10, k + 3, Blocks.air);
		world.setBlock(i + 0, j + 10, k + 4, Blocks.air);
		world.setBlock(i + 0, j + 10, k + 5, Blocks.air);
		world.setBlock(i + 0, j + 10, k + 6, Blocks.air);
		world.setBlock(i + 0, j + 10, k + 7, Blocks.air);
		world.setBlock(i + 0, j + 10, k + 8, Blocks.air);
		world.setBlock(i + 0, j + 10, k + 9, Blocks.air);
		world.setBlock(i + 0, j + 10, k + 10, Blocks.air);
		world.setBlock(i + 0, j + 10, k + 11, Blocks.air);
		world.setBlock(i + 0, j + 10, k + 12, Blocks.air);
		world.setBlock(i + 0, j + 10, k + 13, Blocks.air);
		world.setBlock(i + 0, j + 10, k + 14, Blocks.air);
		world.setBlock(i + 0, j + 10, k + 15, Blocks.air);
		world.setBlock(i + 0, j + 10, k + 16, Blocks.air);
		world.setBlock(i + 0, j + 10, k + 17, Blocks.air);
		world.setBlock(i + 0, j + 10, k + 18, Blocks.air);
		world.setBlock(i + 0, j + 10, k + 19, Blocks.air);
		world.setBlock(i + 0, j + 10, k + 20, Blocks.air);
		world.setBlock(i + 0, j + 10, k + 21, Blocks.air);
		world.setBlock(i + 0, j + 10, k + 22, Blocks.air);
		world.setBlock(i + 0, j + 10, k + 23, Blocks.air);
		world.setBlock(i + 0, j + 10, k + 24, Blocks.air);
		world.setBlock(i + 0, j + 10, k + 25, Blocks.air);
		world.setBlock(i + 1, j + 0, k + 0, Blocks.bedrock);
		world.setBlock(i + 1, j + 0, k + 1, Blocks.bedrock);
		world.setBlock(i + 1, j + 0, k + 2, Blocks.bedrock);
		world.setBlock(i + 1, j + 0, k + 3, Blocks.bedrock);
		world.setBlock(i + 1, j + 0, k + 4, Blocks.bedrock);
		world.setBlock(i + 1, j + 0, k + 5, Blocks.bedrock);
		world.setBlock(i + 1, j + 0, k + 6, Blocks.bedrock);
		world.setBlock(i + 1, j + 0, k + 7, Blocks.bedrock);
		world.setBlock(i + 1, j + 0, k + 8, Blocks.bedrock);
		world.setBlock(i + 1, j + 0, k + 9, Blocks.bedrock);
		world.setBlock(i + 1, j + 0, k + 10, Blocks.bedrock);
		world.setBlock(i + 1, j + 0, k + 11, Blocks.bedrock);
		world.setBlock(i + 1, j + 0, k + 12, Blocks.bedrock);
		world.setBlock(i + 1, j + 0, k + 13, Blocks.bedrock);
		world.setBlock(i + 1, j + 0, k + 14, Blocks.bedrock);
		world.setBlock(i + 1, j + 0, k + 15, Blocks.bedrock);
		world.setBlock(i + 1, j + 0, k + 16, Blocks.bedrock);
		world.setBlock(i + 1, j + 0, k + 17, Blocks.bedrock);
		world.setBlock(i + 1, j + 0, k + 18, Blocks.bedrock);
		world.setBlock(i + 1, j + 0, k + 19, Blocks.bedrock);
		world.setBlock(i + 1, j + 0, k + 20, Blocks.bedrock);
		world.setBlock(i + 1, j + 0, k + 21, Blocks.bedrock);
		world.setBlock(i + 1, j + 0, k + 22, Blocks.bedrock);
		world.setBlock(i + 1, j + 0, k + 23, Blocks.bedrock);
		world.setBlock(i + 1, j + 0, k + 24, Blocks.bedrock);
		world.setBlock(i + 1, j + 0, k + 25, Blocks.quartz_stairs, 3, 3);
		world.setBlock(i + 1, j + 1, k + 0, Blocks.air);
		world.setBlock(i + 1, j + 1, k + 1, Blocks.bedrock);
		world.setBlock(i + 1, j + 1, k + 2, Blocks.bedrock);
		world.setBlock(i + 1, j + 1, k + 3, Blocks.bedrock);
		world.setBlock(i + 1, j + 1, k + 5, Blocks.bedrock);
		world.setBlock(i + 1, j + 1, k + 6, Blocks.bedrock);
		world.setBlock(i + 1, j + 1, k + 7, Blocks.bedrock);
		world.setBlock(i + 1, j + 1, k + 8, Blocks.bedrock);
		world.setBlock(i + 1, j + 1, k + 9, Blocks.bedrock);
		world.setBlock(i + 1, j + 1, k + 10, Blocks.bedrock);
		world.setBlock(i + 1, j + 1, k + 11, Blocks.bedrock);
		world.setBlock(i + 1, j + 1, k + 12, Blocks.bedrock);
		world.setBlock(i + 1, j + 1, k + 13, Blocks.bedrock);
		world.setBlock(i + 1, j + 1, k + 14, Blocks.bedrock);
		world.setBlock(i + 1, j + 1, k + 15, Blocks.bedrock);
		world.setBlock(i + 1, j + 1, k + 16, Blocks.bedrock);
		world.setBlock(i + 1, j + 1, k + 17, Blocks.bedrock);
		world.setBlock(i + 1, j + 1, k + 18, Blocks.bedrock);
		world.setBlock(i + 1, j + 1, k + 19, Blocks.bedrock);
		world.setBlock(i + 1, j + 1, k + 20, Blocks.bedrock);
		world.setBlock(i + 1, j + 1, k + 21, Blocks.bedrock);
		world.setBlock(i + 1, j + 1, k + 22, Blocks.bedrock);
		world.setBlock(i + 1, j + 1, k + 23, Blocks.bedrock);
		world.setBlock(i + 1, j + 1, k + 24, Blocks.quartz_stairs, 3, 3);
		world.setBlock(i + 1, j + 1, k + 25, Blocks.air);
		world.setBlock(i + 1, j + 2, k + 0, Blocks.air);
		world.setBlock(i + 1, j + 2, k + 1, Blocks.air);
		world.setBlock(i + 1, j + 2, k + 2, Blocks.bedrock);
		world.setBlock(i + 1, j + 2, k + 3, Blocks.bedrock);
		world.setBlock(i + 1, j + 2, k + 5, Blocks.bedrock);
		world.setBlock(i + 1, j + 2, k + 22, Blocks.nether_brick);
		world.setBlock(i + 1, j + 2, k + 23, Blocks.quartz_stairs, 3, 3);
		world.setBlock(i + 1, j + 2, k + 24, Blocks.air);
		world.setBlock(i + 1, j + 2, k + 25, Blocks.air);
		world.setBlock(i + 1, j + 3, k + 0, Blocks.air);
		world.setBlock(i + 1, j + 3, k + 1, Blocks.air);
		world.setBlock(i + 1, j + 3, k + 2, Blocks.air);
		world.setBlock(i + 1, j + 3, k + 3, Blocks.nether_brick);
		world.setBlock(i + 1, j + 3, k + 4, Blocks.bedrock);
		world.setBlock(i + 1, j + 3, k + 5, b, ms, 3);
		world.setBlock(i + 1, j + 3, k + 6, Blocks.air);
		world.setBlock(i + 1, j + 3, k + 7, Blocks.air);
		world.setBlock(i + 1, j + 3, k + 8, Blocks.air);
		world.setBlock(i + 1, j + 3, k + 9, Blocks.air);
		world.setBlock(i + 1, j + 3, k + 10, Blocks.air);
		world.setBlock(i + 1, j + 3, k + 11, Blocks.air);
		world.setBlock(i + 1, j + 3, k + 12, Blocks.air);
		world.setBlock(i + 1, j + 3, k + 13, Blocks.air);
		world.setBlock(i + 1, j + 3, k + 14, Blocks.air);
		world.setBlock(i + 1, j + 3, k + 15, Blocks.air);
		world.setBlock(i + 1, j + 3, k + 16, Blocks.air);
		world.setBlock(i + 1, j + 3, k + 17, Blocks.air);
		world.setBlock(i + 1, j + 3, k + 18, Blocks.air);
		world.setBlock(i + 1, j + 3, k + 19, Blocks.air);
		world.setBlock(i + 1, j + 3, k + 20, Blocks.air);
		world.setBlock(i + 1, j + 3, k + 21, Blocks.air);
		world.setBlock(i + 1, j + 3, k + 22, Blocks.air);
		world.setBlock(i + 1, j + 3, k + 23, Blocks.air);
		world.setBlock(i + 1, j + 3, k + 24, Blocks.air);
		world.setBlock(i + 1, j + 3, k + 25, Blocks.air);
		world.setBlock(i + 1, j + 4, k + 0, Blocks.air);
		world.setBlock(i + 1, j + 4, k + 1, Blocks.air);
		world.setBlock(i + 1, j + 4, k + 2, Blocks.air);
		world.setBlock(i + 1, j + 4, k + 3, Blocks.nether_brick);
		world.setBlock(i + 1, j + 4, k + 4, Blocks.bedrock);
		world.setBlock(i + 1, j + 4, k + 5, b, ms, 3);
		world.setBlock(i + 1, j + 4, k + 6, Blocks.air);
		world.setBlock(i + 1, j + 4, k + 7, Blocks.air);
		world.setBlock(i + 1, j + 4, k + 8, Blocks.air);
		world.setBlock(i + 1, j + 4, k + 9, Blocks.air);
		world.setBlock(i + 1, j + 4, k + 10, Blocks.air);
		world.setBlock(i + 1, j + 4, k + 11, Blocks.air);
		world.setBlock(i + 1, j + 4, k + 12, Blocks.air);
		world.setBlock(i + 1, j + 4, k + 13, Blocks.air);
		world.setBlock(i + 1, j + 4, k + 14, Blocks.air);
		world.setBlock(i + 1, j + 4, k + 15, Blocks.air);
		world.setBlock(i + 1, j + 4, k + 16, Blocks.air);
		world.setBlock(i + 1, j + 4, k + 17, Blocks.air);
		world.setBlock(i + 1, j + 4, k + 18, Blocks.air);
		world.setBlock(i + 1, j + 4, k + 19, Blocks.air);
		world.setBlock(i + 1, j + 4, k + 20, Blocks.air);
		world.setBlock(i + 1, j + 4, k + 21, Blocks.air);
		world.setBlock(i + 1, j + 4, k + 22, Blocks.air);
		world.setBlock(i + 1, j + 4, k + 23, Blocks.air);
		world.setBlock(i + 1, j + 4, k + 24, Blocks.air);
		world.setBlock(i + 1, j + 4, k + 25, Blocks.air);
		world.setBlock(i + 1, j + 5, k + 0, Blocks.air);
		world.setBlock(i + 1, j + 5, k + 1, Blocks.air);
		world.setBlock(i + 1, j + 5, k + 2, Blocks.air);
		world.setBlock(i + 1, j + 5, k + 3, Blocks.nether_brick);
		world.setBlock(i + 1, j + 5, k + 4, Blocks.bedrock);
		world.setBlock(i + 1, j + 5, k + 5, b, ms, 3);
		world.setBlock(i + 1, j + 5, k + 6, Blocks.air);
		world.setBlock(i + 1, j + 5, k + 7, Blocks.air);
		world.setBlock(i + 1, j + 5, k + 8, Blocks.air);
		world.setBlock(i + 1, j + 5, k + 9, Blocks.air);
		world.setBlock(i + 1, j + 5, k + 10, Blocks.air);
		world.setBlock(i + 1, j + 5, k + 11, Blocks.air);
		world.setBlock(i + 1, j + 5, k + 12, Blocks.air);
		world.setBlock(i + 1, j + 5, k + 13, Blocks.air);
		world.setBlock(i + 1, j + 5, k + 14, Blocks.air);
		world.setBlock(i + 1, j + 5, k + 15, Blocks.air);
		world.setBlock(i + 1, j + 5, k + 16, Blocks.air);
		world.setBlock(i + 1, j + 5, k + 17, Blocks.air);
		world.setBlock(i + 1, j + 5, k + 18, Blocks.air);
		world.setBlock(i + 1, j + 5, k + 19, Blocks.air);
		world.setBlock(i + 1, j + 5, k + 20, Blocks.air);
		world.setBlock(i + 1, j + 5, k + 21, Blocks.air);
		world.setBlock(i + 1, j + 5, k + 22, Blocks.air);
		world.setBlock(i + 1, j + 5, k + 23, Blocks.air);
		world.setBlock(i + 1, j + 5, k + 24, Blocks.air);
		world.setBlock(i + 1, j + 5, k + 25, Blocks.air);
		world.setBlock(i + 1, j + 6, k + 0, Blocks.air);
		world.setBlock(i + 1, j + 6, k + 1, Blocks.air);
		world.setBlock(i + 1, j + 6, k + 2, Blocks.air);
		world.setBlock(i + 1, j + 6, k + 3, Blocks.nether_brick);
		world.setBlock(i + 1, j + 6, k + 4, Blocks.bedrock);
		world.setBlock(i + 1, j + 6, k + 5, Blocks.nether_brick);
		world.setBlock(i + 1, j + 6, k + 6, Blocks.air);
		world.setBlock(i + 1, j + 6, k + 7, Blocks.air);
		world.setBlock(i + 1, j + 6, k + 8, Blocks.air);
		world.setBlock(i + 1, j + 6, k + 9, Blocks.air);
		world.setBlock(i + 1, j + 6, k + 10, Blocks.air);
		world.setBlock(i + 1, j + 6, k + 11, Blocks.air);
		world.setBlock(i + 1, j + 6, k + 12, Blocks.air);
		world.setBlock(i + 1, j + 6, k + 13, Blocks.air);
		world.setBlock(i + 1, j + 6, k + 14, Blocks.air);
		world.setBlock(i + 1, j + 6, k + 15, Blocks.air);
		world.setBlock(i + 1, j + 6, k + 16, Blocks.air);
		world.setBlock(i + 1, j + 6, k + 17, Blocks.air);
		world.setBlock(i + 1, j + 6, k + 18, Blocks.air);
		world.setBlock(i + 1, j + 6, k + 19, Blocks.air);
		world.setBlock(i + 1, j + 6, k + 20, Blocks.air);
		world.setBlock(i + 1, j + 6, k + 21, Blocks.air);
		world.setBlock(i + 1, j + 6, k + 22, Blocks.air);
		world.setBlock(i + 1, j + 6, k + 23, Blocks.air);
		world.setBlock(i + 1, j + 6, k + 24, Blocks.air);
		world.setBlock(i + 1, j + 6, k + 25, Blocks.air);
		world.setBlock(i + 1, j + 7, k + 0, Blocks.air);
		world.setBlock(i + 1, j + 7, k + 1, Blocks.air);
		world.setBlock(i + 1, j + 7, k + 2, Blocks.air);
		world.setBlock(i + 1, j + 7, k + 3, Blocks.nether_brick);
		world.setBlock(i + 1, j + 7, k + 4, Blocks.bedrock);
		world.setBlock(i + 1, j + 7, k + 5, Blocks.nether_brick);
		world.setBlock(i + 1, j + 7, k + 6, Blocks.nether_brick);
		world.setBlock(i + 1, j + 7, k + 7, Blocks.nether_brick);
		world.setBlock(i + 1, j + 7, k + 8, Blocks.nether_brick);
		world.setBlock(i + 1, j + 7, k + 9, Blocks.nether_brick);
		world.setBlock(i + 1, j + 7, k + 10, Blocks.nether_brick);
		world.setBlock(i + 1, j + 7, k + 11, Blocks.nether_brick);
		world.setBlock(i + 1, j + 7, k + 12, Blocks.nether_brick);
		world.setBlock(i + 1, j + 7, k + 13, Blocks.nether_brick);
		world.setBlock(i + 1, j + 7, k + 14, Blocks.nether_brick);
		world.setBlock(i + 1, j + 7, k + 15, Blocks.nether_brick);
		world.setBlock(i + 1, j + 7, k + 16, Blocks.nether_brick);
		world.setBlock(i + 1, j + 7, k + 17, Blocks.nether_brick);
		world.setBlock(i + 1, j + 7, k + 18, Blocks.nether_brick);
		world.setBlock(i + 1, j + 7, k + 19, Blocks.nether_brick);
		world.setBlock(i + 1, j + 7, k + 20, Blocks.nether_brick);
		world.setBlock(i + 1, j + 7, k + 21, Blocks.nether_brick);
		world.setBlock(i + 1, j + 7, k + 22, Blocks.nether_brick);
		world.setBlock(i + 1, j + 7, k + 23, Blocks.air);
		world.setBlock(i + 1, j + 7, k + 24, Blocks.air);
		world.setBlock(i + 1, j + 7, k + 25, Blocks.air);
		world.setBlock(i + 1, j + 8, k + 0, Blocks.air);
		world.setBlock(i + 1, j + 8, k + 1, Blocks.air);
		world.setBlock(i + 1, j + 8, k + 2, Blocks.air);
		world.setBlock(i + 1, j + 8, k + 3, Blocks.nether_brick);
		world.setBlock(i + 1, j + 8, k + 4, Blocks.nether_brick);
		world.setBlock(i + 1, j + 8, k + 5, Blocks.nether_brick);
		world.setBlock(i + 1, j + 8, k + 6, Blocks.air);
		world.setBlock(i + 1, j + 8, k + 7, Blocks.air);
		world.setBlock(i + 1, j + 8, k + 8, Blocks.air);
		world.setBlock(i + 1, j + 8, k + 9, Blocks.air);
		world.setBlock(i + 1, j + 8, k + 10, Blocks.air);
		world.setBlock(i + 1, j + 8, k + 11, Blocks.air);
		world.setBlock(i + 1, j + 8, k + 12, Blocks.air);
		world.setBlock(i + 1, j + 8, k + 13, Blocks.air);
		world.setBlock(i + 1, j + 8, k + 14, Blocks.air);
		world.setBlock(i + 1, j + 8, k + 15, Blocks.air);
		world.setBlock(i + 1, j + 8, k + 16, Blocks.air);
		world.setBlock(i + 1, j + 8, k + 17, Blocks.air);
		world.setBlock(i + 1, j + 8, k + 18, Blocks.air);
		world.setBlock(i + 1, j + 8, k + 19, Blocks.air);
		world.setBlock(i + 1, j + 8, k + 20, Blocks.air);
		world.setBlock(i + 1, j + 8, k + 21, Blocks.air);
		world.setBlock(i + 1, j + 8, k + 22, Blocks.air);
		world.setBlock(i + 1, j + 8, k + 23, Blocks.air);
		world.setBlock(i + 1, j + 8, k + 24, Blocks.air);
		world.setBlock(i + 1, j + 8, k + 25, Blocks.air);
		world.setBlock(i + 1, j + 9, k + 0, Blocks.air);
		world.setBlock(i + 1, j + 9, k + 1, Blocks.air);
		world.setBlock(i + 1, j + 9, k + 2, Blocks.air);
		world.setBlock(i + 1, j + 9, k + 3, Blocks.air);
		world.setBlock(i + 1, j + 9, k + 4, Blocks.air);
		world.setBlock(i + 1, j + 9, k + 5, Blocks.air);
		world.setBlock(i + 1, j + 9, k + 6, Blocks.air);
		world.setBlock(i + 1, j + 9, k + 7, Blocks.air);
		world.setBlock(i + 1, j + 9, k + 8, Blocks.air);
		world.setBlock(i + 1, j + 9, k + 9, Blocks.air);
		world.setBlock(i + 1, j + 9, k + 10, Blocks.air);
		world.setBlock(i + 1, j + 9, k + 11, Blocks.air);
		world.setBlock(i + 1, j + 9, k + 12, Blocks.air);
		world.setBlock(i + 1, j + 9, k + 13, Blocks.air);
		world.setBlock(i + 1, j + 9, k + 14, Blocks.air);
		world.setBlock(i + 1, j + 9, k + 15, Blocks.air);
		world.setBlock(i + 1, j + 9, k + 16, Blocks.air);
		world.setBlock(i + 1, j + 9, k + 17, Blocks.air);
		world.setBlock(i + 1, j + 9, k + 18, Blocks.air);
		world.setBlock(i + 1, j + 9, k + 19, Blocks.air);
		world.setBlock(i + 1, j + 9, k + 20, Blocks.air);
		world.setBlock(i + 1, j + 9, k + 21, Blocks.air);
		world.setBlock(i + 1, j + 9, k + 22, Blocks.air);
		world.setBlock(i + 1, j + 9, k + 23, Blocks.air);
		world.setBlock(i + 1, j + 9, k + 24, Blocks.air);
		world.setBlock(i + 1, j + 9, k + 25, Blocks.air);
		world.setBlock(i + 1, j + 10, k + 0, Blocks.air);
		world.setBlock(i + 1, j + 10, k + 1, Blocks.air);
		world.setBlock(i + 1, j + 10, k + 2, Blocks.air);
		world.setBlock(i + 1, j + 10, k + 3, Blocks.air);
		world.setBlock(i + 1, j + 10, k + 4, Blocks.air);
		world.setBlock(i + 1, j + 10, k + 5, Blocks.air);
		world.setBlock(i + 1, j + 10, k + 6, Blocks.air);
		world.setBlock(i + 1, j + 10, k + 7, Blocks.air);
		world.setBlock(i + 1, j + 10, k + 8, Blocks.air);
		world.setBlock(i + 1, j + 10, k + 9, Blocks.air);
		world.setBlock(i + 1, j + 10, k + 10, Blocks.air);
		world.setBlock(i + 1, j + 10, k + 11, Blocks.air);
		world.setBlock(i + 1, j + 10, k + 12, Blocks.air);
		world.setBlock(i + 1, j + 10, k + 13, Blocks.air);
		world.setBlock(i + 1, j + 10, k + 14, Blocks.air);
		world.setBlock(i + 1, j + 10, k + 15, Blocks.air);
		world.setBlock(i + 1, j + 10, k + 16, Blocks.air);
		world.setBlock(i + 1, j + 10, k + 17, Blocks.air);
		world.setBlock(i + 1, j + 10, k + 18, Blocks.air);
		world.setBlock(i + 1, j + 10, k + 19, Blocks.air);
		world.setBlock(i + 1, j + 10, k + 20, Blocks.air);
		world.setBlock(i + 1, j + 10, k + 21, Blocks.air);
		world.setBlock(i + 1, j + 10, k + 22, Blocks.air);
		world.setBlock(i + 1, j + 10, k + 23, Blocks.air);
		world.setBlock(i + 1, j + 10, k + 24, Blocks.air);
		world.setBlock(i + 1, j + 10, k + 25, Blocks.air);
		world.setBlock(i + 2, j + 0, k + 0, Blocks.bedrock);
		world.setBlock(i + 2, j + 0, k + 1, Blocks.bedrock);
		world.setBlock(i + 2, j + 0, k + 2, Blocks.bedrock);
		world.setBlock(i + 2, j + 0, k + 3, Blocks.bedrock);
		world.setBlock(i + 2, j + 0, k + 4, Blocks.bedrock);
		world.setBlock(i + 2, j + 0, k + 5, Blocks.bedrock);
		world.setBlock(i + 2, j + 0, k + 6, Blocks.bedrock);
		world.setBlock(i + 2, j + 0, k + 7, Blocks.bedrock);
		world.setBlock(i + 2, j + 0, k + 8, Blocks.bedrock);
		world.setBlock(i + 2, j + 0, k + 9, Blocks.bedrock);
		world.setBlock(i + 2, j + 0, k + 10, Blocks.bedrock);
		world.setBlock(i + 2, j + 0, k + 11, Blocks.bedrock);
		world.setBlock(i + 2, j + 0, k + 12, Blocks.bedrock);
		world.setBlock(i + 2, j + 0, k + 13, Blocks.bedrock);
		world.setBlock(i + 2, j + 0, k + 14, Blocks.bedrock);
		world.setBlock(i + 2, j + 0, k + 15, Blocks.bedrock);
		world.setBlock(i + 2, j + 0, k + 16, Blocks.bedrock);
		world.setBlock(i + 2, j + 0, k + 17, Blocks.bedrock);
		world.setBlock(i + 2, j + 0, k + 18, Blocks.bedrock);
		world.setBlock(i + 2, j + 0, k + 19, Blocks.bedrock);
		world.setBlock(i + 2, j + 0, k + 20, Blocks.bedrock);
		world.setBlock(i + 2, j + 0, k + 21, Blocks.bedrock);
		world.setBlock(i + 2, j + 0, k + 22, Blocks.bedrock);
		world.setBlock(i + 2, j + 0, k + 23, Blocks.bedrock);
		world.setBlock(i + 2, j + 0, k + 24, Blocks.bedrock);
		world.setBlock(i + 2, j + 0, k + 25, Blocks.quartz_stairs, 3, 3);
		world.setBlock(i + 2, j + 1, k + 0, Blocks.air);
		world.setBlock(i + 2, j + 1, k + 1, Blocks.bedrock);
		world.setBlock(i + 2, j + 1, k + 2, Blocks.bedrock);
		world.setBlock(i + 2, j + 1, k + 3, Blocks.bedrock);
		world.setBlock(i + 2, j + 1, k + 4, Blocks.air);
		world.setBlock(i + 2, j + 1, k + 5, Blocks.bedrock);
		world.setBlock(i + 2, j + 1, k + 6, Blocks.bedrock);
		world.setBlock(i + 2, j + 1, k + 7, Blocks.bedrock);
		world.setBlock(i + 2, j + 1, k + 8, Blocks.bedrock);
		world.setBlock(i + 2, j + 1, k + 9, Blocks.bedrock);
		world.setBlock(i + 2, j + 1, k + 10, Blocks.bedrock);
		world.setBlock(i + 2, j + 1, k + 11, Blocks.bedrock);
		world.setBlock(i + 2, j + 1, k + 12, Blocks.bedrock);
		world.setBlock(i + 2, j + 1, k + 13, Blocks.bedrock);
		world.setBlock(i + 2, j + 1, k + 14, Blocks.bedrock);
		world.setBlock(i + 2, j + 1, k + 15, Blocks.bedrock);
		world.setBlock(i + 2, j + 1, k + 16, Blocks.bedrock);
		world.setBlock(i + 2, j + 1, k + 17, Blocks.bedrock);
		world.setBlock(i + 2, j + 1, k + 18, Blocks.bedrock);
		world.setBlock(i + 2, j + 1, k + 19, Blocks.bedrock);
		world.setBlock(i + 2, j + 1, k + 20, Blocks.bedrock);
		world.setBlock(i + 2, j + 1, k + 21, Blocks.bedrock);
		world.setBlock(i + 2, j + 1, k + 22, Blocks.bedrock);
		world.setBlock(i + 2, j + 1, k + 23, Blocks.bedrock);
		world.setBlock(i + 2, j + 1, k + 24, Blocks.quartz_stairs, 3, 3);
		world.setBlock(i + 2, j + 1, k + 25, Blocks.air);
		world.setBlock(i + 2, j + 2, k + 0, Blocks.air);
		world.setBlock(i + 2, j + 2, k + 1, Blocks.air);
		world.setBlock(i + 2, j + 2, k + 2, Blocks.bedrock);
		world.setBlock(i + 2, j + 2, k + 3, Blocks.bedrock);
		world.setBlock(i + 2, j + 2, k + 4, Blocks.air);
		world.setBlock(i + 2, j + 2, k + 5, Blocks.bedrock);
		world.setBlock(i + 2, j + 2, k + 22, Blocks.nether_brick);
		world.setBlock(i + 2, j + 2, k + 23, Blocks.quartz_stairs, 3, 3);
		world.setBlock(i + 2, j + 2, k + 24, Blocks.air);
		world.setBlock(i + 2, j + 2, k + 25, Blocks.air);
		world.setBlock(i + 2, j + 3, k + 0, Blocks.air);
		world.setBlock(i + 2, j + 3, k + 1, Blocks.air);
		world.setBlock(i + 2, j + 3, k + 2, Blocks.air);
		world.setBlock(i + 2, j + 3, k + 3, Blocks.nether_brick);
		world.setBlock(i + 2, j + 3, k + 4, Blocks.air);
		world.setBlock(i + 2, j + 3, k + 5, b, ms, 3);
		world.setBlock(i + 2, j + 3, k + 6, Blocks.air);
		world.setBlock(i + 2, j + 3, k + 7, Blocks.air);
		world.setBlock(i + 2, j + 3, k + 8, Blocks.air);
		world.setBlock(i + 2, j + 3, k + 9, Blocks.air);
		world.setBlock(i + 2, j + 3, k + 10, Blocks.air);
		world.setBlock(i + 2, j + 3, k + 11, Blocks.air);
		world.setBlock(i + 2, j + 3, k + 12, Blocks.air);
		world.setBlock(i + 2, j + 3, k + 13, Blocks.air);
		world.setBlock(i + 2, j + 3, k + 14, Blocks.air);
		world.setBlock(i + 2, j + 3, k + 15, Blocks.air);
		world.setBlock(i + 2, j + 3, k + 16, Blocks.air);
		world.setBlock(i + 2, j + 3, k + 17, Blocks.air);
		world.setBlock(i + 2, j + 3, k + 18, Blocks.air);
		world.setBlock(i + 2, j + 3, k + 19, Blocks.air);
		world.setBlock(i + 2, j + 3, k + 20, Blocks.air);
		world.setBlock(i + 2, j + 3, k + 21, Blocks.air);
		world.setBlock(i + 2, j + 3, k + 22, Blocks.air);
		world.setBlock(i + 2, j + 3, k + 23, Blocks.air);
		world.setBlock(i + 2, j + 3, k + 24, Blocks.air);
		world.setBlock(i + 2, j + 3, k + 25, Blocks.air);
		world.setBlock(i + 2, j + 4, k + 0, Blocks.air);
		world.setBlock(i + 2, j + 4, k + 1, Blocks.air);
		world.setBlock(i + 2, j + 4, k + 2, Blocks.air);
		world.setBlock(i + 2, j + 4, k + 3, Blocks.nether_brick);
		world.setBlock(i + 2, j + 4, k + 4, Blocks.air);
		world.setBlock(i + 2, j + 4, k + 5, Blocks.air);
		world.setBlock(i + 2, j + 4, k + 6, Blocks.air);
		world.setBlock(i + 2, j + 4, k + 7, Blocks.air);
		world.setBlock(i + 2, j + 4, k + 8, Blocks.air);
		world.setBlock(i + 2, j + 4, k + 9, Blocks.air);
		world.setBlock(i + 2, j + 4, k + 10, Blocks.air);
		world.setBlock(i + 2, j + 4, k + 11, Blocks.air);
		world.setBlock(i + 2, j + 4, k + 12, Blocks.air);
		world.setBlock(i + 2, j + 4, k + 13, Blocks.air);
		world.setBlock(i + 2, j + 4, k + 14, Blocks.air);
		world.setBlock(i + 2, j + 4, k + 15, Blocks.air);
		world.setBlock(i + 2, j + 4, k + 16, Blocks.air);
		world.setBlock(i + 2, j + 4, k + 17, Blocks.air);
		world.setBlock(i + 2, j + 4, k + 18, Blocks.air);
		world.setBlock(i + 2, j + 4, k + 19, Blocks.air);
		world.setBlock(i + 2, j + 4, k + 20, Blocks.air);
		world.setBlock(i + 2, j + 4, k + 21, Blocks.air);
		world.setBlock(i + 2, j + 4, k + 22, Blocks.air);
		world.setBlock(i + 2, j + 4, k + 23, Blocks.air);
		world.setBlock(i + 2, j + 4, k + 24, Blocks.air);
		world.setBlock(i + 2, j + 4, k + 25, Blocks.air);
		world.setBlock(i + 2, j + 5, k + 0, Blocks.air);
		world.setBlock(i + 2, j + 5, k + 1, Blocks.air);
		world.setBlock(i + 2, j + 5, k + 2, Blocks.air);
		world.setBlock(i + 2, j + 5, k + 3, Blocks.nether_brick);
		world.setBlock(i + 2, j + 5, k + 4, Blocks.bedrock);
		world.setBlock(i + 2, j + 5, k + 5, b, ms, 3);
		world.setBlock(i + 2, j + 5, k + 6, Blocks.air);
		world.setBlock(i + 2, j + 5, k + 7, Blocks.air);
		world.setBlock(i + 2, j + 5, k + 8, Blocks.air);
		world.setBlock(i + 2, j + 5, k + 9, Blocks.air);
		world.setBlock(i + 2, j + 5, k + 10, Blocks.air);
		world.setBlock(i + 2, j + 5, k + 11, Blocks.air);
		world.setBlock(i + 2, j + 5, k + 12, Blocks.air);
		world.setBlock(i + 2, j + 5, k + 13, Blocks.air);
		world.setBlock(i + 2, j + 5, k + 14, Blocks.air);
		world.setBlock(i + 2, j + 5, k + 15, Blocks.air);
		world.setBlock(i + 2, j + 5, k + 16, Blocks.air);
		world.setBlock(i + 2, j + 5, k + 17, Blocks.air);
		world.setBlock(i + 2, j + 5, k + 18, Blocks.air);
		world.setBlock(i + 2, j + 5, k + 19, Blocks.air);
		world.setBlock(i + 2, j + 5, k + 20, Blocks.air);
		world.setBlock(i + 2, j + 5, k + 21, Blocks.air);
		world.setBlock(i + 2, j + 5, k + 22, Blocks.air);
		world.setBlock(i + 2, j + 5, k + 23, Blocks.air);
		world.setBlock(i + 2, j + 5, k + 24, Blocks.air);
		world.setBlock(i + 2, j + 5, k + 25, Blocks.air);
		world.setBlock(i + 2, j + 6, k + 0, Blocks.air);
		world.setBlock(i + 2, j + 6, k + 1, Blocks.air);
		world.setBlock(i + 2, j + 6, k + 2, Blocks.air);
		world.setBlock(i + 2, j + 6, k + 3, Blocks.nether_brick);
		world.setBlock(i + 2, j + 6, k + 4, Blocks.bedrock);
		world.setBlock(i + 2, j + 6, k + 5, Blocks.nether_brick);
		world.setBlock(i + 2, j + 6, k + 6, Blocks.air);
		world.setBlock(i + 2, j + 6, k + 7, Blocks.air);
		world.setBlock(i + 2, j + 6, k + 8, Blocks.air);
		world.setBlock(i + 2, j + 6, k + 9, Blocks.air);
		world.setBlock(i + 2, j + 6, k + 10, Blocks.air);
		world.setBlock(i + 2, j + 6, k + 11, Blocks.air);
		world.setBlock(i + 2, j + 6, k + 12, Blocks.air);
		world.setBlock(i + 2, j + 6, k + 13, Blocks.air);
		world.setBlock(i + 2, j + 6, k + 14, Blocks.air);
		world.setBlock(i + 2, j + 6, k + 15, Blocks.air);
		world.setBlock(i + 2, j + 6, k + 16, Blocks.air);
		world.setBlock(i + 2, j + 6, k + 17, Blocks.air);
		world.setBlock(i + 2, j + 6, k + 18, Blocks.air);
		world.setBlock(i + 2, j + 6, k + 19, Blocks.air);
		world.setBlock(i + 2, j + 6, k + 20, Blocks.air);
		world.setBlock(i + 2, j + 6, k + 21, Blocks.air);
		world.setBlock(i + 2, j + 6, k + 22, Blocks.air);
		world.setBlock(i + 2, j + 6, k + 23, Blocks.air);
		world.setBlock(i + 2, j + 6, k + 24, Blocks.air);
		world.setBlock(i + 2, j + 6, k + 25, Blocks.air);
		world.setBlock(i + 2, j + 7, k + 0, Blocks.air);
		world.setBlock(i + 2, j + 7, k + 1, Blocks.air);
		world.setBlock(i + 2, j + 7, k + 2, Blocks.air);
		world.setBlock(i + 2, j + 7, k + 3, Blocks.nether_brick);
		world.setBlock(i + 2, j + 7, k + 4, Blocks.bedrock);
		world.setBlock(i + 2, j + 7, k + 5, Blocks.nether_brick);
		world.setBlock(i + 2, j + 7, k + 6, Blocks.nether_brick);
		world.setBlock(i + 2, j + 7, k + 7, Blocks.nether_brick);
		world.setBlock(i + 2, j + 7, k + 8, Blocks.nether_brick);
		world.setBlock(i + 2, j + 7, k + 9, Blocks.nether_brick);
		world.setBlock(i + 2, j + 7, k + 10, Blocks.nether_brick);
		world.setBlock(i + 2, j + 7, k + 11, Blocks.nether_brick);
		world.setBlock(i + 2, j + 7, k + 12, Blocks.nether_brick);
		world.setBlock(i + 2, j + 7, k + 13, Blocks.nether_brick);
		world.setBlock(i + 2, j + 7, k + 14, Blocks.nether_brick);
		world.setBlock(i + 2, j + 7, k + 15, Blocks.nether_brick);
		world.setBlock(i + 2, j + 7, k + 16, Blocks.nether_brick);
		world.setBlock(i + 2, j + 7, k + 17, Blocks.nether_brick);
		world.setBlock(i + 2, j + 7, k + 18, Blocks.nether_brick);
		world.setBlock(i + 2, j + 7, k + 19, Blocks.nether_brick);
		world.setBlock(i + 2, j + 7, k + 20, Blocks.nether_brick);
		world.setBlock(i + 2, j + 7, k + 21, Blocks.nether_brick);
		world.setBlock(i + 2, j + 7, k + 22, Blocks.nether_brick);
		world.setBlock(i + 2, j + 7, k + 23, Blocks.air);
		world.setBlock(i + 2, j + 7, k + 24, Blocks.air);
		world.setBlock(i + 2, j + 7, k + 25, Blocks.air);
		world.setBlock(i + 2, j + 8, k + 0, Blocks.air);
		world.setBlock(i + 2, j + 8, k + 1, Blocks.air);
		world.setBlock(i + 2, j + 8, k + 2, Blocks.air);
		world.setBlock(i + 2, j + 8, k + 3, Blocks.nether_brick);
		world.setBlock(i + 2, j + 8, k + 4, Blocks.nether_brick);
		world.setBlock(i + 2, j + 8, k + 5, Blocks.nether_brick);
		world.setBlock(i + 2, j + 8, k + 6, Blocks.air);
		world.setBlock(i + 2, j + 8, k + 7, Blocks.air);
		world.setBlock(i + 2, j + 8, k + 8, Blocks.air);
		world.setBlock(i + 2, j + 8, k + 9, Blocks.air);
		world.setBlock(i + 2, j + 8, k + 10, Blocks.air);
		world.setBlock(i + 2, j + 8, k + 11, Blocks.air);
		world.setBlock(i + 2, j + 8, k + 12, Blocks.air);
		world.setBlock(i + 2, j + 8, k + 13, Blocks.air);
		world.setBlock(i + 2, j + 8, k + 14, Blocks.air);
		world.setBlock(i + 2, j + 8, k + 15, Blocks.air);
		world.setBlock(i + 2, j + 8, k + 16, Blocks.air);
		world.setBlock(i + 2, j + 8, k + 17, Blocks.air);
		world.setBlock(i + 2, j + 8, k + 18, Blocks.air);
		world.setBlock(i + 2, j + 8, k + 19, Blocks.air);
		world.setBlock(i + 2, j + 8, k + 20, Blocks.air);
		world.setBlock(i + 2, j + 8, k + 21, Blocks.air);
		world.setBlock(i + 2, j + 8, k + 22, Blocks.air);
		world.setBlock(i + 2, j + 8, k + 23, Blocks.air);
		world.setBlock(i + 2, j + 8, k + 24, Blocks.air);
		world.setBlock(i + 2, j + 8, k + 25, Blocks.air);
		world.setBlock(i + 2, j + 9, k + 0, Blocks.air);
		world.setBlock(i + 2, j + 9, k + 1, Blocks.air);
		world.setBlock(i + 2, j + 9, k + 2, Blocks.air);
		world.setBlock(i + 2, j + 9, k + 3, Blocks.air);
		world.setBlock(i + 2, j + 9, k + 4, Blocks.air);
		world.setBlock(i + 2, j + 9, k + 5, Blocks.air);
		world.setBlock(i + 2, j + 9, k + 6, Blocks.air);
		world.setBlock(i + 2, j + 9, k + 7, Blocks.air);
		world.setBlock(i + 2, j + 9, k + 8, Blocks.air);
		world.setBlock(i + 2, j + 9, k + 9, Blocks.air);
		world.setBlock(i + 2, j + 9, k + 10, Blocks.air);
		world.setBlock(i + 2, j + 9, k + 11, Blocks.air);
		world.setBlock(i + 2, j + 9, k + 12, Blocks.air);
		world.setBlock(i + 2, j + 9, k + 13, Blocks.air);
		world.setBlock(i + 2, j + 9, k + 14, Blocks.air);
		world.setBlock(i + 2, j + 9, k + 15, Blocks.air);
		world.setBlock(i + 2, j + 9, k + 16, Blocks.air);
		world.setBlock(i + 2, j + 9, k + 17, Blocks.air);
		world.setBlock(i + 2, j + 9, k + 18, Blocks.air);
		world.setBlock(i + 2, j + 9, k + 19, Blocks.air);
		world.setBlock(i + 2, j + 9, k + 20, Blocks.air);
		world.setBlock(i + 2, j + 9, k + 21, Blocks.air);
		world.setBlock(i + 2, j + 9, k + 22, Blocks.air);
		world.setBlock(i + 2, j + 9, k + 23, Blocks.air);
		world.setBlock(i + 2, j + 9, k + 24, Blocks.air);
		world.setBlock(i + 2, j + 9, k + 25, Blocks.air);
		world.setBlock(i + 2, j + 10, k + 0, Blocks.air);
		world.setBlock(i + 2, j + 10, k + 1, Blocks.air);
		world.setBlock(i + 2, j + 10, k + 2, Blocks.air);
		world.setBlock(i + 2, j + 10, k + 3, Blocks.air);
		world.setBlock(i + 2, j + 10, k + 4, Blocks.air);
		world.setBlock(i + 2, j + 10, k + 5, Blocks.air);
		world.setBlock(i + 2, j + 10, k + 6, Blocks.air);
		world.setBlock(i + 2, j + 10, k + 7, Blocks.air);
		world.setBlock(i + 2, j + 10, k + 8, Blocks.air);
		world.setBlock(i + 2, j + 10, k + 9, Blocks.air);
		world.setBlock(i + 2, j + 10, k + 10, Blocks.air);
		world.setBlock(i + 2, j + 10, k + 11, Blocks.air);
		world.setBlock(i + 2, j + 10, k + 12, Blocks.air);
		world.setBlock(i + 2, j + 10, k + 13, Blocks.air);
		world.setBlock(i + 2, j + 10, k + 14, Blocks.air);
		world.setBlock(i + 2, j + 10, k + 15, Blocks.air);
		world.setBlock(i + 2, j + 10, k + 16, Blocks.air);
		world.setBlock(i + 2, j + 10, k + 17, Blocks.air);
		world.setBlock(i + 2, j + 10, k + 18, Blocks.air);
		world.setBlock(i + 2, j + 10, k + 19, Blocks.air);
		world.setBlock(i + 2, j + 10, k + 20, Blocks.air);
		world.setBlock(i + 2, j + 10, k + 21, Blocks.air);
		world.setBlock(i + 2, j + 10, k + 22, Blocks.air);
		world.setBlock(i + 2, j + 10, k + 23, Blocks.air);
		world.setBlock(i + 2, j + 10, k + 24, Blocks.air);
		world.setBlock(i + 2, j + 10, k + 25, Blocks.air);
		world.setBlock(i + 3, j + 0, k + 0, Blocks.bedrock);
		world.setBlock(i + 3, j + 0, k + 1, Blocks.bedrock);
		world.setBlock(i + 3, j + 0, k + 2, Blocks.bedrock);
		world.setBlock(i + 3, j + 0, k + 3, Blocks.bedrock);
		world.setBlock(i + 3, j + 0, k + 4, Blocks.bedrock);
		world.setBlock(i + 3, j + 0, k + 5, Blocks.bedrock);
		world.setBlock(i + 3, j + 0, k + 6, Blocks.bedrock);
		world.setBlock(i + 3, j + 0, k + 7, Blocks.bedrock);
		world.setBlock(i + 3, j + 0, k + 8, Blocks.bedrock);
		world.setBlock(i + 3, j + 0, k + 9, Blocks.bedrock);
		world.setBlock(i + 3, j + 0, k + 10, Blocks.bedrock);
		world.setBlock(i + 3, j + 0, k + 11, Blocks.bedrock);
		world.setBlock(i + 3, j + 0, k + 12, Blocks.bedrock);
		world.setBlock(i + 3, j + 0, k + 13, Blocks.bedrock);
		world.setBlock(i + 3, j + 0, k + 14, Blocks.bedrock);
		world.setBlock(i + 3, j + 0, k + 15, Blocks.bedrock);
		world.setBlock(i + 3, j + 0, k + 16, Blocks.bedrock);
		world.setBlock(i + 3, j + 0, k + 17, Blocks.bedrock);
		world.setBlock(i + 3, j + 0, k + 18, Blocks.bedrock);
		world.setBlock(i + 3, j + 0, k + 19, Blocks.bedrock);
		world.setBlock(i + 3, j + 0, k + 20, Blocks.bedrock);
		world.setBlock(i + 3, j + 0, k + 21, Blocks.bedrock);
		world.setBlock(i + 3, j + 0, k + 22, Blocks.bedrock);
		world.setBlock(i + 3, j + 0, k + 23, Blocks.bedrock);
		world.setBlock(i + 3, j + 0, k + 24, Blocks.bedrock);
		world.setBlock(i + 3, j + 0, k + 25, Blocks.quartz_stairs, 3, 3);
		world.setBlock(i + 3, j + 1, k + 0, Blocks.air);
		world.setBlock(i + 3, j + 1, k + 1, Blocks.bedrock);
		world.setBlock(i + 3, j + 1, k + 2, Blocks.bedrock);
		world.setBlock(i + 3, j + 1, k + 3, Blocks.bedrock);
		world.setBlock(i + 3, j + 1, k + 5, Blocks.bedrock);
		world.setBlock(i + 3, j + 1, k + 6, Blocks.bedrock);
		world.setBlock(i + 3, j + 1, k + 7, Blocks.bedrock);
		world.setBlock(i + 3, j + 1, k + 8, Blocks.bedrock);
		world.setBlock(i + 3, j + 1, k + 9, Blocks.bedrock);
		world.setBlock(i + 3, j + 1, k + 10, Blocks.bedrock);
		world.setBlock(i + 3, j + 1, k + 11, Blocks.bedrock);
		world.setBlock(i + 3, j + 1, k + 12, Blocks.bedrock);
		world.setBlock(i + 3, j + 1, k + 13, Blocks.bedrock);
		world.setBlock(i + 3, j + 1, k + 14, Blocks.bedrock);
		world.setBlock(i + 3, j + 1, k + 15, Blocks.bedrock);
		world.setBlock(i + 3, j + 1, k + 16, Blocks.bedrock);
		world.setBlock(i + 3, j + 1, k + 17, Blocks.bedrock);
		world.setBlock(i + 3, j + 1, k + 18, Blocks.bedrock);
		world.setBlock(i + 3, j + 1, k + 19, Blocks.bedrock);
		world.setBlock(i + 3, j + 1, k + 20, Blocks.bedrock);
		world.setBlock(i + 3, j + 1, k + 21, Blocks.bedrock);
		world.setBlock(i + 3, j + 1, k + 22, Blocks.bedrock);
		world.setBlock(i + 3, j + 1, k + 23, Blocks.bedrock);
		world.setBlock(i + 3, j + 1, k + 24, Blocks.quartz_stairs, 3, 3);
		world.setBlock(i + 3, j + 1, k + 25, Blocks.air);
		world.setBlock(i + 3, j + 2, k + 0, Blocks.air);
		world.setBlock(i + 3, j + 2, k + 1, Blocks.air);
		world.setBlock(i + 3, j + 2, k + 2, Blocks.bedrock);
		world.setBlock(i + 3, j + 2, k + 3, Blocks.bedrock);
		world.setBlock(i + 3, j + 2, k + 4, Blocks.bedrock);
		world.setBlock(i + 3, j + 2, k + 5, Blocks.bedrock);
		world.setBlock(i + 3, j + 2, k + 22, Blocks.nether_brick);
		world.setBlock(i + 3, j + 2, k + 23, Blocks.quartz_stairs, 3, 3);
		world.setBlock(i + 3, j + 2, k + 24, Blocks.air);
		world.setBlock(i + 3, j + 2, k + 25, Blocks.air);
		world.setBlock(i + 3, j + 3, k + 0, Blocks.air);
		world.setBlock(i + 3, j + 3, k + 1, Blocks.air);
		world.setBlock(i + 3, j + 3, k + 2, Blocks.air);
		world.setBlock(i + 3, j + 3, k + 3, Blocks.nether_brick);
		world.setBlock(i + 3, j + 3, k + 4, Blocks.bedrock);
		world.setBlock(i + 3, j + 3, k + 5, b, ms, 3);
		world.setBlock(i + 3, j + 3, k + 6, Blocks.air);
		world.setBlock(i + 3, j + 3, k + 7, Blocks.air);
		world.setBlock(i + 3, j + 3, k + 8, Blocks.air);
		world.setBlock(i + 3, j + 3, k + 9, Blocks.air);
		world.setBlock(i + 3, j + 3, k + 10, Blocks.air);
		world.setBlock(i + 3, j + 3, k + 11, Blocks.air);
		world.setBlock(i + 3, j + 3, k + 12, Blocks.air);
		world.setBlock(i + 3, j + 3, k + 13, Blocks.air);
		world.setBlock(i + 3, j + 3, k + 14, Blocks.air);
		world.setBlock(i + 3, j + 3, k + 15, Blocks.air);
		world.setBlock(i + 3, j + 3, k + 16, Blocks.air);
		world.setBlock(i + 3, j + 3, k + 17, Blocks.air);
		world.setBlock(i + 3, j + 3, k + 18, Blocks.air);
		world.setBlock(i + 3, j + 3, k + 19, Blocks.air);
		world.setBlock(i + 3, j + 3, k + 20, Blocks.air);
		world.setBlock(i + 3, j + 3, k + 21, Blocks.air);
		world.setBlock(i + 3, j + 3, k + 22, Blocks.air);
		world.setBlock(i + 3, j + 3, k + 23, Blocks.air);
		world.setBlock(i + 3, j + 3, k + 24, Blocks.air);
		world.setBlock(i + 3, j + 3, k + 25, Blocks.air);
		world.setBlock(i + 3, j + 4, k + 0, Blocks.air);
		world.setBlock(i + 3, j + 4, k + 1, Blocks.air);
		world.setBlock(i + 3, j + 4, k + 2, Blocks.air);
		world.setBlock(i + 3, j + 4, k + 3, Blocks.nether_brick);
		world.setBlock(i + 3, j + 4, k + 4, Blocks.bedrock);
		world.setBlock(i + 3, j + 4, k + 5, b, ms, 3);
		world.setBlock(i + 3, j + 4, k + 6, Blocks.air);
		world.setBlock(i + 3, j + 4, k + 7, Blocks.air);
		world.setBlock(i + 3, j + 4, k + 8, Blocks.air);
		world.setBlock(i + 3, j + 4, k + 9, Blocks.air);
		world.setBlock(i + 3, j + 4, k + 10, Blocks.air);
		world.setBlock(i + 3, j + 4, k + 11, Blocks.air);
		world.setBlock(i + 3, j + 4, k + 12, Blocks.air);
		world.setBlock(i + 3, j + 4, k + 13, Blocks.air);
		world.setBlock(i + 3, j + 4, k + 14, Blocks.air);
		world.setBlock(i + 3, j + 4, k + 15, Blocks.air);
		world.setBlock(i + 3, j + 4, k + 16, Blocks.air);
		world.setBlock(i + 3, j + 4, k + 17, Blocks.air);
		world.setBlock(i + 3, j + 4, k + 18, Blocks.air);
		world.setBlock(i + 3, j + 4, k + 19, Blocks.air);
		world.setBlock(i + 3, j + 4, k + 20, Blocks.air);
		world.setBlock(i + 3, j + 4, k + 21, Blocks.air);
		world.setBlock(i + 3, j + 4, k + 22, Blocks.air);
		world.setBlock(i + 3, j + 4, k + 23, Blocks.air);
		world.setBlock(i + 3, j + 4, k + 24, Blocks.air);
		world.setBlock(i + 3, j + 4, k + 25, Blocks.air);
		world.setBlock(i + 3, j + 5, k + 0, Blocks.air);
		world.setBlock(i + 3, j + 5, k + 1, Blocks.air);
		world.setBlock(i + 3, j + 5, k + 2, Blocks.air);
		world.setBlock(i + 3, j + 5, k + 3, Blocks.nether_brick);
		world.setBlock(i + 3, j + 5, k + 4, Blocks.bedrock);
		world.setBlock(i + 3, j + 5, k + 5, b, ms, 3);
		world.setBlock(i + 3, j + 5, k + 6, Blocks.air);
		world.setBlock(i + 3, j + 5, k + 7, Blocks.air);
		world.setBlock(i + 3, j + 5, k + 8, Blocks.air);
		world.setBlock(i + 3, j + 5, k + 9, Blocks.air);
		world.setBlock(i + 3, j + 5, k + 10, Blocks.air);
		world.setBlock(i + 3, j + 5, k + 11, Blocks.air);
		world.setBlock(i + 3, j + 5, k + 12, Blocks.air);
		world.setBlock(i + 3, j + 5, k + 13, Blocks.air);
		world.setBlock(i + 3, j + 5, k + 14, Blocks.air);
		world.setBlock(i + 3, j + 5, k + 15, Blocks.air);
		world.setBlock(i + 3, j + 5, k + 16, Blocks.air);
		world.setBlock(i + 3, j + 5, k + 17, Blocks.air);
		world.setBlock(i + 3, j + 5, k + 18, Blocks.air);
		world.setBlock(i + 3, j + 5, k + 19, Blocks.air);
		world.setBlock(i + 3, j + 5, k + 20, Blocks.air);
		world.setBlock(i + 3, j + 5, k + 21, Blocks.air);
		world.setBlock(i + 3, j + 5, k + 22, Blocks.air);
		world.setBlock(i + 3, j + 5, k + 23, Blocks.air);
		world.setBlock(i + 3, j + 5, k + 24, Blocks.air);
		world.setBlock(i + 3, j + 5, k + 25, Blocks.air);
		world.setBlock(i + 3, j + 6, k + 0, Blocks.air);
		world.setBlock(i + 3, j + 6, k + 1, Blocks.air);
		world.setBlock(i + 3, j + 6, k + 2, Blocks.air);
		world.setBlock(i + 3, j + 6, k + 3, Blocks.nether_brick);
		world.setBlock(i + 3, j + 6, k + 4, Blocks.bedrock);
		world.setBlock(i + 3, j + 6, k + 5, Blocks.nether_brick);
		world.setBlock(i + 3, j + 6, k + 6, Blocks.air);
		world.setBlock(i + 3, j + 6, k + 7, Blocks.air);
		world.setBlock(i + 3, j + 6, k + 8, Blocks.air);
		world.setBlock(i + 3, j + 6, k + 9, Blocks.air);
		world.setBlock(i + 3, j + 6, k + 10, Blocks.air);
		world.setBlock(i + 3, j + 6, k + 11, Blocks.air);
		world.setBlock(i + 3, j + 6, k + 12, Blocks.air);
		world.setBlock(i + 3, j + 6, k + 13, Blocks.air);
		world.setBlock(i + 3, j + 6, k + 14, Blocks.air);
		world.setBlock(i + 3, j + 6, k + 15, Blocks.air);
		world.setBlock(i + 3, j + 6, k + 16, Blocks.air);
		world.setBlock(i + 3, j + 6, k + 17, Blocks.air);
		world.setBlock(i + 3, j + 6, k + 18, Blocks.air);
		world.setBlock(i + 3, j + 6, k + 19, Blocks.air);
		world.setBlock(i + 3, j + 6, k + 20, Blocks.air);
		world.setBlock(i + 3, j + 6, k + 21, Blocks.air);
		world.setBlock(i + 3, j + 6, k + 22, Blocks.air);
		world.setBlock(i + 3, j + 6, k + 23, Blocks.air);
		world.setBlock(i + 3, j + 6, k + 24, Blocks.air);
		world.setBlock(i + 3, j + 6, k + 25, Blocks.air);
		world.setBlock(i + 3, j + 7, k + 0, Blocks.air);
		world.setBlock(i + 3, j + 7, k + 1, Blocks.air);
		world.setBlock(i + 3, j + 7, k + 2, Blocks.air);
		world.setBlock(i + 3, j + 7, k + 3, Blocks.nether_brick);
		world.setBlock(i + 3, j + 7, k + 4, Blocks.bedrock);
		world.setBlock(i + 3, j + 7, k + 5, Blocks.nether_brick);
		world.setBlock(i + 3, j + 7, k + 6, Blocks.nether_brick);
		world.setBlock(i + 3, j + 7, k + 7, Blocks.nether_brick);
		world.setBlock(i + 3, j + 7, k + 8, Blocks.nether_brick);
		world.setBlock(i + 3, j + 7, k + 9, Blocks.nether_brick);
		world.setBlock(i + 3, j + 7, k + 10, Blocks.nether_brick);
		world.setBlock(i + 3, j + 7, k + 11, Blocks.nether_brick);
		world.setBlock(i + 3, j + 7, k + 12, Blocks.nether_brick);
		world.setBlock(i + 3, j + 7, k + 13, Blocks.nether_brick);
		world.setBlock(i + 3, j + 7, k + 14, Blocks.nether_brick);
		world.setBlock(i + 3, j + 7, k + 15, Blocks.nether_brick);
		world.setBlock(i + 3, j + 7, k + 16, Blocks.nether_brick);
		world.setBlock(i + 3, j + 7, k + 17, Blocks.nether_brick);
		world.setBlock(i + 3, j + 7, k + 18, Blocks.nether_brick);
		world.setBlock(i + 3, j + 7, k + 19, Blocks.nether_brick);
		world.setBlock(i + 3, j + 7, k + 20, Blocks.nether_brick);
		world.setBlock(i + 3, j + 7, k + 21, Blocks.nether_brick);
		world.setBlock(i + 3, j + 7, k + 22, Blocks.nether_brick);
		world.setBlock(i + 3, j + 7, k + 23, Blocks.air);
		world.setBlock(i + 3, j + 7, k + 24, Blocks.air);
		world.setBlock(i + 3, j + 7, k + 25, Blocks.air);
		world.setBlock(i + 3, j + 8, k + 0, Blocks.air);
		world.setBlock(i + 3, j + 8, k + 1, Blocks.air);
		world.setBlock(i + 3, j + 8, k + 2, Blocks.air);
		world.setBlock(i + 3, j + 8, k + 3, Blocks.nether_brick);
		world.setBlock(i + 3, j + 8, k + 4, Blocks.nether_brick);
		world.setBlock(i + 3, j + 8, k + 5, Blocks.nether_brick);
		world.setBlock(i + 3, j + 8, k + 6, Blocks.air);
		world.setBlock(i + 3, j + 8, k + 7, Blocks.air);
		world.setBlock(i + 3, j + 8, k + 8, Blocks.air);
		world.setBlock(i + 3, j + 8, k + 9, Blocks.air);
		world.setBlock(i + 3, j + 8, k + 10, Blocks.air);
		world.setBlock(i + 3, j + 8, k + 11, Blocks.air);
		world.setBlock(i + 3, j + 8, k + 12, Blocks.air);
		world.setBlock(i + 3, j + 8, k + 13, Blocks.air);
		world.setBlock(i + 3, j + 8, k + 14, Blocks.air);
		world.setBlock(i + 3, j + 8, k + 15, Blocks.air);
		world.setBlock(i + 3, j + 8, k + 16, Blocks.air);
		world.setBlock(i + 3, j + 8, k + 17, Blocks.air);
		world.setBlock(i + 3, j + 8, k + 18, Blocks.air);
		world.setBlock(i + 3, j + 8, k + 19, Blocks.air);
		world.setBlock(i + 3, j + 8, k + 20, Blocks.air);
		world.setBlock(i + 3, j + 8, k + 21, Blocks.air);
		world.setBlock(i + 3, j + 8, k + 22, Blocks.air);
		world.setBlock(i + 3, j + 8, k + 23, Blocks.air);
		world.setBlock(i + 3, j + 8, k + 24, Blocks.air);
		world.setBlock(i + 3, j + 8, k + 25, Blocks.air);
		world.setBlock(i + 3, j + 9, k + 0, Blocks.air);
		world.setBlock(i + 3, j + 9, k + 1, Blocks.air);
		world.setBlock(i + 3, j + 9, k + 2, Blocks.air);
		world.setBlock(i + 3, j + 9, k + 3, Blocks.air);
		world.setBlock(i + 3, j + 9, k + 4, Blocks.air);
		world.setBlock(i + 3, j + 9, k + 5, Blocks.air);
		world.setBlock(i + 3, j + 9, k + 6, Blocks.air);
		world.setBlock(i + 3, j + 9, k + 7, Blocks.air);
		world.setBlock(i + 3, j + 9, k + 8, Blocks.air);
		world.setBlock(i + 3, j + 9, k + 9, Blocks.air);
		world.setBlock(i + 3, j + 9, k + 10, Blocks.air);
		world.setBlock(i + 3, j + 9, k + 11, Blocks.air);
		world.setBlock(i + 3, j + 9, k + 12, Blocks.air);
		world.setBlock(i + 3, j + 9, k + 13, Blocks.air);
		world.setBlock(i + 3, j + 9, k + 14, Blocks.air);
		world.setBlock(i + 3, j + 9, k + 15, Blocks.air);
		world.setBlock(i + 3, j + 9, k + 16, Blocks.air);
		world.setBlock(i + 3, j + 9, k + 17, Blocks.air);
		world.setBlock(i + 3, j + 9, k + 18, Blocks.air);
		world.setBlock(i + 3, j + 9, k + 19, Blocks.air);
		world.setBlock(i + 3, j + 9, k + 20, Blocks.air);
		world.setBlock(i + 3, j + 9, k + 21, Blocks.air);
		world.setBlock(i + 3, j + 9, k + 22, Blocks.air);
		world.setBlock(i + 3, j + 9, k + 23, Blocks.air);
		world.setBlock(i + 3, j + 9, k + 24, Blocks.air);
		world.setBlock(i + 3, j + 9, k + 25, Blocks.air);
		world.setBlock(i + 3, j + 10, k + 0, Blocks.air);
		world.setBlock(i + 3, j + 10, k + 1, Blocks.air);
		world.setBlock(i + 3, j + 10, k + 2, Blocks.air);
		world.setBlock(i + 3, j + 10, k + 3, Blocks.air);
		world.setBlock(i + 3, j + 10, k + 4, Blocks.air);
		world.setBlock(i + 3, j + 10, k + 5, Blocks.air);
		world.setBlock(i + 3, j + 10, k + 6, Blocks.air);
		world.setBlock(i + 3, j + 10, k + 7, Blocks.air);
		world.setBlock(i + 3, j + 10, k + 8, Blocks.air);
		world.setBlock(i + 3, j + 10, k + 9, Blocks.air);
		world.setBlock(i + 3, j + 10, k + 10, Blocks.air);
		world.setBlock(i + 3, j + 10, k + 11, Blocks.air);
		world.setBlock(i + 3, j + 10, k + 12, Blocks.air);
		world.setBlock(i + 3, j + 10, k + 13, Blocks.air);
		world.setBlock(i + 3, j + 10, k + 14, Blocks.air);
		world.setBlock(i + 3, j + 10, k + 15, Blocks.air);
		world.setBlock(i + 3, j + 10, k + 16, Blocks.air);
		world.setBlock(i + 3, j + 10, k + 17, Blocks.air);
		world.setBlock(i + 3, j + 10, k + 18, Blocks.air);
		world.setBlock(i + 3, j + 10, k + 19, Blocks.air);
		world.setBlock(i + 3, j + 10, k + 20, Blocks.air);
		world.setBlock(i + 3, j + 10, k + 21, Blocks.air);
		world.setBlock(i + 3, j + 10, k + 22, Blocks.air);
		world.setBlock(i + 3, j + 10, k + 23, Blocks.air);
		world.setBlock(i + 3, j + 10, k + 24, Blocks.air);
		world.setBlock(i + 3, j + 10, k + 25, Blocks.air);
		world.setBlock(i + 4, j + 0, k + 0, Blocks.bedrock);
		world.setBlock(i + 4, j + 0, k + 1, Blocks.bedrock);
		world.setBlock(i + 4, j + 0, k + 2, Blocks.bedrock);
		world.setBlock(i + 4, j + 0, k + 3, Blocks.bedrock);
		world.setBlock(i + 4, j + 0, k + 4, Blocks.bedrock);
		world.setBlock(i + 4, j + 0, k + 5, Blocks.bedrock);
		world.setBlock(i + 4, j + 0, k + 6, Blocks.bedrock);
		world.setBlock(i + 4, j + 0, k + 7, Blocks.bedrock);
		world.setBlock(i + 4, j + 0, k + 8, Blocks.bedrock);
		world.setBlock(i + 4, j + 0, k + 9, Blocks.bedrock);
		world.setBlock(i + 4, j + 0, k + 10, Blocks.bedrock);
		world.setBlock(i + 4, j + 0, k + 11, Blocks.bedrock);
		world.setBlock(i + 4, j + 0, k + 12, Blocks.bedrock);
		world.setBlock(i + 4, j + 0, k + 13, Blocks.bedrock);
		world.setBlock(i + 4, j + 0, k + 14, Blocks.bedrock);
		world.setBlock(i + 4, j + 0, k + 15, Blocks.bedrock);
		world.setBlock(i + 4, j + 0, k + 16, Blocks.bedrock);
		world.setBlock(i + 4, j + 0, k + 17, Blocks.bedrock);
		world.setBlock(i + 4, j + 0, k + 18, Blocks.bedrock);
		world.setBlock(i + 4, j + 0, k + 19, Blocks.bedrock);
		world.setBlock(i + 4, j + 0, k + 20, Blocks.bedrock);
		world.setBlock(i + 4, j + 0, k + 21, Blocks.bedrock);
		world.setBlock(i + 4, j + 0, k + 22, Blocks.bedrock);
		world.setBlock(i + 4, j + 0, k + 23, Blocks.bedrock);
		world.setBlock(i + 4, j + 0, k + 24, Blocks.bedrock);
		world.setBlock(i + 4, j + 0, k + 25, Blocks.bedrock);
		world.setBlock(i + 4, j + 1, k + 0, Blocks.air);
		world.setBlock(i + 4, j + 1, k + 1, Blocks.bedrock);
		world.setBlock(i + 4, j + 1, k + 2, Blocks.bedrock);
		world.setBlock(i + 4, j + 1, k + 3, Blocks.bedrock);
		world.setBlock(i + 4, j + 1, k + 4, Blocks.bedrock);
		world.setBlock(i + 4, j + 1, k + 5, Blocks.glowstone);
		world.setBlock(i + 4, j + 1, k + 6, Blocks.bedrock);
		world.setBlock(i + 4, j + 1, k + 7, Blocks.bedrock);
		world.setBlock(i + 4, j + 1, k + 8, Blocks.bedrock);
		world.setBlock(i + 4, j + 1, k + 9, Blocks.bedrock);
		world.setBlock(i + 4, j + 1, k + 10, Blocks.bedrock);
		world.setBlock(i + 4, j + 1, k + 11, Blocks.bedrock);
		world.setBlock(i + 4, j + 1, k + 12, Blocks.bedrock);
		world.setBlock(i + 4, j + 1, k + 13, Blocks.bedrock);
		world.setBlock(i + 4, j + 1, k + 14, Blocks.bedrock);
		world.setBlock(i + 4, j + 1, k + 15, Blocks.bedrock);
		world.setBlock(i + 4, j + 1, k + 16, Blocks.bedrock);
		world.setBlock(i + 4, j + 1, k + 17, Blocks.bedrock);
		world.setBlock(i + 4, j + 1, k + 18, Blocks.bedrock);
		world.setBlock(i + 4, j + 1, k + 19, Blocks.bedrock);
		world.setBlock(i + 4, j + 1, k + 20, Blocks.bedrock);
		world.setBlock(i + 4, j + 1, k + 21, Blocks.bedrock);
		world.setBlock(i + 4, j + 1, k + 22, Blocks.bedrock);
		world.setBlock(i + 4, j + 1, k + 23, Blocks.bedrock);
		world.setBlock(i + 4, j + 1, k + 24, Blocks.bedrock);
		world.setBlock(i + 4, j + 1, k + 25, Blocks.air);
		world.setBlock(i + 4, j + 2, k + 0, Blocks.air);
		world.setBlock(i + 4, j + 2, k + 1, Blocks.air);
		world.setBlock(i + 4, j + 2, k + 2, Blocks.bedrock);
		world.setBlock(i + 4, j + 2, k + 3, b, ms, 3);
		world.setBlock(i + 4, j + 2, k + 4, Blocks.bedrock);
		world.setBlock(i + 4, j + 2, k + 5, b, ms, 3);
		world.setBlock(i + 4, j + 2, k + 6, b, ms, 3);
		world.setBlock(i + 4, j + 2, k + 7, b, ms, 3);
		world.setBlock(i + 4, j + 2, k + 8, b, ms, 3);
		world.setBlock(i + 4, j + 2, k + 9, b, ms, 3);
		world.setBlock(i + 4, j + 2, k + 10, b, ms, 3);
		world.setBlock(i + 4, j + 2, k + 11, b, ms, 3);
		world.setBlock(i + 4, j + 2, k + 12, b, ms, 3);
		world.setBlock(i + 4, j + 2, k + 13, b, ms, 3);
		world.setBlock(i + 4, j + 2, k + 14, Blocks.glowstone);
		world.setBlock(i + 4, j + 2, k + 15, Blocks.glowstone);
		world.setBlock(i + 4, j + 2, k + 16, Blocks.glowstone);
		world.setBlock(i + 4, j + 2, k + 17, Blocks.glowstone);
		world.setBlock(i + 4, j + 2, k + 18, Blocks.glowstone);
		world.setBlock(i + 4, j + 2, k + 19, Blocks.glowstone);
		world.setBlock(i + 4, j + 2, k + 20, Blocks.glowstone);
		world.setBlock(i + 4, j + 2, k + 21, Blocks.glowstone);
		world.setBlock(i + 4, j + 2, k + 22, Blocks.bedrock);
		world.setBlock(i + 4, j + 2, k + 23, Blocks.bedrock);
		world.setBlock(i + 4, j + 2, k + 24, Blocks.air);
		world.setBlock(i + 4, j + 2, k + 25, Blocks.air);
		world.setBlock(i + 4, j + 3, k + 0, Blocks.air);
		world.setBlock(i + 4, j + 3, k + 1, Blocks.air);
		world.setBlock(i + 4, j + 3, k + 2, Blocks.air);
		world.setBlock(i + 4, j + 3, k + 3, Blocks.nether_brick);
		world.setBlock(i + 4, j + 3, k + 4, Blocks.bedrock);
		world.setBlock(i + 4, j + 3, k + 5, b, ms, 3);
		world.setBlock(i + 4, j + 3, k + 6, Blocks.air);
		world.setBlock(i + 4, j + 3, k + 7, Blocks.air);
		world.setBlock(i + 4, j + 3, k + 8, Blocks.air);
		world.setBlock(i + 4, j + 3, k + 9, Blocks.air);
		world.setBlock(i + 4, j + 3, k + 10, Blocks.air);
		world.setBlock(i + 4, j + 3, k + 11, Blocks.air);
		world.setBlock(i + 4, j + 3, k + 12, Blocks.air);
		world.setBlock(i + 4, j + 3, k + 13, Blocks.air);
		world.setBlock(i + 4, j + 3, k + 14, Blocks.air);
		world.setBlock(i + 4, j + 3, k + 15, Blocks.air);
		world.setBlock(i + 4, j + 3, k + 16, Blocks.air);
		world.setBlock(i + 4, j + 3, k + 17, Blocks.air);
		world.setBlock(i + 4, j + 3, k + 18, Blocks.air);
		world.setBlock(i + 4, j + 3, k + 19, Blocks.air);
		world.setBlock(i + 4, j + 3, k + 20, Blocks.air);
		world.setBlock(i + 4, j + 3, k + 21, Blocks.air);
		world.setBlock(i + 4, j + 3, k + 22, Blocks.nether_brick);
		world.setBlock(i + 4, j + 3, k + 23, Blocks.air);
		world.setBlock(i + 4, j + 3, k + 24, Blocks.air);
		world.setBlock(i + 4, j + 3, k + 25, Blocks.air);
		world.setBlock(i + 4, j + 4, k + 0, Blocks.air);
		world.setBlock(i + 4, j + 4, k + 1, Blocks.air);
		world.setBlock(i + 4, j + 4, k + 2, Blocks.air);
		world.setBlock(i + 4, j + 4, k + 3, Blocks.nether_brick);
		world.setBlock(i + 4, j + 4, k + 4, Blocks.bedrock);
		world.setBlock(i + 4, j + 4, k + 5, b, ms, 3);
		world.setBlock(i + 4, j + 4, k + 6, Blocks.air);
		world.setBlock(i + 4, j + 4, k + 7, Blocks.air);
		world.setBlock(i + 4, j + 4, k + 8, Blocks.air);
		world.setBlock(i + 4, j + 4, k + 9, Blocks.air);
		world.setBlock(i + 4, j + 4, k + 10, Blocks.air);
		world.setBlock(i + 4, j + 4, k + 11, Blocks.air);
		world.setBlock(i + 4, j + 4, k + 12, Blocks.air);
		world.setBlock(i + 4, j + 4, k + 13, Blocks.air);
		world.setBlock(i + 4, j + 4, k + 14, Blocks.air);
		world.setBlock(i + 4, j + 4, k + 15, Blocks.air);
		world.setBlock(i + 4, j + 4, k + 16, Blocks.air);
		world.setBlock(i + 4, j + 4, k + 17, Blocks.air);
		world.setBlock(i + 4, j + 4, k + 18, Blocks.air);
		world.setBlock(i + 4, j + 4, k + 19, Blocks.air);
		world.setBlock(i + 4, j + 4, k + 20, Blocks.air);
		world.setBlock(i + 4, j + 4, k + 21, Blocks.air);
		world.setBlock(i + 4, j + 4, k + 22, Blocks.nether_brick);
		world.setBlock(i + 4, j + 4, k + 23, Blocks.air);
		world.setBlock(i + 4, j + 4, k + 24, Blocks.air);
		world.setBlock(i + 4, j + 4, k + 25, Blocks.air);
		world.setBlock(i + 4, j + 5, k + 0, Blocks.air);
		world.setBlock(i + 4, j + 5, k + 1, Blocks.air);
		world.setBlock(i + 4, j + 5, k + 2, Blocks.air);
		world.setBlock(i + 4, j + 5, k + 3, Blocks.nether_brick);
		world.setBlock(i + 4, j + 5, k + 4, Blocks.bedrock);
		world.setBlock(i + 4, j + 5, k + 5, Blocks.nether_brick);
		world.setBlock(i + 4, j + 5, k + 6, Blocks.air);
		world.setBlock(i + 4, j + 5, k + 7, Blocks.air);
		world.setBlock(i + 4, j + 5, k + 8, Blocks.air);
		world.setBlock(i + 4, j + 5, k + 9, Blocks.air);
		world.setBlock(i + 4, j + 5, k + 10, Blocks.air);
		world.setBlock(i + 4, j + 5, k + 11, Blocks.air);
		world.setBlock(i + 4, j + 5, k + 12, Blocks.air);
		world.setBlock(i + 4, j + 5, k + 13, Blocks.air);
		world.setBlock(i + 4, j + 5, k + 14, Blocks.air);
		world.setBlock(i + 4, j + 5, k + 15, Blocks.air);
		world.setBlock(i + 4, j + 5, k + 16, Blocks.air);
		world.setBlock(i + 4, j + 5, k + 17, Blocks.air);
		world.setBlock(i + 4, j + 5, k + 18, Blocks.air);
		world.setBlock(i + 4, j + 5, k + 19, Blocks.air);
		world.setBlock(i + 4, j + 5, k + 20, Blocks.air);
		world.setBlock(i + 4, j + 5, k + 21, Blocks.air);
		world.setBlock(i + 4, j + 5, k + 22, Blocks.nether_brick);
		world.setBlock(i + 4, j + 5, k + 23, Blocks.air);
		world.setBlock(i + 4, j + 5, k + 24, Blocks.air);
		world.setBlock(i + 4, j + 5, k + 25, Blocks.air);
		world.setBlock(i + 4, j + 6, k + 0, Blocks.air);
		world.setBlock(i + 4, j + 6, k + 1, Blocks.air);
		world.setBlock(i + 4, j + 6, k + 2, Blocks.air);
		world.setBlock(i + 4, j + 6, k + 3, Blocks.nether_brick);
		world.setBlock(i + 4, j + 6, k + 4, Blocks.bedrock);
		world.setBlock(i + 4, j + 6, k + 5, Blocks.nether_brick);
		world.setBlock(i + 4, j + 6, k + 6, Blocks.air);
		world.setBlock(i + 4, j + 6, k + 7, Blocks.air);
		world.setBlock(i + 4, j + 6, k + 8, Blocks.air);
		world.setBlock(i + 4, j + 6, k + 9, Blocks.air);
		world.setBlock(i + 4, j + 6, k + 10, Blocks.air);
		world.setBlock(i + 4, j + 6, k + 11, Blocks.air);
		world.setBlock(i + 4, j + 6, k + 12, Blocks.air);
		world.setBlock(i + 4, j + 6, k + 13, Blocks.air);
		world.setBlock(i + 4, j + 6, k + 14, Blocks.air);
		world.setBlock(i + 4, j + 6, k + 15, Blocks.air);
		world.setBlock(i + 4, j + 6, k + 16, Blocks.air);
		world.setBlock(i + 4, j + 6, k + 17, Blocks.air);
		world.setBlock(i + 4, j + 6, k + 18, Blocks.air);
		world.setBlock(i + 4, j + 6, k + 19, Blocks.air);
		world.setBlock(i + 4, j + 6, k + 20, Blocks.air);
		world.setBlock(i + 4, j + 6, k + 21, Blocks.air);
		world.setBlock(i + 4, j + 6, k + 22, Blocks.nether_brick);
		world.setBlock(i + 4, j + 6, k + 23, Blocks.air);
		world.setBlock(i + 4, j + 6, k + 24, Blocks.air);
		world.setBlock(i + 4, j + 6, k + 25, Blocks.air);
		world.setBlock(i + 4, j + 7, k + 0, Blocks.air);
		world.setBlock(i + 4, j + 7, k + 1, Blocks.air);
		world.setBlock(i + 4, j + 7, k + 2, Blocks.air);
		world.setBlock(i + 4, j + 7, k + 3, Blocks.nether_brick);
		world.setBlock(i + 4, j + 7, k + 4, Blocks.bedrock);
		world.setBlock(i + 4, j + 7, k + 5, Blocks.nether_brick);
		world.setBlock(i + 4, j + 7, k + 6, Blocks.nether_brick);
		world.setBlock(i + 4, j + 7, k + 7, Blocks.nether_brick);
		world.setBlock(i + 4, j + 7, k + 8, Blocks.nether_brick);
		world.setBlock(i + 4, j + 7, k + 9, Blocks.nether_brick);
		world.setBlock(i + 4, j + 7, k + 10, Blocks.nether_brick);
		world.setBlock(i + 4, j + 7, k + 11, Blocks.nether_brick);
		world.setBlock(i + 4, j + 7, k + 12, Blocks.nether_brick);
		world.setBlock(i + 4, j + 7, k + 13, Blocks.nether_brick);
		world.setBlock(i + 4, j + 7, k + 14, Blocks.nether_brick);
		world.setBlock(i + 4, j + 7, k + 15, Blocks.nether_brick);
		world.setBlock(i + 4, j + 7, k + 16, Blocks.nether_brick);
		world.setBlock(i + 4, j + 7, k + 17, Blocks.nether_brick);
		world.setBlock(i + 4, j + 7, k + 18, Blocks.nether_brick);
		world.setBlock(i + 4, j + 7, k + 19, Blocks.nether_brick);
		world.setBlock(i + 4, j + 7, k + 20, Blocks.nether_brick);
		world.setBlock(i + 4, j + 7, k + 21, Blocks.nether_brick);
		world.setBlock(i + 4, j + 7, k + 22, Blocks.nether_brick);
		world.setBlock(i + 4, j + 7, k + 23, Blocks.air);
		world.setBlock(i + 4, j + 7, k + 24, Blocks.air);
		world.setBlock(i + 4, j + 7, k + 25, Blocks.air);
		world.setBlock(i + 4, j + 8, k + 0, Blocks.air);
		world.setBlock(i + 4, j + 8, k + 1, Blocks.air);
		world.setBlock(i + 4, j + 8, k + 2, Blocks.air);
		world.setBlock(i + 4, j + 8, k + 3, Blocks.nether_brick);
		world.setBlock(i + 4, j + 8, k + 4, Blocks.nether_brick);
		world.setBlock(i + 4, j + 8, k + 5, Blocks.nether_brick);
		world.setBlock(i + 4, j + 8, k + 6, Blocks.air);
		world.setBlock(i + 4, j + 8, k + 7, Blocks.air);
		world.setBlock(i + 4, j + 8, k + 8, Blocks.air);
		world.setBlock(i + 4, j + 8, k + 9, Blocks.air);
		world.setBlock(i + 4, j + 8, k + 10, Blocks.air);
		world.setBlock(i + 4, j + 8, k + 11, Blocks.air);
		world.setBlock(i + 4, j + 8, k + 12, Blocks.air);
		world.setBlock(i + 4, j + 8, k + 13, Blocks.air);
		world.setBlock(i + 4, j + 8, k + 14, Blocks.air);
		world.setBlock(i + 4, j + 8, k + 15, Blocks.air);
		world.setBlock(i + 4, j + 8, k + 16, Blocks.air);
		world.setBlock(i + 4, j + 8, k + 17, Blocks.air);
		world.setBlock(i + 4, j + 8, k + 18, Blocks.air);
		world.setBlock(i + 4, j + 8, k + 19, Blocks.air);
		world.setBlock(i + 4, j + 8, k + 20, Blocks.air);
		world.setBlock(i + 4, j + 8, k + 21, Blocks.air);
		world.setBlock(i + 4, j + 8, k + 22, Blocks.air);
		world.setBlock(i + 4, j + 8, k + 23, Blocks.air);
		world.setBlock(i + 4, j + 8, k + 24, Blocks.air);
		world.setBlock(i + 4, j + 8, k + 25, Blocks.air);
		world.setBlock(i + 4, j + 9, k + 0, Blocks.air);
		world.setBlock(i + 4, j + 9, k + 1, Blocks.air);
		world.setBlock(i + 4, j + 9, k + 2, Blocks.air);
		world.setBlock(i + 4, j + 9, k + 3, Blocks.air);
		world.setBlock(i + 4, j + 9, k + 4, Blocks.air);
		world.setBlock(i + 4, j + 9, k + 5, Blocks.air);
		world.setBlock(i + 4, j + 9, k + 6, Blocks.air);
		world.setBlock(i + 4, j + 9, k + 7, Blocks.air);
		world.setBlock(i + 4, j + 9, k + 8, Blocks.air);
		world.setBlock(i + 4, j + 9, k + 9, Blocks.air);
		world.setBlock(i + 4, j + 9, k + 10, Blocks.air);
		world.setBlock(i + 4, j + 9, k + 11, Blocks.air);
		world.setBlock(i + 4, j + 9, k + 12, Blocks.air);
		world.setBlock(i + 4, j + 9, k + 13, Blocks.air);
		world.setBlock(i + 4, j + 9, k + 14, Blocks.air);
		world.setBlock(i + 4, j + 9, k + 15, Blocks.air);
		world.setBlock(i + 4, j + 9, k + 16, Blocks.air);
		world.setBlock(i + 4, j + 9, k + 17, Blocks.air);
		world.setBlock(i + 4, j + 9, k + 18, Blocks.air);
		world.setBlock(i + 4, j + 9, k + 19, Blocks.air);
		world.setBlock(i + 4, j + 9, k + 20, Blocks.air);
		world.setBlock(i + 4, j + 9, k + 21, Blocks.air);
		world.setBlock(i + 4, j + 9, k + 22, Blocks.air);
		world.setBlock(i + 4, j + 9, k + 23, Blocks.air);
		world.setBlock(i + 4, j + 9, k + 24, Blocks.air);
		world.setBlock(i + 4, j + 9, k + 25, Blocks.air);
		world.setBlock(i + 4, j + 10, k + 0, Blocks.air);
		world.setBlock(i + 4, j + 10, k + 1, Blocks.air);
		world.setBlock(i + 4, j + 10, k + 2, Blocks.air);
		world.setBlock(i + 4, j + 10, k + 3, Blocks.air);
		world.setBlock(i + 4, j + 10, k + 4, Blocks.air);
		world.setBlock(i + 4, j + 10, k + 5, Blocks.air);
		world.setBlock(i + 4, j + 10, k + 6, Blocks.air);
		world.setBlock(i + 4, j + 10, k + 7, Blocks.air);
		world.setBlock(i + 4, j + 10, k + 8, Blocks.air);
		world.setBlock(i + 4, j + 10, k + 9, Blocks.air);
		world.setBlock(i + 4, j + 10, k + 10, Blocks.air);
		world.setBlock(i + 4, j + 10, k + 11, Blocks.air);
		world.setBlock(i + 4, j + 10, k + 12, Blocks.air);
		world.setBlock(i + 4, j + 10, k + 13, Blocks.air);
		world.setBlock(i + 4, j + 10, k + 14, Blocks.air);
		world.setBlock(i + 4, j + 10, k + 15, Blocks.air);
		world.setBlock(i + 4, j + 10, k + 16, Blocks.air);
		world.setBlock(i + 4, j + 10, k + 17, Blocks.air);
		world.setBlock(i + 4, j + 10, k + 18, Blocks.air);
		world.setBlock(i + 4, j + 10, k + 19, Blocks.air);
		world.setBlock(i + 4, j + 10, k + 20, Blocks.air);
		world.setBlock(i + 4, j + 10, k + 21, Blocks.air);
		world.setBlock(i + 4, j + 10, k + 22, Blocks.air);
		world.setBlock(i + 4, j + 10, k + 23, Blocks.air);
		world.setBlock(i + 4, j + 10, k + 24, Blocks.air);
		world.setBlock(i + 4, j + 10, k + 25, Blocks.air);
		world.setBlock(i + 5, j + 0, k + 0, Blocks.bedrock);
		world.setBlock(i + 5, j + 0, k + 1, Blocks.bedrock);
		world.setBlock(i + 5, j + 0, k + 2, Blocks.bedrock);
		world.setBlock(i + 5, j + 0, k + 3, Blocks.bedrock);
		world.setBlock(i + 5, j + 0, k + 4, Blocks.bedrock);
		world.setBlock(i + 5, j + 0, k + 5, Blocks.sticky_piston, 3, 2);
		world.setBlock(i + 5, j + 0, k + 6, Blocks.redstone_block);
		world.setBlock(i + 5, j + 0, k + 7, Blocks.air);
		world.setBlock(i + 5, j + 0, k + 8, Blocks.bedrock);
		world.setBlock(i + 5, j + 0, k + 9, Blocks.bedrock);
		world.setBlock(i + 5, j + 0, k + 10, Blocks.bedrock);
		world.setBlock(i + 5, j + 0, k + 11, Blocks.bedrock);
		world.setBlock(i + 5, j + 0, k + 12, Blocks.bedrock);
		world.setBlock(i + 5, j + 0, k + 13, Blocks.bedrock);
		world.setBlock(i + 5, j + 0, k + 14, Blocks.bedrock);
		world.setBlock(i + 5, j + 0, k + 15, Blocks.bedrock);
		world.setBlock(i + 5, j + 0, k + 16, Blocks.bedrock);
		world.setBlock(i + 5, j + 0, k + 17, Blocks.bedrock);
		world.setBlock(i + 5, j + 0, k + 18, Blocks.bedrock);
		world.setBlock(i + 5, j + 0, k + 19, Blocks.bedrock);
		world.setBlock(i + 5, j + 0, k + 20, Blocks.bedrock);
		world.setBlock(i + 5, j + 0, k + 21, Blocks.bedrock);
		world.setBlock(i + 5, j + 0, k + 22, Blocks.bedrock);
		world.setBlock(i + 5, j + 0, k + 23, Blocks.bedrock);
		world.setBlock(i + 5, j + 0, k + 24, Blocks.bedrock);
		world.setBlock(i + 5, j + 0, k + 25, Blocks.bedrock);
		world.setBlock(i + 5, j + 1, k + 0, Blocks.air);
		world.setBlock(i + 5, j + 1, k + 1, Blocks.bedrock);
		world.setBlock(i + 5, j + 1, k + 2, Blocks.bedrock);
		world.setBlock(i + 5, j + 1, k + 3, Blocks.bedrock);
		world.setBlock(i + 5, j + 1, k + 5, Blocks.air);
		world.setBlock(i + 5, j + 1, k + 6, Blocks.air);
		world.setBlock(i + 5, j + 1, k + 7, Blocks.bedrock);
		world.setBlock(i + 5, j + 1, k + 8, Blocks.bedrock);
		world.setBlock(i + 5, j + 1, k + 9, Blocks.bedrock);
		world.setBlock(i + 5, j + 1, k + 10, Blocks.bedrock);
		world.setBlock(i + 5, j + 1, k + 11, Blocks.bedrock);
		world.setBlock(i + 5, j + 1, k + 12, Blocks.bedrock);
		world.setBlock(i + 5, j + 1, k + 13, Blocks.bedrock);
		world.setBlock(i + 5, j + 1, k + 14, Blocks.bedrock);
		world.setBlock(i + 5, j + 1, k + 15, Blocks.bedrock);
		world.setBlock(i + 5, j + 1, k + 16, Blocks.bedrock);
		world.setBlock(i + 5, j + 1, k + 17, Blocks.bedrock);
		world.setBlock(i + 5, j + 1, k + 18, Blocks.bedrock);
		world.setBlock(i + 5, j + 1, k + 19, Blocks.bedrock);
		world.setBlock(i + 5, j + 1, k + 20, Blocks.bedrock);
		world.setBlock(i + 5, j + 1, k + 21, Blocks.bedrock);
		world.setBlock(i + 5, j + 1, k + 22, Blocks.bedrock);
		world.setBlock(i + 5, j + 1, k + 23, Blocks.bedrock);
		world.setBlock(i + 5, j + 1, k + 24, Blocks.bedrock);
		world.setBlock(i + 5, j + 1, k + 25, Blocks.bedrock);
		world.setBlock(i + 5, j + 2, k + 0, Blocks.air);
		world.setBlock(i + 5, j + 2, k + 1, Blocks.air);
		world.setBlock(i + 5, j + 2, k + 2, Blocks.bedrock);
		world.setBlock(i + 5, j + 2, k + 3, b, ms, 3);
		world.setBlock(i + 5, j + 2, k + 4, Blocks.bedrock);
		world.setBlock(i + 5, j + 2, k + 5, b, ms, 3);
		world.setBlock(i + 5, j + 2, k + 6, b, ms, 3);
		world.setBlock(i + 5, j + 2, k + 7, b, ms, 3);
		world.setBlock(i + 5, j + 2, k + 8, b, ms, 3);
		world.setBlock(i + 5, j + 2, k + 9, b, ms, 3);
		world.setBlock(i + 5, j + 2, k + 10, b, ms, 3);
		world.setBlock(i + 5, j + 2, k + 11, b, ms, 3);
		world.setBlock(i + 5, j + 2, k + 12, b, ms, 3);
		world.setBlock(i + 5, j + 2, k + 13, b, ms, 3);
		world.setBlock(i + 5, j + 2, k + 14, Blocks.glowstone);
		world.setBlock(i + 5, j + 2, k + 15, Blocks.netherrack);
		world.setBlock(i + 5, j + 2, k + 16, Blocks.netherrack);
		world.setBlock(i + 5, j + 2, k + 17, Blocks.netherrack);
		world.setBlock(i + 5, j + 2, k + 18, Blocks.netherrack);
		world.setBlock(i + 5, j + 2, k + 19, Blocks.netherrack);
		world.setBlock(i + 5, j + 2, k + 20, Blocks.netherrack);
		world.setBlock(i + 5, j + 2, k + 21, Blocks.netherrack);
		world.setBlock(i + 5, j + 2, k + 22, Blocks.nether_brick);
		world.setBlock(i + 5, j + 2, k + 23, Blocks.bedrock);
		world.setBlock(i + 5, j + 2, k + 24, Blocks.bedrock);
		world.setBlock(i + 5, j + 2, k + 25, Blocks.air);
		world.setBlock(i + 5, j + 3, k + 0, Blocks.air);
		world.setBlock(i + 5, j + 3, k + 1, Blocks.air);
		world.setBlock(i + 5, j + 3, k + 2, Blocks.air);
		world.setBlock(i + 5, j + 3, k + 3, Blocks.nether_brick);
		world.setBlock(i + 5, j + 3, k + 4, Blocks.bedrock);
		world.setBlock(i + 5, j + 3, k + 5, b, ms, 3);
		world.setBlock(i + 5, j + 3, k + 6, Blocks.air);
		world.setBlock(i + 5, j + 3, k + 7, Blocks.nether_brick_fence);
		world.setBlock(i + 5, j + 3, k + 8, Blocks.air);
		world.setBlock(i + 5, j + 3, k + 9, Blocks.air);
		world.setBlock(i + 5, j + 3, k + 10, Blocks.nether_brick_fence);
		world.setBlock(i + 5, j + 3, k + 11, Blocks.air);
		world.setBlock(i + 5, j + 3, k + 12, Blocks.nether_brick_fence);
		world.setBlock(i + 5, j + 3, k + 13, Blocks.air);
		world.setBlock(i + 5, j + 3, k + 14, Blocks.air);
		world.setBlock(i + 5, j + 3, k + 15, Blocks.air);
		world.setBlock(i + 5, j + 3, k + 16, Blocks.air);
		world.setBlock(i + 5, j + 3, k + 17, Blocks.air);
		world.setBlock(i + 5, j + 3, k + 18, Blocks.air);
		world.setBlock(i + 5, j + 3, k + 19, Blocks.air);
		world.setBlock(i + 5, j + 3, k + 20, Blocks.air);
		world.setBlock(i + 5, j + 3, k + 21, Blocks.air);
		world.setBlock(i + 5, j + 3, k + 22, Blocks.nether_brick_fence);
		world.setBlock(i + 5, j + 3, k + 23, Blocks.air);
		world.setBlock(i + 5, j + 3, k + 24, Blocks.air);
		world.setBlock(i + 5, j + 3, k + 25, Blocks.air);
		world.setBlock(i + 5, j + 4, k + 0, Blocks.air);
		world.setBlock(i + 5, j + 4, k + 1, Blocks.air);
		world.setBlock(i + 5, j + 4, k + 2, Blocks.air);
		world.setBlock(i + 5, j + 4, k + 3, Blocks.nether_brick);
		world.setBlock(i + 5, j + 4, k + 4, Blocks.bedrock);
		world.setBlock(i + 5, j + 4, k + 5, Blocks.nether_brick);
		world.setBlock(i + 5, j + 4, k + 6, Blocks.air);
		world.setBlock(i + 5, j + 4, k + 7, Blocks.glowstone);
		world.setBlock(i + 5, j + 4, k + 8, Blocks.air);
		world.setBlock(i + 5, j + 4, k + 9, Blocks.air);
		world.setBlock(i + 5, j + 4, k + 10, Blocks.nether_brick_fence);
		world.setBlock(i + 5, j + 4, k + 11, Blocks.air);
		world.setBlock(i + 5, j + 4, k + 12, Blocks.nether_brick_fence);
		world.setBlock(i + 5, j + 4, k + 13, Blocks.air);
		world.setBlock(i + 5, j + 4, k + 14, Blocks.air);
		world.setBlock(i + 5, j + 4, k + 15, Blocks.air);
		world.setBlock(i + 5, j + 4, k + 16, Blocks.air);
		world.setBlock(i + 5, j + 4, k + 17, Blocks.air);

		generate2(world, i, j, k, rand);
	}

	private static void generate2(World world, int i, int j, int k, Random rand) {
		world.setBlock(i + 5, j + 4, k + 18, Blocks.air);
		world.setBlock(i + 5, j + 4, k + 19, Blocks.air);
		world.setBlock(i + 5, j + 4, k + 20, Blocks.air);
		world.setBlock(i + 5, j + 4, k + 21, Blocks.air);
		world.setBlock(i + 5, j + 4, k + 22, Blocks.nether_brick_fence);
		world.setBlock(i + 5, j + 4, k + 23, Blocks.air);
		world.setBlock(i + 5, j + 4, k + 24, Blocks.air);
		world.setBlock(i + 5, j + 4, k + 25, Blocks.air);
		world.setBlock(i + 5, j + 5, k + 0, Blocks.air);
		world.setBlock(i + 5, j + 5, k + 1, Blocks.air);
		world.setBlock(i + 5, j + 5, k + 2, Blocks.air);
		world.setBlock(i + 5, j + 5, k + 3, Blocks.nether_brick);
		world.setBlock(i + 5, j + 5, k + 4, Blocks.bedrock);
		world.setBlock(i + 5, j + 5, k + 5, Blocks.nether_brick);
		world.setBlock(i + 5, j + 5, k + 6, Blocks.air);
		world.setBlock(i + 5, j + 5, k + 7, Blocks.air);
		world.setBlock(i + 5, j + 5, k + 8, Blocks.air);
		world.setBlock(i + 5, j + 5, k + 9, Blocks.air);
		world.setBlock(i + 5, j + 5, k + 10, Blocks.nether_brick_fence);
		world.setBlock(i + 5, j + 5, k + 11, Blocks.nether_brick_fence);
		world.setBlock(i + 5, j + 5, k + 12, Blocks.nether_brick_fence);
		world.setBlock(i + 5, j + 5, k + 13, Blocks.air);
		world.setBlock(i + 5, j + 5, k + 14, Blocks.air);
		world.setBlock(i + 5, j + 5, k + 15, Blocks.air);
		world.setBlock(i + 5, j + 5, k + 16, Blocks.air);
		world.setBlock(i + 5, j + 5, k + 17, Blocks.air);
		world.setBlock(i + 5, j + 5, k + 18, Blocks.air);
		world.setBlock(i + 5, j + 5, k + 19, Blocks.air);
		world.setBlock(i + 5, j + 5, k + 20, Blocks.air);
		world.setBlock(i + 5, j + 5, k + 21, Blocks.air);
		world.setBlock(i + 5, j + 5, k + 22, Blocks.nether_brick_fence);
		world.setBlock(i + 5, j + 5, k + 23, Blocks.air);
		world.setBlock(i + 5, j + 5, k + 24, Blocks.air);
		world.setBlock(i + 5, j + 5, k + 25, Blocks.air);
		world.setBlock(i + 5, j + 6, k + 0, Blocks.air);
		world.setBlock(i + 5, j + 6, k + 1, Blocks.air);
		world.setBlock(i + 5, j + 6, k + 2, Blocks.air);
		world.setBlock(i + 5, j + 6, k + 3, Blocks.nether_brick);
		world.setBlock(i + 5, j + 6, k + 4, Blocks.bedrock);
		world.setBlock(i + 5, j + 6, k + 5, Blocks.nether_brick);
		world.setBlock(i + 5, j + 6, k + 6, Blocks.air);
		world.setBlock(i + 5, j + 6, k + 7, Blocks.air);
		world.setBlock(i + 5, j + 6, k + 8, Blocks.air);
		world.setBlock(i + 5, j + 6, k + 9, Blocks.air);
		world.setBlock(i + 5, j + 6, k + 10, Blocks.nether_brick_fence);
		world.setBlock(i + 5, j + 6, k + 11, Blocks.air);
		world.setBlock(i + 5, j + 6, k + 12, Blocks.nether_brick_fence);
		world.setBlock(i + 5, j + 6, k + 13, Blocks.air);
		world.setBlock(i + 5, j + 6, k + 14, Blocks.air);
		world.setBlock(i + 5, j + 6, k + 15, Blocks.air);
		world.setBlock(i + 5, j + 6, k + 16, Blocks.air);
		world.setBlock(i + 5, j + 6, k + 17, Blocks.air);
		world.setBlock(i + 5, j + 6, k + 18, Blocks.air);
		world.setBlock(i + 5, j + 6, k + 19, Blocks.air);
		world.setBlock(i + 5, j + 6, k + 20, Blocks.air);
		world.setBlock(i + 5, j + 6, k + 21, Blocks.air);
		world.setBlock(i + 5, j + 6, k + 22, Blocks.nether_brick_fence);
		world.setBlock(i + 5, j + 6, k + 23, Blocks.air);
		world.setBlock(i + 5, j + 6, k + 24, Blocks.air);
		world.setBlock(i + 5, j + 6, k + 25, Blocks.air);
		world.setBlock(i + 5, j + 7, k + 0, Blocks.air);
		world.setBlock(i + 5, j + 7, k + 1, Blocks.air);
		world.setBlock(i + 5, j + 7, k + 2, Blocks.air);
		world.setBlock(i + 5, j + 7, k + 3, Blocks.nether_brick);
		world.setBlock(i + 5, j + 7, k + 4, Blocks.bedrock);
		world.setBlock(i + 5, j + 7, k + 5, Blocks.nether_brick);
		world.setBlock(i + 5, j + 7, k + 6, Blocks.nether_brick);
		world.setBlock(i + 5, j + 7, k + 7, Blocks.nether_brick);
		world.setBlock(i + 5, j + 7, k + 8, Blocks.nether_brick);
		world.setBlock(i + 5, j + 7, k + 9, Blocks.nether_brick);
		world.setBlock(i + 5, j + 7, k + 10, Blocks.nether_brick);
		world.setBlock(i + 5, j + 7, k + 11, Blocks.nether_brick);
		world.setBlock(i + 5, j + 7, k + 12, Blocks.nether_brick);
		world.setBlock(i + 5, j + 7, k + 13, Blocks.nether_brick);
		world.setBlock(i + 5, j + 7, k + 14, Blocks.nether_brick);
		world.setBlock(i + 5, j + 7, k + 15, Blocks.nether_brick);
		world.setBlock(i + 5, j + 7, k + 16, Blocks.nether_brick);
		world.setBlock(i + 5, j + 7, k + 17, Blocks.nether_brick);
		world.setBlock(i + 5, j + 7, k + 18, Blocks.nether_brick);
		world.setBlock(i + 5, j + 7, k + 19, Blocks.nether_brick);
		world.setBlock(i + 5, j + 7, k + 20, Blocks.nether_brick);
		world.setBlock(i + 5, j + 7, k + 21, Blocks.nether_brick);
		world.setBlock(i + 5, j + 7, k + 22, Blocks.nether_brick);
		world.setBlock(i + 5, j + 7, k + 23, Blocks.air);
		world.setBlock(i + 5, j + 7, k + 24, Blocks.air);
		world.setBlock(i + 5, j + 7, k + 25, Blocks.air);
		world.setBlock(i + 5, j + 8, k + 0, Blocks.air);
		world.setBlock(i + 5, j + 8, k + 1, Blocks.air);
		world.setBlock(i + 5, j + 8, k + 2, Blocks.air);
		world.setBlock(i + 5, j + 8, k + 3, Blocks.nether_brick);
		world.setBlock(i + 5, j + 8, k + 4, Blocks.nether_brick);
		world.setBlock(i + 5, j + 8, k + 5, Blocks.nether_brick);
		world.setBlock(i + 5, j + 8, k + 6, Blocks.nether_brick);
		world.setBlock(i + 5, j + 8, k + 7, Blocks.nether_brick);
		world.setBlock(i + 5, j + 8, k + 8, Blocks.nether_brick);
		world.setBlock(i + 5, j + 8, k + 9, Blocks.nether_brick);
		world.setBlock(i + 5, j + 8, k + 10, Blocks.nether_brick);
		world.setBlock(i + 5, j + 8, k + 11, Blocks.nether_brick);
		world.setBlock(i + 5, j + 8, k + 12, Blocks.nether_brick);
		world.setBlock(i + 5, j + 8, k + 13, Blocks.air);
		world.setBlock(i + 5, j + 8, k + 14, Blocks.air);
		world.setBlock(i + 5, j + 8, k + 15, Blocks.air);
		world.setBlock(i + 5, j + 8, k + 16, Blocks.air);
		world.setBlock(i + 5, j + 8, k + 17, Blocks.air);
		world.setBlock(i + 5, j + 8, k + 18, Blocks.air);
		world.setBlock(i + 5, j + 8, k + 19, Blocks.air);
		world.setBlock(i + 5, j + 8, k + 20, Blocks.air);
		world.setBlock(i + 5, j + 8, k + 21, Blocks.air);
		world.setBlock(i + 5, j + 8, k + 22, Blocks.air);
		world.setBlock(i + 5, j + 8, k + 23, Blocks.air);
		world.setBlock(i + 5, j + 8, k + 24, Blocks.air);
		world.setBlock(i + 5, j + 8, k + 25, Blocks.air);
		world.setBlock(i + 5, j + 9, k + 0, Blocks.air);
		world.setBlock(i + 5, j + 9, k + 1, Blocks.air);
		world.setBlock(i + 5, j + 9, k + 2, Blocks.air);
		world.setBlock(i + 5, j + 9, k + 3, Blocks.air);
		world.setBlock(i + 5, j + 9, k + 4, Blocks.air);
		world.setBlock(i + 5, j + 9, k + 5, Blocks.air);
		world.setBlock(i + 5, j + 9, k + 6, Blocks.air);
		world.setBlock(i + 5, j + 9, k + 7, Blocks.air);
		world.setBlock(i + 5, j + 9, k + 8, Blocks.air);
		world.setBlock(i + 5, j + 9, k + 9, Blocks.air);
		world.setBlock(i + 5, j + 9, k + 10, Blocks.air);
		world.setBlock(i + 5, j + 9, k + 11, Blocks.air);
		world.setBlock(i + 5, j + 9, k + 12, Blocks.air);
		world.setBlock(i + 5, j + 9, k + 13, Blocks.air);
		world.setBlock(i + 5, j + 9, k + 14, Blocks.air);
		world.setBlock(i + 5, j + 9, k + 15, Blocks.air);
		world.setBlock(i + 5, j + 9, k + 16, Blocks.air);
		world.setBlock(i + 5, j + 9, k + 17, Blocks.air);
		world.setBlock(i + 5, j + 9, k + 18, Blocks.air);
		world.setBlock(i + 5, j + 9, k + 19, Blocks.air);
		world.setBlock(i + 5, j + 9, k + 20, Blocks.air);
		world.setBlock(i + 5, j + 9, k + 21, Blocks.air);
		world.setBlock(i + 5, j + 9, k + 22, Blocks.air);
		world.setBlock(i + 5, j + 9, k + 23, Blocks.air);
		world.setBlock(i + 5, j + 9, k + 24, Blocks.air);
		world.setBlock(i + 5, j + 9, k + 25, Blocks.air);
		world.setBlock(i + 5, j + 10, k + 0, Blocks.air);
		world.setBlock(i + 5, j + 10, k + 1, Blocks.air);
		world.setBlock(i + 5, j + 10, k + 2, Blocks.air);
		world.setBlock(i + 5, j + 10, k + 3, Blocks.air);
		world.setBlock(i + 5, j + 10, k + 4, Blocks.air);
		world.setBlock(i + 5, j + 10, k + 5, Blocks.air);
		world.setBlock(i + 5, j + 10, k + 6, Blocks.air);
		world.setBlock(i + 5, j + 10, k + 7, Blocks.air);
		world.setBlock(i + 5, j + 10, k + 8, Blocks.air);
		world.setBlock(i + 5, j + 10, k + 9, Blocks.air);
		world.setBlock(i + 5, j + 10, k + 10, Blocks.air);
		world.setBlock(i + 5, j + 10, k + 11, Blocks.air);
		world.setBlock(i + 5, j + 10, k + 12, Blocks.air);
		world.setBlock(i + 5, j + 10, k + 13, Blocks.air);
		world.setBlock(i + 5, j + 10, k + 14, Blocks.air);
		world.setBlock(i + 5, j + 10, k + 15, Blocks.air);
		world.setBlock(i + 5, j + 10, k + 16, Blocks.air);
		world.setBlock(i + 5, j + 10, k + 17, Blocks.air);
		world.setBlock(i + 5, j + 10, k + 18, Blocks.air);
		world.setBlock(i + 5, j + 10, k + 19, Blocks.air);
		world.setBlock(i + 5, j + 10, k + 20, Blocks.air);
		world.setBlock(i + 5, j + 10, k + 21, Blocks.air);
		world.setBlock(i + 5, j + 10, k + 22, Blocks.air);
		world.setBlock(i + 5, j + 10, k + 23, Blocks.air);
		world.setBlock(i + 5, j + 10, k + 24, Blocks.air);
		world.setBlock(i + 5, j + 10, k + 25, Blocks.air);
		world.setBlock(i + 6, j + 0, k + 0, Blocks.bedrock);
		world.setBlock(i + 6, j + 0, k + 1, Blocks.bedrock);
		world.setBlock(i + 6, j + 0, k + 2, Blocks.bedrock);
		world.setBlock(i + 6, j + 0, k + 3, Blocks.bedrock);
		world.setBlock(i + 6, j + 0, k + 4, Blocks.bedrock);
		world.setBlock(i + 6, j + 0, k + 5, Blocks.air);
		world.setBlock(i + 6, j + 0, k + 6, Blocks.air);
		world.setBlock(i + 6, j + 0, k + 7, Blocks.sticky_piston, 2, 2);
		world.setBlock(i + 6, j + 0, k + 8, Blocks.bedrock);
		world.setBlock(i + 6, j + 0, k + 9, Blocks.bedrock);
		world.setBlock(i + 6, j + 0, k + 10, Blocks.bedrock);
		world.setBlock(i + 6, j + 0, k + 11, Blocks.bedrock);
		world.setBlock(i + 6, j + 0, k + 12, Blocks.bedrock);
		world.setBlock(i + 6, j + 0, k + 13, Blocks.bedrock);
		world.setBlock(i + 6, j + 0, k + 14, Blocks.bedrock);
		world.setBlock(i + 6, j + 0, k + 15, Blocks.bedrock);
		world.setBlock(i + 6, j + 0, k + 16, Blocks.bedrock);
		world.setBlock(i + 6, j + 0, k + 17, Blocks.bedrock);
		world.setBlock(i + 6, j + 0, k + 18, Blocks.bedrock);
		world.setBlock(i + 6, j + 0, k + 19, Blocks.bedrock);
		world.setBlock(i + 6, j + 0, k + 20, Blocks.bedrock);
		world.setBlock(i + 6, j + 0, k + 21, Blocks.bedrock);
		world.setBlock(i + 6, j + 0, k + 22, Blocks.bedrock);
		world.setBlock(i + 6, j + 0, k + 23, Blocks.bedrock);
		world.setBlock(i + 6, j + 0, k + 24, Blocks.bedrock);
		world.setBlock(i + 6, j + 0, k + 25, Blocks.bedrock);
		world.setBlock(i + 6, j + 1, k + 0, Blocks.air);
		world.setBlock(i + 6, j + 1, k + 1, Blocks.bedrock);
		world.setBlock(i + 6, j + 1, k + 2, Blocks.bedrock);
		world.setBlock(i + 6, j + 1, k + 3, Blocks.bedrock);
		world.setBlock(i + 6, j + 1, k + 4, Blocks.bedrock);
		world.setBlock(i + 6, j + 1, k + 5, Blocks.air);
		world.setBlock(i + 6, j + 1, k + 6, Blocks.air);
		world.setBlock(i + 6, j + 1, k + 7, Blocks.air);
		world.setBlock(i + 6, j + 1, k + 8, Blocks.bedrock);
		world.setBlock(i + 6, j + 1, k + 9, Blocks.bedrock);
		world.setBlock(i + 6, j + 1, k + 10, Blocks.bedrock);
		world.setBlock(i + 6, j + 1, k + 11, Blocks.bedrock);
		world.setBlock(i + 6, j + 1, k + 12, Blocks.bedrock);
		world.setBlock(i + 6, j + 1, k + 13, Blocks.bedrock);
		world.setBlock(i + 6, j + 1, k + 14, Blocks.bedrock);
		world.setBlock(i + 6, j + 1, k + 15, Blocks.bedrock);
		world.setBlock(i + 6, j + 1, k + 16, Blocks.bedrock);
		world.setBlock(i + 6, j + 1, k + 17, Blocks.bedrock);
		world.setBlock(i + 6, j + 1, k + 18, Blocks.bedrock);
		world.setBlock(i + 6, j + 1, k + 19, Blocks.bedrock);
		world.setBlock(i + 6, j + 1, k + 20, Blocks.bedrock);
		world.setBlock(i + 6, j + 1, k + 21, Blocks.bedrock);
		world.setBlock(i + 6, j + 1, k + 22, Blocks.bedrock);
		world.setBlock(i + 6, j + 1, k + 23, Blocks.bedrock);
		world.setBlock(i + 6, j + 1, k + 24, Blocks.bedrock);
		world.setBlock(i + 6, j + 1, k + 25, Blocks.bedrock);
		world.setBlock(i + 6, j + 2, k + 0, Blocks.air);
		world.setBlock(i + 6, j + 2, k + 1, Blocks.air);
		world.setBlock(i + 6, j + 2, k + 2, Blocks.bedrock);
		world.setBlock(i + 6, j + 2, k + 3, b, ms, 3);
		world.setBlock(i + 6, j + 2, k + 4, Blocks.bedrock);
		world.setBlock(i + 6, j + 2, k + 5, b, ms, 3);
		world.setBlock(i + 6, j + 2, k + 6, Blocks.soul_sand);
		world.setBlock(i + 6, j + 2, k + 7, Blocks.soul_sand);
		world.setBlock(i + 6, j + 2, k + 8, Blocks.soul_sand);
		world.setBlock(i + 6, j + 2, k + 9, Blocks.soul_sand);
		world.setBlock(i + 6, j + 2, k + 10, b, ms, 3);
		world.setBlock(i + 6, j + 2, k + 11, b, ms, 3);
		world.setBlock(i + 6, j + 2, k + 12, b, ms, 3);
		world.setBlock(i + 6, j + 2, k + 13, b, ms, 3);
		world.setBlock(i + 6, j + 2, k + 14, Blocks.glowstone);
		world.setBlock(i + 6, j + 2, k + 15, Blocks.netherrack);
		world.setBlock(i + 6, j + 2, k + 16, Blocks.netherrack);
		world.setBlock(i + 6, j + 2, k + 17, Blocks.netherrack);
		world.setBlock(i + 6, j + 2, k + 19, Blocks.netherrack);
		world.setBlock(i + 6, j + 2, k + 20, Blocks.netherrack);
		world.setBlock(i + 6, j + 2, k + 21, Blocks.netherrack);
		world.setBlock(i + 6, j + 2, k + 22, Blocks.nether_brick);
		world.setBlock(i + 6, j + 2, k + 23, Blocks.nether_brick);
		world.setBlock(i + 6, j + 2, k + 24, Blocks.nether_brick);
		world.setBlock(i + 6, j + 2, k + 25, Blocks.nether_brick);
		world.setBlock(i + 6, j + 3, k + 0, Blocks.air);
		world.setBlock(i + 6, j + 3, k + 1, Blocks.air);
		world.setBlock(i + 6, j + 3, k + 2, Blocks.air);
		world.setBlock(i + 6, j + 3, k + 3, Blocks.nether_brick);
		world.setBlock(i + 6, j + 3, k + 4, Blocks.bedrock);
		world.setBlock(i + 6, j + 3, k + 5, Blocks.nether_brick);
		world.setBlock(i + 6, j + 3, k + 6, Blocks.air);
		world.setBlock(i + 6, j + 3, k + 7, Blocks.air);
		world.setBlock(i + 6, j + 3, k + 8, Blocks.air);
		world.setBlock(i + 6, j + 3, k + 9, Blocks.air);
		world.setBlock(i + 6, j + 3, k + 10, Blocks.air);
		world.setBlock(i + 6, j + 3, k + 11, Blocks.brewing_stand);
		world.setBlock(i + 6, j + 3, k + 12, Blocks.air);
		world.setBlock(i + 6, j + 3, k + 13, Blocks.air);
		world.setBlock(i + 6, j + 3, k + 14, Blocks.air);
		world.setBlock(i + 6, j + 3, k + 15, Blocks.air);
		world.setBlock(i + 6, j + 3, k + 16, Blocks.air);
		world.setBlock(i + 6, j + 3, k + 17, Blocks.air);
		world.setBlock(i + 6, j + 3, k + 19, Blocks.air);
		world.setBlock(i + 6, j + 3, k + 20, Blocks.air);
		world.setBlock(i + 6, j + 3, k + 21, Blocks.air);
		world.setBlock(i + 6, j + 3, k + 22, Blocks.nether_brick_fence);
		world.setBlock(i + 6, j + 3, k + 23, Blocks.nether_brick_fence);
		world.setBlock(i + 6, j + 3, k + 24, Blocks.nether_brick_fence);
		world.setBlock(i + 6, j + 3, k + 25, Blocks.nether_brick_fence);
		world.setBlock(i + 6, j + 4, k + 0, Blocks.air);
		world.setBlock(i + 6, j + 4, k + 1, Blocks.air);
		world.setBlock(i + 6, j + 4, k + 2, Blocks.air);
		world.setBlock(i + 6, j + 4, k + 3, Blocks.nether_brick);
		world.setBlock(i + 6, j + 4, k + 4, Blocks.bedrock);
		world.setBlock(i + 6, j + 4, k + 5, Blocks.nether_brick);
		world.setBlock(i + 6, j + 4, k + 6, Blocks.air);
		world.setBlock(i + 6, j + 4, k + 7, Blocks.air);
		world.setBlock(i + 6, j + 4, k + 8, Blocks.air);
		world.setBlock(i + 6, j + 4, k + 9, Blocks.air);
		world.setBlock(i + 6, j + 4, k + 10, Blocks.air);
		world.setBlock(i + 6, j + 4, k + 11, Blocks.air);
		world.setBlock(i + 6, j + 4, k + 12, Blocks.air);
		world.setBlock(i + 6, j + 4, k + 13, Blocks.air);
		world.setBlock(i + 6, j + 4, k + 14, Blocks.air);
		world.setBlock(i + 6, j + 4, k + 15, Blocks.air);
		world.setBlock(i + 6, j + 4, k + 16, Blocks.air);
		world.setBlock(i + 6, j + 4, k + 17, Blocks.air);
		world.setBlock(i + 6, j + 4, k + 19, Blocks.air);
		world.setBlock(i + 6, j + 4, k + 20, Blocks.air);
		world.setBlock(i + 6, j + 4, k + 21, Blocks.air);
		world.setBlock(i + 6, j + 4, k + 22, Blocks.nether_brick_fence);
		world.setBlock(i + 6, j + 4, k + 23, Blocks.air);
		world.setBlock(i + 6, j + 4, k + 24, Blocks.air);
		world.setBlock(i + 6, j + 4, k + 25, Blocks.air);
		world.setBlock(i + 6, j + 5, k + 0, Blocks.air);
		world.setBlock(i + 6, j + 5, k + 1, Blocks.air);
		world.setBlock(i + 6, j + 5, k + 2, Blocks.air);
		world.setBlock(i + 6, j + 5, k + 3, Blocks.nether_brick);
		world.setBlock(i + 6, j + 5, k + 4, Blocks.bedrock);
		world.setBlock(i + 6, j + 5, k + 5, Blocks.nether_brick);
		world.setBlock(i + 6, j + 5, k + 6, Blocks.air);
		world.setBlock(i + 6, j + 5, k + 7, Blocks.air);
		world.setBlock(i + 6, j + 5, k + 8, Blocks.air);
		world.setBlock(i + 6, j + 5, k + 9, Blocks.air);
		world.setBlock(i + 6, j + 5, k + 10, Blocks.air);
		world.setBlock(i + 6, j + 5, k + 11, Blocks.air);
		world.setBlock(i + 6, j + 5, k + 12, Blocks.nether_brick_fence);
		world.setBlock(i + 6, j + 5, k + 13, Blocks.air);
		world.setBlock(i + 6, j + 5, k + 14, Blocks.air);
		world.setBlock(i + 6, j + 5, k + 15, Blocks.air);
		world.setBlock(i + 6, j + 5, k + 16, Blocks.air);
		world.setBlock(i + 6, j + 5, k + 17, Blocks.air);
