/*******************************************************************************
 * @author Reika Kalseki
 * 
 * Copyright 2017
 * 
 * All rights reserved.
 * Distribution of the software in any form is only allowed with
 * explicit, prior permission from the owner.
 ******************************************************************************/
package Reika.ChromatiCraft.World.Dimension.Structure.Music;

import net.minecraft.block.Block;
import net.minecraft.init.Blocks;
import net.minecraft.world.World;

import Reika.ChromatiCraft.Block.Worldgen.BlockStructureShield;
import Reika.ChromatiCraft.Block.Worldgen.BlockStructureShield.BlockType;
import Reika.ChromatiCraft.Registry.ChromaBlocks;


public class MusicFunnel {

	private final Block sh = ChromaBlocks.STRUCTSHIELD.getBlockInstance();
	private final int m1 = BlockType.CLOAK.metadata;
	private final int m2 = BlockType.STONE.metadata;

	protected void generate(World world, int x, int y, int z) {
		x -= 2;
		z -= 7;
		y -= 6;
		this.generateBlocks(world, x, y, z);
		this.generateAir(world, x, y, z);
	}

	private void generateBlocks(World world, int x, int y, int z) {

		for (int i = 0; i <= 14; i++) {
			for (int k = 0; k <= 14; k++) {
				for (int j = -5; j <= 12; j++) {
					int dx = x+i;
					int dy = y+j;
					int dz = z+k;
					Block b = world.getBlock(dx, dy, dz);
					if (j <= 0 && b == Blocks.air)
						world.setBlock(dx, dy, dz, Blocks.dirt);
					else if (j > 0 && !(b instanceof BlockStructureShield))
						world.setBlock(dx, dy, dz, Blocks.air);
				}
			}
		}

		world.setBlock(x+0, y+4, z+0, sh, m1, 3);
		world.setBlock(x+0, y+4, z+1, sh, m1, 3);
		world.setBlock(x+0, y+4, z+2, sh, m1, 3);
		world.setBlock(x+0, y+4, z+3, sh, m1, 3);
		world.setBlock(x+0, y+4, z+4, sh, m1, 3);
		world.setBlock(x+0, y+4, z+5, sh, m1, 3);
		world.setBlock(x+0, y+4, z+6, sh, m1, 3);
		world.setBlock(x+0, y+4, z+7, sh, m1, 3);
		world.setBlock(x+0, y+4, z+8, sh, m1, 3);
		world.setBlock(x+0, y+4, z+9, sh, m1, 3);
		world.setBlock(x+0, y+4, z+10, sh, m1, 3);
		world.setBlock(x+0, y+4, z+11, sh, m1, 3);
		world.setBlock(x+0, y+4, z+12, sh, m1, 3);
		world.setBlock(x+0, y+4, z+13, sh, m1, 3);
		world.setBlock(x+0, y+4, z+14, sh, m1, 3);
		world.setBlock(x+0, y+5, z+0, sh, m1, 3);
		world.setBlock(x+0, y+5, z+1, sh, m1, 3);
		world.setBlock(x+0, y+5, z+2, sh, m1, 3);
		world.setBlock(x+0, y+5, z+3, sh, m1, 3);
		world.setBlock(x+0, y+5, z+4, sh, m1, 3);
		world.setBlock(x+0, y+5, z+5, sh, m1, 3);
		world.setBlock(x+0, y+5, z+6, sh, m1, 3);
		world.setBlock(x+0, y+5, z+7, sh, m1, 3);
		world.setBlock(x+0, y+5, z+8, sh, m1, 3);
		world.setBlock(x+0, y+5, z+9, sh, m1, 3);
		world.setBlock(x+0, y+5, z+10, sh, m1, 3);
		world.setBlock(x+0, y+5, z+11, sh, m1, 3);
		world.setBlock(x+0, y+5, z+12, sh, m1, 3);
		world.setBlock(x+0, y+5, z+13, sh, m1, 3);
		world.setBlock(x+0, y+5, z+14, sh, m1, 3);
		world.setBlock(x+1, y+2, z+1, sh, m1, 3);
		world.setBlock(x+1, y+2, z+2, sh, m1, 3);
		world.setBlock(x+1, y+2, z+3, sh, m1, 3);
		world.setBlock(x+1, y+2, z+4, sh, m1, 3);
		world.setBlock(x+1, y+2, z+5, sh, m1, 3);
		world.setBlock(x+1, y+2, z+6, sh, m1, 3);
		world.setBlock(x+1, y+2, z+7, sh, m1, 3);
		world.setBlock(x+1, y+2, z+8, sh, m1, 3);
		world.setBlock(x+1, y+2, z+9, sh, m1, 3);
		world.setBlock(x+1, y+2, z+10, sh, m1, 3);
		world.setBlock(x+1, y+2, z+11, sh, m1, 3);
		world.setBlock(x+1, y+2, z+12, sh, m1, 3);
		world.setBlock(x+1, y+2, z+13, sh, m1, 3);
		world.setBlock(x+1, y+3, z+1, sh, m1, 3);
		world.setBlock(x+1, y+3, z+2, sh, m1, 3);
		world.setBlock(x+1, y+3, z+3, sh, m1, 3);
		world.setBlock(x+1, y+3, z+4, sh, m1, 3);
		world.setBlock(x+1, y+3, z+5, sh, m1, 3);
		world.setBlock(x+1, y+3, z+6, sh, m1, 3);
		world.setBlock(x+1, y+3, z+7, sh, m1, 3);
		world.setBlock(x+1, y+3, z+8, sh, m1, 3);
		world.setBlock(x+1, y+3, z+9, sh, m1, 3);
		world.setBlock(x+1, y+3, z+10, sh, m1, 3);
		world.setBlock(x+1, y+3, z+11, sh, m1, 3);
		world.setBlock(x+1, y+3, z+12, sh, m1, 3);
		world.setBlock(x+1, y+3, z+13, sh, m1, 3);
		world.setBlock(x+1, y+4, z+0, sh, m1, 3);
		world.setBlock(x+1, y+4, z+1, sh, m1, 3);
		world.setBlock(x+1, y+4, z+2, sh, m1, 3);
		world.setBlock(x+1, y+4, z+3, sh, m1, 3);
		world.setBlock(x+1, y+4, z+4, sh, m1, 3);
		world.setBlock(x+1, y+4, z+5, sh, m1, 3);
		world.setBlock(x+1, y+4, z+6, sh, m1, 3);
		world.setBlock(x+1, y+4, z+7, sh, m1, 3);
		world.setBlock(x+1, y+4, z+8, sh, m1, 3);
		world.setBlock(x+1, y+4, z+9, sh, m1, 3);
		world.setBlock(x+1, y+4, z+10, sh, m1, 3);
		world.setBlock(x+1, y+4, z+11, sh, m1, 3);
		world.setBlock(x+1, y+4, z+12, sh, m1, 3);
		world.setBlock(x+1, y+4, z+13, sh, m1, 3);
		world.setBlock(x+1, y+4, z+14, sh, m1, 3);
		world.setBlock(x+1, y+5, z+0, sh, m1, 3);
		world.setBlock(x+1, y+5, z+14, sh, m1, 3);
		world.setBlock(x+2, y+2, z+1, sh, m1, 3);
		world.setBlock(x+2, y+2, z+2, sh, m1, 3);
		world.setBlock(x+2, y+2, z+3, sh, m1, 3);
		world.setBlock(x+2, y+2, z+4, sh, m1, 3);
		world.setBlock(x+2, y+2, z+5, sh, m1, 3);
		world.setBlock(x+2, y+2, z+6, sh, m1, 3);
		world.setBlock(x+2, y+2, z+7, sh, m1, 3);
		world.setBlock(x+2, y+2, z+8, sh, m1, 3);
		world.setBlock(x+2, y+2, z+9, sh, m1, 3);
		world.setBlock(x+2, y+2, z+10, sh, m1, 3);
		world.setBlock(x+2, y+2, z+11, sh, m1, 3);
		world.setBlock(x+2, y+2, z+12, sh, m1, 3);
		world.setBlock(x+2, y+2, z+13, sh, m1, 3);
		world.setBlock(x+2, y+3, z+1, sh, m1, 3);
		world.setBlock(x+2, y+3, z+13, sh, m1, 3);
		world.setBlock(x+2, y+4, z+0, sh, m1, 3);
		world.setBlock(x+2, y+4, z+1, sh, m1, 3);
		world.setBlock(x+2, y+4, z+13, sh, m1, 3);
		world.setBlock(x+2, y+4, z+14, sh, m1, 3);
		world.setBlock(x+2, y+5, z+0, sh, m1, 3);
		world.setBlock(x+2, y+5, z+14, sh, m1, 3);
		world.setBlock(x+3, y+1, z+3, sh, m2, 3);
		world.setBlock(x+3, y+1, z+4, sh, m2, 3);
		world.setBlock(x+3, y+1, z+5, sh, m2, 3);
		world.setBlock(x+3, y+1, z+6, sh, m2, 3);
		world.setBlock(x+3, y+1, z+7, sh, m2, 3);
		world.setBlock(x+3, y+1, z+8, sh, m2, 3);
		world.setBlock(x+3, y+1, z+9, sh, m2, 3);
		world.setBlock(x+3, y+1, z+10, sh, m2, 3);
		world.setBlock(x+3, y+1, z+11, sh, m2, 3);
		world.setBlock(x+3, y+2, z+1, sh, m1, 3);
		world.setBlock(x+3, y+2, z+2, sh, m1, 3);
		world.setBlock(x+3, y+2, z+3, sh, m2, 3);
		world.setBlock(x+3, y+2, z+4, sh, m1, 3);
		world.setBlock(x+3, y+2, z+5, sh, m1, 3);
		world.setBlock(x+3, y+2, z+6, sh, m1, 3);
		world.setBlock(x+3, y+2, z+7, sh, m2, 3);
		world.setBlock(x+3, y+2, z+8, sh, m1, 3);
		world.setBlock(x+3, y+2, z+9, sh, m1, 3);
		world.setBlock(x+3, y+2, z+10, sh, m1, 3);
		world.setBlock(x+3, y+2, z+11, sh, m2, 3);
		world.setBlock(x+3, y+2, z+12, sh, m1, 3);
		world.setBlock(x+3, y+2, z+13, sh, m1, 3);
		world.setBlock(x+3, y+3, z+1, sh, m1, 3);
		world.setBlock(x+3, y+3, z+13, sh, m1, 3);
		world.setBlock(x+3, y+4, z+0, sh, m1, 3);
		world.setBlock(x+3, y+4, z+1, sh, m1, 3);
		world.setBlock(x+3, y+4, z+13, sh, m1, 3);
		world.setBlock(x+3, y+4, z+14, sh, m1, 3);
		world.setBlock(x+3, y+5, z+0, sh, m1, 3);
		world.setBlock(x+3, y+5, z+14, sh, m1, 3);
		world.setBlock(x+4, y+0, z+4, sh, m2, 3);
		world.setBlock(x+4, y+0, z+5, sh, m2, 3);
		world.setBlock(x+4, y+0, z+6, sh, m2, 3);
		world.setBlock(x+4, y+0, z+7, sh, m2, 3);
		world.setBlock(x+4, y+0, z+8, sh, m2, 3);
		world.setBlock(x+4, y+0, z+9, sh, m2, 3);
		world.setBlock(x+4, y+0, z+10, sh, m2, 3);
		world.setBlock(x+4, y+1, z+3, sh, m2, 3);
		world.setBlock(x+4, y+1, z+4, sh, m2, 3);
		world.setBlock(x+4, y+1, z+5, sh, m1, 3);
		world.setBlock(x+4, y+1, z+6, sh, m1, 3);
		world.setBlock(x+4, y+1, z+7, sh, m2, 3);
		world.setBlock(x+4, y+1, z+8, sh, m1, 3);
		world.setBlock(x+4, y+1, z+9, sh, m1, 3);
		world.setBlock(x+4, y+1, z+10, sh, m2, 3);
		world.setBlock(x+4, y+1, z+11, sh, m2, 3);
		world.setBlock(x+4, y+2, z+1, sh, m1, 3);
		world.setBlock(x+4, y+2, z+2, sh, m1, 3);
		world.setBlock(x+4, y+2, z+3, sh, m1, 3);
		world.setBlock(x+4, y+2, z+11, sh, m1, 3);
		world.setBlock(x+4, y+2, z+12, sh, m1, 3);
		world.setBlock(x+4, y+2, z+13, sh, m1, 3);
		world.setBlock(x+4, y+3, z+1, sh, m1, 3);
		world.setBlock(x+4, y+3, z+13, sh, m1, 3);
		world.setBlock(x+4, y+4, z+0, sh, m1, 3);
		world.setBlock(x+4, y+4, z+1, sh, m1, 3);
		world.setBlock(x+4, y+4, z+13, sh, m1, 3);
		world.setBlock(x+4, y+4, z+14, sh, m1, 3);
		world.setBlock(x+4, y+5, z+0, sh, m1, 3);
		world.setBlock(x+4, y+5, z+14, sh, m1, 3);
		world.setBlock(x+5, y+0, z+4, sh, m2, 3);
		world.setBlock(x+5, y+0, z+5, sh, m2, 3);
		world.setBlock(x+5, y+0, z+6, sh, m2, 3);
		world.setBlock(x+5, y+0, z+7, sh, m2, 3);
		world.setBlock(x+5, y+0, z+8, sh, m2, 3);
		world.setBlock(x+5, y+0, z+9, sh, m2, 3);
		world.setBlock(x+5, y+0, z+10, sh, m2, 3);
		world.setBlock(x+5, y+1, z+3, sh, m2, 3);
		world.setBlock(x+5, y+1, z+4, sh, m1, 3);
		world.setBlock(x+5, y+1, z+10, sh, m1, 3);
		world.setBlock(x+5, y+1, z+11, sh, m2, 3);
		world.setBlock(x+5, y+2, z+1, sh, m1, 3);
		world.setBlock(x+5, y+2, z+2, sh, m1, 3);
		world.setBlock(x+5, y+2, z+3, sh, m1, 3);
		world.setBlock(x+5, y+2, z+11, sh, m1, 3);
		world.setBlock(x+5, y+2, z+12, sh, m1, 3);
		world.setBlock(x+5, y+2, z+13, sh, m1, 3);
		world.setBlock(x+5, y+3, z+1, sh, m1, 3);
		world.setBlock(x+5, y+3, z+13, sh, m1, 3);
		world.setBlock(x+5, y+4, z+0, sh, m1, 3);
		world.setBlock(x+5, y+4, z+1, sh, m1, 3);
		world.setBlock(x+5, y+4, z+13, sh, m1, 3);
		world.setBlock(x+5, y+4, z+14, sh, m1, 3);
		world.setBlock(x+5, y+5, z+0, sh, m1, 3);
		world.setBlock(x+5, y+5, z+14, sh, m1, 3);
		world.setBlock(x+6, y+0, z+4, sh, m2, 3);
		world.setBlock(x+6, y+0, z+5, sh, m2, 3);
		world.setBlock(x+6, y+0, z+9, sh, m2, 3);
		world.setBlock(x+6, y+0, z+10, sh, m2, 3);
		world.setBlock(x+6, y+1, z+3, sh, m2, 3);
		world.setBlock(x+6, y+1, z+4, sh, m1, 3);
		world.setBlock(x+6, y+1, z+10, sh, m1, 3);
		world.setBlock(x+6, y+1, z+11, sh, m2, 3);
		world.setBlock(x+6, y+2, z+1, sh, m1, 3);
		world.setBlock(x+6, y+2, z+2, sh, m1, 3);
		world.setBlock(x+6, y+2, z+3, sh, m1, 3);
		world.setBlock(x+6, y+2, z+11, sh, m1, 3);
		world.setBlock(x+6, y+2, z+12, sh, m1, 3);
		world.setBlock(x+6, y+2, z+13, sh, m1, 3);
		world.setBlock(x+6, y+3, z+1, sh, m1, 3);
		world.setBlock(x+6, y+3, z+13, sh, m1, 3);
		world.setBlock(x+6, y+4, z+0, sh, m1, 3);
		world.setBlock(x+6, y+4, z+1, sh, m1, 3);
		world.setBlock(x+6, y+4, z+13, sh, m1, 3);
		world.setBlock(x+6, y+4, z+14, sh, m1, 3);
		world.setBlock(x+6, y+5, z+0, sh, m1, 3);
		world.setBlock(x+6, y+5, z+14, sh, m1, 3);
		world.setBlock(x+7, y+0, z+4, sh, m2, 3);
		world.setBlock(x+7, y+0, z+5, sh, m2, 3);
		world.setBlock(x+7, y+0, z+9, sh, m2, 3);
		world.setBlock(x+7, y+0, z+10, sh, m2, 3);
		world.setBlock(x+7, y+1, z+3, sh, m2, 3);
		world.setBlock(x+7, y+1, z+4, sh, m2, 3);
		world.setBlock(x+7, y+1, z+10, sh, m2, 3);
		world.setBlock(x+7, y+1, z+11, sh, m2, 3);
		world.setBlock(x+7, y+2, z+1, sh, m1, 3);
		world.setBlock(x+7, y+2, z+2, sh, m1, 3);
		world.setBlock(x+7, y+2, z+3, sh, m2, 3);
		world.setBlock(x+7, y+2, z+11, sh, m2, 3);
		world.setBlock(x+7, y+2, z+12, sh, m1, 3);
		world.setBlock(x+7, y+2, z+13, sh, m1, 3);
		world.setBlock(x+7, y+3, z+1, sh, m1, 3);
		world.setBlock(x+7, y+3, z+13, sh, m1, 3);
		world.setBlock(x+7, y+4, z+0, sh, m1, 3);
		world.setBlock(x+7, y+4, z+1, sh, m1, 3);
		world.setBlock(x+7, y+4, z+13, sh, m1, 3);
		world.setBlock(x+7, y+4, z+14, sh, m1, 3);
		world.setBlock(x+7, y+5, z+0, sh, m1, 3);
		world.setBlock(x+7, y+5, z+14, sh, m1, 3);
		world.setBlock(x+8, y+0, z+4, sh, m2, 3);
		world.setBlock(x+8, y+0, z+5, sh, m2, 3);
		world.setBlock(x+8, y+0, z+9, sh, m2, 3);
		world.setBlock(x+8, y+0, z+10, sh, m2, 3);
		world.setBlock(x+8, y+1, z+3, sh, m2, 3);
		world.setBlock(x+8, y+1, z+4, sh, m1, 3);
		world.setBlock(x+8, y+1, z+10, sh, m1, 3);
		world.setBlock(x+8, y+1, z+11, sh, m2, 3);
		world.setBlock(x+8, y+2, z+1, sh, m1, 3);
		world.setBlock(x+8, y+2, z+2, sh, m1, 3);
		world.setBlock(x+8, y+2, z+3, sh, m1, 3);
		world.setBlock(x+8, y+2, z+11, sh, m1, 3);
		world.setBlock(x+8, y+2, z+12, sh, m1, 3);
		world.setBlock(x+8, y+2, z+13, sh, m1, 3);
		world.setBlock(x+8, y+3, z+1, sh, m1, 3);
		world.setBlock(x+8, y+3, z+13, sh, m1, 3);
		world.setBlock(x+8, y+4, z+0, sh, m1, 3);
		world.setBlock(x+8, y+4, z+1, sh, m1, 3);
		world.setBlock(x+8, y+4, z+13, sh, m1, 3);
		world.setBlock(x+8, y+4, z+14, sh, m1, 3);
		world.setBlock(x+8, y+5, z+0, sh, m1, 3);
		world.setBlock(x+8, y+5, z+14, sh, m1, 3);
		world.setBlock(x+9, y+0, z+4, sh, m2, 3);
		world.setBlock(x+9, y+0, z+5, sh, m2, 3);
		world.setBlock(x+9, y+0, z+6, sh, m2, 3);
		world.setBlock(x+9, y+0, z+7, sh, m2, 3);
		world.setBlock(x+9, y+0, z+8, sh, m2, 3);
		world.setBlock(x+9, y+0, z+9, sh, m2, 3);
		world.setBlock(x+9, y+0, z+10, sh, m2, 3);
		world.setBlock(x+9, y+1, z+3, sh, m2, 3);
		world.setBlock(x+9, y+1, z+4, sh, m1, 3);
		world.setBlock(x+9, y+1, z+10, sh, m1, 3);
		world.setBlock(x+9, y+1, z+11, sh, m2, 3);
		world.setBlock(x+9, y+2, z+1, sh, m1, 3);
		world.setBlock(x+9, y+2, z+2, sh, m1, 3);
		world.setBlock(x+9, y+2, z+3, sh, m1, 3);
		world.setBlock(x+9, y+2, z+11, sh, m1, 3);
		world.setBlock(x+9, y+2, z+12, sh, m1, 3);
		world.setBlock(x+9, y+2, z+13, sh, m1, 3);
		world.setBlock(x+9, y+3, z+1, sh, m1, 3);
		world.setBlock(x+9, y+3, z+13, sh, m1, 3);
		world.setBlock(x+9, y+4, z+0, sh, m1, 3);
		world.setBlock(x+9, y+4, z+1, sh, m1, 3);
		world.setBlock(x+9, y+4, z+13, sh, m1, 3);
		world.setBlock(x+9, y+4, z+14, sh, m1, 3);
		world.setBlock(x+9, y+5, z+0, sh, m1, 3);
		world.setBlock(x+9, y+5, z+14, sh, m1, 3);
		world.setBlock(x+10, y+0, z+4, sh, m2, 3);
		world.setBlock(x+10, y+0, z+5, sh, m2, 3);
		world.setBlock(x+10, y+0, z+6, sh, m2, 3);
		world.setBlock(x+10, y+0, z+7, sh, m2, 3);
		world.setBlock(x+10, y+0, z+8, sh, m2, 3);
		world.setBlock(x+10, y+0, z+9, sh, m2, 3);
		world.setBlock(x+10, y+0, z+10, sh, m2, 3);
		world.setBlock(x+10, y+1, z+3, sh, m2, 3);
		world.setBlock(x+10, y+1, z+4, sh, m2, 3);
		world.setBlock(x+10, y+1, z+5, sh, m1, 3);
		world.setBlock(x+10, y+1, z+6, sh, m1, 3);
		world.setBlock(x+10, y+1, z+7, sh, m2, 3);
		world.setBlock(x+10, y+1, z+8, sh, m1, 3);
		world.setBlock(x+10, y+1, z+9, sh, m1, 3);
		world.setBlock(x+10, y+1, z+10, sh, m2, 3);
		world.setBlock(x+10, y+1, z+11, sh, m2, 3);
		world.setBlock(x+10, y+2, z+1, sh, m1, 3);
		world.setBlock(x+10, y+2, z+2, sh, m1, 3);
		world.setBlock(x+10, y+2, z+3, sh, m1, 3);
		world.setBlock(x+10, y+2, z+11, sh, m1, 3);
		world.setBlock(x+10, y+2, z+12, sh, m1, 3);
		world.setBlock(x+10, y+2, z+13, sh, m1, 3);
		world.setBlock(x+10, y+3, z+1, sh, m1, 3);
		world.setBlock(x+10, y+3, z+13, sh, m1, 3);
		world.setBlock(x+10, y+4, z+0, sh, m1, 3);
		world.setBlock(x+10, y+4, z+1, sh, m1, 3);
		world.setBlock(x+10, y+4, z+13, sh, m1, 3);
		world.setBlock(x+10, y+4, z+14, sh, m1, 3);
		world.setBlock(x+10, y+5, z+0, sh, m1, 3);
		world.setBlock(x+10, y+5, z+14, sh, m1, 3);
		world.setBlock(x+11, y+1, z+3, sh, m2, 3);
		world.setBlock(x+11, y+1, z+4, sh, m2, 3);
		world.setBlock(x+11, y+1, z+5, sh, m2, 3);
		world.setBlock(x+11, y+1, z+6, sh, m2, 3);
		world.setBlock(x+11, y+1, z+7, sh, m2, 3);
		world.setBlock(x+11, y+1, z+8, sh, m2, 3);
		world.setBlock(x+11, y+1, z+9, sh, m2, 3);
		world.setBlock(x+11, y+1, z+10, sh, m2, 3);
		world.setBlock(x+11, y+1, z+11, sh, m2, 3);
		world.setBlock(x+11, y+2, z+1, sh, m1, 3);
		world.setBlock(x+11, y+2, z+2, sh, m1, 3);
		world.setBlock(x+11, y+2, z+3, sh, m2, 3);
		world.setBlock(x+11, y+2, z+4, sh, m1, 3);
		world.setBlock(x+11, y+2, z+5, sh, m1, 3);
		world.setBlock(x+11, y+2, z+6, sh, m1, 3);
		world.setBlock(x+11, y+2, z+7, sh, m2, 3);
		world.setBlock(x+11, y+2, z+8, sh, m1, 3);
		world.setBlock(x+11, y+2, z+9, sh, m1, 3);
		world.setBlock(x+11, y+2, z+10, sh, m1, 3);
		world.setBlock(x+11, y+2, z+11, sh, m2, 3);
		world.setBlock(x+11, y+2, z+12, sh, m1, 3);
		world.setBlock(x+11, y+2, z+13, sh, m1, 3);
		world.setBlock(x+11, y+3, z+1, sh, m1, 3);
		world.setBlock(x+11, y+3, z+13, sh, m1, 3);
		world.setBlock(x+11, y+4, z+0, sh, m1, 3);
		world.setBlock(x+11, y+4, z+1, sh, m1, 3);
		world.setBlock(x+11, y+4, z+13, sh, m1, 3);
		world.setBlock(x+11, y+4, z+14, sh, m1, 3);
		world.setBlock(x+11, y+5, z+0, sh, m1, 3);
		world.setBlock(x+11, y+5, z+14, sh, m1, 3);
		world.setBlock(x+12, y+2, z+1, sh, m1, 3);
		world.setBlock(x+12, y+2, z+2, sh, m1, 3);
		world.setBlock(x+12, y+2, z+3, sh, m1, 3);
		world.setBlock(x+12, y+2, z+4, sh, m1, 3);
		world.setBlock(x+12, y+2, z+5, sh, m1, 3);
		world.setBlock(x+12, y+2, z+6, sh, m1, 3);
		world.setBlock(x+12, y+2, z+7, sh, m1, 3);
		world.setBlock(x+12, y+2, z+8, sh, m1, 3);
		world.setBlock(x+12, y+2, z+9, sh, m1, 3);
		world.setBlock(x+12, y+2, z+10, sh, m1, 3);
		world.setBlock(x+12, y+2, z+11, sh, m1, 3);
		world.setBlock(x+12, y+2, z+12, sh, m1, 3);
		world.setBlock(x+12, y+2, z+13, sh, m1, 3);
		world.setBlock(x+12, y+3, z+1, sh, m1, 3);
		world.setBlock(x+12, y+3, z+13, sh, m1, 3);
		world.setBlock(x+12, y+4, z+0, sh, m1, 3);
		world.setBlock(x+12, y+4, z+1, sh, m1, 3);
		world.setBlock(x+12, y+4, z+13, sh, m1, 3);
		world.setBlock(x+12, y+4, z+14, sh, m1, 3);
		world.setBlock(x+12, y+5, z+0, sh, m1, 3);
		world.setBlock(x+12, y+5, z+14, sh, m1, 3);
		world.setBlock(x+13, y+2, z+1, sh, m1, 3);
		world.setBlock(x+13, y+2, z+2, sh, m1, 3);
		world.setBlock(x+13, y+2, z+3, sh, m1, 3);
		world.setBlock(x+13, y+2, z+4, sh, m1, 3);
		world.setBlock(x+13, y+2, z+5, sh, m1, 3);
		world.setBlock(x+13, y+2, z+6, sh, m1, 3);
		world.setBlock(x+13, y+2, z+7, sh, m1, 3);
		world.setBlock(x+13, y+2, z+8, sh, m1, 3);
		world.setBlock(x+13, y+2, z+9, sh, m1, 3);
		world.setBlock(x+13, y+2, z+10, sh, m1, 3);
		world.setBlock(x+13, y+2, z+11, sh, m1, 3);
		world.setBlock(x+13, y+2, z+12, sh, m1, 3);
		world.setBlock(x+13, y+2, z+13, sh, m1, 3);
		world.setBlock(x+13, y+3, z+1, sh, m1, 3);
		world.setBlock(x+13, y+3, z+2, sh, m1, 3);
		world.setBlock(x+13, y+3, z+3, sh, m1, 3);
		world.setBlock(x+13, y+3, z+4, sh, m1, 3);
		world.setBlock(x+13, y+3, z+5, sh, m1, 3);
		world.setBlock(x+13, y+3, z+6, sh, m1, 3);
		world.setBlock(x+13, y+3, z+7, sh, m1, 3);
		world.setBlock(x+13, y+3, z+8, sh, m1, 3);
		world.setBlock(x+13, y+3, z+9, sh, m1, 3);
		world.setBlock(x+13, y+3, z+10, sh, m1, 3);
		world.setBlock(x+13, y+3, z+11, sh, m1, 3);
		world.setBlock(x+13, y+3, z+12, sh, m1, 3);
		world.setBlock(x+13, y+3, z+13, sh, m1, 3);
		world.setBlock(x+13, y+4, z+0, sh, m1, 3);
		world.setBlock(x+13, y+4, z+1, sh, m1, 3);
		world.setBlock(x+13, y+4, z+2, sh, m1, 3);
		world.setBlock(x+13, y+4, z+3, sh, m1, 3);
		world.setBlock(x+13, y+4, z+4, sh, m1, 3);
		world.setBlock(x+13, y+4, z+5, sh, m1, 3);
		world.setBlock(x+13, y+4, z+6, sh, m1, 3);
		world.setBlock(x+13, y+4, z+7, sh, m1, 3);
		world.setBlock(x+13, y+4, z+8, sh, m1, 3);
		world.setBlock(x+13, y+4, z+9, sh, m1, 3);
		world.setBlock(x+13, y+4, z+10, sh, m1, 3);
		world.setBlock(x+13, y+4, z+11, sh, m1, 3);
		world.setBlock(x+13, y+4, z+12, sh, m1, 3);
		world.setBlock(x+13, y+4, z+13, sh, m1, 3);
		world.setBlock(x+13, y+4, z+14, sh, m1, 3);
		world.setBlock(x+13, y+5, z+0, sh, m1, 3);
		world.setBlock(x+13, y+5, z+14, sh, m1, 3);
		world.setBlock(x+14, y+4, z+0, sh, m1, 3);
		world.setBlock(x+14, y+4, z+1, sh, m1, 3);
		world.setBlock(x+14, y+4, z+2, sh, m1, 3);
		world.setBlock(x+14, y+4, z+3, sh, m1, 3);
		world.setBlock(x+14, y+4, z+4, sh, m1, 3);
		world.setBlock(x+14, y+4, z+5, sh, m1, 3);
		world.setBlock(x+14, y+4, z+6, sh, m1, 3);
		world.setBlock(x+14, y+4, z+7, sh, m1, 3);
		world.setBlock(x+14, y+4, z+8, sh, m1, 3);
		world.setBlock(x+14, y+4, z+9, sh, m1, 3);
		world.setBlock(x+14, y+4, z+10, sh, m1, 3);
		world.setBlock(x+14, y+4, z+11, sh, m1, 3);
		world.setBlock(x+14, y+4, z+12, sh, m1, 3);
		world.setBlock(x+14, y+4, z+13, sh, m1, 3);
		world.setBlock(x+14, y+4, z+14, sh, m1, 3);
		world.setBlock(x+14, y+5, z+0, sh, m1, 3);
		world.setBlock(x+14, y+5, z+1, sh, m1, 3);
		world.setBlock(x+14, y+5, z+2, sh, m1, 3);
		world.setBlock(x+14, y+5, z+3, sh, m1, 3);
		world.setBlock(x+14, y+5, z+4, sh, m1, 3);
		world.setBlock(x+14, y+5, z+5, sh, m1, 3);
		world.setBlock(x+14, y+5, z+6, sh, m1, 3);
		world.setBlock(x+14, y+5, z+7, sh, m1, 3);
		world.setBlock(x+14, y+5, z+8, sh, m1, 3);
		world.setBlock(x+14, y+5, z+9, sh, m1, 3);
		world.setBlock(x+14, y+5, z+10, sh, m1, 3);
		world.setBlock(x+14, y+5, z+11, sh, m1, 3);
		world.setBlock(x+14, y+5, z+12, sh, m1, 3);
		world.setBlock(x+14, y+5, z+13, sh, m1, 3);
		world.setBlock(x+14, y+5, z+14, sh, m1, 3);
	}

	private void generateAir(World world, int x, int y, int z) {

		world.setBlock(x+1, y+5, z+1, Blocks.air);
		world.setBlock(x+1, y+5, z+2, Blocks.air);
		world.setBlock(x+1, y+5, z+3, Blocks.air);
		world.setBlock(x+1, y+5, z+4, Blocks.air);
		world.setBlock(x+1, y+5, z+5, Blocks.air);
		world.setBlock(x+1, y+5, z+6, Blocks.air);
		world.setBlock(x+1, y+5, z+7, Blocks.air);
		world.setBlock(x+1, y+5, z+8, Blocks.air);
		world.setBlock(x+1, y+5, z+9, Blocks.air);
		world.setBlock(x+1, y+5, z+10, Blocks.air);
		world.setBlock(x+1, y+5, z+11, Blocks.air);
		world.setBlock(x+1, y+5, z+12, Blocks.air);
		world.setBlock(x+1, y+5, z+13, Blocks.air);
		world.setBlock(x+2, y+3, z+2, Blocks.air);
		world.setBlock(x+2, y+3, z+3, Blocks.air);
		world.setBlock(x+2, y+3, z+4, Blocks.air);
		world.setBlock(x+2, y+3, z+5, Blocks.air);
		world.setBlock(x+2, y+3, z+6, Blocks.air);
		world.setBlock(x+2, y+3, z+7, Blocks.air);
		world.setBlock(x+2, y+3, z+8, Blocks.air);
		world.setBlock(x+2, y+3, z+9, Blocks.air);
		world.setBlock(x+2, y+3, z+10, Blocks.air);
		world.setBlock(x+2, y+3, z+11, Blocks.air);
		world.setBlock(x+2, y+3, z+12, Blocks.air);
		world.setBlock(x+2, y+4, z+2, Blocks.air);
		world.setBlock(x+2, y+4, z+3, Blocks.air);
		world.setBlock(x+2, y+4, z+4, Blocks.air);
		world.setBlock(x+2, y+4, z+5, Blocks.air);
		world.setBlock(x+2, y+4, z+6, Blocks.air);
		world.setBlock(x+2, y+4, z+7, Blocks.air);
		world.setBlock(x+2, y+4, z+8, Blocks.air);
		world.setBlock(x+2, y+4, z+9, Blocks.air);
		world.setBlock(x+2, y+4, z+10, Blocks.air);
		world.setBlock(x+2, y+4, z+11, Blocks.air);
		world.setBlock(x+2, y+4, z+12, Blocks.air);
		world.setBlock(x+2, y+5, z+1, Blocks.air);
		world.setBlock(x+2, y+5, z+2, Blocks.air);
		world.setBlock(x+2, y+5, z+3, Blocks.air);
		world.setBlock(x+2, y+5, z+4, Blocks.air);
		world.setBlock(x+2, y+5, z+5, Blocks.air);
		world.setBlock(x+2, y+5, z+6, Blocks.air);
		world.setBlock(x+2, y+5, z+7, Blocks.air);
		world.setBlock(x+2, y+5, z+8, Blocks.air);
		world.setBlock(x+2, y+5, z+9, Blocks.air);
		world.setBlock(x+2, y+5, z+10, Blocks.air);
		world.setBlock(x+2, y+5, z+11, Blocks.air);
		world.setBlock(x+2, y+5, z+12, Blocks.air);
		world.setBlock(x+2, y+5, z+13, Blocks.air);
		world.setBlock(x+3, y+3, z+2, Blocks.air);
		world.setBlock(x+3, y+3, z+3, Blocks.air);
		world.setBlock(x+3, y+3, z+4, Blocks.air);
		world.setBlock(x+3, y+3, z+5, Blocks.air);
		world.setBlock(x+3, y+3, z+6, Blocks.air);
		world.setBlock(x+3, y+3, z+7, Blocks.air);
		world.setBlock(x+3, y+3, z+8, Blocks.air);
		world.setBlock(x+3, y+3, z+9, Blocks.air);
		world.setBlock(x+3, y+3, z+10, Blocks.air);
		world.setBlock(x+3, y+3, z+11, Blocks.air);
		world.setBlock(x+3, y+3, z+12, Blocks.air);
		world.setBlock(x+3, y+4, z+2, Blocks.air);
		world.setBlock(x+3, y+4, z+3, Blocks.air);
		world.setBlock(x+3, y+4, z+4, Blocks.air);
		world.setBlock(x+3, y+4, z+5, Blocks.air);
		world.setBlock(x+3, y+4, z+6, Blocks.air);
		world.setBlock(x+3, y+4, z+7, Blocks.air);
		world.setBlock(x+3, y+4, z+8, Blocks.air);
		world.setBlock(x+3, y+4, z+9, Blocks.air);
		world.setBlock(x+3, y+4, z+10, Blocks.air);
		world.setBlock(x+3, y+4, z+11, Blocks.air);
		world.setBlock(x+3, y+4, z+12, Blocks.air);
		world.setBlock(x+3, y+5, z+1, Blocks.air);
		world.setBlock(x+3, y+5, z+2, Blocks.air);
		world.setBlock(x+3, y+5, z+3, Blocks.air);
		world.setBlock(x+3, y+5, z+4, Blocks.air);
		world.setBlock(x+3, y+5, z+5, Blocks.air);
		world.setBlock(x+3, y+5, z+6, Blocks.air);
		world.setBlock(x+3, y+5, z+7, Blocks.air);
		world.setBlock(x+3, y+5, z+8, Blocks.air);
		world.setBlock(x+3, y+5, z+9, Blocks.air);
		world.setBlock(x+3, y+5, z+10, Blocks.air);
		world.setBlock(x+3, y+5, z+11, Blocks.air);
		world.setBlock(x+3, y+5, z+12, Blocks.air);
		world.setBlock(x+3, y+5, z+13, Blocks.air);
		world.setBlock(x+4, y+2, z+4, Blocks.air);
		world.setBlock(x+4, y+2, z+5, Blocks.air);
		world.setBlock(x+4, y+2, z+6, Blocks.air);
		world.setBlock(x+4, y+2, z+7, Blocks.air);
		world.setBlock(x+4, y+2, z+8, Blocks.air);
		world.setBlock(x+4, y+2, z+9, Blocks.air);
		world.setBlock(x+4, y+2, z+10, Blocks.air);
		world.setBlock(x+4, y+3, z+2, Blocks.air);
		world.setBlock(x+4, y+3, z+3, Blocks.air);
		world.setBlock(x+4, y+3, z+4, Blocks.air);
		world.setBlock(x+4, y+3, z+5, Blocks.air);
		world.setBlock(x+4, y+3, z+6, Blocks.air);
		world.setBlock(x+4, y+3, z+7, Blocks.air);
		world.setBlock(x+4, y+3, z+8, Blocks.air);
		world.setBlock(x+4, y+3, z+9, Blocks.air);
		world.setBlock(x+4, y+3, z+10, Blocks.air);
		world.setBlock(x+4, y+3, z+11, Blocks.air);
		world.setBlock(x+4, y+3, z+12, Blocks.air);
		world.setBlock(x+4, y+4, z+2, Blocks.air);
		world.setBlock(x+4, y+4, z+3, Blocks.air);
		world.setBlock(x+4, y+4, z+4, Blocks.air);
		world.setBlock(x+4, y+4, z+5, Blocks.air);
		world.setBlock(x+4, y+4, z+6, Blocks.air);
		world.setBlock(x+4, y+4, z+7, Blocks.air);
		world.setBlock(x+4, y+4, z+8, Blocks.air);
		world.setBlock(x+4, y+4, z+9, Blocks.air);
		world.setBlock(x+4, y+4, z+10, Blocks.air);
		world.setBlock(x+4, y+4, z+11, Blocks.air);
		world.setBlock(x+4, y+4, z+12, Blocks.air);
		world.setBlock(x+4, y+5, z+1, Blocks.air);
		world.setBlock(x+4, y+5, z+2, Blocks.air);
		world.setBlock(x+4, y+5, z+3, Blocks.air);
		world.setBlock(x+4, y+5, z+4, Blocks.air);
		world.setBlock(x+4, y+5, z+5, Blocks.air);
		world.setBlock(x+4, y+5, z+6, Blocks.air);
		world.setBlock(x+4, y+5, z+7, Blocks.air);
		world.setBlock(x+4, y+5, z+8, Blocks.air);
		world.setBlock(x+4, y+5, z+9, Blocks.air);
		world.setBlock(x+4, y+5, z+10, Blocks.air);
		world.setBlock(x+4, y+5, z+11, Blocks.air);
		world.setBlock(x+4, y+5, z+12, Blocks.air);
		world.setBlock(x+4, y+5, z+13, Blocks.air);
		world.setBlock(x+5, y+1, z+5, Blocks.air);
		world.setBlock(x+5, y+1, z+6, Blocks.air);
		world.setBlock(x+5, y+1, z+7, Blocks.air);
		world.setBlock(x+5, y+1, z+8, Blocks.air);
		world.setBlock(x+5, y+1, z+9, Blocks.air);
		world.setBlock(x+5, y+2, z+4, Blocks.air);
		world.setBlock(x+5, y+2, z+5, Blocks.air);
		world.setBlock(x+5, y+2, z+6, Blocks.air);
		world.setBlock(x+5, y+2, z+7, Blocks.air);
		world.setBlock(x+5, y+2, z+8, Blocks.air);
		world.setBlock(x+5, y+2, z+9, Blocks.air);
		world.setBlock(x+5, y+2, z+10, Blocks.air);
		world.setBlock(x+5, y+3, z+2, Blocks.air);
		world.setBlock(x+5, y+3, z+3, Blocks.air);
		world.setBlock(x+5, y+3, z+4, Blocks.air);
		world.setBlock(x+5, y+3, z+5, Blocks.air);
		world.setBlock(x+5, y+3, z+6, Blocks.air);
		world.setBlock(x+5, y+3, z+7, Blocks.air);
		world.setBlock(x+5, y+3, z+8, Blocks.air);
		world.setBlock(x+5, y+3, z+9, Blocks.air);
		world.setBlock(x+5, y+3, z+10, Blocks.air);
		world.setBlock(x+5, y+3, z+11, Blocks.air);
		world.setBlock(x+5, y+3, z+12, Blocks.air);
		world.setBlock(x+5, y+4, z+2, Blocks.air);
		world.setBlock(x+5, y+4, z+3, Blocks.air);
		world.setBlock(x+5, y+4, z+4, Blocks.air);
		world.setBlock(x+5, y+4, z+5, Blocks.air);
		world.setBlock(x+5, y+4, z+6, Blocks.air);
		world.setBlock(x+5, y+4, z+7, Blocks.air);
		world.setBlock(x+5, y+4, z+8, Blocks.air);
		world.setBlock(x+5, y+4, z+9, Blocks.air);
		world.setBlock(x+5, y+4, z+10, Blocks.air);
		world.setBlock(x+5, y+4, z+11, Blocks.air);
		world.setBlock(x+5, y+4, z+12, Blocks.air);
		world.setBlock(x+5, y+5, z+1, Blocks.air);
		world.setBlock(x+5, y+5, z+2, Blocks.air);
		world.setBlock(x+5, y+5, z+3, Blocks.air);
		world.setBlock(x+5, y+5, z+4, Blocks.air);
		world.setBlock(x+5, y+5, z+5, Blocks.air);
		world.setBlock(x+5, y+5, z+6, Blocks.air);
		world.setBlock(x+5, y+5, z+7, Blocks.air);
		world.setBlock(x+5, y+5, z+8, Blocks.air);
		world.setBlock(x+5, y+5, z+9, Blocks.air);
		world.setBlock(x+5, y+5, z+10, Blocks.air);
		world.setBlock(x+5, y+5, z+11, Blocks.air);
		world.setBlock(x+5, y+5, z+12, Blocks.air);
		world.setBlock(x+5, y+5, z+13, Blocks.air);
		world.setBlock(x+6, y+0, z+6, Blocks.air);
		world.setBlock(x+6, y+0, z+7, Blocks.air);
		world.setBlock(x+6, y+0, z+8, Blocks.air);
		world.setBlock(x+6, y+1, z+5, Blocks.air);
		world.setBlock(x+6, y+1, z+6, Blocks.air);
		world.setBlock(x+6, y+1, z+7, Blocks.air);
		world.setBlock(x+6, y+1, z+8, Blocks.air);
		world.setBlock(x+6, y+1, z+9, Blocks.air);
		world.setBlock(x+6, y+2, z+4, Blocks.air);
		world.setBlock(x+6, y+2, z+5, Blocks.air);
		world.setBlock(x+6, y+2, z+6, Blocks.air);
		world.setBlock(x+6, y+2, z+7, Blocks.air);
		world.setBlock(x+6, y+2, z+8, Blocks.air);
		world.setBlock(x+6, y+2, z+9, Blocks.air);
		world.setBlock(x+6, y+2, z+10, Blocks.air);
		world.setBlock(x+6, y+3, z+2, Blocks.air);
		world.setBlock(x+6, y+3, z+3, Blocks.air);
		world.setBlock(x+6, y+3, z+4, Blocks.air);
		world.setBlock(x+6, y+3, z+5, Blocks.air);
		world.setBlock(x+6, y+3, z+6, Blocks.air);
		world.setBlock(x+6, y+3, z+7, Blocks.air);
		world.setBlock(x+6, y+3, z+8, Blocks.air);
		world.setBlock(x+6, y+3, z+9, Blocks.air);
		world.setBlock(x+6, y+3, z+10, Blocks.air);
		world.setBlock(x+6, y+3, z+11, Blocks.air);
		world.setBlock(x+6, y+3, z+12, Blocks.air);
		world.setBlock(x+6, y+4, z+2, Blocks.air);
		world.setBlock(x+6, y+4, z+3, Blocks.air);
		world.setBlock(x+6, y+4, z+4, Blocks.air);
		world.setBlock(x+6, y+4, z+5, Blocks.air);
		world.setBlock(x+6, y+4, z+6, Blocks.air);
		world.setBlock(x+6, y+4, z+7, Blocks.air);
		world.setBlock(x+6, y+4, z+8, Blocks.air);
		world.setBlock(x+6, y+4, z+9, Blocks.air);
		world.setBlock(x+6, y+4, z+10, Blocks.air);
		world.setBlock(x+6, y+4, z+11, Blocks.air);
		world.setBlock(x+6, y+4, z+12, Blocks.air);
		world.setBlock(x+6, y+5, z+1, Blocks.air);
		world.setBlock(x+6, y+5, z+2, Blocks.air);
		world.setBlock(x+6, y+5, z+3, Blocks.air);
		world.setBlock(x+6, y+5, z+4, Blocks.air);
		world.setBlock(x+6, y+5, z+5, Blocks.air);
		world.setBlock(x+6, y+5, z+6, Blocks.air);
		world.setBlock(x+6, y+5, z+7, Blocks.air);
		world.setBlock(x+6, y+5, z+8, Blocks.air);
		world.setBlock(x+6, y+5, z+9, Blocks.air);
		world.setBlock(x+6, y+5, z+10, Blocks.air);
		world.setBlock(x+6, y+5, z+11, Blocks.air);
		world.setBlock(x+6, y+5, z+12, Blocks.air);
		world.setBlock(x+6, y+5, z+13, Blocks.air);
		world.setBlock(x+7, y+0, z+6, Blocks.air);
		world.setBlock(x+7, y+0, z+7, Blocks.air);
		world.setBlock(x+7, y+0, z+8, Blocks.air);
		world.setBlock(x+7, y+1, z+5, Blocks.air);
		world.setBlock(x+7, y+1, z+6, Blocks.air);
		world.setBlock(x+7, y+1, z+7, Blocks.air);
		world.setBlock(x+7, y+1, z+8, Blocks.air);
		world.setBlock(x+7, y+1, z+9, Blocks.air);
		world.setBlock(x+7, y+2, z+4, Blocks.air);
		world.setBlock(x+7, y+2, z+5, Blocks.air);
		world.setBlock(x+7, y+2, z+6, Blocks.air);
		world.setBlock(x+7, y+2, z+7, Blocks.air);
		world.setBlock(x+7, y+2, z+8, Blocks.air);
		world.setBlock(x+7, y+2, z+9, Blocks.air);
		world.setBlock(x+7, y+2, z+10, Blocks.air);
		world.setBlock(x+7, y+3, z+2, Blocks.air);
		world.setBlock(x+7, y+3, z+3, Blocks.air);
		world.setBlock(x+7, y+3, z+4, Blocks.air);
		world.setBlock(x+7, y+3, z+5, Blocks.air);
		world.setBlock(x+7, y+3, z+6, Blocks.air);
		world.setBlock(x+7, y+3, z+7, Blocks.air);
		world.setBlock(x+7, y+3, z+8, Blocks.air);
		world.setBlock(x+7, y+3, z+9, Blocks.air);
		world.setBlock(x+7, y+3, z+10, Blocks.air);
		world.setBlock(x+7, y+3, z+11, Blocks.air);
		world.setBlock(x+7, y+3, z+12, Blocks.air);
		world.setBlock(x+7, y+4, z+2, Blocks.air);
		world.setBlock(x+7, y+4, z+3, Blocks.air);
		world.setBlock(x+7, y+4, z+4, Blocks.air);
		world.setBlock(x+7, y+4, z+5, Blocks.air);
		world.setBlock(x+7, y+4, z+6, Blocks.air);
		world.setBlock(x+7, y+4, z+7, Blocks.air);
		world.setBlock(x+7, y+4, z+8, Blocks.air);
		world.setBlock(x+7, y+4, z+9, Blocks.air);
		world.setBlock(x+7, y+4, z+10, Blocks.air);
		world.setBlock(x+7, y+4, z+11, Blocks.air);
		world.setBlock(x+7, y+4, z+12, Blocks.air);
		world.setBlock(x+7, y+5, z+1, Blocks.air);
		world.setBlock(x+7, y+5, z+2, Blocks.air);
		world.setBlock(x+7, y+5, z+3, Blocks.air);
		world.setBlock(x+7, y+5, z+4, Blocks.air);
		world.setBlock(x+7, y+5, z+5, Blocks.air);
		world.setBlock(x+7, y+5, z+6, Blocks.air);
		world.setBlock(x+7, y+5, z+7, Blocks.air);
		world.setBlock(x+7, y+5, z+8, Blocks.air);
		world.setBlock(x+7, y+5, z+9, Blocks.air);
		world.setBlock(x+7, y+5, z+10, Blocks.air);
		world.setBlock(x+7, y+5, z+11, Blocks.air);
		world.setBlock(x+7, y+5, z+12, Blocks.air);
		world.setBlock(x+7, y+5, z+13, Blocks.air);
		world.setBlock(x+8, y+0, z+6, Blocks.air);
		world.setBlock(x+8, y+0, z+7, Blocks.air);
		world.setBlock(x+8, y+0, z+8, Blocks.air);
		world.setBlock(x+8, y+1, z+5, Blocks.air);
		world.setBlock(x+8, y+1, z+6, Blocks.air);
		world.setBlock(x+8, y+1, z+7, Blocks.air);
		world.setBlock(x+8, y+1, z+8, Blocks.air);
		world.setBlock(x+8, y+1, z+9, Blocks.air);
		world.setBlock(x+8, y+2, z+4, Blocks.air);
		world.setBlock(x+8, y+2, z+5, Blocks.air);
		world.setBlock(x+8, y+2, z+6, Blocks.air);
		world.setBlock(x+8, y+2, z+7, Blocks.air);
		world.setBlock(x+8, y+2, z+8, Blocks.air);
		world.setBlock(x+8, y+2, z+9, Blocks.air);
		world.setBlock(x+8, y+2, z+10, Blocks.air);
		world.setBlock(x+8, y+3, z+2, Blocks.air);
		world.setBlock(x+8, y+3, z+3, Blocks.air);
		world.setBlock(x+8, y+3, z+4, Blocks.air);
		world.setBlock(x+8, y+3, z+5, Blocks.air);
		world.setBlock(x+8, y+3, z+6, Blocks.air);
		world.setBlock(x+8, y+3, z+7, Blocks.air);
		world.setBlock(x+8, y+3, z+8, Blocks.air);
		world.setBlock(x+8, y+3, z+9, Blocks.air);
		world.setBlock(x+8, y+3, z+10, Blocks.air);
		world.setBlock(x+8, y+3, z+11, Blocks.air);
		world.setBlock(x+8, y+3, z+12, Blocks.air);
		world.setBlock(x+8, y+4, z+2, Blocks.air);
		world.setBlock(x+8, y+4, z+3, Blocks.air);
		world.setBlock(x+8, y+4, z+4, Blocks.air);
		world.setBlock(x+8, y+4, z+5, Blocks.air);
		world.setBlock(x+8, y+4, z+6, Blocks.air);
		world.setBlock(x+8, y+4, z+7, Blocks.air);
		world.setBlock(x+8, y+4, z+8, Blocks.air);
		world.setBlock(x+8, y+4, z+9, Blocks.air);
		world.setBlock(x+8, y+4, z+10, Blocks.air);
		world.setBlock(x+8, y+4, z+11, Blocks.air);
		world.setBlock(x+8, y+4, z+12, Blocks.air);
		world.setBlock(x+8, y+5, z+1, Blocks.air);
		world.setBlock(x+8, y+5, z+2, Blocks.air);
		world.setBlock(x+8, y+5, z+3, Blocks.air);
		world.setBlock(x+8, y+5, z+4, Blocks.air);
		world.setBlock(x+8, y+5, z+5, Blocks.air);
		world.setBlock(x+8, y+5, z+6, Blocks.air);
		world.setBlock(x+8, y+5, z+7, Blocks.air);
		world.setBlock(x+8, y+5, z+8, Blocks.air);
		world.setBlock(x+8, y+5, z+9, Blocks.air);
		world.setBlock(x+8, y+5, z+10, Blocks.air);
		world.setBlock(x+8, y+5, z+11, Blocks.air);
		world.setBlock(x+8, y+5, z+12, Blocks.air);
		world.setBlock(x+8, y+5, z+13, Blocks.air);
		world.setBlock(x+9, y+1, z+5, Blocks.air);
		world.setBlock(x+9, y+1, z+6, Blocks.air);
		world.setBlock(x+9, y+1, z+7, Blocks.air);
		world.setBlock(x+9, y+1, z+8, Blocks.air);
		world.setBlock(x+9, y+1, z+9, Blocks.air);
		world.setBlock(x+9, y+2, z+4, Blocks.air);
		world.setBlock(x+9, y+2, z+5, Blocks.air);
		world.setBlock(x+9, y+2, z+6, Blocks.air);
		world.setBlock(x+9, y+2, z+7, Blocks.air);
		world.setBlock(x+9, y+2, z+8, Blocks.air);
		world.setBlock(x+9, y+2, z+9, Blocks.air);
		world.setBlock(x+9, y+2, z+10, Blocks.air);
		world.setBlock(x+9, y+3, z+2, Blocks.air);
		world.setBlock(x+9, y+3, z+3, Blocks.air);
		world.setBlock(x+9, y+3, z+4, Blocks.air);
		world.setBlock(x+9, y+3, z+5, Blocks.air);
		world.setBlock(x+9, y+3, z+6, Blocks.air);
		world.setBlock(x+9, y+3, z+7, Blocks.air);
		world.setBlock(x+9, y+3, z+8, Blocks.air);
		world.setBlock(x+9, y+3, z+9, Blocks.air);
		world.setBlock(x+9, y+3, z+10, Blocks.air);
		world.setBlock(x+9, y+3, z+11, Blocks.air);
		world.setBlock(x+9, y+3, z+12, Blocks.air);
		world.setBlock(x+9, y+4, z+2, Blocks.air);
		world.setBlock(x+9, y+4, z+3, Blocks.air);
		world.setBlock(x+9, y+4, z+4, Blocks.air);
		world.setBlock(x+9, y+4, z+5, Blocks.air);
		world.setBlock(x+9, y+4, z+6, Blocks.air);
		world.setBlock(x+9, y+4, z+7, Blocks.air);
		world.setBlock(x+9, y+4, z+8, Blocks.air);
		world.setBlock(x+9, y+4, z+9, Blocks.air);
		world.setBlock(x+9, y+4, z+10, Blocks.air);
		world.setBlock(x+9, y+4, z+11, Blocks.air);
		world.setBlock(x+9, y+4, z+12, Blocks.air);
		world.setBlock(x+9, y+5, z+1, Blocks.air);
		world.setBlock(x+9, y+5, z+2, Blocks.air);
		world.setBlock(x+9, y+5, z+3, Blocks.air);
		world.setBlock(x+9, y+5, z+4, Blocks.air);
		world.setBlock(x+9, y+5, z+5, Blocks.air);
		world.setBlock(x+9, y+5, z+6, Blocks.air);
		world.setBlock(x+9, y+5, z+7, Blocks.air);
		world.setBlock(x+9, y+5, z+8, Blocks.air);
		world.setBlock(x+9, y+5, z+9, Blocks.air);
		world.setBlock(x+9, y+5, z+10, Blocks.air);
		world.setBlock(x+9, y+5, z+11, Blocks.air);
		world.setBlock(x+9, y+5, z+12, Blocks.air);
		world.setBlock(x+9, y+5, z+13, Blocks.air);
		world.setBlock(x+10, y+2, z+4, Blocks.air);
		world.setBlock(x+10, y+2, z+5, Blocks.air);
		world.setBlock(x+10, y+2, z+6, Blocks.air);
		world.setBlock(x+10, y+2, z+7, Blocks.air);
		world.setBlock(x+10, y+2, z+8, Blocks.air);
		world.setBlock(x+10, y+2, z+9, Blocks.air);
		world.setBlock(x+10, y+2, z+10, Blocks.air);
		world.setBlock(x+10, y+3, z+2, Blocks.air);
		world.setBlock(x+10, y+3, z+3, Blocks.air);
		world.setBlock(x+10, y+3, z+4, Blocks.air);
		world.setBlock(x+10, y+3, z+5, Blocks.air);
		world.setBlock(x+10, y+3, z+6, Blocks.air);
		world.setBlock(x+10, y+3, z+7, Blocks.air);
		world.setBlock(x+10, y+3, z+8, Blocks.air);
		world.setBlock(x+10, y+3, z+9, Blocks.air);
		world.setBlock(x+10, y+3, z+10, Blocks.air);
		world.setBlock(x+10, y+3, z+11, Blocks.air);
		world.setBlock(x+10, y+3, z+12, Blocks.air);
		world.setBlock(x+10, y+4, z+2, Blocks.air);
		world.setBlock(x+10, y+4, z+3, Blocks.air);
		world.setBlock(x+10, y+4, z+4, Blocks.air);
		world.setBlock(x+10, y+4, z+5, Blocks.air);
		world.setBlock(x+10, y+4, z+6, Blocks.air);
		world.setBlock(x+10, y+4, z+7, Blocks.air);
		world.setBlock(x+10, y+4, z+8, Blocks.air);
		world.setBlock(x+10, y+4, z+9, Blocks.air);
		world.setBlock(x+10, y+4, z+10, Blocks.air);
		world.setBlock(x+10, y+4, z+11, Blocks.air);
		world.setBlock(x+10, y+4, z+12, Blocks.air);
		world.setBlock(x+10, y+5, z+1, Blocks.air);
		world.setBlock(x+10, y+5, z+2, Blocks.air);
		world.setBlock(x+10, y+5, z+3, Blocks.air);
		world.setBlock(x+10, y+5, z+4, Blocks.air);
		world.setBlock(x+10, y+5, z+5, Blocks.air);
		world.setBlock(x+10, y+5, z+6, Blocks.air);
		world.setBlock(x+10, y+5, z+7, Blocks.air);
		world.setBlock(x+10, y+5, z+8, Blocks.air);
		world.setBlock(x+10, y+5, z+9, Blocks.air);
		world.setBlock(x+10, y+5, z+10, Blocks.air);
		world.setBlock(x+10, y+5, z+11, Blocks.air);
		world.setBlock(x+10, y+5, z+12, Blocks.air);
		world.setBlock(x+10, y+5, z+13, Blocks.air);
		world.setBlock(x+11, y+3, z+2, Blocks.air);
		world.setBlock(x+11, y+3, z+3, Blocks.air);
		world.setBlock(x+11, y+3, z+4, Blocks.air);
		world.setBlock(x+11, y+3, z+5, Blocks.air);
		world.setBlock(x+11, y+3, z+6, Blocks.air);
		world.setBlock(x+11, y+3, z+7, Blocks.air);
		world.setBlock(x+11, y+3, z+8, Blocks.air);
		world.setBlock(x+11, y+3, z+9, Blocks.air);
		world.setBlock(x+11, y+3, z+10, Blocks.air);
		world.setBlock(x+11, y+3, z+11, Blocks.air);
		world.setBlock(x+11, y+3, z+12, Blocks.air);
		world.setBlock(x+11, y+4, z+2, Blocks.air);
		world.setBlock(x+11, y+4, z+3, Blocks.air);
		world.setBlock(x+11, y+4, z+4, Blocks.air);
		world.setBlock(x+11, y+4, z+5, Blocks.air);
		world.setBlock(x+11, y+4, z+6, Blocks.air);
		world.setBlock(x+11, y+4, z+7, Blocks.air);
		world.setBlock(x+11, y+4, z+8, Blocks.air);
		world.setBlock(x+11, y+4, z+9, Blocks.air);
		world.setBlock(x+11, y+4, z+10, Blocks.air);
		world.setBlock(x+11, y+4, z+11, Blocks.air);
		world.setBlock(x+11, y+4, z+12, Blocks.air);
		world.setBlock(x+11, y+5, z+1, Blocks.air);
		world.setBlock(x+11, y+5, z+2, Blocks.air);
		world.setBlock(x+11, y+5, z+3, Blocks.air);
		world.setBlock(x+11, y+5, z+4, Blocks.air);
		world.setBlock(x+11, y+5, z+5, Blocks.air);
		world.setBlock(x+11, y+5, z+6, Blocks.air);
		world.setBlock(x+11, y+5, z+7, Blocks.air);
		world.setBlock(x+11, y+5, z+8, Blocks.air);
		world.setBlock(x+11, y+5, z+9, Blocks.air);
		world.setBlock(x+11, y+5, z+10, Blocks.air);
		world.setBlock(x+11, y+5, z+11, Blocks.air);
		world.setBlock(x+11, y+5, z+12, Blocks.air);
		world.setBlock(x+11, y+5, z+13, Blocks.air);
		world.setBlock(x+12, y+3, z+2, Blocks.air);
		world.setBlock(x+12, y+3, z+3, Blocks.air);
		world.setBlock(x+12, y+3, z+4, Blocks.air);
		world.setBlock(x+12, y+3, z+5, Blocks.air);
		world.setBlock(x+12, y+3, z+6, Blocks.air);
		world.setBlock(x+12, y+3, z+7, Blocks.air);
		world.setBlock(x+12, y+3, z+8, Blocks.air);
		world.setBlock(x+12, y+3, z+9, Blocks.air);
		world.setBlock(x+12, y+3, z+10, Blocks.air);
		world.setBlock(x+12, y+3, z+11, Blocks.air);
		world.setBlock(x+12, y+3, z+12, Blocks.air);
		world.setBlock(x+12, y+4, z+2, Blocks.air);
		world.setBlock(x+12, y+4, z+3, Blocks.air);
		world.setBlock(x+12, y+4, z+4, Blocks.air);
		world.setBlock(x+12, y+4, z+5, Blocks.air);
		world.setBlock(x+12, y+4, z+6, Blocks.air);
		world.setBlock(x+12, y+4, z+7, Blocks.air);
		world.setBlock(x+12, y+4, z+8, Blocks.air);
		world.setBlock(x+12, y+4, z+9, Blocks.air);
		world.setBlock(x+12, y+4, z+10, Blocks.air);
		world.setBlock(x+12, y+4, z+11, Blocks.air);
		world.setBlock(x+12, y+4, z+12, Blocks.air);
		world.setBlock(x+12, y+5, z+1, Blocks.air);
		world.setBlock(x+12, y+5, z+2, Blocks.air);
		world.setBlock(x+12, y+5, z+3, Blocks.air);
		world.setBlock(x+12, y+5, z+4, Blocks.air);
		world.setBlock(x+12, y+5, z+5, Blocks.air);
		world.setBlock(x+12, y+5, z+6, Blocks.air);
		world.setBlock(x+12, y+5, z+7, Blocks.air);
		world.setBlock(x+12, y+5, z+8, Blocks.air);
		world.setBlock(x+12, y+5, z+9, Blocks.air);
		world.setBlock(x+12, y+5, z+10, Blocks.air);
		world.setBlock(x+12, y+5, z+11, Blocks.air);
		world.setBlock(x+12, y+5, z+12, Blocks.air);
		world.setBlock(x+12, y+5, z+13, Blocks.air);
		world.setBlock(x+13, y+5, z+1, Blocks.air);
		world.setBlock(x+13, y+5, z+2, Blocks.air);
		world.setBlock(x+13, y+5, z+3, Blocks.air);
		world.setBlock(x+13, y+5, z+4, Blocks.air);
		world.setBlock(x+13, y+5, z+5, Blocks.air);
		world.setBlock(x+13, y+5, z+6, Blocks.air);
		world.setBlock(x+13, y+5, z+7, Blocks.air);
		world.setBlock(x+13, y+5, z+8, Blocks.air);
		world.setBlock(x+13, y+5, z+9, Blocks.air);
		world.setBlock(x+13, y+5, z+10, Blocks.air);
		world.setBlock(x+13, y+5, z+11, Blocks.air);
		world.setBlock(x+13, y+5, z+12, Blocks.air);
		world.setBlock(x+13, y+5, z+13, Blocks.air);
	}

}
