/*******************************************************************************
 * @author Reika Kalseki
 * 
 * Copyright 2017
 * 
 * All rights reserved.
 * Distribution of the software in any form is only allowed with
 * explicit, prior permission from the owner.
 ******************************************************************************/
package Reika.ChromatiCraft.World.Dimension.Structure.Music;

import net.minecraft.block.Block;
import net.minecraft.init.Blocks;

import Reika.ChromatiCraft.Block.Worldgen.BlockStructureShield.BlockType;
import Reika.ChromatiCraft.Registry.ChromaBlocks;
import Reika.DragonAPI.Instantiable.Worldgen.ChunkSplicedGenerationCache;


public class MusicPuzzleBlocks {

	private final Block cry = ChromaBlocks.LAMP.getBlockInstance();

	private final Block sh = ChromaBlocks.STRUCTSHIELD.getBlockInstance();
	private final int meta = BlockType.STONE.metadata;

	protected MusicPuzzleBlocks() {

	}

	protected void generate(ChunkSplicedGenerationCache world, int x, int y, int z) {

		world.setBlock(x+9, y+2, z+6, cry, 0);
		world.setBlock(x+9, y+2, z+7, cry, 1);
		world.setBlock(x+9, y+2, z+8, cry, 2);
		world.setBlock(x+9, y+2, z+9, cry, 3);
		world.setBlock(x+9, y+2, z+10, cry, 4);
		world.setBlock(x+9, y+2, z+11, cry, 5);
		world.setBlock(x+9, y+2, z+12, cry, 6);
		world.setBlock(x+9, y+2, z+13, cry, 7);
		world.setBlock(x+1, y+2, z+6, cry, 8);
		world.setBlock(x+1, y+2, z+7, cry, 9);
		world.setBlock(x+1, y+2, z+8, cry, 10);
		world.setBlock(x+1, y+2, z+9, cry, 11);
		world.setBlock(x+1, y+2, z+10, cry, 12);
		world.setBlock(x+1, y+2, z+11, cry, 13);
		world.setBlock(x+1, y+2, z+12, cry, 14);
		world.setBlock(x+1, y+2, z+13, cry, 15);

		world.setBlock(x+5, y+6, z+9, sh, BlockType.LIGHT.metadata);
		world.setBlock(x+5, y+0, z+14, sh, BlockType.LIGHT.metadata);
		world.setBlock(x+5, y+0, z+3, sh, BlockType.LIGHT.metadata);

		world.setBlock(x+0, y+1, z+5, sh, meta);
		world.setBlock(x+0, y+1, z+6, sh, meta);
		world.setBlock(x+0, y+1, z+7, sh, meta);
		world.setBlock(x+0, y+1, z+8, sh, meta);
		world.setBlock(x+0, y+1, z+9, sh, meta);
		world.setBlock(x+0, y+1, z+10, sh, meta);
		world.setBlock(x+0, y+1, z+11, sh, meta);
		world.setBlock(x+0, y+1, z+12, sh, meta);
		world.setBlock(x+0, y+1, z+13, sh, meta);
		world.setBlock(x+0, y+1, z+14, sh, meta);
		world.setBlock(x+0, y+2, z+5, sh, meta);
		world.setBlock(x+0, y+2, z+6, sh, meta);
		world.setBlock(x+0, y+2, z+7, sh, meta);
		world.setBlock(x+0, y+2, z+8, sh, meta);
		world.setBlock(x+0, y+2, z+9, sh, meta);
		world.setBlock(x+0, y+2, z+10, sh, meta);
		world.setBlock(x+0, y+2, z+11, sh, meta);
		world.setBlock(x+0, y+2, z+12, sh, meta);
		world.setBlock(x+0, y+2, z+13, sh, meta);
		world.setBlock(x+0, y+2, z+14, sh, meta);
		world.setBlock(x+0, y+3, z+5, sh, meta);
		world.setBlock(x+0, y+3, z+6, sh, meta);
		world.setBlock(x+0, y+3, z+7, sh, meta);
		world.setBlock(x+0, y+3, z+8, sh, meta);
		world.setBlock(x+0, y+3, z+9, sh, meta);
		world.setBlock(x+0, y+3, z+10, sh, meta);
		world.setBlock(x+0, y+3, z+11, sh, meta);
		world.setBlock(x+0, y+3, z+12, sh, meta);
		world.setBlock(x+0, y+3, z+13, sh, meta);
		world.setBlock(x+0, y+3, z+14, sh, meta);
		world.setBlock(x+0, y+4, z+5, sh, meta);
		world.setBlock(x+0, y+4, z+6, sh, meta);
		world.setBlock(x+0, y+4, z+7, sh, meta);
		world.setBlock(x+0, y+4, z+8, sh, meta);
		world.setBlock(x+0, y+4, z+9, sh, meta);
		world.setBlock(x+0, y+4, z+10, sh, meta);
		world.setBlock(x+0, y+4, z+11, sh, meta);
		world.setBlock(x+0, y+4, z+12, sh, meta);
		world.setBlock(x+0, y+4, z+13, sh, meta);
		world.setBlock(x+0, y+4, z+14, sh, meta);
		world.setBlock(x+1, y+0, z+3, sh, meta);
		world.setBlock(x+1, y+0, z+4, sh, meta);
		world.setBlock(x+1, y+0, z+5, sh, meta);
		world.setBlock(x+1, y+0, z+6, sh, meta);
		world.setBlock(x+1, y+0, z+7, sh, meta);
		world.setBlock(x+1, y+0, z+8, sh, meta);
		world.setBlock(x+1, y+0, z+9, sh, meta);
		world.setBlock(x+1, y+0, z+10, sh, meta);
		world.setBlock(x+1, y+0, z+11, sh, meta);
		world.setBlock(x+1, y+0, z+12, sh, meta);
		world.setBlock(x+1, y+0, z+13, sh, meta);
		world.setBlock(x+1, y+0, z+14, sh, meta);
		world.setBlock(x+1, y+0, z+15, sh, meta);
		world.setBlock(x+1, y+1, z+3, sh, meta);
		world.setBlock(x+1, y+1, z+4, sh, meta);
		world.setBlock(x+1, y+1, z+5, sh, meta);
		world.setBlock(x+1, y+1, z+14, sh, meta);
		world.setBlock(x+1, y+1, z+15, sh, meta);
		world.setBlock(x+1, y+2, z+3, sh, meta);
		world.setBlock(x+1, y+2, z+4, sh, meta);
		world.setBlock(x+1, y+2, z+5, sh, meta);
		world.setBlock(x+1, y+2, z+14, sh, meta);
		world.setBlock(x+1, y+2, z+15, sh, meta);
		world.setBlock(x+1, y+3, z+3, sh, meta);
		world.setBlock(x+1, y+3, z+4, sh, meta);
		world.setBlock(x+1, y+3, z+5, sh, meta);
		world.setBlock(x+1, y+3, z+14, sh, meta);
		world.setBlock(x+1, y+3, z+15, sh, meta);
		world.setBlock(x+1, y+4, z+3, sh, meta);
		world.setBlock(x+1, y+4, z+4, sh, meta);
		world.setBlock(x+1, y+4, z+5, sh, meta);
		world.setBlock(x+1, y+4, z+6, sh, meta);
		world.setBlock(x+1, y+4, z+7, sh, meta);
		world.setBlock(x+1, y+4, z+8, sh, meta);
		world.setBlock(x+1, y+4, z+9, sh, meta);
		world.setBlock(x+1, y+4, z+10, sh, meta);
		world.setBlock(x+1, y+4, z+11, sh, meta);
		world.setBlock(x+1, y+4, z+12, sh, meta);
		world.setBlock(x+1, y+4, z+13, sh, meta);
		world.setBlock(x+1, y+4, z+14, sh, meta);
		world.setBlock(x+1, y+4, z+15, sh, meta);
		world.setBlock(x+1, y+5, z+3, sh, meta);
		world.setBlock(x+1, y+5, z+4, sh, meta);
		world.setBlock(x+1, y+5, z+5, sh, meta);
		world.setBlock(x+1, y+5, z+6, sh, meta);
		world.setBlock(x+1, y+5, z+7, sh, meta);
		world.setBlock(x+1, y+5, z+8, sh, meta);
		world.setBlock(x+1, y+5, z+9, sh, meta);
		world.setBlock(x+1, y+5, z+10, sh, meta);
		world.setBlock(x+1, y+5, z+11, sh, meta);
		world.setBlock(x+1, y+5, z+12, sh, meta);
		world.setBlock(x+1, y+5, z+13, sh, meta);
		world.setBlock(x+1, y+5, z+14, sh, meta);
		world.setBlock(x+1, y+5, z+15, sh, meta);
		world.setBlock(x+2, y+0, z+1, sh, meta);
		world.setBlock(x+2, y+0, z+2, sh, meta);
		world.setBlock(x+2, y+0, z+3, sh, meta);
		world.setBlock(x+2, y+0, z+4, sh, meta);
		world.setBlock(x+2, y+0, z+5, sh, meta);
		world.setBlock(x+2, y+0, z+6, sh, meta);
		world.setBlock(x+2, y+0, z+7, sh, meta);
		world.setBlock(x+2, y+0, z+8, sh, meta);
		world.setBlock(x+2, y+0, z+9, sh, meta);
		world.setBlock(x+2, y+0, z+10, sh, meta);
		world.setBlock(x+2, y+0, z+11, sh, meta);
		world.setBlock(x+2, y+0, z+12, sh, meta);
		world.setBlock(x+2, y+0, z+13, sh, meta);
		world.setBlock(x+2, y+0, z+14, sh, meta);
		world.setBlock(x+2, y+0, z+15, sh, meta);
		world.setBlock(x+2, y+0, z+16, sh, meta);
		world.setBlock(x+2, y+1, z+1, sh, meta);
		world.setBlock(x+2, y+1, z+2, sh, meta);
		world.setBlock(x+2, y+1, z+3, sh, meta);
		world.setBlock(x+2, y+1, z+15, sh, meta);
		world.setBlock(x+2, y+1, z+16, sh, meta);
		world.setBlock(x+2, y+2, z+1, sh, meta);
		world.setBlock(x+2, y+2, z+2, sh, meta);
		world.setBlock(x+2, y+2, z+3, sh, meta);
		world.setBlock(x+2, y+2, z+15, sh, meta);
		world.setBlock(x+2, y+2, z+16, sh, meta);
		world.setBlock(x+2, y+3, z+1, sh, meta);
		world.setBlock(x+2, y+3, z+2, sh, meta);
		world.setBlock(x+2, y+3, z+3, sh, meta);
		world.setBlock(x+2, y+3, z+15, sh, meta);
		world.setBlock(x+2, y+3, z+16, sh, meta);
		world.setBlock(x+2, y+4, z+1, sh, meta);
		world.setBlock(x+2, y+4, z+2, sh, meta);
		world.setBlock(x+2, y+4, z+3, sh, meta);
		world.setBlock(x+2, y+4, z+15, sh, meta);
		world.setBlock(x+2, y+4, z+16, sh, meta);
		world.setBlock(x+2, y+5, z+1, sh, meta);
		world.setBlock(x+2, y+5, z+2, sh, meta);
		world.setBlock(x+2, y+5, z+3, sh, meta);
		world.setBlock(x+2, y+5, z+4, sh, meta);
		world.setBlock(x+2, y+5, z+5, sh, meta);
		world.setBlock(x+2, y+5, z+6, sh, meta);
		world.setBlock(x+2, y+5, z+7, sh, meta);
		world.setBlock(x+2, y+5, z+8, sh, meta);
		world.setBlock(x+2, y+5, z+9, sh, meta);
		world.setBlock(x+2, y+5, z+10, sh, meta);
		world.setBlock(x+2, y+5, z+11, sh, meta);
		world.setBlock(x+2, y+5, z+12, sh, meta);
		world.setBlock(x+2, y+5, z+13, sh, meta);
		world.setBlock(x+2, y+5, z+14, sh, meta);
		world.setBlock(x+2, y+5, z+15, sh, meta);
		world.setBlock(x+2, y+5, z+16, sh, meta);
		world.setBlock(x+3, y+0, z+0, sh, meta);
		world.setBlock(x+3, y+0, z+1, sh, meta);
		world.setBlock(x+3, y+0, z+2, sh, meta);
		world.setBlock(x+3, y+0, z+3, sh, meta);
		world.setBlock(x+3, y+0, z+4, sh, meta);
		world.setBlock(x+3, y+0, z+5, sh, meta);
		world.setBlock(x+3, y+0, z+6, sh, meta);
		world.setBlock(x+3, y+0, z+7, sh, meta);
		world.setBlock(x+3, y+0, z+8, sh, meta);
		world.setBlock(x+3, y+0, z+9, sh, meta);
		world.setBlock(x+3, y+0, z+10, sh, meta);
		world.setBlock(x+3, y+0, z+11, sh, meta);
		world.setBlock(x+3, y+0, z+12, sh, meta);
		world.setBlock(x+3, y+0, z+13, sh, meta);
		world.setBlock(x+3, y+0, z+14, sh, meta);
		world.setBlock(x+3, y+0, z+15, sh, meta);
		world.setBlock(x+3, y+0, z+16, sh, meta);
		world.setBlock(x+3, y+0, z+17, sh, meta);
		world.setBlock(x+3, y+0, z+18, sh, meta);
		world.setBlock(x+3, y+0, z+19, sh, meta);
		world.setBlock(x+3, y+1, z+0, sh, meta);
		world.setBlock(x+3, y+1, z+1, sh, meta);
		world.setBlock(x+3, y+1, z+16, sh, meta);
		world.setBlock(x+3, y+1, z+17, sh, meta);
		world.setBlock(x+3, y+1, z+18, sh, meta);
		world.setBlock(x+3, y+1, z+19, sh, meta);
		world.setBlock(x+3, y+2, z+0, sh, meta);
		world.setBlock(x+3, y+2, z+1, sh, meta);
		world.setBlock(x+3, y+2, z+16, sh, meta);
		world.setBlock(x+3, y+2, z+17, sh, meta);
		world.setBlock(x+3, y+2, z+18, sh, meta);
		world.setBlock(x+3, y+2, z+19, sh, meta);
		world.setBlock(x+3, y+3, z+0, sh, meta);
		world.setBlock(x+3, y+3, z+1, sh, meta);
		world.setBlock(x+3, y+3, z+16, sh, meta);
		world.setBlock(x+3, y+3, z+17, sh, meta);
		world.setBlock(x+3, y+3, z+18, sh, meta);
		world.setBlock(x+3, y+3, z+19, sh, meta);
		world.setBlock(x+3, y+4, z+0, sh, meta);
		world.setBlock(x+3, y+4, z+1, sh, meta);
		world.setBlock(x+3, y+4, z+16, sh, meta);
		world.setBlock(x+3, y+4, z+17, sh, meta);
		world.setBlock(x+3, y+4, z+18, sh, meta);
		world.setBlock(x+3, y+4, z+19, sh, meta);
		world.setBlock(x+3, y+5, z+1, sh, meta);
		world.setBlock(x+3, y+5, z+2, sh, meta);
		world.setBlock(x+3, y+5, z+3, sh, meta);
		world.setBlock(x+3, y+5, z+4, sh, meta);
		world.setBlock(x+3, y+5, z+5, sh, meta);
		world.setBlock(x+3, y+5, z+6, sh, meta);
		world.setBlock(x+3, y+5, z+7, sh, meta);
		world.setBlock(x+3, y+5, z+8, sh, meta);
		world.setBlock(x+3, y+5, z+9, sh, meta);
		world.setBlock(x+3, y+5, z+10, sh, meta);
		world.setBlock(x+3, y+5, z+11, sh, meta);
		world.setBlock(x+3, y+5, z+12, sh, meta);
		world.setBlock(x+3, y+5, z+13, sh, meta);
		world.setBlock(x+3, y+5, z+14, sh, meta);
		world.setBlock(x+3, y+5, z+15, sh, meta);
		world.setBlock(x+3, y+5, z+16, sh, meta);
		world.setBlock(x+3, y+6, z+5, sh, meta);
		world.setBlock(x+3, y+6, z+6, sh, meta);
		world.setBlock(x+3, y+6, z+7, sh, meta);
		world.setBlock(x+3, y+6, z+8, sh, meta);
		world.setBlock(x+3, y+6, z+9, sh, meta);
		world.setBlock(x+3, y+6, z+10, sh, meta);
		world.setBlock(x+3, y+6, z+11, sh, meta);
		world.setBlock(x+3, y+6, z+12, sh, meta);
		world.setBlock(x+3, y+6, z+13, sh, meta);
		world.setBlock(x+3, y+6, z+14, sh, meta);
		world.setBlock(x+4, y+0, z+0, sh, meta);
		world.setBlock(x+4, y+0, z+1, sh, meta);
		world.setBlock(x+4, y+0, z+2, sh, meta);
		world.setBlock(x+4, y+0, z+3, sh, meta);
		world.setBlock(x+4, y+0, z+4, sh, meta);
		world.setBlock(x+4, y+0, z+5, sh, meta);
		world.setBlock(x+4, y+0, z+6, sh, meta);
		world.setBlock(x+4, y+0, z+7, sh, meta);
		world.setBlock(x+4, y+0, z+8, sh, meta);
		world.setBlock(x+4, y+0, z+9, sh, meta);
		world.setBlock(x+4, y+0, z+10, sh, meta);
		world.setBlock(x+4, y+0, z+11, sh, meta);
		world.setBlock(x+4, y+0, z+12, sh, meta);
		world.setBlock(x+4, y+0, z+13, sh, meta);
		world.setBlock(x+4, y+0, z+14, sh, meta);
		world.setBlock(x+4, y+0, z+15, sh, meta);
		world.setBlock(x+4, y+0, z+16, sh, meta);
		world.setBlock(x+4, y+0, z+17, sh, meta);
		world.setBlock(x+4, y+0, z+18, sh, meta);
		world.setBlock(x+4, y+0, z+19, sh, meta);
		world.setBlock(x+4, y+4, z+0, sh, meta);
		world.setBlock(x+4, y+4, z+1, sh, meta);
		world.setBlock(x+4, y+4, z+16, sh, meta);
		world.setBlock(x+4, y+4, z+17, sh, meta);
		world.setBlock(x+4, y+4, z+18, sh, meta);
		world.setBlock(x+4, y+4, z+19, sh, meta);
		world.setBlock(x+4, y+5, z+1, sh, meta);
		world.setBlock(x+4, y+5, z+2, sh, meta);
		world.setBlock(x+4, y+5, z+3, sh, meta);
		world.setBlock(x+4, y+5, z+4, sh, meta);
		world.setBlock(x+4, y+5, z+5, sh, meta);
		world.setBlock(x+4, y+5, z+14, sh, meta);
		world.setBlock(x+4, y+5, z+15, sh, meta);
		world.setBlock(x+4, y+5, z+16, sh, meta);
		world.setBlock(x+4, y+6, z+5, sh, meta);
		world.setBlock(x+4, y+6, z+6, sh, meta);
		world.setBlock(x+4, y+6, z+7, sh, meta);
		world.setBlock(x+4, y+6, z+8, sh, meta);
		world.setBlock(x+4, y+6, z+9, sh, meta);
		world.setBlock(x+4, y+6, z+10, sh, meta);
		world.setBlock(x+4, y+6, z+11, sh, meta);
		world.setBlock(x+4, y+6, z+12, sh, meta);
		world.setBlock(x+4, y+6, z+13, sh, meta);
		world.setBlock(x+4, y+6, z+14, sh, meta);
		world.setBlock(x+5, y+0, z+0, sh, meta);
		world.setBlock(x+5, y+0, z+1, sh, meta);
		world.setBlock(x+5, y+0, z+2, sh, meta);
		world.setBlock(x+5, y+0, z+4, sh, meta);
		world.setBlock(x+5, y+0, z+5, sh, meta);
		world.setBlock(x+5, y+0, z+6, sh, meta);
		world.setBlock(x+5, y+0, z+7, sh, meta);
		world.setBlock(x+5, y+0, z+8, sh, meta);
		world.setBlock(x+5, y+0, z+9, sh, meta);
		world.setBlock(x+5, y+0, z+10, sh, meta);
		world.setBlock(x+5, y+0, z+11, sh, meta);
		world.setBlock(x+5, y+0, z+12, sh, meta);
		world.setBlock(x+5, y+0, z+13, sh, meta);
		world.setBlock(x+5, y+0, z+15, sh, meta);
		world.setBlock(x+5, y+0, z+16, sh, meta);
		world.setBlock(x+5, y+0, z+17, sh, meta);
		world.setBlock(x+5, y+0, z+18, sh, meta);
		world.setBlock(x+5, y+0, z+19, sh, meta);
		world.setBlock(x+5, y+4, z+0, sh, meta);
		world.setBlock(x+5, y+4, z+1, sh, meta);
		world.setBlock(x+5, y+4, z+16, sh, meta);
		world.setBlock(x+5, y+4, z+17, sh, meta);
		world.setBlock(x+5, y+4, z+18, sh, meta);
		world.setBlock(x+5, y+4, z+19, sh, meta);
		world.setBlock(x+5, y+5, z+1, sh, meta);
		world.setBlock(x+5, y+5, z+2, sh, meta);
		world.setBlock(x+5, y+5, z+3, sh, meta);
		world.setBlock(x+5, y+5, z+4, sh, meta);
		world.setBlock(x+5, y+5, z+5, sh, meta);
		world.setBlock(x+5, y+5, z+14, sh, meta);
		world.setBlock(x+5, y+5, z+15, sh, meta);
		world.setBlock(x+5, y+5, z+16, sh, meta);
		world.setBlock(x+5, y+6, z+5, sh, meta);
		world.setBlock(x+5, y+6, z+6, sh, meta);
		world.setBlock(x+5, y+6, z+7, sh, meta);
		world.setBlock(x+5, y+6, z+8, sh, meta);
		world.setBlock(x+5, y+6, z+10, sh, meta);
		world.setBlock(x+5, y+6, z+11, sh, meta);
		world.setBlock(x+5, y+6, z+12, sh, meta);
		world.setBlock(x+5, y+6, z+13, sh, meta);
		world.setBlock(x+5, y+6, z+14, sh, meta);
		world.setBlock(x+6, y+0, z+0, sh, meta);
		world.setBlock(x+6, y+0, z+1, sh, meta);
		world.setBlock(x+6, y+0, z+2, sh, meta);
		world.setBlock(x+6, y+0, z+3, sh, meta);
		world.setBlock(x+6, y+0, z+4, sh, meta);
		world.setBlock(x+6, y+0, z+5, sh, meta);
		world.setBlock(x+6, y+0, z+6, sh, meta);
		world.setBlock(x+6, y+0, z+7, sh, meta);
		world.setBlock(x+6, y+0, z+8, sh, meta);
		world.setBlock(x+6, y+0, z+9, sh, meta);
		world.setBlock(x+6, y+0, z+10, sh, meta);
		world.setBlock(x+6, y+0, z+11, sh, meta);
		world.setBlock(x+6, y+0, z+12, sh, meta);
		world.setBlock(x+6, y+0, z+13, sh, meta);
		world.setBlock(x+6, y+0, z+14, sh, meta);
		world.setBlock(x+6, y+0, z+15, sh, meta);
		world.setBlock(x+6, y+0, z+16, sh, meta);
		world.setBlock(x+6, y+0, z+17, sh, meta);
		world.setBlock(x+6, y+0, z+18, sh, meta);
		world.setBlock(x+6, y+0, z+19, sh, meta);
		world.setBlock(x+6, y+4, z+0, sh, meta);
		world.setBlock(x+6, y+4, z+1, sh, meta);
		world.setBlock(x+6, y+4, z+16, sh, meta);
		world.setBlock(x+6, y+4, z+17, sh, meta);
		world.setBlock(x+6, y+4, z+18, sh, meta);
		world.setBlock(x+6, y+4, z+19, sh, meta);
		world.setBlock(x+6, y+5, z+1, sh, meta);
		world.setBlock(x+6, y+5, z+2, sh, meta);
		world.setBlock(x+6, y+5, z+3, sh, meta);
		world.setBlock(x+6, y+5, z+4, sh, meta);
		world.setBlock(x+6, y+5, z+5, sh, meta);
		world.setBlock(x+6, y+5, z+14, sh, meta);
		world.setBlock(x+6, y+5, z+15, sh, meta);
		world.setBlock(x+6, y+5, z+16, sh, meta);
		world.setBlock(x+6, y+6, z+5, sh, meta);
		world.setBlock(x+6, y+6, z+6, sh, meta);
		world.setBlock(x+6, y+6, z+7, sh, meta);
		world.setBlock(x+6, y+6, z+8, sh, meta);
		world.setBlock(x+6, y+6, z+9, sh, meta);
		world.setBlock(x+6, y+6, z+10, sh, meta);
		world.setBlock(x+6, y+6, z+11, sh, meta);
		world.setBlock(x+6, y+6, z+12, sh, meta);
		world.setBlock(x+6, y+6, z+13, sh, meta);
		world.setBlock(x+6, y+6, z+14, sh, meta);
		world.setBlock(x+7, y+0, z+0, sh, meta);
		world.setBlock(x+7, y+0, z+1, sh, meta);
		world.setBlock(x+7, y+0, z+2, sh, meta);
		world.setBlock(x+7, y+0, z+3, sh, meta);
		world.setBlock(x+7, y+0, z+4, sh, meta);
		world.setBlock(x+7, y+0, z+5, sh, meta);
		world.setBlock(x+7, y+0, z+6, sh, meta);
		world.setBlock(x+7, y+0, z+7, sh, meta);
		world.setBlock(x+7, y+0, z+8, sh, meta);
		world.setBlock(x+7, y+0, z+9, sh, meta);
		world.setBlock(x+7, y+0, z+10, sh, meta);
		world.setBlock(x+7, y+0, z+11, sh, meta);
		world.setBlock(x+7, y+0, z+12, sh, meta);
		world.setBlock(x+7, y+0, z+13, sh, meta);
		world.setBlock(x+7, y+0, z+14, sh, meta);
		world.setBlock(x+7, y+0, z+15, sh, meta);
		world.setBlock(x+7, y+0, z+16, sh, meta);
		world.setBlock(x+7, y+0, z+17, sh, meta);
		world.setBlock(x+7, y+0, z+18, sh, meta);
		world.setBlock(x+7, y+0, z+19, sh, meta);
		world.setBlock(x+7, y+1, z+0, sh, meta);
		world.setBlock(x+7, y+1, z+1, sh, meta);
		world.setBlock(x+7, y+1, z+16, sh, meta);
		world.setBlock(x+7, y+1, z+17, sh, meta);
		world.setBlock(x+7, y+1, z+18, sh, meta);
		world.setBlock(x+7, y+1, z+19, sh, meta);
		world.setBlock(x+7, y+2, z+0, sh, meta);
		world.setBlock(x+7, y+2, z+1, sh, meta);
		world.setBlock(x+7, y+2, z+16, sh, meta);
		world.setBlock(x+7, y+2, z+17, sh, meta);
		world.setBlock(x+7, y+2, z+18, sh, meta);
		world.setBlock(x+7, y+2, z+19, sh, meta);
		world.setBlock(x+7, y+3, z+0, sh, meta);
		world.setBlock(x+7, y+3, z+1, sh, meta);
		world.setBlock(x+7, y+3, z+16, sh, meta);
		world.setBlock(x+7, y+3, z+17, sh, meta);
		world.setBlock(x+7, y+3, z+18, sh, meta);
		world.setBlock(x+7, y+3, z+19, sh, meta);
		world.setBlock(x+7, y+4, z+0, sh, meta);
		world.setBlock(x+7, y+4, z+1, sh, meta);
		world.setBlock(x+7, y+4, z+16, sh, meta);
		world.setBlock(x+7, y+4, z+17, sh, meta);
		world.setBlock(x+7, y+4, z+18, sh, meta);
		world.setBlock(x+7, y+4, z+19, sh, meta);
		world.setBlock(x+7, y+5, z+1, sh, meta);
		world.setBlock(x+7, y+5, z+2, sh, meta);
		world.setBlock(x+7, y+5, z+3, sh, meta);
		world.setBlock(x+7, y+5, z+4, sh, meta);
		world.setBlock(x+7, y+5, z+5, sh, meta);
		world.setBlock(x+7, y+5, z+6, sh, meta);
		world.setBlock(x+7, y+5, z+7, sh, meta);
		world.setBlock(x+7, y+5, z+8, sh, meta);
		world.setBlock(x+7, y+5, z+9, sh, meta);
		world.setBlock(x+7, y+5, z+10, sh, meta);
		world.setBlock(x+7, y+5, z+11, sh, meta);
		world.setBlock(x+7, y+5, z+12, sh, meta);
		world.setBlock(x+7, y+5, z+13, sh, meta);
		world.setBlock(x+7, y+5, z+14, sh, meta);
		world.setBlock(x+7, y+5, z+15, sh, meta);
		world.setBlock(x+7, y+5, z+16, sh, meta);
		world.setBlock(x+7, y+6, z+5, sh, meta);
		world.setBlock(x+7, y+6, z+6, sh, meta);
		world.setBlock(x+7, y+6, z+7, sh, meta);
		world.setBlock(x+7, y+6, z+8, sh, meta);
		world.setBlock(x+7, y+6, z+9, sh, meta);
		world.setBlock(x+7, y+6, z+10, sh, meta);
		world.setBlock(x+7, y+6, z+11, sh, meta);
		world.setBlock(x+7, y+6, z+12, sh, meta);
		world.setBlock(x+7, y+6, z+13, sh, meta);
		world.setBlock(x+7, y+6, z+14, sh, meta);
		world.setBlock(x+8, y+0, z+1, sh, meta);
		world.setBlock(x+8, y+0, z+2, sh, meta);
		world.setBlock(x+8, y+0, z+3, sh, meta);
		world.setBlock(x+8, y+0, z+4, sh, meta);
		world.setBlock(x+8, y+0, z+5, sh, meta);
		world.setBlock(x+8, y+0, z+6, sh, meta);
		world.setBlock(x+8, y+0, z+7, sh, meta);
		world.setBlock(x+8, y+0, z+8, sh, meta);
		world.setBlock(x+8, y+0, z+9, sh, meta);
		world.setBlock(x+8, y+0, z+10, sh, meta);
		world.setBlock(x+8, y+0, z+11, sh, meta);
		world.setBlock(x+8, y+0, z+12, sh, meta);
		world.setBlock(x+8, y+0, z+13, sh, meta);
		world.setBlock(x+8, y+0, z+14, sh, meta);
		world.setBlock(x+8, y+0, z+15, sh, meta);
		world.setBlock(x+8, y+0, z+16, sh, meta);
		world.setBlock(x+8, y+1, z+1, sh, meta);
		world.setBlock(x+8, y+1, z+2, sh, meta);
		world.setBlock(x+8, y+1, z+3, sh, meta);
		world.setBlock(x+8, y+1, z+15, sh, meta);
		world.setBlock(x+8, y+1, z+16, sh, meta);
		world.setBlock(x+8, y+2, z+1, sh, meta);
		world.setBlock(x+8, y+2, z+2, sh, meta);
		world.setBlock(x+8, y+2, z+3, sh, meta);
		world.setBlock(x+8, y+2, z+15, sh, meta);
		world.setBlock(x+8, y+2, z+16, sh, meta);
		world.setBlock(x+8, y+3, z+1, sh, meta);
		world.setBlock(x+8, y+3, z+2, sh, meta);
		world.setBlock(x+8, y+3, z+3, sh, meta);
		world.setBlock(x+8, y+3, z+15, sh, meta);
		world.setBlock(x+8, y+3, z+16, sh, meta);
		world.setBlock(x+8, y+4, z+1, sh, meta);
		world.setBlock(x+8, y+4, z+2, sh, meta);
		world.setBlock(x+8, y+4, z+3, sh, meta);
		world.setBlock(x+8, y+4, z+15, sh, meta);
		world.setBlock(x+8, y+4, z+16, sh, meta);
		world.setBlock(x+8, y+5, z+1, sh, meta);
		world.setBlock(x+8, y+5, z+2, sh, meta);
		world.setBlock(x+8, y+5, z+3, sh, meta);
		world.setBlock(x+8, y+5, z+4, sh, meta);
		world.setBlock(x+8, y+5, z+5, sh, meta);
		world.setBlock(x+8, y+5, z+6, sh, meta);
		world.setBlock(x+8, y+5, z+7, sh, meta);
		world.setBlock(x+8, y+5, z+8, sh, meta);
		world.setBlock(x+8, y+5, z+9, sh, meta);
		world.setBlock(x+8, y+5, z+10, sh, meta);
		world.setBlock(x+8, y+5, z+11, sh, meta);
		world.setBlock(x+8, y+5, z+12, sh, meta);
		world.setBlock(x+8, y+5, z+13, sh, meta);
		world.setBlock(x+8, y+5, z+14, sh, meta);
		world.setBlock(x+8, y+5, z+15, sh, meta);
		world.setBlock(x+8, y+5, z+16, sh, meta);
		world.setBlock(x+9, y+0, z+3, sh, meta);
		world.setBlock(x+9, y+0, z+4, sh, meta);
		world.setBlock(x+9, y+0, z+5, sh, meta);
		world.setBlock(x+9, y+0, z+6, sh, meta);
		world.setBlock(x+9, y+0, z+7, sh, meta);
		world.setBlock(x+9, y+0, z+8, sh, meta);
		world.setBlock(x+9, y+0, z+9, sh, meta);
		world.setBlock(x+9, y+0, z+10, sh, meta);
		world.setBlock(x+9, y+0, z+11, sh, meta);
		world.setBlock(x+9, y+0, z+12, sh, meta);
		world.setBlock(x+9, y+0, z+13, sh, meta);
		world.setBlock(x+9, y+0, z+14, sh, meta);
		world.setBlock(x+9, y+0, z+15, sh, meta);
		world.setBlock(x+9, y+1, z+3, sh, meta);
		world.setBlock(x+9, y+1, z+4, sh, meta);
		world.setBlock(x+9, y+1, z+5, sh, meta);
		world.setBlock(x+9, y+1, z+14, sh, meta);
		world.setBlock(x+9, y+1, z+15, sh, meta);
		world.setBlock(x+9, y+2, z+3, sh, meta);
		world.setBlock(x+9, y+2, z+4, sh, meta);
		world.setBlock(x+9, y+2, z+5, sh, meta);
		world.setBlock(x+9, y+2, z+14, sh, meta);
		world.setBlock(x+9, y+2, z+15, sh, meta);
		world.setBlock(x+9, y+3, z+3, sh, meta);
		world.setBlock(x+9, y+3, z+4, sh, meta);
		world.setBlock(x+9, y+3, z+5, sh, meta);
		world.setBlock(x+9, y+3, z+14, sh, meta);
		world.setBlock(x+9, y+3, z+15, sh, meta);
		world.setBlock(x+9, y+4, z+3, sh, meta);
		world.setBlock(x+9, y+4, z+4, sh, meta);
		world.setBlock(x+9, y+4, z+5, sh, meta);
		world.setBlock(x+9, y+4, z+6, sh, meta);
		world.setBlock(x+9, y+4, z+7, sh, meta);
		world.setBlock(x+9, y+4, z+8, sh, meta);
		world.setBlock(x+9, y+4, z+9, sh, meta);
		world.setBlock(x+9, y+4, z+10, sh, meta);
		world.setBlock(x+9, y+4, z+11, sh, meta);
		world.setBlock(x+9, y+4, z+12, sh, meta);
		world.setBlock(x+9, y+4, z+13, sh, meta);
		world.setBlock(x+9, y+4, z+14, sh, meta);
		world.setBlock(x+9, y+4, z+15, sh, meta);
		world.setBlock(x+9, y+5, z+3, sh, meta);
		world.setBlock(x+9, y+5, z+4, sh, meta);
		world.setBlock(x+9, y+5, z+5, sh, meta);
		world.setBlock(x+9, y+5, z+6, sh, meta);
		world.setBlock(x+9, y+5, z+7, sh, meta);
		world.setBlock(x+9, y+5, z+8, sh, meta);
		world.setBlock(x+9, y+5, z+9, sh, meta);
		world.setBlock(x+9, y+5, z+10, sh, meta);
		world.setBlock(x+9, y+5, z+11, sh, meta);
		world.setBlock(x+9, y+5, z+12, sh, meta);
		world.setBlock(x+9, y+5, z+13, sh, meta);
		world.setBlock(x+9, y+5, z+14, sh, meta);
		world.setBlock(x+9, y+5, z+15, sh, meta);
		world.setBlock(x+10, y+1, z+5, sh, meta);
		world.setBlock(x+10, y+1, z+6, sh, meta);
		world.setBlock(x+10, y+1, z+7, sh, meta);
		world.setBlock(x+10, y+1, z+8, sh, meta);
		world.setBlock(x+10, y+1, z+9, sh, meta);
		world.setBlock(x+10, y+1, z+10, sh, meta);
		world.setBlock(x+10, y+1, z+11, sh, meta);
		world.setBlock(x+10, y+1, z+12, sh, meta);
		world.setBlock(x+10, y+1, z+13, sh, meta);
		world.setBlock(x+10, y+1, z+14, sh, meta);
		world.setBlock(x+10, y+2, z+5, sh, meta);
		world.setBlock(x+10, y+2, z+6, sh, meta);
		world.setBlock(x+10, y+2, z+7, sh, meta);
		world.setBlock(x+10, y+2, z+8, sh, meta);
		world.setBlock(x+10, y+2, z+9, sh, meta);
		world.setBlock(x+10, y+2, z+10, sh, meta);
		world.setBlock(x+10, y+2, z+11, sh, meta);
		world.setBlock(x+10, y+2, z+12, sh, meta);
		world.setBlock(x+10, y+2, z+13, sh, meta);
		world.setBlock(x+10, y+2, z+14, sh, meta);
		world.setBlock(x+10, y+3, z+5, sh, meta);
		world.setBlock(x+10, y+3, z+6, sh, meta);
		world.setBlock(x+10, y+3, z+7, sh, meta);
		world.setBlock(x+10, y+3, z+8, sh, meta);
		world.setBlock(x+10, y+3, z+9, sh, meta);
		world.setBlock(x+10, y+3, z+10, sh, meta);
		world.setBlock(x+10, y+3, z+11, sh, meta);
		world.setBlock(x+10, y+3, z+12, sh, meta);
		world.setBlock(x+10, y+3, z+13, sh, meta);
		world.setBlock(x+10, y+3, z+14, sh, meta);
		world.setBlock(x+10, y+4, z+5, sh, meta);
		world.setBlock(x+10, y+4, z+6, sh, meta);
		world.setBlock(x+10, y+4, z+7, sh, meta);
		world.setBlock(x+10, y+4, z+8, sh, meta);
		world.setBlock(x+10, y+4, z+9, sh, meta);
		world.setBlock(x+10, y+4, z+10, sh, meta);
		world.setBlock(x+10, y+4, z+11, sh, meta);
		world.setBlock(x+10, y+4, z+12, sh, meta);
		world.setBlock(x+10, y+4, z+13, sh, meta);
		world.setBlock(x+10, y+4, z+14, sh, meta);


		world.setBlock(x+1, y+3, z+6, Blocks.air);
		world.setBlock(x+1, y+3, z+7, Blocks.air);
		world.setBlock(x+1, y+3, z+8, Blocks.air);
		world.setBlock(x+1, y+3, z+9, Blocks.air);
		world.setBlock(x+1, y+3, z+10, Blocks.air);
		world.setBlock(x+1, y+3, z+11, Blocks.air);
		world.setBlock(x+1, y+3, z+12, Blocks.air);
		world.setBlock(x+1, y+3, z+13, Blocks.air);
		world.setBlock(x+2, y+1, z+4, Blocks.air);
		world.setBlock(x+2, y+1, z+5, Blocks.air);
		world.setBlock(x+2, y+1, z+6, Blocks.air);
		world.setBlock(x+2, y+1, z+7, Blocks.air);
		world.setBlock(x+2, y+1, z+8, Blocks.air);
		world.setBlock(x+2, y+1, z+9, Blocks.air);
		world.setBlock(x+2, y+1, z+10, Blocks.air);
		world.setBlock(x+2, y+1, z+11, Blocks.air);
		world.setBlock(x+2, y+1, z+12, Blocks.air);
		world.setBlock(x+2, y+1, z+13, Blocks.air);
		world.setBlock(x+2, y+1, z+14, Blocks.air);
		world.setBlock(x+2, y+2, z+4, Blocks.air);
		world.setBlock(x+2, y+2, z+5, Blocks.air);
		world.setBlock(x+2, y+2, z+6, Blocks.air);
		world.setBlock(x+2, y+2, z+7, Blocks.air);
		world.setBlock(x+2, y+2, z+8, Blocks.air);
		world.setBlock(x+2, y+2, z+9, Blocks.air);
		world.setBlock(x+2, y+2, z+10, Blocks.air);
		world.setBlock(x+2, y+2, z+11, Blocks.air);
		world.setBlock(x+2, y+2, z+12, Blocks.air);
		world.setBlock(x+2, y+2, z+13, Blocks.air);
		world.setBlock(x+2, y+2, z+14, Blocks.air);
		world.setBlock(x+2, y+3, z+4, Blocks.air);
		world.setBlock(x+2, y+3, z+5, Blocks.air);
		world.setBlock(x+2, y+3, z+6, Blocks.air);
		world.setBlock(x+2, y+3, z+7, Blocks.air);
		world.setBlock(x+2, y+3, z+8, Blocks.air);
		world.setBlock(x+2, y+3, z+9, Blocks.air);
		world.setBlock(x+2, y+3, z+10, Blocks.air);
		world.setBlock(x+2, y+3, z+11, Blocks.air);
		world.setBlock(x+2, y+3, z+12, Blocks.air);
		world.setBlock(x+2, y+3, z+13, Blocks.air);
		world.setBlock(x+2, y+3, z+14, Blocks.air);
		world.setBlock(x+2, y+4, z+4, Blocks.air);
		world.setBlock(x+2, y+4, z+5, Blocks.air);
		world.setBlock(x+2, y+4, z+6, Blocks.air);
		world.setBlock(x+2, y+4, z+7, Blocks.air);
		world.setBlock(x+2, y+4, z+8, Blocks.air);
		world.setBlock(x+2, y+4, z+9, Blocks.air);
		world.setBlock(x+2, y+4, z+10, Blocks.air);
		world.setBlock(x+2, y+4, z+11, Blocks.air);
		world.setBlock(x+2, y+4, z+12, Blocks.air);
		world.setBlock(x+2, y+4, z+13, Blocks.air);
		world.setBlock(x+2, y+4, z+14, Blocks.air);
		world.setBlock(x+3, y+1, z+2, Blocks.air);
		world.setBlock(x+3, y+1, z+3, Blocks.air);
		world.setBlock(x+3, y+1, z+4, Blocks.air);
		world.setBlock(x+3, y+1, z+5, Blocks.air);
		world.setBlock(x+3, y+1, z+6, Blocks.air);
		world.setBlock(x+3, y+1, z+7, Blocks.air);
		world.setBlock(x+3, y+1, z+8, Blocks.air);
		world.setBlock(x+3, y+1, z+9, Blocks.air);
		world.setBlock(x+3, y+1, z+10, Blocks.air);
		world.setBlock(x+3, y+1, z+11, Blocks.air);
		world.setBlock(x+3, y+1, z+12, Blocks.air);
		world.setBlock(x+3, y+1, z+13, Blocks.air);
		world.setBlock(x+3, y+1, z+14, Blocks.air);
		world.setBlock(x+3, y+1, z+15, Blocks.air);
		world.setBlock(x+3, y+2, z+2, Blocks.air);
		world.setBlock(x+3, y+2, z+3, Blocks.air);
		world.setBlock(x+3, y+2, z+4, Blocks.air);
		world.setBlock(x+3, y+2, z+5, Blocks.air);
		world.setBlock(x+3, y+2, z+6, Blocks.air);
		world.setBlock(x+3, y+2, z+7, Blocks.air);
		world.setBlock(x+3, y+2, z+8, Blocks.air);
		world.setBlock(x+3, y+2, z+9, Blocks.air);
		world.setBlock(x+3, y+2, z+10, Blocks.air);
		world.setBlock(x+3, y+2, z+11, Blocks.air);
		world.setBlock(x+3, y+2, z+12, Blocks.air);
		world.setBlock(x+3, y+2, z+13, Blocks.air);
		world.setBlock(x+3, y+2, z+14, Blocks.air);
		world.setBlock(x+3, y+2, z+15, Blocks.air);
		world.setBlock(x+3, y+3, z+2, Blocks.air);
		world.setBlock(x+3, y+3, z+3, Blocks.air);
		world.setBlock(x+3, y+3, z+4, Blocks.air);
		world.setBlock(x+3, y+3, z+5, Blocks.air);
		world.setBlock(x+3, y+3, z+6, Blocks.air);
		world.setBlock(x+3, y+3, z+7, Blocks.air);
		world.setBlock(x+3, y+3, z+8, Blocks.air);
		world.setBlock(x+3, y+3, z+9, Blocks.air);
		world.setBlock(x+3, y+3, z+10, Blocks.air);
		world.setBlock(x+3, y+3, z+11, Blocks.air);
		world.setBlock(x+3, y+3, z+12, Blocks.air);
		world.setBlock(x+3, y+3, z+13, Blocks.air);
		world.setBlock(x+3, y+3, z+14, Blocks.air);
		world.setBlock(x+3, y+3, z+15, Blocks.air);
		world.setBlock(x+3, y+4, z+2, Blocks.air);
		world.setBlock(x+3, y+4, z+3, Blocks.air);
		world.setBlock(x+3, y+4, z+4, Blocks.air);
		world.setBlock(x+3, y+4, z+5, Blocks.air);
		world.setBlock(x+3, y+4, z+6, Blocks.air);
		world.setBlock(x+3, y+4, z+7, Blocks.air);
		world.setBlock(x+3, y+4, z+8, Blocks.air);
		world.setBlock(x+3, y+4, z+9, Blocks.air);
		world.setBlock(x+3, y+4, z+10, Blocks.air);
		world.setBlock(x+3, y+4, z+11, Blocks.air);
		world.setBlock(x+3, y+4, z+12, Blocks.air);
		world.setBlock(x+3, y+4, z+13, Blocks.air);
		world.setBlock(x+3, y+4, z+14, Blocks.air);
		world.setBlock(x+3, y+4, z+15, Blocks.air);
		world.setBlock(x+4, y+1, z+0, Blocks.air);
		world.setBlock(x+4, y+1, z+1, Blocks.air);
		world.setBlock(x+4, y+1, z+2, Blocks.air);
		world.setBlock(x+4, y+1, z+3, Blocks.air);
		world.setBlock(x+4, y+1, z+4, Blocks.air);
		world.setBlock(x+4, y+1, z+5, Blocks.air);
		world.setBlock(x+4, y+1, z+6, Blocks.air);
		world.setBlock(x+4, y+1, z+7, Blocks.air);
		world.setBlock(x+4, y+1, z+8, Blocks.air);
		world.setBlock(x+4, y+1, z+9, Blocks.air);
		world.setBlock(x+4, y+1, z+10, Blocks.air);
		world.setBlock(x+4, y+1, z+11, Blocks.air);
		world.setBlock(x+4, y+1, z+12, Blocks.air);
		world.setBlock(x+4, y+1, z+13, Blocks.air);
		world.setBlock(x+4, y+1, z+14, Blocks.air);
		world.setBlock(x+4, y+1, z+15, Blocks.air);
		world.setBlock(x+4, y+1, z+16, Blocks.air);
		world.setBlock(x+4, y+1, z+17, Blocks.air);
		world.setBlock(x+4, y+1, z+19, Blocks.air);
		world.setBlock(x+4, y+2, z+0, Blocks.air);
		world.setBlock(x+4, y+2, z+1, Blocks.air);
		world.setBlock(x+4, y+2, z+2, Blocks.air);
		world.setBlock(x+4, y+2, z+3, Blocks.air);
		world.setBlock(x+4, y+2, z+4, Blocks.air);
		world.setBlock(x+4, y+2, z+5, Blocks.air);
		world.setBlock(x+4, y+2, z+6, Blocks.air);
		world.setBlock(x+4, y+2, z+7, Blocks.air);
		world.setBlock(x+4, y+2, z+8, Blocks.air);
		world.setBlock(x+4, y+2, z+9, Blocks.air);
		world.setBlock(x+4, y+2, z+10, Blocks.air);
		world.setBlock(x+4, y+2, z+11, Blocks.air);
		world.setBlock(x+4, y+2, z+12, Blocks.air);
		world.setBlock(x+4, y+2, z+13, Blocks.air);
		world.setBlock(x+4, y+2, z+14, Blocks.air);
		world.setBlock(x+4, y+2, z+15, Blocks.air);
		world.setBlock(x+4, y+2, z+16, Blocks.air);
		world.setBlock(x+4, y+2, z+17, Blocks.air);
		world.setBlock(x+4, y+2, z+19, Blocks.air);
		world.setBlock(x+4, y+3, z+0, Blocks.air);
		world.setBlock(x+4, y+3, z+1, Blocks.air);
		world.setBlock(x+4, y+3, z+2, Blocks.air);
		world.setBlock(x+4, y+3, z+3, Blocks.air);
		world.setBlock(x+4, y+3, z+4, Blocks.air);
		world.setBlock(x+4, y+3, z+5, Blocks.air);
		world.setBlock(x+4, y+3, z+6, Blocks.air);
		world.setBlock(x+4, y+3, z+7, Blocks.air);
		world.setBlock(x+4, y+3, z+8, Blocks.air);
		world.setBlock(x+4, y+3, z+9, Blocks.air);
		world.setBlock(x+4, y+3, z+10, Blocks.air);
		world.setBlock(x+4, y+3, z+11, Blocks.air);
		world.setBlock(x+4, y+3, z+12, Blocks.air);
		world.setBlock(x+4, y+3, z+13, Blocks.air);
		world.setBlock(x+4, y+3, z+14, Blocks.air);
		world.setBlock(x+4, y+3, z+15, Blocks.air);
		world.setBlock(x+4, y+3, z+16, Blocks.air);
		world.setBlock(x+4, y+3, z+17, Blocks.air);
		world.setBlock(x+4, y+3, z+19, Blocks.air);
		world.setBlock(x+4, y+4, z+2, Blocks.air);
		world.setBlock(x+4, y+4, z+3, Blocks.air);
		world.setBlock(x+4, y+4, z+4, Blocks.air);
		world.setBlock(x+4, y+4, z+5, Blocks.air);
		world.setBlock(x+4, y+4, z+6, Blocks.air);
		world.setBlock(x+4, y+4, z+7, Blocks.air);
		world.setBlock(x+4, y+4, z+8, Blocks.air);
		world.setBlock(x+4, y+4, z+9, Blocks.air);
		world.setBlock(x+4, y+4, z+10, Blocks.air);
		world.setBlock(x+4, y+4, z+11, Blocks.air);
		world.setBlock(x+4, y+4, z+12, Blocks.air);
		world.setBlock(x+4, y+4, z+13, Blocks.air);
		world.setBlock(x+4, y+4, z+14, Blocks.air);
		world.setBlock(x+4, y+4, z+15, Blocks.air);
		world.setBlock(x+4, y+5, z+6, Blocks.air);
		world.setBlock(x+4, y+5, z+7, Blocks.air);
		world.setBlock(x+4, y+5, z+8, Blocks.air);
		world.setBlock(x+4, y+5, z+9, Blocks.air);
		world.setBlock(x+4, y+5, z+10, Blocks.air);
		world.setBlock(x+4, y+5, z+11, Blocks.air);
		world.setBlock(x+4, y+5, z+12, Blocks.air);
		world.setBlock(x+4, y+5, z+13, Blocks.air);
		world.setBlock(x+5, y+1, z+0, Blocks.air);
		world.setBlock(x+5, y+1, z+1, Blocks.air);
		world.setBlock(x+5, y+1, z+2, Blocks.air);
		world.setBlock(x+5, y+1, z+3, Blocks.air);
		world.setBlock(x+5, y+1, z+4, Blocks.air);
		world.setBlock(x+5, y+1, z+6, Blocks.air);
		world.setBlock(x+5, y+1, z+7, Blocks.air);
		world.setBlock(x+5, y+1, z+8, Blocks.air);
		world.setBlock(x+5, y+1, z+9, Blocks.air);
		world.setBlock(x+5, y+1, z+10, Blocks.air);
		world.setBlock(x+5, y+1, z+11, Blocks.air);
		world.setBlock(x+5, y+1, z+12, Blocks.air);
		world.setBlock(x+5, y+1, z+13, Blocks.air);
		world.setBlock(x+5, y+1, z+14, Blocks.air);
		world.setBlock(x+5, y+1, z+15, Blocks.air);
		world.setBlock(x+5, y+1, z+16, Blocks.air);
		world.setBlock(x+5, y+1, z+17, Blocks.air);
		world.setBlock(x+5, y+1, z+19, Blocks.air);
		world.setBlock(x+5, y+2, z+0, Blocks.air);
		world.setBlock(x+5, y+2, z+1, Blocks.air);
		world.setBlock(x+5, y+2, z+2, Blocks.air);
		world.setBlock(x+5, y+2, z+3, Blocks.air);
		world.setBlock(x+5, y+2, z+4, Blocks.air);
		world.setBlock(x+5, y+2, z+5, Blocks.air);
		world.setBlock(x+5, y+2, z+6, Blocks.air);
		world.setBlock(x+5, y+2, z+7, Blocks.air);
		world.setBlock(x+5, y+2, z+8, Blocks.air);
		world.setBlock(x+5, y+2, z+9, Blocks.air);
		world.setBlock(x+5, y+2, z+10, Blocks.air);
		world.setBlock(x+5, y+2, z+11, Blocks.air);
		world.setBlock(x+5, y+2, z+12, Blocks.air);
		world.setBlock(x+5, y+2, z+13, Blocks.air);
		world.setBlock(x+5, y+2, z+14, Blocks.air);
		world.setBlock(x+5, y+2, z+15, Blocks.air);
		world.setBlock(x+5, y+2, z+16, Blocks.air);
		world.setBlock(x+5, y+2, z+17, Blocks.air);
		world.setBlock(x+5, y+2, z+19, Blocks.air);
		world.setBlock(x+5, y+3, z+0, Blocks.air);
		world.setBlock(x+5, y+3, z+1, Blocks.air);
		world.setBlock(x+5, y+3, z+2, Blocks.air);
		world.setBlock(x+5, y+3, z+3, Blocks.air);
		world.setBlock(x+5, y+3, z+4, Blocks.air);
		world.setBlock(x+5, y+3, z+5, Blocks.air);
		world.setBlock(x+5, y+3, z+6, Blocks.air);
		world.setBlock(x+5, y+3, z+7, Blocks.air);
		world.setBlock(x+5, y+3, z+8, Blocks.air);
		world.setBlock(x+5, y+3, z+9, Blocks.air);
		world.setBlock(x+5, y+3, z+10, Blocks.air);
		world.setBlock(x+5, y+3, z+11, Blocks.air);
		world.setBlock(x+5, y+3, z+12, Blocks.air);
		world.setBlock(x+5, y+3, z+13, Blocks.air);
		world.setBlock(x+5, y+3, z+14, Blocks.air);
		world.setBlock(x+5, y+3, z+15, Blocks.air);
		world.setBlock(x+5, y+3, z+16, Blocks.air);
		world.setBlock(x+5, y+3, z+17, Blocks.air);
		world.setBlock(x+5, y+3, z+19, Blocks.air);
		world.setBlock(x+5, y+4, z+2, Blocks.air);
		world.setBlock(x+5, y+4, z+3, Blocks.air);
		world.setBlock(x+5, y+4, z+4, Blocks.air);
		world.setBlock(x+5, y+4, z+5, Blocks.air);
		world.setBlock(x+5, y+4, z+6, Blocks.air);
		world.setBlock(x+5, y+4, z+7, Blocks.air);
		world.setBlock(x+5, y+4, z+8, Blocks.air);
		world.setBlock(x+5, y+4, z+9, Blocks.air);
		world.setBlock(x+5, y+4, z+10, Blocks.air);
		world.setBlock(x+5, y+4, z+11, Blocks.air);
		world.setBlock(x+5, y+4, z+12, Blocks.air);
		world.setBlock(x+5, y+4, z+13, Blocks.air);
		world.setBlock(x+5, y+4, z+14, Blocks.air);
		world.setBlock(x+5, y+4, z+15, Blocks.air);
		world.setBlock(x+5, y+5, z+6, Blocks.air);
		world.setBlock(x+5, y+5, z+7, Blocks.air);
		world.setBlock(x+5, y+5, z+8, Blocks.air);
		world.setBlock(x+5, y+5, z+9, Blocks.air);
		world.setBlock(x+5, y+5, z+10, Blocks.air);
		world.setBlock(x+5, y+5, z+11, Blocks.air);
		world.setBlock(x+5, y+5, z+12, Blocks.air);
		world.setBlock(x+5, y+5, z+13, Blocks.air);
		world.setBlock(x+6, y+1, z+0, Blocks.air);
		world.setBlock(x+6, y+1, z+1, Blocks.air);
		world.setBlock(x+6, y+1, z+2, Blocks.air);
		world.setBlock(x+6, y+1, z+3, Blocks.air);
		world.setBlock(x+6, y+1, z+4, Blocks.air);
		world.setBlock(x+6, y+1, z+5, Blocks.air);
		world.setBlock(x+6, y+1, z+6, Blocks.air);
		world.setBlock(x+6, y+1, z+7, Blocks.air);
		world.setBlock(x+6, y+1, z+8, Blocks.air);
		world.setBlock(x+6, y+1, z+9, Blocks.air);
		world.setBlock(x+6, y+1, z+10, Blocks.air);
		world.setBlock(x+6, y+1, z+11, Blocks.air);
		world.setBlock(x+6, y+1, z+12, Blocks.air);
		world.setBlock(x+6, y+1, z+13, Blocks.air);
		world.setBlock(x+6, y+1, z+14, Blocks.air);
		world.setBlock(x+6, y+1, z+15, Blocks.air);
		world.setBlock(x+6, y+1, z+16, Blocks.air);
		world.setBlock(x+6, y+1, z+17, Blocks.air);
		world.setBlock(x+6, y+1, z+19, Blocks.air);
		world.setBlock(x+6, y+2, z+0, Blocks.air);
		world.setBlock(x+6, y+2, z+1, Blocks.air);
		world.setBlock(x+6, y+2, z+2, Blocks.air);
		world.setBlock(x+6, y+2, z+3, Blocks.air);
		world.setBlock(x+6, y+2, z+4, Blocks.air);
		world.setBlock(x+6, y+2, z+5, Blocks.air);
		world.setBlock(x+6, y+2, z+6, Blocks.air);
		world.setBlock(x+6, y+2, z+7, Blocks.air);
		world.setBlock(x+6, y+2, z+8, Blocks.air);
		world.setBlock(x+6, y+2, z+9, Blocks.air);
		world.setBlock(x+6, y+2, z+10, Blocks.air);
		world.setBlock(x+6, y+2, z+11, Blocks.air);
		world.setBlock(x+6, y+2, z+12, Blocks.air);
		world.setBlock(x+6, y+2, z+13, Blocks.air);
		world.setBlock(x+6, y+2, z+14, Blocks.air);
		world.setBlock(x+6, y+2, z+15, Blocks.air);
		world.setBlock(x+6, y+2, z+16, Blocks.air);
		world.setBlock(x+6, y+2, z+17, Blocks.air);
		world.setBlock(x+6, y+2, z+19, Blocks.air);
		world.setBlock(x+6, y+3, z+0, Blocks.air);
		world.setBlock(x+6, y+3, z+1, Blocks.air);
		world.setBlock(x+6, y+3, z+2, Blocks.air);
		world.setBlock(x+6, y+3, z+3, Blocks.air);
		world.setBlock(x+6, y+3, z+4, Blocks.air);
		world.setBlock(x+6, y+3, z+5, Blocks.air);
		world.setBlock(x+6, y+3, z+6, Blocks.air);
		world.setBlock(x+6, y+3, z+7, Blocks.air);
		world.setBlock(x+6, y+3, z+8, Blocks.air);
		world.setBlock(x+6, y+3, z+9, Blocks.air);
		world.setBlock(x+6, y+3, z+10, Blocks.air);
		world.setBlock(x+6, y+3, z+11, Blocks.air);
		world.setBlock(x+6, y+3, z+12, Blocks.air);
		world.setBlock(x+6, y+3, z+13, Blocks.air);
		world.setBlock(x+6, y+3, z+14, Blocks.air);
		world.setBlock(x+6, y+3, z+15, Blocks.air);
		world.setBlock(x+6, y+3, z+16, Blocks.air);
		world.setBlock(x+6, y+3, z+17, Blocks.air);
		world.setBlock(x+6, y+3, z+19, Blocks.air);
		world.setBlock(x+6, y+4, z+2, Blocks.air);
		world.setBlock(x+6, y+4, z+3, Blocks.air);
		world.setBlock(x+6, y+4, z+4, Blocks.air);
		world.setBlock(x+6, y+4, z+5, Blocks.air);
		world.setBlock(x+6, y+4, z+6, Blocks.air);
		world.setBlock(x+6, y+4, z+7, Blocks.air);
		world.setBlock(x+6, y+4, z+8, Blocks.air);
		world.setBlock(x+6, y+4, z+9, Blocks.air);
		world.setBlock(x+6, y+4, z+10, Blocks.air);
		world.setBlock(x+6, y+4, z+11, Blocks.air);
		world.setBlock(x+6, y+4, z+12, Blocks.air);
		world.setBlock(x+6, y+4, z+13, Blocks.air);
		world.setBlock(x+6, y+4, z+14, Blocks.air);
		world.setBlock(x+6, y+4, z+15, Blocks.air);
		world.setBlock(x+6, y+5, z+6, Blocks.air);
		world.setBlock(x+6, y+5, z+7, Blocks.air);
		world.setBlock(x+6, y+5, z+8, Blocks.air);
		world.setBlock(x+6, y+5, z+9, Blocks.air);
		world.setBlock(x+6, y+5, z+10, Blocks.air);
		world.setBlock(x+6, y+5, z+11, Blocks.air);
		world.setBlock(x+6, y+5, z+12, Blocks.air);
		world.setBlock(x+6, y+5, z+13, Blocks.air);
		world.setBlock(x+7, y+1, z+2, Blocks.air);
		world.setBlock(x+7, y+1, z+3, Blocks.air);
		world.setBlock(x+7, y+1, z+4, Blocks.air);
		world.setBlock(x+7, y+1, z+5, Blocks.air);
		world.setBlock(x+7, y+1, z+6, Blocks.air);
		world.setBlock(x+7, y+1, z+7, Blocks.air);
		world.setBlock(x+7, y+1, z+8, Blocks.air);
		world.setBlock(x+7, y+1, z+9, Blocks.air);
		world.setBlock(x+7, y+1, z+10, Blocks.air);
		world.setBlock(x+7, y+1, z+11, Blocks.air);
		world.setBlock(x+7, y+1, z+12, Blocks.air);
		world.setBlock(x+7, y+1, z+13, Blocks.air);
		world.setBlock(x+7, y+1, z+14, Blocks.air);
		world.setBlock(x+7, y+1, z+15, Blocks.air);
		world.setBlock(x+7, y+2, z+2, Blocks.air);
		world.setBlock(x+7, y+2, z+3, Blocks.air);
		world.setBlock(x+7, y+2, z+4, Blocks.air);
		world.setBlock(x+7, y+2, z+5, Blocks.air);
		world.setBlock(x+7, y+2, z+6, Blocks.air);
		world.setBlock(x+7, y+2, z+7, Blocks.air);
		world.setBlock(x+7, y+2, z+8, Blocks.air);
		world.setBlock(x+7, y+2, z+9, Blocks.air);
		world.setBlock(x+7, y+2, z+10, Blocks.air);
		world.setBlock(x+7, y+2, z+11, Blocks.air);
		world.setBlock(x+7, y+2, z+12, Blocks.air);
		world.setBlock(x+7, y+2, z+13, Blocks.air);
		world.setBlock(x+7, y+2, z+14, Blocks.air);
		world.setBlock(x+7, y+2, z+15, Blocks.air);
		world.setBlock(x+7, y+3, z+2, Blocks.air);
		world.setBlock(x+7, y+3, z+3, Blocks.air);
		world.setBlock(x+7, y+3, z+4, Blocks.air);
		world.setBlock(x+7, y+3, z+5, Blocks.air);
		world.setBlock(x+7, y+3, z+6, Blocks.air);
		world.setBlock(x+7, y+3, z+7, Blocks.air);
		world.setBlock(x+7, y+3, z+8, Blocks.air);
		world.setBlock(x+7, y+3, z+9, Blocks.air);
		world.setBlock(x+7, y+3, z+10, Blocks.air);
		world.setBlock(x+7, y+3, z+11, Blocks.air);
		world.setBlock(x+7, y+3, z+12, Blocks.air);
		world.setBlock(x+7, y+3, z+13, Blocks.air);
		world.setBlock(x+7, y+3, z+14, Blocks.air);
		world.setBlock(x+7, y+3, z+15, Blocks.air);
		world.setBlock(x+7, y+4, z+2, Blocks.air);
		world.setBlock(x+7, y+4, z+3, Blocks.air);
		world.setBlock(x+7, y+4, z+4, Blocks.air);
		world.setBlock(x+7, y+4, z+5, Blocks.air);
		world.setBlock(x+7, y+4, z+6, Blocks.air);
		world.setBlock(x+7, y+4, z+7, Blocks.air);
		world.setBlock(x+7, y+4, z+8, Blocks.air);
		world.setBlock(x+7, y+4, z+9, Blocks.air);
		world.setBlock(x+7, y+4, z+10, Blocks.air);
		world.setBlock(x+7, y+4, z+11, Blocks.air);
		world.setBlock(x+7, y+4, z+12, Blocks.air);
		world.setBlock(x+7, y+4, z+13, Blocks.air);
		world.setBlock(x+7, y+4, z+14, Blocks.air);
		world.setBlock(x+7, y+4, z+15, Blocks.air);
		world.setBlock(x+8, y+1, z+4, Blocks.air);
		world.setBlock(x+8, y+1, z+5, Blocks.air);
		world.setBlock(x+8, y+1, z+6, Blocks.air);
		world.setBlock(x+8, y+1, z+7, Blocks.air);
		world.setBlock(x+8, y+1, z+8, Blocks.air);
		world.setBlock(x+8, y+1, z+9, Blocks.air);
		world.setBlock(x+8, y+1, z+10, Blocks.air);
		world.setBlock(x+8, y+1, z+11, Blocks.air);
		world.setBlock(x+8, y+1, z+12, Blocks.air);
		world.setBlock(x+8, y+1, z+13, Blocks.air);
		world.setBlock(x+8, y+1, z+14, Blocks.air);
		world.setBlock(x+8, y+2, z+4, Blocks.air);
		world.setBlock(x+8, y+2, z+5, Blocks.air);
		world.setBlock(x+8, y+2, z+6, Blocks.air);
		world.setBlock(x+8, y+2, z+7, Blocks.air);
		world.setBlock(x+8, y+2, z+8, Blocks.air);
		world.setBlock(x+8, y+2, z+9, Blocks.air);
		world.setBlock(x+8, y+2, z+10, Blocks.air);
		world.setBlock(x+8, y+2, z+11, Blocks.air);
		world.setBlock(x+8, y+2, z+12, Blocks.air);
		world.setBlock(x+8, y+2, z+13, Blocks.air);
		world.setBlock(x+8, y+2, z+14, Blocks.air);
		world.setBlock(x+8, y+3, z+4, Blocks.air);
		world.setBlock(x+8, y+3, z+5, Blocks.air);
		world.setBlock(x+8, y+3, z+6, Blocks.air);
		world.setBlock(x+8, y+3, z+7, Blocks.air);
		world.setBlock(x+8, y+3, z+8, Blocks.air);
		world.setBlock(x+8, y+3, z+9, Blocks.air);
		world.setBlock(x+8, y+3, z+10, Blocks.air);
		world.setBlock(x+8, y+3, z+11, Blocks.air);
		world.setBlock(x+8, y+3, z+12, Blocks.air);
		world.setBlock(x+8, y+3, z+13, Blocks.air);
		world.setBlock(x+8, y+3, z+14, Blocks.air);
		world.setBlock(x+8, y+4, z+4, Blocks.air);
		world.setBlock(x+8, y+4, z+5, Blocks.air);
		world.setBlock(x+8, y+4, z+6, Blocks.air);
		world.setBlock(x+8, y+4, z+7, Blocks.air);
		world.setBlock(x+8, y+4, z+8, Blocks.air);
		world.setBlock(x+8, y+4, z+9, Blocks.air);
		world.setBlock(x+8, y+4, z+10, Blocks.air);
		world.setBlock(x+8, y+4, z+11, Blocks.air);
		world.setBlock(x+8, y+4, z+12, Blocks.air);
		world.setBlock(x+8, y+4, z+13, Blocks.air);
		world.setBlock(x+8, y+4, z+14, Blocks.air);
		world.setBlock(x+9, y+3, z+6, Blocks.air);
		world.setBlock(x+9, y+3, z+7, Blocks.air);
		world.setBlock(x+9, y+3, z+8, Blocks.air);
		world.setBlock(x+9, y+3, z+9, Blocks.air);
		world.setBlock(x+9, y+3, z+10, Blocks.air);
		world.setBlock(x+9, y+3, z+11, Blocks.air);
		world.setBlock(x+9, y+3, z+12, Blocks.air);
		world.setBlock(x+9, y+3, z+13, Blocks.air);
	}

}
